File: Ensayos/Compresion/Clavo4/Clavo4.raw
"Test Type";"Manual"
"Method Name:";"C:\INSTRON\user\template\CYCLE.MTM"
"Name:";""
"Operator ID:";""
"Company:";""
"Lab name:";""
"Test date:";"05/05/2017"
"Temperature:";""
"Humidity:";""
"Note 1:";""
"Note 2:";""
"Note 3:";""
"Geometry:";"Rectangular"
"Specimen";1
"Specimen name:";""
"Width:";0.250000;"in"
"Thickness:";0.060000;"in"
"Length:";1.250000;"in"
"Diameter:";0.039370;"in"
"Inner diameter:";0.019685;"in"
"Outer diameter:";0.039370;"in"
"Wall thickness:";0.019685;"in"
"Area:";0.015000;"in*in"
"Linear density:";1.000000;"den"
"Sled weight:";2.204623;"lbf"
"Loading span:";0.000000;"mm"
"Support span:";1.000000;"mm"
"Span ratio:";"2"
"Fixture type:";"3-point"
"Comment:";""
"Included"
"Final Width:";0.250000;"in"
"Final Thickness:";0.060000;"in"
"Final Length:";1.250000;"in"
"Final Diameter:";0.039370;"in"
"Final Inner diameter:";0.019685;"in"
"Final Outer diameter:";0.039370;"in"
"Final Wall thickness:";0.019685;"in"
"Final Area:";0.015000;"in*in"
"Final Linear density:";1.000000;"den"
"Time sec";"Extension mm";"Strain 1 %";"Load N";"Stress MPa";"Cycle Count ";"Total Cycle Count ";"Repetitions Count ";"Strain [Exten.] %";"True strain %";"Tenacity gf/tex";"True stress Pa"
0;0;0.001514074;47.18984;4.876293;0;0;0;0;0;43308.21;4876293
6;0.02008927;0.001458922;47.30269;4.887955;0;0;0;0.0632733;0.06325329;43411.79;4891047
12;0.0400714;0.00155974;47.4188;4.899953;0;0;0;0.1262091;0.1261296;43518.35;4906137
18;0.05999997;0.001396871;53.83822;5.563293;0;0;0;0.1889763;0.1887979;49409.73;5573807
24;0.07992851;-0.005924216;134.2167;13.86909;0;0;0;0.2517433;0.251427;123176.7;1.3904e+007
30;0.09991065;-0.0228228;270.8679;27.98974;0;0;0;0.3146792;0.3141851;248587.6;2.807782e+007
36;0.1198928;-0.04246044;421.357;43.54031;0;0;0;0.3776151;0.3769039;386698.1;4.370472e+007
42;0.139982;-0.06356732;584.9767;60.44771;0;0;0;0.4408883;0.4399193;536859.2;6.071422e+007
48;0.1599642;-0.08670134;754.8475;78.00107;0;0;0;0.5038242;0.5025593;692757.3;7.839406e+007
54;0.1799999;-0.1106231;928.0982;95.90367;0;0;0;0.5669287;0.5653278;851757.1;9.644738e+007
60;0.199982;-0.1364418;1100.181;113.6856;0;0;0;0.6298646;0.6278893;1009685;1.144016e+008
66;0.2199641;-0.1641011;1268.218;131.0495;0;0;0;0.6928004;0.6904116;1163900;1.319574e+008
72;0.2399463;-0.1913807;1418.251;146.5529;0;0;0;0.7557363;0.7528949;1301593;1.476605e+008
78;0.259982;-0.2229352;1569.226;162.1536;0;0;0;0.8188408;0.8155065;1440148;1.634814e+008
84.00001;0.2800177;-0.2591158;1715.779;177.2975;0;0;0;0.8819455;0.878079;1574647;1.788612e+008
90.00001;0.3000534;-0.300536;1853.532;191.5321;0;0;0;0.9450501;0.9406124;1701069;1.933421e+008
96.00001;0.3200891;-0.3470616;1979.022;204.4993;0;0;0;1.008155;1.003107;1816237;2.06561e+008
102;0.3400712;-0.3993113;2093.386;216.317;0;0;0;1.07109;1.065395;1921194;2.186339e+008
108;0.3600533;-0.4566005;2195.851;226.905;0;0;0;1.134026;1.127644;2015230;2.294782e+008
114;0.3799819;-0.5186378;2287.665;236.3925;0;0;0;1.196793;1.189688;2099493;2.392217e+008
120;0.399964;-0.5844977;2370.276;244.929;0;0;0;1.259729;1.251861;2175308;2.480145e+008
126;0.4198926;-0.6534304;2445.049;252.6556;0;0;0;1.322496;1.313828;2243931;2.559969e+008
132;0.4399818;-0.7247235;2514.125;259.7935;0;0;0;1.38577;1.376256;2307325;2.633936e+008
138;0.4600176;-0.7978994;2578.623;266.4583;0;0;0;1.448874;1.438478;2366518;2.703189e+008
144;0.4800533;-0.8741423;2640.41;272.843;0;0;0;1.511979;1.500662;2423222;2.769683e+008
150;0.500089;-0.9515891;2698.506;278.8462;0;0;0;1.575083;1.562808;2476540;2.832382e+008
154.434;0.5148211;-1.010902;2739.55;283.0874;0;0;0;1.621484;1.608478;2514207;2.876776e+008
160.434;0.4948389;-0.9751047;2492.085;257.516;0;0;0;1.558548;1.546527;2287098;2.615295e+008
166.434;0.4748033;-0.9313177;2291.463;236.785;0;0;0;1.495443;1.484372;2102978;2.40326e+008
172.434;0.4548211;-0.884451;2117.219;218.7798;0;0;0;1.432508;1.422344;1943067;2.219138e+008
178.434;0.434839;-0.8366916;1958.268;202.3548;0;0;0;1.369572;1.360278;1797190;2.051262e+008
184.434;0.4148569;-0.7876589;1809.379;186.9696;0;0;0;1.306636;1.298173;1660548;1.894126e+008
190.434;0.3948212;-0.737455;1664.401;171.9884;0;0;0;1.243531;1.235863;1527495;1.741272e+008
196.434;0.3747854;-0.6864646;1524;157.4803;0;0;0;1.180427;1.173514;1398642;1.593392e+008
202.434;0.3547498;-0.6357455;1388.806;143.5103;0;0;0;1.117322;1.111126;1274570;1.451138e+008
208.434;0.3347141;-0.5854168;1259.011;130.0981;0;0;0;1.054217;1.048699;1155451;1.314696e+008
214.434;0.3146784;-0.5360217;1134.889;117.2721;0;0;0;0.9911129;0.9862336;1041538;1.184344e+008
220.434;0.2946963;-0.487429;1014.901;104.8733;0;0;0;0.9281772;0.9238961;931419.4;1.058467e+008
226.434;0.2747677;-0.4397815;898.8156;92.8778;0;0;0;0.86541;0.8616868;824883.2;9.368157e+007
232.434;0.2548391;-0.393312;786.2146;81.24234;0;0;0;0.8026429;0.7994389;721544.3;8.189443e+007
238.434;0.234857;-0.3475257;674.5218;69.70073;0;0;0;0.7397071;0.7369847;619038.8;7.021631e+007
244.434;0.2148213;-0.3027644;564.2637;58.30737;0;0;0;0.6766025;0.6743238;517850;5.870188e+007
250.434;0.1947856;-0.2600832;455.5686;47.07552;0;0;0;0.6134979;0.6116237;418095.6;4.736433e+007
256.434;0.1746963;-0.2199055;349.1981;36.08388;0;0;0;0.5502247;0.5487164;320474.7;3.628242e+007
262.434;0.1546606;-0.1817246;244.5689;25.27217;0;0;0;0.48712;0.4859374;224451.8;2.539528e+007
268.434;0.1346785;-0.1466595;147.232;15.214;0;0;0;0.4241842;0.4232871;135121.3;1.527853e+007
274.434;0.1146964;-0.1177479;69.07874;7.138151;0;0;0;0.3612484;0.3605974;63396.64;7163937
278.872;0.1198928;-0.1206471;101.2679;10.46437;1;1;0;0.3776151;0.3769039;92938.07;1.050389e+007
284.872;0.1399285;-0.1447905;225.0427;23.25446;1;1;0;0.4407196;0.4397513;206531.7;2.335695e+007
290.872;0.1599642;-0.1716061;369.4088;38.17232;1;1;0;0.5038242;0.5025593;339023;3.836464e+007
296.872;0.1799999;-0.2016074;519.5127;53.68309;1;1;0;0.5669287;0.5653278;476780;5.398743e+007
302.872;0.199982;-0.2339368;669.9279;69.22602;1;1;0;0.6298646;0.6278893;614822.7;6.966205e+007
308.872;0.2199106;-0.2689518;819.3656;84.66795;1;1;0;0.6926317;0.6902441;751968.3;8.525438e+007
314.872;0.2399463;-0.3058811;966.211;99.84201;1;1;0;0.7557363;0.7528949;886734.9;1.005965e+008
320.872;0.259982;-0.3454666;1110.245;114.7255;1;1;0;0.8188408;0.8155065;1018921;1.156649e+008
326.872;0.2800177;-0.387366;1250.599;129.2288;1;1;0;0.8819455;0.878079;1147730;1.303685e+008
332.872;0.3000534;-0.4307876;1386.44;143.2657;1;1;0;0.9450501;0.9406124;1272398;1.446197e+008
338.872;0.3200355;-0.4761054;1518.927;156.9561;1;1;0;1.007986;1.00294;1393987;1.585382e+008
344.872;0.3400712;-0.5242506;1649.973;170.4976;1;1;0;1.07109;1.065395;1514254;1.723238e+008
350.872;0.3600533;-0.5744987;1780.125;183.9466;1;1;0;1.134026;1.127644;1633700;1.860326e+008
356.872;0.3799819;-0.6267374;1908.409;197.2027;1;1;0;1.196793;1.189688;1751432;1.995628e+008
362.872;0.3999105;-0.68053;2034.513;210.2335;1;1;0;1.25956;1.251694;1867164;2.128815e+008
368.872;0.4198926;-0.7357562;2157.299;222.9213;1;1;0;1.322496;1.313828;1979849;2.258694e+008
374.872;0.4399283;-0.791794;2277.871;235.3805;1;1;0;1.385601;1.376089;2090504;2.386419e+008
380.872;0.459964;-0.8493426;2393.776;247.3573;1;1;0;1.448705;1.438312;2196875;2.509408e+008
386.872;0.4800533;-0.9095521;2506.101;258.9643;1;1;0;1.511979;1.500662;2299961;2.628798e+008
392.872;0.500089;-0.9730131;2607.082;269.399;1;1;0;1.575083;1.562808;2392636;2.736423e+008
397.01;0.5072675;-1.005618;2610.678;269.7706;1;1;0;1.597693;1.585064;2395936;2.740807e+008
403.01;0.4871247;-0.9657123;2373.494;245.2615;1;1;0;1.534251;1.5226;2178261;2.490245e+008
409.01;0.467089;-0.9215239;2178.162;225.0771;1;1;0;1.471146;1.46043;1998996;2.283884e+008
415.01;0.4469997;-0.874635;2006.711;207.3605;1;1;0;1.407873;1.398055;1841648;2.102799e+008
421.01;0.4270176;-0.8264765;1851.228;191.2939;1;1;0;1.344937;1.335973;1698954;1.938667e+008
427.01;0.4070354;-0.7778305;1703.27;176.0049;1;1;0;1.282001;1.273853;1563167;1.782613e+008
433.01;0.3871605;-0.7281975;1559.477;161.1463;1;1;0;1.219403;1.212028;1431201;1.631113e+008
439.01;0.3671783;-0.6779825;1420.863;146.8228;1;1;0;1.156467;1.149831;1303989;1.485207e+008
445.01;0.3471962;-0.6277263;1287.42;133.0337;1;1;0;1.093531;1.087596;1181523;1.344884e+008
451.01;0.3271605;-0.5781508;1159.264;119.7909;1;1;0;1.030427;1.025154;1063908;1.210252e+008
457.01;0.3070712;-0.52902;1036.311;107.0857;1;1;0;0.9671534;0.9625064;951069.1;1.081214e+008
463.01;0.2870355;-0.4803083;916.8924;94.74574;1;1;0;0.904049;0.8999869;841473.1;9.560229e+007
469.01;0.2669998;-0.4330711;802.3066;82.90518;1;1;0;0.8409443;0.8374281;736312.6;8.360237e+007
475.01;0.2470177;-0.387056;691.8708;71.49345;1;1;0;0.7780085;0.7749976;634960.7;7.204968e+007
481.01;0.2270891;-0.3421024;583.1082;60.25463;1;1;0;0.7152414;0.7126957;535144.4;6.06856e+007
487.01;0.207107;-0.2983277;475.464;49.13137;1;1;0;0.6523055;0.6501872;436354.5;4.945186e+007
493.01;0.1871784;-0.2573713;369.8034;38.2131;1;1;0;0.5895384;0.5878074;339385.1;3.843838e+007
499.01;0.1671963;-0.2188816;266.327;27.52051;1;1;0;0.5266026;0.5252209;244420.1;2.766543e+007
505.01;0.1471606;-0.183518;166.3956;17.19424;1;1;0;0.463498;0.4624272;152708.6;1.727394e+007
511.01;0.1271785;-0.1526164;81.99806;8.47315;1;1;0;0.4005622;0.3997621;75253.28;8507090
515.82;0.1310356;-0.154117;111.6211;11.53421;2;2;0;0.4127106;0.4118613;102439.7;1.158181e+007
521.82;0.1509642;-0.1788709;237.2478;24.51566;2;2;0;0.4754778;0.4743509;217732.9;2.463222e+007
527.82;0.1709999;-0.2073517;378.8632;39.14928;2;2;0;0.5385823;0.5371371;347699.7;3.936013e+007
533.82;0.1910356;-0.2386091;523.9739;54.14408;2;2;0;0.6016868;0.599884;480874.3;5.446986e+007
539.82;0.2110713;-0.2729344;670.2082;69.25499;2;2;0;0.6647915;0.6625915;615079.9;6.971539e+007
545.82;0.231107;-0.3095486;815.3971;84.25787;2;2;0;0.727896;0.7252596;748326.3;8.487118e+007
551.82;0.2510891;-0.3483219;957.9712;98.99055;2;2;0;0.7908319;0.7877212;879172.9;9.97734e+007
557.82;0.2710177;-0.389374;1097.673;113.4264;2;2;0;0.853599;0.8499764;1007383;1.143946e+008
563.82;0.2910534;-0.4324015;1235.915;127.7115;2;2;0;0.9167036;0.9125273;1134255;1.288822e+008
569.82;0.3110355;-0.4774212;1370.749;141.6443;2;2;0;0.9796394;0.974872;1257997;1.430319e+008
575.82;0.3310712;-0.5237086;1502.821;155.2918;2;2;0;1.042744;1.037345;1379206;1.569111e+008
581.82;0.3511069;-0.5725821;1635.194;168.9704;2;2;0;1.105849;1.099779;1500690;1.708389e+008
587.82;0.3711426;-0.6232208;1767.403;182.632;2;2;0;1.168953;1.162174;1622024;1.847669e+008
593.82;0.3911783;-0.6754871;1898.157;196.1433;2;2;0;1.232058;1.22453;1742023;1.985599e+008
599.82;0.4111604;-0.7286278;2027.357;209.494;2;2;0;1.294994;1.28668;1860596;2.122069e+008
605.82;0.431089;-0.7825162;2153.366;222.5149;2;2;0;1.357761;1.348626;1976240;2.255361e+008
611.82;0.4510175;-0.836852;2277.037;235.2943;2;2;0;1.420528;1.410533;2089739;2.386368e+008
617.82;0.4709997;-0.8932789;2399.476;247.9463;2;2;0;1.483464;1.472568;2202106;2.516245e+008
623.82;0.4910354;-0.9512145;2518.793;260.2758;2;2;0;1.546568;1.534731;2311609;2.643012e+008
629.82;0.5110711;-1.01373;2628.196;271.5808;2;2;0;1.609673;1.596855;2412013;2.759524e+008
635.82;0.5311068;-1.085303;2714.828;280.5327;2;2;0;1.672777;1.65894;2491518;2.852254e+008
641.82;0.5511961;-1.164075;2784.564;287.7388;2;2;0;1.736051;1.721153;2555518;2.927341e+008
647.82;0.5711782;-1.246806;2845.037;293.9878;2;2;0;1.798986;1.782996;2611018;2.992766e+008
653.82;0.5911603;-1.333398;2901.06;299.7768;2;2;0;1.861922;1.844801;2662432;3.053584e+008
659.82;0.6110888;-1.422894;2951.796;305.0196;2;2;0;1.924689;1.906401;2708995;3.108902e+008
665.82;0.6310174;-1.511993;3000.012;310.0019;2;2;0;1.987456;1.967964;2753245;3.16163e+008
671.82;0.6509996;-1.602541;3046.315;314.7865;2;2;0;2.050392;2.029655;2795739;3.212409e+008
677.82;0.6709817;-1.693083;3089.951;319.2956;2;2;0;2.113328;2.091307;2835786;3.260433e+008
683.82;0.6910174;-1.785264;3132.688;323.7118;2;2;0;2.176433;2.153087;2875008;3.307572e+008
689.82;0.7110531;-1.879469;3173.818;327.9619;2;2;0;2.239537;2.214828;2912755;3.353067e+008
695.82;0.7310888;-1.974757;3214.164;332.1309;2;2;0;2.302642;2.276531;2949781;3.397787e+008
700.694;0.7273388;-1.990164;3088.006;319.0946;2;2;0;2.290831;2.264985;2834001;3.264046e+008
706.694;0.7073567;-1.947279;2854.418;294.9571;2;2;0;2.227895;2.20344;2619627;3.015284e+008
712.694;0.6873746;-1.898616;2660.275;274.8957;2;2;0;2.164959;2.141857;2441453;2.80847e+008
718.694;0.6673925;-1.848291;2485.939;256.8808;2;2;0;2.102023;2.080236;2281457;2.622805e+008
724.694;0.6473567;-1.795928;2327.43;240.5016;2;2;0;2.038919;2.018411;2135986;2.454052e+008
730.694;0.627321;-1.742506;2176.528;224.9083;2;2;0;1.975814;1.956548;1997497;2.293521e+008
736.694;0.6073389;-1.687594;2031.1;209.8808;2;2;0;1.912879;1.894813;1864031;2.138955e+008
742.694;0.5873567;-1.631029;1890.647;195.3673;2;2;0;1.849942;1.833039;1735131;1.989814e+008
748.694;0.5673746;-1.57411;1756.852;181.5418;2;2;0;1.787007;1.771227;1612342;1.84786e+008
754.694;0.5474461;-1.51704;1629.457;168.3775;2;2;0;1.72424;1.709543;1495425;1.712808e+008
760.694;0.5274104;-1.459081;1506.949;155.7184;2;2;0;1.661135;1.647489;1382994;1.583051e+008
766.694;0.5073211;-1.400484;1388.545;143.4832;2;2;0;1.597862;1.58523;1274329;1.457759e+008
772.694;0.4872854;-1.341811;1276.373;131.8921;2;2;0;1.534757;1.523099;1171384;1.339163e+008
778.694;0.4672497;-1.282823;1168.103;120.7042;2;2;0;1.471653;1.460929;1072020;1.224806e+008
784.694;0.447214;-1.223178;1064.344;109.9824;2;2;0;1.408548;1.39872;976795.9;1.115316e+008
790.694;0.4272319;-1.162977;964.952;99.7119;2;2;0;1.345612;1.336639;885579.4;1.010536e+008
796.694;0.4073033;-1.10199;869.0622;89.80327;2;2;0;1.282845;1.274686;797577.1;9.095531e+007
802.694;0.3873747;-1.039628;775.6668;80.1524;2;2;0;1.220078;1.212695;711864;8.113032e+007
808.694;0.3673926;-0.97674;686.166;70.90395;2;2;0;1.157142;1.150498;629725.1;7.172442e+007
814.694;0.3473569;-0.9134593;600.1441;62.01501;2;2;0;1.094038;1.088096;550779;6.269348e+007
820.694;0.3273212;-0.8511865;517.555;53.48079;2;2;0;1.030933;1.025655;474983.3;5.403214e+007
826.694;0.3072855;-0.7904061;438.5285;45.3147;2;2;0;0.9678284;0.9631749;402457.2;4.575327e+007
832.694;0.2872498;-0.7314365;363.0578;37.51605;2;2;0;0.9047238;0.9006557;333194.3;3.785546e+007
838.694;0.2672141;-0.6748762;291.5581;30.12773;2;2;0;0.8416193;0.8380974;267575.9;3.038129e+007
844.694;0.247232;-0.6206328;223.4061;23.08534;2;2;0;0.7786834;0.7756673;205029.7;2.32651e+007
850.694;0.2273034;-0.568158;159.2325;16.45406;2;2;0;0.7159163;0.7133658;146134.8;1.657185e+007
856.694;0.2073749;-0.52028;105.1583;10.86638;2;2;0;0.6531492;0.6510254;96508.47;1.093735e+007
862.694;0.1873927;-0.4802831;65.40876;6.758919;2;2;0;0.5902133;0.5884784;60028.54;6798811
866.942;0.1865356;-0.4744703;74.69131;7.718118;3;3;0;0.5875137;0.5857946;68547.55;7763463
872.942;0.2065177;-0.5010532;145.2579;15.01001;3;3;0;0.6504495;0.6483432;133309.6;1.510764e+007
878.942;0.2264463;-0.5350186;243.0944;25.1198;3;3;0;0.7132167;0.7106853;223098.5;2.529896e+007
884.942;0.2464284;-0.5705396;360.3079;37.23189;3;3;0;0.7761524;0.7731558;330670.7;3.752087e+007
890.942;0.2664641;-0.6087316;484.5093;50.06606;3;3;0;0.839257;0.8357548;444655.8;5.048625e+007
896.942;0.2864998;-0.6500801;611.7164;63.21082;3;3;0;0.9023617;0.8983147;561399.4;6.378121e+007
902.942;0.3065355;-0.6948134;738.6843;76.33086;3;3;0;0.9654662;0.9608353;677923.5;7.706781e+007
908.942;0.3265712;-0.7420333;864.517;89.3336;3;3;0;1.028571;1.023317;793405.8;9.025247e+007
914.942;0.3466069;-0.7926196;989.7285;102.2722;3;3;0;1.091675;1.08576;908318;1.033886e+008
920.942;0.3665355;-0.8450637;1113.299;115.0411;3;3;0;1.154442;1.14783;1021724;1.163692e+008
926.942;0.3864641;-0.8993753;1234.692;127.5851;3;3;0;1.21721;1.209861;1133132;1.29138e+008
932.942;0.4064462;-0.9544439;1353.289;139.8401;3;3;0;1.280145;1.272021;1241974;1.416303e+008
938.942;0.4263748;-1.010565;1468.695;151.7654;3;3;0;1.342913;1.333975;1347887;1.538035e+008
944.942;0.4464104;-1.067187;1582.874;163.564;3;3;0;1.406017;1.396224;1452674;1.658637e+008
950.942;0.4664461;-1.125181;1697.475;175.4061;3;3;0;1.469122;1.458435;1557849;1.77983e+008
956.942;0.4864818;-1.184455;1811.56;187.1949;3;3;0;1.532226;1.520606;1662550;1.900632e+008
962.942;0.5064639;-1.244768;1925.873;199.0073;3;3;0;1.595162;1.582573;1767460;2.021818e+008
968.942;0.5264996;-1.306552;2040.527;210.8549;3;3;0;1.658267;1.644667;1872683;2.143514e+008
974.942;0.5464282;-1.369558;2154.934;222.6769;3;3;0;1.721034;1.706392;1977679;2.265093e+008
980.942;0.5664639;-1.434556;2270.325;234.6007;3;3;0;1.784138;1.768409;2083578;2.387863e+008
986.942;0.5864996;-1.500399;2385.453;246.4973;3;3;0;1.847243;1.830389;2189237;2.510507e+008
992.9421;0.6065353;-1.567874;2500.743;258.4107;3;3;0;1.910347;1.892329;2295044;2.633472e+008
998.9421;0.626571;-1.635405;2613.768;270.0899;3;3;0;1.973452;1.954232;2398772;2.7542e+008
1004.942;0.6465532;-1.70328;2723.363;281.4147;3;3;0;2.036388;2.015931;2499352;2.871454e+008
1010.942;0.6665888;-1.771797;2828.596;292.2888;3;3;0;2.099492;2.077757;2595929;2.984254e+008
1016.942;0.686571;-1.842107;2927.988;302.5594;3;3;0;2.162428;2.13938;2687145;3.09102e+008
1022.942;0.7064996;-1.91553;3019.389;312.0042;3;3;0;2.225195;2.200799;2771028;3.189468e+008
1028.942;0.7264281;-1.993755;3098.705;320.2001;3;3;0;2.287963;2.262181;2843820;3.275262e+008
1033.83;0.7160352;-1.983489;2931.854;302.9588;3;3;0;2.255229;2.230175;2690693;3.097912e+008
1039.83;0.6959996;-1.939333;2708.748;279.9045;3;3;0;2.192125;2.168443;2485939;2.860404e+008
1045.83;0.6761245;-1.890531;2520.537;260.456;3;3;0;2.129526;2.107169;2313209;2.660025e+008
1051.83;0.6561424;-1.839866;2350.401;242.8753;3;3;0;2.06659;2.045526;2157068;2.478945e+008
1057.83;0.6361603;-1.787779;2194.927;226.8096;3;3;0;2.003654;1.983846;2014383;2.313541e+008
1063.83;0.6161781;-1.734;2045.262;211.3442;3;3;0;1.940719;1.922127;1877028;2.154458e+008
1069.83;0.596196;-1.678712;1900.431;196.3782;3;3;0;1.877783;1.86037;1744110;2.000658e+008
1075.83;0.5761603;-1.622187;1761.205;181.9916;3;3;0;1.814678;1.798409;1616337;1.852941e+008
1081.83;0.5561246;-1.565474;1629.043;168.3348;3;3;0;1.751574;1.73641;1495045;1.712833e+008
1087.83;0.5361425;-1.508566;1503.275;155.3387;3;3;0;1.688638;1.674539;1379623;1.579619e+008
1093.83;0.5161604;-1.451036;1382.038;142.8109;3;3;0;1.625702;1.612629;1268358;1.451325e+008
1099.83;0.4961782;-1.393136;1266.974;130.9209;3;3;0;1.562766;1.550681;1162758;1.329669e+008
1105.83;0.4761961;-1.334809;1156.685;119.5243;3;3;0;1.49983;1.488694;1061541;1.21317e+008
1111.83;0.4561604;-1.276011;1050.234;108.5244;3;3;0;1.436726;1.426503;963846.3;1.100836e+008
1117.83;0.4361247;-1.216304;947.9499;97.95502;3;3;0;1.373621;1.364273;869975.9;9.930055e+007
1123.83;0.416089;-1.156301;849.8024;87.81309;3;3;0;1.310517;1.302004;779901.6;8.896389e+007
1129.83;0.3960533;-1.094819;754.2981;77.9443;3;3;0;1.247412;1.239696;692253.1;7.891658e+007
1135.83;0.3760176;-1.033108;662.7651;68.48587;3;3;0;1.184307;1.177349;608249.1;6.929695e+007
1141.83;0.356089;-0.9710972;575.4575;59.46406;3;3;0;1.12154;1.115298;528123;6.013097e+007
1147.83;0.3361069;-0.9101705;491.1812;50.75549;3;3;0;1.058604;1.053041;450778.9;5.129279e+007
1153.83;0.3161784;-0.850923;411.4483;42.51641;3;3;0;0.9958374;0.9909116;377604.4;4.29398e+007
1159.83;0.2961962;-0.7937948;334.3628;34.55089;3;3;0;0.9329015;0.9285769;306859.6;3.487321e+007
1165.83;0.2761606;-0.7387866;261.4149;27.01292;3;3;0;0.869797;0.8660361;239912.1;2.724788e+007
1171.83;0.2560713;-0.686079;191.8934;19.82902;3;3;0;0.8065236;0.8032886;176109.1;1.998895e+007
1177.83;0.2360356;-0.6367238;130.5585;13.49108;3;3;0;0.7434191;0.7406693;119819.4;1.359137e+007
1183.83;0.2159999;-0.5932864;83.25513;8.603046;3;3;0;0.6803145;0.6780108;76406.94;8661575
1189.83;0.1960177;-0.5597993;53.38938;5.516914;3;3;0;0.6173787;0.6154807;48997.82;5550974
1194.142;0.2084463;-0.5718769;87.40933;9.032315;4;4;0;0.6565238;0.654378;80219.44;9091615
1200.142;0.228482;-0.6011697;157.0721;16.23081;4;4;0;0.7196283;0.7170514;144152;1.634761e+007
1206.142;0.2485177;-0.6374286;252.1514;26.0557;4;4;0;0.7827329;0.7796854;231410.6;2.625964e+007
1212.142;0.2684998;-0.675019;366.4688;37.86852;4;4;0;0.8456688;0.8421131;336324.8;3.818876e+007
1218.142;0.288482;-0.7151426;487.3135;50.35582;4;4;0;0.9086046;0.9045016;447229.3;5.081336e+007
1224.142;0.3084105;-0.7584567;610.7212;63.10799;4;4;0;0.9713717;0.9666843;560486.1;6.3721e+007
1230.142;0.3283391;-0.804957;733.5697;75.80235;4;4;0;1.034139;1.028828;673229.6;7.658625e+007
1236.142;0.3483212;-0.8547939;857.2951;88.58734;4;4;0;1.097075;1.091101;786778;8.955921e+007
1242.142;0.3684105;-0.9072426;981.0409;101.3744;4;4;0;1.160348;1.153668;900344.9;1.025507e+008
1248.142;0.3884462;-0.961292;1103.636;114.0427;4;4;0;1.223452;1.216029;1012856;1.154379e+008
1254.142;0.4084819;-1.016736;1224.149;126.4956;4;4;0;1.286557;1.278351;1123456;1.281231e+008
1260.142;0.4285711;-1.072156;1341.767;138.6496;4;4;0;1.34983;1.340801;1231400;1.405211e+008
1266.142;0.4484997;-1.127649;1456.471;150.5023;4;4;0;1.412598;1.402713;1336669;1.526283e+008
1272.142;0.4684283;-1.184281;1572.078;162.4484;4;4;0;1.475365;1.464587;1442767;1.648451e+008
1278.142;0.4884104;-1.241663;1686.84;174.3072;4;4;0;1.5383;1.526588;1548088;1.769885e+008
1284.142;0.508339;-1.300608;1803.296;186.341;4;4;0;1.601068;1.588386;1654966;1.893244e+008
1290.142;0.5283211;-1.361188;1921.435;198.5487;4;4;0;1.664003;1.650311;1763387;2.018525e+008
1296.142;0.5483032;-1.422598;2040.516;210.8538;4;4;0;1.726939;1.712197;1872673;2.144951e+008
1302.142;0.5683925;-1.485499;2159.977;223.1981;4;4;0;1.790213;1.774377;1982308;2.271938e+008
1308.142;0.5884282;-1.549473;2280.255;235.6268;4;4;0;1.853317;1.836353;2092692;2.399938e+008
1314.142;0.6084103;-1.61445;2401.078;248.1119;4;4;0;1.916253;1.898124;2203577;2.528664e+008
1320.142;0.6283924;-1.67954;2519.6;260.3592;4;4;0;1.979189;1.959858;2312349;2.655121e+008
1326.142;0.648321;-1.744405;2636.25;272.4131;4;4;0;2.041956;2.021388;2419405;2.779756e+008
1332.142;0.6683567;-1.809416;2751.098;284.2806;4;4;0;2.105061;2.08321;2524805;2.902649e+008
1338.142;0.6883924;-1.875604;2863.502;295.8958;4;4;0;2.168165;2.144995;2627964;3.023113e+008
1344.142;0.7084281;-1.944183;2971.327;307.0377;4;4;0;2.23127;2.206741;2726919;3.138886e+008
1350.142;0.7284638;-2.017985;3066.693;316.8922;4;4;0;2.294374;2.268449;2814441;3.241629e+008
1356.142;0.7484995;-2.098627;3143.764;324.8562;4;4;0;2.357479;2.330119;2885172;3.325147e+008
1362.142;0.7684817;-2.184603;3206.158;331.3036;4;4;0;2.420415;2.391587;2942434;3.393226e+008
1368.142;0.7884638;-2.275297;3259.172;336.7818;4;4;0;2.483351;2.453017;2991088;3.451453e+008
1374.142;0.8083924;-2.366632;3304.156;341.4301;4;4;0;2.546118;2.514244;3032371;3.501234e+008
1380.142;0.8283209;-2.460937;3343.973;345.5446;4;4;0;2.608885;2.575434;3068913;3.545595e+008
1384.296;0.8356602;-2.509353;3316.682;342.7245;4;4;0;2.632;2.597959;3043867;3.51745e+008
1390.296;0.8156244;-2.470171;3063.261;316.5376;4;4;0;2.568896;2.536454;2811292;3.246692e+008
1396.296;0.7956423;-2.42442;2853.522;294.8646;4;4;0;2.50596;2.475076;2618805;3.022538e+008
1402.296;0.7756602;-2.374803;2669.313;275.8296;4;4;0;2.443024;2.41366;2449748;2.825681e+008
1408.296;0.7556245;-2.323474;2501.475;258.4863;4;4;0;2.37992;2.352041;2295715;2.64638e+008
1414.296;0.7355888;-2.271556;2345.837;242.4036;4;4;0;2.316815;2.290385;2152879;2.480197e+008
1420.296;0.7154996;-2.218526;2196.919;227.0154;4;4;0;2.253542;2.228525;2016211;2.321313e+008
1426.296;0.6954638;-2.164521;2054.728;212.3223;4;4;0;2.190437;2.166792;1885715;2.169731e+008
1432.296;0.6754816;-2.109793;1919.302;198.3282;4;4;0;2.127501;2.105186;1761429;2.025477e+008
1438.296;0.6555531;-2.054234;1789.813;184.9477;4;4;0;2.064734;2.043707;1642591;1.887664e+008
1444.296;0.6356245;-1.996875;1663.893;171.936;4;4;0;2.001967;1.982191;1527029;1.753781e+008
1450.296;0.6156424;-1.937928;1541.228;159.2605;4;4;0;1.939031;1.920472;1414454;1.623486e+008
1456.296;0.5956603;-1.877024;1421.005;146.8375;4;4;0;1.876095;1.858714;1304120;1.495923e+008
1462.296;0.5756782;-1.81498;1305.384;134.8899;4;4;0;1.81316;1.796918;1198009;1.373357e+008
1468.296;0.5556425;-1.752513;1194.844;123.4675;4;4;0;1.750055;1.734918;1096562;1.256282e+008
1474.296;0.5356068;-1.689514;1089.101;112.5406;4;4;0;1.686951;1.67288;999516.5;1.144392e+008
1480.296;0.5155711;-1.625842;987.7873;102.0716;4;4;0;1.623846;1.610803;906536.4;1.03729e+008
1486.296;0.4956426;-1.561975;891.6429;92.13662;4;4;0;1.561079;1.549019;818300.5;9.357495e+007
1492.296;0.4756604;-1.498148;801.0749;82.77791;4;4;0;1.498143;1.487032;735182.2;8.401804e+007
1498.296;0.4556783;-1.433751;714.4141;73.82294;4;4;0;1.435207;1.425006;655649.7;7.488245e+007
1504.296;0.4356426;-1.368733;631.3325;65.23782;4;4;0;1.372103;1.362775;579402;6.613295e+007
1510.296;0.4156069;-1.303459;551.4954;56.98797;4;4;0;1.308998;1.300505;506131.9;5.773394e+007
1516.296;0.3955712;-1.237589;474.1952;49.00027;4;4;0;1.245893;1.238196;435190.1;4.961076e+007
1522.296;0.3755355;-1.172394;399.8358;41.31645;4;4;0;1.182789;1.175849;366947.2;4.180514e+007
1528.296;0.3554998;-1.108155;329.1531;34.01256;4;4;0;1.119684;1.113462;302078.5;3.439339e+007
1534.296;0.3355176;-1.045696;262.4928;27.12431;4;4;0;1.056748;1.051204;240901.4;2.741095e+007
1540.296;0.3155891;-0.9856021;200.0686;20.67379;4;4;0;0.9939813;0.9890738;183611.8;2.087929e+007
1546.296;0.2956605;-0.9286428;144.9485;14.97805;4;4;0;0.9312142;0.9269052;133025.8;1.511752e+007
1552.296;0.2756784;-0.8776192;101.8595;10.5255;4;4;0;0.8682783;0.8645305;93480.99;1.061689e+007
1558.296;0.2556427;-0.8333381;70.17778;7.251719;4;4;0;0.8051739;0.8019496;64405.28;7310108
1564.296;0.235607;-0.8010059;49.77006;5.142916;4;4;0;0.7420693;0.7393295;45676.2;5181080
1568.684;0.2477141;-0.8109023;75.79993;7.832675;5;5;0;0.7802019;0.7771741;69564.97;7893785
1574.684;0.2676427;-0.8379079;128.0379;13.23061;5;5;0;0.842969;0.8394359;117506.1;1.334214e+007
1580.684;0.2875713;-0.8735409;202.2215;20.89627;5;5;0;0.9057363;0.901659;185587.7;2.108553e+007
1586.684;0.3075533;-0.9146837;298.2532;30.81956;5;5;0;0.968672;0.9640104;273720.3;3.11181e+007
1592.684;0.3276427;-0.9573315;411.3767;42.50901;5;5;0;1.031945;1.026657;377538.8;4.294768e+007
1598.684;0.3476783;-1.002528;530.8795;54.85766;5;5;0;1.09505;1.089098;487211.8;5.545838e+007
1604.684;0.3677141;-1.051275;651.3059;67.30174;5;5;0;1.158154;1.151499;597732.4;6.80812e+007
1610.684;0.3877498;-1.102835;771.303;79.70146;5;5;0;1.221259;1.213862;707859.1;8.067483e+007
1616.684;0.4077854;-1.156566;890.3598;92.00404;5;5;0;1.284364;1.276186;817122.9;9.31857e+007
1622.684;0.427714;-1.211322;1007.099;104.0671;5;5;0;1.347131;1.338138;924259.9;1.054691e+008
1628.684;0.447589;-1.266958;1121.404;115.8787;5;5;0;1.409729;1.399885;1029163;1.175123e+008
1634.684;0.4675176;-1.323981;1234.68;127.5839;5;5;0;1.472496;1.46176;1133121;1.294626e+008
1640.684;0.4874997;-1.381628;1347.405;139.2321;5;5;0;1.535432;1.523764;1236574;1.4137e+008
1646.684;0.5075354;-1.440371;1460.99;150.9693;5;5;0;1.598537;1.585895;1340816;1.533826e+008
1652.684;0.5275711;-1.500723;1576.188;162.8731;5;5;0;1.661641;1.647987;1446538;1.655795e+008
1658.684;0.5476068;-1.562459;1693.2;174.9644;5;5;0;1.724746;1.710041;1553926;1.779821e+008
1664.684;0.5676425;-1.625126;1810.4;187.075;5;5;0;1.78785;1.772056;1661484;1.904196e+008
1670.684;0.5876246;-1.688987;1928.574;199.2864;5;5;0;1.850786;1.833868;1769938;2.029747e+008
1676.684;0.6075532;-1.753995;2047.52;211.5775;5;5;0;1.913553;1.895475;1879101;2.156262e+008
1682.684;0.6275889;-1.819058;2165.462;223.7648;5;5;0;1.976658;1.957376;1987341;2.281879e+008
1688.684;0.6476246;-1.884118;2282.541;235.8631;5;5;0;2.039762;2.019238;2094790;2.406741e+008
1694.684;0.6676603;-1.948926;2397.766;247.7697;5;5;0;2.102867;2.081062;2200537;2.5298e+008
1700.684;0.6876959;-2.014043;2513.251;259.7031;5;5;0;2.165972;2.142848;2306523;2.653282e+008
1706.684;0.7077317;-2.079929;2628.724;271.6353;5;5;0;2.229076;2.204595;2412497;2.776903e+008
1712.684;0.7277138;-2.146144;2742.638;283.4065;5;5;0;2.292012;2.26614;2517041;2.899022e+008
1718.684;0.7477495;-2.213272;2855.343;295.0527;5;5;0;2.355117;2.327812;2620475;3.020015e+008
1724.684;0.7676245;-2.280677;2963.55;306.2341;5;5;0;2.417715;2.388951;2719782;3.13638e+008
1730.684;0.7875531;-2.350838;3068.566;317.0858;5;5;0;2.480482;2.450218;2816160;3.249511e+008
1736.684;0.8075352;-2.423494;3164.441;326.9929;5;5;0;2.543418;2.511611;2904148;3.353097e+008
1742.684;0.8276245;-2.501374;3247.738;335.6003;5;5;0;2.606691;2.573296;2980594;3.443484e+008
1747.12;0.8157852;-2.485351;3076.323;317.8874;5;5;0;2.569402;2.536948;2823279;3.260552e+008
1753.12;0.7958566;-2.442066;2848.575;294.3533;5;5;0;2.506635;2.475734;2614264;3.017317e+008
1759.12;0.7758209;-2.393654;2653.82;274.2286;5;5;0;2.44353;2.414154;2435529;2.809294e+008
1765.12;0.7557852;-2.34299;2479.111;256.1754;5;5;0;2.380426;2.352535;2275191;2.622734e+008
1771.12;0.7357495;-2.291213;2319.893;239.7227;5;5;0;2.317321;2.290879;2129069;2.452779e+008
1777.12;0.7156603;-2.23854;2168.524;224.0813;5;5;0;2.254048;2.22902;1990152;2.291322e+008
1783.12;0.6956245;-2.185097;2024.194;209.1672;5;5;0;2.190943;2.167287;1857693;2.137499e+008
1789.12;0.6756424;-2.13044;1886.713;194.9608;5;5;0;2.128008;2.105682;1731521;1.991095e+008
1795.12;0.6557674;-2.075159;1755.42;181.3938;5;5;0;2.065409;2.044369;1611027;1.851403e+008
1801.12;0.6357853;-2.0184;1627.813;168.2076;5;5;0;2.002473;1.982687;1493916;1.71576e+008
1807.12;0.6158031;-1.959843;1503.417;155.3534;5;5;0;1.939538;1.920968;1379753;1.583666e+008
1813.12;0.5958211;-1.89957;1381.891;142.7957;5;5;0;1.876602;1.859211;1268223;1.454754e+008
1819.12;0.5758389;-1.83788;1264.478;130.6629;5;5;0;1.813666;1.797415;1160468;1.330327e+008
1825.12;0.5558032;-1.775932;1152.794;119.1223;5;5;0;1.750561;1.735415;1057971;1.212076e+008
1831.12;0.5357675;-1.713702;1045.867;108.0732;5;5;0;1.687457;1.673377;959839.1;1.098969e+008
1837.12;0.5157318;-1.650963;943.783;97.52444;5;5;0;1.624352;1.611301;866151.7;9.910857e+007
1843.12;0.4958033;-1.587995;847.7367;87.59964;5;5;0;1.561585;1.549518;778005.8;8.896758e+007
1849.12;0.4758747;-1.525175;756.466;78.1683;5;5;0;1.498818;1.487697;694242.6;7.933991e+007
1855.12;0.455839;-1.461208;669.0476;69.13506;5;5;0;1.435713;1.425505;614014.9;7.012764e+007
1861.12;0.4358033;-1.397284;585.6088;60.51303;5;5;0;1.372609;1.363274;537439.3;6.134363e+007
1867.12;0.4157676;-1.333348;505.683;52.25401;5;5;0;1.309504;1.301004;464087.8;5.293828e+007
1873.12;0.3956783;-1.269396;427.9798;44.22466;5;5;0;1.246231;1.238529;392776.1;4.47758e+007
1879.12;0.3756426;-1.206299;354.1123;36.59168;5;5;0;1.183126;1.176182;324984.7;3.702461e+007
1885.12;0.3556605;-1.14435;283.6343;29.30894;5;5;0;1.120191;1.113963;260303.8;2.963725e+007
1891.12;0.3357319;-1.08402;216.91;22.41408;5;5;0;1.057423;1.051872;199068;2.265109e+007
1897.12;0.3157498;-1.027594;157.2109;16.24515;5;5;0;0.9944875;0.989575;144279.4;1.640671e+007
1903.12;0.2958212;-0.9758756;109.9549;11.36203;5;5;0;0.9317204;0.9274067;100910.5;1.146789e+007
1909.12;0.2758391;-0.9309596;75.94421;7.847584;5;5;0;0.8687845;0.8650324;69697.38;7915762
1915.12;0.2557498;-0.8968407;52.7627;5.452157;5;5;0;0.8055112;0.8022843;48422.68;5496074
1919.29;0.2552677;-0.8927674;57.39038;5.930351;6;6;0;0.8039927;0.8007779;52669.71;5978031
1925.29;0.2753034;-0.916298;101.8449;10.524;6;6;0;0.8670973;0.8633595;93467.63;1.061525e+007
1931.29;0.2952855;-0.9496102;163.6716;16.91276;6;6;0;0.9300331;0.9257349;150208.7;1.707006e+007
1937.29;0.3151605;-0.9896294;247.0947;25.53317;6;6;0;0.9926315;0.9877373;226769.9;2.578662e+007
1943.29;0.3351426;-1.032786;352.4743;36.42241;6;6;0;1.055567;1.050035;323481.3;3.680688e+007
1949.29;0.3550712;-1.078211;467.7592;48.33521;6;6;0;1.118335;1.112127;429283.5;4.887576e+007
1955.29;0.3751069;-1.126271;586.289;60.58332;6;6;0;1.181439;1.174515;538063.6;6.129907e+007
1961.29;0.395089;-1.177354;704.4486;72.79316;6;6;0;1.244375;1.236696;646503.9;7.369898e+007
1967.29;0.4151783;-1.230647;822.5312;84.99506;6;6;0;1.307648;1.299172;754873.6;8.61065e+007
1973.29;0.435214;-1.285502;938.6094;96.98984;6;6;0;1.370753;1.361443;861403.8;9.831933e+007
1979.29;0.4551961;-1.341011;1052.671;108.7762;6;6;0;1.433689;1.423508;966083.1;1.103357e+008
1985.29;0.4751247;-1.398087;1167.048;120.5952;6;6;0;1.496456;1.485369;1071052;1.223998e+008
1991.29;0.4951068;-1.455441;1280.627;132.3317;6;6;0;1.559391;1.547358;1175289;1.343953e+008
1997.29;0.5151961;-1.514174;1395.184;144.1693;6;6;0;1.622665;1.60964;1280422;1.465086e+008
2003.29;0.5351782;-1.573763;1511.157;156.1532;6;6;0;1.685601;1.671552;1386856;1.587853e+008
2009.29;0.5552139;-1.634748;1629.191;168.35;6;6;0;1.748705;1.733591;1495181;1.71294e+008
2015.29;0.5752496;-1.69711;1747.998;180.6268;6;6;0;1.81181;1.795592;1604216;1.838994e+008
2021.29;0.5952853;-1.760392;1869.446;193.1765;6;6;0;1.874915;1.857555;1715674;1.967984e+008
2027.29;0.6152674;-1.82418;1990.59;205.6947;6;6;0;1.93785;1.919313;1826853;2.096808e+008
2033.29;0.635196;-1.887757;2109.706;218.0034;6;6;0;2.000618;1.980868;1936172;2.223648e+008
2039.29;0.6551246;-1.951188;2228.317;230.2599;6;6;0;2.063385;2.042385;2045026;2.35011e+008
2045.29;0.6751067;-2.014444;2346.134;242.4343;6;6;0;2.12632;2.10403;2153152;2.475893e+008
2051.29;0.6951424;-2.078554;2464.895;254.7063;6;6;0;2.189425;2.165801;2262144;2.602829e+008
2057.29;0.7151781;-2.1428;2583.21;266.9323;6;6;0;2.252529;2.227535;2370728;2.72945e+008
2063.29;0.7352674;-2.207716;2702.267;279.2348;6;6;0;2.315803;2.289395;2479991;2.857013e+008
2069.29;0.7552495;-2.272695;2819.79;291.3788;6;6;0;2.378739;2.350887;2587847;2.9831e+008
2075.29;0.7753388;-2.338191;2936.412;303.4299;6;6;0;2.442012;2.412671;2694877;3.108397e+008
2081.29;0.7952673;-2.405091;3049.444;315.1098;6;6;0;2.504779;2.473924;2798611;3.230026e+008
2087.29;0.8151959;-2.474256;3153.317;325.8434;6;6;0;2.567546;2.535138;2893939;3.342096e+008
2093.29;0.8351245;-2.548976;3241.849;334.9917;6;6;0;2.630313;2.596316;2975189;3.43803e+008
2099.29;0.8551066;-2.630155;3309.839;342.0173;6;6;0;2.693249;2.65762;3037587;3.512287e+008
2105.29;0.8750887;-2.716026;3363.03;347.5138;6;6;0;2.756185;2.718886;3086403;3.57092e+008
2111.29;0.8951244;-2.804864;3409.301;352.2951;6;6;0;2.819289;2.780279;3128867;3.622273e+008
2117.29;0.9151601;-2.896245;3450.179;356.5192;6;6;0;2.882394;2.841635;3166383;3.667955e+008
2123.29;0.9351959;-2.988007;3487.293;360.3543;6;6;0;2.945499;2.902952;3200444;3.709685e+008
2127.352;0.9355173;-3.012046;3404.502;351.7992;6;6;0;2.946511;2.903936;3124463;3.62165e+008
2133.352;0.915428;-2.974007;3163.216;326.8664;6;6;0;2.883238;2.842455;2903025;3.362907e+008
2139.352;0.8953923;-2.930445;2961.036;305.9744;6;6;0;2.820133;2.7811;2717475;3.146033e+008
2145.352;0.8753566;-2.883818;2780.576;287.3268;6;6;0;2.757029;2.719707;2551859;2.952484e+008
2151.352;0.8553208;-2.835529;2614.565;270.1722;6;6;0;2.693924;2.658277;2399503;2.774504e+008
2157.352;0.8353387;-2.786165;2459.624;254.1617;6;6;0;2.630988;2.596973;2257307;2.608486e+008
2163.352;0.8153566;-2.736256;2310.81;238.7842;6;6;0;2.568052;2.535632;2120734;2.449163e+008
2169.352;0.7954281;-2.684945;2168.186;224.0464;6;6;0;2.505285;2.474417;1989841;2.296594e+008
2175.352;0.775446;-2.631797;2029.784;209.7448;6;6;0;2.442349;2.413001;1862823;2.148675e+008
2181.352;0.7554638;-2.577209;1896.795;196.0025;6;6;0;2.379414;2.351547;1740773;2.006662e+008
2187.352;0.7354281;-2.521226;1768.757;182.772;6;6;0;2.316309;2.28989;1623268;1.870055e+008
2193.352;0.7153388;-2.463617;1644.689;169.9516;6;6;0;2.253036;2.22803;1509405;1.737807e+008
2199.352;0.6953031;-2.404502;1524.846;157.5677;6;6;0;2.189931;2.166296;1399419;1.610183e+008
2205.352;0.6752674;-2.344591;1409.209;145.6185;6;6;0;2.126827;2.104525;1293294;1.487156e+008
2211.352;0.6553389;-2.283324;1298.838;134.2135;6;6;0;2.064059;2.043046;1192002;1.369838e+008
2217.352;0.6354103;-2.22074;1191.642;123.1365;6;6;0;2.001292;1.98153;1093623;1.256009e+008
2223.352;0.6154282;-2.155833;1087.345;112.3592;6;6;0;1.938357;1.91981;997904.8;1.145371e+008
2229.352;0.595446;-2.089566;985.8583;101.8722;6;6;0;1.875421;1.858051;904766.1;1.037828e+008
2235.352;0.5754639;-2.021882;888.4934;91.81116;6;6;0;1.812485;1.796255;815410;9.347523e+007
2241.352;0.5554818;-1.954126;796.701;82.32593;6;6;0;1.749549;1.734421;731168;8.376626e+007
2247.352;0.5354461;-1.885817;709.2851;73.29294;6;6;0;1.686444;1.672382;650942.6;7.452898e+007
2253.352;0.5154104;-1.817346;626.8058;64.77007;6;6;0;1.62334;1.610305;575247.6;6.58215e+007
2259.352;0.4954282;-1.749225;548.8737;56.71706;6;6;0;1.560404;1.548355;503725.8;5.760207e+007
2265.352;0.4754461;-1.681697;475.3833;49.12304;6;6;0;1.497468;1.486367;436280.5;4.985864e+007
2271.352;0.4555176;-1.614913;405.8065;41.93342;6;6;0;1.434701;1.424507;372426.7;4.253504e+007
2277.352;0.4354819;-1.548364;339.5093;35.0827;6;6;0;1.371596;1.362275;311582.8;3.556389e+007
2283.352;0.4154462;-1.482758;276.4784;28.56949;6;6;0;1.308492;1.300005;253736.6;2.894332e+007
2289.352;0.3954105;-1.417274;215.6433;22.28319;6;6;0;1.245387;1.237696;197905.5;2.25607e+007
2295.352;0.3753212;-1.354205;159.8745;16.5204;6;6;0;1.182114;1.175182;146724;1.671569e+007
2301.352;0.3552855;-1.295149;115.3942;11.92409;6;6;0;1.119009;1.112795;105902.4;1.205752e+007
2307.352;0.3353034;-1.242672;83.4391;8.622058;6;6;0;1.056074;1.050536;76575.78;8713113
2313.352;0.3153748;-1.198606;60.11544;6.211941;6;6;0;0.9933065;0.9884057;55170.62;6273644
2317.988;0.3132319;-1.189497;66.97364;6.920623;7;7;0;0.9865573;0.9817226;61464.7;6988899
2323.988;0.3332676;-1.216825;114.1482;11.79534;7;7;0;1.049662;1.044191;104758.9;1.191915e+007
2329.988;0.3532498;-1.254109;177.7843;18.37108;7;7;0;1.112598;1.106454;163160.5;1.857547e+007
2335.988;0.3732855;-1.298066;264.5873;27.34074;7;7;0;1.175702;1.168845;242823.6;2.766219e+007
2341.988;0.393214;-1.344037;370.0783;38.2415;7;7;0;1.238469;1.230863;339637.3;3.871511e+007
2347.988;0.4132497;-1.392073;483.2319;49.93406;7;7;0;1.301574;1.293176;443483.5;5.058399e+007
2353.988;0.4332855;-1.441897;597.0949;61.69993;7;7;0;1.364679;1.355451;547980.6;6.254193e+007
2359.988;0.4533211;-1.494029;710.2355;73.39114;7;7;0;1.427783;1.417686;651814.8;7.443901e+007
2365.988;0.4733033;-1.548658;822.8763;85.03072;7;7;0;1.490719;1.479717;755190.3;8.629829e+007
2371.988;0.4933925;-1.605291;936.0862;96.7291;7;7;0;1.553992;1.542041;859088.1;9.823226e+007
2377.988;0.5133747;-1.663718;1050.467;108.5484;7;7;0;1.616928;1.603995;964060.1;1.103036e+008
2383.988;0.5333568;-1.723882;1164.982;120.3817;7;7;0;1.679864;1.66591;1069156;1.224039e+008
2389.988;0.5532318;-1.784429;1279.036;132.1673;7;7;0;1.742462;1.727456;1173828;1.344702e+008
2395.988;0.5732139;-1.845908;1393.042;143.948;7;7;0;1.805398;1.789294;1278457;1.465468e+008
2401.988;0.593196;-1.908972;1509.974;156.031;7;7;0;1.868334;1.851095;1385771;1.589462e+008
2407.988;0.6132318;-1.972917;1628.282;168.2561;7;7;0;1.931439;1.913023;1494347;1.715059e+008
2413.988;0.633321;-2.037009;1746.64;180.4865;7;7;0;1.994712;1.975078;1602970;1.840867e+008
2419.988;0.6533567;-2.100825;1864.266;192.6412;7;7;0;2.057816;2.036929;1710920;1.966054e+008
2425.988;0.6733924;-2.16435;1981.196;204.724;7;7;0;2.120921;2.098743;1818232;2.090661e+008
2431.988;0.6933745;-2.228456;2098.364;216.8314;7;7;0;2.183857;2.160352;1925763;2.215667e+008
2437.988;0.7133031;-2.29248;2214.565;228.8388;7;7;0;2.246624;2.221759;2032405;2.3398e+008
2443.988;0.7332316;-2.357078;2330.837;240.8537;7;7;0;2.309391;2.283128;2139114;2.464159e+008
2449.988;0.7531603;-2.422087;2446.879;252.8447;7;7;0;2.372158;2.34446;2245610;2.588426e+008
2455.988;0.7731959;-2.487486;2563.762;264.9226;7;7;0;2.435263;2.406083;2352879;2.713741e+008
2461.988;0.7932316;-2.553068;2680.349;276.97;7;7;0;2.498367;2.467668;2459876;2.838897e+008
2467.988;0.8132137;-2.618223;2795.372;288.8557;7;7;0;2.561303;2.529051;2565438;2.962542e+008
2473.988;0.8332494;-2.683511;2908.969;300.594;7;7;0;2.624408;2.590561;2669690;3.084828e+008
2479.988;0.8532852;-2.748677;3018.633;311.9261;7;7;0;2.687512;2.652033;2770334;3.203091e+008
2485.988;0.8732673;-2.813955;3123.908;322.8045;7;7;0;2.750448;2.713303;2866950;3.31683e+008
2491.988;0.8931959;-2.880492;3223.173;333.0618;7;7;0;2.813215;2.774371;2958049;3.424316e+008
2497.988;0.9132316;-2.950574;3313.937;342.4408;7;7;0;2.87632;2.83573;3041347;3.522905e+008
2503.988;0.9332673;-3.025696;3391.375;350.4428;7;7;0;2.939425;2.897052;3112417;3.607438e+008
2509.988;0.953303;-3.106762;3452.991;356.8098;7;7;0;3.002529;2.958336;3168964;3.675231e+008
2515.988;0.9733387;-3.194655;3501.999;361.8739;7;7;0;3.065634;3.019582;3213941;3.729677e+008
2521.988;0.9933743;-3.28507;3542.599;366.0693;7;7;0;3.128738;3.08079;3251201;3.775226e+008
2527.988;1.013357;-3.380649;3576.509;369.5734;7;7;0;3.191674;3.141799;3282322;3.813689e+008
2533.988;1.033339;-3.4755;3608.999;372.9307;7;7;0;3.25461;3.202769;3312140;3.850681e+008
2539.988;1.053267;-3.57228;3637.911;375.9183;7;7;0;3.317377;3.263539;3338674;3.883889e+008
2545.988;1.073142;-3.672105;3664.537;378.6696;7;7;0;3.379975;3.32411;3363109;3.914685e+008
2551.988;1.093231;-3.773827;3690.503;381.3528;7;7;0;3.443249;3.385295;3386939;3.944837e+008
2557.988;1.113267;-3.87675;3713.898;383.7702;7;7;0;3.506353;3.446281;3408410;3.972266e+008
2563.988;1.133303;-3.987271;3732.159;385.6572;7;7;0;3.569458;3.507229;3425169;3.994231e+008
2569.988;1.153392;-4.100948;3750.26;387.5276;7;7;0;3.632731;3.568303;3441781;4.016054e+008
2575.988;1.173374;-4.219368;3763.52;388.8978;7;7;0;3.695667;3.629014;3453950;4.032702e+008
2581.988;1.19341;-4.332793;3779.652;390.5648;7;7;0;3.758771;3.689851;3468756;4.052453e+008
2587.988;1.213338;-4.44446;3795.248;392.1765;7;7;0;3.821538;3.750326;3483069;4.071636e+008
2593.578;1.231821;-4.557163;3799.973;392.6646;7;7;0;3.87975;3.806379;3487405;4.07899e+008
2598.58;1.215267;-4.536051;3579.365;369.8685;7;7;0;3.827613;3.756177;3284943;3.840256e+008
2604.58;1.195178;-4.496681;3356.106;346.7983;7;7;0;3.76434;3.695218;3080048;3.59853e+008
2610.58;1.175142;-4.453599;3164.734;327.0232;7;7;0;3.701235;3.634384;2904418;3.391271e+008
2616.58;1.15516;-4.408695;2989.366;308.9017;7;7;0;3.638299;3.573676;2743474;3.201405e+008
2622.58;1.135231;-4.363109;2829.736;292.4066;7;7;0;3.575532;3.513094;2596975;3.028617e+008
2628.58;1.115249;-4.317923;2679.098;276.8407;7;7;0;3.512596;3.452312;2458728;2.86565e+008
2634.58;1.095321;-4.272963;2535.542;262.0065;7;7;0;3.449829;3.391656;2326980;2.710453e+008
2640.58;1.075339;-4.227541;2396.552;247.6441;7;7;0;3.386893;3.330801;2199422;2.560316e+008
2646.58;1.055303;-4.181106;2261.752;233.7149;7;7;0;3.323789;3.269745;2075711;2.41483e+008
2652.58;1.035267;-4.133655;2131.389;220.244;7;7;0;3.260684;3.208652;1956071;2.274255e+008
2658.58;1.015231;-4.085321;2006.069;207.2943;7;7;0;3.197579;3.147521;1841059;2.139227e+008
2664.58;0.9952494;-4.035541;1884.62;194.7445;7;7;0;3.134644;3.086517;1729600;2.00849e+008
2670.58;0.9752672;-3.984249;1767.499;182.6419;7;7;0;3.071708;3.025475;1622112;1.882521e+008
2676.58;0.9553387;-3.931081;1654.185;170.9328;7;7;0;3.008941;2.96456;1518119;1.76076e+008
2682.58;0.9353566;-3.876468;1544.221;159.5698;7;7;0;2.946005;2.903444;1417201;1.642708e+008
2688.58;0.9153209;-3.819848;1437.194;148.5104;7;7;0;2.8829;2.842127;1318977;1.527918e+008
2694.58;0.8952851;-3.761159;1333.113;137.7553;7;7;0;2.819796;2.780771;1223457;1.416397e+008
2700.58;0.8751958;-3.700247;1231.827;127.289;7;7;0;2.756522;2.719214;1130502;1.307978e+008
2706.58;0.8551602;-3.637592;1133.079;117.085;7;7;0;2.693418;2.657784;1039877;1.202386e+008
2712.58;0.8351781;-3.572269;1038.011;107.2613;7;7;0;2.630482;2.59648;952628.9;1.100828e+008
2718.58;0.8151959;-3.505051;946.366;97.79135;7;7;0;2.567546;2.535138;868522.3;1.003022e+008
2724.58;0.7952673;-3.435782;857.999;88.66007;7;7;0;2.504779;2.473924;787423.9;9.088081e+007
2730.58;0.7752852;-3.364591;773.8389;79.96352;7;7;0;2.441843;2.412507;710186.5;8.19161e+007
2736.58;0.7553031;-3.291732;692.7535;71.58467;7;7;0;2.378907;2.351052;635770.8;7.328761e+007
2742.58;0.7352674;-3.217841;615.7827;63.631;7;7;0;2.315803;2.289395;565131.2;6.510457e+007
2748.58;0.7152317;-3.142748;543.087;56.1191;7;7;0;2.252698;2.2277;498415.1;5.738329e+007
2754.58;0.695196;-3.066842;473.547;48.93329;7;7;0;2.189594;2.165966;434595.2;5.000473e+007
2760.58;0.6751603;-2.99103;408.3677;42.19808;7;7;0;2.126489;2.104195;374777.2;4.309541e+007
2766.58;0.6551782;-2.915009;346.8535;35.84159;7;7;0;2.063553;2.04255;318322.9;3.658121e+007
2772.58;0.635196;-2.83914;289.3846;29.90314;7;7;0;2.000618;1.980868;265581.2;3.050138e+007
2778.58;0.6152674;-2.762349;233.8273;24.1622;7;7;0;1.93785;1.919313;214593.8;2.463043e+007
2784.58;0.5952853;-2.685444;181.6136;18.76678;7;7;0;1.874915;1.857555;166674.9;1.911864e+007
2790.58;0.5753032;-2.608968;134.4294;13.89106;7;7;0;1.811979;1.795758;123371.8;1.414277e+007
2796.58;0.5553211;-2.536272;97.30006;10.05436;7;7;0;1.749043;1.733923;89296.6;1.023021e+007
2802.58;0.5352853;-2.471769;71.33685;7.371489;7;7;0;1.685938;1.671884;65469.01;7495768
2808.58;0.5152497;-2.418349;54.64744;5.646913;7;7;0;1.622834;1.609806;50152.39;5738553
2814.58;0.4952675;-2.392485;50.01829;5.168567;7;7;0;1.559898;1.547856;45904.02;5249191
2820.58;0.4752854;-2.383568;49.21427;5.085485;7;7;0;1.496962;1.485868;45166.13;5161612
2826.58;0.4553033;-2.37909;49.35047;5.099559;7;7;0;1.434026;1.423841;45291.13;5172688
2831.452;0.4390712;-2.376675;49.26519;5.090746;7;7;0;1.382901;1.373426;45212.86;5161147