File: Ensayos/Resistencia/comp/Clavo6/clavo6.raw
"Test Type";"Manual"
"Method Name:";"C:\INSTRON\user\template\CYCLE.MTM"
"Name:";""
"Operator ID:";""
"Company:";""
"Lab name:";""
"Test date:";"05/06/2017"
"Temperature:";""
"Humidity:";""
"Note 1:";""
"Note 2:";""
"Note 3:";""
"Geometry:";"Rectangular"
"Specimen";1
"Specimen name:";""
"Width:";0.250000;"in"
"Thickness:";0.060000;"in"
"Length:";1.250000;"in"
"Diameter:";0.039370;"in"
"Inner diameter:";0.019685;"in"
"Outer diameter:";0.039370;"in"
"Wall thickness:";0.019685;"in"
"Area:";0.015000;"in*in"
"Linear density:";1.000000;"den"
"Sled weight:";2.204623;"lbf"
"Loading span:";0.000000;"mm"
"Support span:";1.000000;"mm"
"Span ratio:";"2"
"Fixture type:";"3-point"
"Comment:";""
"Included"
"Final Width:";0.250000;"in"
"Final Thickness:";0.060000;"in"
"Final Length:";1.250000;"in"
"Final Diameter:";0.039370;"in"
"Final Inner diameter:";0.019685;"in"
"Final Outer diameter:";0.039370;"in"
"Final Wall thickness:";0.019685;"in"
"Final Area:";0.015000;"in*in"
"Final Linear density:";1.000000;"den"
"Time sec";"Extension mm";"Strain 1 %";"Load N";"Stress MPa";"Cycle Count ";"Total Cycle Count ";"Repetitions Count ";"Strain [Exten.] %";"True strain %";"Tenacity gf/tex";"True stress Pa"
0;0;0.004529341;-0.2711746;-0.02802144;0;0;0;0;0;-248.8691;-28021.44
5;0.0001071428;0.00405168;-0.1098464;-0.01135081;0;0;0;0.0003374576;0.000337457;-100.8109;-11350.85
10;0.0002142856;0.004798476;0.1664438;0.01719922;0;0;0;0.0006749152;0.000674913;152.7529;17199.34
15;0.0003214284;0.004509256;0.3244245;0.03352393;0;0;0;0.001012373;0.001012368;297.7388;33524.27
20;0.0003214284;0.004558588;0.3674434;0.03796923;0;0;0;0.001012373;0.001012368;337.2192;37969.61
25;0.0004285712;0.004844872;0.2933569;0.03031361;0;0;0;0.00134983;0.001349821;269.2267;30314.02
30;0.0005357139;0.004091185;0.3209301;0.03316284;0;0;0;0.001687288;0.001687274;294.5319;33163.4
35;0.0006428567;0.005032216;0.07993607;0.008260077;0;0;0;0.002024746;0.002024725;73.3609;8260.244
40;0.0006964281;0.004640025;0.1823006;0.01883777;0;0;0;0.002193474;0.00219345;167.3054;18838.18
45;0.0007499995;0.003639286;-0.09677911;-0.01000053;0;0;0;0.002362203;0.002362175;-88.8185;-10000.76
50;0.0008571423;0.004249401;0.3697045;0.03820287;0;0;0;0.002699661;0.002699624;339.2943;38203.9
55;0.0009642851;0.005153394;-0.04157402;-0.004295991;0;0;0;0.003037118;0.003037072;-38.15434;-4296.121
60;0.001017856;0.004761203;-0.09666168;-0.009988394;0;0;0;0.003205847;0.003205796;-88.71073;-9988.714
65;0.001124999;0.00461763;-0.2683556;-0.02773013;0;0;0;0.003543305;0.003543242;-246.2819;-27731.11
70;0.001178571;0.0052649;-0.3618226;-0.03738841;0;0;0;0.003712033;0.003711965;-332.0608;-37389.8
75;0.001285713;0.005818048;-0.1022702;-0.01056795;0;0;0;0.004049491;0.004049409;-93.85796;-10568.37
80;0.001392856;0.00555506;0.1230137;0.01271144;0;0;0;0.004386948;0.004386852;112.8952;12712
85.00001;0.001499999;0.005379304;-0.08277228;-0.008553152;0;0;0;0.004724406;0.004724294;-75.96381;-8553.556
90.00001;0.00155357;0.005521819;-0.1767973;-0.01826909;0;0;0;0.004893135;0.004893015;-162.2547;-18269.98
95.00001;0.001607142;0.005903087;-0.1111971;-0.01149039;0;0;0;0.005061864;0.005061736;-102.0505;-11490.97
100;0.001767856;0.005727879;-0.2026673;-0.02094233;0;0;0;0.00556805;0.005567895;-185.9968;-20943.5
105;0.001767856;0.005060211;-0.3363637;-0.03475765;0;0;0;0.00556805;0.005567895;-308.696;-34759.59
110;0.001874999;0.005667898;-0.1708363;-0.01765312;0;0;0;0.005905509;0.005905334;-156.7841;-17654.16
115;0.001982142;0.00610253;-0.189835;-0.01961633;0;0;0;0.006242966;0.006242771;-174.2201;-19617.55
120;0.002035713;0.005296418;-0.06362672;-0.006574774;0;0;0;0.006411694;0.006411489;-58.39308;-6575.196
125;0.002142856;0.005184755;-0.211095;-0.02181319;0;0;0;0.006749152;0.006748924;-193.7313;-21814.66
130;0.002249999;0.005953398;0.002355227;0.000243374;0;0;0;0.007086609;0.007086358;2.161497;243.3912
135;0.002357141;0.005318891;-0.2608383;-0.02695334;0;0;0;0.007424067;0.007423791;-239.3829;-26955.34
140;0.002357141;0.004623386;-0.1807321;-0.01867568;0;0;0;0.007424067;0.007423791;-165.8659;-18677.07
145;0.002464284;0.005723573;-0.2901147;-0.02997858;0;0;0;0.007761525;0.007761224;-266.2512;-29980.91
150;0.002517856;0.005852854;-0.31205;-0.03224523;0;0;0;0.007930254;0.00792994;-286.3822;-32247.78
155;0.002624998;0.006987809;-0.08946743;-0.009244986;0;0;0;0.008267712;0.00826737;-82.10825;-9245.751
160;0.00267857;0.00444669;-0.1204175;-0.01244317;0;0;0;0.00843644;0.008436084;-110.5125;-12444.22
165;0.002785712;0.005430006;-0.07701692;-0.007958431;0;0;0;0.008773897;0.008773512;-70.68186;-7959.129
170;0.002892855;0.0072876;-0.2012873;-0.02079972;0;0;0;0.009111355;0.00911094;-184.7303;-20801.62
175;0.002946427;0.004997136;-0.179117;-0.0185088;0;0;0;0.009280084;0.009279653;-164.3837;-18510.51
180;0.002999998;0.006071012;-0.1346006;-0.01390876;0;0;0;0.009448812;0.009448366;-123.529;-13910.07
185;0.003107141;0.006250801;0.0635214;0.006563891;0;0;0;0.009786271;0.009785792;58.29642;6564.534
190;0.003214284;0.006875871;0.06998158;0.007231444;0;0;0;0.01012373;0.01012322;64.22521;7232.176
195;0.003267855;0.005915263;0.001474255;0.0001523399;0;0;0;0.01029246;0.01029193;1.352989;152.3556
200;0.003321426;0.00761934;-0.02131252;-0.002202298;0;0;0;0.01046119;0.01046064;-19.55945;-2202.528
205;0.003428569;0.006154173;-0.06876544;-0.007105776;0;0;0;0.01079864;0.01079806;-63.10911;-7106.544
210;0.003535712;0.006238977;0.1050134;0.0108514;0;0;0;0.0111361;0.01113548;96.37543;10852.61
215;0.003642855;0.006558971;-0.09390144;-0.009703168;0;0;0;0.01147356;0.0114729;-86.17754;-9704.281
220;0.003749998;0.007200486;-0.077105;-0.007967533;0;0;0;0.01181102;0.01181032;-70.7627;-7968.473
225;0.003749998;0.007015842;-0.154451;-0.01595997;0;0;0;0.01181102;0.01181032;-141.7466;-15961.85
230;0.00385714;0.006148065;-0.1540692;-0.01592052;0;0;0;0.01214847;0.01214774;-141.3962;-15922.45
235;0.003964283;0.00560216;-0.01238568;-0.001279856;0;0;0;0.01248593;0.01248515;-11.36689;-1280.016
240;0.004017854;0.005286043;0.1588384;0.01641333;0;0;0;0.01265466;0.01265386;145.7731;16415.41
245;0.004124997;0.005828814;-0.09034829;-0.009336009;0;0;0;0.01299212;0.01299127;-82.91666;-9337.222
250;0.004178569;0.004864683;-0.01467619;-0.001516543;0;0;0;0.01316085;0.01315998;-13.46899;-1516.742
255;0.004285712;0.006077355;0.0883637;0.009130934;0;0;0;0.0134983;0.01349739;81.09531;9132.167
260;0.004339283;0.00538044;0.0247897;0.002561607;0;0;0;0.01366703;0.0136661;22.75061;2561.957
265;0.004446426;0.005676746;0.1015189;0.01049031;0;0;0;0.01400449;0.01400351;93.16845;10491.78
270;0.004499997;0.005084759;-0.0924919;-0.009557515;0;0;0;0.01417322;0.01417221;-84.88394;-9558.87
275;0.00460714;0.006503765;-0.02968143;-0.003067087;0;0;0;0.01451068;0.01450962;-27.23997;-3067.533
280;0.004714283;0.005988283;0.04886857;0.005049762;0;0;0;0.01484813;0.01484703;44.84887;5050.512
285;0.004767854;0.005411213;0.03477355;0.003593274;0;0;0;0.01501686;0.01501574;31.91323;3593.813
290;0.004874997;0.005441518;0.1137052;0.01174956;0;0;0;0.01535432;0.01535314;104.3523;11751.37
295;0.00498214;0.00539935;0.02302775;0.002379539;0;0;0;0.01569178;0.01569055;21.13359;2379.912
300;0.005035711;0.006351109;-0.1205938;-0.01246138;0;0;0;0.01586051;0.01585925;-110.6743;-12463.36
305;0.005142854;0.006789971;-0.02580524;-0.002666547;0;0;0;0.01619796;0.01619665;-23.68262;-2666.979
310;0.005142854;0.006402791;0.01962151;0.00202756;0;0;0;0.01619796;0.01619665;18.00754;2027.889
315;0.005249997;0.007423381;0.0125447;0.001296288;0;0;0;0.01653542;0.01653406;11.51283;1296.502
320;0.005357139;0.006577764;-0.1661673;-0.01717065;0;0;0;0.01687288;0.01687146;-152.4991;-17173.55
325;0.005464282;0.006297236;-0.06386159;-0.006599044;0;0;0;0.01721034;0.01720886;-58.60863;-6600.18
330;0.005571425;0.006928022;-0.03291152;-0.003400864;0;0;0;0.01754779;0.01754625;-30.20437;-3401.461
335;0.005624996;0.007022224;-0.2028435;-0.02096053;0;0;0;0.01771652;0.01771495;-186.1585;-20964.25
340;0.005732139;0.007441313;-0.05975053;-0.006174234;0;0;0;0.01805398;0.01805235;-54.83572;-6175.348
345;0.005732139;0.007603522;0.03342284;0.0034537;0;0;0;0.01805398;0.01805235;30.67363;3454.324
350;0.005839282;0.006106758;-0.08139221;-0.008410545;0;0;0;0.01839144;0.01838975;-74.69726;-8412.092
355;0.005946425;0.008826335;-0.1621738;-0.01675799;0;0;0;0.0187289;0.01872714;-148.8341;-16761.13
360;0.006053567;0.01025313;-0.05232141;-0.005406557;0;0;0;0.01906635;0.01906453;-48.01769;-5407.587
365;0.006107139;0.008890702;-0.09169911;-0.009475593;0;0;0;0.01923508;0.01923323;-84.15636;-9477.417
370;0.006214282;0.01003368;-0.1317815;-0.01361745;0;0;0;0.01957254;0.01957063;-120.9418;-13620.12
375;0.006321425;0.01047728;-0.08937935;-0.009235885;0;0;0;0.01991;0.01990802;-82.02742;-9237.724
380;0.006374996;0.008380583;0.01395423;0.00144194;0;0;0;0.02007873;0.02007671;12.80642;1442.23
385;0.006482139;0.007945089;-0.07014562;-0.007248395;0;0;0;0.02041619;0.0204141;-64.37576;-7249.875
390;0.006589282;0.01012365;0.05791273;0.005984327;0;0;0;0.02075364;0.02075149;53.14909;5985.569
395;0.006642853;0.01011234;-0.1150144;-0.01188485;0;0;0;0.02092237;0.02092018;-105.5539;-11887.34
400;0.006696424;0.009392442;0.1224851;0.01265682;0;0;0;0.0210911;0.02108888;112.4101;12659.49
405;0.006803567;0.0103007;-0.1588263;-0.01641208;0;0;0;0.02142856;0.02142626;-145.7619;-16415.6
410;0.006857139;0.008823242;-0.1073504;-0.01109289;0;0;0;0.02159729;0.02159496;-98.5202;-11095.29
415;0.006964281;0.009901542;-0.09278559;-0.009587864;0;0;0;0.02193474;0.02193234;-85.15348;-9589.967
420;0.007017853;0.01007417;0.0004759568;4.91823e-005;0;0;0;0.02210347;0.02210103;0.4368067;49.19317
425;0.007124995;0.01064348;0.02373257;0.002452371;0;0;0;0.02244093;0.02243841;21.78044;2452.921
430;0.007178567;0.01098427;-0.02521796;-0.002605861;0;0;0;0.02260966;0.0226071;-23.14365;-2606.45
435;0.00728571;0.01154047;0.1484728;0.01534222;0;0;0;0.02294712;0.02294448;136.2601;15345.74
440;0.007392853;0.01458039;0.05576912;0.005762821;0;0;0;0.02328457;0.02328186;51.18181;5764.163
445;0.007499996;0.01713102;0.0403235;0.00416677;0;0;0;0.02362203;0.02361924;37.00668;4167.755
450;0.007499996;0.02116334;0.02067864;0.002136796;0;0;0;0.02362203;0.02361924;18.97771;2137.301
455;0.007607138;0.02523662;-0.1645229;-0.01700073;0;0;0;0.02395949;0.02395662;-150.99;-17004.81
460;0.007714281;0.03204243;0.07203711;0.007443849;0;0;0;0.02429695;0.024294;66.11167;7445.658
465;0.007821424;0.03981229;-0.1193017;-0.01232786;0;0;0;0.02463441;0.02463137;-109.4884;-12330.9
470;0.007928567;0.04680369;-0.02019668;-0.002086994;0;0;0;0.02497186;0.02496875;-18.53539;-2087.515
475;0.007928567;0.05161268;-0.06092519;-0.006295616;0;0;0;0.02497186;0.02496875;-55.91377;-6297.188
480;0.008035709;0.05531616;-0.08027637;-0.008295242;0;0;0;0.02530932;0.02530612;-73.6732;-8297.341
485;0.008142852;0.05915707;-0.1915088;-0.01978928;0;0;0;0.02564678;0.02564349;-175.7562;-19794.36
490;0.008249995;0.06153558;0.08254952;0.008530134;0;0;0;0.02598424;0.02598086;75.75938;8532.351
495;0.008303566;0.06511538;-0.1979396;-0.0204538;0;0;0;0.02615296;0.02614954;-181.658;-20459.15
500;0.008410709;0.06925788;-0.08321276;-0.008598669;0;0;0;0.02649042;0.02648691;-76.36806;-8600.947
505;0.00846428;0.07121688;-0.0158801;-0.001640947;0;0;0;0.02665915;0.0266556;-14.57388;-1641.385
510;0.008571423;0.07353988;-0.04368827;-0.004514464;0;0;0;0.02699661;0.02699296;-40.09467;-4515.682
515;0.008571423;0.07616443;-0.05763639;-0.005955772;0;0;0;0.02699661;0.02699296;-52.89548;-5957.38
520;0.008678566;0.07630256;0.1139989;0.01177991;0;0;0;0.02733407;0.02733033;104.6219;11783.13
525;0.008785709;0.07962579;0.1375491;0.01421344;0;0;0;0.02767153;0.0276677;126.2349;14217.37
530;0.008892851;0.08021234;-0.01543962;-0.00159543;0;0;0;0.02800898;0.02800506;-14.16963;-1595.877
535;0.008946423;0.08223675;-0.03214798;-0.003321965;0;0;0;0.02817771;0.02817374;-29.50364;-3322.901
540;0.009053566;0.08441802;-0.1318991;-0.0136296;0;0;0;0.02851517;0.0285111;-121.0497;-13633.48
545;0.009107137;0.08334497;-0.02022603;-0.002090028;0;0;0;0.0286839;0.02867978;-18.56233;-2090.627
550;0.009160708;0.08378473;0.06422611;0.006636712;0;0;0;0.02885262;0.02884846;58.94317;6638.627
555;0.009267851;0.08479173;0.09338499;0.009649801;0;0;0;0.02919008;0.02918582;85.70357;9652.618
560;0.009321422;0.08591706;-0.03373367;-0.003485819;0;0;0;0.02935881;0.0293545;-30.95889;-3486.843
565;0.009428565;0.08531431;0.1313826;0.01357623;0;0;0;0.02969627;0.02969186;120.5757;13580.26
570;0.009535708;0.08633599;-0.1585032;-0.0163787;0;0;0;0.03003373;0.03002922;-145.4655;-16383.62
575;0.009642851;0.08696239;-0.02298628;-0.002375253;0;0;0;0.03037118;0.03036657;-21.09553;-2375.975
580;0.009749994;0.08717409;0.1940757;0.02005452;0;0;0;0.03070864;0.03070393;178.1119;20060.68
585;0.009749994;0.08723247;0.06146587;0.006351486;0;0;0;0.03070864;0.03070393;56.40997;6353.437
590;0.009857137;0.08764317;0.1274185;0.0131666;0;0;0;0.0310461;0.03104128;116.9376;13170.69
595;0.00996428;0.08796967;-0.04192632;-0.004332395;0;0;0;0.03138356;0.03137863;-38.47766;-4333.755
600;0.01007142;0.08776381;-0.06882416;-0.007111844;0;0;0;0.03172101;0.03171599;-63.163;-7114.1
605;0.01017856;0.0879611;-0.0687948;-0.00710881;0;0;0;0.03205847;0.03205333;-63.13605;-7111.089
610;0.01017856;0.0868122;-0.02718542;-0.002809165;0;0;0;0.03205847;0.03205333;-24.94927;-2810.066
615;0.01028571;0.08664059;0.09438339;0.00975297;0;0;0;0.03239593;0.03239068;86.61985;9756.13
620;0.01039285;0.08645019;0.09905238;0.01023543;0;0;0;0.03273339;0.03272803;90.90479;10238.78
625;0.01049999;0.08832149;-0.02545294;-0.002630142;0;0;0;0.03307085;0.03306538;-23.35929;-2631.012
630;0.01060714;0.08718634;-0.06383223;-0.00659601;0;0;0;0.0334083;0.03340272;-58.58168;-6598.214
635;0.01060714;0.08700777;0.2548307;0.02633256;0;0;0;0.0334083;0.03340272;233.8695;26341.36
640;0.01071428;0.08763734;-0.0106532;-0.001100833;0;0;0;0.03374576;0.03374007;-9.776919;-1101.205
645.0001;0.01082142;0.08797202;-0.01006592;-0.001040148;0;0;0;0.03408322;0.03407741;-9.237947;-1040.502
650.0001;0.01082142;0.08898376;-0.01726017;-0.001783555;0;0;0;0.03408322;0.03407741;-15.84043;-1784.163
655.0001;0.01092856;0.08844149;0.1036625;0.01071182;0;0;0;0.03442068;0.03441475;95.13573;10715.5
660.0001;0.01103571;0.0884323;0.1056887;0.01092119;0;0;0;0.03475814;0.03475209;96.99524;10924.98
665.0001;0.01114285;0.08763946;0.002267152;0.0002342728;0;0;0;0.03509559;0.03508943;2.080667;234.3551
670.0001;0.01124999;0.0880977;0.1620685;0.01674711;0;0;0;0.03543305;0.03542677;148.7375;16753.04
675.0001;0.01124999;0.08830646;0.05380178;0.005559528;0;0;0;0.03543305;0.03542677;49.37629;5561.498
680.0001;0.01135714;0.0890892;0.07620678;0.007874716;0;0;0;0.03577051;0.03576411;69.93836;7877.533
685.0001;0.01146428;0.08903728;-0.0820382;-0.008477299;0;0;0;0.03610796;0.03610145;-75.29012;-8480.359
690.0001;0.01151785;0.08899093;0.0343037;0.003544723;0;0;0;0.03627669;0.03627011;31.48204;3546.009
695.0001;0.01162499;0.08933727;-0.05531652;-0.005716052;0;0;0;0.03661415;0.03660745;-50.76644;-5718.145
700.0001;0.01167856;0.08842282;-0.03461464;-0.003576853;0;0;0;0.03678288;0.03677611;-31.7674;-3578.169
705.0001;0.01178571;0.08887821;0.1308541;0.01352161;0;0;0;0.03712033;0.03711345;120.0906;13526.63
710.0001;0.01183928;0.08869865;0.1686754;0.01742983;0;0;0;0.03728906;0.03728211;154.801;17436.33
715.0001;0.01194642;0.08982519;0.02417306;0.002497888;0;0;0;0.03762652;0.03761945;22.18469;2498.828
720.0001;0.01205356;0.09045186;-0.01079999;-0.001116002;0;0;0;0.03796398;0.03795678;-9.911637;-1116.425
725.0001;0.01210713;0.09122442;0.04678368;0.004834323;0;0;0;0.0381327;0.03812543;42.93547;4836.167
730.0001;0.01221428;0.08945355;0.2752096;0.02843839;0;0;0;0.03847016;0.03846277;252.5722;28449.33
735.0001;0.01226785;0.09073677;-0.147609;-0.01525296;0;0;0;0.03863889;0.03863143;-135.4674;-15258.86
740.0001;0.01237499;0.08860233;0.01680255;0.001736267;0;0;0;0.03897635;0.03896876;15.42045;1736.944
745.0001;0.01248213;0.09215731;0.1804799;0.01864963;0;0;0;0.03931381;0.03930608;165.6345;18656.96
750.0001;0.01253571;0.08898012;0.1943106;0.02007881;0;0;0;0.03948254;0.03947475;178.3275;20086.73
755.0001;0.01264285;0.0916183;0.1213987;0.01254455;0;0;0;0.03982;0.03981207;111.413;12549.55
760.0001;0.01274999;0.09124411;0.2760613;0.02852639;0;0;0;0.04015746;0.0401494;253.3537;28537.84
765.0001;0.01280356;0.08976419;0.07338782;0.007583423;0;0;0;0.04032618;0.04031805;67.35127;7586.481
770.0001;0.01291071;0.09045547;0.346859;0.03584217;0;0;0;0.04066364;0.04065538;318.3279;35856.74
775.0001;0.01296428;0.09115689;0.05253904;0.005429044;0;0;0;0.04083237;0.04082404;48.21741;5431.261
780.0001;0.01307142;0.09154911;0.1158782;0.0119741;0;0;0;0.04116983;0.04116136;106.3466;11979.03
785.0001;0.01312499;0.09319508;0.002296511;0.0002373066;0;0;0;0.04133856;0.04133002;2.10761;237.4047
790.0001;0.01317856;0.09154312;0.1703198;0.01759975;0;0;0;0.04150729;0.04149867;156.3101;17607.06
795.0001;0.01328571;0.09028042;0.1877037;0.01939608;0;0;0;0.04184474;0.04183599;172.264;19404.2
800.0001;0.01333928;0.0929023;-0.07102648;-0.007339417;0;0;0;0.04201347;0.04200465;-65.18417;-7342.501
805.0001;0.01349999;0.09307524;0.1100346;0.01137027;0;0;0;0.04251966;0.04251062;100.9837;11375.1
810.0001;0.01349999;0.09394192;0.3386956;0.03499861;0;0;0;0.04251966;0.04251062;310.836;35013.49
815.0001;0.01360713;0.09382;0.2320733;0.02398095;0;0;0;0.04285712;0.04284794;212.984;23991.23
820.0001;0.01371428;0.09438282;0.1285343;0.0132819;0;0;0;0.04319457;0.04318525;117.9617;13287.64
825.0001;0.01382142;0.09596881;0.1388412;0.01434695;0;0;0;0.04353203;0.04352256;127.4208;14353.2
830.0001;0.01382142;0.09644354;0.1329096;0.01373402;0;0;0;0.04353203;0.04352256;121.9771;13740
835.0001;0.01392856;0.09726566;0.313912;0.03243764;0;0;0;0.04386949;0.04385987;288.091;32451.87
840.0001;0.01403571;0.09682942;0.2536268;0.02620815;0;0;0;0.04420695;0.04419718;232.7646;26219.74
845.0001;0.01414285;0.09733946;0.09925789;0.01025667;0;0;0;0.0445444;0.04453448;91.09339;10261.24
850.0001;0.01424999;0.0968876;0.2889816;0.02986149;0;0;0;0.04488186;0.04487179;265.2113;29874.9
855.0001;0.01424999;0.09825552;-0.08664836;-0.008953682;0;0;0;0.04488186;0.04487179;-79.52106;-8957.7
860.0001;0.01435713;0.09795221;-0.05740141;-0.005931491;0;0;0;0.04521932;0.0452091;-52.67984;-5934.173
865.0001;0.0144107;0.09745199;0.1536702;0.01587928;0;0;0;0.04538805;0.04537775;141.03;15886.49
870.0001;0.01457142;0.09954442;0.269513;0.02784973;0;0;0;0.04589424;0.04588371;247.3441;27862.51
875.0001;0.01457142;0.09871399;0.2126634;0.02197526;0;0;0;0.04589424;0.04588371;195.1707;21985.35
880.0001;0.01467856;0.09925923;0.1969241;0.02034886;0;0;0;0.04623169;0.04622101;180.726;20358.27
885.0001;0.01478571;0.0981022;0.1464759;0.01513588;0;0;0;0.04656915;0.04655831;134.4275;15142.93
890.0001;0.01489285;0.09811214;0.2916831;0.03014065;0;0;0;0.04690661;0.04689561;267.6906;30154.79
895.0001;0.01494642;0.09949317;0.2816992;0.02910897;0;0;0;0.04707533;0.04706426;258.5279;29122.68
900.0001;0.01505356;0.09819875;0.1177869;0.01217134;0;0;0;0.04741279;0.04740156;108.0983;12177.11
905.0001;0.01510713;0.0980549;0.2508959;0.02592596;0;0;0;0.04758152;0.04757021;230.2584;25938.3
910.0001;0.01521428;0.09906942;0.2002422;0.02069174;0;0;0;0.04791898;0.0479075;183.7712;20701.66
915.0001;0.01532142;0.09967903;0.1423355;0.01470803;0;0;0;0.04825644;0.0482448;130.6277;14715.13
920.0001;0.01542856;0.09942594;0.02499521;0.002582843;0;0;0;0.04859389;0.04858209;22.93921;2584.098
925.0001;0.01542856;0.09897271;0.2168919;0.02241221;0;0;0;0.04859389;0.04858209;199.0514;22423.1
930.0001;0.0155357;0.09885894;0.3415734;0.03529599;0;0;0;0.04893135;0.04891938;313.4771;35313.26
935.0001;0.01564285;0.09931663;0.2827563;0.02921821;0;0;0;0.04926881;0.04925668;259.4981;29232.6
940.0001;0.01574999;0.09996578;0.2254076;0.02329217;0;0;0;0.04960626;0.04959397;206.8666;23303.72
945.0001;0.01585713;0.09993473;0.2938267;0.03036216;0;0;0;0.04994373;0.04993126;269.6579;30377.32
950.0001;0.01585713;0.09992126;0.2268464;0.02344084;0;0;0;0.04994373;0.04993126;208.187;23452.55
955.0001;0.01596428;0.09958937;0.366445;0.03786606;0;0;0;0.05028118;0.05026855;336.3029;37885.1
960.0001;0.01601785;0.09923692;0.4997596;0.05164193;0;0;0;0.05044991;0.05043719;458.6517;51667.98
965.0001;0.01612499;0.09893196;0.348885;0.03605153;0;0;0;0.05078737;0.05077448;320.1873;36069.84
970.0001;0.01623213;0.1001238;0.3692053;0.03815129;0;0;0;0.05112483;0.05111176;338.8361;38170.79
975.0001;0.0162857;0.1003516;-0.01300243;-0.001343587;0;0;0;0.05129355;0.0512804;-11.93291;-1344.276
980.0001;0.01639285;0.09994159;0.1131766;0.01169494;0;0;0;0.05163101;0.05161768;103.8673;11700.98
985.0001;0.01649999;0.100142;0.05104153;0.005274302;0;0;0;0.05196847;0.05195497;46.84309;5277.043
990.0001;0.01655356;0.100668;0.1203415;0.01243532;0;0;0;0.0521372;0.05212361;110.4428;12441.8
995.0001;0.01660713;0.099715;0.2816111;0.02909987;0;0;0;0.05230593;0.05229225;258.4471;29115.09
1000;0.01671428;0.1004841;0.1870282;0.01932629;0;0;0;0.05264339;0.05262954;171.6441;19336.46
1005;0.01682142;0.1002824;0.2217077;0.02290984;0;0;0;0.05298084;0.05296681;203.471;22921.98
1010;0.01682142;0.1005324;0.1868227;0.01930505;0;0;0;0.05298084;0.05296681;171.4555;19315.28
1015;0.01692856;0.100474;0.4342769;0.04487537;0;0;0;0.0533183;0.05330409;398.5553;44899.29
1020;0.0170357;0.1003837;0.1992438;0.02058857;0;0;0;0.05365576;0.05364137;182.8549;20599.62
1025;0.01714285;0.1005807;0.2456984;0.02538888;0;0;0;0.05399322;0.05397865;225.4883;25402.59
1030;0.01719642;0.1009963;0.3068058;0.03170333;0;0;0;0.05416194;0.05414728;281.5694;31720.5
1035;0.01724999;0.1006941;0.1925488;0.01989675;0;0;0;0.05433067;0.05431592;176.7106;19907.56
1040;0.01735713;0.1002355;0.2628178;0.0271579;0;0;0;0.05466813;0.0546532;241.1997;27172.75
1045;0.0174107;0.1003892;0.2439072;0.02520379;0;0;0;0.05483686;0.05482183;223.8445;25217.61
1050;0.01751784;0.1006424;0.3776035;0.03901911;0;0;0;0.05517431;0.0551591;346.5436;39040.64
1055;0.01762499;0.1016161;0.4356277;0.04501495;0;0;0;0.05551178;0.05549637;399.795;45039.94
1060;0.01767856;0.1000792;0.4263191;0.04405306;0;0;0;0.05568051;0.05566501;391.252;44077.59
1065;0.0177857;0.1010054;0.3830359;0.03958046;0;0;0;0.05601796;0.05600228;351.5292;39602.63
1070;0.01783927;0.1003404;0.5586353;0.05772576;0;0;0;0.05618669;0.05617091;512.6845;57758.2
1075;0.01794642;0.1007946;0.3067177;0.03169423;0;0;0;0.05652415;0.05650818;281.4886;31712.14
1080;0.01799999;0.1014017;0.452894;0.04679914;0;0;0;0.05669288;0.05667681;415.641;46825.67
1085;0.01810713;0.1018918;0.4052354;0.04187441;0;0;0;0.05703034;0.05701408;371.9026;41898.29
1090;0.01821427;0.1010812;0.2757382;0.028493;0;0;0;0.05736779;0.05735134;253.0573;28509.35
1095;0.01826785;0.1020013;-0.005954862;-0.000615337;0;0;0;0.05753652;0.05751997;-5.465043;-615.691
1100;0.01837499;0.1020763;0.2284908;0.02361076;0;0;0;0.05787398;0.05785724;209.6962;23624.43
1105;0.01842856;0.1033708;0.361365;0.03734113;0;0;0;0.05804271;0.05802587;331.6408;37362.8
1110;0.0185357;0.1033508;0.4756808;0.04915377;0;0;0;0.05838016;0.05836313;436.5534;49182.47
1115;0.01864284;0.1028867;0.542015;0.05600833;0;0;0;0.05871762;0.05870039;497.4313;56041.22
1120;0.01874999;0.1041495;0.3120034;0.03224041;0;0;0;0.05905508;0.05903765;286.3394;32259.45
1125;0.01874999;0.1034688;0.05482954;0.005665731;0;0;0;0.05905508;0.05903765;50.31952;5669.077
1130;0.0189107;0.1031572;0.2091984;0.02161722;0;0;0;0.05956126;0.05954353;191.9907;21630.09
1135;0.01901785;0.1035112;-0.04621354;-0.004775408;0;0;0;0.05989873;0.05988079;-42.41222;-4778.269
1140;0.01901785;0.1039223;-0.1723633;-0.01781091;0;0;0;0.05989873;0.05988079;-158.1854;-17821.57
1145;0.01912499;0.1041783;-0.09616248;-0.009936809;0;0;0;0.06023618;0.06021804;-88.25259;-9942.795
1150;0.01923213;0.1021576;-0.2068371;-0.02137321;0;0;0;0.06057364;0.0605553;-189.8236;-21386.16
1155;0.01933927;0.1022432;0.1933416;0.01997867;0;0;0;0.06091109;0.06089255;177.4382;19990.84
1160;0.01939284;0.1034446;-0.05020716;-0.005188084;0;0;0;0.06107982;0.06106118;-46.07735;-5191.253
1165;0.01949999;0.1040838;-0.2538202;-0.02622814;0;0;0;0.06141728;0.06139843;-232.9421;-26244.25
1170;0.01960713;0.1026456;-0.03966528;-0.004098754;0;0;0;0.06175474;0.06173568;-36.4026;-4101.285
1175;0.01960713;0.1027577;-0.2619835;-0.02707168;0;0;0;0.06175474;0.06173568;-240.4339;-27088.4
1180;0.01971427;0.1023995;-0.1719521;-0.01776842;0;0;0;0.0620922;0.06207293;-157.8081;-17779.45
1185;0.01982142;0.1045225;-0.3894252;-0.04024068;0;0;0;0.06242966;0.06241018;-357.3929;-40265.81
1190;0.01982142;0.1013173;-0.2865909;-0.02961445;0;0;0;0.06242966;0.06241018;-263.0173;-29632.94
1195;0.01992856;0.101414;-0.1622619;-0.01676709;0;0;0;0.06276712;0.06274743;-148.9149;-16777.62
1200;0.0200357;0.1005461;-0.1566239;-0.01618451;0;0;0;0.06310457;0.06308466;-143.7408;-16194.72
1205;0.02014285;0.1011688;-0.2440125;-0.02521467;0;0;0;0.06344203;0.06342192;-223.9411;-25230.67
1210;0.02024999;0.0996004;-0.06071958;-0.006274369;0;0;0;0.06377948;0.06375915;-55.72506;-6278.371
1215;0.02024999;0.1000549;-0.2016689;-0.02083916;0;0;0;0.06377948;0.06375915;-185.0806;-20852.45
1220;0.02035713;0.1005697;-0.1726568;-0.01784124;0;0;0;0.06411694;0.0640964;-158.4549;-17852.68
1225;0.02046427;0.09998488;-0.08653093;-0.008941547;0;0;0;0.0644544;0.06443364;-79.41329;-8947.31
1230;0.02057142;0.09985733;-0.02859495;-0.002954817;0;0;0;0.06479186;0.06477088;-26.24286;-2956.732
1235;0.02067856;0.09882973;-0.1676943;-0.01732844;0;0;0;0.06512932;0.06510812;-153.9005;-17339.73
1240;0.02067856;0.09850554;-0.2677096;-0.02766338;0;0;0;0.06512932;0.06510812;-245.689;-27681.4
1245;0.0207857;0.09852837;-0.3614409;-0.03734896;0;0;0;0.06546678;0.06544535;-331.7104;-37373.42
1250;0.02089284;0.09760907;-0.3602076;-0.03722152;0;0;0;0.06580423;0.06578258;-330.5786;-37246.02
1255;0.02099999;0.09742682;-0.0001701483;-1.758202e-005;0;0;0;0.06614169;0.06611983;-0.1561527;-17.59365
1260;0.02099999;0.09675218;-0.3212997;-0.03320104;0;0;0;0.06614169;0.06611983;-294.8711;-33223
1265;0.02110713;0.09570884;-0.3582695;-0.03702126;0;0;0;0.06647915;0.06645706;-328.7999;-37045.87
1270;0.02121427;0.09412845;-0.2003769;-0.02070566;0;0;0;0.06681661;0.0667943;-183.8948;-20719.49
1275;0.02132141;0.09384416;0.2271401;0.02347119;0;0;0;0.06715406;0.06713152;208.4566;23486.95
1280;0.02132141;0.09385191;-0.2837426;-0.02932013;0;0;0;0.06715406;0.06713152;-260.4032;-29339.82
1285;0.02142856;0.09274241;-0.2601923;-0.02688659;0;0;0;0.06749152;0.06746875;-238.7901;-26904.74
1290;0.0215357;0.0925504;-0.2753443;-0.0284523;0;0;0;0.06782898;0.06780598;-252.6958;-28471.6
1295;0.02158927;0.09043984;-0.2342341;-0.02420424;0;0;0;0.06799771;0.0679746;-214.9671;-24220.7
1300;0.02169641;0.09131663;-0.4312989;-0.04456764;0;0;0;0.06833516;0.06831183;-395.8222;-44598.1
1305;0.02174999;0.08851295;0.009696378;0.001001961;0;0;0;0.06850389;0.06848044;8.898798;1002.647
1310;0.02185713;0.0880773;-0.09219832;-0.009527178;0;0;0;0.06884135;0.06881767;-84.6145;-9533.737
1315;0.0219107;0.0862914;-0.3478158;-0.03594104;0;0;0;0.06901008;0.06898628;-319.2061;-35965.84
1320;0.02201784;0.08178431;-0.06973449;-0.007205911;0;0;0;0.06934753;0.0693235;-63.99845;-7210.909
1325;0.02212499;0.07953652;-0.352984;-0.03647508;0;0;0;0.069685;0.06966073;-323.9492;-36500.5
1330;0.02217856;0.07550502;-0.3091135;-0.03194179;0;0;0;0.06985372;0.06982934;-283.6872;-31964.1
1335;0.0222857;0.06905206;-0.2765483;-0.02857672;0;0;0;0.07019117;0.07016655;-253.8008;-28596.78
1340;0.02239284;0.06325563;0.06839589;0.00706759;0;0;0;0.07052864;0.07050378;62.76996;7072.574
1345;0.02244641;0.05643871;-0.1484018;-0.01533488;0;0;0;0.07069737;0.07067239;-136.195;-15345.73
1350;0.02255356;0.05063833;-0.2235748;-0.02310278;0;0;0;0.07103483;0.07100961;-205.1846;-23119.19
1355;0.02260713;0.04370363;-0.3681947;-0.03804687;0;0;0;0.07120355;0.07117821;-337.9087;-38073.96
1360;0.02271427;0.03508451;-0.3188037;-0.03294312;0;0;0;0.07154101;0.07151543;-292.5804;-32966.69
1365;0.02282141;0.0287241;-0.4394328;-0.04540815;0;0;0;0.07187847;0.07185265;-403.2871;-45440.79
1370;0.02287499;0.01970985;-0.3599434;-0.03719422;0;0;0;0.0720472;0.07202126;-330.3361;-37221.02
1375;0.02292856;0.01331005;-0.2875893;-0.02971762;0;0;0;0.07221593;0.07218986;-263.9335;-29739.08
1380;0.0230357;0.01206124;-0.3120205;-0.03224218;0;0;0;0.07255339;0.07252708;-286.3551;-32265.57
1385;0.02314284;0.008266688;-0.1539518;-0.01590838;0;0;0;0.07289084;0.07286428;-141.2884;-15919.98
1390;0.02324999;0.005530629;-0.0292703;-0.003024604;0;0;0;0.0732283;0.0732015;-26.86266;-3026.819
1395;0.02324999;0.005792794;-0.1974111;-0.02039918;0;0;0;0.0732283;0.0732015;-181.1729;-20414.12
1400;0.02335713;0.004688457;-0.1380656;-0.0142668;0;0;0;0.07356575;0.07353871;-126.7089;-14277.3
1405;0.02346427;0.00258851;-0.2452458;-0.02534211;0;0;0;0.07390321;0.07387592;-225.073;-25360.84
1410;0.02351784;0.003517796;-0.2906139;-0.03003016;0;0;0;0.07407194;0.07404452;-266.7093;-30052.41
1415;0.02367856;0.003166088;-0.2988359;-0.03087977;0;0;0;0.07457813;0.07455033;-274.255;-30902.8
1420;0.02367856;0.004382597;-0.3866356;-0.03995242;0;0;0;0.07457813;0.07455033;-354.8327;-39982.22
1425;0.0237857;0.007245198;-0.3667558;-0.03789818;0;0;0;0.07491559;0.07488754;-336.5882;-37926.57
1430;0.02383927;0.004617591;-0.4249856;-0.04391527;0;0;0;0.07508431;0.07505614;-390.0283;-43948.24
1435;0.02399998;0.004033435;-0.332928;-0.03440263;0;0;0;0.0755905;0.07556194;-305.5429;-34428.63
1440;0.02399998;0.004718566;-0.1910391;-0.01974074;0;0;0;0.0755905;0.07556194;-175.3251;-19755.67
1445;0.02410713;0.004373436;-0.2168798;-0.02241096;0;0;0;0.07592797;0.07589915;-199.0403;-22427.97
1450;0.02421427;0.005021215;-0.2193463;-0.02266583;0;0;0;0.07626541;0.07623634;-201.3039;-22683.12
1455;0.02426784;0.004553772;-0.4113898;-0.04251036;0;0;0;0.07643414;0.07640495;-377.5508;-42542.86
1460;0.02432141;0.003894248;-0.1366267;-0.01411812;0;0;0;0.07660288;0.07657355;-125.3884;-14128.93
1465;0.02442855;0.002893978;-0.03620033;-0.003740708;0;0;0;0.07694033;0.07691075;-33.22265;-3743.586
1470;0.0245357;0.003668337;-0.2921996;-0.03019402;0;0;0;0.07727779;0.07724794;-268.1646;-30217.35
1475;0.02464284;0.002006898;-0.2636867;-0.02724768;0;0;0;0.07761525;0.07758514;-241.9971;-27268.83
1480;0.02469641;0.003965701;-0.3555386;-0.03673906;0;0;0;0.07778398;0.07775375;-326.2936;-36767.64
1485;0.02474998;0.003160764;-0.08817533;-0.009111469;0;0;0;0.07795271;0.07792234;-80.92243;-9118.572
1490;0.02485713;0.003395875;-0.3340732;-0.03452097;0;0;0;0.07829016;0.07825953;-306.5939;-34547.99
1495;0.02496427;0.002552411;-0.2554059;-0.02639199;0;0;0;0.07862762;0.07859673;-234.3974;-26412.74
1500;0.02501784;0.0009621514;-0.3580346;-0.03699699;0;0;0;0.07879635;0.07876532;-328.5844;-37026.14
1505;0.02512498;0.000319658;-0.1062932;-0.01098366;0;0;0;0.0791338;0.07910251;-97.55003;-10992.35
1510;0.02517856;0.0008084776;-0.1676649;-0.01732541;0;0;0;0.07930254;0.07927112;-153.8736;-17339.15
1515;0.0252857;0.0003251001;-0.160265;-0.01656075;0;0;0;0.07963999;0.0796083;-147.0824;-16573.94
1520;0.02539284;0.0003589279;-0.398352;-0.04116312;0;0;0;0.07997745;0.07994548;-365.5854;-41196.05
1525;0.02549998;0.001186417;-0.2577257;-0.02663171;0;0;0;0.08031491;0.08028268;-236.5264;-26653.1
1530;0.02549998;-0.0002387751;-0.082185;-0.008492467;0;0;0;0.08031491;0.08028268;-75.42484;-8499.287
1535;0.02560713;-0.0008403542;-0.09595697;-0.009915573;0;0;0;0.08065236;0.08061986;-88.06399;-9923.57
1540;0.02571427;-0.0007864019;-0.2029904;-0.02097571;0;0;0;0.08098982;0.08095704;-186.2933;-20992.7
1545;0.02582141;-0.002062384;-0.329463;-0.03404458;0;0;0;0.08132728;0.08129423;-302.3629;-34072.27
1550;0.02592855;-0.0009861191;-0.2316794;-0.02394025;0;0;0;0.08166474;0.08163141;-212.6225;-23959.8
1555;0.02592855;-0.001343856;-0.3098475;-0.03201764;0;0;0;0.08166474;0.08163141;-284.3609;-32043.79
1560;0.0260357;-0.001058551;-0.3651408;-0.03773129;0;0;0;0.0820022;0.08196859;-335.106;-37762.23
1565;0.02614284;-0.002361588;-0.3280241;-0.03389589;0;0;0;0.08233966;0.08230578;-301.0424;-33923.81
1570;0.02619641;-0.004587685;-0.08491588;-0.008774659;0;0;0;0.08250839;0.08247437;-77.93109;-8781.899
1575;0.02630356;-0.003807727;-0.2889108;-0.02985417;0;0;0;0.08284584;0.08281155;-265.1463;-29878.91
1580;0.0264107;-0.005810068;-0.1221206;-0.01261916;0;0;0;0.0831833;0.08314872;-112.0755;-12629.65
1585;0.02646427;-0.006739236;-0.246391;-0.02546045;0;0;0;0.08335202;0.08331731;-226.124;-25481.67
1590;0.02657141;-0.006155941;-0.2391967;-0.02471704;0;0;0;0.08368948;0.08365448;-219.5215;-24737.73
1595;0.02662498;-0.008015884;-0.1857241;-0.01919153;0;0;0;0.08385822;0.08382308;-170.4473;-19207.62
1600;0.02673213;-0.008704499;-0.1572112;-0.01624519;0;0;0;0.08419567;0.08416025;-144.2797;-16258.87
1605;0.0267857;-0.008473733;-0.101125;-0.01044961;0;0;0;0.0843644;0.08432883;-92.80696;-10458.42
1610;0.02683927;-0.008957463;-0.1068218;-0.01103827;0;0;0;0.08453313;0.08449742;-98.03512;-11047.6
1615;0.02699998;-0.009794114;0.0308681;0.00318971;0;0;0;0.08503932;0.08500318;28.32904;3192.423
1620;0.02699998;-0.009819368;-0.02624573;-0.002712064;0;0;0;0.08503932;0.08500318;-24.08687;-2714.37
1625;0.02710713;-0.01059349;-0.1047956;-0.0108289;0;0;0;0.08537678;0.08534035;-96.17561;-10838.15
1630;0.02721427;-0.01084689;-0.1580334;-0.01633015;0;0;0;0.08571424;0.08567752;-145.0343;-16344.14
1635;0.02732141;-0.01178357;-0.02307435;-0.002384355;0;0;0;0.08605169;0.08601469;-21.17636;-2386.406
1640;0.02732141;-0.01142294;-0.02222285;-0.002296366;0;0;0;0.08605169;0.08601469;-20.3949;-2298.342
1645;0.02742855;-0.01352758;-0.17251;-0.01782607;0;0;0;0.08638915;0.08635186;-158.3202;-17841.47
1650;0.0275357;-0.01222705;-0.1052067;-0.01087139;0;0;0;0.08672661;0.08668902;-96.55293;-10880.81
1655;0.02758927;-0.01328801;-0.09152296;-0.009457392;0;0;0;0.08689533;0.0868576;-83.99471;-9465.61
1660;0.02769641;-0.01224922;-0.2491513;-0.02574569;0;0;0;0.08723279;0.08719476;-228.6573;-25768.15
1665;0.02774998;-0.01442136;-0.1467281;-0.01516193;0;0;0;0.08740152;0.08736335;-134.6589;-15175.18
1670;0.02785712;-0.01204593;-0.1053829;-0.01088959;0;0;0;0.08773898;0.08770051;-96.71458;-10899.14
1675;0.0279107;-0.01271486;-0.1578279;-0.01630891;0;0;0;0.0879077;0.08786909;-144.8457;-16323.25
1680;0.02801784;-0.01490121;0.05817707;0.006011642;0;0;0;0.08824516;0.08820625;53.39169;6016.947
1685;0.02812498;-0.01415825;0.09638021;0.009959308;0;0;0;0.08858262;0.08854341;88.45242;9968.13
1690;0.02817855;-0.0140211;0.01645014;0.001699851;0;0;0;0.08875135;0.08871199;15.09703;1701.36
1695;0.0282857;-0.01655846;0.1000508;0.0103386;0;0;0;0.08908881;0.08904914;91.82107;10347.81
1700;0.02833927;-0.01682916;-0.09228639;-0.009536279;0;0;0;0.08925754;0.08921773;-84.69534;-9544.791
1705;0.02849998;-0.01555729;-0.1200652;-0.01240676;0;0;0;0.08976372;0.08972345;-110.1892;-12417.9
1710;0.02849998;-0.01542934;-0.09680847;-0.01000356;0;0;0;0.08976372;0.08972345;-88.84545;-10012.54
1715;0.02860713;-0.01587991;-0.1335728;-0.01380255;0;0;0;0.09010118;0.09006062;-122.5857;-13814.99
1720;0.02871427;-0.01425109;-0.1557723;-0.01609651;0;0;0;0.09043863;0.09039776;-142.9592;-16111.06
1725;0.02882141;-0.01381806;-0.1456709;-0.01505269;0;0;0;0.09077609;0.09073492;-133.6887;-15066.36
1730;0.02887498;-0.01419717;-0.2703818;-0.0279395;0;0;0;0.09094483;0.0909035;-248.1414;-27964.91
1735;0.02898212;-0.01470839;0.05039543;0.005207538;0;0;0;0.09128228;0.09124064;46.25013;5212.292
1740;0.0290357;-0.01441658;-0.003693822;-0.0003816957;0;0;0;0.09145101;0.09140922;-3.389985;-382.0447
1745;0.02914284;-0.01533988;0.02361514;0.002440236;0;0;0;0.09178847;0.09174637;21.67267;2442.476
1750;0.02919641;-0.01795883;-0.1330149;-0.0137449;0;0;0;0.0919572;0.09191494;-122.0737;-13757.54
1755;0.02930355;-0.01636693;-0.005015281;-0.0005182468;0;0;0;0.09229466;0.09225209;-4.602747;-518.7251
1760;0.02935712;-0.01733294;-0.07783907;-0.008043386;0;0;0;0.09246338;0.09242066;-71.43639;-8050.824
1765;0.02946427;-0.01703233;0.006319387;0.0006530047;0;0;0;0.09280084;0.09275781;5.799583;653.6107
1770;0.02957141;-0.01648075;-0.2024031;-0.02091503;0;0;0;0.0931383;0.09309495;-185.7543;-20934.51
1775;0.02957141;-0.01371376;-0.0640671;-0.00662028;0;0;0;0.0931383;0.09309495;-58.79723;-6626.446
1780;0.0297857;-0.01329948;0.3109169;0.03212814;0;0;0;0.09381322;0.09376924;285.3423;32158.28
1785;0.0297857;-0.01329067;-0.08441668;-0.008723075;0;0;0;0.09381322;0.09376924;-77.47295;-8731.258
1790;0.02989284;-0.01323097;-0.0977188;-0.01009763;0;0;0;0.09415067;0.09410638;-89.6809;-10107.14
1795;0.02999998;-0.01401222;-0.0344971;-0.003564707;0;0;0;0.09448814;0.09444352;-31.65952;-3568.075
1800;0.02999998;-0.0148049;0.09226915;0.009534498;0;0;0;0.09448814;0.09444352;84.67951;9543.507
1805;0.03010712;-0.01596996;0.2935919;0.03033789;0;0;0;0.09482559;0.09478066;269.4424;30366.66
1810;0.03021427;-0.0159599;-0.001608933;-0.0001662567;0;0;0;0.09516305;0.09511779;-1.476589;-166.4149
1815;0.03032141;-0.01697368;0.1023999;0.01058134;0;0;0;0.09550051;0.09545493;93.97695;10591.45
1820;0.03042855;-0.01542406;0.09643893;0.009965376;0;0;0;0.09583796;0.09579207;88.5063;9974.926
1825;0.03042855;-0.01402447;-0.1592079;-0.01645152;0;0;0;0.09583796;0.09579207;-146.1122;-16467.28
1830;0.03053569;-0.01270166;0.1848259;0.01909871;0;0;0;0.0961754;0.09612919;169.623;19117.08
1835;0.03064284;-0.01396316;-0.1144859;-0.01183023;0;0;0;0.09651288;0.09646633;-105.0688;-11841.65
1840;0.03064284;-0.01184806;-0.132868;-0.01372972;0;0;0;0.09651288;0.09646633;-121.9389;-13742.97
1845;0.03074998;-0.01147427;0.01830016;0.00189102;0;0;0;0.09685033;0.09680346;16.79487;1892.852
1850;0.03085712;-0.01442723;0.2920355;0.03017707;0;0;0;0.09718779;0.09714059;268.014;30206.4
1855;0.03096426;-0.0135573;-0.08767613;-0.009059885;0;0;0;0.09752524;0.09747771;-80.46429;-9068.72
1860;0.03107141;-0.01268048;0.1548742;0.0160037;0;0;0;0.0978627;0.09781484;142.135;16019.36
1865;0.03117855;-0.01386864;0.2260536;0.02335892;0;0;0;0.09820016;0.09815198;207.4595;23381.86
1870;0.03117855;-0.01417247;0.03603629;0.003723757;0;0;0;0.09820016;0.09815198;33.07211;3727.414
1875;0.03128569;-0.01107738;0.005908369;0.0006105326;0;0;0;0.09853762;0.0984891;5.422373;611.1342
1880;0.03139284;-0.01170958;0.09776028;0.01010192;0;0;0;0.09887508;0.09882623;89.71896;10111.9
1885;0.03149998;-0.01214605;0.1990383;0.02056734;0;0;0;0.09921253;0.09916335;182.6664;20587.74
1890;0.03149998;-0.008571067;-0.1861939;-0.01924008;0;0;0;0.09921253;0.09916335;-170.8785;-19259.17
1895;0.03160712;-0.01236374;0.06748556;0.006973522;0;0;0;0.09954999;0.09950047;61.93451;6980.464
1900;0.03171427;-0.01301198;-0.006630326;-0.000685135;0;0;0;0.09988745;0.0998376;-6.084945;-685.8194
1905;0.03176784;-0.01332842;0.06912996;0.007143444;0;0;0;0.1000562;0.1000062;63.44365;7150.591
1910;0.03182141;-0.01242227;0.2357145;0.02435721;0;0;0;0.1002249;0.1001747;216.3257;24381.63
1915;0.03192855;-0.01257179;0.1566361;0.01618576;0;0;0;0.1005624;0.1005118;143.7519;16202.03
1920;0.03203569;-0.01037248;0.2916538;0.03013762;0;0;0;0.1008998;0.100849;267.6637;30168.03
1925;0.03214283;-0.007520799;0.3158501;0.03263791;0;0;0;0.1012373;0.1011861;289.8697;32670.95
1930;0.03224998;-0.0100694;0.2642274;0.02730355;0;0;0;0.1015747;0.1015232;242.4933;27331.28
1935;0.03224998;-0.01018137;0.4988787;0.0515509;0;0;0;0.1015747;0.1015232;457.8432;51603.26
1940;0.03235712;-0.008888359;0.3036344;0.03137562;0;0;0;0.1019122;0.1018603;278.6589;31407.6
1945;0.03246427;-0.012106;0.2798786;0.02892085;0;0;0;0.1022497;0.1021974;256.8571;28950.42
1950;0.03257141;-0.01113947;0.4432037;0.04579781;0;0;0;0.1025871;0.1025345;406.7478;45844.79
1955;0.03262498;-0.00931524;0.1040443;0.01075127;0;0;0;0.1027558;0.1027031;95.4861;10762.31
1960;0.03273212;-0.008877631;0.5437476;0.05618737;0;0;0;0.1030933;0.1030402;499.0214;56245.29
1965;0.03283926;-0.007094702;0.2865737;0.02961267;0;0;0;0.1034308;0.1033773;263.0014;29643.3
1970;0.03289284;-0.006524406;0.2635814;0.0272368;0;0;0;0.1035995;0.1035459;241.9004;27265.01
1975;0.03299998;-0.008491783;0.3363171;0.03475283;0;0;0;0.1039369;0.103883;308.6532;34788.96
1980;0.03305355;-0.009160665;0.185237;0.0191412;0;0;0;0.1041057;0.1040515;170.0003;19161.12
1985;0.03310712;-0.009323579;0.145595;0.01504484;0;0;0;0.1042744;0.1042201;133.619;15060.53
1990;0.03321426;-0.009167869;0.2000955;0.02067657;0;0;0;0.1046119;0.1045572;183.6365;20698.2
1995;0.03332141;-0.008525689;-0.0184642;-0.001907971;0;0;0;0.1049493;0.1048943;-16.94542;-1909.973
2000;0.03337498;-0.006186441;0.2546252;0.02631132;0;0;0;0.105118;0.1050628;233.6809;26338.98
2005;0.03348212;-0.005230844;0.08645497;0.008933698;0;0;0;0.1054555;0.1053999;79.34357;8943.119
2010;0.03353569;-0.008061614;0.2493396;0.02576514;0;0;0;0.1056242;0.1055685;228.83;25792.35
2015;0.03358926;-0.008154484;-0.01356035;-0.001401239;0;0;0;0.105793;0.105737;-12.44494;-1402.721
2020;0.03369641;-0.008136121;0.2610854;0.02697887;0;0;0;0.1061304;0.1060741;239.6097;27007.51
2025;0.03374998;-0.009050412;0.1509393;0.01559709;0;0;0;0.1062991;0.1062427;138.5237;15613.67
2030;0.03385712;-0.004802789;0.1260676;0.01302702;0;0;0;0.1066366;0.1065798;115.6979;13040.91
2035;0.03391069;-0.00400486;0.3291228;0.03400943;0;0;0;0.1068053;0.1067483;302.0507;34045.75
2040;0.03401783;-0.003881686;0.3213999;0.03321139;0;0;0;0.1071428;0.1070854;294.963;33246.98
2045;0.03412498;-0.003681342;0.2636107;0.02723983;0;0;0;0.1074802;0.1074225;241.9273;27269.11
2050;0.03417855;-0.006251239;0.1860886;0.0192292;0;0;0;0.107649;0.1075911;170.7818;19249.9
2055;0.03428569;-0.007020821;0.03218945;0.00332625;0;0;0;0.1079864;0.1079282;29.5417;3329.842
2060;0.03433926;-0.004838614;0.3258046;0.03366654;0;0;0;0.1081552;0.1080967;299.0054;33702.95
2065;0.03444641;-0.004502724;0.3069232;0.03171547;0;0;0;0.1084926;0.1084338;281.6772;31749.87
2070;0.03449998;-0.003465181;0.2572974;0.02658745;0;0;0;0.1086613;0.1086024;236.1333;26616.34
2075;0.03460712;-0.004473281;0.4016823;0.04150726;0;0;0;0.1089988;0.1089394;368.6418;41552.5
2080;0.03471426;-0.005816332;0.6901;0.07131048;0;0;0;0.1093363;0.1092765;633.3355;71388.44
2085;0.03476783;-0.006328721;0.5625702;0.05813237;0;0;0;0.109505;0.1094451;516.2958;58196.03
2090;0.03482141;-0.004116797;0.4863401;0.05025524;0;0;0;0.1096737;0.1096136;446.336;50310.36
2095;0.03492855;-0.003975378;0.4913614;0.05077411;0;0;0;0.1100112;0.1099507;450.9442;50829.97
2100;0.03503569;-0.002375252;0.5257471;0.05432731;0;0;0;0.1103486;0.1102878;482.5016;54387.26
2105;0.03508926;-0.001348633;0.4443196;0.04591311;0;0;0;0.1105174;0.1104563;407.7719;45963.85
2107.95;0.03514284;-0.003720456;0.4947971;0.05112913;0;0;0;0.1106861;0.1106249;454.0973;51185.72