File: Ensayos/Resistencia/comp/Clavo6/Clavo6h.raw
"Test Type";"Manual"
"Method Name:";"C:\INSTRON\user\template\CYCLE.MTM"
"Name:";""
"Operator ID:";""
"Company:";""
"Lab name:";""
"Test date:";"09/06/2017"
"Temperature:";""
"Humidity:";""
"Note 1:";""
"Note 2:";""
"Note 3:";""
"Geometry:";"Rectangular"
"Specimen";1
"Specimen name:";""
"Width:";0.250000;"in"
"Thickness:";0.060000;"in"
"Length:";1.250000;"in"
"Diameter:";0.039370;"in"
"Inner diameter:";0.019685;"in"
"Outer diameter:";0.039370;"in"
"Wall thickness:";0.019685;"in"
"Area:";0.015000;"in*in"
"Linear density:";1.000000;"den"
"Sled weight:";2.204623;"lbf"
"Loading span:";0.000000;"mm"
"Support span:";1.000000;"mm"
"Span ratio:";"2"
"Fixture type:";"3-point"
"Comment:";""
"Included"
"Final Width:";0.250000;"in"
"Final Thickness:";0.060000;"in"
"Final Length:";1.250000;"in"
"Final Diameter:";0.039370;"in"
"Final Inner diameter:";0.019685;"in"
"Final Outer diameter:";0.039370;"in"
"Final Wall thickness:";0.019685;"in"
"Final Area:";0.015000;"in*in"
"Final Linear density:";1.000000;"den"
"Time sec";"Extension mm";"Strain 1 %";"Load N";"Stress MPa";"Cycle Count ";"Total Cycle Count ";"Repetitions Count ";"Strain [Exten.] %";"True strain %";"Tenacity gf/tex";"True stress Pa"
0;0.2955534;-0.0009135634;116.6784;12.05679;0;0;0;0.9308768;0.9265708;107081;1.216903e+007
15;0.2957677;-0.002008582;123.2997;12.741;0;0;0;0.9315518;0.9272396;113157.7;1.285969e+007
30;0.2960355;-0.003252381;130.0853;13.44218;0;0;0;0.9323953;0.9280754;119385.1;1.356751e+007
43.782;0.2908927;0.0007981865;107.5323;11.1117;0;0;0;0.9161974;0.9120258;98687.21;1.12135e+007
58.782;0.2659284;0.01482107;51.03613;5.273744;0;0;0;0.8375697;0.8340816;46838.13;5317915
73.78201;0.2593927;0.01480227;52.07924;5.381532;0;0;0;0.8169848;0.8136656;47795.44;5425499
88.78201;0.2590713;0.01400325;53.88985;5.568629;0;0;0;0.8159725;0.8126615;49457.12;5614068
103.782;0.258857;0.01246471;56.11078;5.798125;0;0;0;0.8152976;0.811992;51495.36;5845397
118.782;0.2585356;0.010908;59.72703;6.171806;0;0;0;0.8142852;0.8109878;54814.16;6222062
133.782;0.2583213;0.009308701;64.43069;6.657851;0;0;0;0.8136103;0.8103183;59130.92;6712020
148.782;0.258107;0.008603014;65.60576;6.779276;0;0;0;0.8129354;0.8096488;60209.34;6834387
163.782;0.2578927;0.007312546;70.44846;7.279689;0;0;0;0.8122604;0.8089793;64653.7;7338819
178.782;0.2569284;0.006997447;71.28793;7.366435;0;0;0;0.8092234;0.8059667;65424.11;7426045
193.782;0.2455177;0.01184234;51.23222;5.294007;0;0;0;0.7732841;0.7703096;47018.1;5334945
208.782;0.2408034;0.01230779;51.97902;5.371176;0;0;0;0.758436;0.7555743;47703.46;5411913
223.782;0.2399999;0.01257841;52.58542;5.433838;0;0;0;0.7559051;0.7530624;48259.99;5474913
238.782;0.2383927;0.01322803;52.42627;5.417392;0;0;0;0.7508432;0.7480384;48113.93;5458068
253.782;0.2367856;0.01404178;52.17403;5.391327;0;0;0;0.7457813;0.7430141;47882.43;5431535
268.782;0.2355534;0.01463564;52.57547;5.432809;0;0;0;0.7419006;0.739162;48250.85;5473115
283.782;0.2343213;0.01573818;52.6337;5.438827;0;0;0;0.7380198;0.7353097;48304.29;5478966
298.782;0.2330356;0.01717836;52.92356;5.468779;0;0;0;0.7339703;0.7312898;48570.31;5508918
313.782;0.2317499;0.01830439;53.13354;5.490477;0;0;0;0.7299208;0.7272698;48763.02;5530553
328.782;0.2302499;0.01981944;52.16498;5.390392;0;0;0;0.7251964;0.7225795;47874.13;5429483
343.782;0.2287499;0.02179774;52.4517;5.42002;0;0;0;0.720472;0.717889;48137.27;5459070
358.782;0.2272499;0.02476926;52.61044;5.436423;0;0;0;0.7157476;0.7131983;48282.95;5475334
373.782;0.2257499;0.0279638;52.815;5.457561;0;0;0;0.7110232;0.7085073;48470.68;5496365
388.782;0.2241427;0.03000099;52.38184;5.412801;0;0;0;0.7059613;0.7034811;48073.15;5451013
403.782;0.2227499;0.03119373;53.13293;5.490413;0;0;0;0.7015744;0.6991248;48762.46;5528933
418.782;0.2212499;0.03270502;53.63564;5.542361;0;0;0;0.6968499;0.6944332;49223.82;5580983
433.782;0.2197499;0.033811;53.99712;5.579714;0;0;0;0.6921255;0.6897413;49555.57;5618332
448.782;0.2178213;0.03413769;53.78162;5.557445;0;0;0;0.6860513;0.6837087;49357.79;5595572
463.782;0.2159999;0.03559479;53.98179;5.57813;0;0;0;0.6803145;0.6780108;49541.5;5616079
478.782;0.2142856;0.0359788;54.54709;5.636544;0;0;0;0.6749152;0.6726478;50060.3;5674586
493.782;0.2125713;0.03677375;54.49535;5.631197;0;0;0;0.6695158;0.6672846;50012.81;5668899
508.782;0.2107499;0.03518792;53.06498;5.483392;0;0;0;0.6637791;0.6615858;48700.09;5519790
523.782;0.2090356;0.0363152;51.9195;5.365026;0;0;0;0.6583797;0.6562219;47648.84;5400348
538.7821;0.2075356;0.03658707;52.11454;5.38518;0;0;0;0.6536554;0.6515283;47827.83;5420380
553.7821;0.2060356;0.0323279;51.78689;5.351322;0;0;0;0.648931;0.6468345;47527.14;5386049
568.7821;0.2045356;0.02387753;52.59403;5.434727;0;0;0;0.6442066;0.6421404;48267.89;5469738
583.7821;0.2030356;0.01930639;53.58032;5.536644;0;0;0;0.6394822;0.6374462;49173.05;5572050
598.7821;0.2015356;0.01222447;56.30989;5.818701;0;0;0;0.6347578;0.6327516;51678.1;5855635
613.7821;0.1991784;0.005826001;59.57913;6.156522;0;0;0;0.6273337;0.6253741;54678.42;6195144
628.7821;0.1956427;0.002460447;60.21257;6.221979;0;0;0;0.6161975;0.6143068;55259.77;6260318
643.7821;0.1911427;-0.001825035;60.59989;6.262001;0;0;0;0.6020244;0.6002194;55615.22;6299700
658.7821;0.1866427;-0.00588907;59.92498;6.19226;0;0;0;0.5878512;0.58613;54995.82;6228661
673.7821;0.1821427;-0.008830212;58.74999;6.070844;0;0;0;0.5736779;0.5720387;53917.48;6105671
688.7821;0.1792499;-0.01194644;61.4381;6.348616;0;0;0;0.5645666;0.5629788;56384.48;6384459
703.7821;0.175607;-0.01395481;61.4603;6.35091;0;0;0;0.553093;0.551569;56404.86;6386037
718.7821;0.1718035;-0.01942051;63.36896;6.548139;0;0;0;0.5411133;0.5396545;58156.52;6583572
733.7821;0.1677856;-0.02014374;61.60075;6.365424;0;0;0;0.5284586;0.5270671;56533.76;6399062
748.7821;0.1631785;-0.02198109;60.47069;6.248651;0;0;0;0.5139479;0.5126317;55496.65;6280765
763.7821;0.1584642;-0.02143044;58.40954;6.035665;0;0;0;0.4990998;0.4978584;53605.04;6065789
778.7821;0.1537499;-0.02079649;56.77928;5.867205;0;0;0;0.4842516;0.4830829;52108.88;5895616
793.7821;0.1490356;-0.02065804;54.81803;5.664542;0;0;0;0.4694035;0.4683053;50308.95;5691131
808.7821;0.1443213;-0.01989535;54.13229;5.593681;0;0;0;0.4545554;0.4535254;49679.61;5619107
823.7821;0.1404642;-0.02211859;55.70596;5.756294;0;0;0;0.4424069;0.4414312;51123.84;5781760
838.7821;0.1361785;-0.02215023;55.26179;5.710396;0;0;0;0.4289086;0.4279914;50716.21;5734889
853.7821;0.1318928;-0.0207423;55.08137;5.691753;0;0;0;0.4154103;0.4145498;50550.63;5715397
868.7821;0.1276071;-0.02086728;54.88915;5.671891;0;0;0;0.401912;0.4011065;50374.23;5694687
883.7821;0.1232142;-0.02200458;55.06549;5.690112;0;0;0;0.3880762;0.3873251;50536.05;5712194
898.7821;0.1188214;-0.02201711;54.71517;5.653913;0;0;0;0.3742405;0.3735419;50214.55;5675072
913.7821;0.1144821;-0.0224885;54.92011;5.675089;0;0;0;0.3605734;0.3599249;50402.63;5695552
928.7821;0.1103035;-0.02342535;56.17444;5.804703;0;0;0;0.3474126;0.3468105;51553.79;5824870
943.7821;0.1058035;-0.02263697;56.73259;5.86238;0;0;0;0.3332394;0.3326854;52066.03;5881916
958.7821;0.1010356;-0.02247754;56.48737;5.83704;0;0;0;0.3182225;0.3177173;51840.98;5855615
973.7821;0.09632136;-0.02245342;57.26756;5.91766;0;0;0;0.3033744;0.3029151;52556.99;5935612
988.7821;0.09149994;-0.02161243;56.02321;5.789076;0;0;0;0.2881888;0.2877743;51415;5805760
1003.782;0.08678566;-0.02312998;57.25813;5.916686;0;0;0;0.2733406;0.2729678;52548.34;5932858
1018.782;0.08207137;-0.02299843;57.91402;5.98446;0;0;0;0.2584925;0.258159;53150.27;5999930
1033.782;0.07724994;-0.0230429;58.34315;6.028804;0;0;0;0.2433069;0.2430114;53544.11;6043473
1048.782;0.07253567;-0.02193003;56.97068;5.886982;0;0;0;0.2284588;0.2281982;52284.54;5900432
1063.782;0.06782138;-0.02001344;55.0309;5.686537;0;0;0;0.2136107;0.2133828;50504.31;5698684
1078.782;0.06305353;-0.02071035;53.11078;5.488125;0;0;0;0.1985938;0.1983969;48742.13;5499024
1093.782;0.05839282;-0.02196793;52.43308;5.418096;0;0;0;0.1839144;0.1837455;48120.18;5428061
1108.782;0.05421425;-0.02359261;52.6465;5.44015;0;0;0;0.1707536;0.1706079;48316.04;5449439
1123.782;0.05014283;-0.02537452;51.95961;5.36917;0;0;0;0.1579302;0.1578056;47685.65;5377650
1138.782;0.04617854;-0.02713858;52.07437;5.381029;0;0;0;0.1454442;0.1453385;47790.97;5388855
1153.782;0.04221426;-0.02905987;51.66118;5.338333;0;0;0;0.1329583;0.13287;47411.77;5345430
1168.782;0.03824997;-0.0302191;51.61376;5.333432;0;0;0;0.1204724;0.1203998;47368.25;5339857
1183.782;0.03417855;-0.03196436;51.90567;5.363596;0;0;0;0.107649;0.1075911;47636.15;5369370
1198.782;0.03010712;-0.03330338;51.65029;5.337207;0;0;0;0.09482559;0.09478066;47401.77;5342268
1213.782;0.02614284;-0.03478711;51.60683;5.332716;0;0;0;0.08233966;0.08230578;47361.89;5337107
1228.782;0.02217856;-0.03590029;51.77799;5.350403;0;0;0;0.06985372;0.06982934;47518.97;5354141
1243.782;0.01821427;-0.03726218;51.59828;5.331833;0;0;0;0.05736779;0.05735134;47354.04;5334892
1258.782;0.01424999;-0.0379071;51.58548;5.33051;0;0;0;0.04488186;0.04487179;47342.29;5332902
1273.782;0.01017856;-0.03856736;51.78152;5.350767;0;0;0;0.03205847;0.03205333;47522.21;5352483
1288.782;0.006107139;-0.03962292;51.59132;5.331114;0;0;0;0.01923508;0.01923323;47347.66;5332139
1303.782;0.002196427;-0.04024498;51.59484;5.331478;0;0;0;0.006917881;0.006917642;47350.89;5331847
1318.782;-0.001821428;-0.04085857;51.53717;5.325519;0;0;0;-0.00573678;-0.005736945;47297.96;5325213
1333.782;-0.005785711;-0.04151947;51.3673;5.307965;0;0;0;-0.01822271;-0.01822437;47142.06;5306998
1348.782;-0.009857138;-0.04187905;51.51994;5.323738;0;0;0;-0.0310461;-0.03105092;47282.14;5322085
1363.782;-0.01382142;-0.04232382;51.43266;5.314719;0;0;0;-0.04353204;-0.04354151;47202.05;5312406
1378.782;-0.01778571;-0.04261543;51.47654;5.319252;0;0;0;-0.05601797;-0.05603367;47242.31;5316273
1393.782;-0.02185713;-0.0426502;51.45257;5.316777;0;0;0;-0.06884137;-0.06886507;47220.32;5313117
1408.782;-0.02582142;-0.04309779;51.38439;5.309731;0;0;0;-0.0813273;-0.08136038;47157.75;5305413
1423.782;-0.0297857;-0.04292019;51.19699;5.290366;0;0;0;-0.09381323;-0.09385726;46985.76;5285403
1438.782;-0.03385712;-0.04338595;51.28164;5.299114;0;0;0;-0.1066366;-0.1066935;47063.45;5293463
1453.782;-0.03782141;-0.04358077;51.39978;5.311321;0;0;0;-0.1191225;-0.1191936;47171.87;5304994
1468.782;-0.04183927;-0.04355603;51.19631;5.290296;0;0;0;-0.1317772;-0.1318641;46985.14;5283325
1483.782;-0.04585712;-0.04326254;51.29477;5.30047;0;0;0;-0.1444319;-0.1445363;47075.5;5292815
1498.782;-0.04982141;-0.04307022;51.00321;5.270342;0;0;0;-0.1569178;-0.1570411;46807.92;5262072
1513.782;-0.05378569;-0.04332894;51.04138;5.274287;0;0;0;-0.1694037;-0.1695474;46842.95;5265352
1528.782;-0.05780354;-0.04349057;51.02864;5.27297;0;0;0;-0.1820584;-0.1822243;46831.26;5263370
1543.782;-0.0618214;-0.04307837;50.99355;5.269344;0;0;0;-0.1947131;-0.1949029;46799.05;5259084
1558.782;-0.06578568;-0.04249828;50.95309;5.265163;0;0;0;-0.207199;-0.207414;46761.92;5254253
1573.782;-0.06974997;-0.04296279;50.89004;5.258648;0;0;0;-0.2196849;-0.2199266;46704.06;5247096
1588.782;-0.07382139;-0.04314978;50.96844;5.26675;0;0;0;-0.2325083;-0.232779;46776.01;5254504
1603.782;-0.07778568;-0.04277893;50.94583;5.264413;0;0;0;-0.2449943;-0.2452949;46755.26;5251516
1618.782;-0.08185711;-0.04323717;50.80794;5.250164;0;0;0;-0.2578177;-0.2581506;46628.71;5236628
1633.782;-0.08582139;-0.04381068;50.96712;5.266613;0;0;0;-0.2703036;-0.2706696;46774.8;5252377
1648.782;-0.08978567;-0.04466639;50.99279;5.269265;0;0;0;-0.2827895;-0.2831901;46798.35;5254364
1663.782;-0.09374996;-0.04529628;50.84952;5.254461;0;0;0;-0.2952754;-0.2957123;46666.87;5238946
1678.782;-0.09782138;-0.04813688;50.86461;5.25602;0;0;0;-0.3080988;-0.3085744;46680.72;5239826
1693.782;-0.1017857;-0.051286;51.09424;5.279749;0;0;0;-0.3205848;-0.3210997;46891.46;5262823
1708.782;-0.1058571;-0.05402918;50.90554;5.26025;0;0;0;-0.3334081;-0.3339652;46718.29;5242712
1723.782;-0.1097678;-0.05596833;50.94897;5.264738;0;0;0;-0.3457254;-0.3463244;46758.14;5246536
1738.782;-0.1138392;-0.05804216;50.92909;5.262683;0;0;0;-0.3585488;-0.3591931;46739.9;5243814
1753.782;-0.1177499;-0.05992086;50.78773;5.248076;0;0;0;-0.370866;-0.3715554;46610.17;5228613
1768.782;-0.1218214;-0.06164357;51.15893;5.286433;0;0;0;-0.3836893;-0.3844273;46950.83;5266150
1783.782;-0.1257857;-0.06178766;50.86382;5.255938;0;0;0;-0.3961753;-0.3969622;46679.99;5235115
1798.782;-0.1298571;-0.06156464;50.75041;5.24422;0;0;0;-0.4089987;-0.4098374;46575.92;5222771
1813.782;-0.1338214;-0.06068481;50.69424;5.238415;0;0;0;-0.4214846;-0.4223753;46524.36;5216336
1828.782;-0.1377856;-0.05920108;50.65075;5.233921;0;0;0;-0.4339705;-0.4349149;46484.45;5211207
1843.782;-0.1418035;-0.05171981;50.54718;5.223219;0;0;0;-0.4466252;-0.4476256;46389.4;5199891
1858.782;-0.1458214;-0.0419655;50.43339;5.211461;0;0;0;-0.4592799;-0.4603378;46284.98;5187526
1873.782;-0.1497856;-0.02917639;50.59017;5.227662;0;0;0;-0.4717658;-0.4728821;46428.86;5202999
1888.782;-0.1538571;-0.01379601;50.38835;5.206807;0;0;0;-0.4845892;-0.4857671;46243.63;5181575
1903.782;-0.1578214;-0.009451641;50.42156;5.210238;0;0;0;-0.4970751;-0.4983147;46274.11;5184339
1918.782;-0.1617856;-0.004582315;50.62056;5.230802;0;0;0;-0.5095611;-0.5108638;46456.75;5204148
1933.782;-0.1657499;-0.002686705;50.41803;5.209874;0;0;0;-0.522047;-0.5234144;46270.88;5182676
1948.782;-0.1698213;-0.002453042;50.63178;5.231961;0;0;0;-0.5348704;-0.5363059;46467.04;5203977
1963.782;-0.1738928;-0.003099216;50.55725;5.22426;0;0;0;-0.5476938;-0.5491992;46398.64;5195647
1978.782;-0.1778571;-0.002711136;50.33103;5.200883;0;0;0;-0.5601797;-0.5617546;46191.03;5171749
1993.782;-0.1818213;-0.002831413;50.33217;5.201002;0;0;0;-0.5726656;-0.5743117;46192.08;5171217
2008.782;-0.1857856;-0.003747583;50.34768;5.202604;0;0;0;-0.5851516;-0.5868703;46206.31;5172161
2023.782;-0.1897499;-0.004518419;50.20714;5.188081;0;0;0;-0.5976375;-0.5994305;46077.33;5157075
2038.782;-0.1938213;-0.005928223;50.20362;5.187717;0;0;0;-0.6104609;-0.6123319;46074.1;5156048
2053.782;-0.1978928;-0.007687584;49.84387;5.150544;0;0;0;-0.6232843;-0.6252348;45743.94;5118441
2068.782;-0.2018571;-0.009492047;50.22529;5.189957;0;0;0;-0.6357703;-0.6377999;46093.98;5156960
2083.782;-0.2058213;-0.01066568;49.48149;5.113097;0;0;0;-0.6482561;-0.6503664;45411.37;5079951
2098.782;-0.2097856;-0.01117059;49.07273;5.070859;0;0;0;-0.6607421;-0.6629346;45036.23;5037354
2113.782;-0.213857;-0.01139737;48.65041;5.027219;0;0;0;-0.6735654;-0.6758442;44648.65;4993358
2128.782;-0.2178213;-0.01116402;48.26982;4.987891;0;0;0;-0.6860514;-0.6884156;44299.37;4953672
2143.782;-0.2217856;-0.01081164;47.09113;4.866093;0;0;0;-0.6985373;-0.7009886;43217.63;4832102
2158.782;-0.225857;-0.009062621;42.99688;4.443019;0;0;0;-0.7113607;-0.7139029;39460.15;4411413
2173.782;-0.2298213;-0.007555718;39.17506;4.048098;0;0;0;-0.7238467;-0.7264792;35952.7;4018796
2188.782;-0.2337856;-0.006364227;39.07029;4.037271;0;0;0;-0.7363326;-0.7390569;35856.55;4007544
2203.782;-0.237857;-0.00566919;39.16302;4.046854;0;0;0;-0.749156;-0.7519762;35941.65;4016537
2218.782;-0.2418213;-0.004552873;39.1849;4.049115;0;0;0;-0.7616419;-0.7645572;35961.73;4018275
2233.782;-0.2458927;-0.003209783;39.16394;4.046948;0;0;0;-0.7744653;-0.7774799;35942.49;4015606
2248.782;-0.2498035;-0.002287035;39.00175;4.030189;0;0;0;-0.7867826;-0.789894;35793.65;3998480
2263.782;-0.2538213;-0.0009524031;39.25629;4.056491;0;0;0;-0.7994372;-0.8026498;36027.25;4024062
2278.782;-0.2577856;0.0003471493;38.95228;4.025076;0;0;0;-0.8119231;-0.8152372;35748.24;3992396
2293.782;-0.2617499;0.00160379;38.90147;4.019827;0;0;0;-0.824409;-0.8278261;35701.62;3986687
2308.782;-0.2658213;0.002911799;39.05846;4.036048;0;0;0;-0.8372325;-0.8407569;35845.69;4002258
2323.782;-0.2697856;0.003881216;39.02719;4.032817;0;0;0;-0.8497183;-0.853349;35816.99;3998550
2338.782;-0.2737499;0.004865981;38.7491;4.004082;0;0;0;-0.8622043;-0.8659428;35561.78;3969558
2353.782;-0.2778213;0.006201867;38.87936;4.017542;0;0;0;-0.8750277;-0.8788785;35681.32;3982388
2368.782;-0.2817856;0.007066668;38.7351;4.002635;0;0;0;-0.8875136;-0.8914755;35548.93;3967111
2383.782;-0.285857;0.007674316;38.94065;4.023875;0;0;0;-0.900337;-0.9044145;35737.57;3987646
2398.782;-0.2898213;0.007964044;39.02087;4.032165;0;0;0;-0.912823;-0.9170147;35811.2;3995358
2413.782;-0.2937856;0.007899521;39.0204;4.032116;0;0;0;-0.9253089;-0.9296165;35810.76;3994806
2428.782;-0.2977498;0.007773606;38.76053;4.005262;0;0;0;-0.9377948;-0.9422198;35572.26;3967701
2443.782;-0.3018213;0.007630151;38.9933;4.029315;0;0;0;-0.9506183;-0.9551655;35785.89;3991012
2458.782;-0.3057856;0.007511441;38.93886;4.02369;0;0;0;-0.9631042;-0.967772;35735.93;3984938
2473.782;-0.309857;0.007329147;39.02501;4.032593;0;0;0;-0.9759275;-0.9807209;35815;3993238
2488.782;-0.3138213;0.007178801;39.17577;4.048171;0;0;0;-0.9884135;-0.9933308;35953.35;4008158
2503.782;-0.3177856;0.007085775;38.94241;4.024057;0;0;0;-1.000899;-1.005942;35739.19;3983780
2518.782;-0.3217499;0.006770361;38.9403;4.023839;0;0;0;-1.013385;-1.018555;35737.25;3983062
2533.782;-0.3258213;0.006557684;38.91225;4.020941;0;0;0;-1.026209;-1.031511;35711.51;3979678
2548.782;-0.3297856;0.006563322;38.91128;4.020841;0;0;0;-1.038695;-1.044127;35710.62;3979076
2563.782;-0.333857;0.006333732;38.91584;4.021311;0;0;0;-1.051518;-1.057086;35714.8;3979026
2578.782;-0.3378213;0.006215648;38.89313;4.018965;0;0;0;-1.064004;-1.069705;35693.96;3976203
2593.782;-0.3417856;0.006059038;38.92667;4.02243;0;0;0;-1.07649;-1.082326;35724.74;3979129
2608.782;-0.3457498;0.006097564;38.86242;4.015791;0;0;0;-1.088976;-1.094949;35665.78;3972061
2623.782;-0.3498213;0.005968204;38.75609;4.004804;0;0;0;-1.101799;-1.107914;35568.19;3960679
2638.782;-0.3537855;0.005967891;38.89754;4.019421;0;0;0;-1.114285;-1.12054;35698.01;3974633
2653.782;-0.357857;0.006145487;38.70391;3.999412;0;0;0;-1.127109;-1.133509;35520.31;3954335
2668.782;-0.3618213;0.006364741;38.87158;4.016738;0;0;0;-1.139595;-1.146138;35674.18;3970964
2683.782;-0.3657856;0.00649003;38.99559;4.029552;0;0;0;-1.152081;-1.158768;35787.99;3983129
2698.782;-0.3697498;0.006637556;38.64283;3.993101;0;0;0;-1.164566;-1.1714;35464.25;3946598
2713.782;-0.3738213;0.006779132;38.86903;4.016474;0;0;0;-1.17739;-1.184376;35671.84;3969184
2728.782;-0.3778391;0.007000265;38.83852;4.013322;0;0;0;-1.190044;-1.197182;35643.84;3965561
2743.782;-0.381857;0.007180367;38.83024;4.012466;0;0;0;-1.202699;-1.20999;35636.24;3964208
2758.782;-0.3858212;0.007375816;38.89983;4.019657;0;0;0;-1.215185;-1.222629;35700.11;3970811
2773.782;-0.3897855;0.007706891;38.72673;4.00177;0;0;0;-1.227671;-1.235269;35541.24;3952641
2788.782;-0.3937498;0.007767968;38.88714;4.018346;0;0;0;-1.240157;-1.247911;35688.46;3968513
2803.782;-0.3978212;0.008123161;38.83435;4.012891;0;0;0;-1.25298;-1.260896;35640.02;3962610
2818.782;-0.4017855;0.008271941;38.8902;4.018662;0;0;0;-1.265466;-1.273542;35691.27;3967807
2833.782;-0.4057498;0.008625566;38.81009;4.010385;0;0;0;-1.277952;-1.286188;35617.75;3959134
2848.782;-0.4098212;0.00871734;38.86204;4.015752;0;0;0;-1.290776;-1.299178;35665.43;3963918
2863.782;-0.4137855;0.009117636;38.72799;4.0019;0;0;0;-1.303261;-1.311828;35542.4;3949745
2878.782;-0.4178034;0.009096337;38.75339;4.004525;0;0;0;-1.315916;-1.324651;35565.71;3951829
2893.782;-0.4218212;0.009404859;38.63423;3.992212;0;0;0;-1.328571;-1.337475;35456.36;3939172
2908.782;-0.4257855;0.009717454;38.91683;4.021414;0;0;0;-1.341057;-1.35013;35715.71;3967485
2923.782;-0.4298569;0.009785108;38.70603;3.999631;0;0;0;-1.35388;-1.363129;35522.25;3945480
2938.782;-0.4338212;0.01003224;38.82216;4.011631;0;0;0;-1.366366;-1.375787;35628.83;3956818
2953.782;-0.4377855;0.01026997;38.87857;4.01746;0;0;0;-1.378852;-1.388447;35680.6;3962066
2968.782;-0.4418569;0.01041406;38.8019;4.009538;0;0;0;-1.391675;-1.40145;35610.23;3953738
2983.782;-0.4458212;0.01081404;38.7518;4.004361;0;0;0;-1.404161;-1.414113;35564.26;3948133
2998.782;-0.4498927;0.0109694;38.69901;3.998905;0;0;0;-1.416985;-1.42712;35515.8;3942241
3013.782;-0.4538034;0.01123313;38.71372;4.000426;0;0;0;-1.429302;-1.439615;35529.31;3943248
3028.782;-0.4578212;0.0113628;38.60912;3.989617;0;0;0;-1.441957;-1.452454;35433.32;3932089
3043.782;-0.4617855;0.01146021;38.52012;3.98042;0;0;0;-1.454443;-1.465123;35351.63;3922527
3058.782;-0.4657498;0.01166099;38.90118;4.019797;0;0;0;-1.466928;-1.477794;35701.35;3960829
3073.782;-0.4698212;0.0120049;38.85948;4.015488;0;0;0;-1.479752;-1.490809;35663.08;3956069
3088.782;-0.4738926;0.01208853;38.52669;3.9811;0;0;0;-1.492575;-1.503826;35357.66;3921679
3103.782;-0.4777497;0.01227991;38.64553;3.99338;0;0;0;-1.504724;-1.516159;35466.73;3933290
3118.782;-0.4817676;0.01268115;38.75823;4.005025;0;0;0;-1.517378;-1.529008;35570.16;3944254
3133.782;-0.4857855;0.01284653;38.81409;4.010797;0;0;0;-1.530033;-1.541859;35621.42;3949430
3148.782;-0.4898569;0.01304511;38.27795;3.955396;0;0;0;-1.542856;-1.554882;35129.38;3894370
3163.782;-0.4916247;0.01326374;38.61708;3.99044;0;0;0;-1.548424;-1.560538;35440.62;3928651
3178.782;-0.4931784;0.01328034;38.57997;3.986604;0;0;0;-1.553318;-1.565508;35406.55;3924680
3193.782;-0.4946248;0.01363521;38.7775;4.007016;0;0;0;-1.557873;-1.570136;35587.84;3944592
3208.782;-0.4961783;0.01366497;38.49918;3.978257;0;0;0;-1.562766;-1.575106;35332.41;3916086
3223.782;-0.4976783;0.01381187;38.50884;3.979255;0;0;0;-1.567491;-1.579906;35341.28;3916880
3238.782;-0.4991783;0.01410473;38.59238;3.987888;0;0;0;-1.572215;-1.584706;35417.95;3925190
3253.782;-0.5006784;0.01425289;38.53142;3.981588;0;0;0;-1.57694;-1.589506;35362;3918801
3268.782;-0.5021247;0.01461654;38.54596;3.98309;0;0;0;-1.581495;-1.594134;35375.35;3920098
3283.782;-0.5036783;0.01475529;38.79855;4.009192;0;0;0;-1.586388;-1.599106;35607.16;3945590
3298.782;-0.5051783;0.01490532;38.65217;3.994066;0;0;0;-1.591113;-1.603907;35472.82;3930516
3313.782;-0.5066783;0.01521165;38.60046;3.988722;0;0;0;-1.595837;-1.608708;35425.36;3925069
3328.782;-0.5081783;0.01520038;38.66779;3.99568;0;0;0;-1.600562;-1.613509;35487.16;3931727
3343.782;-0.5096783;0.01546474;38.60002;3.988677;0;0;0;-1.605286;-1.61831;35424.96;3924647
3358.782;-0.5111248;0.0153999;38.62322;3.991074;0;0;0;-1.609842;-1.622941;35446.25;3926824
3373.782;-0.5126783;0.01581178;38.52344;3.980763;0;0;0;-1.614735;-1.627914;35354.68;3916484
3388.782;-0.5141784;0.01585313;38.63305;3.99209;0;0;0;-1.619459;-1.632716;35455.28;3927440
3403.782;-0.5156783;0.01609118;38.59562;3.988222;0;0;0;-1.624184;-1.637518;35420.92;3923446
3418.782;-0.5171783;0.01619548;38.57521;3.986113;0;0;0;-1.628908;-1.642321;35402.19;3921182
3433.782;-0.5186783;0.01644543;38.3301;3.960785;0;0;0;-1.633633;-1.647123;35177.24;3896080
3448.782;-0.5201783;0.01670258;38.42028;3.970104;0;0;0;-1.638357;-1.651926;35260;3905059
3463.782;-0.5216248;0.01683163;37.95154;3.921667;0;0;0;-1.642913;-1.656558;34829.82;3857237
3478.782;-0.5231248;0.01696099;38.02841;3.92961;0;0;0;-1.647637;-1.661362;34900.37;3864865
3493.782;-0.5246783;0.01728956;37.94455;3.920944;0;0;0;-1.65253;-1.666337;34823.4;3856150
3508.782;-0.5261783;0.0174753;37.94904;3.921408;0;0;0;-1.657255;-1.671141;34827.52;3856421
3523.782;-0.5276783;0.01745118;38.12164;3.939244;0;0;0;-1.661979;-1.675945;34985.93;3873775
3538.782;-0.5291784;0.01770583;37.90632;3.916994;0;0;0;-1.666703;-1.680749;34788.32;3851709
3553.782;-0.5306783;0.01782986;37.69874;3.895544;0;0;0;-1.671428;-1.685554;34597.81;3830433
3568.782;-0.5321783;0.01790786;37.94772;3.921272;0;0;0;-1.676152;-1.690359;34826.31;3855546
3583.782;-0.5336783;0.01810832;37.88326;3.914612;0;0;0;-1.680877;-1.695164;34767.16;3848812
3598.782;-0.5351783;0.01822703;37.75239;3.901088;0;0;0;-1.685601;-1.699969;34647.05;3835331
3613.782;-0.5366247;0.01868402;37.87228;3.913477;0;0;0;-1.690157;-1.704603;34757.08;3847333
3628.782;-0.5381783;0.01847259;37.76539;3.902432;0;0;0;-1.69505;-1.70958;34658.99;3836284
3643.782;-0.5396783;0.01839679;37.8857;3.914863;0;0;0;-1.699774;-1.714386;34769.39;3848320
3658.782;-0.5411783;0.01817253;37.86242;3.912457;0;0;0;-1.704499;-1.719192;34748.03;3845770
3673.782;-0.5426783;0.01788656;37.79253;3.905236;0;0;0;-1.709223;-1.723999;34683.89;3838486
3688.782;-0.5441783;0.0178283;37.82333;3.908419;0;0;0;-1.713947;-1.728805;34712.16;3841430
3703.782;-0.5456783;0.0177691;37.82709;3.908807;0;0;0;-1.718672;-1.733612;34715.61;3841627
3718.782;-0.5471783;0.01778382;37.80692;3.906723;0;0;0;-1.723396;-1.73842;34697.09;3839394
3733.782;-0.5486247;0.01800026;37.75356;3.901209;0;0;0;-1.727952;-1.743055;34648.13;3833798
3748.782;-0.5501783;0.01834699;37.7353;3.899322;0;0;0;-1.732845;-1.748035;34631.36;3831753
3763.782;-0.5516783;0.01839429;37.79526;3.905518;0;0;0;-1.737569;-1.752842;34686.39;3837657
3778.782;-0.5531783;0.01870218;37.96449;3.923005;0;0;0;-1.742294;-1.75765;34841.7;3854654
3793.782;-0.5546783;0.01910686;37.79179;3.90516;0;0;0;-1.747018;-1.762459;34683.21;3836936
3808.782;-0.5561247;0.01944702;37.9392;3.920392;0;0;0;-1.751574;-1.767096;34818.5;3851724
3823.782;-0.5576247;0.01958452;37.85631;3.911826;0;0;0;-1.756298;-1.771904;34742.42;3843123
3838.782;-0.5591783;0.02010948;37.68579;3.894206;0;0;0;-1.761191;-1.776885;34585.93;3825621
3853.782;-0.5606783;0.0205339;37.79564;3.905557;0;0;0;-1.765916;-1.781694;34686.74;3836588
3868.782;-0.5621783;0.02075503;37.84342;3.910494;0;0;0;-1.77064;-1.786504;34730.59;3841253
3883.782;-0.5636783;0.02118226;37.74079;3.899889;0;0;0;-1.775365;-1.791313;34636.4;3830652
3898.782;-0.5651783;0.02159321;37.76683;3.90258;0;0;0;-1.780089;-1.796123;34660.31;3833111
3913.782;-0.5666247;0.02192961;37.76131;3.90201;0;0;0;-1.784645;-1.800762;34655.24;3832373
3928.782;-0.5681783;0.02196657;37.65634;3.891162;0;0;0;-1.789538;-1.805744;34558.9;3821529
3943.782;-0.5696783;0.02217204;37.7363;3.899425;0;0;0;-1.794262;-1.810554;34632.28;3829459
3958.782;-0.5711783;0.02209687;37.77972;3.903913;0;0;0;-1.798987;-1.815365;34672.14;3833682
3973.782;-0.5726783;0.02207901;37.66112;3.891657;0;0;0;-1.803711;-1.820176;34563.29;3821463
3988.782;-0.5741247;0.02213195;37.77858;3.903794;0;0;0;-1.808267;-1.824816;34671.09;3833203
4003.782;-0.5756783;0.02234243;37.4677;3.87167;0;0;0;-1.81316;-1.829799;34385.78;3801470
4018.782;-0.5771783;0.02227321;37.07556;3.831149;0;0;0;-1.817884;-1.834611;34025.9;3761503
4033.782;-0.5786783;0.02261556;36.69477;3.7918;0;0;0;-1.822609;-1.839423;33676.43;3722691
4048.782;-0.5801783;0.02283638;36.44126;3.765605;0;0;0;-1.827333;-1.844235;33443.77;3696795
4063.782;-0.5816783;0.02302369;35.53875;3.672344;0;0;0;-1.832058;-1.849048;32615.49;3605065
4078.782;-0.5831783;0.02334066;34.43408;3.558196;0;0;0;-1.836782;-1.85386;31601.7;3492840
4093.782;-0.5846783;0.02369178;32.76704;3.385934;0;0;0;-1.841506;-1.858673;30071.77;3323582
4108.782;-0.5861783;0.02416851;30.76335;3.178886;0;0;0;-1.846231;-1.863486;28232.9;3120196
4123.782;-0.5876247;0.02475454;29.46586;3.044811;0;0;0;-1.850786;-1.868128;27042.13;2988458
4138.782;-0.5891783;0.02514763;28.02198;2.89561;0;0;0;-1.85568;-1.873113;25717.02;2841877
4153.782;-0.5906247;0.02564096;26.40074;2.728082;0;0;0;-1.860235;-1.877755;24229.13;2677333
4168.782;-0.5921783;0.02603687;24.78094;2.560702;0;0;0;-1.865129;-1.882741;22742.57;2512941
4183.782;-0.5936783;0.02644844;23.12751;2.389848;0;0;0;-1.869853;-1.887556;21225.15;2345161
4198.782;-0.5951783;0.02665579;22.11494;2.285215;0;0;0;-1.874577;-1.89237;20295.86;2242377
4213.782;-0.5966783;0.02679455;21.1317;2.183613;0;0;0;-1.879302;-1.897185;19393.5;2142576
4228.782;-0.5981783;0.02730635;19.9501;2.061515;0;0;0;-1.884026;-1.902;18309.1;2022675
4243.782;-0.5996783;0.02750368;19.15864;1.97973;0;0;0;-1.888751;-1.906815;17582.74;1942338
4258.782;-0.6011783;0.02783788;18.2324;1.884018;0;0;0;-1.893475;-1.911631;16732.69;1848345
4273.782;-0.6026783;0.02796004;17.55649;1.814174;0;0;0;-1.898199;-1.916446;16112.37;1779737
4288.782;-0.6041247;0.02831461;16.78749;1.734711;0;0;0;-1.902755;-1.92109;15406.63;1701704
4303.782;-0.6056783;0.02841264;15.93578;1.6467;0;0;0;-1.907648;-1.926079;14624.97;1615287
4318.782;-0.6071783;0.02886556;15.44463;1.595948;0;0;0;-1.912373;-1.930895;14174.22;1565428
4333.782;-0.6086782;0.02919507;14.71915;1.520982;0;0;0;-1.917097;-1.935711;13508.42;1491823
4346.876;-0.608839;0.02870926;16.21723;1.675784;1;1;0;-1.917603;-1.936228;14883.28;1643649
4361.876;-0.4884104;0.02320128;38.58261;3.986877;1;1;0;-1.538301;-1.550255;35408.98;3925547
4376.876;-0.363482;0.02270984;38.72021;4.001096;1;1;0;-1.144825;-1.151429;35535.26;3955291
4391.876;-0.2384463;0.02234995;38.97198;4.027112;1;1;0;-0.751012;-0.7538463;35766.32;3996869
4406.876;-0.1135178;0.01939847;50.49218;5.217535;1;1;0;-0.3575364;-0.3581771;46338.93;5198881
4421.876;0.01162499;0.01926598;51.11444;5.281836;1;1;0;0.03661415;0.03660745;46910;5283770
4436.876;0.1364999;0.0188068;51.73133;5.345582;1;1;0;0.4299209;0.4289994;47476.15;5368563
4451.876;0.2172856;-0.003679927;171.5477;17.72663;1;1;0;0.684364;0.6820329;157437;1.784795e+007
4466.876;0.2672677;-0.03994146;393.5777;40.66978;1;1;0;0.841788;0.8382647;361203.8;4.101213e+007
4481.876;0.3173569;-0.08101094;660.3582;68.23715;1;1;0;0.9995494;0.9945869;606040.1;6.891921e+007
4496.876;0.3673926;-0.1259061;951.1304;98.28368;1;1;0;1.157142;1.150498;872894.8;9.942096e+007
4511.876;0.417214;-0.1720106;1239.655;128.098;1;1;0;1.31406;1.305501;1137687;1.297812e+008
4526.876;0.4673033;-0.2346068;1541.805;159.3201;1;1;0;1.471821;1.461095;1414983;1.616651e+008
4541.876;0.5173925;-0.3177577;1839.701;190.1028;1;1;0;1.629583;1.616448;1688376;1.932007e+008
4556.876;0.5673211;-0.4195838;2127.404;219.8322;1;1;0;1.786838;1.771062;1952413;2.237602e+008
4571.876;0.617196;-0.5464093;2396.121;247.5997;1;1;0;1.943924;1.925271;2199027;2.524128e+008
4586.876;0.6672853;-0.703484;2644.892;273.3061;1;1;0;2.101686;2.079905;2427336;2.790501e+008
4601.876;0.7172674;-0.887154;2862.698;295.8127;1;1;0;2.25911;2.23397;2627226;3.024955e+008
4616.876;0.7672494;-1.09609;3050.222;315.1902;1;1;0;2.416534;2.387798;2799324;3.228069e+008
4631.876;0.8173387;-1.320669;3208.125;331.5069;1;1;0;2.574295;2.541718;2944239;3.400408e+008
4646.877;0.8673745;-1.558263;3348.828;346.0462;1;1;0;2.731888;2.695238;3073369;3.554998e+008
4661.877;0.9172494;-1.810808;3482.763;359.8862;1;1;0;2.888974;2.84803;3196287;3.702833e+008
4675.047;0.9477316;-1.984544;3481.489;359.7546;1;1;0;2.984982;2.941298;3195118;3.704932e+008
4690.047;0.8979101;-1.802327;2946.412;304.4632;1;1;0;2.828063;2.788812;2704054;3.130736e+008
4705.047;0.847928;-1.575797;2573.813;265.9612;1;1;0;2.67064;2.6356;2362103;2.730641e+008
4720.047;0.7978923;-1.320336;2307.957;238.4894;1;1;0;2.513047;2.481989;2118115;2.444827e+008
4735.047;0.7479102;-1.062893;2065.117;213.3958;1;1;0;2.355623;2.328306;1895250;2.184226e+008
4750.047;0.6979281;-0.8309432;1808.412;186.8696;1;1;0;2.198199;2.174387;1659661;1.909774e+008
4765.047;0.6477853;-0.6377488;1531.461;158.2513;1;1;0;2.040269;2.019734;1405490;1.614801e+008
4780.047;0.5978032;-0.4752801;1257.069;129.8974;1;1;0;1.882845;1.865338;1153669;1.323432e+008
4795.047;0.5479282;-0.3403685;996.1885;102.9397;1;1;0;1.725758;1.711036;914246.6;1.047162e+008
4810.047;0.497839;-0.2281516;750.5793;77.56002;1;1;0;1.567997;1.555831;688840.1;7.877616e+007
4825.047;0.4477497;-0.1453684;516.4863;53.37036;1;1;0;1.410235;1.400384;474002.5;5.4123e+007
4840.047;0.3978748;-0.08679142;304.138;31.42766;1;1;0;1.253149;1.245362;279121;3.182149e+007
4855.047;0.3478926;-0.04151884;132.2902;13.67001;1;1;0;1.095725;1.089765;121408.6;1.38198e+007
4870.047;0.2979105;-0.01467616;50.59854;5.228526;1;1;0;0.9383009;0.9339262;46436.54;5277585
4884.742;0.2489463;-0.01310724;50.23257;5.19071;1;1;0;0.7840827;0.7810247;46100.67;5231409
4898.744;0.2956069;-0.01722703;69.89321;7.222313;2;2;0;0.9310455;0.9267379;64144.12;7289556
4913.744;0.3597855;-0.07790567;364.4837;37.66339;2;2;0;1.133183;1.12681;334503;3.809019e+007
4928.744;0.459964;-0.2011467;958.987;99.09552;2;2;0;1.448705;1.438312;880105.1;1.005311e+008
4943.744;0.5597675;-0.3615369;1604.81;165.8307;2;2;0;1.763047;1.747686;1472806;1.687544e+008
4958.744;0.659946;-0.6090728;2239.552;231.4208;2;2;0;2.07857;2.057263;2055337;2.362311e+008
4973.744;0.7597495;-0.9670228;2765.68;285.7875;2;2;0;2.392912;2.36473;2538188;2.926261e+008
4988.744;0.8598209;-1.428688;3177.566;328.3492;2;2;0;2.708097;2.672077;2916194;3.372412e+008
5003.744;0.9599458;-1.944187;3550.721;366.9085;2;2;0;3.023451;2.978646;3258655;3.780018e+008
5016.682;0.9039637;-1.771359;2859.675;295.5004;2;2;0;2.84713;2.807352;2624452;3.039136e+008
5031.682;0.8039459;-1.283035;2253.151;232.826;2;2;0;2.532113;2.500586;2067817;2.387214e+008
5046.682;0.7040353;-0.8162034;1736.265;179.4144;2;2;0;2.217434;2.193206;1593448;1.833928e+008
5061.682;0.6040175;-0.4781229;1173.968;121.3102;2;2;0;1.902417;1.884548;1077402;1.236181e+008
5076.682;0.5040533;-0.2377377;668.3378;69.06171;2;2;0;1.587569;1.575099;613363.4;7.015811e+007
5091.682;0.4039819;-0.09200842;240.8712;24.89008;2;2;0;1.272384;1.264357;221058.3;2.520677e+007
5106.682;0.3039641;-0.02861071;50.37928;5.205869;2;2;0;0.9573672;0.9528135;46235.31;5255708
5119.768;0.2834998;-0.02827682;50.47532;5.215794;3;3;0;0.8929128;0.8889499;46323.46;5262367
5134.768;0.3833569;-0.09663219;355.9679;36.78342;3;3;0;1.207423;1.200192;326687.6;3.722755e+007
5149.768;0.4834283;-0.230938;943.4346;97.48844;3;3;0;1.522609;1.511133;865832;9.897281e+007
5164.768;0.5834461;-0.4015971;1595.075;164.8248;3;3;0;1.837625;1.820945;1463872;1.678536e+008
5179.768;0.6834639;-0.6588151;2232.053;230.6459;3;3;0;2.152642;2.1298;2048455;2.356109e+008
5194.768;0.7834816;-1.02592;2761.575;285.3633;3;3;0;2.467659;2.437704;2534421;2.924051e+008
5209.768;0.8833387;-1.4949;3186.203;329.2417;3;3;0;2.782169;2.74417;2924121;3.384017e+008
5223.372;0.9740351;-1.954767;3540.543;365.8568;3;3;0;3.067827;3.02171;3249314;3.770807e+008
5238.085;0.8759458;-1.580212;2606.64;269.3534;3;3;0;2.758884;2.721513;2392230;2.767845e+008
5253.085;0.7760888;-1.086011;2060.162;212.8839;3;3;0;2.444374;2.414977;1890703;2.180875e+008
5268.085;0.676071;-0.6789843;1501.293;155.134;3;3;0;2.129358;2.107003;1377804;1.584373e+008
5283.085;0.5759996;-0.3869509;948.3292;97.99421;3;3;0;1.814172;1.797912;870324;9.9772e+007
5298.085;0.476089;-0.181617;475.051;49.0887;3;3;0;1.499493;1.488362;435975.4;4.982478e+007
5313.085;0.3759105;-0.06265715;109.0294;11.26639;3;3;0;1.18397;1.177016;100061.1;1.139978e+007
5328.085;0.276107;-0.03648539;49.80191;5.146207;3;3;0;0.8696283;0.8658688;45705.43;5190960
5341.978;0.3168748;-0.03750054;51.34081;5.305228;4;4;0;0.9980308;0.9930834;47117.75;5358176
5356.978;0.4166783;-0.1345212;475.6393;49.14949;4;4;0;1.312373;1.303836;436515.3;4.979451e+007
5371.978;0.5168032;-0.2781895;1080.495;111.6514;4;4;0;1.627727;1.614621;991618.6;1.134688e+008
5386.978;0.6167139;-0.4685117;1734.68;179.2507;4;4;0;1.942406;1.923782;1591994;1.827324e+008
5401.978;0.7166781;-0.7502642;2353.065;243.1506;4;4;0;2.257254;2.232155;2159513;2.486391e+008
5416.978;0.8168566;-1.141894;2855.503;295.0692;4;4;0;2.572777;2.540238;2620623;3.026607e+008
5431.978;0.9167137;-1.628615;3280.366;338.9719;4;4;0;2.887287;2.84639;3010538;3.487589e+008
5445.306;0.9426958;-1.816091;3139.285;324.3934;4;4;0;2.969121;2.925896;2881062;3.340251e+008
5460.306;0.8425709;-1.372739;2377.77;245.7034;4;4;0;2.653767;2.619165;2182185;2.522238e+008
5475.306;0.7426066;-0.8989944;1840.177;190.152;4;4;0;2.338918;2.311985;1688812;1.945995e+008
5490.306;0.6426424;-0.5519301;1260.752;130.278;4;4;0;2.024071;2.003859;1157049;1.329149e+008
5505.306;0.5426782;-0.3025371;731.2428;75.56191;4;4;0;1.709223;1.69478;671094.1;7.685343e+007
5520.306;0.4426604;-0.1328232;297.9157;30.78469;4;4;0;1.394206;1.384576;273410.5;3.121389e+007
5535.306;0.3425355;-0.04370387;50.33567;5.201363;4;4;0;1.078852;1.073074;46195.29;5257478
5549.182;0.2499641;-0.04194764;49.71837;5.137575;5;5;0;0.7872886;0.7842057;45628.77;5178023
5564.182;0.3500891;-0.06029767;116.1377;12.00092;5;5;0;1.102643;1.096608;106584.7;1.213325e+007
5579.182;0.4501604;-0.1781018;622.285;64.30291;5;5;0;1.417828;1.407871;571098.6;6.521461e+007
5594.182;0.5500711;-0.3297979;1243.136;128.4576;5;5;0;1.732507;1.717671;1140881;1.306832e+008
5609.182;0.6502496;-0.5436367;1900.557;196.3913;5;5;0;2.04803;2.02734;1744226;2.004134e+008
5624.182;0.7499995;-0.8520931;2488.253;257.12;5;5;0;2.362203;2.334735;2283581;2.631937e+008
5639.182;0.8500709;-1.26978;2966.286;306.5168;5;5;0;2.677389;2.642174;2722293;3.147235e+008
5654.182;0.9501958;-1.765936;3391.645;350.4707;5;5;0;2.992743;2.948834;3112664;3.609593e+008
5667.521;0.9092673;-1.651089;2815.548;290.9406;5;5;0;2.863834;2.823593;2583954;2.992726e+008
5682.521;0.8092495;-1.173681;2177.318;224.99;5;5;0;2.548817;2.516876;1998222;2.307246e+008
5697.521;0.709071;-0.7474252;1613.243;166.7021;5;5;0;2.233294;2.208722;1480545;1.704251e+008
5712.521;0.6092674;-0.4462749;1037.595;107.2184;5;5;0;1.918953;1.900773;952247.6;1.092759e+008
5727.521;0.5090889;-0.2298057;542.1301;56.02022;5;5;0;1.60343;1.590711;497537;5.691847e+007
5742.521;0.4092854;-0.09300071;158.3547;16.36335;5;5;0;1.289088;1.28085;145329.2;1.657429e+007
5757.521;0.3092677;-0.04671611;49.99081;5.165728;5;5;0;0.9740714;0.9693579;45878.8;5216046
5771.386;0.2834998;-0.04665222;50.31183;5.198899;6;6;0;0.8929128;0.8889499;46173.41;5245321
5786.386;0.3833569;-0.09349371;234.1168;24.19211;6;6;0;1.207423;1.200192;214859.4;2.448421e+007
5801.386;0.4834283;-0.2248324;785.7068;81.18987;6;6;0;1.522609;1.511133;721078.2;8.242607e+007
5816.386;0.5833925;-0.3876507;1421.643;146.9034;6;6;0;1.837457;1.820779;1304706;1.496027e+008
5831.386;0.6834639;-0.6259714;2069.621;213.8613;6;6;0;2.152642;2.1298;1899383;2.184649e+008
5846.386;0.7834816;-0.9657342;2628.165;271.5776;6;6;0;2.467659;2.437704;2411985;2.782792e+008
5861.386;0.8833387;-1.410554;3087.907;319.0844;6;6;0;2.782169;2.74417;2833910;3.279618e+008
5874.992;0.9740351;-1.856575;3473.569;358.9362;6;6;0;3.067827;3.02171;3187849;3.699477e+008
5889.74;0.8757316;-1.474586;2546.038;263.0911;6;6;0;2.75821;2.720857;2336612;2.703477e+008
5904.74;0.7758209;-0.9945001;1975.147;204.0989;6;6;0;2.44353;2.414154;1812680;2.090861e+008
5919.74;0.6758032;-0.623459;1387.492;143.3745;6;6;0;2.128514;2.106177;1273364;1.464262e+008
5934.74;0.5757853;-0.3595231;831.4488;85.91654;6;6;0;1.813497;1.797249;763057.6;8.747464e+007
5949.74;0.4758211;-0.1731451;376.8899;38.94537;6;6;0;1.498649;1.48753;345888.7;3.952903e+007
5964.74;0.3756962;-0.05882866;66.47263;6.868853;6;6;0;1.183295;1.176349;61004.9;6950131
5979.74;0.2758391;-0.04927324;49.67561;5.133157;6;6;0;0.8687845;0.8650324;45589.53;5177753
5993.596;0.3168748;-0.05004001;50.68314;5.237268;7;7;0;0.9980308;0.9930834;46514.18;5289537
6008.596;0.4167319;-0.1320386;377.9121;39.05099;7;7;0;1.312541;1.304002;346826.8;3.956356e+007
6023.596;0.5168032;-0.2713951;968.1823;100.0457;7;7;0;1.627727;1.614621;888544.1;1.016742e+008
6038.596;0.6167139;-0.4530129;1610.014;166.3684;7;7;0;1.942406;1.923782;1477582;1.696e+008
6053.596;0.7166781;-0.7185537;2240.504;231.5193;7;7;0;2.257254;2.232155;2056211;2.367452e+008
6068.596;0.8169102;-1.087972;2767.725;285.9988;7;7;0;2.572945;2.540402;2540065;2.933574e+008
6083.596;0.9167137;-1.558742;3215.071;332.2247;7;7;0;2.887287;2.84639;2950614;3.418169e+008
6096.954;0.9424816;-1.736121;3090.825;319.3859;7;7;0;2.968446;2.92524;2836588;3.288667e+008
6111.954;0.842303;-1.290063;2328.589;240.6214;7;7;0;2.652923;2.618343;2137051;2.470049e+008
6126.954;0.7423924;-0.8381613;1764.241;182.3053;7;7;0;2.338244;2.311326;1619123;1.865681e+008
6141.954;0.6423746;-0.5158177;1170.589;120.9611;7;7;0;2.023227;2.003032;1074301;1.234084e+008
6156.954;0.5424639;-0.2855718;645.1981;66.6706;7;7;0;1.708548;1.694116;592127;6.78097e+007
6171.954;0.4424997;-0.1282289;234.0576;24.186;7;7;0;1.3937;1.384077;214805.1;2.452308e+007
6186.954;0.3423212;-0.05265477;50.42819;5.210924;7;7;0;1.078177;1.072406;46280.2;5267107
6200.801;0.2499641;-0.05145357;49.8343;5.149554;8;8;0;0.7872886;0.7842057;45735.16;5190096
6215.801;0.3500891;-0.05843024;72.09023;7.449338;8;8;0;1.102643;1.096608;66160.41;7531478
6230.801;0.4501604;-0.1748502;541.3129;55.93578;8;8;0;1.417828;1.407871;496787;5.672885e+007
6245.801;0.5500711;-0.3212758;1151.182;118.9557;8;8;0;1.732507;1.717671;1056491;1.210166e+008
6260.801;0.6502496;-0.5270278;1805.017;186.5188;8;8;0;2.04803;2.02734;1656544;1.903387e+008
6275.801;0.749946;-0.8210194;2406.258;248.6472;8;8;0;2.362035;2.33457;2208331;2.545203e+008
6290.801;0.8500709;-1.221313;2904.318;300.1134;8;8;0;2.677389;2.642174;2665422;3.081486e+008
6305.801;0.9501958;-1.706838;3348.347;345.9966;8;8;0;2.992743;2.948834;3072928;3.563514e+008
6319.317;0.9917136;-1.954805;3314.799;342.5299;8;8;0;3.123507;3.075719;3042139;3.532289e+008
6334.317;0.8917494;-1.530881;2510.806;259.4505;8;8;0;2.80866;2.76994;2304279;2.667376e+008
6349.317;0.791678;-1.032489;1972.558;203.8314;8;8;0;2.493474;2.462894;1810304;2.089139e+008
6364.317;0.6916602;-0.6539959;1397.288;144.3867;8;8;0;2.178457;2.155068;1282353;1.475321e+008
6379.317;0.5917496;-0.386151;843.6568;87.17805;8;8;0;1.863778;1.846623;774261.5;8.880285e+007
6394.317;0.4917318;-0.1941183;390.5798;40.35999;8;8;0;1.548762;1.536891;358452.5;4.098507e+007
6409.317;0.391714;-0.07138974;76.81344;7.937405;8;8;0;1.233745;1.226196;70495.13;8035332
6424.317;0.2916427;-0.05653996;49.92136;5.158551;8;8;0;0.9185596;0.9143665;45815.06;5205936
6437.556;0.2968391;-0.05716421;50.41598;5.209662;9;9;0;0.9349263;0.930583;46268.99;5258368
6452.556;0.3966962;-0.1074637;237.0923;24.49959;9;9;0;1.249437;1.241696;217590.2;2.480569e+007
6467.556;0.4968747;-0.2407177;785.8744;81.20718;9;9;0;1.56496;1.55284;721232;8.247804e+007
6482.556;0.5966782;-0.4066413;1410.864;145.7896;9;9;0;1.879301;1.861861;1294813;1.485294e+008
6497.556;0.6967496;-0.6472328;2058.799;212.743;9;9;0;2.194487;2.170755;1889452;2.174116e+008
6512.556;0.7968745;-0.9867212;2616.986;270.4224;9;9;0;2.509841;2.478862;2401725;2.772096e+008
6527.556;0.896678;-1.431192;3085.472;318.8327;9;9;0;2.824183;2.785038;2831675;3.278371e+008
6542.556;0.9968565;-1.915914;3517.389;363.4642;9;9;0;3.139705;3.091425;3228064;3.748759e+008
6555.99;0.9438209;-1.753642;2861.815;295.7215;9;9;0;2.972664;2.929337;2626415;3.045123e+008
6570.99;0.8440173;-1.265028;2233.766;230.823;9;9;0;2.658322;2.623603;2050027;2.36959e+008
6585.99;0.7438924;-0.8233946;1677.619;173.3543;9;9;0;2.342968;2.315942;1539625;1.774159e+008
6600.99;0.6440352;-0.5105236;1097.449;113.4033;9;9;0;2.028457;2.008158;1007178;1.157037e+008
6615.99;0.5440175;-0.2847797;591.2247;61.09335;9;9;0;1.713441;1.698927;542593.3;6.214014e+007
6630.99;0.443839;-0.1286583;199.5931;20.62466;9;9;0;1.397918;1.388237;183175.5;2.091298e+007
6645.99;0.3440355;-0.06110327;50.31024;5.198735;9;9;0;1.083576;1.077748;46171.95;5255067
6659.563;0.2499641;-0.05980779;49.92098;5.158512;10;10;0;0.7872886;0.7842057;45814.71;5199124
6674.563;0.3751605;-0.08286301;123.1902;12.72968;10;10;0;1.181608;1.174681;113057.2;1.28801e+007
6689.563;0.5001425;-0.2443977;773.5545;79.93413;10;10;0;1.575252;1.562974;709925.4;8.119329e+007
6704.563;0.625071;-0.4653685;1569.68;162.2006;10;10;0;1.968727;1.949599;1440565;1.653939e+008
6719.563;0.749946;-0.813038;2349.531;242.7854;10;10;0;2.362035;2.33457;2156270;2.4852e+008
6734.563;0.8751958;-1.323435;2982.429;308.1849;10;10;0;2.756522;2.719214;2737108;3.166801e+008
6749.563;1.000178;-1.929356;3535.48;365.3336;10;10;0;3.150167;3.101567;3244667;3.768422e+008
6761.937;0.9269459;-1.677451;2738.026;282.9299;10;10;0;2.919515;2.877708;2512809;2.911901e+008
6776.937;0.8020173;-1.063344;2007.301;207.4215;10;10;0;2.526039;2.494662;1842189;2.12661e+008
6791.937;0.6770888;-0.6027405;1280.14;132.2814;10;10;0;2.132563;2.110142;1174842;1.351024e+008
6806.937;0.5521068;-0.3018477;614.7738;63.52675;10;10;0;1.738919;1.723973;564205.3;6.463143e+007
6821.937;0.4269104;-0.1084556;138.4073;14.30212;10;10;0;1.3446;1.33564;127022.6;1.449443e+007
6836.937;0.3020355;-0.06358867;50.08959;5.175935;10;10;0;0.9512929;0.9467967;45969.45;5225173
6850.187;0.4084283;-0.1133284;217.6489;22.49043;11;11;0;1.286388;1.278185;199746.1;2.277975e+007
6865.187;0.5332497;-0.2893323;924.8789;95.57101;11;11;0;1.679526;1.665578;848802.6;9.717615e+007
6880.187;0.6581782;-0.5359935;1739.554;179.7543;11;11;0;2.073002;2.051808;1596466;1.834806e+008
6895.187;0.7833745;-0.9202417;2495.646;257.8839;11;11;0;2.467321;2.437374;2290366;2.642468e+008
6910.187;0.9084101;-1.468624;3109.715;321.3379;11;11;0;2.861134;2.820968;2853924;3.305318e+008
6923.731;1.009339;-1.971591;3506.754;362.3653;11;11;0;3.179019;3.129535;3218305;3.73885e+008
6937.591;0.8935708;-1.502204;2496.318;257.9534;11;11;0;2.814396;2.77552;2290982;2.652132e+008
6952.591;0.7686959;-0.9073233;1798.356;185.8305;11;11;0;2.421089;2.392246;1650431;1.903296e+008
6967.591;0.6437139;-0.503682;1064.134;109.9608;11;11;0;2.027445;2.007166;976603.6;1.121902e+008
6982.591;0.5185175;-0.2354133;448.0373;46.29728;11;11;0;1.633126;1.619934;411183.8;4.705338e+007
6997.591;0.3935354;-0.0730686;60.58037;6.259984;11;11;0;1.239482;1.231863;55597.3;6337575
7010.826;0.3167677;-0.06636349;50.17692;5.184959;12;12;0;0.9976934;0.9927493;46049.6;5236689
7025.826;0.441589;-0.154967;360.3967;37.24107;12;12;0;1.390831;1.381248;330752.2;3.775903e+007
7040.826;0.5665175;-0.3420223;1108.273;114.5218;12;12;0;1.784307;1.768575;1017112;1.165652e+008
7055.826;0.6917138;-0.6197267;1933.19;199.7634;12;12;0;2.178626;2.155233;1774175;2.041155e+008
7070.826;0.8167495;-1.042446;2651.584;273.9976;12;12;0;2.572439;2.539909;2433477;2.81046e+008
7085.826;0.9416245;-1.622398;3247.217;335.5464;12;12;0;2.965746;2.922619;2980116;3.454979e+008
7098.457;0.9834636;-1.87548;3198.24;330.4855;12;12;0;3.097523;3.050518;2935168;3.407223e+008
7113.24;0.860303;-1.318873;2296.744;237.3307;12;12;0;2.709616;2.673556;2107824;2.437614e+008
7128.24;0.7353209;-0.774239;1586.812;163.9709;12;12;0;2.315971;2.28956;1456288;1.677684e+008
7143.24;0.6101782;-0.4175385;864.6076;89.34296;12;12;0;1.921821;1.903587;793488.9;9.105997e+007
7158.24;0.4851426;-0.1822006;304.3935;31.45406;12;12;0;1.528008;1.516452;279355.5;3.193468e+007
7173.24;0.3603212;-0.06924606;50.48061;5.216341;12;12;0;1.13487;1.128479;46328.31;5275539
7186.47;0.3499819;-0.06908914;50.93823;5.263627;13;13;0;1.102305;1.096274;46748.28;5321648
7201.47;0.4748568;-0.2014411;524.8776;54.23746;13;13;0;1.495612;1.484538;481703.6;5.504864e+007
7216.47;0.5999996;-0.4032062;1306.848;135.0413;13;13;0;1.889763;1.872128;1199353;1.375932e+008
7231.47;0.7250888;-0.7142664;2122.815;219.358;13;13;0;2.283744;2.258057;1948202;2.243676e+008
7246.47;0.8499637;-1.177686;2804.527;289.8017;13;13;0;2.677051;2.641845;2573839;2.975598e+008
7261.47;0.9748386;-1.77469;3384.519;349.7343;13;13;0;3.070358;3.024166;3106124;3.604724e+008
7273.365;1.026053;-2.072969;3404.92;351.8425;13;13;0;3.231663;3.180543;3124847;3.632128e+008
7287.905;0.9050351;-1.549139;2470.855;255.3222;13;13;0;2.850504;2.810633;2267614;2.626002e+008
7302.905;0.7799459;-0.9412096;1794.389;185.4205;13;13;0;2.456522;2.426835;1646790;1.899754e+008
7317.905;0.6550174;-0.5300194;1072.796;110.8558;13;13;0;2.063047;2.042054;984552.3;1.131428e+008
7332.905;0.5299818;-0.2558519;458.2494;47.35253;13;13;0;1.669234;1.655455;420555.9;4.814296e+007
7347.905;0.4050533;-0.0836044;66.76736;6.899308;13;13;0;1.275758;1.267689;61275.39;6987326
7361.507;0.3081962;-0.07324432;50.26942;5.194518;14;14;0;0.9706967;0.9660157;46134.49;5244940
7376.507;0.4331783;-0.1441762;285.3679;29.48807;14;14;0;1.364341;1.355118;261894.8;2.989039e+007
7391.507;0.5584282;-0.3293118;1014.86;104.869;14;14;0;1.758829;1.743541;931382;1.067135e+008
7406.507;0.6833032;-0.5953149;1830.36;189.1376;14;14;0;2.152136;2.129304;1679803;1.932081e+008
7421.507;0.8082852;-1.001843;2565.826;265.1359;14;14;0;2.54578;2.513915;2354773;2.718856e+008
7436.507;0.9332137;-1.567613;3177.166;328.3079;14;14;0;2.939256;2.896888;2915827;3.379577e+008
7451.507;1.05841;-2.174959;3724.561;384.872;14;14;0;3.333575;3.279216;3418196;3.977021e+008
7463.505;0.9872136;-1.950743;2903.187;299.9966;14;14;0;3.109334;3.061974;2664385;3.093245e+008
7478.505;0.8621244;-1.319249;2182.26;225.5007;14;14;0;2.715353;2.679141;2002757;2.316238e+008
7493.505;0.7372495;-0.7823361;1498.503;154.8457;14;14;0;2.322046;2.295496;1375244;1.584413e+008
7508.505;0.6122675;-0.4281479;804.5515;83.13715;14;14;0;1.928401;1.910043;738372.8;8.474037e+007
7523.505;0.4872318;-0.1886301;270.7551;27.97808;14;14;0;1.534588;1.522933;248484;2.840743e+007
7538.505;0.362089;-0.08056773;50.37963;5.205905;14;14;0;1.140438;1.133984;46235.63;5265275
7553.505;0.2372677;-0.07913068;49.79877;5.145883;14;14;0;0.7472998;0.7445214;45702.55;5184338
7568.395;0.1132499;-0.07842436;49.46836;5.111741;14;14;0;0.3566927;0.356058;45399.32;5129974