File: Ensayos/Resistencia/comp/Clavo6/Clavo6b.raw
"Test Type";"Manual"
"Method Name:";"C:\INSTRON\user\template\CYCLE.MTM"
"Name:";""
"Operator ID:";""
"Company:";""
"Lab name:";""
"Test date:";"05/06/2017"
"Temperature:";""
"Humidity:";""
"Note 1:";""
"Note 2:";""
"Note 3:";""
"Geometry:";"Rectangular"
"Specimen";1
"Specimen name:";""
"Width:";0.250000;"in"
"Thickness:";0.060000;"in"
"Length:";1.250000;"in"
"Diameter:";0.039370;"in"
"Inner diameter:";0.019685;"in"
"Outer diameter:";0.039370;"in"
"Wall thickness:";0.019685;"in"
"Area:";0.015000;"in*in"
"Linear density:";1.000000;"den"
"Sled weight:";2.204623;"lbf"
"Loading span:";0.000000;"mm"
"Support span:";1.000000;"mm"
"Span ratio:";"2"
"Fixture type:";"3-point"
"Comment:";""
"Included"
"Final Width:";0.250000;"in"
"Final Thickness:";0.060000;"in"
"Final Length:";1.250000;"in"
"Final Diameter:";0.039370;"in"
"Final Inner diameter:";0.019685;"in"
"Final Outer diameter:";0.039370;"in"
"Final Wall thickness:";0.019685;"in"
"Final Area:";0.015000;"in*in"
"Final Linear density:";1.000000;"den"
"Time sec";"Extension mm";"Strain 1 %";"Load N";"Stress MPa";"Cycle Count ";"Total Cycle Count ";"Repetitions Count ";"Strain [Exten.] %";"True strain %";"Tenacity gf/tex";"True stress Pa"
0;0;0.001510713;55.32841;5.71728;0;0;0;0;0;50777.35;5717280
21;0.0003749997;0.003172739;55.16209;5.700094;0;0;0;0.001181102;0.001181095;50624.71;5700161
42;0.0007499995;0.004679447;55.60593;5.745958;0;0;0;0.002362203;0.002362175;51032.04;5746094
63;0.001071428;0.005866396;55.28292;5.71258;0;0;0;0.003374576;0.003374519;50735.6;5712773
84.00001;0.001392856;0.007884123;55.29361;5.713685;0;0;0;0.004386948;0.004386852;50745.41;5713935
105;0.001767856;0.008422588;55.2688;5.711121;0;0;0;0.00556805;0.005567895;50722.64;5711439
126;0.002142856;0.009966021;55.15704;5.699572;0;0;0;0.006749152;0.006748924;50620.07;5699957
147;0.002464284;0.01074543;55.25823;5.710028;0;0;0;0.007761525;0.007761224;50712.94;5710471
168;0.002839284;0.01232124;55.25685;5.709886;0;0;0;0.008942626;0.008942227;50711.67;5710396
189;0.003214284;0.01287228;55.2868;5.712981;0;0;0;0.01012373;0.01012322;50739.16;5713559
210;0.003535712;0.013739;55.26789;5.711027;0;0;0;0.0111361;0.01113548;50721.8;5711662
231;0.00385714;0.01551108;55.18226;5.702178;0;0;0;0.01214847;0.01214774;50643.22;5702871
252;0.00423214;0.01683949;55.13786;5.697591;0;0;0;0.01332957;0.01332869;50602.48;5698350
273;0.004553569;0.0178277;55.29385;5.713709;0;0;0;0.01434195;0.01434092;50745.63;5714528
294;0.00498214;0.01858346;55.20452;5.704479;0;0;0;0.01569178;0.01569055;50663.65;5705374
315;0.005249997;0.01911734;55.15936;5.699811;0;0;0;0.01653542;0.01653406;50622.2;5700754
336;0.005678568;0.02046298;55.36373;5.720931;0;0;0;0.01788525;0.01788365;50809.77;5721954
357;0.006053567;0.02075662;55.27479;5.71174;0;0;0;0.01906635;0.01906453;50728.14;5712829
378;0.006321425;0.02148016;55.27024;5.711269;0;0;0;0.01991;0.01990802;50723.96;5712406
399;0.006642853;0.02114787;55.31287;5.715675;0;0;0;0.02092237;0.02092018;50763.09;5716871
420;0.006964281;0.02123045;55.36265;5.720819;0;0;0;0.02193474;0.02193234;50808.77;5722073
441;0.007392853;0.02152143;55.38981;5.723625;0;0;0;0.02328457;0.02328186;50833.7;5724958
462;0.007714281;0.02093042;55.21351;5.705407;0;0;0;0.02429695;0.024294;50671.9;5706793
483;0.008035709;0.02076684;55.13813;5.697618;0;0;0;0.02530932;0.02530612;50602.71;5699060
504;0.008410709;0.02094718;55.14688;5.698522;0;0;0;0.02649042;0.02648691;50610.75;5700032
525;0.008785709;0.02031972;55.11011;5.694723;0;0;0;0.02767153;0.0276677;50577.01;5696299
546;0.009107137;0.02033472;55.19818;5.703823;0;0;0;0.0286839;0.02867978;50657.83;5705459
567;0.009482137;0.02033413;55.20129;5.704144;0;0;0;0.029865;0.02986054;50660.68;5705848
588;0.009857137;0.02101789;55.13108;5.696889;0;0;0;0.0310461;0.03104128;50596.25;5698658
609;0.01017856;0.02106229;55.33405;5.717863;0;0;0;0.03205847;0.03205333;50782.52;5719696
630;0.04060711;0.02075607;55.61915;5.747323;0;0;0;0.1278964;0.1278147;51044.17;5754674
651.0001;0.07553567;0.01966994;56.3061;5.818308;0;0;0;0.2379076;0.2376251;51674.62;5832151
672.0001;0.1104642;0.009594816;103.2908;10.6734;0;0;0;0.3479188;0.347315;94794.57;1.071054e+007
693.0001;0.1454999;-0.002055811;171.5053;17.72225;0;0;0;0.4582674;0.4572205;157398.1;1.780347e+007
714.0001;0.1805356;-0.01531917;247.123;25.53609;0;0;0;0.568616;0.5670055;226795.8;2.56813e+007
735.0001;0.2154642;-0.02849581;332.674;34.37639;0;0;0;0.6786273;0.6763349;305309.8;3.460967e+007
756.0001;0.2503927;-0.04667364;431.9235;44.63219;0;0;0;0.7886384;0.7855449;396395.5;4.498417e+007
777.0001;0.2855355;-0.06851443;541.0927;55.91302;0;0;0;0.8993245;0.8953047;496584.9;5.641586e+007
798.0001;0.3205176;-0.0956827;653.8006;67.55953;0;0;0;1.009504;1.004443;600022;6.824155e+007
819.0001;0.3553926;-0.1311932;766.2819;79.18262;0;0;0;1.119347;1.113129;703251;8.006895e+007
840.0001;0.3674997;-0.1385895;768.6053;79.42271;0;0;0;1.15748;1.150832;705383.3;8.0342e+007
861.0001;0.3760176;-0.1426001;779.4348;80.54176;0;0;0;1.184307;1.177349;715322.1;8.149562e+007
882.0001;0.3863569;-0.1526228;802.8736;82.96378;0;0;0;1.216872;1.209528;736832.9;8.397334e+007
903.0001;0.3915533;-0.1540267;798.0436;82.46468;0;0;0;1.233239;1.225696;732400.3;8.348166e+007
924.0001;0.3967497;-0.1558037;800.1792;82.68535;0;0;0;1.249606;1.241862;734360.1;8.371859e+007
945.0001;0.4011426;-0.1578173;798.8226;82.54517;0;0;0;1.263441;1.255526;733115.1;8.358808e+007
966.0001;0.4053212;-0.1598545;798.6337;82.52565;0;0;0;1.276602;1.268522;732941.8;8.357917e+007
987.0001;0.4098212;-0.163156;802.0189;82.87545;0;0;0;1.290775;1.282516;736048.5;8.394519e+007
1008;0.4139997;-0.1628913;805.333;83.21791;0;0;0;1.303936;1.295508;739090.1;8.430302e+007
1029;0.4170533;-0.16249;804.6789;83.15032;0;0;0;1.313554;1.305001;738489.7;8.424254e+007
1050;0.4198926;-0.1651152;803.815;83.06105;0;0;0;1.322496;1.313828;737696.9;8.415953e+007
1071;0.4226783;-0.1675365;801.7772;82.85047;0;0;0;1.33127;1.322487;735826.6;8.395343e+007
1092;0.425464;-0.1709401;800.8553;82.75521;0;0;0;1.340044;1.331145;734980.6;8.386417e+007
1113;0.4282497;-0.1760889;800.5648;82.7252;0;0;0;1.348818;1.339802;734714.1;8.384101e+007
1134;0.431089;-0.1819071;800.8229;82.75186;0;0;0;1.357761;1.348626;734950.9;8.387544e+007
1155;0.4338212;-0.1905008;799.2767;82.59209;0;0;0;1.366366;1.357115;733531.9;8.37206e+007
1176;0.4366604;-0.1998955;799.7824;82.64434;0;0;0;1.375309;1.365937;733995.9;8.378096e+007
1197;0.4394997;-0.2120833;798.4289;82.50448;0;0;0;1.384251;1.374758;732753.8;8.364655e+007
1218;0.4422854;-0.2258858;796.1994;82.27411;0;0;0;1.393025;1.383412;730707.8;8.342021e+007
1239;0.445714;-0.2437439;799.6046;82.62598;0;0;0;1.403824;1.394061;733832.8;8.37859e+007
1260;0.4499461;-0.2676673;802.5726;82.93267;0;0;0;1.417153;1.407205;736556.7;8.410796e+007
1281;0.4538568;-0.2933571;803.2454;83.00219;0;0;0;1.42947;1.41935;737174.1;8.418868e+007
1302;0.4575533;-0.3192212;806.3567;83.32369;0;0;0;1.441113;1.430827;740029.5;8.452448e+007
1323;0.4603926;-0.3460697;803.9336;83.07331;0;0;0;1.450055;1.439643;737805.8;8.427792e+007
1344;0.4632854;-0.3778661;798.058;82.46616;0;0;0;1.459167;1.448623;732413.4;8.366948e+007
1365;0.4674104;-0.4176581;792.4785;81.88961;0;0;0;1.472159;1.461428;727292.9;8.309515e+007
1386;0.4736783;-0.4716113;792.304;81.87158;0;0;0;1.4919;1.480881;727132.8;8.309302e+007
1407;0.4812854;-0.5355166;792.0322;81.8435;0;0;0;1.515859;1.504485;726883.3;8.308413e+007
1428;0.4911425;-0.6138486;794.3333;82.08128;0;0;0;1.546906;1.535063;728995.1;8.3351e+007
1449;0.501964;-0.7030332;785.6356;81.18251;0;0;0;1.580989;1.568621;721012.8;8.2466e+007
1470;0.5187318;-0.8228409;785.5377;81.17239;0;0;0;1.633801;1.620598;720922.9;8.249858e+007
1491;0.5453568;-0.9925838;795.5494;82.20693;0;0;0;1.717659;1.703074;730111.1;8.361897e+007
1512;0.5750889;-1.176623;791.0059;81.73744;0;0;0;1.811304;1.795095;725941.4;8.321795e+007
1533;0.6118924;-1.391406;790.1085;81.64471;0;0;0;1.92722;1.908884;725117.8;8.321819e+007
1554;0.6582317;-1.628776;813.5669;84.06874;0;0;0;2.073171;2.051973;746646.6;8.581163e+007
1575;0.6908567;-1.796256;791.3605;81.77409;0;0;0;2.175927;2.152591;726266.8;8.355343e+007
1596;0.7250353;-1.961097;805.064;83.19011;0;0;0;2.283576;2.257892;738843.1;8.508982e+007
1617;0.7509638;-2.090678;809.4602;83.64439;0;0;0;2.36524;2.337702;742877.7;8.562278e+007
1638;0.7701959;-2.195996;814.9291;84.20951;0;0;0;2.425814;2.396858;747896.8;8.625228e+007
1659;0.7791424;-2.264926;793.9349;82.04011;0;0;0;2.453992;2.424365;728629.5;8.405336e+007
1680;0.7902852;-2.331891;817.2256;84.44681;0;0;0;2.489087;2.458614;750004.3;8.654876e+007
1701;0.7944638;-2.376896;813.2206;84.03296;0;0;0;2.502248;2.471455;746328.8;8.613567e+007
1722;0.7972494;-2.413284;820.1299;84.74693;0;0;0;2.511022;2.480014;752669.8;8.687494e+007
1742.662;0.7982138;-2.440218;831.4243;85.91402;0;0;0;2.514059;2.482977;763035.1;8.807394e+007
1762.664;0.7967138;-2.46044;834.5877;86.2409;0;0;0;2.509335;2.478368;765938.3;8.840497e+007
1783.664;0.7908209;-2.469071;807.9863;83.49208;0;0;0;2.490775;2.46026;741525.1;8.557168e+007
1804.664;0.7891066;-2.484968;822.89;85.03214;0;0;0;2.485375;2.454992;755202.9;8.714551e+007
1825.664;0.7864281;-2.497106;836.7637;86.46576;0;0;0;2.476939;2.44676;767935.4;8.860746e+007
1846.664;0.7793566;-2.500235;813.3269;84.04395;0;0;0;2.454667;2.425024;746426.3;8.610694e+007
1867.664;0.7727138;-2.503991;800.6361;82.73257;0;0;0;2.433744;2.4046;734779.5;8.474607e+007
1888.664;0.7682138;-2.511407;808.0124;83.49478;0;0;0;2.419571;2.390763;741549;8.5515e+007
1909.664;0.7631246;-2.516624;810.367;83.7381;0;0;0;2.403542;2.375111;743709.9;8.575077e+007
1930.664;0.7568031;-2.520068;804.0599;83.08636;0;0;0;2.383632;2.355667;737921.6;8.506683e+007
1951.664;0.7507495;-2.523395;800.3899;82.70712;0;0;0;2.364565;2.337043;734553.6;8.466279e+007
1972.664;0.7449638;-2.528205;801.5017;82.82201;0;0;0;2.346343;2.319239;735573.8;8.476529e+007
1993.664;0.7387495;-2.530663;799.042;82.56784;0;0;0;2.32677;2.300114;733316.5;8.4489e+007
2014.664;0.7331781;-2.534261;802.4853;82.92365;0;0;0;2.309222;2.282964;736476.6;8.483854e+007
2035.664;0.727821;-2.538805;805.3602;83.22072;0;0;0;2.292349;2.26647;739114.9;8.512843e+007
2056.664;0.7223566;-2.540294;809.8345;83.68307;0;0;0;2.275139;2.249644;743221.3;8.558697e+007
2077.664;0.7163567;-2.537363;794.6695;82.11601;0;0;0;2.256242;2.231165;729303.6;8.396875e+007
2098.664;0.7121781;-2.538941;789.5431;81.58628;0;0;0;2.243081;2.218293;724598.9;8.341633e+007
2119.664;0.709821;-2.54343;801.4477;82.81643;0;0;0;2.235656;2.211032;735524.3;8.466792e+007
2140.664;0.7058567;-2.544816;791.8669;81.82641;0;0;0;2.223171;2.198819;726731.6;8.364555e+007
2161.664;0.7033924;-2.547147;796.7135;82.32723;0;0;0;2.215409;2.191226;731179.6;8.415111e+007
2182.664;0.7012496;-2.54902;801.6308;82.83535;0;0;0;2.20866;2.184623;735692.3;8.46649e+007
2203.664;0.6989996;-2.553137;802.2347;82.89776;0;0;0;2.201573;2.177689;736246.6;8.472281e+007
2224.664;0.6967496;-2.551602;801.367;82.80809;0;0;0;2.194487;2.170755;735450.3;8.46253e+007
2245.664;0.6943924;-2.556038;797.6906;82.4282;0;0;0;2.187063;2.16349;732076.3;8.423095e+007
2266.664;0.6923567;-2.553659;795.8401;82.23698;0;0;0;2.180651;2.157215;730378;8.403028e+007
2287.664;0.6908567;-2.55626;798.1003;82.47054;0;0;0;2.175927;2.152591;732452.3;8.426503e+007
2308.664;0.6894638;-2.557324;800.0411;82.67108;0;0;0;2.17154;2.148298;734233.4;8.446631e+007
2329.664;0.688071;-2.559406;800.4193;82.71017;0;0;0;2.167153;2.144004;734580.5;8.450262e+007
2350.664;0.6866782;-2.556733;800.0962;82.67677;0;0;0;2.162766;2.13971;734283.9;8.446488e+007
2371.664;0.6852853;-2.561222;798.6846;82.53091;0;0;0;2.158379;2.135416;732988.4;8.431223e+007
2392.664;0.6844282;-2.557741;801.28;82.7991;0;0;0;2.155679;2.132773;735370.4;8.458399e+007
2413.664;0.6834639;-2.558657;801.6557;82.83792;0;0;0;2.152642;2.1298;735715.1;8.462112e+007
2434.664;0.6823924;-2.562032;799.8682;82.65321;0;0;0;2.149267;2.126496;734074.7;8.442965e+007
2455.664;0.681321;-2.55757;797.0095;82.35782;0;0;0;2.145893;2.123193;731451.2;8.412513e+007
2476.664;0.6806781;-2.558033;796.7201;82.32791;0;0;0;2.143868;2.121211;731185.6;8.409291e+007
2497.664;0.6803567;-2.557647;797.2262;82.38021;0;0;0;2.142856;2.120219;731650.1;8.41455e+007
2516.67;0.6802496;-2.557955;797.5257;82.41116;1;1;0;2.142518;2.119889;731924.9;8.417683e+007
2537.67;0.6806246;-2.556996;799.4769;82.61279;1;1;0;2.143699;2.121045;733715.6;8.438375e+007
2556.494;0.680571;-2.555926;795.8979;82.24295;2;2;0;2.143531;2.12088;730431;8.400585e+007
2577.494;0.6812139;-2.556008;797.4144;82.39965;2;2;0;2.145555;2.122862;731822.8;8.416758e+007
2598.494;0.6821246;-2.555127;799.3992;82.60475;2;2;0;2.148424;2.125671;733644.3;8.437945e+007
2619.494;0.6830353;-2.554419;799.9804;82.66481;2;2;0;2.151292;2.128478;734177.7;8.444317e+007
2640.494;0.6838924;-2.552194;798.956;82.55895;2;2;0;2.153992;2.131121;733237.6;8.433727e+007
2661.494;0.6847495;-2.550034;794.5902;82.10782;2;2;0;2.156692;2.133764;729230.9;8.387863e+007
2682.494;0.6860353;-2.549342;793.5914;82.00461;2;2;0;2.160741;2.137728;728314.2;8.377651e+007
2703.494;0.6877496;-2.549694;794.1413;82.06143;2;2;0;2.16614;2.143013;728818.9;8.3839e+007
2724.494;0.6894638;-2.551961;793.3845;81.98323;2;2;0;2.17154;2.148298;728124.4;8.376353e+007
2745.494;0.6920353;-2.555285;800.3052;82.69836;2;2;0;2.179639;2.156224;734475.8;8.450089e+007
2766.494;0.6936424;-2.555985;796.7484;82.33083;2;2;0;2.1847;2.161178;731211.6;8.412951e+007
2787.494;0.6949817;-2.555498;789.1238;81.54295;2;2;0;2.188919;2.165306;724214.1;8.332786e+007
2808.494;0.6977138;-2.556641;796.2165;82.27587;2;2;0;2.197524;2.173726;730723.4;8.408391e+007
2829.494;0.7001781;-2.5551;800.858;82.7555;2;2;0;2.205286;2.181321;734983.1;8.458049e+007
2850.494;0.7022674;-2.552762;804.5073;83.13259;2;2;0;2.211866;2.187759;738332.3;8.497137e+007
2871.494;0.7039281;-2.549149;804.2195;83.10285;2;2;0;2.217096;2.192876;738068.1;8.494532e+007
2892.494;0.7053209;-2.541578;805.1424;83.19822;2;2;0;2.221483;2.197168;738915.1;8.504645e+007
2912.348;0.7060174;-2.531334;809.9042;83.69027;2;2;0;2.223677;2.199314;743285.3;8.555127e+007
2933.348;0.7047853;-2.51776;807.0976;83.40025;2;2;0;2.219796;2.195517;740709.4;8.525157e+007
2954.348;0.7028567;-2.498327;814.5625;84.17163;2;2;0;2.213722;2.189575;747560.3;8.603495e+007
2975.348;0.6957853;-2.469968;814.4912;84.16426;2;2;0;2.19145;2.167783;747494.9;8.600868e+007
2996.348;0.6819639;-2.433729;809.4554;83.64389;2;2;0;2.147918;2.125175;742873.3;8.544049e+007
3017.348;0.6578567;-2.374935;813.1967;84.03049;2;2;0;2.07199;2.050816;746306.9;8.57716e+007
3038.348;0.6176782;-2.249689;812.625;83.97141;2;2;0;1.945443;1.926761;745782.2;8.560503e+007
3059.348;0.5705353;-2.00788;811.5609;83.86146;2;2;0;1.796962;1.781007;744805.6;8.536842e+007
3080.348;0.5096782;-1.656911;809.046;83.60159;2;2;0;1.605286;1.592537;742497.6;8.494363e+007
3101.348;0.4523569;-1.29266;771.4467;79.71632;2;2;0;1.424746;1.414692;707991.1;8.085208e+007
3122.348;0.4257319;-1.076057;766.0221;79.15578;2;2;0;1.340888;1.331977;703012.7;8.021717e+007
3141.644;0.411214;-0.9292696;771.7204;79.7446;3;3;0;1.295162;1.286847;708242.2;8.077742e+007
3161.392;0.4053212;-0.8373143;793.2154;81.96575;3;3;0;1.276602;1.268522;727969.1;8.301213e+007
3182.392;0.3981426;-0.7474839;793.3203;81.97659;3;3;0;1.253992;1.246195;728065.4;8.300458e+007
3203.392;0.3921426;-0.6597277;800.9468;82.76467;3;3;0;1.235095;1.22753;735064.6;8.378689e+007
3224.392;0.3856069;-0.5754924;801.8154;82.85442;3;3;0;1.21451;1.207194;735861.8;8.38607e+007
3245.392;0.3799283;-0.5080402;792.9385;81.93715;3;3;0;1.196625;1.189522;727715.1;8.291763e+007
3266.392;0.3769283;-0.4495366;800.7124;82.74044;3;3;0;1.187176;1.180184;734849.4;8.372272e+007
3287.392;0.3741426;-0.3994229;801.593;82.83144;3;3;0;1.178402;1.171513;735657.6;8.380753e+007
3308.392;0.371464;-0.3587282;793.1565;81.95967;3;3;0;1.169966;1.163174;727915.1;8.291857e+007
3329.392;0.3709283;-0.3320043;788.2085;81.44838;3;3;0;1.168278;1.161506;723374.1;8.239992e+007
3348.484;0.3718926;-0.3162175;782.1466;80.82198;4;4;0;1.171315;1.164508;717810.8;8.176866e+007
3369.484;0.3753748;-0.3111012;779.6125;80.56012;4;4;0;1.182283;1.175348;715485.1;8.151257e+007
3390.484;0.3788569;-0.3078609;775.1531;80.09931;4;4;0;1.19325;1.186187;711392.6;8.10551e+007
3411.484;0.387214;-0.3150509;808.1634;83.51039;4;4;0;1.219572;1.212195;741687.6;8.452886e+007
3432.484;0.3907497;-0.3135071;806.0475;83.29173;4;4;0;1.230708;1.223196;739745.7;8.431681e+007
3453.484;0.3942855;-0.3113192;805.772;83.26327;4;4;0;1.241844;1.234196;739492.9;8.429727e+007
3474.484;0.397714;-0.3105658;805.5077;83.23596;4;4;0;1.252643;1.244862;739250.4;8.427861e+007
3495.484;0.4012497;-0.3119706;806.7623;83.3656;4;4;0;1.263779;1.25586;740401.7;8.441916e+007
3516.484;0.4047855;-0.3125336;808.5823;83.55367;4;4;0;1.274915;1.266856;742072.1;8.461891e+007
3537.484;0.4079998;-0.3138311;809.4225;83.64049;4;4;0;1.285039;1.276852;742843.1;8.47153e+007
3558.484;0.4107319;-0.3151289;807.5366;83.44561;4;4;0;1.293644;1.285348;741112.3;8.45251e+007
3579.484;0.413464;-0.3170165;806.5467;83.34333;4;4;0;1.302249;1.293842;740203.9;8.442867e+007
3600.484;0.4163569;-0.3186854;809.2021;83.61772;4;4;0;1.31136;1.302836;742640.9;8.471425e+007
3621.484;0.4191426;-0.3203588;812.1859;83.92605;4;4;0;1.320134;1.311496;745379.3;8.503398e+007
3642.484;0.420589;-0.3196893;806.6863;83.35775;4;4;0;1.32469;1.315993;740331.9;8.446198e+007
3663.484;0.4212319;-0.3166374;797.3545;82.39346;4;4;0;1.326715;1.317991;731767.8;8.348659e+007
3683.554;0.4227319;-0.3166813;796.4181;82.2967;4;4;0;1.331439;1.322653;730908.4;8.339243e+007
3703.556;0.3992676;-0.2536411;657.3009;67.92123;4;4;0;1.257536;1.249694;603234.3;6.877536e+007
3724.556;0.3642319;-0.1599932;517.3123;53.45571;4;4;0;1.147187;1.140657;474760.6;5.406895e+007
3745.556;0.3291426;-0.09633898;376.168;38.87077;4;4;0;1.03667;1.031333;345226.1;3.927373e+007
3766.556;0.2941605;-0.05663437;242.4574;25.05398;4;4;0;0.9264899;0.9222243;222513.9;2.52861e+007
3787.556;0.2591784;-0.02730585;129.6134;13.39341;4;4;0;0.8163099;0.8129961;118952;1.350274e+007
3808.556;0.2241427;-0.007217921;61.23656;6.327791;4;4;0;0.7059613;0.7034811;56199.53;6372463
3829.556;0.2144999;-0.003748142;57.05783;5.895988;4;4;0;0.6755902;0.6733183;52364.52;5935820
3850.556;0.2141784;-0.003146093;57.55367;5.947225;4;4;0;0.6745778;0.6723127;52819.57;5987344
3871.556;0.2137499;-0.002455912;57.93092;5.986207;4;4;0;0.6732279;0.6709719;53165.79;6026508
3892.556;0.213482;-0.00297574;57.80019;5.972698;4;4;0;0.6723843;0.6701338;53045.81;6012858
3913.556;0.213107;-0.001772543;58.00516;5.993878;4;4;0;0.6712031;0.6689606;53233.92;6034109
3934.556;0.212732;-0.001057734;57.96598;5.98983;4;4;0;0.6700221;0.6677874;53197.96;6029963
3955.556;0.212357;-0.001342178;58.0591;5.999452;4;4;0;0.6688409;0.6666142;53283.42;6039579
3976.556;0.2120356;0.001129602;57.86773;5.979677;4;4;0;0.6678286;0.6656085;53107.79;6019611
3997.556;0.2117141;0.00158984;57.99188;5.992507;4;4;0;0.6668162;0.6646028;53221.73;6032465
4018.556;0.2112856;0.002688813;58.16096;6.009978;4;4;0;0.6654664;0.663262;53376.91;6049972
4039.556;0.2109642;0.004552867;58.27346;6.021603;4;4;0;0.664454;0.6622563;53480.15;6061613
4060.556;0.2105892;0.006017368;58.40704;6.035406;4;4;0;0.6632729;0.6610829;53602.74;6075437
4081.556;0.2102677;0.009140724;58.93181;6.089632;4;4;0;0.6622605;0.6600772;54084.35;6129961
4102.556;0.2099999;0.009824171;59.47393;6.145652;4;4;0;0.6614169;0.6592392;54581.88;6186300
4123.556;0.2095713;0.01150511;60.20681;6.221383;4;4;0;0.6600671;0.6578982;55254.48;6262448
4144.556;0.2093034;0.01254238;60.55819;6.257692;4;4;0;0.6592234;0.65706;55576.95;6298944
4165.556;0.2088749;0.01510303;61.44449;6.349277;4;4;0;0.6578736;0.655719;56390.35;6391047
4186.556;0.2084999;0.01704653;62.71336;6.480393;4;4;0;0.6566924;0.6545456;57554.84;6522950
4207.556;0.2081784;0.01911143;63.81195;6.593914;4;4;0;0.6556801;0.6535399;58563.07;6637149
4228.556;0.207857;0.02024032;65.32093;6.749843;4;4;0;0.6546677;0.6525341;59947.93;6794032
4249.556;0.2074284;0.02397943;66.32202;6.853289;4;4;0;0.6533179;0.651193;60866.67;6898063
4270.556;0.207107;0.0242302;67.58125;6.98341;4;4;0;0.6523055;0.6501872;62022.33;7028963
4291.556;0.206732;0.0264543;67.99095;7.025745;4;4;0;0.6511244;0.6490138;62398.32;7071491
4312.556;0.2064642;0.0241811;66.24561;6.845394;4;4;0;0.6502808;0.6481756;60796.55;6889908
4333.556;0.2060892;0.009487733;58.64703;6.060205;4;4;0;0.6490997;0.6470021;53823;6099542
4354.556;0.2057677;-0.03053225;56.46249;5.834469;4;4;0;0.6480873;0.6459962;51818.15;5872282
4375.556;0.2053927;-0.1295305;56.25709;5.813244;4;4;0;0.6469062;0.6448227;51629.64;5850850
4396.556;0.2050177;-0.2919506;55.98373;5.784997;4;4;0;0.6457251;0.6436492;51378.77;5822353
4417.556;0.2046427;-0.4246383;55.71793;5.757531;4;4;0;0.6445439;0.6424757;51134.82;5794640
4438.556;0.2043213;-0.5319813;56.0336;5.79015;4;4;0;0.6435316;0.6414698;51424.53;5827411
4459.556;0.2039999;-0.6451807;55.54441;5.739601;4;4;0;0.6425193;0.640464;50975.59;5776479
4480.556;0.2035713;-0.7288747;55.65233;5.750752;4;4;0;0.6411694;0.6391227;51074.62;5787624
4501.556;0.2033034;-0.7862335;55.70366;5.756056;4;4;0;0.6403257;0.6382844;51121.73;5792913
4522.556;0.2029284;-0.8238377;55.60901;5.746276;4;4;0;0.6391447;0.6371108;51034.87;5783003
4543.556;0.202607;-0.8432896;55.97143;5.783726;4;4;0;0.6381323;0.6361049;51367.48;5820634
4564.556;0.2021784;-0.861541;56.13299;5.800421;4;4;0;0.6367825;0.6347636;51515.75;5837357
4585.556;0.201857;-0.8703567;56.08093;5.795041;4;4;0;0.6357701;0.6337576;51467.97;5831884
4606.556;0.2015356;-0.8741107;56.05268;5.792122;4;4;0;0.6347578;0.6327516;51442.05;5828888
4627.556;0.2012142;-0.8770454;56.03829;5.790635;4;4;0;0.6337454;0.6317456;51428.84;5827333
4648.556;0.2008927;-0.8788049;56.04851;5.791691;4;4;0;0.632733;0.6307397;51438.22;5828337
4669.556;0.2004641;-0.8845398;56.3364;5.82144;4;4;0;0.6313831;0.6293983;51702.43;5858195
4690.556;0.2001427;-0.8865172;56.3618;5.824065;4;4;0;0.6303708;0.6283923;51725.74;5860778
4711.556;0.1998213;-0.8886258;56.35719;5.823588;4;4;0;0.6293584;0.6273862;51721.51;5860239
4732.556;0.1993927;-0.8887738;56.48249;5.836535;4;4;0;0.6280086;0.6260448;51836.5;5873189
4753.556;0.1990177;-0.8907218;56.476;5.835865;4;4;0;0.6268275;0.6248711;51830.54;5872446
4774.556;0.1987499;-0.8905169;56.35426;5.823285;4;4;0;0.6259838;0.6240327;51718.81;5859738
4795.556;0.1983749;-0.8940466;56.4412;5.832269;4;4;0;0.6248028;0.622859;51798.61;5868710
4816.556;0.1979999;-0.8946782;56.64167;5.852985;4;4;0;0.6236216;0.6216852;51982.59;5889485
4837.556;0.1976785;-0.8917406;56.47917;5.836193;4;4;0;0.6226093;0.6206791;51833.45;5872529
4858.556;0.197357;-0.8903936;56.54609;5.843108;4;4;0;0.6215969;0.6196729;51894.87;5879429
4879.556;0.196982;-0.8926077;56.60685;5.849386;4;4;0;0.6204157;0.6184991;51950.63;5885676
4900.556;0.196607;-0.8945546;56.87034;5.876613;4;4;0;0.6192347;0.6173253;52192.45;5913003
4921.556;0.1962856;-0.897065;56.90407;5.880099;4;4;0;0.6182223;0.6163192;52223.41;5916451
4942.556;0.1959642;-0.9000999;56.99026;5.889005;4;4;0;0.61721;0.615313;52302.5;5925353
4963.556;0.1955892;-0.9010973;57.05231;5.895417;4;4;0;0.6160288;0.6141392;52359.45;5931734
4984.556;0.1952677;-0.9033439;56.96724;5.886626;4;4;0;0.6150165;0.613133;52281.38;5922830
5005.556;0.1948927;-0.9035606;56.95573;5.885437;4;4;0;0.6138353;0.6119591;52270.81;5921564
5026.556;0.1945713;-0.9062222;57.11315;5.901704;4;4;0;0.612823;0.6109529;52415.29;5937871
5047.556;0.1941963;-0.9075643;57.12078;5.902493;4;4;0;0.6116419;0.609779;52422.29;5938595
5068.556;0.1938213;-0.9081231;57.24999;5.915844;4;4;0;0.6104608;0.608605;52540.87;5951958
5089.556;0.1934463;-0.9088648;57.23892;5.9147;4;4;0;0.6092797;0.6074311;52530.71;5950737
5110.556;0.1930713;-0.9096271;57.34683;5.925851;4;4;0;0.6080986;0.6062571;52629.75;5961886
5131.556;0.1928034;-0.9093253;57.58078;5.950026;4;4;0;0.6072549;0.6054186;52844.45;5986158
5152.556;0.1924285;-0.9102099;57.3698;5.928224;4;4;0;0.6060739;0.6042446;52650.82;5964154
5173.556;0.192107;-0.9105385;57.54689;5.946524;4;4;0;0.6050615;0.6032383;52813.35;5982504
5194.556;0.1916784;-0.9100732;57.36192;5.927411;4;4;0;0.6037117;0.6018966;52643.6;5963195
5215.556;0.191357;-0.9103458;57.72302;5.964724;4;4;0;0.6026993;0.6008903;52974.99;6000673
5236.556;0.1910356;-0.9097705;58.08482;6.00211;4;4;0;0.6016868;0.599884;53307.03;6038224
5257.556;0.1907142;-0.9090836;57.75873;5.968414;4;4;0;0.6006745;0.5988777;53007.76;6004265
5278.556;0.1903927;-0.9093677;57.85008;5.977853;4;4;0;0.5996621;0.5978713;53091.6;6013700
5299.556;0.1899642;-0.9086668;58.25416;6.019609;4;4;0;0.5983123;0.5965295;53462.45;6055625
5320.556;0.1896427;-0.9082462;57.76557;5.969121;4;4;0;0.5973;0.5955232;53014.04;6004774
5341.556;0.1893213;-0.907512;57.60521;5.95255;4;4;0;0.5962875;0.5945168;52866.87;5988045
5362.556;0.1888927;-0.9081598;57.5799;5.949935;4;4;0;0.5949377;0.593175;52843.64;5985333
5383.556;0.1885713;-0.9070837;57.12854;5.903294;4;4;0;0.5939254;0.5921686;52429.41;5938355
5404.556;0.1882499;-0.9073116;57.15526;5.906055;4;4;0;0.592913;0.5911622;52453.93;5941073
5425.556;0.1878213;-0.9074185;57.151;5.905615;4;4;0;0.5915632;0.5898203;52450.02;5940551
5446.556;0.1874999;-0.9069148;56.99149;5.889133;4;4;0;0.5905508;0.5888139;52303.64;5923911
5467.556;0.1871784;-0.9067094;57.16325;5.90688;4;4;0;0.5895384;0.5878074;52461.26;5941704
5488.556;0.186857;-0.9069168;57.02042;5.892122;4;4;0;0.588526;0.586801;52330.18;5926798
5509.556;0.186482;-0.9081747;57.22597;5.913362;4;4;0;0.5873449;0.5856268;52518.82;5948094
5530.556;0.1861606;-0.910604;56.91356;5.88108;4;4;0;0.5863326;0.5846203;52232.11;5915562
5551.556;0.1857856;-0.9135383;57.04491;5.894652;4;4;0;0.5851515;0.5834461;52352.66;5929145
5572.556;0.1854642;-0.9116866;56.70407;5.859433;4;4;0;0.5841391;0.5824396;52039.86;5893660
5593.556;0.1850892;-0.9118105;56.80987;5.870366;4;4;0;0.582958;0.5812653;52136.96;5904587
5614.556;0.1847142;-0.9084041;56.71441;5.860501;4;4;0;0.5817769;0.5800911;52049.34;5894596
5635.556;0.1843927;-0.9021657;56.49203;5.837522;4;4;0;0.5807645;0.5790846;51845.26;5871424
5656.556;0.1840713;-0.8925329;56.45277;5.833465;4;4;0;0.5797521;0.578078;51809.23;5867285
5677.556;0.1836963;-0.8790775;56.52533;5.840963;4;4;0;0.5785711;0.5769038;51875.82;5874757
5698.556;0.1833749;-0.8517557;56.97326;5.887249;4;4;0;0.5775586;0.5758972;52286.9;5921251
5719.556;0.1829463;-0.8054045;57.22556;5.91332;4;4;0;0.5762089;0.5745551;52518.45;5947393
5740.556;0.1826249;-0.7342567;57.41883;5.933291;4;4;0;0.5751965;0.5735486;52695.82;5967419
5761.556;0.1823034;-0.5719466;71.59634;7.398303;4;4;0;0.5741841;0.5725419;65707.15;7440783
5782.556;0.1819284;-0.407166;132.3388;13.67504;4;4;0;0.573003;0.5713676;121453.2;1.37534e+007
5803.556;0.181607;-0.2898321;195.0115;20.15123;4;4;0;0.5719907;0.570361;178970.8;2.026649e+007
5824.556;0.181232;-0.2069449;244.5996;25.27534;4;4;0;0.5708095;0.5691866;224479.9;2.541961e+007
5845.556;0.180857;-0.1626054;266.6379;27.55264;4;4;0;0.5696284;0.5680122;244705.5;2.770958e+007
5866.556;0.1805356;-0.134121;275.8864;28.50832;4;4;0;0.568616;0.5670055;253193.3;2.867042e+007
5887.556;0.1802142;-0.1124332;278.8465;28.8142;4;4;0;0.5676037;0.5659989;255909.9;2.897775e+007
5908.556;0.1797856;-0.1006368;273.3331;28.24447;4;4;0;0.5662538;0.5646566;250850;2.840441e+007
5929.556;0.1794642;-0.08919881;266.3113;27.51889;4;4;0;0.5652415;0.56365;244405.7;2.767444e+007
5950.556;0.1791428;-0.0822024;255.1396;26.36448;4;4;0;0.5642291;0.5626433;234153;2.651324e+007
5971.556;0.1774285;-0.07842379;235.7003;24.35575;4;4;0;0.5588298;0.5572741;216312.7;2.449186e+007
5992.556;0.1690713;-0.06583428;190.6401;19.69952;4;4;0;0.5325081;0.5310953;174958.9;1.980442e+007
6013.556;0.1340892;-0.03750121;72.9469;7.537861;4;4;0;0.4223282;0.4214389;66946.63;7569696
6034.556;0.1128214;-0.03341024;56.93403;5.883195;4;4;0;0.3553429;0.354713;52250.9;5904100
6055.556;0.1123928;-0.03438212;57.06115;5.89633;4;4;0;0.353993;0.3533679;52367.56;5917203
6076.556;0.1120714;-0.03661249;56.95778;5.88565;4;4;0;0.3529806;0.3523591;52272.7;5906425
6097.556;0.1116428;-0.03846139;56.81848;5.871254;4;4;0;0.3516308;0.351014;52144.85;5891899
6118.556;0.1113214;-0.04116535;56.79076;5.86839;4;4;0;0.3506184;0.3500052;52119.41;5888966
6139.556;0.1109999;-0.04171564;56.50589;5.838954;4;4;0;0.3496061;0.3489964;51857.98;5859367
6160.556;0.1106785;-0.04232959;56.79193;5.868511;4;4;0;0.3485937;0.3479875;52120.49;5888969
6181.556;0.1103571;-0.04203313;56.6131;5.850032;4;4;0;0.3475813;0.3469787;51956.37;5870366
6202.556;0.1099285;-0.04107635;56.6237;5.851128;4;4;0;0.3462315;0.3456335;51966.1;5871386
6223.556;0.1096071;-0.03972011;56.49526;5.837856;4;4;0;0.3452191;0.3446246;51848.22;5858009
6244.556;0.1092856;-0.03774956;56.44652;5.832819;4;4;0;0.3442068;0.3436157;51803.49;5852896
6265.556;0.1089642;-0.03525961;56.34779;5.822617;4;4;0;0.3431944;0.3426068;51712.88;5842600
6286.556;0.1085356;-0.03334008;56.39405;5.827396;4;4;0;0.3418445;0.3412616;51755.33;5847317
6307.556;0.1082142;-0.03109644;56.50081;5.838429;4;4;0;0.3408322;0.3402527;51853.32;5858328
6328.556;0.1078928;-0.02944358;56.37152;5.825069;4;4;0;0.3398198;0.3392437;51734.66;5844864
6349.556;0.1074642;-0.0270326;56.57196;5.845781;4;4;0;0.33847;0.3378985;51918.61;5865567
6370.556;0.1071428;-0.02556191;56.52542;5.840972;4;4;0;0.3374576;0.3368895;51875.9;5860683
6391.556;0.1068214;-0.02309381;56.4464;5.832807;4;4;0;0.3364452;0.3358805;51803.38;5852431
6412.556;0.1063928;-0.02069188;56.1687;5.804111;4;4;0;0.3350954;0.3345352;51548.52;5823560
6433.556;0.1060714;-0.01908698;56.57528;5.846124;4;4;0;0.334083;0.3335262;51921.66;5865655
6454.556;0.1057499;-0.01708617;56.17959;5.805236;4;4;0;0.3330707;0.3325172;51558.52;5824572
6475.556;0.1054285;-0.01510834;56.31928;5.819671;4;4;0;0.3320583;0.3315082;51686.71;5838995
6496.556;0.1050535;-0.01375785;56.32248;5.820002;4;4;0;0.3308772;0.330331;51689.65;5839258
6517.556;0.1047321;-0.01140662;56.31752;5.819489;4;4;0;0.3298648;0.3293219;51685.1;5838685
6538.556;0.1043571;-0.00970677;56.46217;5.834436;4;4;0;0.3286837;0.3281447;51817.85;5853613
6559.556;0.1039821;-0.008391362;56.31878;5.819619;4;4;0;0.3275026;0.3269675;51686.26;5838679
6580.556;0.1036606;-0.007499818;56.2267;5.810103;4;4;0;0.3264902;0.3259584;51601.75;5829073
6601.556;0.1033392;-0.005293611;56.31271;5.818991;4;4;0;0.3254779;0.3249493;51680.68;5837931
6622.556;0.1029642;-0.003648929;56.23007;5.810452;4;4;0;0.3242968;0.3237721;51604.85;5829296
6643.556;0.1026428;-0.002613775;56.22717;5.810152;4;4;0;0.3232844;0.3227629;51602.18;5828935
6664.556;0.1022142;-0.002033221;56.27705;5.815307;4;4;0;0.3219346;0.3214174;51647.96;5834029
6685.556;0.1018928;-0.0004020464;56.37026;5.824938;4;4;0;0.3209222;0.3204083;51733.5;5843632
6706.556;0.1015714;0.0009850504;56.28945;5.816588;4;4;0;0.3199098;0.3193992;51659.34;5835196
6727.556;0.1011428;0.002083045;56.37557;5.825488;4;4;0;0.31856;0.3180537;51738.38;5844045
6748.556;0.1008214;0.00307936;56.10645;5.797678;4;4;0;0.3175476;0.3170445;51491.39;5816088
6769.556;0.1004999;0.003371869;56.10607;5.797638;4;4;0;0.3165352;0.3160353;51491.04;5815990
6790.556;0.1001785;0.004853558;56.04437;5.791264;4;4;0;0.3155229;0.3150261;51434.42;5809536
6811.556;0.09985708;0.00560427;56.23354;5.810811;4;4;0;0.3145105;0.3140169;51608.03;5829086
6832.556;0.09942851;0.00549934;56.25351;5.812874;4;4;0;0.3131607;0.3126713;51626.35;5831077
6853.556;0.09910708;0.006981265;56.11526;5.798588;4;4;0;0.3121483;0.3116621;51499.48;5816689
6874.556;0.09878565;0.007466287;56.12136;5.799219;4;4;0;0.3111359;0.3106529;51505.08;5817263
6895.556;0.09846422;0.008221696;56.26704;5.814272;4;4;0;0.3101235;0.3096437;51638.77;5832304
6916.556;0.09803565;0.008777037;56.15831;5.803037;4;4;0;0.3087737;0.308298;51538.98;5820955
6937.556;0.09771422;0.00939087;56.22875;5.810316;4;4;0;0.3077613;0.3072887;51603.63;5828198
6958.556;0.09739279;0.009333473;55.90818;5.77719;4;4;0;0.306749;0.3062794;51309.43;5794912
6979.556;0.09696422;0.00987182;56.14139;5.801289;4;4;0;0.3053991;0.3049337;51523.46;5819006
7000.556;0.0966428;0.01152187;56.0733;5.794252;4;4;0;0.3043868;0.3039244;51460.96;5811889
7021.556;0.09632136;0.01116812;56.06507;5.793403;4;4;0;0.3033744;0.3029151;51453.42;5810978
7042.556;0.09599993;0.01197725;56.25063;5.812576;4;4;0;0.302362;0.3019058;51623.71;5830151
7063.556;0.09551779;0.01283489;56.05298;5.792152;4;4;0;0.3008434;0.3003918;51442.32;5809578
7084.556;0.09524993;0.01256266;56.04628;5.791461;4;4;0;0.2999998;0.2995507;51436.17;5808835
7105.556;0.09492851;0.01369064;56.12815;5.799921;4;4;0;0.2989874;0.2985414;51511.3;5817261
7126.556;0.09449994;0.01463093;56.21178;5.808562;4;4;0;0.2976376;0.2971955;51588.06;5825851
7147.556;0.0941785;0.01466703;55.94539;5.781035;4;4;0;0.2966252;0.2961861;51343.57;5798183
7168.556;0.09385708;0.01460619;56.11623;5.798688;4;4;0;0.2956128;0.2951768;51500.36;5815830
7189.556;0.09353565;0.01532675;56.24558;5.812055;4;4;0;0.2946005;0.2941674;51619.07;5829177
7210.556;0.09310708;0.01545858;56.2999;5.817668;4;4;0;0.2932507;0.2928215;51668.93;5834729
7231.556;0.09278566;0.0161688;55.97443;5.784036;4;4;0;0.2922383;0.2918121;51370.23;5800939
7252.556;0.09246422;0.01753225;56.26264;5.813818;4;4;0;0.2912259;0.2908027;51634.73;5830749
7273.556;0.0921428;0.01659416;56.22916;5.810359;4;4;0;0.2902136;0.2897932;51604.01;5827221
7294.556;0.0917678;0.01708407;56.12583;5.799681;4;4;0;0.2890324;0.2886155;51509.18;5816443
7315.556;0.0913928;0.01684532;56.15648;5.802848;4;4;0;0.2878514;0.2874379;51537.31;5819552
7336.556;0.09107137;0.01738798;56.02311;5.789066;4;4;0;0.2868389;0.2864284;51414.91;5805672
7357.556;0.09074994;0.01801266;56.18697;5.805998;4;4;0;0.2858266;0.2854189;51565.29;5822593
7378.556;0.09037494;0.01770077;55.99909;5.786584;4;4;0;0.2846455;0.2842411;51392.86;5803056
7399.556;0.08999994;0.01788866;56.2772;5.815322;4;4;0;0.2834644;0.2830634;51648.1;5831807
7420.556;0.08967851;0.01871012;56.11088;5.798136;4;4;0;0.282452;0.2820539;51495.46;5814513
7441.556;0.08930351;0.01908242;56.09958;5.796968;4;4;0;0.2812709;0.2808761;51485.09;5813273
7462.556;0.08892851;0.01989276;56.12557;5.799654;4;4;0;0.2800898;0.2796983;51508.93;5815898
7483.556;0.08860708;0.01907342;56.11056;5.798103;4;4;0;0.2790774;0.2786887;51495.16;5814284
7504.556;0.08828566;0.01974371;56.25274;5.812795;4;4;0;0.2780651;0.2776792;51625.65;5828959
7525.556;0.08796423;0.01957797;56.16574;5.803804;4;4;0;0.2770527;0.2766696;51545.8;5819884
7546.556;0.08753565;0.01934091;56.07497;5.794425;4;4;0;0.2757028;0.2753235;51462.5;5810401
7567.556;0.08721423;0.0195483;56.21627;5.809026;4;4;0;0.2746905;0.2743139;51592.18;5824983
7588.556;0.08689281;0.02076766;56.29876;5.81755;4;4;0;0.2736781;0.2733043;51667.88;5833471
7609.556;0.08646422;0.02119779;56.19454;5.806781;4;4;0;0.2723283;0.2719581;51572.24;5822594
7630.556;0.0861428;0.02075005;56.09696;5.796698;4;4;0;0.2713159;0.2709485;51482.68;5812425
7651.556;0.08582138;0.0214811;56.19078;5.806393;4;4;0;0.2703035;0.2699389;51568.79;5822088
7672.556;0.08539279;0.02084769;56.21034;5.808414;4;4;0;0.2689537;0.2685926;51586.74;5824036
7693.556;0.08517852;0.02135566;56.22537;5.809967;4;4;0;0.2682788;0.2679196;51600.53;5825554
7714.556;0.08474995;0.02162984;56.24129;5.811612;4;4;0;0.266929;0.2665733;51615.14;5827124
7735.556;0.08442851;0.0217381;56.09468;5.796462;4;4;0;0.2659166;0.2655637;51480.59;5811875
7756.556;0.08410709;0.02246054;56.21794;5.809199;4;4;0;0.2649042;0.264554;51593.71;5824588
7777.556;0.08373209;0.02165752;56.20828;5.808201;4;4;0;0.2637231;0.263376;51584.85;5823519
7798.556;0.08330351;0.02238165;56.09288;5.796276;4;4;0;0.2623733;0.2620297;51478.94;5811484
7819.556;0.08303566;0.02215042;56.15746;5.802948;4;4;0;0.2615296;0.2611882;51538.2;5818125
7840.556;0.08260708;0.02246137;56.238;5.811272;4;4;0;0.2601798;0.2598419;51612.12;5826392
7861.556;0.08228566;0.02250678;56.20937;5.808313;4;4;0;0.2591674;0.2588322;51585.85;5823367
7882.556;0.08196423;0.02242252;56.47142;5.835392;4;4;0;0.258155;0.2578224;51826.34;5850456
7903.556;0.08158923;0.02183919;56.19337;5.80666;4;4;0;0.256974;0.2566443;51571.16;5821581
7924.556;0.08121423;0.02293585;56.21859;5.809266;4;4;0;0.2557929;0.2554663;51594.31;5824126
7945.556;0.08089281;0.02301925;56.26378;5.813936;4;4;0;0.2547805;0.2544565;51635.78;5828749
7966.556;0.08057138;0.02336927;56.28695;5.81633;4;4;0;0.2537681;0.2534467;51657.05;5831090
7987.556;0.08024995;0.02300848;56.27544;5.815141;4;4;0;0.2527557;0.2524368;51646.48;5829839
8008.556;0.07987494;0.02382536;56.35255;5.823109;4;4;0;0.2515746;0.2512587;51717.25;5837758
8029.556;0.07949995;0.02399971;56.25768;5.813305;4;4;0;0.2503935;0.2500806;51630.18;5827861
8050.556;0.07917852;0.02358837;56.33235;5.821021;4;4;0;0.2493812;0.2490707;51698.71;5835538
8071.556;0.07874995;0.02400558;56.36923;5.824832;4;4;0;0.2480313;0.2477243;51732.56;5839280
8092.556;0.07842852;0.02329073;56.44426;5.832585;4;4;0;0.247019;0.2467144;51801.41;5846992
8113.556;0.07810709;0.02353203;56.37182;5.825099;4;4;0;0.2460066;0.2457045;51734.93;5839429
8134.556;0.07778566;0.02332037;56.47277;5.835531;4;4;0;0.2449942;0.2446946;51827.58;5849828
8155.556;0.07746423;0.02410499;56.42141;5.830224;4;4;0;0.2439818;0.2436847;51780.45;5844449
8176.556;0.07703567;0.02488745;56.4563;5.833829;4;4;0;0.242632;0.2423381;51812.46;5847984
8197.557;0.07671423;0.02423016;56.32354;5.820111;4;4;0;0.2416196;0.2413282;51690.63;5834173
8218.557;0.07639281;0.0246025;56.37878;5.825819;4;4;0;0.2406073;0.2403183;51741.32;5839836
8239.557;0.07596424;0.02439867;56.45929;5.834138;4;4;0;0.2392574;0.2389717;51815.21;5848097
8260.557;0.07564281;0.02519672;56.48619;5.836918;4;4;0;0.2382451;0.2379617;51839.89;5850824
8281.557;0.07532138;0.0251365;56.44396;5.832554;4;4;0;0.2372327;0.2369517;51801.14;5846391
8302.557;0.07489281;0.02483127;56.35384;5.823242;4;4;0;0.2358829;0.2356051;51718.43;5836978
8323.557;0.07457138;0.02443986;56.3961;5.827609;4;4;0;0.2348705;0.2345951;51757.21;5841296
8344.557;0.07430352;0.02480386;56.4262;5.830719;4;4;0;0.2340268;0.2337534;51784.84;5844364
8365.557;0.07392853;0.02559729;56.49885;5.838226;4;4;0;0.2328458;0.2325751;51851.51;5851820
8386.557;0.07355352;0.02563495;56.37816;5.825755;4;4;0;0.2316646;0.2313967;51740.75;5839251
8407.557;0.07317853;0.02492962;56.46111;5.834326;4;4;0;0.2304835;0.2302183;51816.88;5847774
8428.557;0.0728571;0.02487493;56.53893;5.842368;4;4;0;0.2294712;0.2292083;51888.3;5855774
8449.557;0.07253567;0.02512687;56.49424;5.837749;4;4;0;0.2284588;0.2281982;51847.28;5851086
8470.557;0.07216067;0.02525435;56.51846;5.840252;4;4;0;0.2272777;0.2270198;51869.51;5853526
8491.557;0.07178567;0.02484979;56.28487;5.816114;4;4;0;0.2260966;0.2258414;51655.13;5829265
8512.557;0.07146424;0.02563766;56.54013;5.842492;4;4;0;0.2250842;0.2248313;51889.4;5855642
8533.557;0.07114281;0.02627306;56.57053;5.845633;4;4;0;0.2240718;0.2238212;51917.29;5858731
8554.557;0.07076781;0.02532769;56.43539;5.831668;4;4;0;0.2228907;0.2226427;51793.27;5844667
8575.557;0.07039281;0.02551836;56.43521;5.83165;4;4;0;0.2217096;0.2214642;51793.11;5844580
8596.557;0.07007138;0.02563374;56.55902;5.844443;4;4;0;0.2206973;0.2204541;51906.73;5857342
8617.557;0.06969638;0.02556393;56.44479;5.83264;4;4;0;0.2195162;0.2192756;51801.9;5845443
8638.557;0.06932138;0.02584411;56.36826;5.824732;4;4;0;0.2183351;0.2180971;51731.67;5837450
8659.557;0.06899996;0.02588561;56.54236;5.842722;4;4;0;0.2173227;0.2170869;51891.45;5855420
8680.557;0.06867853;0.02558644;56.59472;5.848133;4;4;0;0.2163103;0.2160767;51939.5;5860783
8701.557;0.06824995;0.02576008;56.62092;5.85084;4;4;0;0.2149605;0.2147298;51963.54;5863417
8722.557;0.06803567;0.02708591;56.53012;5.841457;4;4;0;0.2142856;0.2140563;51880.21;5853975
8743.557;0.0676071;0.0258786;56.71555;5.860619;4;4;0;0.2129358;0.2127094;52050.39;5873098
8764.557;0.06728567;0.0264756;56.81137;5.87052;4;4;0;0.2119234;0.2116991;52138.33;5882961
8785.557;0.06696424;0.02608235;56.72566;5.861663;4;4;0;0.210911;0.2106889;52059.66;5874026
8806.557;0.06653567;0.02669626;56.68645;5.857612;4;4;0;0.2095612;0.2093419;52023.69;5869887
8827.557;0.06621424;0.02621688;56.64646;5.853479;4;4;0;0.2085488;0.2083316;51986.98;5865687
8848.557;0.06589281;0.02642047;56.57417;5.846009;4;4;0;0.2075364;0.2073213;51920.63;5858141
8869.557;0.06546424;0.02704245;56.61575;5.850306;4;4;0;0.2061866;0.2059743;51958.8;5862368
8890.557;0.06514281;0.02651886;56.74674;5.863842;4;4;0;0.2051742;0.204964;52079.02;5875873
8911.557;0.06482138;0.0257133;56.68487;5.857448;4;4;0;0.2041618;0.2039537;52022.23;5869407
8932.557;0.06439282;0.02637494;56.7364;5.862773;4;4;0;0.202812;0.2026066;52069.53;5874664
8953.557;0.06417853;0.02577394;56.61442;5.850169;4;4;0;0.2021371;0.2019331;51957.58;5861994
8974.557;0.06374995;0.0260688;56.7128;5.860334;4;4;0;0.2007873;0.2005859;52047.86;5872101
8995.557;0.06342853;0.02690546;56.64816;5.853655;4;4;0;0.1997749;0.1995756;51988.55;5865349
9016.557;0.0631071;0.02670233;56.61671;5.850406;4;4;0;0.1987625;0.1985653;51959.68;5862034
9037.557;0.0627321;0.02650257;56.6469;5.853525;4;4;0;0.1975814;0.1973865;51987.39;5865090
9058.557;0.0623571;0.02649263;56.64796;5.853634;4;4;0;0.1964003;0.1962077;51988.36;5865131
9079.557;0.06203567;0.02650473;56.61116;5.849832;4;4;0;0.1953879;0.1951973;51954.59;5861262
9100.557;0.06166067;0.02693012;56.84723;5.874225;4;4;0;0.1942068;0.1940185;52171.23;5885633
9121.557;0.06128568;0.02661338;56.65442;5.854301;4;4;0;0.1930258;0.1928397;51994.29;5865602
9142.557;0.06096425;0.02636558;56.81522;5.870918;4;4;0;0.1920134;0.1918293;52141.86;5882191
9163.557;0.06064282;0.02612276;56.66966;5.855876;4;4;0;0.191001;0.1908188;52008.27;5867061
9184.557;0.06026782;0.02658444;56.74874;5.864048;4;4;0;0.1898199;0.18964;52080.84;5875179
9205.557;0.05994639;0.02687519;56.81296;5.870684;4;4;0;0.1888075;0.1886295;52139.79;5881768
9226.557;0.05957139;0.02707479;56.85239;5.874759;4;4;0;0.1876264;0.1874506;52175.98;5885782
9247.557;0.05924996;0.02705553;56.83856;5.87333;4;4;0;0.1866141;0.1864401;52163.28;5884290
9268.557;0.05882139;0.0269035;56.83803;5.873275;4;4;0;0.1852642;0.1850928;52162.8;5884156
9289.557;0.05849996;0.02659783;56.81081;5.870462;4;4;0;0.1842519;0.1840823;52137.82;5881279
9310.557;0.05817853;0.0271213;56.90117;5.879799;4;4;0;0.1832395;0.1830718;52220.74;5890573
9331.557;0.05774997;0.02678533;56.90061;5.879741;4;4;0;0.1818897;0.1817244;52220.23;5890436
9352.557;0.05742853;0.0273144;56.94627;5.88446;4;4;0;0.1808773;0.1807139;52262.13;5895104
9373.557;0.0571071;0.02706308;56.76366;5.86559;4;4;0;0.1798649;0.1797033;52094.54;5876140
9394.557;0.05678568;0.02712185;56.84024;5.873503;4;4;0;0.1788525;0.1786928;52164.82;5884008
9415.557;0.05646425;0.02680546;56.9337;5.883161;4;4;0;0.1778402;0.1776822;52250.6;5893624
9436.557;0.05603568;0.02698556;56.81959;5.87137;4;4;0;0.1764903;0.1763348;52145.88;5881732
9457.557;0.05571425;0.02672645;56.91926;5.881668;4;4;0;0.175478;0.1753242;52237.34;5891989
9478.557;0.05539282;0.02660973;56.85771;5.875308;4;4;0;0.1744656;0.1743136;52180.86;5885559
9499.557;0.05496425;0.02683721;56.81234;5.87062;4;4;0;0.1731158;0.1729661;52139.22;5880783
9520.557;0.05464282;0.02730829;56.94187;5.884005;4;4;0;0.1721034;0.1719555;52258.09;5894131
9541.557;0.05432139;0.02705224;57.05319;5.895508;4;4;0;0.171091;0.1709448;52360.25;5905595
9562.557;0.05389282;0.02726703;56.65263;5.854116;4;4;0;0.1697412;0.1695973;51992.64;5864053
9583.557;0.05367854;0.02667919;56.95156;5.885006;4;4;0;0.1690663;0.1689235;52266.98;5894956
9604.557;0.05330354;0.02745457;56.99687;5.889688;4;4;0;0.1678852;0.1677444;52308.57;5899576
9625.557;0.05292854;0.02722788;56.78277;5.867565;4;4;0;0.166704;0.1665653;52112.08;5877346
9646.557;0.05260711;0.02759384;57.0649;5.896719;4;4;0;0.1656917;0.1655546;52371.01;5906489
9667.557;0.05223211;0.02725849;56.98571;5.888535;4;4;0;0.1645106;0.1643754;52298.33;5898222
9688.557;0.05191068;0.02736922;56.72651;5.861751;4;4;0;0.1634982;0.1633647;52060.45;5871335
9709.557;0.05153568;0.02774559;56.98961;5.888938;4;4;0;0.1623171;0.1621855;52301.91;5898497
9730.557;0.05116068;0.02739134;57.09797;5.900135;4;4;0;0.161136;0.1610063;52401.35;5909642
9751.557;0.05073211;0.02788485;56.88898;5.87854;4;4;0;0.1597862;0.1596587;52209.55;5887933
9772.557;0.05051782;0.0276057;56.89985;5.879663;4;4;0;0.1591113;0.1589848;52219.53;5889018
9793.557;0.05008926;0.02717843;57.05263;5.89545;4;4;0;0.1577614;0.1576371;52359.74;5904751
9814.557;0.04971425;0.02777347;56.89762;5.879432;4;4;0;0.1565803;0.1564579;52217.48;5888638
9835.557;0.04944639;0.02758217;56.92392;5.882151;4;4;0;0.1557367;0.1556155;52241.63;5891311
9856.557;0.0490714;0.02767809;57.11347;5.901738;4;4;0;0.1545556;0.1544363;52415.58;5910859
9877.557;0.04874997;0.02768373;56.77047;5.866293;4;4;0;0.1535432;0.1534255;52100.79;5875301
9898.557;0.04837497;0.02713364;57.09471;5.899798;4;4;0;0.1523621;0.1522462;52398.36;5908788
9919.557;0.0479464;0.02769508;57.14815;5.905321;4;4;0;0.1510123;0.1508984;52447.41;5914239
9940.557;0.04767854;0.02715094;57.15241;5.905761;4;4;0;0.1501686;0.150056;52451.32;5914630
9961.557;0.04735711;0.0275472;57.13417;5.903876;4;4;0;0.1491563;0.1490451;52434.58;5912682
9982.557;0.04698211;0.02716053;57.11394;5.901786;4;4;0;0.1479752;0.1478658;52416.01;5910519
10003.56;0.04666068;0.02853267;57.05383;5.895575;4;4;0;0.1469628;0.1468549;52360.85;5904239
10024.56;0.04623211;0.02781912;56.98389;5.888347;4;4;0;0.145613;0.145507;52296.65;5896921
10045.56;0.04585711;0.02713305;56.97922;5.887864;4;4;0;0.1444319;0.1443277;52292.37;5896368
10066.56;0.04553568;0.02769191;57.26041;5.916921;4;4;0;0.1434195;0.1433167;52550.43;5925407
10087.56;0.04521426;0.02783063;57.31594;5.922659;4;4;0;0.1424071;0.1423058;52601.39;5931093
10108.56;0.04489283;0.02787119;57.1478;5.905285;4;4;0;0.1413947;0.1412949;52447.09;5913634
10129.56;0.04446425;0.02764622;57.18075;5.908689;4;4;0;0.1400449;0.1399469;52477.32;5916964
10150.56;0.04414283;0.02787468;57.08522;5.898818;4;4;0;0.1390325;0.138936;52389.66;5907020
10171.56;0.0438214;0.02725462;57.33661;5.924795;4;4;0;0.1380202;0.137925;52620.37;5932973
10192.56;0.0434464;0.02785721;57.35846;5.927052;4;4;0;0.1368391;0.1367455;52640.42;5935163
10213.56;0.04312497;0.02712905;57.12675;5.903109;4;4;0;0.1358267;0.1357345;52427.76;5911127
10234.56;0.04280354;0.02727682;57.09582;5.899914;4;4;0;0.1348143;0.1347235;52399.38;5907867
10255.56;0.04242855;0.02791081;57.27727;5.918663;4;4;0;0.1336332;0.133544;52565.9;5926572
10276.56;0.04205354;0.02765566;57.02676;5.892777;4;4;0;0.1324521;0.1323645;52336;5900582
10297.56;0.04173211;0.02799945;57.17549;5.908146;4;4;0;0.1314397;0.1313534;52472.5;5915911
10318.56;0.04130354;0.02808289;57.06273;5.896494;4;4;0;0.1300899;0.1300054;52369.02;5904165
10339.56;0.04103569;0.02790897;57.14736;5.905239;4;4;0;0.1292463;0.1291628;52446.68;5912871
10360.56;0.04060711;0.02831475;57.20826;5.911532;4;4;0;0.1278964;0.1278147;52502.57;5919093
10381.56;0.04028569;0.02794178;57.33271;5.924392;4;4;0;0.1268841;0.1268036;52616.78;5931909
10402.56;0.03996426;0.02771748;57.00333;5.890356;4;4;0;0.1258717;0.1257925;52314.49;5897770
10423.56;0.03964283;0.02719867;57.24227;5.915046;4;4;0;0.1248593;0.1247814;52533.78;5922431
10444.56;0.03926783;0.02722134;57.19995;5.910674;4;4;0;0.1236782;0.1236018;52494.95;5917984
10465.56;0.03889283;0.02838092;57.07897;5.898172;4;4;0;0.1224971;0.1224221;52383.91;5905397
10486.56;0.0385714;0.02755821;57.35494;5.926689;4;4;0;0.1214847;0.121411;52637.18;5933889
10507.56;0.03824997;0.02800975;57.37443;5.928703;4;4;0;0.1204724;0.1203998;52655.08;5935846
10528.56;0.0378214;0.02781274;57.26144;5.917027;4;4;0;0.1191225;0.1190516;52551.38;5924076
10549.56;0.03749998;0.0275649;57.11923;5.902332;4;4;0;0.1181102;0.1180405;52420.86;5909303
10570.56;0.03717855;0.02742184;57.09019;5.899331;4;4;0;0.1170978;0.1170293;52394.21;5906239
10591.56;0.03674998;0.02809765;57.30619;5.921652;4;4;0;0.115748;0.115681;52592.45;5928506
10612.56;0.03642855;0.02775424;57.34222;5.925375;4;4;0;0.1147356;0.1146698;52625.52;5932173
10633.56;0.03610712;0.02777304;57.54504;5.946333;4;4;0;0.1137232;0.1136586;52811.65;5953095
10654.56;0.03573212;0.02785553;57.21807;5.912546;4;4;0;0.1125421;0.1124788;52511.57;5919200
10675.56;0.03541069;0.02868791;57.19684;5.910352;4;4;0;0.1115297;0.1114676;52492.09;5916944
10696.56;0.03508926;0.0279704;57.49078;5.940725;4;4;0;0.1105174;0.1104563;52761.85;5947291
10717.56;0.03471426;0.02818935;57.12583;5.903015;4;4;0;0.1093363;0.1092765;52426.93;5909469
10738.56;0.03439283;0.02810665;57.03275;5.893396;4;4;0;0.1083239;0.1082653;52341.5;5899780
10759.56;0.03396427;0.02718677;57.21531;5.91226;4;4;0;0.1069741;0.1069169;52509.04;5918585
10780.56;0.03364283;0.02733445;57.4225;5.933671;4;4;0;0.1059617;0.1059056;52699.19;5939958
10801.56;0.03332141;0.0276618;57.14551;5.905048;4;4;0;0.1049493;0.1048943;52444.98;5911245
10822.56;0.03299998;0.02783795;57.24905;5.915747;4;4;0;0.1039369;0.103883;52540;5921895
10843.56;0.03267855;0.02840962;57.33826;5.924965;4;4;0;0.1029246;0.1028716;52621.88;5931064
10864.56;0.03224998;0.02843323;57.63868;5.956009;4;4;0;0.1015747;0.1015232;52897.59;5962059
10885.56;0.03187498;0.02843483;57.37438;5.928697;4;4;0;0.1003936;0.1003433;52655.02;5934649
10906.56;0.03155355;0.02788979;57.36621;5.927854;4;4;0;0.09938127;0.09933192;52647.53;5933745
10927.56;0.03123212;0.02712075;57.40662;5.932029;4;4;0;0.09836888;0.09832053;52684.61;5937864
10948.56;0.03080355;0.02724287;57.36745;5.927981;4;4;0;0.09701905;0.09697202;52648.66;5933733
10969.56;0.03053569;0.02778862;57.38157;5.92944;4;4;0;0.0961754;0.09612919;52661.63;5935143
10990.56;0.0301607;0.02814487;57.38656;5.929957;4;4;0;0.09499431;0.09494922;52666.21;5935590
11011.56;0.02973213;0.0277268;57.49512;5.941175;4;4;0;0.09364449;0.09360067;52765.84;5946738
11022.4;0.02967855;0.02831271;57.2753;5.918459;4;4;0;0.09347575;0.09343209;52564.1;5923992