File: Ensayos/Resistencia/comp/Clavo6/Clavo6d.raw
"Test Type";"Manual"
"Method Name:";"C:\INSTRON\user\template\CYCLE.MTM"
"Name:";""
"Operator ID:";""
"Company:";""
"Lab name:";""
"Test date:";"06/06/2017"
"Temperature:";""
"Humidity:";""
"Note 1:";""
"Note 2:";""
"Note 3:";""
"Geometry:";"Rectangular"
"Specimen";1
"Specimen name:";""
"Width:";0.250000;"in"
"Thickness:";0.060000;"in"
"Length:";1.250000;"in"
"Diameter:";0.039370;"in"
"Inner diameter:";0.019685;"in"
"Outer diameter:";0.039370;"in"
"Wall thickness:";0.019685;"in"
"Area:";0.015000;"in*in"
"Linear density:";1.000000;"den"
"Sled weight:";2.204623;"lbf"
"Loading span:";0.000000;"mm"
"Support span:";1.000000;"mm"
"Span ratio:";"2"
"Fixture type:";"3-point"
"Comment:";""
"Included"
"Final Width:";0.250000;"in"
"Final Thickness:";0.060000;"in"
"Final Length:";1.250000;"in"
"Final Diameter:";0.039370;"in"
"Final Inner diameter:";0.019685;"in"
"Final Outer diameter:";0.039370;"in"
"Final Wall thickness:";0.019685;"in"
"Final Area:";0.015000;"in*in"
"Final Linear density:";1.000000;"den"
"Time sec";"Extension mm";"Strain 1 %";"Load N";"Stress MPa";"Cycle Count ";"Total Cycle Count ";"Repetitions Count ";"Strain [Exten.] %";"True strain %";"Tenacity gf/tex";"True stress Pa"
0;0;-0.001471568;11.1212;1.149193;0;0;0;0;0;10206.42;1149193
4;0;-0.001833181;11.35254;1.173098;0;0;0;0;0;10418.73;1173098
8;0.0001071428;-0.002145188;11.48791;1.187086;0;0;0;0.0003374576;0.000337457;10542.96;1187090
12;0.0001607142;-0.002578411;11.75128;1.214301;0;0;0;0.0005061864;0.0005061851;10784.67;1214307
16;0.0002142856;-0.002937636;11.59098;1.197737;0;0;0;0.0006749152;0.000674913;10637.55;1197745
20;0.0003214284;-0.003340711;11.47481;1.185733;0;0;0;0.001012373;0.001012368;10530.94;1185745
24;0.0003749997;-0.003445914;11.47252;1.185496;0;0;0;0.001181102;0.001181095;10528.84;1185510
28;0.0004821425;-0.003898675;11.60395;1.199078;0;0;0;0.001518559;0.001518548;10649.47;1199096
32;0.0004821425;-0.004096591;11.65079;1.203917;0;0;0;0.001518559;0.001518548;10692.45;1203936
36;0.0005892853;-0.004478093;11.33013;1.170783;0;0;0;0.001856017;0.001856;10398.17;1170804
40;0.0006428567;-0.004591753;11.64192;1.203001;0;0;0;0.002024746;0.002024725;10684.31;1203025
44;0.0006964281;-0.005002503;11.71143;1.210183;0;0;0;0.002193474;0.00219345;10748.1;1210210
48;0.0008035709;-0.005097683;11.57623;1.196213;0;0;0;0.002530932;0.0025309;10624.03;1196244
52;0.0008571423;-0.005380599;11.63355;1.202136;0;0;0;0.002699661;0.002699624;10676.63;1202169
56;0.0009107137;-0.005815154;11.3708;1.174985;0;0;0;0.00286839;0.002868348;10435.49;1175019
60;0.001017856;-0.005975993;11.33307;1.171086;0;0;0;0.003205847;0.003205796;10400.86;1171124
64;0.001071428;-0.006156055;11.49354;1.187669;0;0;0;0.003374576;0.003374519;10548.14;1187709
68;0.001124999;-0.00641685;11.57474;1.196059;0;0;0;0.003543305;0.003543242;10622.65;1196101
72;0.001232142;-0.006595934;11.49017;1.18732;0;0;0;0.003880762;0.003880687;10545.04;1187366
76;0.001285713;-0.006735121;11.4749;1.185742;0;0;0;0.004049491;0.004049409;10531.03;1185790
80;0.001339285;-0.006932998;11.52922;1.191355;0;0;0;0.00421822;0.004218131;10580.88;1191406
84.00001;0.001392856;-0.007280047;11.27208;1.164784;0;0;0;0.004386948;0.004386852;10344.89;1164835
88.00001;0.001446428;-0.007313718;11.55104;1.19361;0;0;0;0.004555678;0.004555574;10600.9;1193664
92.00001;0.001499999;-0.007597652;11.34534;1.172354;0;0;0;0.004724406;0.004724294;10412.13;1172410
96.00001;0.00155357;-0.007814284;11.0083;1.137526;0;0;0;0.004893135;0.004893015;10102.8;1137582
100;0.001607142;-0.007699371;11.50367;1.188715;0;0;0;0.005061864;0.005061736;10557.44;1188776
104;0.001714285;-0.007728343;11.2532;1.162832;0;0;0;0.005399322;0.005399176;10327.56;1162895
108;0.001821427;-0.007840085;11.37359;1.175273;0;0;0;0.005736779;0.005736615;10438.05;1175341
112;0.001821427;-0.008057029;11.40055;1.178059;0;0;0;0.005736779;0.005736615;10462.79;1178126
116;0.00192857;-0.008371737;11.51583;1.189972;0;0;0;0.006074237;0.006074052;10568.59;1190044
120;0.001982142;-0.008473299;11.59738;1.198398;0;0;0;0.006242966;0.006242771;10643.43;1198473
124;0.002035713;-0.008792588;11.57016;1.195585;0;0;0;0.006411694;0.006411489;10618.45;1195662
128;0.002089284;-0.008958556;11.40936;1.178969;0;0;0;0.006580424;0.006580207;10470.88;1179047
132;0.002142856;-0.009317154;11.29108;1.166747;0;0;0;0.006749152;0.006748924;10362.32;1166826
136;0.002249999;-0.009557434;11.25202;1.162711;0;0;0;0.007086609;0.007086358;10326.48;1162794
140;0.00230357;-0.009819091;11.40525;1.178544;0;0;0;0.007255339;0.007255075;10467.1;1178630
144;0.002357141;-0.009895242;11.54191;1.192666;0;0;0;0.007424067;0.007423791;10592.52;1192755
148;0.002464284;-0.01011567;11.47499;1.185751;0;0;0;0.007761525;0.007761224;10531.11;1185843
152;0.002517856;-0.01045422;11.47455;1.185705;0;0;0;0.007930254;0.00792994;10530.7;1185799
156;0.002571427;-0.01060852;11.60536;1.199223;0;0;0;0.008098982;0.008098654;10650.76;1199320
160;0.002624998;-0.01085025;11.80701;1.22006;0;0;0;0.008267712;0.00826737;10835.82;1220161
164;0.00267857;-0.01097166;11.49466;1.187784;0;0;0;0.00843644;0.008436084;10549.16;1187884
168;0.002785712;-0.01121214;11.47525;1.185778;0;0;0;0.008773897;0.008773512;10531.35;1185882
172;0.002839284;-0.01159662;11.56555;1.195109;0;0;0;0.008942626;0.008942227;10614.22;1195216
176;0.002892855;-0.0118905;11.37521;1.17544;0;0;0;0.009111355;0.00911094;10439.53;1175547
180;0.002999998;-0.01232478;11.41438;1.179488;0;0;0;0.009448812;0.009448366;10475.48;1179600
184;0.003053569;-0.01261572;11.33553;1.171341;0;0;0;0.009617541;0.009617079;10403.13;1171454
188;0.003107141;-0.01287788;11.52678;1.191103;0;0;0;0.009786271;0.009785792;10578.64;1191220
192;0.003160712;-0.01347954;11.12945;1.150046;0;0;0;0.009954999;0.009954504;10214;1150160
196;0.003267855;-0.01384135;11.09331;1.146311;0;0;0;0.01029246;0.01029193;10180.82;1146429
200;0.003374998;-0.01407345;10.98933;1.135566;0;0;0;0.01062991;0.01062935;10085.4;1135687
204;0.003374998;-0.01413958;11.18463;1.155747;0;0;0;0.01062991;0.01062935;10264.63;1155870
208;0.003428569;-0.0144082;11.25969;1.163503;0;0;0;0.01079864;0.01079806;10333.52;1163629
212;0.003482141;-0.01466136;11.15538;1.152725;0;0;0;0.01096737;0.01096677;10237.79;1152852
216;0.003589283;-0.0147659;11.38008;1.175944;0;0;0;0.01130483;0.01130419;10444.01;1176077
220;0.003642855;-0.01488167;11.0763;1.144554;0;0;0;0.01147356;0.0114729;10165.22;1144685
224;0.003749998;-0.0150198;11.18607;1.155896;0;0;0;0.01181102;0.01181032;10265.95;1156033
228;0.003749998;-0.01534489;11.2305;1.160487;0;0;0;0.01181102;0.01181032;10306.73;1160624
232;0.00385714;-0.01560306;11.2909;1.166729;0;0;0;0.01214847;0.01214774;10362.16;1166870
236;0.003910712;-0.01555071;11.05778;1.142639;0;0;0;0.0123172;0.01231644;10148.21;1142780
240;0.004017854;-0.01596651;10.97699;1.134292;0;0;0;0.01265466;0.01265386;10074.08;1134435
244;0.004071426;-0.01606482;11.18592;1.155881;0;0;0;0.01282339;0.01282257;10265.82;1156029
248;0.004071426;-0.01628063;11.03;1.139769;0;0;0;0.01282339;0.01282257;10122.72;1139915
252;0.004178569;-0.01652291;11.60842;1.199539;0;0;0;0.01316085;0.01315998;10653.56;1199697
256;0.00423214;-0.01665615;11.54593;1.193082;0;0;0;0.01332957;0.01332869;10596.21;1193241
260;0.004285712;-0.01685657;11.19244;1.156555;0;0;0;0.0134983;0.01349739;10271.8;1156711
264;0.004339283;-0.01697641;11.21361;1.158742;0;0;0;0.01366703;0.0136661;10291.23;1158901
268;0.004446426;-0.01710108;11.19611;1.156934;0;0;0;0.01400449;0.01400351;10275.17;1157096
272;0.004499997;-0.01726708;11.39479;1.177464;0;0;0;0.01417322;0.01417221;10457.51;1177631
276;0.004553569;-0.017354;11.29557;1.167211;0;0;0;0.01434195;0.01434092;10366.45;1167379
280;0.004660711;-0.01745341;11.52711;1.191137;0;0;0;0.0146794;0.01467833;10578.94;1191312
284;0.004714283;-0.01749894;11.42471;1.180556;0;0;0;0.01484813;0.01484703;10484.97;1180731
288;0.004767854;-0.01763163;11.29043;1.16668;0;0;0;0.01501686;0.01501574;10361.73;1166855
292;0.004821425;-0.01756542;11.58129;1.196735;0;0;0;0.01518559;0.01518444;10628.66;1196917
296;0.004928568;-0.01767176;11.4677;1.184998;0;0;0;0.01552305;0.01552184;10524.42;1185182
300;0.00498214;-0.01771569;11.38616;1.176572;0;0;0;0.01569178;0.01569055;10449.58;1176757
304;0.00498214;-0.01774498;11.23423;1.160872;0;0;0;0.01569178;0.01569055;10310.15;1161055
308;0.005089282;-0.01778159;11.2598;1.163515;0;0;0;0.01602923;0.01602795;10333.62;1163702
312;0.005142854;-0.01784815;11.51116;1.189489;0;0;0;0.01619796;0.01619665;10564.31;1189682
316;0.005249997;-0.01788828;11.39256;1.177234;0;0;0;0.01653542;0.01653406;10455.46;1177428
320;0.005303568;-0.01792923;11.35427;1.173277;0;0;0;0.01670415;0.01670276;10420.32;1173473
324;0.005357139;-0.01798028;11.52963;1.191398;0;0;0;0.01687288;0.01687146;10581.26;1191599
328;0.005464282;-0.01779298;11.53965;1.192433;0;0;0;0.01721034;0.01720886;10590.45;1192638
332;0.005517854;-0.01787767;11.53407;1.191856;0;0;0;0.01737907;0.01737756;10585.33;1192063
336;0.005571425;-0.01784638;11.46905;1.185138;0;0;0;0.01754779;0.01754625;10525.66;1185346
340;0.005624996;-0.01779901;11.5365;1.192108;0;0;0;0.01771652;0.01771495;10587.56;1192319
344;0.005678568;-0.01792986;11.47393;1.185642;0;0;0;0.01788525;0.01788365;10530.14;1185854
348;0.00578571;-0.01781917;11.39864;1.177862;0;0;0;0.01822271;0.01822105;10461.04;1178076
352;0.005839282;-0.01780038;11.65429;1.204279;0;0;0;0.01839144;0.01838975;10695.66;1204500
356;0.005892853;-0.01781894;11.23152;1.160593;0;0;0;0.01856017;0.01855845;10307.67;1160809
360;0.005946425;-0.01772012;11.58269;1.196881;0;0;0;0.0187289;0.01872714;10629.96;1197105
364;0.005999996;-0.017513;11.45922;1.184121;0;0;0;0.01889762;0.01889584;10516.63;1184345
368;0.006107139;-0.01755391;11.574;1.195983;0;0;0;0.01923508;0.01923323;10621.98;1196213
372;0.006214282;-0.01741762;11.45963;1.184164;0;0;0;0.01957254;0.01957063;10517.01;1184396
376;0.006214282;-0.01725385;11.54593;1.193082;0;0;0;0.01957254;0.01957063;10596.21;1193315
380;0.006321425;-0.01722311;11.54558;1.193045;0;0;0;0.01991;0.01990802;10595.89;1193283
384;0.006374996;-0.01732182;11.60395;1.199078;0;0;0;0.02007873;0.02007671;10649.47;1199318
388;0.006428567;-0.01704779;11.42002;1.180071;0;0;0;0.02024746;0.02024541;10480.66;1180310
392;0.00653571;-0.01718314;11.58936;1.19757;0;0;0;0.02058491;0.0205828;10636.07;1197816
396;0.006589282;-0.01681585;11.66635;1.205526;0;0;0;0.02075364;0.02075149;10706.73;1205776
400;0.006642853;-0.01704074;11.43528;1.181648;0;0;0;0.02092237;0.02092018;10494.67;1181896
404;0.006696424;-0.01670325;11.49489;1.187808;0;0;0;0.0210911;0.02108888;10549.38;1188059
408;0.006803567;-0.01664702;11.43464;1.181582;0;0;0;0.02142856;0.02142626;10494.08;1181835
412;0.006803567;-0.01629226;11.5987;1.198535;0;0;0;0.02142856;0.02142626;10644.64;1198791
416;0.006964281;-0.01649691;11.4833;1.18661;0;0;0;0.02193474;0.02193234;10538.73;1186870
420;0.006964281;-0.01616854;11.39567;1.177555;0;0;0;0.02193474;0.02193234;10458.32;1177813
424;0.007071424;-0.01591052;11.44119;1.182258;0;0;0;0.0222722;0.02226972;10500.09;1182522
428;0.007124995;-0.01563657;11.59523;1.198177;0;0;0;0.02244093;0.02243841;10641.46;1198445
432;0.007178567;-0.0156291;11.56079;1.194617;0;0;0;0.02260966;0.0226071;10609.85;1194887
436;0.00728571;-0.01516036;11.4374;1.181867;0;0;0;0.02294712;0.02294448;10496.61;1182138
440;0.00728571;-0.01535135;11.8036;1.219708;0;0;0;0.02294712;0.02294448;10832.69;1219988
444;0.007446424;-0.01511396;11.43449;1.181566;0;0;0;0.0234533;0.02345055;10493.94;1181844
448;0.007446424;-0.01539293;11.66139;1.205013;0;0;0;0.0234533;0.02345055;10702.18;1205295
452;0.007499996;-0.0150108;11.43305;1.181418;0;0;0;0.02362203;0.02361924;10492.62;1181697
456;0.007553567;-0.01478497;11.4907;1.187374;0;0;0;0.02379076;0.02378793;10545.52;1187657
460;0.00766071;-0.01461959;11.62662;1.20142;0;0;0;0.02412822;0.02412531;10670.27;1201710
464;0.007714281;-0.01408547;11.66163;1.205037;0;0;0;0.02429695;0.024294;10702.39;1205330
468;0.007767852;-0.0137825;11.43038;1.181142;0;0;0;0.02446567;0.02446268;10490.17;1181431
472;0.007821424;-0.01387659;11.63385;1.202167;0;0;0;0.02463441;0.02463137;10676.9;1202463
476;0.007874995;-0.0139177;11.57923;1.196523;0;0;0;0.02480313;0.02480006;10626.78;1196820
480;0.008035709;-0.01347273;11.63717;1.20251;0;0;0;0.02530932;0.02530612;10679.95;1202814
484;0.008035709;-0.01360816;11.66615;1.205504;0;0;0;0.02530932;0.02530612;10706.54;1205810
488;0.008142852;-0.01339027;11.53366;1.191813;0;0;0;0.02564678;0.02564349;10584.95;1192119
492;0.008142852;-0.01336592;11.6675;1.205644;0;0;0;0.02564678;0.02564349;10707.78;1205953
496;0.008249995;-0.01281567;11.65082;1.20392;0;0;0;0.02598424;0.02598086;10692.48;1204233
500;0.008303566;-0.01278858;11.80448;1.219799;0;0;0;0.02615296;0.02614954;10833.5;1220118
504;0.008357138;-0.01234823;11.43358;1.181473;0;0;0;0.02632169;0.02631823;10493.11;1181783
508;0.008410709;-0.01224557;11.67416;1.206333;0;0;0;0.02649042;0.02648691;10713.9;1206652
512;0.008517852;-0.01176497;11.75089;1.214261;0;0;0;0.02682788;0.02682428;10784.32;1214587
516;0.008571423;-0.01168843;11.53489;1.191941;0;0;0;0.02699661;0.02699296;10586.08;1192263
520;0.008624995;-0.01129318;11.79899;1.219232;0;0;0;0.02716534;0.02716165;10828.46;1219563
524;0.008678566;-0.01111606;11.79015;1.218318;0;0;0;0.02733407;0.02733033;10820.35;1218651
528;0.008732137;-0.01056968;11.53471;1.191923;0;0;0;0.02750279;0.02749901;10585.92;1192251
532;0.00883928;-0.0109008;11.69058;1.208029;0;0;0;0.02784025;0.02783638;10728.97;1208365
536;0.008892851;-0.01067242;11.66386;1.205268;0;0;0;0.02800898;0.02800506;10704.44;1205605
540;0.008946423;-0.01019362;11.75368;1.21455;0;0;0;0.02817771;0.02817374;10786.88;1214892
544;0.008999994;-0.0100405;11.68911;1.207877;0;0;0;0.02834644;0.02834242;10727.62;1208220
548;0.009107137;-0.009878681;11.69193;1.208169;0;0;0;0.0286839;0.02867978;10730.21;1208515
552;0.009160708;-0.009701084;11.91818;1.231548;0;0;0;0.02885262;0.02884846;10937.85;1231903
556;0.00921428;-0.01012918;11.63479;1.202264;0;0;0;0.02902135;0.02901714;10677.76;1202613
560;0.009321422;-0.009927974;11.78493;1.217778;0;0;0;0.02935881;0.0293545;10815.55;1218136
564;0.009374994;-0.00964169;11.84019;1.223489;0;0;0;0.02952754;0.02952318;10866.27;1223850
568;0.009428565;-0.009505674;11.7343;1.212547;0;0;0;0.02969627;0.02969186;10769.09;1212907
572;0.009482137;-0.01024397;11.8978;1.229442;0;0;0;0.029865;0.02986054;10919.15;1229809
576;0.009589279;-0.009904091;11.76842;1.216073;0;0;0;0.03020245;0.03019789;10800.41;1216440
580;0.009642851;-0.009820617;11.78869;1.218167;0;0;0;0.03037118;0.03036657;10819;1218537
584;0.009696422;-0.01022898;11.68982;1.20795;0;0;0;0.03053991;0.03053525;10728.27;1208319
588;0.009803565;-0.01004868;11.8209;1.221495;0;0;0;0.03087737;0.0308726;10848.57;1221873
592;0.009857137;-0.01034346;11.72638;1.211728;0;0;0;0.0310461;0.03104128;10761.82;1212104
596;0.009910708;-0.01128602;11.82401;1.221817;0;0;0;0.03121483;0.03120996;10851.42;1222198
600;0.01001785;-0.01236839;11.72817;1.211913;0;0;0;0.03155228;0.03154731;10763.46;1212295
604;0.01007142;-0.01460459;11.82028;1.221432;0;0;0;0.03172101;0.03171599;10848;1221819
608;0.01012499;-0.01704595;11.81738;1.221131;0;0;0;0.03188974;0.03188466;10845.33;1221521
612;0.01017856;-0.02014033;11.83687;1.223146;0;0;0;0.03205847;0.03205333;10863.23;1223538
616;0.01023214;-0.02397239;11.69032;1.208002;0;0;0;0.0322272;0.03222201;10728.72;1208391
620;0.01028571;-0.02773174;11.86674;1.226232;0;0;0;0.03239593;0.03239068;10890.63;1226629
624;0.01039285;-0.03222324;11.91995;1.23173;0;0;0;0.03273339;0.03272803;10939.47;1232133
628;0.01049999;-0.03664361;11.8182;1.221216;0;0;0;0.03307085;0.03306538;10846.09;1221620
632;0.01055356;-0.04170733;11.80029;1.219365;0;0;0;0.03323957;0.03323405;10829.65;1219771
636;0.01060714;-0.04887722;11.82848;1.222278;0;0;0;0.0334083;0.03340272;10855.52;1222687
640;0.01060714;-0.05568718;11.78983;1.218285;0;0;0;0.0334083;0.03340272;10820.05;1218692
644.0001;0.01071428;-0.06212265;11.86186;1.225728;0;0;0;0.03374576;0.03374007;10886.16;1226142
648.0001;0.01076785;-0.07113608;11.83256;1.2227;0;0;0;0.03391449;0.03390874;10859.26;1223115
652.0001;0.01087499;-0.07960333;11.95976;1.235845;0;0;0;0.03425195;0.03424608;10976.01;1236268
656.0001;0.01092856;-0.09011148;11.76147;1.215354;0;0;0;0.03442068;0.03441475;10794.02;1215772
660.0001;0.01103571;-0.104467;11.73639;1.212762;0;0;0;0.03475814;0.03475209;10771.01;1213184
664.0001;0.01108928;-0.1214755;11.68209;1.207152;0;0;0;0.03492686;0.03492077;10721.18;1207574
668.0001;0.01108928;-0.1375375;12.17727;1.25832;0;0;0;0.03492686;0.03492077;11175.62;1258759
672.0001;0.01114285;-0.1538252;11.80786;1.220148;0;0;0;0.03509559;0.03508943;10836.6;1220576
676.0001;0.01124999;-0.1693171;11.95853;1.235717;0;0;0;0.03543305;0.03542677;10974.88;1236155
680.0001;0.01130356;-0.1807759;11.93428;1.233211;0;0;0;0.03560178;0.03559544;10952.62;1233650
684.0001;0.01135714;-0.1942231;11.80683;1.220042;0;0;0;0.03577051;0.03576411;10835.66;1220478
688.0001;0.01141071;-0.2075748;11.90106;1.229779;0;0;0;0.03593924;0.03593278;10922.14;1230221
692.0001;0.01151785;-0.2183086;11.75151;1.214325;0;0;0;0.03627669;0.03627011;10784.89;1214766
696.0001;0.01157142;-0.2311596;11.92596;1.232352;0;0;0;0.03644542;0.03643878;10944.99;1232801
700.0001;0.01162499;-0.2423958;11.75377;1.214559;0;0;0;0.03661415;0.03660745;10786.96;1215004
704.0001;0.01173213;-0.2526679;11.91763;1.23149;0;0;0;0.03695161;0.03694478;10937.34;1231946
708.0001;0.01178571;-0.2637425;11.87038;1.226608;0;0;0;0.03712033;0.03711345;10893.98;1227063
712.0001;0.01189285;-0.2729803;12.06873;1.247105;0;0;0;0.03745779;0.03745078;11076.02;1247572
716.0001;0.01189285;-0.282522;12.03288;1.2434;0;0;0;0.03745779;0.03745078;11043.11;1243866
720.0001;0.01199999;-0.2930436;11.83317;1.222764;0;0;0;0.03779525;0.03778811;10859.83;1223226
724.0001;0.01199999;-0.3051342;11.63664;1.202455;0;0;0;0.03779525;0.03778811;10679.46;1202909
728.0001;0.01210713;-0.3163818;11.80851;1.220215;0;0;0;0.0381327;0.03812543;10837.19;1220680
732.0001;0.01216071;-0.3283929;11.97371;1.237286;0;0;0;0.03830144;0.03829411;10988.81;1237760
736.0001;0.01221428;-0.338687;11.96898;1.236797;0;0;0;0.03847016;0.03846277;10984.47;1237273
740.0001;0.01232142;-0.3483943;12.14138;1.254612;0;0;0;0.03880762;0.0388001;11142.69;1255099
744.0001;0.01237499;-0.356527;11.67569;1.206491;0;0;0;0.03897635;0.03896876;10715.3;1206961
748.0001;0.01242856;-0.3663836;11.92544;1.232298;0;0;0;0.03914508;0.03913742;10944.5;1232780
752.0001;0.01248213;-0.3748968;11.95277;1.235123;0;0;0;0.03931381;0.03930608;10969.59;1235608
756.0001;0.01258928;-0.3826348;11.94858;1.234689;0;0;0;0.03965127;0.03964341;10965.74;1235178
760.0001;0.01264285;-0.3912541;11.84677;1.224169;0;0;0;0.03982;0.03981207;10872.31;1224656
764.0001;0.01269642;-0.396919;12.10321;1.250667;0;0;0;0.03998872;0.03998073;11107.65;1251168
768.0001;0.01274999;-0.4034234;11.97577;1.237498;0;0;0;0.04015746;0.0401494;10990.7;1237995
772.0001;0.01280356;-0.4103521;11.87628;1.227218;0;0;0;0.04032618;0.04031805;10899.39;1227713
776.0001;0.01291071;-0.4174882;12.12579;1.253001;0;0;0;0.04066364;0.04065538;11128.38;1253510
780.0001;0.01301785;-0.4245634;12.09176;1.249484;0;0;0;0.0410011;0.0409927;11097.14;1249996
784.0001;0.01301785;-0.4308626;12.02313;1.242393;0;0;0;0.0410011;0.0409927;11034.16;1242902
788.0001;0.01312499;-0.4383912;11.8638;1.225929;0;0;0;0.04133856;0.04133002;10887.94;1226435
792.0001;0.01317856;-0.4446009;11.86207;1.225749;0;0;0;0.04150729;0.04149867;10886.35;1226258
796.0001;0.01323213;-0.449369;11.9166;1.231384;0;0;0;0.04167601;0.04166733;10936.39;1231897
800.0001;0.01333928;-0.4533439;11.98833;1.238797;0;0;0;0.04201347;0.04200465;11002.23;1239318
804.0001;0.01339285;-0.4584001;11.93245;1.233023;0;0;0;0.0421822;0.04217331;10950.95;1233543
808.0001;0.01349999;-0.4619807;12.19312;1.259959;0;0;0;0.04251966;0.04251062;11190.17;1260494
812.0001;0.01355356;-0.4653905;12.07202;1.247445;0;0;0;0.04268839;0.04267928;11079.03;1247977
816.0001;0.01355356;-0.4687732;11.85846;1.225376;0;0;0;0.04268839;0.04267928;10883.03;1225899
820.0001;0.01366071;-0.4715444;12.13968;1.254436;0;0;0;0.04302584;0.04301659;11141.13;1254976
824.0001;0.01371428;-0.4743214;12.19327;1.259974;0;0;0;0.04319457;0.04318525;11190.31;1260518
828.0001;0.01376785;-0.4768044;12.20231;1.260908;0;0;0;0.0433633;0.0433539;11198.61;1261455
832.0001;0.01387499;-0.4785372;12.18549;1.25917;0;0;0;0.04370076;0.04369122;11183.17;1259720
836.0001;0.01392856;-0.4808821;12.00827;1.240857;0;0;0;0.04386949;0.04385987;11020.53;1241402
840.0001;0.01403571;-0.4837171;12.11713;1.252106;0;0;0;0.04420695;0.04419718;11120.43;1252659
844.0001;0.01403571;-0.4863926;12.06589;1.246811;0;0;0;0.04420695;0.04419718;11073.4;1247362
848.0001;0.01408928;-0.4885071;11.99397;1.23938;0;0;0;0.04437568;0.04436583;11007.4;1239930
852.0001;0.01414285;-0.4909858;12.20995;1.261697;0;0;0;0.0445444;0.04453448;11205.61;1262259
856.0001;0.01424999;-0.4921314;12.12934;1.253368;0;0;0;0.04488186;0.04487179;11131.64;1253930
860.0001;0.01435713;-0.4936942;12.11698;1.25209;0;0;0;0.04521932;0.0452091;11120.29;1252657
864.0001;0.0144107;-0.4951026;12.18243;1.258854;0;0;0;0.04538805;0.04537775;11180.36;1259425
868.0001;0.01446428;-0.4959293;12.27141;1.268048;0;0;0;0.04555678;0.0455464;11262.02;1268626
872.0001;0.01451785;-0.4972371;12.30938;1.271971;0;0;0;0.04572551;0.04571505;11296.86;1272553
876.0001;0.01457142;-0.4982708;12.37169;1.27841;0;0;0;0.04589424;0.04588371;11354.05;1278997
880.0001;0.01467856;-0.4989105;12.12576;1.252998;0;0;0;0.04623169;0.04622101;11128.35;1253577
884.0001;0.01478571;-0.4996827;12.09281;1.249593;0;0;0;0.04656915;0.04655831;11098.11;1250175
888.0001;0.01478571;-0.5005939;12.14761;1.255255;0;0;0;0.04656915;0.04655831;11148.4;1255840
892.0001;0.01478571;-0.5011485;12.32782;1.273877;0;0;0;0.04656915;0.04655831;11313.79;1274470
896.0001;0.01489285;-0.5022475;12.37929;1.279196;0;0;0;0.04690661;0.04689561;11361.03;1279796
900.0001;0.01499999;-0.5023281;12.24263;1.265074;0;0;0;0.04724407;0.04723291;11235.61;1265672
904.0001;0.01505356;-0.5031228;12.41303;1.282683;0;0;0;0.04741279;0.04740156;11391.99;1283291
908.0001;0.0151607;-0.5040094;12.33619;1.274742;0;0;0;0.04775025;0.04773885;11321.47;1275351
912.0001;0.0151607;-0.5047138;12.34315;1.275461;0;0;0;0.04775025;0.04773885;11327.86;1276070
916.0001;0.01521428;-0.5055993;12.47264;1.288842;0;0;0;0.04791898;0.0479075;11446.7;1289460
920.0001;0.01532142;-0.5066442;12.21896;1.262629;0;0;0;0.04825644;0.0482448;11213.89;1263238
924.0001;0.01537499;-0.5071246;12.31584;1.272639;0;0;0;0.04842516;0.04841344;11302.79;1273255
928.0001;0.01542856;-0.5069405;12.41982;1.283384;0;0;0;0.04859389;0.04858209;11398.22;1284007
932.0001;0.01548213;-0.5074504;12.4098;1.282349;0;0;0;0.04876262;0.04875073;11389.03;1282974
936.0001;0.01558928;-0.5083329;12.21708;1.262434;0;0;0;0.04910008;0.04908803;11212.16;1263054
940.0001;0.01564285;-0.5083958;12.32623;1.273713;0;0;0;0.04926881;0.04925668;11312.33;1274341
944.0001;0.01569642;-0.5086514;12.3504;1.27621;0;0;0;0.04943754;0.04942532;11334.51;1276841
948.0001;0.01574999;-0.5090339;12.42798;1.284227;0;0;0;0.04960626;0.04959397;11405.71;1284864
952.0001;0.01585713;-0.5089769;12.59885;1.301884;0;0;0;0.04994373;0.04993126;11562.53;1302534
956.0001;0.0159107;-0.5091175;12.29622;1.270612;0;0;0;0.05011245;0.0500999;11284.79;1271249
960.0001;0.01596428;-0.5096542;12.45825;1.287356;0;0;0;0.05028118;0.05026855;11433.5;1288003
964.0001;0.01601785;-0.5101879;12.49502;1.291155;0;0;0;0.05044991;0.05043719;11467.24;1291806
968.0001;0.01607142;-0.5106357;12.58675;1.300634;0;0;0;0.05061864;0.05060583;11551.42;1301292
972.0001;0.01617856;-0.5108391;12.62778;1.304873;0;0;0;0.0509561;0.05094312;11589.07;1305538
976.0001;0.01623213;-0.5111037;12.5033;1.29201;0;0;0;0.05112483;0.05111176;11474.83;1292671
980.0001;0.0162857;-0.5111364;12.45934;1.287468;0;0;0;0.05129355;0.0512804;11434.49;1288128
984.0001;0.01639285;-0.5116012;12.37733;1.278993;0;0;0;0.05163101;0.05161768;11359.22;1279653
988.0001;0.01644642;-0.512409;12.44351;1.285832;0;0;0;0.05179974;0.05178633;11419.97;1286498
992.0001;0.01649999;-0.5118886;12.1415;1.254624;0;0;0;0.05196847;0.05195497;11142.8;1255276
996.0001;0.01655356;-0.5124029;12.07608;1.247864;0;0;0;0.0521372;0.05212361;11082.75;1248514
1000;0.0166607;-0.5118208;12.4;1.281335;0;0;0;0.05247466;0.05246089;11380.03;1282008
1004;0.01671428;-0.5118572;12.23511;1.264298;0;0;0;0.05264339;0.05262954;11228.71;1264963
1008;0.01676785;-0.5119879;12.50694;1.292386;0;0;0;0.05281211;0.05279818;11478.18;1293069
1012;0.01682142;-0.512276;12.29443;1.270427;0;0;0;0.05298084;0.05296681;11283.15;1271100
1016;0.01687499;-0.5118546;12.32424;1.273507;0;0;0;0.05314957;0.05313545;11310.5;1274184
1020;0.0170357;-0.5126929;12.39309;1.280622;0;0;0;0.05365576;0.05364137;11373.7;1281309
1024;0.0170357;-0.5126793;12.2584;1.266704;0;0;0;0.05365576;0.05364137;11250.08;1267384
1028;0.01708927;-0.5129618;12.29995;1.270997;0;0;0;0.05382449;0.05381001;11288.21;1271682
1032;0.01719642;-0.5128177;12.46677;1.288236;0;0;0;0.05416194;0.05414728;11441.31;1288933
1036;0.01724999;-0.5126723;12.21964;1.262699;0;0;0;0.05433067;0.05431592;11214.51;1263385
1040;0.01735713;-0.5131628;12.27725;1.268652;0;0;0;0.05466813;0.0546532;11267.38;1269345
1044;0.01735713;-0.5124277;12.39177;1.280486;0;0;0;0.05466813;0.0546532;11372.48;1281186
1048;0.01746427;-0.5132046;12.46422;1.287971;0;0;0;0.05500559;0.05499047;11438.97;1288680
1052;0.01757142;-0.5129549;12.3326;1.274372;0;0;0;0.05534305;0.05532774;11318.18;1275077
1056;0.01757142;-0.5128782;12.34168;1.275309;0;0;0;0.05534305;0.05532774;11326.51;1276015
1060;0.01767856;-0.5124388;12.18458;1.259076;0;0;0;0.05568051;0.05566501;11182.33;1259777
1064;0.0177857;-0.5127616;12.27261;1.268173;0;0;0;0.05601796;0.05600228;11263.12;1268883
1068;0.0177857;-0.5129139;12.27012;1.267915;0;0;0;0.05601796;0.05600228;11260.83;1268625
1072;0.0177857;-0.512645;12.19855;1.26052;0;0;0;0.05601796;0.05600228;11195.16;1261226
1076;0.01789285;-0.5124097;12.17777;1.258372;0;0;0;0.05635542;0.05633955;11176.08;1259081
1080;0.01799999;-0.512122;12.26909;1.267808;0;0;0;0.05669288;0.05667681;11259.89;1268527
1084;0.01810713;-0.5120472;12.0821;1.248486;0;0;0;0.05703034;0.05701408;11088.28;1249198
1088;0.01810713;-0.5116727;12.24774;1.265602;0;0;0;0.05703034;0.05701408;11240.3;1266324
1092;0.01821427;-0.5109018;12.13454;1.253905;0;0;0;0.05736779;0.05735134;11136.41;1254624
1096;0.01821427;-0.5102515;12.22986;1.263754;0;0;0;0.05736779;0.05735134;11223.89;1264479
1100;0.01832142;-0.5098609;12.15539;1.256059;0;0;0;0.05770525;0.0576886;11155.54;1256784
1104;0.01837499;-0.5095937;11.9617;1.236045;0;0;0;0.05787398;0.05785724;10977.79;1236760
1108;0.01842856;-0.5089827;12.16344;1.256891;0;0;0;0.05804271;0.05802587;11162.93;1257620
1112;0.01848213;-0.5086921;12.25426;1.266276;0;0;0;0.05821144;0.0581945;11246.28;1267013
1116;0.0185357;-0.5082101;12.13463;1.253914;0;0;0;0.05838016;0.05836313;11136.49;1254646
1120;0.01864284;-0.5083337;12.10923;1.251289;0;0;0;0.05871762;0.05870039;11113.18;1252024
1124;0.01869642;-0.507612;12.27358;1.268273;0;0;0;0.05888636;0.05886902;11264.01;1269019
1128;0.01874999;-0.507271;12.46002;1.287538;0;0;0;0.05905508;0.05903765;11435.11;1288298
1132;0.01880356;-0.5068827;12.39929;1.281263;0;0;0;0.05922381;0.05920628;11379.38;1282021
1136;0.0189107;-0.506634;12.21479;1.262198;0;0;0;0.05956126;0.05954353;11210.06;1262950
1140;0.01896427;-0.5064427;12.21171;1.261879;0;0;0;0.05973;0.05971217;11207.23;1262633
1144;0.01901785;-0.5059773;12.14984;1.255486;0;0;0;0.05989873;0.05988079;11150.45;1256238
1148;0.01907142;-0.5058217;12.16951;1.257519;0;0;0;0.06006745;0.06004942;11168.51;1258274
1152;0.01917856;-0.50607;12.33278;1.27439;0;0;0;0.06040491;0.06038667;11318.34;1275160
1156;0.01923213;-0.5059737;12.14312;1.254791;0;0;0;0.06057364;0.0605553;11144.28;1255551
1160;0.0192857;-0.5057133;12.15413;1.255929;0;0;0;0.06074237;0.06072392;11154.38;1256692
1164;0.01939284;-0.5058379;12.33349;1.274463;0;0;0;0.06107982;0.06106118;11318.99;1275241
1168;0.01944642;-0.5055834;12.10861;1.251226;0;0;0;0.06124855;0.0612298;11112.61;1251992
1172;0.01949999;-0.5052449;12.30383;1.271398;0;0;0;0.06141728;0.06139843;11291.77;1272179
1176;0.01955356;-0.5052986;12.41844;1.283241;0;0;0;0.06158601;0.06156705;11396.95;1284031
1180;0.0196607;-0.5051066;12.28489;1.269441;0;0;0;0.06192347;0.0619043;11274.39;1270227
1184;0.01971427;-0.5050577;12.25391;1.26624;0;0;0;0.0620922;0.06207293;11245.96;1267026
1188;0.01976784;-0.5051634;12.31249;1.272293;0;0;0;0.06226092;0.06224155;11299.72;1273085
1192;0.01982142;-0.5052105;12.21996;1.262732;0;0;0;0.06242966;0.06241018;11214.8;1263520
1196;0.01992856;-0.5048006;12.28307;1.269253;0;0;0;0.06276712;0.06274743;11272.72;1270049
1200;0.0200357;-0.5045757;12.51449;1.293166;0;0;0;0.06310457;0.06308466;11485.1;1293982
1204;0.0200357;-0.504852;12.45303;1.286815;0;0;0;0.06310457;0.06308466;11428.7;1287627
1208;0.02014285;-0.5049808;12.52838;1.294601;0;0;0;0.06344203;0.06342192;11497.85;1295423
1212;0.02019641;-0.5048131;12.36799;1.278028;0;0;0;0.06361075;0.06359053;11350.65;1278841
1216;0.02024999;-0.5046767;12.31043;1.272081;0;0;0;0.06377948;0.06375915;11297.83;1272892
1220;0.02035713;-0.5047657;12.58669;1.300628;0;0;0;0.06411694;0.0640964;11551.37;1301462
1224;0.0204107;-0.5043943;12.42079;1.283484;0;0;0;0.06428567;0.06426502;11399.11;1284309
1228;0.02046427;-0.5046247;12.50926;1.292626;0;0;0;0.0644544;0.06443364;11480.31;1293459
1232;0.02046427;-0.5046619;12.36584;1.277807;0;0;0;0.0644544;0.06443364;11348.69;1278630
1236;0.02057142;-0.5042251;12.70151;1.312492;0;0;0;0.06479186;0.06477088;11656.74;1313342
1240;0.02062499;-0.5046524;12.41717;1.28311;0;0;0;0.06496058;0.0649395;11395.79;1283944
1244;0.02073213;-0.5042466;12.3839;1.279673;0;0;0;0.06529804;0.06527674;11365.26;1280508
1248;0.02073213;-0.5040627;12.67952;1.310219;0;0;0;0.06529804;0.06527674;11636.56;1311075
1252;0.02089284;-0.5043638;12.65194;1.30737;0;0;0;0.06580423;0.06578258;11611.25;1308230
1256;0.02089284;-0.5039192;12.71475;1.31386;0;0;0;0.06580423;0.06578258;11668.9;1314725
1260;0.02099999;-0.5041357;12.58065;1.300003;0;0;0;0.06614169;0.06611983;11545.82;1300862
1264;0.02110713;-0.5037304;12.64971;1.307139;0;0;0;0.06647915;0.06645706;11609.2;1308008
1268;0.02110713;-0.5040832;12.85459;1.32831;0;0;0;0.06647915;0.06645706;11797.23;1329193
1272;0.02121427;-0.5040238;12.61098;1.303137;0;0;0;0.06681661;0.0667943;11573.66;1304008
1276;0.02126784;-0.5042804;12.63303;1.305416;0;0;0;0.06698534;0.06696291;11593.9;1306290
1280;0.02132141;-0.5041758;12.69426;1.311742;0;0;0;0.06715406;0.06713152;11650.08;1312623
1284;0.02137499;-0.5035475;12.6155;1.303604;0;0;0;0.06732279;0.06730014;11577.81;1304482
1288;0.02142856;-0.5034938;12.636;1.305722;0;0;0;0.06749152;0.06746875;11596.62;1306604
1292;0.0215357;-0.5035618;12.63388;1.305504;0;0;0;0.06782898;0.06780598;11594.68;1306389
1296;0.02158927;-0.5035226;12.68703;1.310996;0;0;0;0.06799771;0.0679746;11643.46;1311887
1300;0.02164284;-0.5035185;12.43655;1.285113;0;0;0;0.06816643;0.06814321;11413.58;1285989
1304;0.02169641;-0.5033285;12.61177;1.303219;0;0;0;0.06833516;0.06831183;11574.38;1304110
1308;0.02180356;-0.5032614;12.75363;1.317878;0;0;0;0.06867262;0.06864905;11704.58;1318783
1312;0.02185713;-0.5033835;12.78009;1.320612;0;0;0;0.06884135;0.06881767;11728.86;1321521
1316;0.0219107;-0.5028724;12.57066;1.298971;0;0;0;0.06901008;0.06898628;11536.66;1299867
1320;0.02201784;-0.5031939;12.83388;1.326171;0;0;0;0.06934753;0.0693235;11778.23;1327090
1324;0.02201784;-0.5031782;12.52841;1.294605;0;0;0;0.06934753;0.0693235;11497.88;1295502
1328;0.02212499;-0.503284;12.69672;1.311997;0;0;0;0.069685;0.06966073;11652.35;1312912
1332;0.02217856;-0.5030955;12.79263;1.321908;0;0;0;0.06985372;0.06982934;11740.36;1322831
1336;0.02223213;-0.5029713;12.78734;1.321361;0;0;0;0.07002245;0.06999794;11735.51;1322287
1340;0.0222857;-0.5029936;12.74015;1.316485;0;0;0;0.07019117;0.07016655;11692.21;1317409
1344;0.02239284;-0.5028827;12.87132;1.33004;0;0;0;0.07052864;0.07050378;11812.59;1330978
1348;0.02244641;-0.5029439;12.52438;1.294189;0;0;0;0.07069737;0.07067239;11494.18;1295104
1352;0.02249998;-0.5029751;12.88283;1.331229;0;0;0;0.07086609;0.070841;11823.15;1332172
1356;0.02255356;-0.5026152;12.24166;1.264974;0;0;0;0.07103483;0.07100961;11234.72;1265873
1360;0.02260713;-0.5027306;12.47869;1.289467;0;0;0;0.07120355;0.07117821;11452.25;1290386
1364;0.02271427;-0.50242;12.43177;1.284618;0;0;0;0.07154101;0.07151543;11409.19;1285538
1368;0.02276784;-0.5022975;12.63538;1.305659;0;0;0;0.07170974;0.07168404;11596.05;1306595
1372;0.02282141;-0.5024829;12.59377;1.301359;0;0;0;0.07187847;0.07185265;11557.87;1302294
1376;0.02287499;-0.5024135;12.67717;1.309976;0;0;0;0.0720472;0.07202126;11634.4;1310920
1380;0.0230357;-0.5021226;12.58919;1.300886;0;0;0;0.07255339;0.07252708;11553.66;1301829
1384;0.0230357;-0.5020845;12.71234;1.313612;0;0;0;0.07255339;0.07252708;11666.69;1314565
1388;0.02308927;-0.5015224;12.83139;1.325913;0;0;0;0.07272211;0.07269568;11775.94;1326877
1392;0.02314284;-0.5020126;12.73064;1.315502;0;0;0;0.07289084;0.07286428;11683.47;1316461
1396;0.02324999;-0.5021342;12.6754;1.309794;0;0;0;0.0732283;0.0732015;11632.78;1310754
1400;0.02330356;-0.5015647;12.56602;1.298491;0;0;0;0.07339703;0.0733701;11532.4;1299445
1404;0.02335713;-0.501696;12.73319;1.315766;0;0;0;0.07356575;0.07353871;11685.82;1316734
1408;0.02346427;-0.5014561;12.98238;1.341515;0;0;0;0.07390321;0.07387592;11914.51;1342507
1412;0.02351784;-0.5014317;12.80255;1.322933;0;0;0;0.07407194;0.07404452;11749.47;1323913
1416;0.02357141;-0.501321;12.6934;1.311654;0;0;0;0.07424067;0.07421313;11649.3;1312628
1420;0.02367856;-0.5013004;12.58995;1.300964;0;0;0;0.07457813;0.07455033;11554.36;1301935
1424;0.02373213;-0.5010863;12.57695;1.29962;0;0;0;0.07474685;0.07471894;11542.42;1300592
1428;0.0237857;-0.5008766;12.6964;1.311964;0;0;0;0.07491559;0.07488754;11652.05;1312947
1432;0.02383927;-0.5009091;12.578;1.29973;0;0;0;0.07508431;0.07505614;11543.39;1300705
1436;0.02394641;-0.5007621;12.68066;1.310338;0;0;0;0.07542177;0.07539335;11637.61;1311326
1440;0.02399998;-0.5006607;12.35237;1.276414;0;0;0;0.0755905;0.07556194;11336.32;1277379
1444;0.02405356;-0.5007019;12.54799;1.296628;0;0;0;0.07575923;0.07573055;11515.85;1297611
1448;0.0241607;-0.5003148;12.67256;1.3095;0;0;0;0.07609669;0.07606775;11630.17;1310497
1452;0.0241607;-0.5004337;12.62566;1.304654;0;0;0;0.07609669;0.07606775;11587.13;1305647
1456;0.02421427;-0.500112;12.58126;1.300066;0;0;0;0.07626541;0.07623634;11546.38;1301058
1460;0.02432141;-0.4999113;12.70721;1.313081;0;0;0;0.07660288;0.07657355;11661.97;1314086
1464;0.02437499;-0.4997005;12.46049;1.287586;0;0;0;0.07677161;0.07674215;11435.54;1288575
1468;0.02448213;-0.499577;12.45332;1.286846;0;0;0;0.07710906;0.07707935;11428.97;1287838
1472;0.0245357;-0.4996166;12.64795;1.306957;0;0;0;0.07727779;0.07724794;11607.59;1307967
1476;0.0245357;-0.4993395;12.60654;1.302679;0;0;0;0.07727779;0.07724794;11569.59;1303686
1480;0.02464284;-0.4991974;12.60819;1.302849;0;0;0;0.07761525;0.07758514;11571.1;1303860
1484;0.02474998;-0.499189;12.89159;1.332133;0;0;0;0.07795271;0.07792234;11831.18;1333172
1488;0.02474998;-0.499074;12.7758;1.320169;0;0;0;0.07795271;0.07792234;11724.92;1321198
1492;0.02485713;-0.4991057;12.85112;1.327952;0;0;0;0.07829016;0.07825953;11794.05;1328991
1496;0.02485713;-0.498958;12.66839;1.309069;0;0;0;0.07829016;0.07825953;11626.34;1310094
1500;0.02496427;-0.4988425;12.52661;1.294419;0;0;0;0.07862762;0.07859673;11496.23;1295437
1504;0.02507141;-0.4988519;12.72042;1.314446;0;0;0;0.07896508;0.07893392;11674.1;1315484
1508;0.02507141;-0.4985728;12.42175;1.283584;0;0;0;0.07896508;0.07893392;11400;1284597
1512;0.02517856;-0.4984726;12.72773;1.315202;0;0;0;0.07930254;0.07927112;11680.81;1316245
1516;0.0252857;-0.4984374;12.84208;1.327017;0;0;0;0.07963999;0.0796083;11785.75;1328074
1520;0.0252857;-0.498076;12.6804;1.31031;0;0;0;0.07963999;0.0796083;11637.37;1311354
1524;0.02539284;-0.4980389;12.90976;1.334011;0;0;0;0.07997745;0.07994548;11847.86;1335078
1528;0.02549998;-0.4977576;12.68289;1.310568;0;0;0;0.08031491;0.08028268;11639.66;1311621
1532;0.02549998;-0.4977654;12.7102;1.31339;0;0;0;0.08031491;0.08028268;11664.72;1314445
1536;0.02560713;-0.4978244;12.68122;1.310395;0;0;0;0.08065236;0.08061986;11638.12;1311452
1540;0.0256607;-0.4974179;12.89162;1.332136;0;0;0;0.0808211;0.08078845;11831.21;1333213
1544;0.02571427;-0.4974902;12.79741;1.322402;0;0;0;0.08098982;0.08095704;11744.76;1323473
1548;0.02582141;-0.4971097;12.6969;1.312016;0;0;0;0.08132728;0.08129423;11652.51;1313083
1552;0.02587498;-0.4971039;12.72168;1.314577;0;0;0;0.08149601;0.08146282;11675.25;1315648
1556;0.02592855;-0.4968825;12.78602;1.321225;0;0;0;0.08166474;0.08163141;11734.3;1322304
1560;0.02598213;-0.4967305;12.70268;1.312613;0;0;0;0.08183347;0.0818;11657.82;1313687
1564;0.0260357;-0.4966528;12.68307;1.310586;0;0;0;0.0820022;0.08196859;11639.82;1311661
1568;0.02608927;-0.4965961;12.79319;1.321965;0;0;0;0.08217093;0.08213719;11740.88;1323051
1572;0.02614284;-0.4967217;12.65908;1.308107;0;0;0;0.08233966;0.08230578;11617.8;1309184
1576;0.02624998;-0.4962932;12.71408;1.313791;0;0;0;0.08267711;0.08264296;11668.28;1314877
1580;0.02630356;-0.4962369;12.82017;1.324754;0;0;0;0.08284584;0.08281155;11765.64;1325851
1584;0.02635713;-0.4960456;13.15548;1.359403;0;0;0;0.08301457;0.08298013;12073.37;1360531
1588;0.02646427;-0.495616;12.90512;1.333532;0;0;0;0.08335202;0.08331731;11843.61;1334643
1592;0.02651784;-0.4953901;12.72306;1.314719;0;0;0;0.08352076;0.08348589;11676.52;1315817
1596;0.02657141;-0.4952203;12.95951;1.339152;0;0;0;0.08368948;0.08365448;11893.52;1340272
1600;0.02667855;-0.4947917;13.20159;1.364167;0;0;0;0.08402694;0.08399166;12115.68;1365313
1604;0.02667855;-0.4947351;13.01732;1.345126;0;0;0;0.08402694;0.08399166;11946.58;1346256
1608;0.0267857;-0.4943596;12.93319;1.336433;0;0;0;0.0843644;0.08432883;11869.37;1337560
1612;0.02683927;-0.4940864;12.66069;1.308274;0;0;0;0.08453313;0.08449742;11619.28;1309380
1616;0.02694641;-0.4940023;12.56303;1.298182;0;0;0;0.08487058;0.08483459;11529.65;1299284
1620;0.02694641;-0.4937776;12.76247;1.318791;0;0;0;0.08487058;0.08483459;11712.69;1319910
1624;0.02699998;-0.49311;12.73651;1.316109;0;0;0;0.08503932;0.08500318;11688.86;1317228
1628;0.02710713;-0.4925188;12.78153;1.32076;0;0;0;0.08537678;0.08534035;11730.18;1321888
1632;0.02721427;-0.4926777;12.67123;1.309363;0;0;0;0.08571424;0.08567752;11628.96;1310486
1636;0.02721427;-0.4920923;12.61938;1.304005;0;0;0;0.08571424;0.08567752;11581.37;1305123
1640;0.02732141;-0.491862;12.59195;1.301171;0;0;0;0.08605169;0.08601469;11556.19;1302291
1644;0.02742855;-0.4914144;12.51745;1.293473;0;0;0;0.08638915;0.08635186;11487.83;1294590
1648;0.02742855;-0.4908215;12.47085;1.288657;0;0;0;0.08638915;0.08635186;11445.06;1289770
1652;0.0275357;-0.4908461;12.33437;1.274554;0;0;0;0.08672661;0.08668902;11319.8;1275659
1656;0.0275357;-0.4901438;12.42824;1.284254;0;0;0;0.08672661;0.08668902;11405.95;1285368
1660;0.02764284;-0.4901065;12.60646;1.30267;0;0;0;0.08706406;0.08702618;11569.51;1303804
1664;0.02774998;-0.4893719;12.41979;1.283381;0;0;0;0.08740152;0.08736335;11398.19;1284502
1668;0.02774998;-0.4894996;12.30597;1.27162;0;0;0;0.08740152;0.08736335;11293.74;1272731
1672;0.02785712;-0.4890336;12.27364;1.268279;0;0;0;0.08773898;0.08770051;11264.07;1269391
1676;0.02785712;-0.4887543;12.13713;1.254172;0;0;0;0.08773898;0.08770051;11138.78;1255272
1680;0.02796427;-0.4885466;12.30189;1.271198;0;0;0;0.08807644;0.08803767;11289.99;1272317
1684;0.02807141;-0.4880145;12.36135;1.277342;0;0;0;0.08841389;0.08837483;11344.56;1278472
1688;0.02807141;-0.4875553;12.21098;1.261803;0;0;0;0.08841389;0.08837483;11206.56;1262919
1692;0.02817855;-0.4870513;12.35956;1.277157;0;0;0;0.08875135;0.08871199;11342.92;1278291
1696;0.0282857;-0.4864922;12.16963;1.257531;0;0;0;0.08908881;0.08904914;11168.61;1258651
1700;0.0282857;-0.4861585;12.01024;1.241061;0;0;0;0.08908881;0.08904914;11022.33;1242166
1704;0.02839284;-0.4847422;12.05482;1.245667;0;0;0;0.08942626;0.08938631;11063.24;1246781
1708;0.02844641;-0.4843233;12.19738;1.260399;0;0;0;0.089595;0.08955488;11194.08;1261528
1712;0.02849998;-0.4830416;12.12914;1.253347;0;0;0;0.08976372;0.08972345;11131.45;1254472
1716;0.02855355;-0.4820859;11.90197;1.229873;0;0;0;0.08993245;0.08989203;10922.97;1230979
1720;0.02860713;-0.4807783;12.01004;1.24104;0;0;0;0.09010118;0.09006062;11022.14;1242158
1724;0.02871427;-0.4798636;12.05399;1.245582;0;0;0;0.09043863;0.09039776;11062.49;1246708
1728;0.02876784;-0.4786672;12.17539;1.258126;0;0;0;0.09060737;0.09056634;11173.9;1259266
1732;0.02882141;-0.4770928;12.06274;1.246486;0;0;0;0.09077609;0.09073492;11070.52;1247618
1736;0.02887498;-0.4761088;12.05728;1.245922;0;0;0;0.09094483;0.0909035;11065.51;1247055
1740;0.02892855;-0.4746304;11.98296;1.238242;0;0;0;0.09111355;0.09107207;10997.3;1239370
1744;0.0290357;-0.4734926;12.13848;1.254312;0;0;0;0.09145101;0.09140922;11140.02;1255459
1748;0.02908927;-0.4723026;11.92403;1.232152;0;0;0;0.09161974;0.09157779;10943.21;1233281
1752;0.02914284;-0.4709509;12.06483;1.246701;0;0;0;0.09178847;0.09174637;11072.43;1247846
1756;0.02924998;-0.4697327;12.39063;1.280367;0;0;0;0.09212593;0.09208352;11371.43;1281547
1760;0.02930355;-0.468117;12.32118;1.273191;0;0;0;0.09229466;0.09225209;11307.7;1274366
1764;0.02935712;-0.4666209;12.01015;1.241052;0;0;0;0.09246338;0.09242066;11022.25;1242199
1768;0.02946427;-0.464494;12.23873;1.264671;0;0;0;0.09280084;0.09275781;11232.02;1265844
1772;0.02951784;-0.4624611;12.02155;1.242229;0;0;0;0.09296957;0.09292638;11032.71;1243384
1776;0.02957141;-0.4598069;12.16167;1.256709;0;0;0;0.0931383;0.09309495;11161.31;1257879
1780;0.02962498;-0.4567999;12.0811;1.248383;0;0;0;0.09330703;0.09326352;11087.36;1249547
1784;0.02967855;-0.4538094;12.14226;1.254703;0;0;0;0.09347575;0.09343209;11143.5;1255876
1788;0.0297857;-0.450137;11.89901;1.229567;0;0;0;0.09381322;0.09376924;10920.25;1230720
1792;0.02983927;-0.447002;12.16023;1.25656;0;0;0;0.09398194;0.09393781;11159.99;1257741
1796;0.02989284;-0.4429651;12.3038;1.271395;0;0;0;0.09415067;0.09410638;11291.74;1272592
1800;0.02994641;-0.438637;12.27611;1.268534;0;0;0;0.0943194;0.09427495;11266.33;1269730
1804;0.02999998;-0.4331884;12.00352;1.240366;0;0;0;0.09448814;0.09444352;11016.16;1241538
1808;0.03010712;-0.426942;12.17859;1.258457;0;0;0;0.09482559;0.09478066;11176.83;1259650
1812;0.0301607;-0.4178412;12.06809;1.247038;0;0;0;0.09499431;0.09494922;11075.42;1248223
1816;0.03021427;-0.4066011;12.14241;1.254718;0;0;0;0.09516305;0.09511779;11143.63;1255912
1820;0.03032141;-0.3927772;11.97923;1.237856;0;0;0;0.09550051;0.09545493;10993.88;1239039
1824;0.03037498;-0.3759845;11.99867;1.239865;0;0;0;0.09566923;0.0956235;11011.72;1241051
1828;0.03048212;-0.3557002;12.07285;1.24753;0;0;0;0.09600669;0.09596063;11079.79;1248728
1832;0.03053569;-0.3309112;12.0845;1.248734;0;0;0;0.0961754;0.09612919;11090.49;1249935
1836;0.03053569;-0.3022532;11.92523;1.232276;0;0;0;0.0961754;0.09612919;10944.32;1233461
1840;0.03064284;-0.2671374;11.96291;1.236169;0;0;0;0.09651288;0.09646633;10978.89;1237362
1844;0.03069641;-0.2297778;12.20478;1.261163;0;0;0;0.0966816;0.09663489;11200.87;1262382
1848;0.03080355;-0.190087;12.22213;1.262957;0;0;0;0.09701905;0.09697202;11216.8;1264182
1852;0.03085712;-0.1521176;12.46689;1.288248;0;0;0;0.09718779;0.09714059;11441.42;1289500
1856;0.03096426;-0.1174633;12.13868;1.254333;0;0;0;0.09752524;0.09747771;11140.21;1255556
1860;0.03096426;-0.0876401;12.159;1.256433;0;0;0;0.09752524;0.09747771;11158.86;1257658
1864;0.03101784;-0.0635673;11.91921;1.231654;0;0;0;0.09769397;0.09764629;10938.79;1232858
1868;0.03107141;-0.04569361;12.05587;1.245776;0;0;0;0.0978627;0.09781484;11064.21;1246995
1872;0.03117855;-0.0297616;12.22813;1.263575;0;0;0;0.09820016;0.09815198;11222.3;1264816
1876;0.03123212;-0.0191105;12.12397;1.252813;0;0;0;0.09836888;0.09832053;11126.71;1254045
1880;0.03133926;-0.01215023;12.14347;1.254827;0;0;0;0.09870634;0.09865766;11144.6;1256066
1884;0.03144641;-0.008000336;12.21171;1.261879;0;0;0;0.09904381;0.09899479;11207.23;1263129
1888;0.03144641;-0.004831054;12.08785;1.24908;0;0;0;0.09904381;0.09899479;11093.56;1250318
1892;0.03149998;-0.002700802;11.99926;1.239926;0;0;0;0.09921253;0.09916335;11012.25;1241156
1896;0.03155355;-0.001263746;12.01159;1.2412;0;0;0;0.09938127;0.09933192;11023.57;1242434
1900;0.03166069;-0.0007501822;12.08289;1.248568;0;0;0;0.09971872;0.09966903;11089.01;1249813
1904;0.03166069;-0.0001293792;12.16038;1.256575;0;0;0;0.09971872;0.09966903;11160.12;1257828
1908;0.03176784;8.549003e-005;12.10462;1.250813;0;0;0;0.1000562;0.1000062;11108.95;1252065
1912;0.03187498;0.0001424178;12.12879;1.25331;0;0;0;0.1003936;0.1003433;11131.13;1254569
1916;0.03192855;0.0001384634;12.22084;1.262823;0;0;0;0.1005624;0.1005118;11215.61;1264093
1920;0.03198212;6.058894e-005;12.22522;1.263275;0;0;0;0.1007311;0.1006804;11219.63;1264548
1924;0.03208927;0.000167593;12.31866;1.27293;0;0;0;0.1010685;0.1010175;11305.38;1274217
1928;0.03208927;0.0001972314;12.04219;1.244362;0;0;0;0.1010685;0.1010175;11051.65;1245620
1932;0.03214283;0.0001214712;12.83112;1.325885;0;0;0;0.1012373;0.1011861;11775.69;1327228
1936;0.03224998;2.640882e-005;12.2024;1.260917;0;0;0;0.1015747;0.1015232;11198.69;1262198
1940;0.03230355;-7.961629e-005;12.25414;1.266264;0;0;0;0.1017435;0.1016917;11246.17;1267552
1944;0.03235712;-1.477965e-005;12.29373;1.270354;0;0;0;0.1019122;0.1018603;11282.5;1271649
1948;0.03246427;-0.000133921;12.12576;1.252998;0;0;0;0.1022497;0.1021974;11128.35;1254279
1952;0.03251783;-6.007918e-005;12.37548;1.278802;0;0;0;0.1024184;0.102366;11357.53;1280111
1956;0.03257141;-0.0007680358;11.92256;1.232;0;0;0;0.1025871;0.1025345;10941.86;1233264
1960;0.03262498;-0.000587425;12.25605;1.266461;0;0;0;0.1027558;0.1027031;11247.92;1267763
1964;0.03267855;-0.0004279567;12.11636;1.252027;0;0;0;0.1029246;0.1028716;11119.73;1253315
1968;0.03273212;-0.0004237282;12.13909;1.254375;0;0;0;0.1030933;0.1030402;11140.59;1255669
1972;0.03283926;-0.0007895306;12.21268;1.261979;0;0;0;0.1034308;0.1033773;11208.12;1263285
1976;0.03289284;-0.0007213268;11.92018;1.231754;0;0;0;0.1035995;0.1035459;10939.68;1233031
1980;0.03294641;-0.001402738;12.14479;1.254964;0;0;0;0.1037682;0.1037144;11145.81;1256266
1984;0.03299998;-0.001747006;12.14599;1.255088;0;0;0;0.1039369;0.103883;11146.92;1256393
1988;0.03310712;-0.002244596;12.16411;1.256961;0;0;0;0.1042744;0.1042201;11163.55;1258271
1992;0.03316069;-0.002213901;12.35615;1.276805;0;0;0;0.1044431;0.1043886;11339.79;1278139
1996;0.03321426;-0.00244678;12.20029;1.260699;0;0;0;0.1046119;0.1045572;11196.75;1262018
2000;0.03332141;-0.002939045;12.38041;1.279311;0;0;0;0.1049493;0.1048943;11362.05;1280654
2004;0.03337498;-0.003240363;12.19483;1.260134;0;0;0;0.105118;0.1050628;11191.74;1261459
2008;0.03342855;-0.003583653;11.94267;1.234079;0;0;0;0.1052868;0.1052314;10960.32;1235378
2012;0.03348212;-0.00353714;12.162;1.256742;0;0;0;0.1054555;0.1053999;11161.61;1258067
2016;0.03358926;-0.004231824;12.17806;1.258402;0;0;0;0.105793;0.105737;11176.35;1259733
2020;0.03364283;-0.003888143;12.2202;1.262756;0;0;0;0.1059617;0.1059056;11215.02;1264094
2024;0.03369641;-0.00433875;12.32617;1.273707;0;0;0;0.1061304;0.1060741;11312.28;1275059
2028;0.03380355;-0.004576836;12.23209;1.263985;0;0;0;0.1064679;0.1064112;11225.93;1265331
2032;0.03385712;-0.004947415;12.09314;1.249627;0;0;0;0.1066366;0.1065798;11098.41;1250959
2035.236;0.03396427;-0.00477624;12.06501;1.24672;0;0;0;0.1069741;0.1069169;11072.59;1248053