File: Ensayos/Resistencia/comp/Clavo6/Clavo6g.raw
"Test Type";"Manual"
"Method Name:";"C:\INSTRON\user\template\CYCLE.MTM"
"Name:";""
"Operator ID:";""
"Company:";""
"Lab name:";""
"Test date:";"09/06/2017"
"Temperature:";""
"Humidity:";""
"Note 1:";""
"Note 2:";""
"Note 3:";""
"Geometry:";"Rectangular"
"Specimen";1
"Specimen name:";""
"Width:";0.250000;"in"
"Thickness:";0.060000;"in"
"Length:";1.250000;"in"
"Diameter:";0.039370;"in"
"Inner diameter:";0.019685;"in"
"Outer diameter:";0.039370;"in"
"Wall thickness:";0.019685;"in"
"Area:";0.015000;"in*in"
"Linear density:";1.000000;"den"
"Sled weight:";2.204623;"lbf"
"Loading span:";0.000000;"mm"
"Support span:";1.000000;"mm"
"Span ratio:";"2"
"Fixture type:";"3-point"
"Comment:";""
"Included"
"Final Width:";0.250000;"in"
"Final Thickness:";0.060000;"in"
"Final Length:";1.250000;"in"
"Final Diameter:";0.039370;"in"
"Final Inner diameter:";0.019685;"in"
"Final Outer diameter:";0.039370;"in"
"Final Wall thickness:";0.019685;"in"
"Final Area:";0.015000;"in*in"
"Final Linear density:";1.000000;"den"
"Time sec";"Extension mm";"Strain 1 %";"Load N";"Stress MPa";"Cycle Count ";"Total Cycle Count ";"Repetitions Count ";"Strain [Exten.] %";"True strain %";"Tenacity gf/tex";"True stress Pa"
0;0;0.0002393092;51.98947;5.372256;0;0;0;0;0;47713.06;5372256
4;0.006749996;-0.001375342;68.32406;7.060167;0;0;0;0.02125983;0.02125757;62704.04;7061668
8;0.01333928;-0.00263073;81.8451;8.457344;0;0;0;0.04201347;0.04200465;75112.9;8460897
12;0.02014285;-0.004455553;97.18576;10.04255;0;0;0;0.06344203;0.06342192;89191.71;1.004892e+007
16;0.0267857;-0.006100587;112.6395;11.63944;0;0;0;0.0843644;0.08432883;103374.3;1.164926e+007
20;0.03332141;-0.007690494;127.3947;13.16414;0;0;0;0.1049493;0.1048943;116915.8;1.317796e+007
24;0.0400714;-0.009722982;142.8652;14.76276;0;0;0;0.1262091;0.1261296;131113.7;1.478139e+007
28;0.04671425;-0.01159823;158.2805;16.35569;0;0;0;0.1471315;0.1470234;145261.1;1.637975e+007
32;0.05330354;-0.01325204;173.0215;17.87892;0;0;0;0.1678852;0.1677444;158789.5;1.790894e+007
36;0.05999997;-0.01518367;188.2462;19.45215;0;0;0;0.1889763;0.1887979;172761.9;1.948891e+007
40;0.06669638;-0.01706832;203.6807;21.04705;0;0;0;0.2100673;0.209847;186926.8;2.109126e+007
44;0.07328566;-0.01913181;219.269;22.65784;0;0;0;0.230821;0.230555;201232.9;2.271014e+007
48;0.07998209;-0.02092187;235.5142;24.33652;0;0;0;0.2519121;0.2515953;216141.9;2.439782e+007
52;0.08662494;-0.02300353;252.3168;26.07279;0;0;0;0.2728345;0.2724629;231562.4;2.614393e+007
56;0.09332137;-0.0251115;269.5564;27.85421;0;0;0;0.2939256;0.2934945;247383.9;2.793608e+007
60;0.09996422;-0.02746066;286.6987;29.62559;0;0;0;0.3148479;0.3143533;263116.2;2.971887e+007
64;0.1066071;-0.02971585;304.6198;31.47744;0;0;0;0.3357703;0.3352079;279563.2;3.158313e+007
68;0.1133571;-0.0321361;323.6707;33.44604;0;0;0;0.3570302;0.3563943;297047.1;3.356546e+007
72;0.1200535;-0.034645;343.5333;35.49852;0;0;0;0.3781212;0.3774082;315275.9;3.563274e+007
76;0.1266428;-0.03719806;362.4607;37.45435;0;0;0;0.3988749;0.3980815;332646.3;3.760374e+007
80;0.1333928;-0.03983631;383.6455;39.64345;0;0;0;0.4201347;0.4192546;352088.6;3.981001e+007
84.00001;0.1400356;-0.04267033;404.7531;41.82457;0;0;0;0.4410571;0.4400873;371460;4.200904e+007
88.00001;0.1466785;-0.04522746;425.5068;43.96912;0;0;0;0.4619794;0.4609156;390506.5;4.417225e+007
92.00001;0.1534285;-0.04832929;447.4026;46.23169;0;0;0;0.4832393;0.4820754;410601.3;4.64551e+007
96.00001;0.1601249;-0.0512626;469.8946;48.55588;0;0;0;0.5043303;0.5030628;431243.3;4.880076e+007
100;0.1667142;-0.05417523;491.9178;50.83161;0;0;0;0.525084;0.5237103;451454.9;5.109852e+007
104;0.1734642;-0.05716023;515.5044;53.26889;0;0;0;0.5463438;0.5448568;473101.3;5.355992e+007
108;0.180107;-0.0603485;538.4616;55.64114;0;0;0;0.5672662;0.5656634;494170.2;5.595677e+007
112;0.1866427;-0.06328713;561.4305;58.01461;0;0;0;0.5878512;0.58613;515249.8;5.835565e+007
116;0.1933927;-0.06649576;585.7684;60.52952;0;0;0;0.609111;0.6072634;537585.8;6.089822e+007
120;0.2000892;-0.0694914;609.9393;63.02719;0;0;0;0.6302021;0.6282246;559768.5;6.342439e+007
124;0.2066785;-0.07249644;633.5198;65.46384;0;0;0;0.6509557;0.6488462;581409.4;6.588998e+007
128;0.2133749;-0.07607812;659.0103;68.09786;0;0;0;0.6720468;0.6697986;604803.1;6.855551e+007
132;0.2200177;-0.07930272;684.4878;70.73055;0;0;0;0.6929692;0.6905792;628184.9;7.122069e+007
136;0.226607;-0.0826476;710.1615;73.3835;0;0;0;0.7137229;0.7111879;651746.9;7.390726e+007
140;0.2333034;-0.08605294;736.5367;76.10895;0;0;0;0.734814;0.7321274;675952.6;7.666821e+007
144;0.2399999;-0.08951466;763.3373;78.87834;0;0;0;0.7559051;0.7530624;700548.7;7.947459e+007
148;0.2466963;-0.09320533;790.6123;81.69677;0;0;0;0.7769961;0.7739931;725580.1;8.233155e+007
152;0.2532855;-0.09700093;818.1105;84.53825;0;0;0;0.7977498;0.7945845;750816.4;8.521265e+007
156;0.259982;-0.1007699;846.6526;87.48761;0;0;0;0.8188408;0.8155065;777010.8;8.820399e+007
160;0.2666784;-0.1047879;875.3919;90.45735;0;0;0;0.839932;0.8364242;803386.3;9.121713e+007
164;0.2733213;-0.1087627;903.7333;93.38596;0;0;0;0.8608543;0.8571701;829396.4;9.418988e+007
168;0.2799641;-0.1125298;932.2194;96.32953;0;0;0;0.8817767;0.8779117;855539.3;9.717894e+007
172;0.2867141;-0.1165716;961.8061;99.38683;0;0;0;0.9030365;0.8989835;882692.3;1.002843e+008
176;0.293357;-0.1204176;989.8026;102.2798;0;0;0;0.9239589;0.9197165;908386;1.032248e+008
180;0.2999998;-0.1245174;1016.724;105.0617;0;0;0;0.9448813;0.9404452;933092.9;1.060544e+008
184;0.3067498;-0.1282228;1042.892;107.7657;0;0;0;0.966141;0.9615038;957108.4;1.088069e+008
188;0.3133927;-0.1323663;1071.203;110.6912;0;0;0;0.9870635;0.9822239;983091.1;1.117838e+008
192;0.3200355;-0.1367937;1100.07;113.6741;0;0;0;1.007986;1.00294;1009583;1.148199e+008
196;0.3267319;-0.1413063;1129.802;116.7465;0;0;0;1.029077;1.023818;1036870;1.179479e+008
200;0.3334284;-0.1458802;1160.112;119.8784;0;0;0;1.050168;1.044692;1064686;1.211374e+008
204;0.3400176;-0.1506083;1189.952;122.9619;0;0;0;1.070922;1.065228;1092072;1.242788e+008
208;0.3467676;-0.1556756;1220.764;126.1459;0;0;0;1.092182;1.08626;1120350;1.275236e+008
212;0.3534641;-0.1610645;1250.522;129.2208;0;0;0;1.113273;1.107121;1147660;1.306594e+008
216;0.3599998;-0.1665835;1280.197;132.2873;0;0;0;1.133857;1.127478;1174894;1.337872e+008
220;0.3667497;-0.1721845;1311.378;135.5093;0;0;0;1.155117;1.148497;1203510;1.370746e+008
224;0.3733926;-0.1782209;1341.875;138.6607;0;0;0;1.17604;1.169178;1231499;1.402914e+008
228;0.3799819;-0.1840026;1371.558;141.7279;0;0;0;1.196793;1.189688;1258740;1.434241e+008
232;0.3866783;-0.1907225;1401.706;144.8433;0;0;0;1.217884;1.210528;1286409;1.466073e+008
236;0.3933212;-0.1973186;1432.387;148.0136;0;0;0;1.238807;1.231196;1314566;1.498472e+008
240;0.4000176;-0.2045584;1462.872;151.1638;0;0;0;1.259898;1.252027;1342543;1.530683e+008
244;0.4066069;-0.2114417;1492.51;154.2264;0;0;0;1.280651;1.272521;1369743;1.562015e+008
248;0.4133033;-0.2190066;1522.907;157.3674;0;0;0;1.301743;1.293343;1397640;1.594159e+008
252;0.4199997;-0.2270448;1552.687;160.4447;0;0;0;1.322834;1.314161;1424971;1.625671e+008
256;0.4266426;-0.2353686;1581.22;163.3931;0;0;0;1.343756;1.334808;1451156;1.655887e+008
260;0.4332855;-0.2433253;1609.981;166.365;0;0;0;1.364679;1.355451;1477551;1.686353e+008
264;0.4400354;-0.2520272;1639.533;169.4188;0;0;0;1.385938;1.376422;1504673;1.717668e+008
268;0.4466783;-0.2603717;1667.766;172.3362;0;0;0;1.406861;1.397056;1530583;1.747607e+008
272;0.4533211;-0.2690432;1696.121;175.2662;0;0;0;1.427783;1.417686;1556606;1.777686e+008
276;0.4600711;-0.2780812;1724.958;178.246;0;0;0;1.449043;1.438645;1583071;1.808289e+008
280;0.466714;-0.287164;1752.583;181.1006;0;0;0;1.469965;1.459266;1608423;1.837627e+008
284;0.4733568;-0.2960999;1780.217;183.9561;0;0;0;1.490888;1.479883;1633784;1.866987e+008
288;0.4800533;-0.30568;1809.573;186.9896;0;0;0;1.511979;1.500662;1660726;1.898168e+008
292;0.4867497;-0.3153419;1839.458;190.0777;0;0;0;1.53307;1.521437;1688153;1.929918e+008
296;0.4933925;-0.3250314;1868.803;193.1101;0;0;0;1.553992;1.542041;1715084;1.96111e+008
300;0.5000353;-0.3354425;1898.944;196.2246;0;0;0;1.574914;1.562641;1742746;1.99315e+008
304;0.5067854;-0.3457369;1928.221;199.2499;0;0;0;1.596174;1.583569;1769615;2.024303e+008
308;0.5133211;-0.356081;1957.321;202.2569;0;0;0;1.616759;1.603829;1796321;2.055269e+008
312;0.5200711;-0.3666396;1986.113;205.2321;0;0;0;1.638019;1.624748;1822745;2.085939e+008
316;0.5267675;-0.3777618;2015.016;208.2187;0;0;0;1.65911;1.645497;1849270;2.116733e+008
320;0.5333568;-0.3883618;2042.305;211.0386;0;0;0;1.679864;1.66591;1874314;2.145837e+008
324;0.5400533;-0.4000549;2070.714;213.9742;0;0;0;1.700955;1.686651;1900386;2.176138e+008
328;0.5466961;-0.4117049;2098.552;216.8508;0;0;0;1.721877;1.707221;1925935;2.205847e+008
332;0.5532854;-0.4236764;2125.319;219.6168;0;0;0;1.742631;1.727621;1950500;2.234439e+008
336;0.5600354;-0.4359156;2153.554;222.5344;0;0;0;1.763891;1.748515;1976413;2.264596e+008
340;0.5666782;-0.4485311;2181.121;225.3829;0;0;0;1.784813;1.769072;2001712;2.294056e+008
344;0.5733211;-0.4616958;2208.345;228.1962;0;0;0;1.805736;1.789626;2026697;2.323168e+008
348;0.5799639;-0.4749074;2235.05;230.9556;0;0;0;1.826658;1.810175;2051205;2.351744e+008
352;0.5866067;-0.4887079;2262.134;233.7543;0;0;0;1.84758;1.83072;2076061;2.380731e+008
355.43;0.5923925;-0.501419;2285.972;236.2176;0;0;0;1.865803;1.84861;2097939;2.40625e+008
358.432;0.5873567;-0.4890039;2214.645;228.8471;0;0;0;1.849942;1.833039;2032479;2.330806e+008
362.432;0.5806068;-0.4714877;2128.731;219.9693;0;0;0;1.828683;1.812163;1953631;2.239918e+008
366.432;0.5740711;-0.4550348;2051.04;211.9412;0;0;0;1.808098;1.791946;1882331;2.157733e+008
370.432;0.5673211;-0.4385259;1975.913;204.1781;0;0;0;1.786838;1.771062;1813383;2.078264e+008
374.432;0.5606782;-0.4228176;1904.418;196.7902;0;0;0;1.765916;1.750504;1747769;2.002654e+008
378.432;0.5540889;-0.4072032;1835.987;189.7191;0;0;0;1.745162;1.730109;1684967;1.9303e+008
382.432;0.5473925;-0.392007;1769.213;182.8191;0;0;0;1.724071;1.709377;1623686;1.85971e+008
386.432;0.5407496;-0.376735;1707.849;176.4781;0;0;0;1.703148;1.688808;1567369;1.794837e+008
390.432;0.5341068;-0.3614361;1648.76;170.3722;0;0;0;1.682226;1.668233;1513141;1.732383e+008
394.432;0.5274639;-0.3458885;1592.083;164.5155;0;0;0;1.661304;1.647655;1461125;1.672487e+008
398.432;0.5207675;-0.3301147;1540.52;159.1874;0;0;0;1.640213;1.626907;1413804;1.617984e+008
402.432;0.5141782;-0.3142676;1490.362;154.0043;0;0;0;1.619459;1.606486;1367771;1.564984e+008
406.432;0.5074818;-0.2983121;1441.154;148.9196;0;0;0;1.598368;1.585729;1322611;1.512998e+008
410.432;0.5007854;-0.2823473;1392.859;143.929;0;0;0;1.577277;1.564967;1278289;1.461992e+008
414.432;0.494089;-0.2672579;1345.687;139.0546;0;0;0;1.556186;1.544201;1234997;1.412185e+008
418.432;0.4874461;-0.2527755;1299.732;134.3059;0;0;0;1.535263;1.523597;1192822;1.363678e+008
422.432;0.4808033;-0.2389049;1254.16;129.5968;0;0;0;1.514341;1.502989;1150998;1.315593e+008
426.432;0.4741069;-0.2254254;1208.623;124.8913;0;0;0;1.49325;1.482211;1109207;1.267562e+008
430.432;0.467464;-0.2127124;1164.893;120.3725;0;0;0;1.472327;1.461594;1069074;1.221448e+008
434.432;0.4608211;-0.2007869;1121.349;115.873;0;0;0;1.451405;1.440973;1029112;1.175547e+008
438.432;0.4540176;-0.1895526;1078.43;111.438;0;0;0;1.429977;1.419849;989723.5;1.130315e+008
442.432;0.4473747;-0.1790168;1035.363;106.9877;0;0;0;1.409054;1.399219;950198.9;1.084953e+008
446.432;0.4407319;-0.1695729;993.4718;102.659;0;0;0;1.388132;1.378586;911753.4;1.04084e+008
450.432;0.4340355;-0.1600516;950.6423;98.23323;0;0;0;1.367041;1.357781;872446.8;9.957612e+007
454.432;0.4273926;-0.1517409;908.8101;93.91056;0;0;0;1.346118;1.337139;834055.6;9.517471e+007
458.432;0.4207497;-0.1438756;868.2792;89.72236;0;0;0;1.325196;1.316492;796858.5;9.091136e+007
462.432;0.4139997;-0.1364984;828.5616;85.61821;0;0;0;1.303936;1.295508;760407.9;8.673461e+007
466.432;0.4073033;-0.1293181;789.2755;81.55864;0;0;0;1.282845;1.274686;724353.4;8.260491e+007
470.432;0.4007141;-0.1225914;751.7619;77.68222;0;0;0;1.262092;1.254194;689925.4;7.866264e+007
474.432;0.3940712;-0.11617;713.82;73.76155;0;0;0;1.241169;1.23353;655104.5;7.467706e+007
478.432;0.3873212;-0.1097105;676.6726;69.92297;0;0;0;1.219909;1.212528;621012.6;7.077597e+007
482.432;0.3807855;-0.103545;641.6596;66.30496;0;0;0;1.199324;1.192189;588879.6;6.710017e+007
486.432;0.374089;-0.09782501;606.0747;62.62785;0;0;0;1.178233;1.171346;556221.8;6.336575e+007
490.432;0.3673926;-0.0916599;571.0509;59.00871;0;0;0;1.157142;1.150498;524078.9;5.969153e+007
494.432;0.3608034;-0.08639811;537.6733;55.55968;0;0;0;1.136389;1.12998;493446.8;5.619106e+007
498.432;0.3541069;-0.08076828;503.8102;52.06049;0;0;0;1.115297;1.109124;462369.1;5.264112e+007
502.432;0.347464;-0.07545105;470.7531;48.64458;0;0;0;1.094375;1.08843;432031.1;4.917693e+007
506.432;0.3408212;-0.07018143;438.9868;45.36206;0;0;0;1.073453;1.067732;402877.8;4.5849e+007
510.432;0.3341248;-0.06510506;408.2061;42.18138;0;0;0;1.052361;1.046863;374629;4.262528e+007
514.432;0.3274819;-0.06041334;378.0999;39.0704;0;0;0;1.031439;1.026156;346999.2;3.947339e+007
518.432;0.3207855;-0.05564675;348.7973;36.04246;0;0;0;1.010348;1.005278;320106.8;3.640662e+007
522.432;0.3140891;-0.05098446;320.1036;33.07744;0;0;0;0.989257;0.9843958;293773.3;3.340466e+007
526.432;0.3074462;-0.04656053;292.2584;30.20009;0;0;0;0.9683345;0.9636762;268218.5;3.049253e+007
530.432;0.3008034;-0.04212721;265.6943;27.45514;0;0;0;0.9474122;0.9429524;243839.5;2.771525e+007
534.432;0.294107;-0.03781604;240.2475;24.82562;0;0;0;0.9263211;0.9220571;220485.8;2.505559e+007
538.432;0.2874641;-0.03363204;216.0318;22.32333;0;0;0;0.9053987;0.9013246;198262;2.252545e+007
542.432;0.2807141;-0.0297052;193.0986;19.95356;0;0;0;0.8841389;0.8802533;177215.2;2.012998e+007
546.432;0.2740177;-0.02616518;171.6575;17.73797;0;0;0;0.8630478;0.8593449;157537.7;1.789106e+007
550.432;0.2674284;-0.02263644;151.86;15.69223;0;0;0;0.8422942;0.8387667;139368.7;1.582441e+007
554.432;0.2606784;-0.01951707;132.2009;13.66079;0;0;0;0.8210343;0.8176821;121326.7;1.377295e+007
558.432;0.2540355;-0.01667397;115.0352;11.88699;0;0;0;0.8001119;0.796928;105572.9;1.19821e+007
562.432;0.2473927;-0.0141231;99.47812;10.27943;0;0;0;0.7791896;0.7761696;91295.51;1.035952e+007
566.432;0.2406963;-0.01179901;85.48156;8.833113;0;0;0;0.7580985;0.7552394;78450.24;8900076
570.432;0.2339999;-0.009566685;74.1147;7.658535;0;0;0;0.7370074;0.7343048;68018.37;7714978
574.432;0.2274106;-0.007292078;64.2565;6.639852;0;0;0;0.7162538;0.7137008;58971.05;6687410
578.432;0.2207141;-0.005549006;57.6039;5.952415;0;0;0;0.6951627;0.6927575;52865.66;5993793
582.208;0.2144999;-0.005134929;52.32452;5.406878;0;0;0;0.6755902;0.6733183;48020.55;5443407
585.21;0.2193749;-0.008399625;72.99839;7.543181;1;1;0;0.6909444;0.6885683;66993.88;7595301
589.21;0.2261248;-0.01331155;103.7359;10.7194;1;1;0;0.7122042;0.70968;95203.08;1.079574e+007
593.21;0.2327141;-0.0179707;134.659;13.91479;1;1;0;0.7329579;0.7302848;123582.5;1.401678e+007
597.21;0.2394106;-0.02269908;166.1885;17.17284;1;1;0;0.754049;0.7512203;152518.6;1.730233e+007
601.21;0.246107;-0.02746223;199.2259;20.58672;1;1;0;0.77514;0.7721512;182838.5;2.07463e+007
605.21;0.2527498;-0.03260092;232.1973;23.99377;1;1;0;0.7960625;0.7929106;213097.8;2.418478e+007
609.21;0.2593927;-0.03743642;265.8629;27.47255;1;1;0;0.8169848;0.8136656;243994.2;2.7697e+007
613.21;0.2661427;-0.04226064;300.7779;31.08045;1;1;0;0.8382447;0.8347509;276037.3;3.134098e+007
617.21;0.2728391;-0.04703976;335.533;34.67181;1;1;0;0.8593357;0.8556645;307933.6;3.496976e+007
621.21;0.2794284;-0.05197862;371.0789;38.3449;1;1;0;0.8800894;0.8762392;340555.7;3.868237e+007
625.21;0.2861784;-0.0571928;407.8028;42.1397;1;1;0;0.9013492;0.8973113;374258.8;4.251953e+007
629.21;0.2928212;-0.0623246;444.7275;45.95527;1;1;0;0.9222716;0.9180447;408146.3;4.63791e+007
633.21;0.2994641;-0.06764748;481.8681;49.79313;1;1;0;0.943194;0.9387737;442231.8;5.026278e+007
637.21;0.3061605;-0.07300574;520.036;53.73716;1;1;0;0.9642851;0.9596655;477260.3;5.425534e+007
641.21;0.3128569;-0.07849555;558.3252;57.69371;1;1;0;0.9853762;0.980553;512399.9;5.826222e+007
645.21;0.3194998;-0.08383127;596.8192;61.67144;1;1;0;1.006299;1.001269;547727.6;6.229204e+007
649.21;0.3261962;-0.08947769;636.371;65.75846;1;1;0;1.02739;1.022148;584026;6.643406e+007
653.21;0.3328926;-0.09491207;675.2928;69.7804;1;1;0;1.048481;1.043022;619746.4;7.051203e+007
657.21;0.3394284;-0.1001591;713.7083;73.75001;1;1;0;1.069066;1.063392;655001.9;7.453844e+007
661.21;0.3461783;-0.105928;753.5446;77.86643;1;1;0;1.090325;1.084424;691561.5;7.871543e+007
665.21;0.3528212;-0.1114113;793.1026;81.95409;1;1;0;1.111248;1.105119;727865.6;8.286481e+007
669.21;0.3594105;-0.1169271;832.9591;86.07262;1;1;0;1.132002;1.125642;764443.8;8.704696e+007
673.21;0.3661069;-0.1223624;872.3634;90.14439;1;1;0;1.153093;1.146495;800606.8;9.118385e+007
677.21;0.3727498;-0.1280007;912.1887;94.25968;1;1;0;1.174015;1.167177;837156.2;9.536631e+007
681.21;0.3793926;-0.1335635;951.7303;98.34566;1;1;0;1.194937;1.187854;873445.4;9.952084e+007
685.21;0.3860355;-0.1391588;990.4554;102.3473;1;1;0;1.21586;1.208528;908985.1;1.035917e+008
689.21;0.3927319;-0.1446612;1029.244;106.3554;1;1;0;1.236951;1.229363;944583.1;1.07671e+008
693.21;0.3994283;-0.1506785;1067.828;110.3424;1;1;0;1.258042;1.250194;979993.1;1.117306e+008
697.21;0.4060712;-0.1563982;1105.2;114.2042;1;1;0;1.278964;1.270855;1014291;1.156648e+008
701.21;0.4149105;-0.1649873;1160.43;119.9113;1;1;0;1.306805;1.29834;1064978;1.214783e+008
705.21;0.4281961;-0.1796749;1244.712;128.6205;1;1;0;1.348649;1.339636;1142328;1.303551e+008
709.21;0.4413747;-0.1949801;1326.049;137.0253;1;1;0;1.390157;1.380583;1216974;1.389302e+008
713.21;0.4547676;-0.211914;1407.349;145.4264;1;1;0;1.432339;1.422178;1291587;1.475094e+008
717.21;0.4680533;-0.2296567;1490.345;154.0026;1;1;0;1.474184;1.463423;1367756;1.562729e+008
721.21;0.4814461;-0.2488571;1574.135;162.6609;1;1;0;1.516366;1.504984;1444654;1.651274e+008
725.21;0.4946782;-0.2682862;1656.414;171.1631;1;1;0;1.558042;1.546029;1520165;1.738299e+008
729.21;0.5081246;-0.2895579;1739.361;179.7344;1;1;0;1.600393;1.587721;1596290;1.826108e+008
733.21;0.5215175;-0.3120362;1820.377;188.106;1;1;0;1.642575;1.629231;1670641;1.911958e+008
737.21;0.5347497;-0.3355537;1898.607;196.1897;1;1;0;1.684251;1.670225;1742436;1.994941e+008
741.21;0.5481961;-0.360525;1977.74;204.3669;1;1;0;1.726602;1.711865;1815061;2.078955e+008
745.21;0.5615354;-0.3867825;2055.234;212.3746;1;1;0;1.768615;1.753157;1886180;2.161307e+008
749.21;0.5747675;-0.4138087;2129.847;220.0847;1;1;0;1.810291;1.794101;1954656;2.240688e+008
753.21;0.5882139;-0.4429878;2204.652;227.8145;1;1;0;1.852642;1.83569;2023307;2.320351e+008
757.21;0.6014996;-0.4735268;2275.702;235.1564;1;1;0;1.894487;1.876765;2088514;2.396114e+008
761.21;0.6147318;-0.5055225;2343.377;242.1495;1;1;0;1.936163;1.917658;2150622;2.468379e+008
765.21;0.628071;-0.539107;2408.817;248.9116;1;1;0;1.978176;1.958865;2210679;2.538355e+008
769.21;0.6414103;-0.575454;2471.209;255.3588;1;1;0;2.02019;2.000055;2267939;2.605176e+008
773.21;0.6547495;-0.6127802;2533.129;261.7572;1;1;0;2.062203;2.041228;2324766;2.671552e+008
777.21;0.6680353;-0.6511369;2592.877;267.9312;1;1;0;2.104048;2.082218;2379599;2.735686e+008
781.21;0.6814281;-0.6914568;2652.312;274.0728;1;1;0;2.14623;2.123523;2434145;2.79955e+008
785.21;0.694821;-0.7340091;2709.125;279.9435;1;1;0;2.188413;2.164811;2486285;2.860698e+008
789.21;0.7081067;-0.7774963;2762.761;285.4859;1;1;0;2.230257;2.205751;2535509;2.918529e+008
793.21;0.7215531;-0.8235689;2815.098;290.8941;1;1;0;2.272608;2.247169;2583541;2.975049e+008
797.21;0.7348924;-0.8708767;2864.984;296.049;1;1;0;2.314622;2.288241;2629324;3.029014e+008
801.21;0.7481245;-0.9198099;2910.918;300.7954;1;1;0;2.356298;2.328966;2671479;3.078831e+008
805.21;0.7615174;-0.9709109;2957.2;305.578;1;1;0;2.39848;2.370168;2713955;3.129072e+008
808.0501;0.7708388;-1.007849;2987.984;308.759;1;1;0;2.427839;2.398835;2742207;3.162552e+008
812.0501;0.7576067;-0.9666856;2820.115;291.4125;1;1;0;2.386163;2.358139;2588145;2.98366e+008
816.0501;0.7442138;-0.9205519;2672.817;276.1917;1;1;0;2.34398;2.316931;2452964;2.826656e+008
820.0501;0.7309281;-0.8757144;2538.456;262.3076;1;1;0;2.302136;2.276036;2329654;2.683463e+008
824.0501;0.7176959;-0.8304891;2410.328;249.0678;1;1;0;2.26046;2.23529;2212066;2.546978e+008
828.0501;0.7043032;-0.785432;2286.518;236.274;1;1;0;2.218278;2.194032;2098440;2.415152e+008
832.0501;0.6910174;-0.7390272;2176.323;224.8872;1;1;0;2.176433;2.153087;1997309;2.297817e+008
836.0501;0.6776246;-0.6922054;2073.54;214.2662;1;1;0;2.134251;2.111794;1902980;2.188392e+008
840.0501;0.6643389;-0.6464586;1976.408;204.2292;1;1;0;2.092406;2.070816;1813838;2.085025e+008
844.0501;0.6508924;-0.600153;1884.414;194.7232;1;1;0;2.050055;2.029324;1729411;1.987151e+008
848.0501;0.6375532;-0.5564077;1794.498;185.4318;1;1;0;2.008041;1.988146;1646891;1.891553e+008
852.0501;0.6242674;-0.5143651;1710.109;176.7116;1;1;0;1.966197;1.947117;1569443;1.801861e+008
856.0501;0.610821;-0.4729846;1625.893;168.0092;1;1;0;1.923846;1.905574;1492154;1.712415e+008
860.0501;0.5974817;-0.4345518;1543.737;159.5198;1;1;0;1.881832;1.864345;1416756;1.625217e+008
864.0501;0.5843032;-0.3988581;1463.531;151.2319;1;1;0;1.840325;1.823596;1343148;1.54015e+008
868.0501;0.5708568;-0.3649705;1382.539;142.8627;1;1;0;1.797974;1.782002;1268818;1.454313e+008
872.0501;0.5576246;-0.3325406;1304.234;134.7711;1;1;0;1.756298;1.741053;1196954;1.371381e+008
876.0501;0.5443389;-0.300691;1227.958;126.8892;1;1;0;1.714453;1.699922;1126952;1.290647e+008
880.0501;0.5309996;-0.270309;1151.362;118.9743;1;1;0;1.67244;1.658609;1056656;1.209641e+008
884.0501;0.5176603;-0.2423152;1076.754;111.2648;1;1;0;1.630426;1.617278;988184.9;1.130789e+008
888.0501;0.5042675;-0.2164614;1002.89;103.6322;1;1;0;1.588244;1.575764;920397;1.052781e+008
892.0501;0.4909818;-0.1936483;930.2983;96.13101;1;1;0;1.546399;1.534564;853776.2;9.761758e+007
896.0501;0.477589;-0.1736663;857.1213;88.56938;1;1;0;1.504217;1.493016;786618.5;8.990166e+007
900.0501;0.4641961;-0.1566425;785.3972;81.15787;1;1;0;1.462035;1.45145;720794;8.234443e+007
904.0501;0.450964;-0.1412571;715.723;73.95819;1;1;0;1.420359;1.410366;656850.9;7.500866e+007
908.0501;0.437464;-0.1268258;646.1547;66.76945;1;1;0;1.377839;1.368433;593005;6.768943e+007
912.0501;0.4241783;-0.1135418;578.9481;59.82476;1;1;0;1.335995;1.327149;531326.5;6.062401e+007
916.0501;0.4109462;-0.1011793;514.0567;53.1193;1;1;0;1.294319;1.286014;471772.8;5.380683e+007
920.0501;0.3975533;-0.08920957;450.9875;46.60213;1;1;0;1.252136;1.244362;413891.3;4.718565e+007
924.0501;0.3843212;-0.07827223;390.8703;40.39001;1;1;0;1.21046;1.203193;358719.1;4.087891e+007
928.0501;0.3710355;-0.06775992;333.8687;34.49983;1;1;0;1.168616;1.16184;306406.2;3.4903e+007
932.0501;0.3576426;-0.05781329;279.4136;28.8728;1;1;0;1.126433;1.120136;256430.3;2.919803e+007
936.0501;0.3443033;-0.04834056;228.9348;23.65664;1;1;0;1.08442;1.078582;210103.7;2.391318e+007
940.0501;0.3309105;-0.03937651;181.4231;18.74709;1;1;0;1.042238;1.036844;166500;1.894248e+007
944.0501;0.3176248;-0.03106301;139.6285;14.42831;1;1;0;1.000393;0.9954223;128143.3;1.457265e+007
948.0501;0.3042319;-0.02339537;102.5578;10.59766;1;1;0;0.9582108;0.9536491;94121.82;1.06992e+007
952.0501;0.2908391;-0.01731576;73.7263;7.6184;1;1;0;0.9160286;0.9118585;67661.91;7688186
956.0501;0.2776069;-0.01316434;55.50968;5.736012;1;1;0;0.8743526;0.8705522;50943.71;5786165
960.0501;0.2641605;-0.01138994;49.6113;5.126512;1;1;0;0.8320017;0.8285596;45530.51;5169164
963.218;0.253607;-0.01090351;49.31053;5.095431;1;1;0;0.7987621;0.7955889;45254.47;5136132
966.2201;0.2636248;-0.01169251;54.47241;5.628827;2;2;0;0.8303144;0.8268863;49991.76;5675564
970.2201;0.2770177;-0.0201764;100.9534;10.43187;2;2;0;0.8724966;0.8687124;92649.43;1.052289e+007
974.2201;0.2902498;-0.03094273;160.3109;16.56549;2;2;0;0.9141727;0.9100194;147124.4;1.671693e+007
978.2201;0.3037498;-0.04175761;225.9914;23.35249;2;2;0;0.9566923;0.952145;207402.4;2.35759e+007
982.2201;0.3170891;-0.05302384;296.953;30.68521;2;2;0;0.9987057;0.9937516;272527;3.099166e+007
986.2201;0.3303748;-0.06452623;369.9821;38.23156;2;2;0;1.04055;1.035174;339549.1;3.862938e+007
990.2201;0.3438212;-0.07628641;446.279;46.11559;2;2;0;1.082901;1.07708;409570.1;4.661497e+007
994.2201;0.3571069;-0.08792318;524.0078;54.14758;2;2;0;1.124746;1.118468;480905.3;5.47566e+007
998.2201;0.370339;-0.09994333;602.4734;62.25571;2;2;0;1.166422;1.159672;552916.7;6.298187e+007
1002.22;0.3837319;-0.1123102;683.9737;70.67742;2;2;0;1.208604;1.201359;627713.2;7.153163e+007
1006.22;0.396964;-0.1247983;765.9799;79.15141;2;2;0;1.25028;1.242529;702973.9;8.014103e+007
1010.22;0.4103033;-0.1374606;848.6683;87.6959;2;2;0;1.292294;1.284015;778860.8;8.882919e+007
1014.22;0.423589;-0.1505544;930.7243;96.17503;2;2;0;1.334139;1.325317;854167.2;9.745814e+007
1018.22;0.4369819;-0.1644135;1011.387;104.5102;2;2;0;1.376321;1.366936;928195.2;1.059486e+008
1022.22;0.4503747;-0.1790021;1091.364;112.7745;2;2;0;1.418503;1.408536;1001593;1.143742e+008
1026.22;0.4636068;-0.1949071;1172.167;121.1242;2;2;0;1.460179;1.449621;1075750;1.228928e+008
1030.22;0.4770533;-0.2122232;1254.37;129.6185;2;2;0;1.50253;1.491354;1151192;1.315661e+008
1034.22;0.4904461;-0.2304795;1336.809;138.1372;2;2;0;1.544712;1.532903;1226849;1.40271e+008
1038.22;0.5036782;-0.2490369;1420.232;146.7576;2;2;0;1.586388;1.573937;1303410;1.490857e+008
1042.22;0.5171247;-0.2688494;1505.421;155.5605;2;2;0;1.628739;1.615617;1381592;1.580942e+008
1046.22;0.5304104;-0.289785;1587.273;164.0186;2;2;0;1.670584;1.656783;1456711;1.667586e+008
1050.22;0.5436425;-0.3120967;1668.673;172.4299;2;2;0;1.71226;1.697766;1531416;1.753824e+008
1054.22;0.5569818;-0.3364377;1750.576;180.8932;2;2;0;1.754273;1.739064;1606582;1.840666e+008
1058.22;0.5703211;-0.3617546;1831.102;189.2142;2;2;0;1.796287;1.780344;1680484;1.926131e+008
1062.22;0.5836603;-0.3889146;1911.216;197.4928;2;2;0;1.8383;1.821608;1754008;2.011233e+008
1066.22;0.596946;-0.417059;1990.621;205.6979;2;2;0;1.880145;1.862689;1826882;2.095653e+008
1070.22;0.6103389;-0.4470794;2068.922;213.789;2;2;0;1.922327;1.904084;1898742;2.178988e+008
1074.22;0.6237318;-0.4790802;2145.86;221.7393;2;2;0;1.964509;1.945462;1969352;2.260954e+008
1078.22;0.6369639;-0.5123742;2220.708;229.4736;2;2;0;2.006186;1.986327;2038043;2.340773e+008
1082.22;0.6504638;-0.5480253;2295.812;237.2344;2;2;0;2.048705;2.028001;2106969;2.420946e+008
1086.22;0.6637496;-0.5847871;2369.321;244.8303;2;2;0;2.09055;2.068998;2174431;2.499486e+008
1090.22;0.6770353;-0.6230761;2440.342;252.1692;2;2;0;2.132395;2.109977;2239611;2.575464e+008
1094.22;0.6904817;-0.6638386;2511.569;259.5293;2;2;0;2.174746;2.151435;2304979;2.651734e+008
1098.22;0.7037674;-0.7057876;2579.115;266.5091;2;2;0;2.21659;2.192381;2366969;2.724165e+008
1102.22;0.7169459;-0.7492074;2644.44;273.2593;2;2;0;2.258097;2.23298;2426921;2.794298e+008
1106.22;0.7303389;-0.7951591;2709.26;279.9574;2;2;0;2.30028;2.274222;2486408;2.863972e+008
1110.22;0.7435709;-0.8423261;2770.07;286.2411;2;2;0;2.341956;2.314953;2542217;2.929448e+008
1114.22;0.7569638;-0.892114;2830.836;292.5203;2;2;0;2.384138;2.356161;2597984;2.994943e+008
1118.22;0.7702495;-0.9429124;2888.625;298.4918;2;2;0;2.425982;2.397023;2651020;3.057332e+008
1122.22;0.7836959;-0.9965204;2944.452;304.2607;2;2;0;2.468334;2.438363;2702255;3.117709e+008
1124.982;0.7796245;-0.9884726;2868.401;296.402;2;2;0;2.45551;2.425847;2632459;3.036802e+008
1128.982;0.7662852;-0.9434045;2714.739;280.5236;2;2;0;2.413497;2.384832;2491437;2.87294e+008
1132.982;0.7528924;-0.8975196;2574.958;266.0795;2;2;0;2.371315;2.343636;2363154;2.723891e+008
1136.982;0.7394995;-0.8517937;2443.605;252.5064;2;2;0;2.329132;2.302422;2242605;2.583876e+008
1140.982;0.7262674;-0.8072269;2320.318;239.7666;2;2;0;2.287456;2.261686;2129459;2.452512e+008
1144.982;0.712821;-0.7615221;2200.397;227.3748;2;2;0;2.245106;2.220274;2019402;2.324796e+008
1148.982;0.6994817;-0.714404;2096.08;216.5953;2;2;0;2.203092;2.179174;1923666;2.213671e+008
1152.982;0.6862496;-0.6687301;1997.596;206.4187;2;2;0;2.161416;2.138389;1833283;2.108803e+008
1156.982;0.6728567;-0.6225436;1903.667;196.7126;2;2;0;2.119234;2.09709;1747080;2.008815e+008
1160.982;0.659571;-0.5780635;1815.054;187.5559;2;2;0;2.077389;2.056106;1665756;1.914522e+008
1164.982;0.6463388;-0.5359735;1726.148;178.369;2;2;0;2.035713;2.015269;1584163;1.820001e+008
1168.982;0.632946;-0.494229;1641.927;169.6661;2;2;0;1.993531;1.97392;1506869;1.730485e+008
1172.982;0.6196067;-0.45495;1559.05;161.1021;2;2;0;1.951517;1.932719;1430810;1.642461e+008
1176.982;0.6062675;-0.4177105;1475.684;152.4876;2;2;0;1.909504;1.891502;1354301;1.553994e+008
1180.982;0.5929818;-0.3834308;1394.122;144.0596;2;2;0;1.867659;1.850433;1279448;1.467501e+008
1184.982;0.5795353;-0.3510701;1313.087;135.6859;2;2;0;1.825308;1.808849;1205079;1.381626e+008
1188.982;0.5661961;-0.3200142;1234.031;127.5168;2;2;0;1.783295;1.767581;1132525;1.297908e+008
1192.982;0.5529103;-0.2894546;1157.418;119.6001;2;2;0;1.74145;1.72646;1062214;1.216829e+008
1196.982;0.5394639;-0.2604613;1081.966;111.8033;2;2;0;1.699099;1.684826;992968.1;1.13703e+008
1200.982;0.5261247;-0.2338003;1008.074;104.1679;2;2;0;1.657086;1.643506;925154.8;1.05894e+008
1204.982;0.5128925;-0.2102035;936.2904;96.7502;2;2;0;1.615409;1.602501;859275.4;9.831311e+007
1208.982;0.4994997;-0.1887445;863.3477;89.21278;2;2;0;1.573227;1.56098;792332.7;9.061629e+007
1212.982;0.4862675;-0.1703328;792.7198;81.91454;2;2;0;1.531551;1.519941;727514.3;8.316911e+007
1216.982;0.4729818;-0.1537668;722.4415;74.65244;2;2;0;1.489707;1.478719;663016.8;7.576454e+007
1220.982;0.459589;-0.1388165;653.9318;67.57309;2;2;0;1.447524;1.437148;600142.4;6.855123e+007
1224.982;0.4462497;-0.1248146;586.7464;60.63058;2;2;0;1.405511;1.395725;538483.3;6.148275e+007
1228.982;0.4329105;-0.1115954;520.8853;53.82492;2;2;0;1.363497;1.354286;478039.7;5.455883e+007
1232.982;0.4196247;-0.09932942;457.8427;47.31051;2;2;0;1.321653;1.312995;420182.7;4.793579e+007
1236.982;0.4061783;-0.08761967;396.5953;40.98159;2;2;0;1.279302;1.271188;363973.2;4.150587e+007
1240.982;0.392839;-0.07666102;338.9242;35.02224;2;2;0;1.237288;1.229696;311045.9;3.545556e+007
1244.982;0.3796069;-0.06640054;284.9392;29.44378;2;2;0;1.195612;1.188521;261501.4;2.979581e+007
1248.982;0.3661069;-0.05640944;233.8704;24.16666;2;2;0;1.153093;1.146495;214633.3;2.444532e+007
1252.982;0.3528212;-0.04674627;187.1786;19.34183;2;2;0;1.111248;1.105119;171782.2;1.955677e+007
1256.982;0.3395891;-0.03773805;144.9723;14.98051;2;2;0;1.069572;1.063892;133047.6;1.514073e+007
1260.982;0.3261962;-0.02940482;107.7102;11.13007;2;2;0;1.02739;1.022148;98850.41;1.124442e+007
1264.982;0.3129641;-0.02226966;77.68533;8.0275;2;2;0;0.9857136;0.9808872;71295.29;8106628
1268.982;0.2996784;-0.01696777;57.21576;5.912307;2;2;0;0.9438689;0.9394424;52509.45;5968111
1272.982;0.2862855;-0.01471102;49.78115;5.144063;2;2;0;0.9016867;0.8976458;45686.38;5190446
1276.982;0.2729463;-0.01398936;49.4518;5.110029;2;2;0;0.8596733;0.8559991;45384.12;5153959
1280.982;0.2595534;-0.01342274;49.40071;5.10475;2;2;0;0.817491;0.8141677;45337.23;5146481
1284.182;0.2489463;-0.01299645;49.29778;5.094114;2;2;0;0.7840827;0.7810247;45242.77;5134056
1287.184;0.258857;-0.01333567;50.15141;5.182323;3;3;0;0.8152976;0.811992;46026.18;5224574
1291.184;0.2723034;-0.0133081;50.83196;5.252646;3;3;0;0.8576485;0.8539916;46650.75;5297695
1295.184;0.2856427;-0.01939523;82.48745;8.52372;3;3;0;0.8996619;0.8956391;75702.41;8600405
1299.184;0.2988748;-0.02994888;137.0691;14.16383;3;3;0;0.9413379;0.936935;125794.4;1.429716e+007
1303.184;0.3122677;-0.04077191;198.7244;20.5349;3;3;0;0.9835202;0.9787151;182378.3;2.073686e+007
1307.184;0.3254998;-0.0516228;264.4418;27.3257;3;3;0;1.025196;1.019977;242690;2.760585e+007
1311.184;0.3388391;-0.06273524;334.4641;34.56136;3;3;0;1.06721;1.061555;306952.6;3.49302e+007
1315.184;0.3521248;-0.07438109;406.5163;42.00677;3;3;0;1.109054;1.102949;373078.1;4.247265e+007
1319.184;0.3655176;-0.08637681;481.8414;49.79038;3;3;0;1.151237;1.14466;442207.3;5.036358e+007
1323.184;0.3789105;-0.09891973;559.8988;57.85632;3;3;0;1.193419;1.186354;513844.1;5.854679e+007
1327.184;0.3921426;-0.1113652;638.247;65.95232;3;3;0;1.235095;1.22753;585747.8;6.67669e+007
1331.184;0.405589;-0.1241412;719.5801;74.35676;3;3;0;1.277446;1.269355;660390.8;7.530662e+007
1335.184;0.4189819;-0.1370286;801.0859;82.77905;3;3;0;1.319628;1.310997;735192.3;8.387142e+007
1339.184;0.432214;-0.1507587;883.1164;91.25555;3;3;0;1.361304;1.352121;810475.3;9.249781e+007
1343.184;0.4456604;-0.1651374;966.0624;99.82664;3;3;0;1.403655;1.393895;886598.6;1.012279e+008
1347.184;0.4589462;-0.1799138;1046.114;108.0986;3;3;0;1.4455;1.435152;960065.2;1.096612e+008
1351.184;0.4721783;-0.1954596;1125.725;116.3252;3;3;0;1.487176;1.476226;1033128;1.180552e+008
1355.184;0.4855711;-0.2122802;1207.569;124.7823;3;3;0;1.529358;1.517781;1108240;1.266907e+008
1359.184;0.4988032;-0.2296241;1290.836;133.3866;3;3;0;1.571034;1.558821;1184658;1.354822e+008
1363.184;0.5121961;-0.2473969;1375.708;142.1568;3;3;0;1.613216;1.600342;1262549;1.444501e+008
1367.184;0.5254818;-0.2667617;1459.632;150.8289;3;3;0;1.655061;1.641514;1339569;1.533252e+008
1371.184;0.5388747;-0.2873062;1544.009;159.548;3;3;0;1.697243;1.683001;1417006;1.622559e+008
1375.184;0.5522675;-0.3098872;1627.339;168.1588;3;3;0;1.739425;1.72447;1493482;1.710837e+008
1379.184;0.5654996;-0.3338009;1709.187;176.6163;3;3;0;1.781101;1.765426;1568597;1.79762e+008
1383.184;0.578946;-0.3591499;1791.979;185.1715;3;3;0;1.823452;1.807027;1644579;1.88548e+008
1387.184;0.5922853;-0.3858999;1873.694;193.6155;3;3;0;1.865466;1.848279;1719573;1.972273e+008
1391.184;0.605571;-0.4139569;1953.762;201.8891;3;3;0;1.90731;1.889349;1793054;2.057397e+008
1395.184;0.6189639;-0.4436978;2034.53;210.2352;3;3;0;1.949493;1.930733;1867179;2.143338e+008
1399.184;0.6322496;-0.4749976;2113.018;218.3457;3;3;0;1.991337;1.971769;1939211;2.226937e+008
1403.184;0.6454817;-0.508271;2190.239;226.3252;3;3;0;2.033013;2.012623;2010080;2.309264e+008
1407.184;0.6588746;-0.5429912;2268.778;234.4409;3;3;0;2.075196;2.053957;2082159;2.39306e+008
1411.184;0.6721067;-0.5796133;2343.398;242.1516;3;3;0;2.116871;2.094777;2150641;2.472776e+008
1415.184;0.6855531;-0.6184786;2417.618;249.8211;3;3;0;2.159222;2.136241;2218756;2.552153e+008
1419.184;0.6987853;-0.6585533;2488.331;257.1281;3;3;0;2.200899;2.177028;2283653;2.627872e+008
1423.184;0.7122316;-0.7011911;2558.016;264.3289;3;3;0;2.243249;2.218458;2347606;2.702584e+008
1427.184;0.7255709;-0.7453126;2626.163;271.3708;3;3;0;2.285263;2.259542;2410147;2.775723e+008
1431.184;0.7388566;-0.7911098;2691.045;278.0752;3;3;0;2.327107;2.300443;2469692;2.845463e+008
1435.184;0.7523566;-0.8391202;2755.889;284.7757;3;3;0;2.369627;2.341987;2529202;2.915239e+008
1439.184;0.7656423;-0.8883075;2818.488;291.2443;3;3;0;2.411472;2.382855;2586652;2.982676e+008
1443.184;0.7788745;-0.9379494;2880.411;297.643;3;3;0;2.453148;2.423541;2643482;3.049447e+008
1447.184;0.7923209;-0.9908445;2940.138;303.8148;3;3;0;2.495499;2.46487;2698296;3.113965e+008
1449.418;0.793178;-0.9997647;2914.111;301.1255;3;3;0;2.498199;2.467504;2674410;3.086482e+008
1453.418;0.7797316;-0.9551365;2754.185;284.5997;3;3;0;2.455848;2.426177;2527638;2.91589e+008
1457.418;0.7663923;-0.9098257;2612.588;269.968;3;3;0;2.413834;2.385162;2397688;2.764845e+008
1461.418;0.7529995;-0.8636623;2478.983;256.1621;3;3;0;2.371652;2.343965;2275074;2.622374e+008
1465.418;0.7396066;-0.8175872;2352.13;243.0539;3;3;0;2.32947;2.302752;2158655;2.487158e+008
1469.418;0.7263746;-0.7729866;2232.384;230.6801;3;3;0;2.287794;2.262016;2048758;2.359576e+008
1473.418;0.7128745;-0.7258988;2121.697;219.2424;3;3;0;2.245274;2.220439;1947176;2.24165e+008
1477.418;0.6995889;-0.6795742;2020.246;208.7592;3;3;0;2.203429;2.179505;1854070;2.133591e+008
1481.418;0.6863567;-0.6344579;1924.111;198.8252;3;3;0;2.161753;2.138719;1765843;2.031233e+008
1485.418;0.6729639;-0.5892695;1833.842;189.4974;3;3;0;2.119571;2.097421;1682999;1.935139e+008
1489.418;0.6596781;-0.5466785;1744.483;180.2636;3;3;0;2.077726;2.056436;1600990;1.84009e+008
1493.418;0.646446;-0.5057975;1658.284;171.3563;3;3;0;2.03605;2.0156;1521881;1.748452e+008
1497.418;0.6330532;-0.4662748;1573.266;162.5711;3;3;0;1.993868;1.974251;1443856;1.658126e+008
1501.418;0.6197138;-0.4289091;1489.711;153.9371;3;3;0;1.951855;1.93305;1367175;1.569418e+008
1505.418;0.6063746;-0.3938472;1405.541;145.2395;3;3;0;1.909841;1.891833;1289928;1.480134e+008
1509.418;0.5930889;-0.3612594;1324.096;136.8235;3;3;0;1.867997;1.850764;1215182;1.393794e+008
1513.418;0.5796425;-0.3303524;1243.011;128.4447;3;3;0;1.825646;1.809181;1140767;1.307897e+008
1517.418;0.5663032;-0.3011217;1164.411;120.3227;3;3;0;1.783632;1.767912;1068632;1.224688e+008
1521.418;0.5530175;-0.2724902;1088.546;112.4834;3;3;0;1.741787;1.726792;999007.6;1.144426e+008
1525.418;0.539571;-0.2453888;1013.764;104.7558;3;3;0;1.699436;1.685158;930376.4;1.065361e+008
1529.418;0.5262318;-0.2209915;940.665;97.20225;3;3;0;1.657423;1.643838;863290.3;9.88133e+007
1533.418;0.5130532;-0.1991478;869.2653;89.82426;3;3;0;1.615916;1.602999;797763.6;9.127575e+007
1537.418;0.4996604;-0.1795862;796.5258;82.30783;3;3;0;1.573733;1.561479;731007.3;8.360314e+007
1541.418;0.4863747;-0.1623719;726.817;75.10458;3;3;0;1.531889;1.520274;667032.4;7.625509e+007
1545.418;0.473089;-0.1468713;657.9051;67.98366;3;3;0;1.490044;1.479052;603788.8;6.899665e+007
1549.418;0.4597497;-0.1325703;590.691;61.0382;3;3;0;1.448031;1.437647;542103.5;6.192205e+007
1553.418;0.4463569;-0.1190632;525.4477;54.29637;3;3;0;1.405848;1.396058;482226.8;5.505969e+007
1557.418;0.4330176;-0.106386;461.6232;47.70116;3;3;0;1.363835;1.354618;423652.2;4.835172e+007
1561.418;0.4197319;-0.09434389;401.0776;41.44477;3;3;0;1.32199;1.313328;368086.8;4.199267e+007
1565.418;0.4062854;-0.08291196;343.0481;35.44838;3;3;0;1.279639;1.271521;314830.5;3.590199e+007
1569.418;0.3929462;-0.07208424;288.166;29.77721;3;3;0;1.237626;1.23003;264462.8;3.014574e+007
1573.418;0.3796605;-0.06186887;237.9108;24.58416;3;3;0;1.195781;1.188688;218341.3;2.487813e+007
1577.418;0.366214;-0.05208888;190.3152;19.66594;3;3;0;1.15343;1.146829;174660.7;1.989277e+007
1581.418;0.3529284;-0.04229541;148.0909;15.30275;3;3;0;1.111585;1.105453;135909.6;1.547285e+007
1585.418;0.3396962;-0.03346384;110.4235;11.41045;3;3;0;1.069909;1.064226;101340.6;1.153253e+007
1589.418;0.3263033;-0.02556348;79.51383;8.216445;3;3;0;1.027727;1.022482;72973.38;8300888
1593.418;0.3130712;-0.01964424;58.37727;6.03233;3;3;0;0.9860511;0.9812213;53575.42;6091812
1597.418;0.2997319;-0.01683497;49.77249;5.143167;3;3;0;0.9440376;0.9396094;45678.43;5191721
1601.418;0.2863927;-0.01622795;49.65033;5.130545;3;3;0;0.9020241;0.8979802;45566.32;5176823
1605.418;0.2730534;-0.01572084;49.51376;5.116432;3;3;0;0.8600107;0.8563337;45440.98;5160434
1609.418;0.2596605;-0.01516957;49.45559;5.110421;3;3;0;0.8178285;0.8145024;45387.6;5152215
1612.302;0.2499641;-0.0149713;49.27323;5.091578;4;4;0;0.7872886;0.7842057;45220.25;5131663
1616.302;0.263357;-0.01510818;49.63894;5.129367;4;4;0;0.8294708;0.8260495;45555.87;5171914
1620.302;0.2767498;-0.01520935;50.05638;5.172503;4;4;0;0.871653;0.867876;45938.98;5217590
1624.302;0.289982;-0.01772201;63.20942;6.531653;4;4;0;0.913329;0.9091834;58010.1;6591309
1628.302;0.3034819;-0.02811184;115.9925;11.98591;4;4;0;0.9558486;0.9513093;106451.5;1.210048e+007
1632.302;0.3168212;-0.03899532;174.7748;18.0601;4;4;0;0.997862;0.9929163;160398.6;1.824031e+007
1636.302;0.3300533;-0.04984308;238.0047;24.59387;4;4;0;1.039538;1.034172;218427.5;2.484953e+007
1640.302;0.3434998;-0.06154469;306.4821;31.66988;4;4;0;1.081889;1.076079;281272.3;3.201251e+007
1644.302;0.3567855;-0.0731871;377.4315;39.00134;4;4;0;1.123734;1.117467;346385.7;3.943961e+007
1648.302;0.3700176;-0.08522479;450.2912;46.53018;4;4;0;1.16541;1.158671;413252.3;4.707245e+007
1652.302;0.3833569;-0.09788641;526.6739;54.42308;4;4;0;1.207423;1.200192;483352.2;5.50802e+007
1656.302;0.3966426;-0.1106821;604.5345;62.46869;4;4;0;1.249268;1.241529;554808.3;6.324909e+007
1660.302;0.4100354;-0.123967;685.7332;70.85924;4;4;0;1.29145;1.283182;629327.9;7.177435e+007
1664.302;0.4232676;-0.1374869;766.9484;79.2515;4;4;0;1.333126;1.324318;703862.8;8.030802e+007
1668.302;0.436714;-0.1518947;850.0232;87.8359;4;4;0;1.375477;1.366103;780104.2;8.904407e+007
1672.302;0.4501069;-0.1662227;933.5346;96.46543;4;4;0;1.417659;1.407705;856746.3;9.783298e+007
1676.302;0.463339;-0.1809963;1014.039;104.7842;4;4;0;1.459335;1.44879;930628.4;1.063133e+008
1680.302;0.4767854;-0.1968594;1095.575;113.2097;4;4;0;1.501686;1.490523;1005458;1.149097e+008
1684.302;0.4901247;-0.2133696;1178.795;121.8091;4;4;0;1.5437;1.531906;1081833;1.236894e+008
1688.302;0.5034104;-0.2295718;1263.733;130.586;4;4;0;1.585544;1.573106;1159784;1.326565e+008
1692.302;0.5168032;-0.2473133;1349.886;139.4885;4;4;0;1.627727;1.614621;1238851;1.41759e+008
1696.302;0.5300354;-0.2663777;1434.128;148.1935;4;4;0;1.669403;1.655621;1316163;1.506674e+008
1700.302;0.5433211;-0.2869469;1518.768;156.9397;4;4;0;1.711247;1.696771;1393842;1.596253e+008
1704.302;0.5566603;-0.3089316;1603.518;165.6972;4;4;0;1.753261;1.738069;1471620;1.686023e+008
1708.302;0.5699996;-0.3331867;1687.516;174.377;4;4;0;1.795274;1.77935;1548708;1.775075e+008
1712.302;0.5833925;-0.358629;1771.075;183.0114;4;4;0;1.837457;1.820779;1625394;1.863742e+008
1716.302;0.5966246;-0.3854119;1853.669;191.5462;4;4;0;1.879133;1.861695;1701195;1.951456e+008
1720.302;0.6100711;-0.4141508;1936.858;200.1424;4;4;0;1.921484;1.903256;1777541;2.039881e+008
1724.302;0.6234639;-0.4440273;2019.715;208.7043;4;4;0;1.963666;1.944635;1853583;2.128026e+008
1728.302;0.636696;-0.4751326;2100.896;217.093;4;4;0;2.005342;1.9855;1928086;2.214465e+008
1732.302;0.6501959;-0.5092511;2182.939;225.5708;4;4;0;2.047861;2.027175;2003380;2.301902e+008
1736.302;0.6634817;-0.5448082;2261.79;233.7188;4;4;0;2.089706;2.068171;2075746;2.386028e+008
1740.302;0.6767139;-0.581752;2337.241;241.5154;4;4;0;2.131382;2.108986;2144991;2.46663e+008
1744.302;0.6901067;-0.6211235;2412.313;249.2729;4;4;0;2.173564;2.150279;2213888;2.54691e+008
1748.302;0.7033924;-0.6621306;2483.843;256.6643;4;4;0;2.215409;2.191226;2279534;2.623505e+008
1752.302;0.7166781;-0.7048457;2553.267;263.8382;4;4;0;2.257254;2.232155;2343247;2.697937e+008
1756.302;0.7299638;-0.749724;2621.003;270.8375;4;4;0;2.299098;2.273068;2405411;2.770643e+008
1760.302;0.7433031;-0.796085;2686.751;277.6315;4;4;0;2.341112;2.314128;2465751;2.841312e+008
1764.302;0.756696;-0.8446849;2752.952;284.4723;4;4;0;2.383294;2.355337;2526507;2.912521e+008
1768.302;0.7699281;-0.8938543;2817.09;291.0999;4;4;0;2.42497;2.396035;2585370;2.98159e+008
1772.302;0.783428;-0.9452306;2882.228;297.8308;4;4;0;2.46749;2.437539;2645150;3.051798e+008
1776.302;0.7967673;-0.9981109;2942.638;304.0732;4;4;0;2.509503;2.478532;2700590;3.117039e+008
1778.542;0.7908209;-0.9825098;2860.375;295.5727;4;4;0;2.490775;2.46026;2625094;3.029347e+008
1782.542;0.7775352;-0.9380572;2708.826;279.9126;4;4;0;2.44893;2.419424;2486011;2.867675e+008
1786.542;0.7640888;-0.8923364;2569.198;265.4843;4;4;0;2.406579;2.378077;2357868;2.718734e+008
1790.542;0.7508031;-0.8464449;2438.55;251.984;4;4;0;2.364734;2.337207;2237966;2.579427e+008
1794.542;0.737571;-0.8012309;2314.927;239.2096;4;4;0;2.323058;2.296486;2124512;2.447666e+008
1798.542;0.7241781;-0.7562251;2194.977;226.8147;4;4;0;2.280876;2.255253;2014428;2.319881e+008
1802.542;0.7108924;-0.7097858;2089.323;215.8972;4;4;0;2.239031;2.214333;1917465;2.207312e+008
1806.542;0.6976067;-0.6640103;1987.708;205.3969;4;4;0;2.197186;2.173396;1824208;2.099098e+008
1810.542;0.6842674;-0.6193957;1890.852;195.3884;4;4;0;2.155173;2.132278;1735319;1.995994e+008
1814.542;0.6708745;-0.5746309;1801.066;186.1105;4;4;0;2.112991;2.090976;1652918;1.90043e+008
1818.542;0.6575353;-0.5329901;1710.488;176.7508;4;4;0;2.070977;2.049824;1569791;1.804113e+008
1822.542;0.6442496;-0.4929661;1623.027;167.7131;4;4;0;2.029133;2.00882;1489524;1.711162e+008
1826.542;0.6308032;-0.454145;1538.055;158.9327;4;4;0;1.986782;1.967303;1411542;1.620904e+008
1830.542;0.6174639;-0.4179386;1453.035;150.1472;4;4;0;1.944768;1.926099;1333515;1.530672e+008
1834.542;0.6041782;-0.3845396;1369.754;141.5415;4;4;0;1.902923;1.885044;1257084;1.442349e+008
1838.542;0.5907318;-0.3522114;1286.388;132.927;4;4;0;1.860572;1.843476;1180576;1.354002e+008
1842.542;0.5774996;-0.3228787;1207.583;124.7838;4;4;0;1.818897;1.802552;1108253;1.270535e+008
1846.542;0.5642675;-0.2948357;1128.826;116.6456;4;4;0;1.77722;1.761613;1035974;1.187187e+008
1850.542;0.5508746;-0.2675013;1052.92;108.802;4;4;0;1.735038;1.720158;966312;1.106897e+008
1854.542;0.5375889;-0.24155;979.1401;101.178;4;4;0;1.693193;1.679019;898600.5;1.028911e+008
1858.542;0.5242496;-0.2176954;905.588;93.57761;4;4;0;1.65118;1.637696;831098.4;9.512275e+007
1862.542;0.5109104;-0.1965941;833.305;86.10835;4;4;0;1.609167;1.596357;764761.1;8.749398e+007
1866.542;0.4975711;-0.1776408;761.3683;78.67488;4;4;0;1.567153;1.555;698741.6;7.990783e+007
1870.542;0.4841783;-0.1607328;691.2249;71.42672;4;4;0;1.524971;1.51346;634367.9;7.251596e+007
1874.542;0.4708926;-0.1452469;623.0425;64.38118;4;4;0;1.483126;1.472235;571793.8;6.533604e+007
1878.542;0.4574461;-0.1312143;556.4341;57.49831;4;4;0;1.440775;1.430495;510664.4;5.832673e+007
1882.542;0.4441068;-0.1178445;491.8317;50.82271;4;4;0;1.398762;1.389069;451375.9;5.15336e+007
1886.542;0.4308747;-0.1051901;429.7473;44.40731;4;4;0;1.357086;1.34796;394398.3;4.500996e+007
1890.542;0.4174283;-0.09288929;369.7197;38.20445;4;4;0;1.314735;1.306167;339308.3;3.870673e+007
1894.542;0.4041962;-0.08174866;314.0114;32.44791;4;4;0;1.273059;1.265024;288182.3;3.286099e+007
1898.542;0.3909105;-0.07102807;261.4462;27.01616;4;4;0;1.231214;1.223696;239940.8;2.734879e+007
1902.542;0.3775176;-0.06050636;212.3431;21.94216;4;4;0;1.189032;1.182018;194876.7;2.220306e+007
1906.542;0.3642319;-0.05053436;167.6685;17.32578;4;4;0;1.147187;1.140657;153876.8;1.752454e+007
1910.542;0.3508926;-0.04064474;126.8511;13.10797;4;4;0;1.105174;1.099111;116416.9;1.325284e+007
1914.542;0.3376069;-0.03193126;92.57989;9.566607;4;4;0;1.063329;1.057715;84964.69;9668332
1918.542;0.3242141;-0.02424576;66.51888;6.873631;4;4;0;1.021147;1.015968;61047.34;6943821
1922.542;0.3108212;-0.01933259;51.54589;5.32642;4;4;0;0.9789645;0.9742037;47305.96;5378563
1926.542;0.2975355;-0.01812199;49.67147;5.132729;4;4;0;0.9371198;0.9327561;45585.73;5180829
1927.128;0.2955534;-0.01797572;49.43979;5.108788;4;4;0;0.9308768;0.9265708;45373.1;5156345