File: Ensayos/Resistencia/comp/Clavo6/Clavo6f.raw
"Test Type";"Manual"
"Method Name:";"C:\INSTRON\user\template\CYCLE.MTM"
"Name:";""
"Operator ID:";""
"Company:";""
"Lab name:";""
"Test date:";"07/06/2017"
"Temperature:";""
"Humidity:";""
"Note 1:";""
"Note 2:";""
"Note 3:";""
"Geometry:";"Rectangular"
"Specimen";1
"Specimen name:";""
"Width:";0.250000;"in"
"Thickness:";0.060000;"in"
"Length:";1.250000;"in"
"Diameter:";0.039370;"in"
"Inner diameter:";0.019685;"in"
"Outer diameter:";0.039370;"in"
"Wall thickness:";0.019685;"in"
"Area:";0.015000;"in*in"
"Linear density:";1.000000;"den"
"Sled weight:";2.204623;"lbf"
"Loading span:";0.000000;"mm"
"Support span:";1.000000;"mm"
"Span ratio:";"2"
"Fixture type:";"3-point"
"Comment:";""
"Included"
"Final Width:";0.250000;"in"
"Final Thickness:";0.060000;"in"
"Final Length:";1.250000;"in"
"Final Diameter:";0.039370;"in"
"Final Inner diameter:";0.019685;"in"
"Final Outer diameter:";0.039370;"in"
"Final Wall thickness:";0.019685;"in"
"Final Area:";0.015000;"in*in"
"Final Linear density:";1.000000;"den"
"Time sec";"Extension mm";"Strain 1 %";"Load N";"Stress MPa";"Cycle Count ";"Total Cycle Count ";"Repetitions Count ";"Strain [Exten.] %";"True strain %";"Tenacity gf/tex";"True stress Pa"
0;0;0.0004018206;76.45822;7.900699;0;0;0;0;0;70169.12;7900698
5;0.0001071428;0.00036212;76.36322;7.890882;0;0;0;0.0003374576;0.000337457;70081.94;7890909
10;0.0001071428;0.0005506002;76.72497;7.928262;0;0;0;0.0003374576;0.000337457;70413.92;7928289
15;0.0002142856;0.0004572608;76.54032;7.909182;0;0;0;0.0006749152;0.000674913;70244.46;7909236
20;0.0003214284;0.0007834015;76.67842;7.923452;0;0;0;0.001012373;0.001012368;70371.2;7923533
25;0.0004285712;0.000721149;76.73451;7.929248;0;0;0;0.00134983;0.001349821;70422.68;7929355
30;0.0005357139;0.0008126875;76.50379;7.905407;0;0;0;0.001687288;0.001687274;70210.94;7905541
35;0.0005357139;0.000749887;76.55659;7.910863;0;0;0;0.001687288;0.001687274;70259.39;7910997
40;0.0006428567;0.0008449494;76.49025;7.904008;0;0;0;0.002024746;0.002024725;70198.52;7904169
45;0.0007499995;0.0009381323;76.60559;7.915927;0;0;0;0.002362203;0.002362175;70304.37;7916114
50;0.0008571423;0.0008431482;76.95424;7.951954;0;0;0;0.002699661;0.002699624;70624.34;7952169
55;0.0009107137;0.0007676621;76.41071;7.895789;0;0;0;0.00286839;0.002868348;70125.52;7896015
60;0.0009642851;0.0009166767;76.52425;7.907522;0;0;0;0.003037118;0.003037072;70229.72;7907762
65;0.001071428;0.0009681232;76.52534;7.907635;0;0;0;0.003374576;0.003374519;70230.72;7907902
70;0.001178571;0.001054964;76.6729;7.922882;0;0;0;0.003712033;0.003711965;70366.14;7923176
75;0.001178571;0.001035857;76.57159;7.912414;0;0;0;0.003712033;0.003711965;70273.16;7912707
80;0.001285713;0.001212122;76.53034;7.908151;0;0;0;0.004049491;0.004049409;70235.3;7908471
85.00001;0.001392856;0.001312431;76.4196;7.896708;0;0;0;0.004386948;0.004386852;70133.67;7897054
90.00001;0.001499999;0.001324255;76.43476;7.898274;0;0;0;0.004724406;0.004724294;70147.59;7898647
95.00001;0.001607142;0.00138502;75.88356;7.841316;0;0;0;0.005061864;0.005061736;69641.73;7841713
100;0.001607142;0.00156379;75.76105;7.828657;0;0;0;0.005061864;0.005061736;69529.29;7829053
105;0.001714285;0.001289487;76.37979;7.892593;0;0;0;0.005399322;0.005399176;70097.13;7893020
110;0.001821427;0.001442652;76.57147;7.912401;0;0;0;0.005736779;0.005736615;70273.05;7912855
115;0.00192857;0.001567157;76.81497;7.937562;0;0;0;0.006074237;0.006074052;70496.52;7938045
120;0.002035713;0.001715546;76.81226;7.937283;0;0;0;0.006411694;0.006411489;70494.04;7937792
125;0.002035713;0.00172596;75.23756;7.774564;0;0;0;0.006411694;0.006411489;69048.87;7775062
130;0.002142856;0.001808494;75.27516;7.778448;0;0;0;0.006749152;0.006748924;69083.37;7778973
135;0.002249999;0.001723141;76.40536;7.895236;0;0;0;0.007086609;0.007086358;70120.6;7895796
140;0.002357141;0.001861037;76.70705;7.926411;0;0;0;0.007424067;0.007423791;70397.48;7926999
145;0.002410713;0.001880065;76.85437;7.941634;0;0;0;0.007592796;0.007592507;70532.68;7942237
150;0.002464284;0.001804265;76.41816;7.896559;0;0;0;0.007761525;0.007761224;70132.35;7897172
155;0.002571427;0.00196808;76.27172;7.881427;0;0;0;0.008098982;0.008098654;69997.96;7882065
160;0.00267857;0.002062594;76.71574;7.927309;0;0;0;0.00843644;0.008436084;70405.45;7927978
165;0.002785712;0.002080447;76.31421;7.885818;0;0;0;0.008773897;0.008773512;70036.95;7886509
170;0.002785712;0.002116938;76.3091;7.88529;0;0;0;0.008773897;0.008773512;70032.27;7885982
175;0.002892855;0.002012714;76.51612;7.906682;0;0;0;0.009111355;0.00911094;70222.26;7907402
180;0.002999998;0.002350052;76.59056;7.914374;0;0;0;0.009448812;0.009448366;70290.58;7915122
185;0.003107141;0.002261567;76.98487;7.955119;0;0;0;0.009786271;0.009785792;70652.45;7955897
190;0.003107141;0.002347938;76.03337;7.856797;0;0;0;0.009786271;0.009785792;69779.21;7857566
195;0.003214284;0.002441669;76.93794;7.95027;0;0;0;0.01012373;0.01012322;70609.38;7951075
200;0.003321426;0.002665152;76.89466;7.945797;0;0;0;0.01046119;0.01046064;70569.66;7946628
205;0.003428569;0.002678464;76.45305;7.900164;0;0;0;0.01079864;0.01079806;70164.38;7901017
210;0.003428569;0.00257933;76.53759;7.9089;0;0;0;0.01079864;0.01079806;70241.96;7909754
215;0.003535712;0.00283664;76.97673;7.954278;0;0;0;0.0111361;0.01113548;70644.98;7955164
220;0.003642855;0.002541117;76.40304;7.894996;0;0;0;0.01147356;0.0114729;70118.48;7895902
225;0.003749998;0.002711195;76.6389;7.919369;0;0;0;0.01181102;0.01181032;70334.94;7920304
230;0.00385714;0.002850265;76.69222;7.924879;0;0;0;0.01214847;0.01214774;70383.87;7925841
235;0.00385714;0.002757004;76.49131;7.904118;0;0;0;0.01214847;0.01214774;70199.48;7905078
240;0.003964283;0.002644636;76.57394;7.912656;0;0;0;0.01248593;0.01248515;70275.32;7913644
245;0.004071426;0.00290915;76.80607;7.936643;0;0;0;0.01282339;0.01282257;70488.35;7937661
250;0.004124997;0.002860915;76.51964;7.907046;0;0;0;0.01299212;0.01299127;70225.49;7908073
255;0.00423214;0.002997792;76.63884;7.919362;0;0;0;0.01332957;0.01332869;70334.88;7920418
260;0.004285712;0.003078916;76.55729;7.910936;0;0;0;0.0134983;0.01349739;70260.04;7912004
265;0.004392855;0.003089252;76.45364;7.900225;0;0;0;0.01383576;0.01383481;70164.91;7901318
270;0.004446426;0.002994112;76.48133;7.903086;0;0;0;0.01400449;0.01400351;70190.32;7904193
275;0.004553569;0.003307254;76.42025;7.896775;0;0;0;0.01434195;0.01434092;70134.27;7897907
280;0.00460714;0.003372873;76.57271;7.912529;0;0;0;0.01451068;0.01450962;70274.19;7913677
285;0.004714283;0.003369193;76.31674;7.886079;0;0;0;0.01484813;0.01484703;70039.27;7887250
290;0.004767854;0.003487591;76.57444;7.912708;0;0;0;0.01501686;0.01501574;70275.78;7913896
295;0.004874997;0.003419544;76.56569;7.911804;0;0;0;0.01535432;0.01535314;70267.75;7913018
300;0.00498214;0.003419152;76.52769;7.907877;0;0;0;0.01569178;0.01569055;70232.88;7909118
305;0.005035711;0.003475297;76.47486;7.902419;0;0;0;0.01586051;0.01585925;70184.39;7903672
310;0.005142854;0.003532459;76.08814;7.862456;0;0;0;0.01619796;0.01619665;69829.48;7863730
315;0.005196425;0.003608024;76.68591;7.924226;0;0;0;0.01636669;0.01636535;70378.08;7925523
320;0.005357139;0.003649839;76.79397;7.935393;0;0;0;0.01687288;0.01687146;70477.25;7936732
325;0.005357139;0.00386463;76.40627;7.89533;0;0;0;0.01687288;0.01687146;70121.45;7896663
330;0.005464282;0.003687817;76.47052;7.901969;0;0;0;0.01721034;0.01720886;70180.41;7903329
335;0.005571425;0.003689383;76.49017;7.904;0;0;0;0.01754779;0.01754625;70198.44;7905387
340;0.005678568;0.003605596;76.72675;7.928447;0;0;0;0.01788525;0.01788365;70415.56;7929865
345;0.00578571;0.00390668;76.52784;7.907892;0;0;0;0.01822271;0.01822105;70233.01;7909333
350;0.00578571;0.003841686;76.43155;7.897943;0;0;0;0.01822271;0.01822105;70144.64;7899382
355;0.005892853;0.003878881;76.54432;7.909595;0;0;0;0.01856017;0.01855845;70248.13;7911063
360;0.005999996;0.00384568;76.67992;7.923608;0;0;0;0.01889762;0.01889584;70372.59;7925105
365;0.006107139;0.003922497;76.6541;7.92094;0;0;0;0.01923508;0.01923323;70348.89;7922464
370;0.006107139;0.003901746;76.41461;7.896193;0;0;0;0.01923508;0.01923323;70129.09;7897711
375;0.006214282;0.003975432;76.48376;7.903338;0;0;0;0.01957254;0.01957063;70192.56;7904885
380;0.006321425;0.003904487;76.55812;7.911021;0;0;0;0.01991;0.01990802;70260.8;7912596
385;0.006428567;0.00413118;76.56449;7.91168;0;0;0;0.02024746;0.02024541;70266.64;7913281
390;0.006428567;0.004135331;76.34501;7.889;0;0;0;0.02024746;0.02024541;70065.23;7890598
395;0.00653571;0.004221075;76.49906;7.904919;0;0;0;0.02058491;0.0205828;70206.6;7906546
400;0.006696424;0.00416861;76.40633;7.895336;0;0;0;0.0210911;0.02108888;70121.49;7897002
405;0.006749996;0.004042461;76.36464;7.891028;0;0;0;0.02125983;0.02125757;70083.23;7892706
410;0.006857139;0.004119043;76.52367;7.907462;0;0;0;0.02159729;0.02159496;70229.18;7909169
415;0.006857139;0.00440611;76.556;7.910802;0;0;0;0.02159729;0.02159496;70258.86;7912511
420;0.006964281;0.004306114;76.42354;7.897115;0;0;0;0.02193474;0.02193234;70137.29;7898847
425;0.007071424;0.004157647;76.33315;7.887775;0;0;0;0.0222722;0.02226972;70054.34;7889532
430;0.007178567;0.004343152;76.73571;7.929372;0;0;0;0.02260966;0.0226071;70423.78;7931165
435;0.00728571;0.004565069;76.6401;7.919493;0;0;0;0.02294712;0.02294448;70336.04;7921310
440;0.00728571;0.004462333;76.54989;7.910171;0;0;0;0.02294712;0.02294448;70253.25;7911986
445;0.007392853;0.004311439;76.49251;7.904243;0;0;0;0.02328457;0.02328186;70200.59;7906083
450;0.007499996;0.004563503;76.35377;7.889905;0;0;0;0.02362203;0.02361924;70073.26;7891769
455;0.007607138;0.004621214;76.51612;7.906682;0;0;0;0.02395949;0.02395662;70222.26;7908576
460;0.007607138;0.004896065;76.46283;7.901175;0;0;0;0.02395949;0.02395662;70173.35;7903068
465;0.007714281;0.004857852;76.39461;7.894126;0;0;0;0.02429695;0.024294;70110.74;7896044
470;0.007821424;0.004816428;76.62732;7.918173;0;0;0;0.02463441;0.02463137;70324.31;7920123
475;0.007928567;0.004760675;76.95997;7.952546;0;0;0;0.02497186;0.02496875;70629.59;7954532
480;0.008035709;0.005025816;76.83258;7.939383;0;0;0;0.02530932;0.02530612;70512.69;7941392
485;0.008035709;0.005070529;76.75988;7.93187;0;0;0;0.02530932;0.02530612;70445.96;7933877
490;0.008142852;0.005176945;76.78196;7.934151;0;0;0;0.02564678;0.02564349;70466.23;7936186
495;0.008249995;0.005141395;76.51436;7.9065;0;0;0;0.02598424;0.02598086;70220.64;7908555
500;0.008357138;0.005302468;76.72061;7.927813;0;0;0;0.02632169;0.02631823;70409.93;7929899
505;0.008357138;0.005343735;76.56046;7.911264;0;0;0;0.02632169;0.02631823;70262.95;7913346
510;0.00846428;0.005564399;76.48121;7.903074;0;0;0;0.02665915;0.0266556;70190.21;7905181
515;0.008571423;0.005563303;76.50681;7.90572;0;0;0;0.02699661;0.02699296;70213.71;7907854
520;0.008678566;0.005521409;76.74631;7.930468;0;0;0;0.02733407;0.02733033;70433.52;7932636
525;0.008678566;0.005865482;76.59224;7.914547;0;0;0;0.02733407;0.02733033;70292.11;7916711
530;0.008785709;0.005915832;76.63114;7.918568;0;0;0;0.02767153;0.0276677;70327.82;7920759
535;0.008892851;0.005751391;76.61264;7.916656;0;0;0;0.02800898;0.02800506;70310.84;7918873
540;0.008999994;0.006089591;76.63972;7.919453;0;0;0;0.02834644;0.02834242;70335.69;7921698
545;0.009107137;0.005880908;76.74951;7.930799;0;0;0;0.0286839;0.02867978;70436.45;7933074
550;0.009107137;0.006200002;76.71169;7.92689;0;0;0;0.0286839;0.02867978;70401.73;7929164
555;0.00921428;0.006281517;76.78933;7.934914;0;0;0;0.02902135;0.02901714;70472.99;7937216
560;0.009321422;0.006226077;76.69422;7.925085;0;0;0;0.02935881;0.0293545;70385.7;7927412
565;0.009428565;0.00657336;77.00531;7.957231;0;0;0;0.02969627;0.02969186;70671.2;7959594
570;0.009535708;0.006570854;76.95865;7.952409;0;0;0;0.03003373;0.03002922;70628.38;7954798
575;0.009535708;0.006761136;76.88485;7.944784;0;0;0;0.03003373;0.03002922;70560.66;7947170
580;0.009642851;0.006495447;76.88985;7.9453;0;0;0;0.03037118;0.03036657;70565.24;7947713
585;0.009749994;0.006810077;76.76275;7.932167;0;0;0;0.03070864;0.03070393;70448.6;7934603
590;0.009749994;0.006783297;76.90265;7.946623;0;0;0;0.03070864;0.03070393;70576.99;7949063
595;0.00996428;0.006972012;76.61437;7.916834;0;0;0;0.03138356;0.03137863;70312.43;7919319
600;0.00996428;0.00701735;76.83053;7.93917;0;0;0;0.03138356;0.03137863;70510.8;7941662
605;0.01007142;0.007421248;76.91609;7.948012;0;0;0;0.03172101;0.03171599;70589.33;7950534
610;0.01017856;0.007160179;76.9777;7.954379;0;0;0;0.03205847;0.03205333;70645.87;7956928
615;0.01017856;0.007422501;76.99509;7.956175;0;0;0;0.03205847;0.03205333;70661.83;7958726
620;0.01028571;0.007529309;76.99209;7.955865;0;0;0;0.03239593;0.03239068;70659.08;7958443
625;0.01039285;0.007676523;76.99855;7.956533;0;0;0;0.03273339;0.03272803;70665.01;7959137
630;0.01049999;0.007532285;77.16191;7.973413;0;0;0;0.03307085;0.03306538;70814.92;7976050
635;0.01060714;0.007824441;77.02759;7.959534;0;0;0;0.0334083;0.03340272;70691.66;7962193
640;0.01060714;0.007898126;76.96182;7.952737;0;0;0;0.0334083;0.03340272;70631.29;7955394
645.0001;0.01071428;0.008219177;76.76396;7.932292;0;0;0;0.03374576;0.03374007;70449.7;7934968
650.0001;0.01082142;0.008087782;76.92085;7.948504;0;0;0;0.03408322;0.03407741;70593.7;7951213
655.0001;0.01092856;0.008505539;77.16446;7.973677;0;0;0;0.03442068;0.03441475;70817.27;7976421
660.0001;0.01103571;0.008929326;76.8917;7.945491;0;0;0;0.03475814;0.03475209;70566.94;7948253
665.0001;0.01103571;0.008749068;76.90544;7.946911;0;0;0;0.03475814;0.03475209;70579.55;7949673
670.0001;0.01114285;0.008488155;76.97929;7.954542;0;0;0;0.03509559;0.03508943;70647.33;7957334
675.0001;0.01124999;0.008071573;76.83775;7.939917;0;0;0;0.03543305;0.03542677;70517.43;7942730
680.0001;0.01135714;0.008771072;76.99124;7.955777;0;0;0;0.03577051;0.03576411;70658.29;7958623
685.0001;0.01146428;0.009090478;76.94038;7.950522;0;0;0;0.03610796;0.03610145;70611.62;7953393
690.0001;0.01146428;0.008923767;77.08667;7.965639;0;0;0;0.03610796;0.03610145;70745.88;7968515
695.0001;0.01157142;0.008812887;76.92934;7.949381;0;0;0;0.03644542;0.03643878;70601.48;7952278
700.0001;0.01167856;0.009464307;76.9526;7.951784;0;0;0;0.03678288;0.03677611;70622.83;7954709
705.0001;0.01178571;0.009463915;77.08518;7.965484;0;0;0;0.03712033;0.03711345;70744.51;7968441
710.0001;0.01178571;0.009867343;76.87745;7.944019;0;0;0;0.03712033;0.03711345;70553.87;7946968
715.0001;0.01189285;0.01020319;76.91724;7.948131;0;0;0;0.03745779;0.03745078;70590.38;7951108
720.0001;0.01199999;0.009580042;76.85378;7.941573;0;0;0;0.03779525;0.03778811;70532.14;7944575
725.0001;0.01210713;0.009283814;77.11698;7.968771;0;0;0;0.0381327;0.03812543;70773.7;7971809
730.0001;0.01210713;0.009694837;76.94267;7.950758;0;0;0;0.0381327;0.03812543;70613.72;7953791
735.0001;0.01221428;0.009849882;77.05396;7.962259;0;0;0;0.03847016;0.03846277;70715.86;7965322
740.0001;0.01232142;0.009888564;77.02847;7.959625;0;0;0;0.03880762;0.0388001;70692.47;7962714
745.0001;0.01242856;0.01044774;76.92455;7.948886;0;0;0;0.03914508;0.03913742;70597.09;7951998
750.0001;0.01253571;0.0101981;77.06679;7.963584;0;0;0;0.03948254;0.03947475;70727.63;7966729
755.0001;0.01253571;0.01136563;77.13762;7.970903;0;0;0;0.03948254;0.03947475;70792.63;7974051
760.0001;0.01264285;0.01134778;77.11308;7.968367;0;0;0;0.03982;0.03981207;70770.11;7971540
765.0001;0.01274999;0.01113784;77.05769;7.962644;0;0;0;0.04015746;0.0401494;70719.28;7965842
770.0001;0.01285713;0.01166546;77.11148;7.968203;0;0;0;0.04049491;0.04048671;70768.65;7971429
775.0001;0.01296428;0.01137299;76.88744;7.945051;0;0;0;0.04083237;0.04082404;70563.03;7948295
780.0001;0.01296428;0.01150353;77.08982;7.965964;0;0;0;0.04083237;0.04082404;70748.77;7969216
785.0001;0.01307142;0.01210319;76.93321;7.949781;0;0;0;0.04116983;0.04116136;70605.04;7953054
790.0001;0.01317856;0.01206756;77.08007;7.964956;0;0;0;0.04150729;0.04149867;70739.81;7968262
795.0001;0.01317856;0.01243097;77.15406;7.972602;0;0;0;0.04150729;0.04149867;70807.73;7975912
800.0001;0.01328571;0.01215362;76.81626;7.937696;0;0;0;0.04184474;0.04183599;70497.7;7941017
805.0001;0.01339285;0.01264373;76.97955;7.95457;0;0;0;0.0421822;0.04217331;70647.57;7957925
810.0001;0.01349999;0.01256605;76.8771;7.943983;0;0;0;0.04251966;0.04251062;70553.54;7947360
815.0001;0.01360713;0.01288796;76.70693;7.926399;0;0;0;0.04285712;0.04284794;70397.37;7929796
820.0001;0.01360713;0.01350587;76.9269;7.949129;0;0;0;0.04285712;0.04284794;70599.25;7952536
825.0001;0.01371428;0.01327526;77.13037;7.970154;0;0;0;0.04319457;0.04318525;70785.98;7973597
830.0001;0.01382142;0.01400318;76.96131;7.952685;0;0;0;0.04353203;0.04352256;70630.83;7956147
835.0001;0.01392856;0.0135036;76.8897;7.945285;0;0;0;0.04386949;0.04385987;70565.1;7948770
840.0001;0.01403571;0.01413348;76.86659;7.942896;0;0;0;0.04420695;0.04419718;70543.89;7946408
845.0001;0.01403571;0.01486376;76.78812;7.934789;0;0;0;0.04420695;0.04419718;70471.88;7938296
850.0001;0.01414285;0.01432917;77.09953;7.966968;0;0;0;0.0445444;0.04453448;70757.68;7970516
855.0001;0.01424999;0.01565707;77.13045;7.970163;0;0;0;0.04488186;0.04487179;70786.05;7973740
860.0001;0.01430356;0.01605259;76.83094;7.939213;0;0;0;0.04505059;0.04504045;70511.18;7942790
865.0001;0.01435713;0.01551956;76.98372;7.955;0;0;0;0.04521932;0.0452091;70651.4;7958598
870.0001;0.01446428;0.01579669;76.98784;7.955426;0;0;0;0.04555678;0.0455464;70655.17;7959050
875.0001;0.01451785;0.0185867;77.03892;7.960705;0;0;0;0.04572551;0.04571505;70702.05;7964345
880.0001;0.01462499;0.01618766;76.94848;7.951359;0;0;0;0.04606296;0.04605236;70619.05;7955022
885.0001;0.01473213;0.01594562;77.17982;7.975264;0;0;0;0.04640042;0.04638966;70831.36;7978964
890.0001;0.01478571;0.01713022;77.06674;7.963579;0;0;0;0.04656915;0.04655831;70727.59;7967287
895.0001;0.01489285;0.01636776;76.80466;7.936497;0;0;0;0.04690661;0.04689561;70487.05;7940220
900.0001;0.01494642;0.01756599;77.22498;7.979931;0;0;0;0.04707533;0.04706426;70872.81;7983687
905.0001;0.01505356;0.01880924;77.01735;7.958475;0;0;0;0.04741279;0.04740156;70682.26;7962249
910.0001;0.01510713;0.01940553;76.92018;7.948434;0;0;0;0.04758152;0.04757021;70593.08;7952217
915.0001;0.01521428;0.01845969;76.96984;7.953566;0;0;0;0.04791898;0.0479075;70638.65;7957377
920.0001;0.01532142;0.0183048;77.03479;7.960278;0;0;0;0.04825644;0.0482448;70698.26;7964119
925.0001;0.01537499;0.01872553;76.97614;7.954217;0;0;0;0.04842516;0.04841344;70644.44;7958069
930.0001;0.01548213;0.01946841;76.97506;7.954105;0;0;0;0.04876262;0.04875073;70643.45;7957984
935.0001;0.0155357;0.01869797;77.07448;7.964379;0;0;0;0.04893135;0.04891938;70734.69;7968276
940.0001;0.01564285;0.01927884;77.26139;7.983693;0;0;0;0.04926881;0.04925668;70906.23;7987627
945.0001;0.01574999;0.02063038;76.98384;7.955013;0;0;0;0.04960626;0.04959397;70651.5;7958959
950.0001;0.01580356;0.01941595;76.95882;7.952427;0;0;0;0.04977499;0.04976261;70628.54;7956386
955.0001;0.0159107;0.0195255;76.84841;7.941018;0;0;0;0.05011245;0.0500999;70527.21;7944998
960.0001;0.01596428;0.02025452;77.24137;7.981624;0;0;0;0.05028118;0.05026855;70887.85;7985637
965.0001;0.01607142;0.02030197;76.88048;7.944332;0;0;0;0.05061864;0.05060583;70556.64;7948353
970.0001;0.01617856;0.02087125;77.16816;7.974059;0;0;0;0.0509561;0.05094312;70820.66;7978122
975.0001;0.0162857;0.02112605;77.33369;7.991164;0;0;0;0.05129355;0.0512804;70972.57;7995263
980.0001;0.0162857;0.0280653;77.06333;7.963227;0;0;0;0.05129355;0.0512804;70724.45;7967311
985.0001;0.01639285;0.03255696;77.1358;7.970715;0;0;0;0.05163101;0.05161768;70790.96;7974830
990.0001;0.01649999;0.03325309;77.14616;7.971786;0;0;0;0.05196847;0.05195497;70800.48;7975929
995.0001;0.01660713;0.03746465;77.13859;7.971004;0;0;0;0.05230593;0.05229225;70793.52;7975173
1000;0.0166607;0.0423595;77.13906;7.971052;0;0;0;0.05247466;0.05246089;70793.95;7975235
1005;0.01676785;0.04612348;76.97036;7.95362;0;0;0;0.05281211;0.05279818;70639.13;7957820
1010;0.01682142;0.05291699;77.1873;7.976038;0;0;0;0.05298084;0.05296681;70838.23;7980263
1015;0.01687499;0.05880882;77.16722;7.973962;0;0;0;0.05314957;0.05313545;70819.8;7978200
1020;0.01698213;0.06266966;77.21858;7.979269;0;0;0;0.05348703;0.05347273;70866.93;7983537
1025;0.01708927;0.06809863;77.00187;7.956876;0;0;0;0.05382449;0.05381001;70668.05;7961158
1030;0.01714285;0.07464369;76.99338;7.955999;0;0;0;0.05399322;0.05397865;70660.26;7960294
1035;0.01724999;0.08200711;77.26462;7.984027;0;0;0;0.05433067;0.05431592;70909.19;7988365
1040;0.01735713;0.09301289;77.15254;7.972445;0;0;0;0.05466813;0.0546532;70806.33;7976804
1045;0.0174107;0.1047592;77.16455;7.973686;0;0;0;0.05483686;0.05482183;70817.34;7978058
1050;0.01757142;0.1141646;77.0697;7.963885;0;0;0;0.05534305;0.05532774;70730.3;7968292
1055;0.01757142;0.1224961;77.32406;7.990169;0;0;0;0.05534305;0.05532774;70963.73;7994590
1060;0.01757142;0.1287215;77.26941;7.984521;0;0;0;0.05534305;0.05532774;70913.58;7988940
1065;0.0177857;0.1379824;76.9567;7.952209;0;0;0;0.05601796;0.05600228;70626.6;7956663
1070;0.0177857;0.1454549;77.0105;7.957768;0;0;0;0.05601796;0.05600228;70675.97;7962226
1075;0.01789285;0.153;77.10618;7.967654;0;0;0;0.05635542;0.05633955;70763.77;7972144
1080;0.01799999;0.159285;77.31093;7.988812;0;0;0;0.05669288;0.05667681;70951.69;7993341
1085;0.01805356;0.1642928;77.27898;7.985511;0;0;0;0.05686161;0.05684545;70922.37;7990051
1090;0.01810713;0.1682484;77.13207;7.97033;0;0;0;0.05703034;0.05701408;70787.54;7974875
1095;0.01821427;0.1708385;77.20364;7.977725;0;0;0;0.05736779;0.05735134;70853.22;7982302
1100;0.01832142;0.1746863;77.17383;7.974645;0;0;0;0.05770525;0.0576886;70825.87;7979247
1105;0.01837499;0.1777279;77.12247;7.969338;0;0;0;0.05787398;0.05785724;70778.73;7973950
1110;0.01848213;0.1779953;77.08503;7.965469;0;0;0;0.05821144;0.0581945;70744.37;7970106
1115;0.0185357;0.1809856;77.27358;7.984952;0;0;0;0.05838016;0.05836313;70917.41;7989614
1120;0.01864284;0.1822954;77.22815;7.980258;0;0;0;0.05871762;0.05870039;70875.72;7984944
1125;0.01869642;0.1827648;77.23588;7.981057;0;0;0;0.05888636;0.05886902;70882.81;7985756
1130;0.01880356;0.1838114;77.17204;7.97446;0;0;0;0.05922381;0.05920628;70824.22;7979182
1135;0.01885713;0.1846498;77.0705;7.963967;0;0;0;0.05939253;0.05937491;70731.03;7968697
1140;0.01896427;0.1853888;76.89102;7.945421;0;0;0;0.05973;0.05971217;70566.32;7950167
1145;0.01907142;0.1865908;76.96522;7.953089;0;0;0;0.06006745;0.06004942;70634.41;7957866
1150;0.01912499;0.1858035;77.31445;7.989176;0;0;0;0.06023618;0.06021804;70954.92;7993988
1155;0.01923213;0.1863888;77.2209;7.979509;0;0;0;0.06057364;0.0605553;70869.06;7984343
1160;0.01933927;0.1870677;77.11046;7.968096;0;0;0;0.06091109;0.06089255;70767.7;7972950
1165;0.01939284;0.187736;77.07264;7.964189;0;0;0;0.06107982;0.06106118;70733;7969053
1170;0.01949999;0.1874886;77.09393;7.966389;0;0;0;0.06141728;0.06139843;70752.54;7971281
1175;0.01955356;0.1872685;77.17574;7.974842;0;0;0;0.06158601;0.06156705;70827.62;7979754
1180;0.0196607;0.1874776;77.29196;7.986852;0;0;0;0.06192347;0.0619043;70934.28;7991798
1185;0.01976784;0.1880531;77.10068;7.967086;0;0;0;0.06226092;0.06224155;70758.73;7972046
1190;0.01982142;0.1876279;77.07199;7.964122;0;0;0;0.06242966;0.06241018;70732.41;7969094
1195;0.01992856;0.1881853;77.17732;7.975006;0;0;0;0.06276712;0.06274743;70829.07;7980012
1200;0.01998213;0.1886378;77.05111;7.961964;0;0;0;0.06293584;0.06291604;70713.24;7966975
1205;0.02014285;0.1886907;77.03223;7.960013;0;0;0;0.06344203;0.06342192;70695.91;7965063
1210;0.02014285;0.1884024;77.39635;7.997639;0;0;0;0.06344203;0.06342192;71030.08;8002713
1215;0.02024999;0.1880937;77.19843;7.977187;0;0;0;0.06377948;0.06375915;70848.45;7982275
1220;0.02035713;0.1889717;77.24063;7.981548;0;0;0;0.06411694;0.0640964;70887.17;7986666
1225;0.02035713;0.1890421;77.19467;7.976799;0;0;0;0.06411694;0.0640964;70844.99;7981913
1230;0.02046427;0.1892359;77.30174;7.987862;0;0;0;0.0644544;0.06443364;70943.25;7993011
1235;0.02057142;0.1886078;77.21242;7.978632;0;0;0;0.06479186;0.06477088;70861.27;7983802
1240;0.02067856;0.1894784;77.16199;7.973422;0;0;0;0.06512932;0.06510812;70815;7978615
1245;0.0207857;0.1889855;77.33272;7.991064;0;0;0;0.06546678;0.06544535;70971.68;7996295
1250;0.0207857;0.1893803;77.12532;7.969633;0;0;0;0.06546678;0.06544535;70781.34;7974850
1255;0.02089284;0.1874943;77.121;7.969186;0;0;0;0.06580423;0.06578258;70777.38;7974430
1260;0.02099999;0.1880878;77.3422;7.992043;0;0;0;0.06614169;0.06611983;70980.39;7997330
1265;0.02110713;0.189846;77.29064;7.986715;0;0;0;0.06647915;0.06645706;70933.07;7992025
1270;0.02110713;0.1907103;77.11055;7.968106;0;0;0;0.06647915;0.06645706;70767.79;7973403
1275;0.02121427;0.1904357;77.11748;7.968822;0;0;0;0.06681661;0.0667943;70774.15;7974146
1280;0.02132141;0.1907866;77.09058;7.966043;0;0;0;0.06715406;0.06713152;70749.46;7971392
1285;0.02142856;0.1908208;77.31968;7.989717;0;0;0;0.06749152;0.06746875;70959.72;7995109
1290;0.0215357;0.1909327;77.29278;7.986937;0;0;0;0.06782898;0.06780598;70935.03;7992354
1295;0.0215357;0.191191;77.3563;7.9935;0;0;0;0.06782898;0.06780598;70993.32;7998922
1300;0.02164284;0.1922195;77.18725;7.976032;0;0;0;0.06816643;0.06814321;70838.18;7981469
1305;0.02174999;0.1910639;77.11219;7.968276;0;0;0;0.06850389;0.06848044;70769.3;7973734
1310;0.02174999;0.1923833;77.33898;7.99171;0;0;0;0.06850389;0.06848044;70977.43;7997185
1315;0.02185713;0.1916393;77.13078;7.970197;0;0;0;0.06884135;0.06881767;70786.36;7975684
1320;0.02196427;0.1927304;77.01576;7.958312;0;0;0;0.06917881;0.06915489;70680.8;7963817
1325;0.02207142;0.1926397;77.30759;7.988466;0;0;0;0.06951627;0.06949212;70948.62;7994020
1330;0.02217856;0.1929379;77.06806;7.963715;0;0;0;0.06985372;0.06982934;70728.8;7969278
1335;0.02217856;0.1933309;77.31586;7.989322;0;0;0;0.06985372;0.06982934;70956.21;7994903
1340;0.0222857;0.1932467;77.11445;7.968509;0;0;0;0.07019117;0.07016655;70771.38;7974103
1345;0.02239284;0.1928631;77.15818;7.973028;0;0;0;0.07052864;0.07050378;70811.5;7978651
1350;0.02249998;0.1935162;77.07619;7.964555;0;0;0;0.07086609;0.070841;70736.26;7970200
1355;0.02260713;0.1939903;77.31164;7.988885;0;0;0;0.07120355;0.07117821;70952.34;7994573
1360;0.02260713;0.1940023;77.27701;7.985307;0;0;0;0.07120355;0.07117821;70920.56;7990993
1365;0.02271427;0.194002;77.13733;7.970873;0;0;0;0.07154101;0.07151543;70792.37;7976576
1370;0.02282141;0.1939207;77.35001;7.99285;0;0;0;0.07187847;0.07185265;70987.55;7998596
1375;0.02292856;0.1948377;76.91304;7.947697;0;0;0;0.07221593;0.07218986;70586.53;7953436
1380;0.0230357;0.1958324;77.21591;7.978993;0;0;0;0.07255339;0.07252708;70864.48;7984782
1385;0.0230357;0.1965236;77.21024;7.978407;0;0;0;0.07255339;0.07252708;70859.27;7984196
1390;0.02314284;0.1972878;77.07102;7.964021;0;0;0;0.07289084;0.07286428;70731.51;7969826
1395;0.02324999;0.1979795;77.17013;7.974263;0;0;0;0.0732283;0.0732015;70822.47;7980102
1400;0.02324999;0.1983123;77.37621;7.995557;0;0;0;0.0732283;0.0732015;71011.59;8001412
1405;0.02346427;0.1987882;77.03857;7.960669;0;0;0;0.07390321;0.07387592;70701.73;7966552
1410;0.02346427;0.1991638;77.21902;7.979314;0;0;0;0.07390321;0.07387592;70867.34;7985211
1415;0.02357141;0.1992249;77.28418;7.986048;0;0;0;0.07424067;0.07421313;70927.14;7991977
1420;0.02367856;0.1996337;77.43808;8.00195;0;0;0;0.07457813;0.07455033;71068.38;8007918
1425;0.02367856;0.1997336;77.27566;7.985168;0;0;0;0.07457813;0.07455033;70919.32;7991123
1430;0.0237857;0.2001077;77.38364;7.996325;0;0;0;0.07491559;0.07488754;71018.41;8002316
1435;0.02389284;0.1999541;77.06703;7.963609;0;0;0;0.07525305;0.07522474;70727.85;7969602
1440;0.02399998;0.2004441;77.26662;7.984233;0;0;0;0.0755905;0.07556194;70911.02;7990269
1445;0.02410713;0.2002828;77.1913;7.97645;0;0;0;0.07592797;0.07589915;70841.9;7982507
1450;0.02410713;0.200556;77.38801;7.996777;0;0;0;0.07592797;0.07589915;71022.43;8002849
1455;0.02421427;0.2005093;77.34064;7.991883;0;0;0;0.07626541;0.07623634;70978.96;7997978
1460;0.02432141;0.2001384;77.35072;7.992923;0;0;0;0.07660288;0.07657355;70988.2;7999046
1465;0.02442855;0.2005788;77.29032;7.986682;0;0;0;0.07694033;0.07691075;70932.77;7992827
1470;0.02448213;0.2005161;77.27499;7.985098;0;0;0;0.07710906;0.07707935;70918.7;7991255
1475;0.0245357;0.2002913;77.29425;7.987089;0;0;0;0.07727779;0.07724794;70936.38;7993261
1480;0.02464284;0.2004261;77.25446;7.982977;0;0;0;0.07761525;0.07758514;70899.87;7989173
1485;0.02474998;0.200332;77.48926;8.00724;0;0;0;0.07795271;0.07792234;71115.35;8013482
1490;0.02485713;0.2000823;77.5807;8.016688;0;0;0;0.07829016;0.07825953;71199.27;8022965
1495;0.02485713;0.200317;76.8936;7.945688;0;0;0;0.07829016;0.07825953;70568.69;7951909
1500;0.02496427;0.2005382;77.25843;7.983387;0;0;0;0.07862762;0.07859673;70903.5;7989664
1505;0.02501784;0.200134;77.33942;7.991755;0;0;0;0.07879635;0.07876532;70977.83;7998053
1510;0.02512498;0.1997907;77.30752;7.98846;0;0;0;0.0791338;0.07910251;70948.56;7994782
1515;0.0252857;0.2003502;77.44375;8.002537;0;0;0;0.07963999;0.0796083;71073.58;8008910
1520;0.0252857;0.1996887;77.34611;7.992447;0;0;0;0.07963999;0.0796083;70983.97;7998812
1525;0.02539284;0.199747;77.53114;8.011567;0;0;0;0.07997745;0.07994548;71153.78;8017974
1530;0.02549998;0.1999;77.37606;7.995542;0;0;0;0.08031491;0.08028268;71011.46;8001964
1535;0.02555355;0.1998163;77.22615;7.980052;0;0;0;0.08048364;0.08045126;70873.88;7986475
1540;0.02560713;0.1992477;77.20924;7.978304;0;0;0;0.08065236;0.08061986;70858.37;7984739
1545;0.02571427;0.1995724;77.39439;7.997436;0;0;0;0.08098982;0.08095704;71028.28;8003913
1550;0.02582141;0.1993774;77.32591;7.99036;0;0;0;0.08132728;0.08129423;70965.43;7996858
1555;0.02592855;0.1993503;77.17028;7.974278;0;0;0;0.08166474;0.08163141;70822.6;7980790
1560;0.02598213;0.1992722;77.4022;7.998243;0;0;0;0.08183347;0.0818;71035.45;8004788
1565;0.02608927;0.1988993;77.35084;7.992936;0;0;0;0.08217093;0.08213719;70988.31;7999504
1570;0.02619641;0.1990989;77.11692;7.968764;0;0;0;0.08250839;0.08247437;70773.63;7975339
1575;0.02624998;0.1990974;77.52958;8.011406;0;0;0;0.08267711;0.08264296;71152.35;8018030
1580;0.02630356;0.1987319;77.41244;7.999302;0;0;0;0.08284584;0.08281155;71044.85;8005929
1585;0.0264107;0.1988437;77.39944;7.997958;0;0;0;0.0831833;0.08314872;71032.91;8004611
1590;0.02651784;0.1989935;77.56053;8.014605;0;0;0;0.08352076;0.08348589;71180.76;8021298
1595;0.02657141;0.198412;77.30098;7.987783;0;0;0;0.08368948;0.08365448;70942.55;7994469
1600;0.02662498;0.1987511;77.40959;7.999007;0;0;0;0.08385822;0.08382308;71042.23;8005715
1605;0.02673213;0.1986296;77.49129;8.007449;0;0;0;0.08419567;0.08416025;71117.21;8014191
1610;0.02683927;0.1986156;77.60281;8.018973;0;0;0;0.08453313;0.08449742;71219.56;8025752
1615;0.02689284;0.1984436;77.40736;7.998777;0;0;0;0.08470186;0.08466601;71040.19;8005552
1620;0.02694641;0.1985457;77.62792;8.021568;0;0;0;0.08487058;0.08483459;71242.6;8028376
1625;0.02705355;0.1983731;77.58714;8.017353;0;0;0;0.08520804;0.08517176;71205.17;8024185
1630;0.02710713;0.1987584;77.5812;8.01674;0;0;0;0.08537678;0.08534035;71199.73;8023584
1635;0.02721427;0.1983974;77.60593;8.019295;0;0;0;0.08571424;0.08567752;71222.42;8026169
1640;0.02732141;0.198577;77.64114;8.022933;0;0;0;0.08605169;0.08601469;71254.73;8029837
1645;0.02748213;0.1985642;77.62214;8.02097;0;0;0;0.08655788;0.08652044;71237.3;8027913
1650;0.02748213;0.1983959;77.71399;8.030461;0;0;0;0.08655788;0.08652044;71321.59;8037413
1655;0.0275357;0.1983899;77.55756;8.014297;0;0;0;0.08672661;0.08668902;71178.03;8021248
1660;0.02764284;0.1984612;77.53589;8.012058;0;0;0;0.08706406;0.08702618;71158.15;8019034
1665;0.02774998;0.198432;77.4989;8.008235;0;0;0;0.08740152;0.08736335;71124.2;8015234
1670;0.02785712;0.198148;77.53413;8.011876;0;0;0;0.08773898;0.08770051;71156.52;8018905
1675;0.02785712;0.1983435;77.53642;8.012113;0;0;0;0.08773898;0.08770051;71158.63;8019142
1680;0.02796427;0.198434;77.53058;8.011509;0;0;0;0.08807644;0.08803767;71153.27;8018565
1685;0.02807141;0.1983803;77.55644;8.014182;0;0;0;0.08841389;0.08837483;71177.01;8021268
1690;0.02817855;0.1982049;77.58161;8.016783;0;0;0;0.08875135;0.08871199;71200.1;8023897
1695;0.02817855;0.1979822;77.88938;8.048585;0;0;0;0.08875135;0.08871199;71482.55;8055729
1700;0.0282857;0.1981799;77.66706;8.025613;0;0;0;0.08908881;0.08904914;71278.53;8032763
1705;0.02839284;0.1984803;77.65596;8.024466;0;0;0;0.08942626;0.08938631;71268.34;8031642
1710;0.02849998;0.198308;77.84184;8.043673;0;0;0;0.08976372;0.08972345;71438.93;8050893
1715;0.02860713;0.1982515;77.62933;8.021713;0;0;0;0.09010118;0.09006062;71243.9;8028941
1720;0.02860713;0.1982103;77.8207;8.041488;0;0;0;0.09010118;0.09006062;71419.52;8048734
1725;0.02871427;0.198388;77.60043;8.018727;0;0;0;0.09043863;0.09039776;71217.38;8025980
1730;0.02882141;0.1982598;77.55709;8.014249;0;0;0;0.09077609;0.09073492;71177.6;8021524
1735;0.02887498;0.1982781;77.45684;8.003889;0;0;0;0.09094483;0.0909035;71085.59;8011168
1740;0.02898212;0.1985085;77.79571;8.038906;0;0;0;0.09128228;0.09124064;71396.59;8046244
1745;0.0290357;0.1983544;77.53302;8.011761;0;0;0;0.09145101;0.09140922;71155.51;8019088
1750;0.02914284;0.1983804;77.74599;8.033769;0;0;0;0.09178847;0.09174637;71350.97;8041143
1755;0.02924998;0.1985811;77.73636;8.032773;0;0;0;0.09212593;0.09208352;71342.13;8040174
1760;0.02930355;0.1983899;77.84718;8.044225;0;0;0;0.09229466;0.09225209;71443.84;8051650
1765;0.0294107;0.198222;77.64339;8.023167;0;0;0;0.09263211;0.09258924;71256.8;8030599
1770;0.02946427;0.1983911;77.79257;8.038582;0;0;0;0.09280084;0.09275781;71393.71;8046041
1775;0.02957141;0.1985229;77.68489;8.027454;0;0;0;0.0931383;0.09309495;71294.89;8034931
1780;0.02967855;0.1985539;77.62022;8.020772;0;0;0;0.09347575;0.09343209;71235.54;8028270
1785;0.0297857;0.198558;77.63846;8.022657;0;0;0;0.09381322;0.09376924;71252.28;8030183
1790;0.0297857;0.1984066;77.66292;8.025185;0;0;0;0.09381322;0.09376924;71274.73;8032713
1795;0.02989284;0.1986624;77.5854;8.017174;0;0;0;0.09415067;0.09410638;71203.58;8024722
1800;0.02999998;0.19917;77.78463;8.037762;0;0;0;0.09448814;0.09444352;71386.43;8045356
1805;0.02999998;0.1995048;77.81227;8.040617;0;0;0;0.09448814;0.09444352;71411.79;8048214
1810;0.0301607;0.1996907;77.60707;8.019413;0;0;0;0.09499431;0.09494922;71223.47;8027031
1815;0.03026784;0.2000386;77.80261;8.039618;0;0;0;0.09533177;0.09528636;71402.92;8047283
1820;0.03032141;0.1988813;77.75677;8.034883;0;0;0;0.09550051;0.09545493;71360.86;8042556
1825;0.03042855;0.2002603;77.6476;8.023602;0;0;0;0.09583796;0.09579207;71260.66;8031291
1830;0.03042855;0.2001283;77.40375;7.998404;0;0;0;0.09583796;0.09579207;71036.88;8006069
1835;0.03053569;0.2004827;77.77712;8.036985;0;0;0;0.0961754;0.09612919;71379.53;8044715
1840;0.03064284;0.1998401;77.72365;8.03146;0;0;0;0.09651288;0.09646633;71330.46;8039211
1845;0.03074998;0.1985025;77.3637;7.994265;0;0;0;0.09685033;0.09680346;71000.11;8002007
1850;0.03085712;0.1997106;77.52509;8.010942;0;0;0;0.09718779;0.09714059;71148.23;8018727
1855;0.03085712;0.1987019;77.39418;7.997414;0;0;0;0.09718779;0.09714059;71028.09;8005187
1860;0.03096426;0.1994661;77.36056;7.99394;0;0;0;0.09752524;0.09747771;70997.23;8001737
1865;0.03107141;0.1994232;77.35803;7.993679;0;0;0;0.0978627;0.09781484;70994.91;8001502
1870;0.03117855;0.198708;77.04979;7.961828;0;0;0;0.09820016;0.09815198;70712.03;7969646
1875;0.03128569;0.1985708;76.82709;7.938816;0;0;0;0.09853762;0.0984891;70507.65;7946638
1880;0.03128569;0.1984677;76.73527;7.929327;0;0;0;0.09853762;0.0984891;70423.38;7937140
1885;0.03139284;0.1974128;76.7817;7.934124;0;0;0;0.09887508;0.09882623;70465.98;7941969
1890;0.03149998;0.1982108;76.66183;7.921738;0;0;0;0.09921253;0.09916335;70355.98;7929598
1895;0.03155355;0.1975719;76.99514;7.956181;0;0;0;0.09938127;0.09933192;70661.88;7964088
1900;0.03171427;0.1974438;76.89765;7.946107;0;0;0;0.09988745;0.0998376;70572.41;7954044
1905;0.03171427;0.1985083;76.86506;7.942739;0;0;0;0.09988745;0.0998376;70542.49;7950673
1910;0.03182141;0.1957075;76.92426;7.948856;0;0;0;0.1002249;0.1001747;70596.82;7956823
1915;0.03192855;0.1956099;76.91612;7.948015;0;0;0;0.1005624;0.1005118;70589.35;7956008
1920;0.03203569;0.1949326;76.78963;7.934944;0;0;0;0.1008998;0.100849;70473.27;7942950
1925;0.03203569;0.193269;76.75694;7.931567;0;0;0;0.1008998;0.100849;70443.27;7939570
1930;0.03214283;0.1931616;76.8729;7.943549;0;0;0;0.1012373;0.1011861;70549.69;7951591
1935;0.03224998;0.1930258;76.8648;7.942711;0;0;0;0.1015747;0.1015232;70542.25;7950779
1940;0.03235712;0.1915914;77.33184;7.990973;0;0;0;0.1019122;0.1018603;70970.88;7999116
1945;0.03246427;0.1901155;76.98138;7.954758;0;0;0;0.1022497;0.1021974;70649.24;7962892
1950;0.03246427;0.1884675;76.91716;7.948122;0;0;0;0.1022497;0.1021974;70590.3;7956249
1955;0.03257141;0.1868675;76.75509;7.931376;0;0;0;0.1025871;0.1025345;70441.57;7939512
1960;0.03267855;0.1833941;76.99955;7.956636;0;0;0;0.1029246;0.1028716;70665.92;7964825
1965;0.03267855;0.1805142;76.88185;7.944474;0;0;0;0.1029246;0.1028716;70557.91;7952651
1970;0.03278569;0.1761202;76.84268;7.940426;0;0;0;0.103262;0.1032087;70521.95;7948626
1975;0.03289284;0.1737678;76.69815;7.925491;0;0;0;0.1035995;0.1035459;70389.31;7933702
1980;0.03299998;0.1676681;77.01958;7.958705;0;0;0;0.1039369;0.103883;70684.3;7966977
1985;0.03310712;0.1620716;76.99984;7.956666;0;0;0;0.1042744;0.1042201;70666.19;7964963
1990;0.03310712;0.153861;76.88941;7.945254;0;0;0;0.1042744;0.1042201;70564.84;7953539
1995;0.03321426;0.1422491;76.91836;7.948246;0;0;0;0.1046119;0.1045572;70591.41;7956561
2000;0.03332141;0.1255178;76.89395;7.945724;0;0;0;0.1049493;0.1048943;70569.01;7954063
2005;0.03342855;0.1082857;77.03097;7.959883;0;0;0;0.1052868;0.1052314;70694.76;7968263
2010;0.03353569;0.09018639;76.89572;7.945907;0;0;0;0.1056242;0.1055685;70570.63;7954300
2015;0.03353569;0.07606712;76.8658;7.942815;0;0;0;0.1056242;0.1055685;70543.17;7951204
2020;0.03364283;0.06386225;76.81197;7.937253;0;0;0;0.1059617;0.1059056;70493.77;7945663
2025;0.03374998;0.05529942;76.80125;7.936145;0;0;0;0.1062991;0.1062427;70483.93;7944581
2030;0.03374998;0.0448453;76.6588;7.921426;0;0;0;0.1062991;0.1062427;70353.2;7929846
2035;0.03385712;0.03787129;77.20176;7.977531;0;0;0;0.1066366;0.1065798;70851.49;7986038
2040;0.03396427;0.03677933;76.94582;7.951084;0;0;0;0.1069741;0.1069169;70616.61;7959589
2045;0.03407141;0.03568846;76.75712;7.931585;0;0;0;0.1073115;0.107254;70443.43;7940096
2050;0.03417855;0.03198423;76.93718;7.950191;0;0;0;0.107649;0.1075911;70608.68;7958750
2055;0.03417855;0.03013474;76.85622;7.941825;0;0;0;0.107649;0.1075911;70534.38;7950375
2060;0.03428569;0.03126602;76.62042;7.917459;0;0;0;0.1079864;0.1079282;70317.98;7926009
2065;0.03439283;0.03108568;77.03135;7.959922;0;0;0;0.1083239;0.1082653;70695.11;7968545
2070;0.03449998;0.03176811;76.84965;7.941146;0;0;0;0.1086613;0.1086024;70528.35;7949775
2075;0.03460712;0.03151824;76.84154;7.940308;0;0;0;0.1089988;0.1089394;70520.91;7948963
2080;0.03460712;0.03200506;76.88362;7.944657;0;0;0;0.1089988;0.1089394;70559.53;7953316
2085;0.03471426;0.03172747;76.87219;7.943476;0;0;0;0.1093363;0.1092765;70549.04;7952161
2090;0.03482141;0.03281889;76.97577;7.954178;0;0;0;0.1096737;0.1096136;70644.09;7962902
2095;0.03492855;0.03279829;76.88579;7.944881;0;0;0;0.1100112;0.1099507;70561.52;7953622
2100;0.03503569;0.03201007;77.05158;7.962013;0;0;0;0.1103486;0.1102878;70713.67;7970799
2105;0.03503569;0.03274653;76.75577;7.931446;0;0;0;0.1103486;0.1102878;70442.2;7940198
2110;0.03514284;0.03279594;76.61367;7.916761;0;0;0;0.1106861;0.1106249;70311.78;7925524
2115;0.03524998;0.03247975;76.75365;7.931227;0;0;0;0.1110236;0.110962;70440.25;7940032
2120;0.03535712;0.03279861;76.70834;7.926545;0;0;0;0.111361;0.111299;70398.66;7935372
2125;0.03541069;0.03269242;76.82419;7.938515;0;0;0;0.1115297;0.1114676;70504.98;7947369
2130;0.03546426;0.03290698;76.71797;7.92754;0;0;0;0.1116985;0.1116361;70407.51;7936395
2135;0.0355714;0.03112139;76.73888;7.9297;0;0;0;0.1120359;0.1119732;70426.7;7938584
2140;0.03562498;0.03269752;76.68391;7.92402;0;0;0;0.1122047;0.1121418;70376.24;7932911
2145;0.03573212;0.03249987;76.96699;7.953271;0;0;0;0.1125421;0.1124788;70636.04;7962222
2150;0.03578569;0.03166655;76.83255;7.93938;0;0;0;0.1127108;0.1126474;70512.66;7948328
2155;0.03589283;0.03090949;76.70952;7.926666;0;0;0;0.1130483;0.1129844;70399.74;7935627
2160;0.03605355;0.03071898;76.73671;7.929476;0;0;0;0.1135545;0.1134901;70424.7;7938480
2165;0.03605355;0.03117894;76.75439;7.931303;0;0;0;0.1135545;0.1134901;70440.92;7940309
2170;0.03616069;0.0308088;76.70502;7.926202;0;0;0;0.1138919;0.1138271;70395.62;7935229
2175;0.03621426;0.03120776;76.54561;7.909729;0;0;0;0.1140607;0.1139957;70249.32;7918750
2180;0.03632141;0.03095335;76.73797;7.929606;0;0;0;0.1143981;0.1143327;70425.86;7938678
2185;0.03642855;0.02940619;76.73897;7.929709;0;0;0;0.1147356;0.1146698;70426.77;7938808
2190;0.03648212;0.02951292;76.95703;7.952243;0;0;0;0.1149043;0.1148384;70626.9;7961380
2195;0.03658926;0.02852816;76.85;7.941182;0;0;0;0.1152418;0.1151754;70528.67;7950334
2200;0.03658926;0.02894004;76.79159;7.935147;0;0;0;0.1152418;0.1151754;70475.06;7944291
2205;0.03669641;0.02845001;76.82862;7.938973;0;0;0;0.1155792;0.1155125;70509.05;7948149
2210;0.03680355;0.02752014;76.92223;7.948647;0;0;0;0.1159167;0.1158496;70594.96;7957861
2215;0.03691069;0.02687185;77.05787;7.962662;0;0;0;0.1162541;0.1161866;70719.44;7971919
2220;0.03701783;0.02757816;76.97714;7.95432;0;0;0;0.1165916;0.1165237;70645.36;7963595
2225;0.0370714;0.02574958;76.59987;7.915336;0;0;0;0.1167603;0.1166922;70299.12;7924578
2230;0.03712498;0.02732304;76.87842;7.94412;0;0;0;0.1169291;0.1168608;70554.76;7953409
2235;0.03723212;0.02536471;76.76273;7.932164;0;0;0;0.1172665;0.1171978;70448.58;7941466
2240;0.03733926;0.02655229;76.81896;7.937974;0;0;0;0.117604;0.1175349;70500.18;7947310
2245;0.03739284;0.02543761;76.93213;7.949669;0;0;0;0.1177727;0.1177034;70604.05;7959032
2250;0.03755355;0.02578599;76.79711;7.935718;0;0;0;0.1182789;0.118209;70480.13;7945104
2255;0.03755355;0.02467633;76.8968;7.946019;0;0;0;0.1182789;0.118209;70571.63;7955417
2260;0.03760712;0.02412201;77.00116;7.956803;0;0;0;0.1184476;0.1183775;70667.4;7966227
2265;0.03771426;0.02352243;76.76355;7.93225;0;0;0;0.1187851;0.1187146;70449.34;7941672
2270;0.0378214;0.02328203;76.64979;7.920494;0;0;0;0.1191225;0.1190516;70344.93;7929929
2275;0.03792855;0.02415302;76.97174;7.953763;0;0;0;0.11946;0.1193887;70640.4;7963264
2280;0.03803569;0.02209445;76.93348;7.949809;0;0;0;0.1197975;0.1197258;70605.28;7959332
2285;0.03803569;0.02200887;76.81206;7.937262;0;0;0;0.1197975;0.1197258;70493.85;7946771
2290;0.03814283;0.02098871;76.77705;7.933645;0;0;0;0.1201349;0.1200628;70461.73;7943176
2295;0.03824997;0.02047557;76.9395;7.950431;0;0;0;0.1204724;0.1203998;70610.81;7960009
2300;0.03830355;0.02122425;77.05023;7.961874;0;0;0;0.1206411;0.1205684;70712.44;7971479
2305;0.03835712;0.02050454;76.99773;7.956448;0;0;0;0.1208098;0.1207369;70664.25;7966060
2310;0.03846426;0.01952793;76.95768;7.952309;0;0;0;0.1211473;0.121074;70627.49;7961943
2315;0.0385714;0.01950271;76.80468;7.9365;0;0;0;0.1214847;0.121411;70487.09;7946142
2320;0.03862497;0.01887173;76.99979;7.956661;0;0;0;0.1216535;0.1215795;70666.14;7966340
2325;0.03873211;0.02003315;76.97685;7.95429;0;0;0;0.1219909;0.1219166;70645.09;7963994
2330;0.03878569;0.0189989;76.85463;7.941661;0;0;0;0.1221596;0.1220851;70532.92;7951363
2335;0.03889283;0.01864284;76.91398;7.947794;0;0;0;0.1224971;0.1224221;70587.39;7957530
2340;0.0389464;0.01800677;76.98848;7.955492;0;0;0;0.1226658;0.1225907;70655.76;7965251
2345;0.03905354;0.01693462;77.00093;7.956779;0;0;0;0.1230033;0.1229277;70667.19;7966566
2350;0.03910712;0.01601312;76.96843;7.95342;0;0;0;0.123172;0.1230962;70637.36;7963216
2355;0.03921426;0.01643166;76.94396;7.950892;0;0;0;0.1235095;0.1234333;70614.91;7960712
2360;0.0393214;0.01545684;76.93507;7.949973;0;0;0;0.1238469;0.1237703;70606.74;7959818
2365;0.03942855;0.01538966;77.18589;7.975892;0;0;0;0.1241844;0.1241074;70836.94;7985796
2370;0.03948212;0.01526507;77.05129;7.961982;0;0;0;0.1243531;0.1242759;70713.41;7971883
2375;0.03953568;0.01467802;76.95024;7.951541;0;0;0;0.1245218;0.1244444;70620.67;7961442
2380;0.03964283;0.01458718;77.01223;7.957947;0;0;0;0.1248593;0.1247814;70677.56;7967883
2385;0.03974998;0.01462399;76.83731;7.939871;0;0;0;0.1251968;0.1251185;70517.02;7949812
2390;0.03980354;0.01448656;77.10743;7.967784;0;0;0;0.1253655;0.125287;70764.93;7977773
2395;0.03991069;0.01478733;77.08841;7.965818;0;0;0;0.1257029;0.125624;70747.47;7975831
2400;0.04001783;0.01466917;76.81265;7.937323;0;0;0;0.1260404;0.125961;70494.39;7947327
2405;0.0400714;0.01517056;77.11789;7.968864;0;0;0;0.1262091;0.1261296;70774.52;7978922
2410;0.04012497;0.01537204;76.9597;7.952518;0;0;0;0.1263779;0.1262981;70629.35;7962569
2415;0.04023212;0.01540164;76.97931;7.954545;0;0;0;0.1267153;0.1266351;70647.35;7964625
2420;0.04033926;0.01561557;76.81121;7.937174;0;0;0;0.1270528;0.1269721;70493.07;7947259
2425;0.04039283;0.01588556;76.92505;7.948937;0;0;0;0.1272215;0.1271407;70597.55;7959050
2430;0.04049997;0.01588854;76.84641;7.940812;0;0;0;0.127559;0.1274777;70525.38;7950941
2432.464;0.04055355;0.01607733;77.08635;7.965606;0;0;0;0.1277277;0.1276462;70745.59;7975780