File: Ensayos/Resistencia/comp/Clavo6/Clavo6e.raw
"Test Type";"Manual"
"Method Name:";"C:\INSTRON\user\template\CYCLE.MTM"
"Name:";""
"Operator ID:";""
"Company:";""
"Lab name:";""
"Test date:";"06/06/2017"
"Temperature:";""
"Humidity:";""
"Note 1:";""
"Note 2:";""
"Note 3:";""
"Geometry:";"Rectangular"
"Specimen";1
"Specimen name:";""
"Width:";0.250000;"in"
"Thickness:";0.060000;"in"
"Length:";1.250000;"in"
"Diameter:";0.039370;"in"
"Inner diameter:";0.019685;"in"
"Outer diameter:";0.039370;"in"
"Wall thickness:";0.019685;"in"
"Area:";0.015000;"in*in"
"Linear density:";1.000000;"den"
"Sled weight:";2.204623;"lbf"
"Loading span:";0.000000;"mm"
"Support span:";1.000000;"mm"
"Span ratio:";"2"
"Fixture type:";"3-point"
"Comment:";""
"Included"
"Final Width:";0.250000;"in"
"Final Thickness:";0.060000;"in"
"Final Length:";1.250000;"in"
"Final Diameter:";0.039370;"in"
"Final Inner diameter:";0.019685;"in"
"Final Outer diameter:";0.039370;"in"
"Final Wall thickness:";0.019685;"in"
"Final Area:";0.015000;"in*in"
"Final Linear density:";1.000000;"den"
"Time sec";"Extension mm";"Strain 1 %";"Load N";"Stress MPa";"Cycle Count ";"Total Cycle Count ";"Repetitions Count ";"Strain [Exten.] %";"True strain %";"Tenacity gf/tex";"True stress Pa"
0;0;-0.001349191;60.95296;6.298485;0;0;0;0;0;55939.25;6298485
9;0.0001607142;-0.001446837;60.96635;6.299869;0;0;0;0.0005061864;0.0005061851;55951.54;6299901
18;0.000267857;-0.001644871;60.7613;6.27868;0;0;0;0.000843644;0.0008436404;55763.35;6278733
27;0.0004285712;-0.001652623;60.88251;6.291205;0;0;0;0.00134983;0.001349821;55874.6;6291290
36;0.0006428567;-0.00175489;60.83577;6.286376;0;0;0;0.002024746;0.002024725;55831.7;6286503
45;0.0007499995;-0.00168974;60.72509;6.274939;0;0;0;0.002362203;0.002362175;55730.13;6275087
54;0.0008571423;-0.001798114;60.78341;6.280965;0;0;0;0.002699661;0.002699624;55783.64;6281135
63;0.001071428;-0.001614175;61.04499;6.307995;0;0;0;0.003374576;0.003374519;56023.71;6308208
72;0.001178571;-0.001442452;60.82082;6.284831;0;0;0;0.003712033;0.003711965;55817.98;6285064
81.00001;0.001392856;-0.001423032;60.78878;6.28152;0;0;0;0.004386948;0.004386852;55788.57;6281796
90.00001;0.001499999;-0.001220614;60.84032;6.286845;0;0;0;0.004724406;0.004724294;55835.87;6287142
99.00001;0.001607142;-0.001097988;60.86094;6.288976;0;0;0;0.005061864;0.005061736;55854.79;6289294
108;0.001767856;-0.0009744224;60.84419;6.287246;0;0;0;0.00556805;0.005567895;55839.43;6287596
117;0.00192857;-0.0007197741;60.74289;6.276778;0;0;0;0.006074237;0.006074052;55746.46;6277159
126;0.002142856;-0.0005991058;60.88636;6.291603;0;0;0;0.006749152;0.006748924;55878.13;6292028
135;0.002249999;-0.0002004547;60.69954;6.272299;0;0;0;0.007086609;0.007086358;55706.68;6272743
144;0.002357141;-3.585708e-005;60.54688;6.256524;0;0;0;0.007424067;0.007423791;55566.57;6256988
153;0.002571427;0.0003122873;60.74547;6.277044;0;0;0;0.008098982;0.008098654;55748.82;6277553
162;0.00267857;0.000533186;60.71825;6.274231;0;0;0;0.00843644;0.008436084;55723.84;6274761
171;0.002785712;0.0009058401;60.70965;6.273343;0;0;0;0.008773897;0.008773512;55715.95;6273893
180;0.002999998;0.001125721;60.62573;6.264671;0;0;0;0.009448812;0.009448366;55638.93;6265263
189;0.003214284;0.001501742;60.72665;6.2751;0;0;0;0.01012373;0.01012322;55731.55;6275735
198;0.003321426;0.001711991;60.74403;6.276896;0;0;0;0.01046119;0.01046064;55747.5;6277552
207;0.003428569;0.001993655;60.57615;6.259548;0;0;0;0.01079864;0.01079806;55593.44;6260224
216;0.003642855;0.00207243;60.59113;6.261096;0;0;0;0.01147356;0.0114729;55607.18;6261814
225;0.003749998;0.002291919;60.57483;6.259412;0;0;0;0.01181102;0.01181032;55592.23;6260151
234;0.00385714;0.002609838;60.76826;6.279399;0;0;0;0.01214847;0.01214774;55769.74;6280162
243;0.004071426;0.002969102;60.43679;6.245148;0;0;0;0.01282339;0.01282257;55465.54;6245948
252;0.004178569;0.003444923;60.60993;6.263038;0;0;0;0.01316085;0.01315998;55624.43;6263862
261;0.004392855;0.003658539;60.46219;6.247773;0;0;0;0.01383576;0.01383481;55488.85;6248637
270;0.004499997;0.003948973;60.53834;6.255641;0;0;0;0.01417322;0.01417221;55558.73;6256527
279;0.00460714;0.00436724;60.43335;6.244792;0;0;0;0.01451068;0.01450962;55462.38;6245699
288;0.004767854;0.004808176;60.60793;6.262832;0;0;0;0.01501686;0.01501574;55622.6;6263772
297;0.004928568;0.005166383;60.31534;6.232598;0;0;0;0.01552305;0.01552184;55354.08;6233566
306;0.005142854;0.005429919;60.53246;6.255033;0;0;0;0.01619796;0.01619665;55553.34;6256047
315;0.005249997;0.005590366;60.39395;6.240721;0;0;0;0.01653542;0.01653406;55426.22;6241753
324;0.005464282;0.006119747;60.41871;6.243279;0;0;0;0.01721034;0.01720886;55448.94;6244353
333;0.005571425;0.006446045;60.47476;6.249071;0;0;0;0.01754779;0.01754625;55500.38;6250168
342;0.005678568;0.006760323;60.35716;6.236918;0;0;0;0.01788525;0.01788365;55392.45;6238034
351;0.005892853;0.007181291;60.54312;6.256135;0;0;0;0.01856017;0.01855845;55563.12;6257296
360;0.005999996;0.007506335;60.50806;6.252512;0;0;0;0.01889762;0.01889584;55530.94;6253693
369;0.006107139;0.007763568;60.34154;6.235305;0;0;0;0.01923508;0.01923323;55378.12;6236504
378;0.006321425;0.008028317;60.43268;6.244723;0;0;0;0.01991;0.01990802;55461.77;6245966
387;0.006428567;0.008351717;60.40284;6.24164;0;0;0;0.02024746;0.02024541;55434.38;6242903
396;0.00653571;0.008760588;60.48527;6.250157;0;0;0;0.02058491;0.0205828;55510.03;6251444
405;0.006749996;0.008967039;60.41403;6.242796;0;0;0;0.02125983;0.02125757;55444.65;6244123
414;0.00691071;0.009486398;60.29194;6.230179;0;0;0;0.02176601;0.02176365;55332.6;6231535
423;0.007071424;0.009558399;60.27978;6.228923;0;0;0;0.0222722;0.02226972;55321.45;6230311
432;0.007178567;0.009950512;60.12691;6.213127;0;0;0;0.02260966;0.0226071;55181.15;6214531
441;0.007392853;0.01017732;60.15055;6.215569;0;0;0;0.02328457;0.02328186;55202.84;6217016
450;0.007499996;0.01050233;60.34849;6.236023;0;0;0;0.02362203;0.02361924;55384.5;6237497
459;0.007607138;0.01094671;60.48351;6.249976;0;0;0;0.02395949;0.02395662;55508.42;6251473
468;0.02110713;0.01095618;60.68281;6.270569;0;0;0;0.06647915;0.06645706;55691.32;6274738
477;0.03621426;0.01142136;60.73132;6.275582;0;0;0;0.1140607;0.1139957;55735.84;6282740
486;0.05121425;0.01146368;60.88895;6.29187;0;0;0;0.1613047;0.1611748;55880.5;6302019
495;0.06616067;0.01189655;60.82778;6.28555;0;0;0;0.2083801;0.2081633;55824.36;6298648
504;0.08121423;0.01206929;60.78764;6.281402;0;0;0;0.2557929;0.2554663;55787.52;6297469
513;0.09616066;0.01220347;60.83395;6.286187;0;0;0;0.3028682;0.3024105;55830.02;6305226
522;0.1112142;0.01237907;61.04355;6.307846;0;0;0;0.350281;0.3496689;56022.39;6329941
531;0.1262678;0.01273641;61.23871;6.328012;0;0;0;0.3976938;0.396905;56201.49;6353179
540;0.1411606;0.01288367;61.31056;6.335437;0;0;0;0.4446004;0.443615;56267.44;6363605
549;0.1563213;0.01312238;61.43615;6.348415;0;0;0;0.4923506;0.4911426;56382.7;6379671
558;0.1712142;0.01337068;61.58703;6.364006;0;0;0;0.5392572;0.5378085;56521.16;6398324
567;0.1862677;0.01355349;61.58506;6.363802;0;0;0;0.58667;0.5849558;56519.36;6401137
576;0.2012142;0.01377055;62.06488;6.413383;0;0;0;0.6337454;0.6317456;56959.71;6454028
585;0.2162142;0.01383448;63.49213;6.560867;0;0;0;0.6809894;0.6786812;58269.56;6605546
594;0.2312677;0.01432033;72.93533;7.536665;0;0;0;0.7284023;0.7257622;66936;7591563
603;0.2461605;0.0146606;86.84618;8.974123;0;0;0;0.7753088;0.7723187;79702.61;9043700
612;0.2613213;0.01490824;102.7983;10.62251;0;0;0;0.8230591;0.8196904;94342.58;1.070994e+007
621;0.2761606;0.01518141;120.182;12.41884;0;0;0;0.869797;0.8660361;110296.4;1.252685e+007
630;0.2912141;0.0151304;139.5669;14.42194;0;0;0;0.9172097;0.9130289;128086.8;1.455422e+007
639;0.3062141;0.01481588;160.5012;16.58516;0;0;0;0.9644539;0.9598327;147299.1;1.674511e+007
648.0001;0.3211605;0.01445321;183.9481;19.00801;0;0;0;1.011529;1.006447;168817.4;1.920028e+007
657.0001;0.3362141;0.01375551;209.3909;21.6371;0;0;0;1.058942;1.053374;192167.3;2.186623e+007
666.0001;0.3512676;0.01285755;237.0074;24.49082;0;0;0;1.106355;1.100279;217512.3;2.476177e+007
675.0001;0.366214;0.01185986;266.1471;27.50193;0;0;0;1.15343;1.146829;244255.1;2.781914e+007
684.0001;0.3812676;0.01068294;298.0474;30.7983;0;0;0;1.200843;1.19369;273531.4;3.116814e+007
693.0001;0.3961605;0.009307353;331.7313;34.27897;0;0;0;1.247749;1.240029;304444.6;3.470668e+007
702.0001;0.4113212;0.007785611;368.2687;38.05451;0;0;0;1.2955;1.28718;337976.6;3.85475e+007
711.0001;0.426214;0.006124955;406.1909;41.97315;0;0;0;1.342406;1.333476;372779.5;4.25366e+007
720.0001;0.4413212;0.004049517;446.8964;46.17939;0;0;0;1.389988;1.380416;410136.8;4.682127e+007
729.0001;0.4562676;0.00170557;488.5777;50.48647;0;0;0;1.437063;1.426835;448389.6;5.121199e+007
738.0001;0.4711604;-0.0002555814;531.7466;54.94726;0;0;0;1.48397;1.473067;488007.6;5.576266e+007
747.0001;0.4863211;-0.002713109;576.6696;59.58931;0;0;0;1.53172;1.520108;529235.4;6.050205e+007
756.0001;0.5011604;-0.005277211;622.8475;64.36104;0;0;0;1.578458;1.56613;571614.9;6.537695e+007
765.0001;0.5163211;-0.008077559;671.1272;69.34995;0;0;0;1.626208;1.613127;615923.4;7.047772e+007
774.0001;0.5311603;-0.01073617;719.5321;74.3518;0;0;0;1.672946;1.659106;660346.8;7.559567e+007
783.0001;0.546214;-0.01379931;770.3136;79.59924;0;0;0;1.720359;1.705728;706951.1;8.096862e+007
792.0001;0.5612675;-0.01695517;822.1575;84.95644;0;0;0;1.767772;1.752328;754530.6;8.645828e+007
801.0001;0.5761603;-0.01995872;874.0446;90.31812;0;0;0;1.814678;1.798409;802149.7;9.19571e+007
810.0001;0.5912139;-0.02324244;926.6272;95.75167;0;0;0;1.862091;1.844966;850407.1;9.753465e+007
819.0001;0.6062139;-0.02662757;977.1794;100.9754;0;0;0;1.909335;1.891336;896801.1;1.029034e+008
828.0001;0.6211603;-0.02990746;1029.667;106.3991;0;0;0;1.95641;1.937519;944971.4;1.084807e+008
837.0001;0.6362674;-0.03337928;1086.199;112.2408;0;0;0;2.003992;1.984176;996853.4;1.144901e+008
846.0001;0.6511603;-0.03722774;1142.176;118.0251;0;0;0;2.050899;2.030151;1048226;1.204457e+008
855.0001;0.666321;-0.0409181;1200.293;124.0305;0;0;0;2.098649;2.07693;1101562;1.266334e+008
864.0001;0.667446;-0.03998706;1189.764;122.9426;0;0;0;2.102192;2.080401;1091900;1.25527e+008
873.0001;0.6685709;-0.03965849;1188.746;122.8374;0;0;0;2.105735;2.083871;1090965;1.25424e+008
882.0001;0.6699638;-0.03943281;1189.916;122.9582;0;0;0;2.110122;2.088168;1092039;1.255528e+008
891.0001;0.6714639;-0.03928732;1192.523;123.2277;0;0;0;2.114847;2.092794;1094432;1.258337e+008
900.0001;0.673071;-0.03921904;1195.047;123.4885;0;0;0;2.119909;2.097751;1096748;1.261063e+008
909.0001;0.6752139;-0.03930635;1201.309;124.1355;0;0;0;2.126658;2.10436;1102495;1.267754e+008
918.0001;0.676821;-0.03895327;1204.157;124.4298;0;0;0;2.13172;2.109316;1105109;1.270823e+008
927.0001;0.6781067;-0.03854835;1200.956;124.099;0;0;0;2.135769;2.113281;1102171;1.267495e+008
936.0001;0.6795531;-0.03822323;1204.179;124.432;0;0;0;2.140325;2.117742;1105128;1.270953e+008
945.0001;0.6807852;-0.03778417;1205.687;124.5879;0;0;0;2.144206;2.121541;1106513;1.272593e+008
954.0001;0.6819639;-0.03723745;1206.949;124.7183;0;0;0;2.147918;2.125175;1107671;1.273971e+008
963.0001;0.6830353;-0.03654429;1207.935;124.8202;0;0;0;2.151292;2.128478;1108576;1.275055e+008
972.0001;0.6837853;-0.03581535;1207.196;124.7438;0;0;0;2.153654;2.130791;1107897;1.274304e+008
981.0001;0.6844282;-0.03501084;1206.653;124.6877;0;0;0;2.155679;2.132773;1107399;1.273756e+008
990.0001;0.6849638;-0.03409577;1204.963;124.5131;0;0;0;2.157366;2.134425;1105848;1.271993e+008
999.0001;0.6856067;-0.03304327;1204.757;124.4918;0;0;0;2.159391;2.136407;1105659;1.2718e+008
1008;0.6861959;-0.03219632;1204.241;124.4385;0;0;0;2.161247;2.138223;1105186;1.271279e+008
1017;0.6867853;-0.03150277;1203.918;124.4051;0;0;0;2.163103;2.14004;1104890;1.270962e+008
1026;0.6874281;-0.03048105;1204.196;124.4339;0;0;0;2.165128;2.142022;1105145;1.27128e+008
1035;0.6879638;-0.02964545;1203.632;124.3756;0;0;0;2.166815;2.143673;1104627;1.270705e+008
1044;0.6886067;-0.02862639;1204.384;124.4533;0;0;0;2.16884;2.145655;1105317;1.271525e+008
1053;0.6891959;-0.02778594;1204.969;124.5138;0;0;0;2.170696;2.147472;1105854;1.272166e+008
1062;0.6898389;-0.02676946;1205.962;124.6164;0;0;0;2.172721;2.149454;1106766;1.273239e+008
1071;0.6904281;-0.02572268;1206.336;124.655;0;0;0;2.174577;2.15127;1107109;1.273657e+008
1080;0.6909639;-0.02471286;1206.867;124.7099;0;0;0;2.176264;2.152922;1107596;1.274239e+008
1089;0.6915531;-0.02363483;1208.136;124.8409;0;0;0;2.17812;2.154738;1108760;1.275601e+008
1098;0.6920889;-0.02267998;1209.509;124.9829;0;0;0;2.179807;2.156389;1110020;1.277072e+008
1107;0.6922495;-0.02113925;1207.941;124.8209;0;0;0;2.180313;2.156885;1108582;1.275424e+008
1116;0.6924102;-0.01961183;1207.13;124.737;0;0;0;2.18082;2.15738;1107837;1.274573e+008
1125;0.692571;-0.01810946;1207.119;124.7359;0;0;0;2.181326;2.157875;1107827;1.274568e+008
1134;0.6926781;-0.01658204;1206.244;124.6455;0;0;0;2.181664;2.158206;1107024;1.273648e+008
1143;0.6928389;-0.01486975;1206.698;124.6924;0;0;0;2.18217;2.158701;1107441;1.274134e+008
1152;0.6929995;-0.01345039;1204.46;124.4612;0;0;0;2.182676;2.159196;1105387;1.271777e+008
1161;0.6931603;-0.01184999;1205.413;124.5596;0;0;0;2.183182;2.159692;1106262;1.27279e+008
1170;0.693321;-0.009977946;1206.864;124.7095;0;0;0;2.183688;2.160187;1107593;1.274328e+008
1179;0.6934817;-0.008091262;1208.529;124.8816;0;0;0;2.184194;2.160683;1109121;1.276093e+008
1186.42;0.6935353;-0.006678246;1209.594;124.9916;0;0;0;2.184363;2.160848;1110098;1.277219e+008
1195.42;0.6928924;-0.004469415;1206.874;124.7106;0;0;0;2.182338;2.158866;1107602;1.274322e+008
1204.42;0.6916067;-0.00228619;1200.33;124.0344;0;0;0;2.178289;2.154903;1101597;1.267362e+008
1213.42;0.6913924;-0.0003489995;1202.082;124.2154;0;0;0;2.177614;2.154243;1103205;1.269204e+008
1222.42;0.6906424;0.001863747;1198.661;123.8619;0;0;0;2.175252;2.151931;1100065;1.265562e+008
1231.42;0.6901067;0.003931707;1198.534;123.8487;0;0;0;2.173564;2.150279;1099948;1.265407e+008
1240.42;0.6894638;0.006720426;1198.365;123.8313;0;0;0;2.17154;2.148298;1099793;1.265203e+008
1249.42;0.688821;0.009302302;1197.741;123.7668;0;0;0;2.169515;2.146316;1099220;1.264519e+008
1258.42;0.6883924;0.01128843;1198.926;123.8893;0;0;0;2.168165;2.144995;1100308;1.265754e+008
1267.42;0.6879638;0.01302199;1200.26;124.0271;0;0;0;2.166815;2.143673;1101532;1.267146e+008
1276.42;0.6875353;0.01459831;1202.553;124.264;0;0;0;2.165465;2.142352;1103636;1.269549e+008
1285.42;0.6871067;0.01638058;1203.258;124.3369;0;0;0;2.164115;2.141031;1104284;1.270277e+008
1294.42;0.6865175;0.01863204;1204.065;124.4203;0;0;0;2.16226;2.139214;1105024;1.271106e+008
1303.42;0.6856067;0.02053768;1203.534;124.3655;0;0;0;2.159391;2.136407;1104537;1.27051e+008
1312.42;0.6845353;0.02248211;1201.718;124.1777;0;0;0;2.156017;2.133103;1102870;1.26855e+008
1321.42;0.6834639;0.02393929;1200.146;124.0154;0;0;0;2.152642;2.1298;1101428;1.26685e+008
1330.42;0.6824995;0.02539444;1200.37;124.0385;0;0;0;2.149605;2.126827;1101633;1.267048e+008
1339.42;0.6815352;0.0267768;1200.098;124.0104;0;0;0;2.146568;2.123853;1101383;1.266723e+008
1348.42;0.6804639;0.02848518;1199.583;123.9571;0;0;0;2.143193;2.12055;1100910;1.266138e+008
1357.42;0.6793924;0.03053481;1199.23;123.9207;0;0;0;2.139819;2.117246;1100587;1.265724e+008
1366.42;0.6784281;0.03233579;1199.587;123.9576;0;0;0;2.136781;2.114272;1100915;1.266063e+008
1375.42;0.6773567;0.03407616;1197.198;123.7107;0;0;0;2.133407;2.110968;1098722;1.2635e+008
1384.42;0.6762853;0.03560209;1196.635;123.6526;0;0;0;2.130032;2.107664;1098206;1.262864e+008
1393.42;0.6755353;0.03564465;1200.728;124.0754;0;0;0;2.12767;2.105351;1101961;1.267154e+008
1402.42;0.674571;0.03716988;1202.227;124.2303;0;0;0;2.124633;2.102377;1103337;1.268698e+008
1411.42;0.6733924;0.03865102;1201.424;124.1474;0;0;0;2.120921;2.098743;1102600;1.267805e+008
1420.42;0.6722139;0.04057443;1201.129;124.1169;0;0;0;2.117209;2.095108;1102330;1.267447e+008
1429.42;0.6710352;0.0420948;1201.058;124.1096;0;0;0;2.113497;2.091472;1102265;1.267327e+008
1438.42;0.6697496;0.04309268;1200.41;124.0426;0;0;0;2.109447;2.087507;1101670;1.266592e+008
1447.42;0.6686781;0.04341843;1202.932;124.3032;0;0;0;2.106073;2.084202;1103984;1.269211e+008
1456.42;0.6674996;0.04410235;1202.374;124.2456;0;0;0;2.102361;2.080566;1103472;1.268576e+008
1465.42;0.6662138;0.04593316;1202.418;124.2501;0;0;0;2.098311;2.0766;1103513;1.268572e+008
1474.42;0.6650353;0.04709983;1204.272;124.4417;0;0;0;2.094599;2.072964;1105214;1.270483e+008
1483.42;0.6636424;0.04810331;1203.71;124.3836;0;0;0;2.090212;2.068667;1104699;1.269835e+008
1492.42;0.6621424;0.04933513;1202.948;124.3049;0;0;0;2.085488;2.064039;1103999;1.268972e+008
1501.42;0.6606425;0.05061937;1200.861;124.0892;0;0;0;2.080764;2.059411;1102084;1.266712e+008
1510.42;0.6591425;0.050692;1202.444;124.2528;0;0;0;2.076039;2.054783;1103536;1.268323e+008
1519.42;0.6575353;0.05194989;1200.469;124.0488;0;0;0;2.070977;2.049824;1101724;1.266178e+008
1528.42;0.655821;0.0533245;1198.196;123.8139;0;0;0;2.065578;2.044534;1099638;1.263713e+008
1537.42;0.6542139;0.05430754;1196.68;123.6572;0;0;0;2.060516;2.039575;1098247;1.262052e+008
1546.42;0.6526067;0.05493007;1197.455;123.7372;0;0;0;2.055454;2.034615;1098958;1.262806e+008
1555.42;0.651321;0.05491727;1199.78;123.9776;0;0;0;2.051405;2.030647;1101092;1.265208e+008
1564.42;0.6499282;0.05599443;1199.61;123.96;0;0;0;2.047018;2.026348;1100936;1.264974e+008
1573.42;0.6485353;0.05580259;1201.216;124.1259;0;0;0;2.042631;2.022049;1102410;1.266613e+008
1582.42;0.6472495;0.05591906;1204.282;124.4427;0;0;0;2.038581;2.01808;1105224;1.269796e+008
1591.42;0.6458567;0.0565659;1206.689;124.6914;0;0;0;2.034194;2.013781;1107432;1.272279e+008
1600.42;0.6444639;0.05722281;1208.024;124.8294;0;0;0;2.029808;2.009481;1108657;1.273632e+008
1609.42;0.6427496;0.05828654;1206.909;124.7142;0;0;0;2.024408;2.004189;1107635;1.272389e+008
1618.42;0.6404996;0.05943989;1200.324;124.0337;0;0;0;2.017321;1.997243;1101590;1.265358e+008
1627.42;0.6388925;0.0585868;1202.015;124.2084;0;0;0;2.01226;1.992281;1103143;1.267078e+008
1636.42;0.6373924;0.05900847;1203.938;124.4071;0;0;0;2.007535;1.98765;1104907;1.269047e+008
1645.42;0.6358924;0.058611;1206.934;124.7167;0;0;0;2.002811;1.983018;1107657;1.272146e+008
1654.42;0.6334817;0.05879184;1200.28;124.0291;0;0;0;1.995218;1.975574;1101550;1.265038e+008
1663.42;0.6317138;0.05863249;1198.977;123.8946;0;0;0;1.98965;1.970115;1100355;1.263596e+008
1672.42;0.6302138;0.05856104;1199.981;123.9983;0;0;0;1.984926;1.965483;1101276;1.264596e+008
1681.42;0.6287138;0.05797837;1201.211;124.1254;0;0;0;1.980201;1.96085;1102405;1.265833e+008
1690.42;0.6272138;0.05530272;1204.61;124.4766;0;0;0;1.975477;1.956217;1105524;1.269356e+008
1699.42;0.6257139;0.05358588;1203.378;124.3493;0;0;0;1.970752;1.951584;1104394;1.268e+008
1708.42;0.6242139;0.05209558;1204.282;124.4428;0;0;0;1.966028;1.946951;1105224;1.268893e+008
1717.42;0.6227139;0.04919022;1205.158;124.5332;0;0;0;1.961303;1.942318;1106027;1.269757e+008
1726.42;0.6212138;0.04574785;1205.085;124.5257;0;0;0;1.956579;1.937684;1105960;1.269621e+008
1735.42;0.6197138;0.04300205;1204.92;124.5086;0;0;0;1.951855;1.93305;1105809;1.269389e+008
1744.42;0.6182139;0.03999384;1202.035;124.2106;0;0;0;1.94713;1.928416;1103161;1.266291e+008
1753.42;0.6167139;0.03397813;1201.896;124.1962;0;0;0;1.942406;1.923782;1103034;1.266086e+008
1762.42;0.6155353;0.02504042;1200.956;124.099;0;0;0;1.938694;1.920141;1102171;1.265049e+008
1771.42;0.6154282;0.01256927;1205.938;124.6138;0;0;0;1.938357;1.91981;1106743;1.270293e+008
1780.42;0.6152139;0.001797422;1207.408;124.7657;0;0;0;1.937681;1.919147;1108092;1.271833e+008
1789.42;0.6151067;-0.01110256;1207.56;124.7814;0;0;0;1.937344;1.918816;1108231;1.271989e+008
1798.42;0.6148924;-0.02516898;1205.81;124.6006;0;0;0;1.936669;1.918154;1106626;1.270137e+008
1807.42;0.6146782;-0.04645944;1195.039;123.4876;0;0;0;1.935994;1.917492;1096741;1.258784e+008
1814.434;0.614571;-0.06545118;1185.795;122.5324;1;1;0;1.935657;1.917161;1088257;1.249042e+008
1823.434;0.6164996;-0.1007433;1177.732;121.6992;1;1;0;1.941731;1.92312;1080857;1.240623e+008
1832.434;0.6214282;-0.1478523;1186.299;122.5845;1;1;0;1.957254;1.938346;1088719;1.249837e+008
1841.434;0.6290353;-0.2142512;1195.714;123.5574;1;1;0;1.981213;1.961843;1097360;1.260053e+008
1850.434;0.6369103;-0.2840773;1205.037;124.5207;1;1;0;2.006017;1.986161;1105916;1.270186e+008
1859.434;0.6450532;-0.3561878;1211.179;125.1554;1;1;0;2.031663;2.011301;1111553;1.276982e+008
1868.434;0.6530353;-0.4475442;1180.413;121.9763;1;1;0;2.056804;2.035938;1083318;1.244851e+008
1877.434;0.6628924;-0.5404473;1168.644;120.7601;1;1;0;2.08785;2.066353;1072517;1.232814e+008
1886.434;0.6794459;-0.6739796;1165.444;120.4294;1;1;0;2.139987;2.117411;1069580;1.230066e+008
1895.434;0.701946;-0.8337668;1177.15;121.639;1;1;0;2.210854;2.186769;1080323;1.243283e+008
1904.434;0.7243924;-0.9905249;1182.669;122.2094;1;1;0;2.281551;2.255913;1085388;1.249976e+008
1913.434;0.7480173;-1.144428;1187.817;122.7413;1;1;0;2.35596;2.328636;1090113;1.256331e+008
1922.434;0.7745888;-1.303938;1213.991;125.446;1;1;0;2.43965;2.410366;1114134;1.285064e+008
1931.434;0.7960173;-1.441078;1218.816;125.9446;1;1;0;2.507141;2.476228;1118562;1.291022e+008
1940.434;0.8125709;-1.547807;1178.501;121.7787;1;1;0;2.559278;2.527077;1081563;1.248954e+008
1949.434;0.8354994;-1.664976;1187.042;122.6612;1;1;0;2.631494;2.597466;1089401;1.25889e+008
1958.434;0.8619638;-1.786016;1210.193;125.0536;1;1;0;2.714847;2.678648;1110648;1.284486e+008
1967.434;0.886928;-1.886941;1242.033;128.3437;1;1;0;2.793474;2.755168;1139870;1.31929e+008
1976.434;0.9094816;-1.973204;1270.148;131.2489;1;1;0;2.864509;2.824249;1165672;1.350086e+008
1985.434;0.925553;-2.036697;1275.798;131.8327;1;1;0;2.915128;2.873446;1170857;1.356758e+008
1994.434;0.9357851;-2.080563;1242.166;128.3574;1;1;0;2.947355;2.904755;1139991;1.321405e+008
2003.434;0.943178;-2.115134;1211.858;125.2255;1;1;0;2.970639;2.927371;1112176;1.289455e+008
2012.434;0.9507316;-2.149659;1196.054;123.5925;1;1;0;2.99443;2.950472;1097672;1.272934e+008
2021.434;0.9549637;-2.177578;1164.419;120.3235;1;1;0;3.00776;2.963414;1068639;1.239426e+008
2030.434;0.9560351;-2.19435;1127.469;116.5053;1;1;0;3.011134;2.96669;1034728;1.200135e+008
2039.434;0.9562494;-2.210846;1083.861;111.9992;1;1;0;3.011809;2.967345;994707.7;1.153724e+008
2046.518;0.9561422;-2.222364;1058.107;109.338;1;1;0;3.011472;2.967017;971072.2;1.126306e+008
2055.518;0.9545351;-2.238636;1011.312;104.5025;1;1;0;3.00641;2.962103;928126.3;1.076442e+008
2064.518;0.9485352;-2.243714;943.6449;97.51017;1;1;0;2.987512;2.943756;866025.1;1.004233e+008
2073.518;0.9186423;-2.205482;704.3773;72.7858;1;1;0;2.893362;2.852294;646438.4;7.489175e+007
2082.518;0.8596602;-2.132125;356.3156;36.81935;1;1;0;2.707591;2.671584;327006.7;3.781627e+007
2091.518;0.8598744;-2.135722;376.8303;38.93921;1;1;0;2.708266;2.672241;345834;3.999379e+007
2100.518;0.8596602;-2.14088;386.7718;39.9665;1;1;0;2.707591;2.671584;354957.8;4.104863e+007
2109.518;0.859553;-2.14894;395.2742;40.84508;1;1;0;2.707254;2.671256;362760.8;4.195086e+007
2118.518;0.8594459;-2.15949;400.5023;41.38532;1;1;0;2.706916;2.670927;367558.8;4.250558e+007
2127.518;0.8592316;-2.167673;407.213;42.07876;1;1;0;2.706241;2.67027;373717.5;4.321751e+007
2136.518;0.8591244;-2.177164;415.3648;42.92112;1;1;0;2.705904;2.669941;381198.8;4.408252e+007
2145.518;0.8590173;-2.18492;424.3279;43.84731;1;1;0;2.705566;2.669613;389424.6;4.503362e+007
2154.518;0.858803;-2.192066;432.676;44.70994;1;1;0;2.704891;2.668956;397086;4.591929e+007
2163.518;0.8585888;-2.198822;443.7559;45.85487;1;1;0;2.704216;2.668299;407254.6;4.709489e+007
2172.518;0.8584816;-2.208472;455.0708;47.02408;1;1;0;2.703879;2.66797;417638.8;4.829555e+007
2181.518;0.8581602;-2.219125;466.3194;48.18643;1;1;0;2.702867;2.666984;427962.1;4.948885e+007
2189.266;0.8585351;-2.227076;480.6731;49.66966;2;2;0;2.704048;2.668134;441135.2;5.101275e+007
2198.266;0.8600351;-2.236587;505.4645;52.23144;2;2;0;2.708772;2.672734;463887.3;5.364627e+007
2207.266;0.8614816;-2.247925;531.0162;54.87178;2;2;0;2.713328;2.67717;487337.3;5.636063e+007
2216.266;0.8644816;-2.258253;567.3873;58.63014;2;2;0;2.722777;2.686368;520716.6;6.02265e+007
2225.266;0.8719281;-2.275385;635.8424;65.70385;2;2;0;2.74623;2.709198;583540.9;6.750823e+007
2234.266;0.8794816;-2.296069;708.3034;73.1915;2;2;0;2.770021;2.73235;650041.6;7.521892e+007
2243.266;0.8869816;-2.316373;781.0385;80.70747;2;2;0;2.793643;2.755332;716793.9;8.296216e+007
2252.266;0.8945351;-2.339068;855.3413;88.38544;2;2;0;2.817433;2.778474;784984.9;9.087565e+007
2261.266;0.901928;-2.361218;934.2117;96.53541;2;2;0;2.840718;2.801118;857367.8;9.92777e+007
2270.266;0.9094281;-2.384865;1011.23;104.4939;2;2;0;2.86434;2.824085;928050.4;1.07487e+008
2279.266;0.9169816;-2.40601;1087.84;112.4104;2;2;0;2.888131;2.847211;998359.8;1.15657e+008
2288.266;0.9244816;-2.430524;1170.602;120.9624;2;2;0;2.911753;2.870167;1074313;1.244845e+008
2297.266;0.9293566;-2.452018;1229.135;127.0109;2;2;0;2.927107;2.885086;1128032;1.307286e+008
2306.266;0.9298387;-2.463338;1253.928;129.5728;2;2;0;2.928626;2.886561;1150786;1.333675e+008
2313.376;0.9287137;-2.468407;1262.463;130.4548;2;2;0;2.925082;2.883118;1158619;1.342707e+008
2322.376;0.9268922;-2.473974;1268.738;131.1032;2;2;0;2.919346;2.877544;1164377;1.349305e+008
2331.376;0.9238923;-2.476914;1264.049;130.6187;2;2;0;2.909897;2.868363;1160075;1.344196e+008
2340.376;0.9202494;-2.478343;1257.344;129.9258;2;2;0;2.898423;2.857214;1153921;1.336916e+008
2349.376;0.9164994;-2.47927;1247.878;128.9476;2;2;0;2.886612;2.845734;1145233;1.326698e+008
2358.376;0.912053;-2.480855;1235.084;127.6256;2;2;0;2.872608;2.832122;1133492;1.312918e+008
2367.376;0.9074994;-2.481643;1222.361;126.3109;2;2;0;2.858266;2.81818;1121815;1.299212e+008
2376.376;0.9029995;-2.481573;1208.659;124.895;2;2;0;2.844093;2.804399;1109241;1.284472e+008
2385.376;0.8991423;-2.482585;1206.022;124.6226;2;2;0;2.831944;2.792586;1106821;1.281518e+008
2394.376;0.8954995;-2.483434;1203.616;124.3739;2;2;0;2.820471;2.781428;1104612;1.278818e+008
2403.376;0.8918566;-2.481744;1197.606;123.7529;2;2;0;2.808997;2.770268;1099097;1.272291e+008
2412.376;0.888803;-2.48333;1199.998;124;2;2;0;2.79938;2.760913;1101291;1.274712e+008
2421.376;0.8856959;-2.485676;1201.123;124.1163;2;2;0;2.789593;2.751393;1102324;1.275787e+008
2430.376;0.8825887;-2.485497;1198.476;123.8428;2;2;0;2.779807;2.741872;1099895;1.272854e+008
2439.376;0.8793744;-2.487009;1196.636;123.6526;2;2;0;2.769683;2.732021;1098206;1.270774e+008
2448.376;0.8765352;-2.488449;1198.108;123.8047;2;2;0;2.760741;2.72332;1099557;1.272227e+008
2457.376;0.8739102;-2.491393;1202.275;124.2353;2;2;0;2.752473;2.715273;1103381;1.276549e+008
2466.376;0.8711781;-2.490752;1203.096;124.3201;2;2;0;2.743868;2.706899;1104135;1.277313e+008
2475.376;0.8684994;-2.492617;1205.507;124.5693;2;2;0;2.735431;2.698687;1106347;1.279768e+008
2484.376;0.8658209;-2.493455;1207.316;124.7562;2;2;0;2.726995;2.690475;1108008;1.281583e+008
2493.376;0.862928;-2.495278;1207.526;124.778;2;2;0;2.717883;2.681605;1108201;1.281693e+008
2502.376;0.8599816;-2.496343;1205.833;124.603;2;2;0;2.708603;2.67257;1106647;1.27978e+008
2511.376;0.8572495;-2.496497;1204.64;124.4797;2;2;0;2.699998;2.664191;1105552;1.278406e+008
2520.376;0.8547852;-2.497801;1200.901;124.0933;2;2;0;2.692237;2.656634;1102120;1.274342e+008
2529.376;0.8526423;-2.497369;1200.031;124.0035;2;2;0;2.685488;2.650061;1101322;1.273336e+008
2538.376;0.8507137;-2.498011;1199.71;123.9703;2;2;0;2.679413;2.644146;1101028;1.27292e+008
2547.376;0.8489995;-2.499215;1201.247;124.1291;2;2;0;2.674014;2.638887;1102438;1.274483e+008
2556.376;0.8472852;-2.500974;1201.812;124.1875;2;2;0;2.668615;2.633628;1102957;1.275016e+008
2565.376;0.8454637;-2.501977;1199.62;123.961;2;2;0;2.662878;2.62804;1100945;1.272619e+008
2574.376;0.8437494;-2.502819;1198.245;123.8189;2;2;0;2.657479;2.622781;1099683;1.271093e+008
2583.376;0.8422494;-2.503747;1198.394;123.8343;2;2;0;2.652754;2.618179;1099820;1.271193e+008
2592.376;0.8407494;-2.504505;1197.83;123.776;2;2;0;2.64803;2.613576;1099302;1.270536e+008
2601.376;0.8394638;-2.505547;1198.641;123.8598;2;2;0;2.64398;2.609631;1100046;1.271346e+008
2610.376;0.8382852;-2.506998;1199.861;123.9859;2;2;0;2.640268;2.606015;1101166;1.272594e+008
2619.376;0.8371066;-2.508306;1200.737;124.0764;2;2;0;2.636556;2.602398;1101970;1.273477e+008
2628.376;0.8358209;-2.509038;1199.208;123.9184;2;2;0;2.632507;2.598453;1100566;1.271805e+008
2637.376;0.8346423;-2.509944;1198.562;123.8516;2;2;0;2.628794;2.594835;1099973;1.271074e+008
2646.376;0.8334638;-2.510995;1197.587;123.7509;2;2;0;2.625083;2.591219;1099079;1.269994e+008
2655.376;0.8322851;-2.511382;1195.506;123.5359;2;2;0;2.621371;2.587602;1097170;1.267743e+008
2664.376;0.8315887;-2.512679;1199.156;123.9131;2;2;0;2.619177;2.585464;1100519;1.271586e+008
2673.376;0.8313745;-2.514321;1208.052;124.8323;2;2;0;2.618502;2.584807;1108684;1.281011e+008
2682.376;0.8308923;-2.515934;1212.041;125.2445;2;2;0;2.616984;2.583327;1112345;1.285222e+008
2691.376;0.8302495;-2.517178;1214.077;125.4549;2;2;0;2.614959;2.581354;1114213;1.287355e+008
2700.376;0.829553;-2.518416;1215.158;125.5665;2;2;0;2.612766;2.579216;1115204;1.288473e+008
2709.376;0.8283209;-2.518592;1208.897;124.9196;2;2;0;2.608885;2.575434;1109459;1.281786e+008
2718.376;0.8271423;-2.518828;1203.705;124.383;2;2;0;2.605173;2.571816;1104693;1.276234e+008
2727.376;0.8260709;-2.519329;1199.898;123.9897;2;2;0;2.601798;2.568527;1101200;1.272156e+008
2736.376;0.8252138;-2.520287;1197.915;123.7848;2;2;0;2.599098;2.565896;1099380;1.270021e+008
2745.376;0.8242495;-2.520691;1194.972;123.4807;2;2;0;2.596061;2.562936;1096679;1.266863e+008
2754.376;0.8238209;-2.521785;1197.921;123.7855;2;2;0;2.594712;2.56162;1099386;1.269973e+008
2763.376;0.8233923;-2.522868;1199.649;123.964;2;2;0;2.593362;2.560304;1100972;1.271788e+008
2772.376;0.8229638;-2.523554;1201.796;124.1858;2;2;0;2.592012;2.558989;1102942;1.274047e+008
2781.376;0.822428;-2.524223;1201.959;124.2027;2;2;0;2.590325;2.557344;1103092;1.274199e+008
2790.376;0.8218923;-2.524749;1202.403;124.2486;2;2;0;2.588637;2.555699;1103499;1.274649e+008
2799.376;0.8212495;-2.525446;1201.078;124.1116;2;2;0;2.586612;2.553726;1102282;1.273219e+008
2808.376;0.8206067;-2.52599;1199.181;123.9156;2;2;0;2.584588;2.551752;1100542;1.271183e+008
2817.376;0.8200709;-2.526277;1198.702;123.8661;2;2;0;2.5829;2.550107;1100103;1.270655e+008
2826.376;0.819428;-2.526741;1196.447;123.6331;2;2;0;2.580876;2.548133;1098033;1.268239e+008
2835.376;0.8191066;-2.527491;1198.315;123.8261;2;2;0;2.579864;2.547146;1099747;1.270206e+008
2844.376;0.818678;-2.528076;1198.576;123.8531;2;2;0;2.578513;2.54583;1099987;1.270467e+008
2853.376;0.8182495;-2.528702;1198.206;123.8148;2;2;0;2.577164;2.544515;1099647;1.270057e+008
2862.376;0.8178209;-2.529164;1197.724;123.7651;2;2;0;2.575814;2.543199;1099205;1.26953e+008
2871.376;0.8173924;-2.529821;1197.234;123.7144;2;2;0;2.574464;2.541883;1098755;1.268994e+008
2880.376;0.8169637;-2.530439;1196.714;123.6607;2;2;0;2.573114;2.540567;1098278;1.268426e+008
2889.376;0.8166424;-2.530683;1197.01;123.6913;2;2;0;2.572102;2.53958;1098549;1.268727e+008
2898.376;0.8163209;-2.531438;1197.194;123.7103;2;2;0;2.57109;2.538593;1098719;1.26891e+008
2907.376;0.8161066;-2.531835;1198.366;123.8314;2;2;0;2.570415;2.537935;1099794;1.270144e+008
2916.376;0.8157852;-2.532108;1198.294;123.824;2;2;0;2.569402;2.536948;1099728;1.270055e+008
2925.376;0.8154637;-2.532559;1198.043;123.798;2;2;0;2.56839;2.535961;1099497;1.269776e+008
2934.376;0.8151423;-2.532575;1197.005;123.6907;2;2;0;2.567377;2.534974;1098545;1.268663e+008
2943.376;0.8148744;-2.532888;1196.812;123.6708;2;2;0;2.566534;2.534151;1098368;1.268449e+008
2952.376;0.8146066;-2.533077;1196.684;123.6575;2;2;0;2.56569;2.533329;1098250;1.268302e+008
2961.376;0.8142852;-2.532761;1195.085;123.4923;2;2;0;2.564678;2.532342;1096782;1.266595e+008
2970.376;0.8141781;-2.533182;1195.801;123.5663;2;2;0;2.56434;2.532013;1097440;1.26735e+008
2979.376;0.8139637;-2.533303;1194.65;123.4475;2;2;0;2.563665;2.531354;1096384;1.266122e+008
2988.376;0.8138566;-2.533811;1194.336;123.415;2;2;0;2.563328;2.531025;1096096;1.265785e+008
2997.376;0.8136423;-2.533737;1192.822;123.2585;2;2;0;2.562653;2.530367;1094706;1.264172e+008
3004.988;0.8135352;-2.534269;1192.346;123.2094;3;3;0;2.562316;2.530039;1094269;1.263664e+008
3013.988;0.813696;-2.535142;1194.048;123.3852;3;3;0;2.562822;2.530532;1095831;1.265473e+008
3022.988;0.8138566;-2.535511;1196.163;123.6038;3;3;0;2.563328;2.531025;1097772;1.267722e+008
3031.988;0.8140173;-2.536028;1198.224;123.8167;3;3;0;2.563834;2.531519;1099664;1.269912e+008
3040.988;0.8141244;-2.536068;1199.032;123.9003;3;3;0;2.564172;2.531848;1100406;1.270773e+008
3048.692;0.8142852;-2.53606;1199.581;123.9569;3;3;0;2.564678;2.532342;1100909;1.27136e+008
3057.692;0.8141244;-2.534963;1196.276;123.6154;3;3;0;2.564172;2.531848;1097876;1.267851e+008
3066.692;0.8139637;-2.534864;1192.327;123.2074;3;3;0;2.563665;2.531354;1094252;1.26366e+008
3073.894;0.8139637;-2.53446;1190.655;123.0346;4;4;0;2.563665;2.531354;1092717;1.261888e+008
3082.894;0.8146066;-2.534601;1193.351;123.3132;4;4;0;2.56569;2.533329;1095192;1.264771e+008
3091.894;0.8154637;-2.535267;1197.948;123.7882;4;4;0;2.56839;2.535961;1099410;1.269675e+008
3100.894;0.8159995;-2.535965;1198.544;123.8498;4;4;0;2.570077;2.537606;1099957;1.270328e+008
3109.894;0.8164816;-2.536081;1197.307;123.7219;4;4;0;2.571596;2.539086;1098822;1.269036e+008
3118.894;0.8168566;-2.536356;1195.6;123.5456;4;4;0;2.572777;2.540238;1097256;1.267242e+008
3127.894;0.8173924;-2.536162;1195.204;123.5046;4;4;0;2.574464;2.541883;1096892;1.266842e+008
3136.894;0.8180352;-2.535962;1195.962;123.583;4;4;0;2.576489;2.543857;1097588;1.267671e+008
3145.894;0.8186245;-2.535577;1195.648;123.5505;4;4;0;2.578345;2.545666;1097299;1.267361e+008
3154.894;0.8192673;-2.535214;1194.664;123.4488;4;4;0;2.580369;2.54764;1096396;1.266343e+008
3163.894;0.8200173;-2.534903;1194.983;123.4818;4;4;0;2.582732;2.549943;1096689;1.26671e+008
3172.894;0.8207138;-2.534257;1194.665;123.4489;4;4;0;2.584925;2.552081;1096397;1.2664e+008
3181.894;0.8215709;-2.534097;1195.773;123.5634;4;4;0;2.587625;2.554712;1097414;1.267608e+008
3190.894;0.8225351;-2.533724;1198.146;123.8086;4;4;0;2.590662;2.557673;1099592;1.270161e+008
3199.894;0.8233923;-2.532125;1198.215;123.8158;4;4;0;2.593362;2.560304;1099656;1.270268e+008
3208.894;0.8242495;-2.531103;1197.502;123.7421;4;4;0;2.596061;2.562936;1099001;1.269546e+008
3217.894;0.8249994;-2.529975;1195.525;123.5378;4;4;0;2.598423;2.565238;1097186;1.267478e+008
3226.894;0.8257494;-2.528847;1193.277;123.3055;4;4;0;2.600786;2.56754;1095123;1.265124e+008
3235.894;0.8269816;-2.528891;1196.832;123.6729;4;4;0;2.604666;2.571323;1098386;1.268941e+008
3244.894;0.8283745;-2.529217;1202.043;124.2113;4;4;0;2.609053;2.575598;1103168;1.274521e+008
3253.894;0.8293923;-2.528802;1202.483;124.2568;4;4;0;2.612259;2.578723;1103572;1.275027e+008
3262.894;0.8303566;-2.528253;1200.434;124.0451;4;4;0;2.615296;2.581682;1101692;1.272893e+008
3271.894;0.8311602;-2.527596;1198.129;123.8069;4;4;0;2.617827;2.584149;1099577;1.27048e+008
3280.894;0.8320709;-2.527257;1195.047;123.4884;4;4;0;2.620696;2.586944;1096748;1.267247e+008
3289.894;0.8331423;-2.527901;1194.103;123.3909;4;4;0;2.62407;2.590232;1095881;1.266287e+008
3298.894;0.8343209;-2.529591;1193.38;123.3161;4;4;0;2.627782;2.593849;1095218;1.265566e+008
3307.894;0.8357137;-2.531745;1194.594;123.4416;4;4;0;2.632169;2.598124;1096332;1.266908e+008
3316.894;0.8372137;-2.533286;1198.542;123.8496;4;4;0;2.636894;2.602727;1099955;1.271154e+008
3325.894;0.8386066;-2.534272;1200.15;124.0157;4;4;0;2.641281;2.607001;1101431;1.272913e+008
3334.894;0.8397852;-2.535483;1199.914;123.9914;4;4;0;2.644993;2.610618;1101215;1.27271e+008
3343.894;0.8409638;-2.536488;1199.09;123.9062;4;4;0;2.648705;2.614234;1100458;1.271881e+008
3352.894;0.8421959;-2.537699;1199.486;123.9472;4;4;0;2.652586;2.618014;1100822;1.27235e+008
3361.894;0.8432137;-2.538345;1196.765;123.666;4;4;0;2.655791;2.621137;1098325;1.269503e+008
3370.894;0.8441781;-2.538732;1194.026;123.3829;4;4;0;2.658828;2.624096;1095811;1.266635e+008
3379.894;0.8446065;-2.537743;1185.903;122.5435;4;4;0;2.660178;2.625411;1088356;1.258034e+008
3388.894;0.8454102;-2.536703;1181.701;122.1094;4;4;0;2.662709;2.627876;1084500;1.253608e+008
3397.894;0.8466424;-2.537012;1183.068;122.2506;4;4;0;2.66659;2.631656;1085754;1.255105e+008
3406.894;0.848678;-2.538138;1193.37;123.3151;4;4;0;2.673002;2.637901;1095209;1.266113e+008
3415.894;0.8504995;-2.539238;1200.269;124.028;4;4;0;2.678739;2.643488;1101540;1.273504e+008
3424.894;0.8519995;-2.539967;1203.957;124.4091;4;4;0;2.683463;2.64809;1104925;1.277476e+008
3433.894;0.8534994;-2.539922;1208.157;124.8431;4;4;0;2.688187;2.65269;1108779;1.281991e+008
3442.894;0.854678;-2.539098;1209.815;125.0145;4;4;0;2.691899;2.656305;1110302;1.283798e+008
3451.894;0.8555352;-2.537512;1208.225;124.8502;4;4;0;2.694599;2.658934;1108842;1.282144e+008
3459.81;0.8554816;-2.534954;1203.154;124.3262;4;4;0;2.69443;2.658769;1104188;1.27676e+008
3468.81;0.8551066;-2.530605;1194.46;123.4277;4;4;0;2.693249;2.65762;1096209;1.267519e+008
3476.342;0.8551066;-2.52772;1189.84;122.9504;5;5;0;2.693249;2.65762;1091969;1.262617e+008
3485.342;0.8563923;-2.52614;1199.616;123.9605;5;5;0;2.697299;2.661563;1100941;1.273041e+008
3494.342;0.8564995;-2.522603;1196.484;123.6369;5;5;0;2.697636;2.661891;1098067;1.269722e+008
3503.342;0.8568208;-2.519157;1203.014;124.3117;5;5;0;2.698648;2.662877;1104060;1.276665e+008
3512.342;0.8570352;-2.515691;1210.122;125.0462;5;5;0;2.699323;2.663534;1110583;1.284216e+008
3520.092;0.856928;-2.513266;1218.396;125.9012;5;5;0;2.698986;2.663206;1118176;1.292992e+008
3529.092;0.8545708;-2.507002;1214.056;125.4527;5;5;0;2.691562;2.655976;1114193;1.288293e+008
3538.092;0.8518388;-2.501095;1209.851;125.0182;5;5;0;2.682957;2.647597;1110334;1.283724e+008
3547.092;0.8487852;-2.496191;1209.769;125.0097;5;5;0;2.673339;2.63823;1110259;1.283516e+008
3556.092;0.8454637;-2.493655;1215.025;125.5528;5;5;0;2.662878;2.62804;1115083;1.288962e+008
3565.092;0.8414994;-2.493954;1226.378;126.726;5;5;0;2.650392;2.615878;1125502;1.300847e+008
3574.092;0.8336781;-2.492734;1220.809;126.1505;5;5;0;2.625758;2.591876;1120391;1.294629e+008
3583.092;0.8216244;-2.486605;1203.731;124.3858;5;5;0;2.587793;2.554877;1104718;1.276047e+008
3592.092;0.8098924;-2.478684;1199.302;123.9281;5;5;0;2.550842;2.518851;1100653;1.270893e+008
3601.092;0.7993923;-2.469621;1213.826;125.4289;5;5;0;2.517771;2.486597;1113982;1.285869e+008
3610.092;0.7876066;-2.448479;1216.278;125.6823;5;5;0;2.480651;2.450382;1116233;1.288001e+008
3619.092;0.7734638;-2.40781;1215.685;125.621;5;5;0;2.436106;2.406907;1115688;1.286813e+008
3628.092;0.7584638;-2.349222;1217.169;125.7743;5;5;0;2.388862;2.360775;1117050;1.287789e+008
3637.092;0.7434638;-2.27434;1242.765;128.4193;5;5;0;2.341618;2.314623;1140541;1.314264e+008
3646.092;0.7190888;-2.156606;1233.27;127.4381;5;5;0;2.264847;2.23958;1131827;1.303244e+008
3655.092;0.6890353;-1.998006;1218.341;125.8955;5;5;0;2.17019;2.146977;1118126;1.286277e+008
3664.092;0.6620353;-1.839196;1222.374;126.3122;5;5;0;2.08515;2.063709;1121827;1.28946e+008
3673.092;0.6320888;-1.654213;1208.246;124.8524;5;5;0;1.990831;1.971273;1108861;1.27338e+008
3682.092;0.6024639;-1.450448;1204.779;124.494;5;5;0;1.897524;1.879746;1105679;1.268563e+008
3691.092;0.5741782;-1.229503;1215.504;125.6023;5;5;0;1.808435;1.792278;1115522;1.278737e+008
3700.092;0.5442318;-0.9725884;1224.419;126.5235;5;5;0;1.714116;1.699591;1123704;1.286923e+008
3709.092;0.5116604;-0.6947871;1205.194;124.5369;5;5;0;1.611529;1.598681;1106060;1.265439e+008
3718.092;0.4815533;-0.4588489;1151.363;118.9744;5;5;0;1.516703;1.505316;1056657;1.207789e+008
3727.092;0.4593212;-0.3117287;1073.053;110.8824;5;5;0;1.446681;1.436316;984788.8;1.124865e+008
3736.092;0.4466247;-0.2351768;1013.674;104.7465;5;5;0;1.406692;1.39689;930293.7;1.0622e+008
3745.092;0.4436247;-0.2023133;1006.667;104.0224;5;5;0;1.397243;1.387572;923863;1.054759e+008
3754.092;0.443089;-0.1812417;1009.136;104.2776;5;5;0;1.395556;1.385908;926128.8;1.057328e+008
3763.092;0.4429818;-0.1647128;1008.547;104.2167;5;5;0;1.395218;1.385575;925588.5;1.056708e+008
3772.092;0.4427676;-0.1497879;1004.372;103.7854;5;5;0;1.394544;1.384909;921757.4;1.052327e+008
3781.092;0.4426604;-0.1370018;999.515;103.2834;5;5;0;1.394206;1.384576;917299.5;1.047234e+008
3788.212;0.4425533;-0.128905;991.8827;102.4948;6;6;0;1.393869;1.384244;910294.9;1.039234e+008
3797.212;0.443464;-0.121655;989.6689;102.266;6;6;0;1.396737;1.387073;908263.3;1.036944e+008
3806.212;0.444964;-0.1159173;992.755;102.5849;6;6;0;1.401461;1.391732;911095.5;1.040226e+008
3815.212;0.446464;-0.1110082;993.6619;102.6786;6;6;0;1.406186;1.396391;911927.8;1.041225e+008
3824.212;0.447964;-0.1070152;994.2387;102.7382;6;6;0;1.41091;1.401049;912457.2;1.041877e+008
3833.212;0.449464;-0.1043482;992.5243;102.5611;6;6;0;1.415635;1.405708;910883.8;1.040129e+008
3842.212;0.4511783;-0.1024204;993.1354;102.6242;6;6;0;1.421034;1.411032;911444.6;1.040825e+008
3851.212;0.4534283;-0.1018624;998.859;103.2156;6;6;0;1.428121;1.418019;916697.4;1.046897e+008
3860.212;0.4556783;-0.1007572;1002.704;103.613;6;6;0;1.435207;1.425006;920226.3;1.051e+008
3869.212;0.4579283;-0.09982446;1006.284;103.9829;6;6;0;1.442294;1.431992;923511.4;1.054826e+008
3878.212;0.4601783;-0.09920334;1009.287;104.2932;6;6;0;1.44938;1.438977;926268.1;1.058048e+008
3887.212;0.4619997;-0.09853556;1007.651;104.1241;6;6;0;1.455117;1.444632;924766.1;1.056393e+008
3896.212;0.4636604;-0.09776175;1004.247;103.7724;6;6;0;1.460348;1.449787;921641.9;1.052878e+008
3905.212;0.465589;-0.09740397;1002.076;103.5481;6;6;0;1.466422;1.455774;919649.9;1.050665e+008
3914.212;0.4675711;-0.09709146;1001.1;103.4472;6;6;0;1.472665;1.461927;918754.4;1.049707e+008
3923.212;0.4696069;-0.09704698;1000.733;103.4093;6;6;0;1.479077;1.468245;918417.7;1.049388e+008
3932.212;0.4717497;-0.09682396;999.9096;103.3242;6;6;0;1.485826;1.474896;917661.7;1.048594e+008
3941.212;0.4739461;-0.09677793;998.7735;103.2068;6;6;0;1.492744;1.481712;916619;1.047474e+008
3950.212;0.476464;-0.0975277;1002.418;103.5834;6;6;0;1.500674;1.489525;919963.4;1.051378e+008
3959.212;0.4788211;-0.09810535;1003.346;103.6793;6;6;0;1.508098;1.496839;920815.6;1.052429e+008
3968.212;0.4812854;-0.09866797;1005.084;103.8589;6;6;0;1.515859;1.504485;922410.4;1.054332e+008
3977.212;0.4836425;-0.09894087;1005.37;103.8884;6;6;0;1.523284;1.511798;922672.5;1.054709e+008
3986.212;0.4861068;-0.09924203;1006.762;104.0323;6;6;0;1.531045;1.519443;923950.7;1.056251e+008
3995.212;0.488464;-0.0994847;1006.821;104.0384;6;6;0;1.538469;1.526755;924004.9;1.05639e+008
4004.212;0.4908211;-0.09990919;1005.95;103.9483;6;6;0;1.545893;1.534066;923204.8;1.055553e+008
4013.212;0.4932854;-0.1006209;1006.569;104.0123;6;6;0;1.553655;1.541709;923773.1;1.056283e+008
4022.212;0.4957497;-0.1010741;1007.337;104.0917;6;6;0;1.561416;1.549352;924478.4;1.05717e+008
4031.212;0.4981068;-0.1017759;1006.428;103.9977;6;6;0;1.56884;1.556661;923643.4;1.056293e+008
4040.212;0.5004639;-0.1024016;1007.844;104.1441;6;6;0;1.576264;1.56397;924943.3;1.057857e+008
4049.212;0.5028211;-0.1027347;1008.744;104.2371;6;6;0;1.583689;1.571279;925769.1;1.058878e+008
4058.212;0.5049639;-0.1026815;1007.788;104.1383;6;6;0;1.590438;1.577923;924891.6;1.057945e+008
4067.212;0.5071068;-0.1024825;1006.977;104.0545;6;6;0;1.597187;1.584566;924147.3;1.057164e+008
4076.212;0.5091425;-0.1022275;1005.925;103.9457;6;6;0;1.603598;1.590877;923181.9;1.056126e+008
4085.212;0.5110711;-0.1016595;1003.244;103.6688;6;6;0;1.609673;1.596855;920721.8;1.053375e+008
4094.212;0.5130532;-0.1012328;1001.379;103.476;6;6;0;1.615916;1.602999;919010;1.051481e+008
4103.213;0.5149818;-0.100459;998.6326;103.1922;6;6;0;1.62199;1.608976;916489.6;1.04866e+008
4112.213;0.516964;-0.09999031;995.8625;102.906;6;6;0;1.628233;1.615119;913947.4;1.045815e+008
4121.213;0.5195354;-0.1006209;998.8993;103.2198;6;6;0;1.636332;1.623088;916734.4;1.049088e+008
4130.213;0.5222139;-0.1014683;1002.036;103.544;6;6;0;1.644768;1.631388;919613.4;1.05247e+008
4139.213;0.5244639;-0.1019951;1001.163;103.4537;6;6;0;1.651855;1.63836;918811.6;1.051626e+008
4148.213;0.5267139;-0.102064;1000.907;103.4273;6;6;0;1.658942;1.645331;918577.1;1.051431e+008
4157.213;0.5289639;-0.1029381;999.7261;103.3052;6;6;0;1.666028;1.652302;917493.3;1.050263e+008
4166.213;0.531214;-0.1033509;998.7695;103.2064;6;6;0;1.673115;1.659272;916615.3;1.049331e+008
4175.213;0.5338925;-0.1044313;1002.282;103.5693;6;6;0;1.681551;1.66757;919838.8;1.053109e+008
4184.213;0.5363032;-0.1055627;1002.891;103.6322;6;6;0;1.689144;1.675037;920397.5;1.053827e+008
4193.213;0.5387139;-0.1067272;1003.87;103.7334;6;6;0;1.696737;1.682503;921296.2;1.054935e+008
4202.213;0.5410711;-0.1076139;1006.156;103.9697;6;6;0;1.704161;1.689803;923394.5;1.057415e+008
4211.213;0.5435354;-0.1080536;1010.105;104.3778;6;6;0;1.711922;1.697434;927018.6;1.061646e+008
4220.213;0.5457318;-0.108575;1011.686;104.5411;6;6;0;1.71884;1.704235;928469.6;1.06338e+008
4229.213;0.5479282;-0.1085682;1012.618;104.6374;6;6;0;1.725758;1.711036;929324.4;1.064432e+008
4238.213;0.5500711;-0.1084628;1014.386;104.8201;6;6;0;1.732507;1.717671;930947.1;1.066361e+008
4247.213;0.5519461;-0.1079791;1014.51;104.8329;6;6;0;1.738413;1.723475;931061.1;1.066553e+008
4256.188;0.5539282;-0.1073685;1014.845;104.8675;6;6;0;1.744656;1.729611;931368.5;1.066971e+008
4264.191;0.5513568;-0.1035608;975.2695;100.7781;6;6;0;1.736557;1.721651;895048.3;1.025281e+008
4273.191;0.5361961;-0.09121803;839.9119;86.79107;6;6;0;1.688807;1.674705;770824.6;8.82568e+007
4282.191;0.5212497;-0.08078136;727.7157;75.19743;6;6;0;1.641731;1.628401;667857.1;7.643198e+007
4291.191;0.5061961;-0.07138937;626.9704;64.78707;6;6;0;1.594319;1.581743;575398.8;6.581999e+007
4300.191;0.4912497;-0.06298237;538.3818;55.6329;6;6;0;1.547243;1.535395;494097;5.649368e+007
4309.191;0.4762497;-0.05539609;458.8297;47.4125;6;6;0;1.499999;1.48886;421088.5;4.812369e+007
4318.191;0.4612497;-0.04820933;386.3091;39.91869;6;6;0;1.452755;1.442304;354533.1;4.049861e+007
4327.191;0.4463033;-0.04202315;323.1592;33.39318;6;6;0;1.40568;1.395892;296577.6;3.386258e+007
4336.191;0.4311961;-0.03628095;265.4209;27.42688;6;6;0;1.358098;1.348959;243588.6;2.779936e+007
4345.191;0.4163033;-0.03126324;215.6954;22.28857;6;6;0;1.311191;1.30267;197953.3;2.258082e+007
4354.191;0.4012497;-0.02704063;172.8341;17.85956;6;6;0;1.263779;1.25586;158617.5;1.808526e+007
4363.191;0.3862497;-0.02390044;136.3922;14.09389;6;6;0;1.216535;1.209194;125173.2;1.426535e+007
4372.191;0.3713033;-0.0219627;108.1783;11.17845;6;6;0;1.169459;1.162674;99280.09;1.130918e+007
4381.191;0.3562498;-0.02077442;86.3358;8.921384;6;6;0;1.122046;1.115798;79234.21;9021485
4390.191;0.3412498;-0.0200382;71.23328;7.360786;6;6;0;1.074802;1.069067;65373.95;7439900
4399.191;0.3263033;-0.01914787;62.69682;6.478685;6;6;0;1.027727;1.022482;57539.67;6545268
4408.191;0.3112498;-0.01760753;61.44807;6.349647;6;6;0;0.9803143;0.9755404;56393.64;6411894
4412.859;0.3035355;-0.01694256;61.3305;6.337497;6;6;0;0.9560174;0.9514764;56285.73;6398085