File: Ensayos/Resistencia/comp/Clavo6/Clavo6a.raw
"Test Type";"Manual"
"Method Name:";"C:\INSTRON\user\template\CYCLE.MTM"
"Name:";""
"Operator ID:";""
"Company:";""
"Lab name:";""
"Test date:";"05/06/2017"
"Temperature:";""
"Humidity:";""
"Note 1:";""
"Note 2:";""
"Note 3:";""
"Geometry:";"Rectangular"
"Specimen";1
"Specimen name:";""
"Width:";0.250000;"in"
"Thickness:";0.060000;"in"
"Length:";1.250000;"in"
"Diameter:";0.039370;"in"
"Inner diameter:";0.019685;"in"
"Outer diameter:";0.039370;"in"
"Wall thickness:";0.019685;"in"
"Area:";0.015000;"in*in"
"Linear density:";1.000000;"den"
"Sled weight:";2.204623;"lbf"
"Loading span:";0.000000;"mm"
"Support span:";1.000000;"mm"
"Span ratio:";"2"
"Fixture type:";"3-point"
"Comment:";""
"Included"
"Final Width:";0.250000;"in"
"Final Thickness:";0.060000;"in"
"Final Length:";1.250000;"in"
"Final Diameter:";0.039370;"in"
"Final Inner diameter:";0.019685;"in"
"Final Outer diameter:";0.039370;"in"
"Final Wall thickness:";0.019685;"in"
"Final Area:";0.015000;"in*in"
"Final Linear density:";1.000000;"den"
"Time sec";"Extension mm";"Strain 1 %";"Load N";"Stress MPa";"Cycle Count ";"Total Cycle Count ";"Repetitions Count ";"Strain [Exten.] %";"True strain %";"Tenacity gf/tex";"True stress Pa"
0;0;-0.002387312;49.67449;5.133041;0;0;0;0;0;45588.5;5133041
5;0.008357138;-0.006882418;54.65229;5.647415;0;0;0;0.02632169;0.02631823;50156.85;5648901
10;0.01671428;-0.005834735;64.64871;6.68038;0;0;0;0.05264339;0.05262954;59331;6683897
15;0.02496427;-0.008384153;73.00848;7.544225;0;0;0;0.07862762;0.07859673;67003.14;7550156
20;0.03342855;-0.01120024;80.78021;8.347305;0;0;0;0.1052868;0.1052314;74135.6;8356094
25;0.04167855;-0.0139751;88.04883;9.098397;0;0;0;0.131271;0.1311849;80806.34;9110340
30;0.05014283;-0.01160343;95.0553;9.822401;0;0;0;0.1579302;0.1578056;87236.49;9837913
35;0.05833925;-0.01470956;102.3228;10.57337;0;0;0;0.1837457;0.1835771;93906.16;1.05928e+007
40;0.06664281;-0.01788997;110.0619;11.37308;0;0;0;0.2098986;0.2096786;101008.7;1.139696e+007
45;0.07510709;-0.01696698;117.9338;12.18651;0;0;0;0.2365578;0.2362784;108233.1;1.221534e+007
50;0.08335709;-0.01807273;125.8588;13.00544;0;0;0;0.262542;0.262198;115506.3;1.303958e+007
55;0.0917678;-0.02082743;134.3825;13.88622;0;0;0;0.2890324;0.2886155;123328.8;1.392635e+007
60;0.09996422;-0.02275835;143.8;14.85936;0;0;0;0.3148479;0.3143533;131971.7;1.490615e+007
65;0.1083749;-0.02067356;153.6081;15.87287;0;0;0;0.3413384;0.3407571;140973;1.592705e+007
70;0.1166785;-0.02763269;163.3911;16.88378;0;0;0;0.3674913;0.3668177;149951.3;1.694583e+007
75;0.1250892;-0.02781952;173.9331;17.97312;0;0;0;0.3939817;0.3932077;159626.1;1.804393e+007
80;0.1333392;-0.02923622;184.12;19.02577;0;0;0;0.419966;0.4190866;168975.1;1.910567e+007
85.00001;0.1417499;-0.03167543;195.3711;20.18839;0;0;0;0.4464564;0.4454627;179300.8;2.027852e+007
90.00001;0.1499999;-0.03530283;206.1307;21.30022;0;0;0;0.4724407;0.4713281;189175.4;2.140085e+007
95.00001;0.158357;-0.03415124;217.8115;22.50723;0;0;0;0.4987623;0.4975226;199895.3;2.261949e+007
100;0.1667677;-0.0361903;229.7395;23.7398;0;0;0;0.5252528;0.5238781;210842.2;2.386449e+007
105;0.1749642;-0.04139736;241.7974;24.98578;0;0;0;0.5510682;0.5495554;221908.3;2.512347e+007
110;0.1834285;-0.04140155;254.6589;26.31481;0;0;0;0.5777274;0.576065;233711.9;2.646684e+007
115;0.1916784;-0.04447225;267.5495;27.64684;0;0;0;0.6037117;0.6018966;245542.1;2.781375e+007
120;0.2000356;-0.04902714;280.8972;29.0261;0;0;0;0.6300333;0.6280569;257791.9;2.920898e+007
125;0.2083927;-0.05093688;294.7032;30.45273;0;0;0;0.656355;0.6542104;270462.3;3.065261e+007
130;0.2167499;-0.05262346;309.73;32.00549;0;0;0;0.6826767;0.6803571;284253;3.222399e+007
135;0.2250534;-0.06144527;324.4389;33.52542;0;0;0;0.7088297;0.7063293;297752;3.376305e+007
140;0.2334641;-0.06495726;340.4834;35.18336;0;0;0;0.7353202;0.7326298;312476.8;3.544207e+007
145;0.2416606;-0.06901104;356.1806;36.80541;0;0;0;0.7611356;0.7582536;326882.9;3.708555e+007
150;0.2500177;-0.07850103;373.171;38.56108;0;0;0;0.7874572;0.784373;342475.6;3.886473e+007
155;0.2584284;-0.0869397;390.4403;40.34558;0;0;0;0.8139477;0.810653;358324.5;4.067397e+007
160;0.2666784;-0.09062443;407.779;42.13725;0;0;0;0.839932;0.8364242;374236.9;4.249117e+007
165;0.2750891;-0.1045425;425.9669;44.01667;0;0;0;0.8664224;0.8626905;390928.8;4.439804e+007
170;0.2833391;-0.113052;443.9721;45.87721;0;0;0;0.8924066;0.8884482;407453;4.628662e+007
175;0.2860712;-0.1165048;443.5614;45.83477;0;0;0;0.9010118;0.8969768;407076.1;4.624774e+007
180;0.286232;-0.1168115;438.7712;45.33978;0;0;0;0.901518;0.8974785;402679.9;4.574853e+007
185;0.286232;-0.116112;434.4299;44.89118;0;0;0;0.901518;0.8974785;398695.7;4.529588e+007
190;0.2863391;-0.1133344;431.8237;44.62187;0;0;0;0.9018554;0.897813;396303.8;4.50243e+007
195;0.2864462;-0.1161756;429.3124;44.36237;0;0;0;0.9021929;0.8981475;393999.2;4.476261e+007
200;0.2865534;-0.1151886;426.8256;44.1054;0;0;0;0.9025304;0.8984819;391716.8;4.450346e+007
205;0.286607;-0.1128022;424.5853;43.8739;0;0;0;0.9026991;0.8986491;389660.9;4.426995e+007
210;0.2867141;-0.1150205;423.0118;43.7113;0;0;0;0.9030365;0.8989835;388216.8;4.410603e+007
215;0.2867677;-0.1128242;421.0435;43.50792;0;0;0;0.9032052;0.8991507;386410.4;4.390088e+007
220;0.2883212;-0.1114466;426.2205;44.04287;0;0;0;0.9080983;0.9039999;391161.5;4.444282e+007
225;0.2965177;-0.1239306;455.2582;47.04345;0;0;0;0.9339139;0.9295799;417810.8;4.748279e+007
230;0.2979641;-0.1247619;455.4244;47.06061;0;0;0;0.9384696;0.9340933;417963.3;4.750226e+007
235;0.2988212;-0.1226943;455.8815;47.10785;0;0;0;0.9411693;0.9367678;418382.8;4.755122e+007
240;0.2996784;-0.1262713;456.1481;47.1354;0;0;0;0.9438689;0.9394424;418627.4;4.758029e+007
245;0.3005355;-0.1243716;457.0622;47.22985;0;0;0;0.9465685;0.9421167;419466.3;4.767692e+007
249.212;0.3011784;-0.1285517;457.1253;47.23638;0;0;0;0.9485933;0.9441224;419524.3;4.768446e+007
252.648;0.3006427;-0.1254548;452.5192;46.76041;0;0;0;0.946906;0.942451;415297;4.720318e+007
256.65;0.3012855;-0.1266335;453.9227;46.90544;1;1;0;0.9489308;0.9444567;416585.1;4.735054e+007
261.65;0.3021427;-0.1283391;455.4083;47.05896;1;1;0;0.9516305;0.947131;417948.5;4.750678e+007
266.65;0.3029462;-0.127018;455.9059;47.11037;1;1;0;0.9541613;0.949638;418405.2;4.755988e+007
271.65;0.3034284;-0.1284089;455.1533;47.0326;1;1;0;0.95568;0.9511422;417714.5;4.748209e+007
276.65;0.3035355;-0.1298194;453.4004;46.85147;1;1;0;0.9560174;0.9514764;416105.8;4.729938e+007
281.65;0.3035891;-0.1260788;451.7645;46.68242;1;1;0;0.9561861;0.9516436;414604.4;4.71288e+007
286.65;0.3036962;-0.1296002;450.3227;46.53344;1;1;0;0.9565236;0.9519778;413281.2;4.697854e+007
291.65;0.3044998;-0.129046;452.4146;46.7496;1;1;0;0.9590546;0.9544848;415201.1;4.719796e+007
296.65;0.305357;-0.1294484;453.1768;46.82836;1;1;0;0.9617542;0.9571588;415900.5;4.727873e+007
301.65;0.3058926;-0.132334;452.9406;46.80396;1;1;0;0.9634414;0.9588299;415683.8;4.725489e+007
306.65;0.3059998;-0.131393;451.0019;46.60362;1;1;0;0.9637789;0.9591641;413904.5;4.705277e+007
311.65;0.3059998;-0.1305835;448.8841;46.38479;1;1;0;0.9637789;0.9591641;411961;4.683183e+007
316.65;0.3069641;-0.1354508;451.8457;46.69082;1;1;0;0.9668161;0.9621723;414679;4.714223e+007
321.65;0.3077677;-0.1335305;452.3443;46.74234;1;1;0;0.9693469;0.9646789;415136.5;4.719543e+007
326.65;0.3085712;-0.1383555;452.7356;46.78278;1;1;0;0.9718779;0.9671855;415495.7;4.723745e+007
331.65;0.3092141;-0.1405467;452.3852;46.74656;1;1;0;0.9739026;0.9691908;415174.1;4.720183e+007
336.65;0.3092141;-0.139353;449.5329;46.45182;1;1;0;0.9739026;0.9691908;412556.3;4.690422e+007
341.65;0.3099641;-0.1436046;450.5425;46.55615;1;1;0;0.9762648;0.9715302;413482.9;4.701066e+007
346.65;0.3108212;-0.1454661;450.5103;46.55283;1;1;0;0.9789645;0.9742037;413453.4;4.700856e+007
351.65;0.3116783;-0.1469753;450.7912;46.58186;1;1;0;0.9816641;0.976877;413711.2;4.703913e+007
356.65;0.3125355;-0.1533306;450.5118;46.55297;1;1;0;0.9843637;0.9795504;413454.7;4.701123e+007
361.65;0.3132855;-0.1539827;449.8054;46.47998;1;1;0;0.9867259;0.9818896;412806.5;4.693862e+007
366.65;0.3141426;-0.1583008;449.2578;46.4234;1;1;0;0.9894256;0.9845629;412303.9;4.688272e+007
371.65;0.3149998;-0.1639279;448.3127;46.32573;1;1;0;0.9921254;0.9872362;411436.5;4.678534e+007
376.65;0.3158569;-0.1658795;446.7454;46.16378;1;1;0;0.9948249;0.9899091;409998.1;4.662303e+007
381.65;0.3167141;-0.17535;444.727;45.95521;1;1;0;0.9975246;0.9925822;408145.8;4.641363e+007
386.65;0.3208927;-0.1837485;455.6296;47.08182;1;1;0;1.010686;1.005612;418151.6;4.755767e+007
391.65;0.3234641;-0.1967561;457.1962;47.2437;1;1;0;1.018785;1.01363;419589.3;4.772501e+007
396.65;0.3243212;-0.2043736;453.323;46.84347;1;1;0;1.021484;1.016302;416034.7;4.732197e+007
401.65;0.3258212;-0.2125569;452.1771;46.72506;1;1;0;1.026209;1.020979;414983.1;4.720456e+007
406.65;0.3297855;-0.2297392;458.0596;47.33292;1;1;0;1.038695;1.033337;420381.8;4.782457e+007
411.65;0.3313927;-0.2424208;454.6749;46.98316;1;1;0;1.043756;1.038347;417275.4;4.747355e+007
416.65;0.3331069;-0.2525427;451.4066;46.64544;1;1;0;1.049156;1.04369;414275.9;4.713482e+007
421.65;0.3352498;-0.2740685;449.4862;46.447;1;1;0;1.055905;1.050369;412513.6;4.693744e+007
426.65;0.337714;-0.2865107;446.1776;46.10511;1;1;0;1.063666;1.058049;409477;4.659551e+007
431.65;0.3407141;-0.3112405;443.8453;45.86411;1;1;0;1.073115;1.067398;407336.7;4.635628e+007
436.65;0.3444641;-0.3338942;442.4655;45.72153;1;1;0;1.084926;1.079083;406070.3;4.621757e+007
441.65;0.3486426;-0.359669;441.1369;45.58424;1;1;0;1.098087;1.092102;404851;4.608479e+007
446.65;0.3544819;-0.3942701;444.1902;45.89975;1;1;0;1.116479;1.110292;407653.2;4.641221e+007
451.65;0.3628926;-0.433117;453.3403;46.84525;1;1;0;1.142969;1.136486;416050.6;4.738068e+007
456.65;0.3667497;-0.4685839;446.0447;46.09138;1;1;0;1.155117;1.148497;409355.1;4.662379e+007
461.65;0.3701783;-0.5001612;440.0162;45.46843;1;1;0;1.165916;1.159172;403822.5;4.599855e+007
466.65;0.3784283;-0.5408005;449.3971;46.4378;1;1;0;1.1919;1.184853;412431.8;4.699129e+007
471.65;0.3837855;-0.5799059;447.099;46.20033;1;1;0;1.208773;1.201526;410322.7;4.675878e+007
476.65;0.3876962;-0.6107105;441.2482;45.59574;1;1;0;1.22109;1.213695;404953.2;4.615251e+007
481.65;0.392839;-0.6513331;438.9626;45.35956;1;1;0;1.237288;1.229696;402855.5;4.592079e+007
486.65;0.3987319;-0.692912;439.429;45.40776;1;1;0;1.255849;1.248028;403283.6;4.597801e+007
491.65;0.4054283;-0.7344916;441.8527;45.6582;1;1;0;1.27694;1.268855;405507.9;4.624123e+007
496.65;0.4121783;-0.7819269;443.0312;45.77998;1;1;0;1.298199;1.289845;406589.5;4.63743e+007
501.65;0.4188211;-0.8230185;441.9208;45.66525;1;1;0;1.319122;1.310497;405570.5;4.626763e+007
506.65;0.4263748;-0.8746918;442.3817;45.71287;1;1;0;1.342913;1.333975;405993.4;4.632675e+007
511.65;0.4338212;-0.9167177;442.888;45.76519;1;1;0;1.366366;1.357115;406458.1;4.639051e+007
516.65;0.4414819;-0.9619457;443.9706;45.87706;1;1;0;1.390494;1.380915;407451.7;4.651498e+007
521.65;0.449464;-1.004232;449.1173;46.40889;1;1;0;1.415635;1.405708;412175;4.706587e+007
526.65;0.4573926;-1.044295;453.4778;46.85946;1;1;0;1.440606;1.430328;416176.8;4.753452e+007
531.65;0.4648925;-1.089395;456.674;47.18974;1;1;0;1.464229;1.453612;419110.1;4.788071e+007
536.65;0.4709461;-1.12026;455.9663;47.11661;1;1;0;1.483295;1.472402;418460.6;4.781549e+007
541.65;0.4767854;-1.160194;456.1931;47.14005;1;1;0;1.501686;1.490523;418668.7;4.784794e+007
546.65;0.4826247;-1.187633;458.6597;47.39493;1;1;0;1.520078;1.50864;420932.5;4.811537e+007
551.65;0.4874997;-1.219636;458.6769;47.39671;1;1;0;1.535432;1.523764;420948.2;4.812445e+007
556.65;0.492589;-1.25037;460.2472;47.55897;1;1;0;1.551461;1.539549;422389.3;4.829683e+007
561.65;0.4968211;-1.27666;458.4872;47.37711;1;1;0;1.564791;1.552674;420774.2;4.811846e+007
566.65;0.5009461;-1.305571;457.2758;47.25193;1;1;0;1.577783;1.565465;419662.4;4.799746e+007
571.65;0.5043211;-1.324449;455.9658;47.11656;1;1;0;1.588413;1.57593;418460.1;4.786496e+007
576.65;0.5076425;-1.350929;454.4886;46.96392;1;1;0;1.598874;1.586227;417104.5;4.771481e+007
581.65;0.510964;-1.370573;455.4454;47.06279;1;1;0;1.609335;1.596523;417982.6;4.782018e+007
586.65;0.5136425;-1.390578;454.5226;46.96743;1;1;0;1.617772;1.604825;417135.7;4.772726e+007
591.65;0.5161068;-1.408169;455.1835;47.03572;1;1;0;1.625533;1.612463;417742.2;4.780031e+007
596.65;0.5185711;-1.425104;456.1915;47.13988;1;1;0;1.633295;1.6201;418667.3;4.790982e+007
601.65;0.5210354;-1.43886;460.2078;47.5549;1;1;0;1.641056;1.627736;422353.2;4.83353e+007
606.65;0.5232854;-1.451446;463.1671;47.8607;1;1;0;1.648143;1.634708;425069.1;4.864951e+007
611.65;0.5241425;-1.463528;461.7983;47.71926;1;1;0;1.650843;1.637364;423812.9;4.850703e+007
616.65;0.5248925;-1.470612;460.8565;47.62193;1;1;0;1.653205;1.639688;422948.6;4.840922e+007
621.65;0.5257496;-1.482994;459.2635;47.45732;1;1;0;1.655904;1.642344;421486.6;4.824317e+007
626.65;0.5266068;-1.495389;458.2055;47.348;1;1;0;1.658604;1.645;420515.6;4.813331e+007
631.65;0.5274639;-1.505618;458.6744;47.39645;1;1;0;1.661304;1.647655;420945.9;4.818384e+007
636.65;0.5282139;-1.513451;459.5147;47.48328;1;1;0;1.663666;1.649979;421717.1;4.827324e+007
641.65;0.5283211;-1.517314;458.246;47.35218;1;1;0;1.664003;1.650311;420552.8;4.814012e+007
646.65;0.5284282;-1.526961;458.1083;47.33796;1;1;0;1.664341;1.650643;420426.4;4.812582e+007
651.65;0.5284818;-1.526924;457.7466;47.30058;1;1;0;1.66451;1.650808;420094.5;4.80879e+007
656.65;0.528589;-1.535178;458.2007;47.3475;1;1;0;1.664847;1.65114;420511.2;4.813576e+007
661.65;0.5286425;-1.537091;458.077;47.33472;1;1;0;1.665016;1.651306;420397.7;4.812285e+007
666.65;0.5287497;-1.540969;459.5508;47.48701;1;1;0;1.665353;1.651638;421750.3;4.827784e+007
671.65;0.5288568;-1.54616;460.695;47.60525;1;1;0;1.665691;1.65197;422800.4;4.839821e+007
676.65;0.5289104;-1.547482;462.1726;47.75793;1;1;0;1.665859;1.652136;424156.4;4.855351e+007
680.348;0.5289639;-1.549878;463.0736;47.85104;1;1;0;1.666028;1.652302;424983.3;4.864825e+007
685.348;0.5288568;-1.558188;463.8397;47.93019;1;1;0;1.665691;1.65197;425686.4;4.872857e+007
690.348;0.5283211;-1.557688;462.9231;47.83548;1;1;0;1.664003;1.650311;424845.2;4.863147e+007
695.348;0.5274639;-1.564597;460.3052;47.56497;1;1;0;1.661304;1.647655;422442.6;4.835516e+007
700.348;0.5266068;-1.562582;458.2448;47.35205;1;1;0;1.658604;1.645;420551.7;4.813744e+007
705.348;0.5257496;-1.566502;456.6594;47.18824;1;1;0;1.655904;1.642344;419096.7;4.796963e+007
710.348;0.5249996;-1.569012;455.4484;47.0631;1;1;0;1.653542;1.64002;417985.3;4.78413e+007
715.348;0.5241425;-1.569066;453.0256;46.81274;1;1;0;1.650843;1.637364;415761.8;4.758555e+007
720.348;0.5232854;-1.570635;452.1921;46.7266;1;1;0;1.648143;1.634708;414996.8;4.749673e+007
725.348;0.5224282;-1.570513;449.9884;46.4989;1;1;0;1.645443;1.632052;412974.4;4.726401e+007
730.348;0.5218925;-1.572769;450.7508;46.57768;1;1;0;1.643756;1.630393;413674.2;4.73433e+007
734.082;0.5218925;-1.574003;452.8877;46.79849;2;2;0;1.643756;1.630393;415635.2;4.756774e+007
739.082;0.5219997;-1.575794;456.2198;47.1428;2;2;0;1.644094;1.630725;418693.3;4.791788e+007
744.082;0.5221068;-1.578732;460.5704;47.59237;2;2;0;1.644431;1.631056;422686;4.837499e+007
747.442;0.5221604;-1.580505;463.2255;47.86673;2;2;0;1.6446;1.631223;425122.7;4.865395e+007
752.442;0.5221604;-1.584128;466.7872;48.23477;2;2;0;1.6446;1.631223;428391.4;4.902804e+007
757.442;0.5216783;-1.586994;468.0786;48.36822;2;2;0;1.643081;1.629729;429576.6;4.916295e+007
762.442;0.5208211;-1.586315;466.733;48.22918;2;2;0;1.640381;1.627072;428341.7;4.902032e+007
767.442;0.5199639;-1.587627;465.7821;48.13091;2;2;0;1.637682;1.624416;427469;4.891914e+007
772.442;0.5191068;-1.587954;465.3017;48.08128;2;2;0;1.634982;1.62176;427028.2;4.88674e+007
777.442;0.5170711;-1.585853;457.8078;47.3069;2;2;0;1.62857;1.615452;420150.6;4.807732e+007
782.442;0.5151425;-1.58769;451.6738;46.67305;2;2;0;1.622496;1.609474;414521.2;4.743032e+007
787.442;0.5150354;-1.586885;455.8729;47.10696;2;2;0;1.622159;1.609142;418374.9;4.787111e+007
792.442;0.5147139;-1.588995;459.1026;47.44069;2;2;0;1.621146;1.608146;421338.9;4.820978e+007
797.442;0.5138568;-1.589381;458.4626;47.37457;2;2;0;1.618447;1.605489;420751.6;4.81413e+007
802.442;0.5129996;-1.589747;458.4201;47.37017;2;2;0;1.615747;1.602833;420712.5;4.813555e+007
807.442;0.5121425;-1.592951;459.187;47.44942;2;2;0;1.613047;1.600176;421416.4;4.82148e+007
812.442;0.5113925;-1.593384;460.6322;47.59876;2;2;0;1.610685;1.597851;422742.7;4.836542e+007
817.442;0.5105354;-1.593792;461.3884;47.6769;2;2;0;1.607985;1.595194;423436.7;4.844353e+007
822.442;0.5096782;-1.593274;460.9009;47.62652;2;2;0;1.605286;1.592537;422989.3;4.839106e+007
827.442;0.5057139;-1.591992;443.1534;45.79261;2;2;0;1.5928;1.580248;406701.6;4.652199e+007
832.442;0.5020175;-1.589173;427.464;44.17137;2;2;0;1.581157;1.568787;392302.8;4.486979e+007
837.442;0.5012139;-1.589266;428.9965;44.32972;2;2;0;1.578627;1.566296;393709.2;4.502953e+007
842.442;0.5004639;-1.589071;430.44;44.47889;2;2;0;1.576264;1.56397;395034;4.518e+007
847.442;0.4996068;-1.589394;431.061;44.54306;2;2;0;1.573565;1.561313;395603.9;4.524398e+007
852.442;0.4987497;-1.589438;431.6152;44.60032;2;2;0;1.570865;1.558655;396112.5;4.530093e+007
857.442;0.4978925;-1.587074;430.6153;44.497;2;2;0;1.568165;1.555997;395194.8;4.519479e+007
862.442;0.4970889;-1.587979;429.7344;44.40597;2;2;0;1.565634;1.553505;394386.4;4.510121e+007
867.442;0.4962854;-1.586048;428.5524;44.28384;2;2;0;1.563104;1.551013;393301.7;4.497604e+007
872.442;0.4961782;-1.585773;431.8535;44.62495;2;2;0;1.562766;1.550681;396331.3;4.532234e+007
877.442;0.4961782;-1.585443;435.4434;44.99591;2;2;0;1.562766;1.550681;399625.9;4.569909e+007
882.442;0.4960711;-1.587527;438.3522;45.29649;2;2;0;1.562429;1.550348;402295.4;4.600421e+007
887.442;0.495964;-1.587259;441.3984;45.61126;2;2;0;1.562091;1.550016;405091;4.632375e+007
892.442;0.4958568;-1.588166;443.9718;45.87717;2;2;0;1.561754;1.549684;407452.7;4.659366e+007
897.442;0.4957497;-1.588557;446.7749;46.16683;2;2;0;1.561416;1.549352;410025.3;4.688769e+007
902.442;0.4957497;-1.589531;449.8116;46.48063;2;2;0;1.561416;1.549352;412812.2;4.720638e+007
907.442;0.4949997;-1.589119;447.9848;46.29185;2;2;0;1.559054;1.547026;411135.6;4.701357e+007
912.442;0.4941426;-1.58965;445.6058;46.04603;2;2;0;1.556355;1.544368;408952.3;4.676267e+007
917.442;0.4936068;-1.589795;445.2184;46.006;2;2;0;1.554667;1.542706;408596.8;4.672124e+007
922.442;0.4936068;-1.589598;449.0604;46.403;2;2;0;1.554667;1.542706;412122.8;4.712442e+007
927.442;0.4933925;-1.58992;450.2423;46.52513;2;2;0;1.553992;1.542041;413207.4;4.724813e+007
932.442;0.492964;-1.590198;450.6656;46.56887;2;2;0;1.552642;1.540712;413595.9;4.729192e+007
937.442;0.4925354;-1.590752;450.7636;46.579;2;2;0;1.551293;1.539383;413685.9;4.730158e+007
942.442;0.4921068;-1.591574;450.7255;46.57507;2;2;0;1.549943;1.538054;413650.9;4.729695e+007
947.442;0.4916783;-1.591309;450.9624;46.59954;2;2;0;1.548593;1.536725;413868.3;4.732118e+007
952.442;0.4912497;-1.59144;450.7575;46.57837;2;2;0;1.547243;1.535395;413680.2;4.729904e+007
957.442;0.4908211;-1.591464;450.6301;46.56521;2;2;0;1.545893;1.534066;413563.4;4.728506e+007
962.442;0.4903925;-1.591901;450.5263;46.55447;2;2;0;1.544543;1.532737;413468;4.727353e+007
967.442;0.489964;-1.592519;450.3802;46.53939;2;2;0;1.543194;1.531407;413334;4.725758e+007
972.442;0.4895354;-1.592364;450.4544;46.54705;2;2;0;1.541844;1.530078;413402.1;4.726473e+007
977.442;0.489214;-1.592685;450.5244;46.55429;2;2;0;1.540831;1.529081;413466.4;4.727161e+007
982.442;0.4886782;-1.593053;450.1963;46.52037;2;2;0;1.539144;1.527419;413165.2;4.723639e+007
987.442;0.4883568;-1.592938;450.209;46.52169;2;2;0;1.538132;1.526422;413176.9;4.723726e+007
992.4421;0.4880354;-1.593376;450.5042;46.5522;2;2;0;1.537119;1.525425;413447.8;4.726776e+007
997.4421;0.487714;-1.593488;450.698;46.57222;2;2;0;1.536107;1.524428;413625.6;4.728762e+007
1002.442;0.4874997;-1.593006;451.7677;46.68276;2;2;0;1.535432;1.523764;414607.4;4.739954e+007
1007.442;0.4872854;-1.59336;452.8351;46.79306;2;2;0;1.534757;1.523099;415587;4.751122e+007
1012.442;0.486964;-1.594311;452.8947;46.79922;2;2;0;1.533745;1.522102;415641.7;4.7517e+007
1017.442;0.4867497;-1.593878;453.5809;46.87012;2;2;0;1.53307;1.521437;416271.4;4.758868e+007
1022.442;0.4865354;-1.594274;454.7436;46.99026;2;2;0;1.532395;1.520772;417338.5;4.771034e+007
1027.442;0.486214;-1.594251;454.4451;46.95942;2;2;0;1.531383;1.519775;417064.5;4.767855e+007
1032.442;0.4857854;-1.594931;453.5849;46.87053;2;2;0;1.530033;1.518446;416275.1;4.758767e+007
1037.442;0.4853569;-1.594374;452.8712;46.79679;2;2;0;1.528683;1.517116;415620.1;4.751216e+007
1042.442;0.4849283;-1.594288;452.3456;46.74247;2;2;0;1.527333;1.515787;415137.7;4.745638e+007
1047.442;0.4844997;-1.593609;451.5248;46.65765;2;2;0;1.525983;1.514457;414384.4;4.736964e+007
1052.442;0.4840711;-1.59425;450.6358;46.56579;2;2;0;1.524634;1.513128;413568.6;4.727575e+007
1057.442;0.4836425;-1.593916;450.1275;46.51327;2;2;0;1.523284;1.511798;413102.1;4.722179e+007
1062.442;0.4832675;-1.593639;449.6989;46.46898;2;2;0;1.522102;1.510635;412708.8;4.717629e+007
1067.442;0.4828925;-1.59449;449.0469;46.40161;2;2;0;1.520921;1.509471;412110.4;4.710734e+007
1072.442;0.482464;-1.593785;448.2321;46.31741;2;2;0;1.519572;1.508142;411362.6;4.702123e+007
1077.442;0.4822497;-1.59345;448.5706;46.35239;2;2;0;1.518897;1.507477;411673.3;4.705643e+007
1082.442;0.4821426;-1.592773;449.7046;46.46957;2;2;0;1.518559;1.507145;412714;4.717524e+007
1087.442;0.4820354;-1.592532;450.7794;46.58063;2;2;0;1.518222;1.506812;413700.3;4.728783e+007
1092.442;0.4819283;-1.593826;451.7209;46.67792;2;2;0;1.517884;1.50648;414564.4;4.738643e+007
1097.442;0.4819283;-1.593058;453.2467;46.83559;2;2;0;1.517884;1.50648;415964.7;4.75465e+007
1102.442;0.4811783;-1.593202;449.4028;46.43838;2;2;0;1.515522;1.504153;412437;4.714216e+007
1107.442;0.4811783;-1.592915;450.7522;46.57782;2;2;0;1.515522;1.504153;413675.4;4.728372e+007
1112.442;0.4810711;-1.593701;452.0566;46.71261;2;2;0;1.515185;1.50382;414872.5;4.742039e+007
1117.442;0.480964;-1.593523;453.072;46.81754;2;2;0;1.514847;1.503488;415804.4;4.752675e+007
1122.442;0.4789283;-1.592388;441.8944;45.66251;2;2;0;1.508435;1.497172;405546.2;4.63513e+007
1127.442;0.478714;-1.592932;442.4705;45.72205;2;2;0;1.507761;1.496507;406074.9;4.641142e+007
1132.442;0.4784997;-1.593133;442.3649;45.71113;2;2;0;1.507086;1.495842;405978;4.640004e+007
1137.442;0.4781783;-1.592312;441.55;45.62693;2;2;0;1.506073;1.494845;405230.2;4.63141e+007
1142.442;0.477964;-1.591965;441.9167;45.66482;2;2;0;1.505398;1.49418;405566.7;4.635226e+007
1147.442;0.4777497;-1.592382;441.8502;45.65795;2;2;0;1.504724;1.493515;405505.7;4.634498e+007
1152.442;0.4774818;-1.591803;441.6815;45.64051;2;2;0;1.50388;1.492684;405350.8;4.632689e+007
1157.442;0.4771604;-1.59083;440.7878;45.54817;2;2;0;1.502867;1.491686;404530.7;4.62327e+007
1162.442;0.4770533;-1.592114;441.3087;45.60199;2;2;0;1.50253;1.491354;405008.6;4.628717e+007
1167.442;0.4769462;-1.59205;442.1075;45.68453;2;2;0;1.502193;1.491021;405741.8;4.63708e+007
1172.442;0.4768926;-1.59191;442.7593;45.75188;2;2;0;1.502024;1.490855;406339.9;4.643909e+007
1177.442;0.4767854;-1.591818;443.3506;45.81299;2;2;0;1.501686;1.490523;406882.6;4.650095e+007
1182.442;0.4766783;-1.592623;443.8701;45.86667;2;2;0;1.501349;1.49019;407359.4;4.655529e+007
1185.528;0.4766783;-1.59237;444.5279;45.93464;3;3;0;1.501349;1.49019;407963;4.662428e+007
1190.528;0.4768926;-1.591898;446.6596;46.15491;3;3;0;1.502024;1.490855;409919.4;4.684817e+007
1194.106;0.4770533;-1.592397;448.5014;46.34524;3;3;0;1.50253;1.491354;411609.8;4.704159e+007
1199.106;0.476839;-1.591617;447.9126;46.28439;3;3;0;1.501855;1.490689;411069.3;4.697952e+007
1204.106;0.4765711;-1.591527;447.3224;46.22341;3;3;0;1.501011;1.489858;410527.7;4.691723e+007
1209.106;0.476464;-1.592341;447.5987;46.25196;3;3;0;1.500674;1.489525;410781.3;4.694605e+007
1214.106;0.4763568;-1.592477;447.6739;46.25973;3;3;0;1.500337;1.489193;410850.3;4.695378e+007
1219.106;0.4763568;-1.592279;448.7423;46.37012;3;3;0;1.500337;1.489193;411830.8;4.706583e+007
1224.106;0.4762497;-1.590977;448.5263;46.34781;3;3;0;1.499999;1.48886;411632.6;4.704303e+007
1229.106;0.4761426;-1.590718;448.2324;46.31744;3;3;0;1.499662;1.488528;411362.9;4.701205e+007
1234.106;0.4760354;-1.59079;447.6264;46.25482;3;3;0;1.499324;1.488195;410806.7;4.694833e+007
1239.106;0.4760354;-1.590298;447.9148;46.28462;3;3;0;1.499324;1.488195;411071.3;4.697858e+007
1244.106;0.4759282;-1.58992;446.8498;46.17457;3;3;0;1.498987;1.487863;410094;4.686672e+007
1249.106;0.4758211;-1.589554;446.1998;46.1074;3;3;0;1.498649;1.48753;409497.4;4.679839e+007
1254.106;0.475714;-1.589058;445.3619;46.02083;3;3;0;1.498312;1.487198;408728.5;4.671036e+007
1259.106;0.4756068;-1.589827;444.4148;45.92295;3;3;0;1.497974;1.486865;407859.3;4.661086e+007
1262.34;0.4756068;-1.589807;444.6457;45.94681;4;4;0;1.497974;1.486865;408071.2;4.663508e+007
1267.34;0.4757676;-1.589889;444.9363;45.97684;4;4;0;1.49848;1.487364;408337.9;4.66658e+007
1272.34;0.4760354;-1.589929;446.141;46.10133;4;4;0;1.499324;1.488195;409443.5;4.679254e+007
1277.34;0.4763032;-1.590864;447.5037;46.24214;4;4;0;1.500168;1.489026;410694.1;4.693585e+007
1282.34;0.4765176;-1.590929;448.3856;46.33327;4;4;0;1.500843;1.489692;411503.4;4.702866e+007
1287.34;0.4767854;-1.590762;449.3998;46.43807;4;4;0;1.501686;1.490523;412434.2;4.713543e+007
1292.34;0.4770533;-1.591507;450.461;46.54773;4;4;0;1.50253;1.491354;413408.1;4.724712e+007
1295.578;0.4771068;-1.591153;449.9209;46.49192;4;4;0;1.502699;1.49152;412912.5;4.719056e+007
1300.578;0.4771068;-1.59088;449.1602;46.41332;4;4;0;1.502699;1.49152;412214.4;4.711077e+007
1305.578;0.4769997;-1.590666;448.1062;46.30439;4;4;0;1.502361;1.491188;411247;4.700005e+007
1310.578;0.4768926;-1.59099;446.6416;46.15306;4;4;0;1.502024;1.490855;409902.9;4.684629e+007
1315.578;0.476839;-1.591415;445.4835;46.03338;4;4;0;1.501855;1.490689;408840;4.672474e+007
1320.578;0.4767318;-1.591484;444.3326;45.91447;4;4;0;1.501518;1.490356;407783.9;4.660388e+007
1325.578;0.4766783;-1.591379;443.0458;45.78149;4;4;0;1.501349;1.49019;406602.9;4.646883e+007
1330.578;0.4765711;-1.5916;441.8038;45.65315;4;4;0;1.501011;1.489858;405463;4.633841e+007
1335.578;0.476464;-1.591554;440.4147;45.50961;4;4;0;1.500674;1.489525;404188.2;4.619256e+007
1340.578;0.4763568;-1.590991;439.1703;45.38102;4;4;0;1.500337;1.489193;403046.1;4.606189e+007
1345.578;0.4762497;-1.59189;437.7796;45.23732;4;4;0;1.499999;1.48886;401769.9;4.591588e+007
1350.578;0.4762497;-1.591151;436.6585;45.12147;4;4;0;1.499999;1.48886;400741;4.579829e+007
1355.578;0.4761426;-1.592477;434.8498;44.93457;4;4;0;1.499662;1.488528;399081.1;4.560844e+007
1360.578;0.4760354;-1.590213;433.4366;44.78854;4;4;0;1.499324;1.488195;397784.1;4.546007e+007
1365.578;0.4759282;-1.590424;431.5073;44.58918;4;4;0;1.498987;1.487863;396013.5;4.525757e+007
1370.578;0.4759282;-1.591619;430.3171;44.46619;4;4;0;1.498987;1.487863;394921.2;4.513273e+007
1375.578;0.4758211;-1.591537;428.4251;44.27068;4;4;0;1.498649;1.48753;393184.8;4.493415e+007
1380.578;0.475714;-1.591146;426.9574;44.11901;4;4;0;1.498312;1.487198;391837.8;4.478006e+007
1383.744;0.475714;-1.590856;425.9568;44.01562;5;5;0;1.498312;1.487198;390919.5;4.467511e+007
1388.744;0.4758211;-1.592339;425.1731;43.93464;5;5;0;1.498649;1.48753;390200.3;4.459307e+007
1393.744;0.4763568;-1.59164;427.127;44.13654;5;5;0;1.500337;1.489193;391993.5;4.479874e+007
1398.744;0.4771604;-1.592783;430.2993;44.46435;5;5;0;1.502867;1.491686;394904.8;4.513259e+007
1403.744;0.477964;-1.593074;433.4299;44.78785;5;5;0;1.505398;1.49418;397778;4.546208e+007
1408.744;0.4788211;-1.59437;436.8674;45.14306;5;5;0;1.508098;1.496839;400932.8;4.582386e+007
1413.744;0.4796783;-1.594103;439.5926;45.42466;5;5;0;1.510798;1.499499;403433.7;4.611093e+007
1418.744;0.4804818;-1.594044;442.7306;45.74892;5;5;0;1.513329;1.501992;406313.6;4.644125e+007
1423.744;0.481339;-1.594276;445.1561;45.99955;5;5;0;1.516028;1.504651;408539.6;4.669692e+007
1428.744;0.4821426;-1.594901;448.152;46.30914;5;5;0;1.518559;1.507145;411289.1;4.701237e+007
1433.744;0.4829997;-1.594423;450.8154;46.58435;5;5;0;1.521259;1.509804;413733.4;4.729302e+007
1437.024;0.4834283;-1.594983;451.9497;46.70156;5;5;0;1.522609;1.511133;414774.4;4.741264e+007
1442.024;0.4833211;-1.59484;449.1682;46.41414;5;5;0;1.522271;1.510801;412221.7;4.712069e+007
1447.024;0.4832675;-1.593367;447.1499;46.20558;5;5;0;1.522102;1.510635;410369.4;4.690887e+007
1452.024;0.4831604;-1.593397;444.8436;45.96727;5;5;0;1.521765;1.510302;408252.8;4.666678e+007
1457.024;0.4831069;-1.592783;443.2115;45.79861;5;5;0;1.521596;1.510136;406755;4.649548e+007
1460.93;0.4833211;-1.592313;443.3293;45.81079;6;6;0;1.522271;1.510801;406863.1;4.650815e+007
1465.93;0.4842854;-1.591853;447.0945;46.19986;6;6;0;1.525308;1.513793;410318.6;4.690455e+007
1470.93;0.485089;-1.591029;450.0042;46.50052;6;6;0;1.527839;1.516285;412988.9;4.721098e+007
1475.93;0.4858926;-1.590857;452.4612;46.75442;6;6;0;1.53037;1.518778;415243.8;4.746993e+007
1478.992;0.4858926;-1.590007;451.7232;46.67816;6;6;0;1.53037;1.518778;414566.6;4.739251e+007
1483.992;0.4858926;-1.588566;450.2609;46.52705;6;6;0;1.53037;1.518778;413224.5;4.723908e+007
1488.992;0.4857854;-1.586043;448.4225;46.33708;6;6;0;1.530033;1.518446;411537.3;4.704605e+007
1493.992;0.4856247;-1.58453;447.2988;46.22096;6;6;0;1.529527;1.517947;410506;4.692793e+007
1498.992;0.4856247;-1.581485;446.7109;46.16022;6;6;0;1.529527;1.517947;409966.5;4.686625e+007
1503.992;0.4855176;-1.579449;445.8273;46.06891;6;6;0;1.529189;1.517615;409155.6;4.677339e+007
1508.992;0.4854104;-1.578097;445.2978;46.0142;6;6;0;1.528852;1.517283;408669.7;4.671769e+007
1513.992;0.4853033;-1.574183;444.6514;45.9474;6;6;0;1.528514;1.51695;408076.4;4.664971e+007
1518.992;0.4853033;-1.572012;444.8731;45.97032;6;6;0;1.528514;1.51695;408279.9;4.667298e+007
1523.992;0.4851961;-1.569304;444.8921;45.97228;6;6;0;1.528177;1.516618;408297.3;4.667481e+007
1528.992;0.485089;-1.565356;445.5207;46.03723;6;6;0;1.527839;1.516285;408874.2;4.67406e+007
1533.992;0.4849819;-1.561926;446.2517;46.11277;6;6;0;1.527502;1.515953;409545.1;4.681715e+007
1538.992;0.4848747;-1.557111;448.2658;46.3209;6;6;0;1.527164;1.515621;411393.5;4.702829e+007
1543.992;0.4847676;-1.551895;450.8943;46.5925;6;6;0;1.526827;1.515288;413805.8;4.730389e+007
1548.992;0.4839104;-1.546844;450.9873;46.60211;6;6;0;1.524127;1.512629;413891.2;4.731239e+007
1553.992;0.4831604;-1.539535;452.5888;46.7676;6;6;0;1.521765;1.510302;415360.9;4.747929e+007
1558.992;0.4814461;-1.531087;450.5468;46.55659;6;6;0;1.516366;1.504984;413486.9;4.726256e+007
1563.992;0.479839;-1.522347;450.7704;46.5797;6;6;0;1.511304;1.499997;413692.1;4.728366e+007
1568.992;0.4781247;-1.513037;452.1128;46.71841;6;6;0;1.505905;1.494678;414924;4.742195e+007
1573.992;0.4765176;-1.503374;454.725;46.98834;6;6;0;1.500843;1.489692;417321.4;4.769356e+007
1578.992;0.4743747;-1.492841;456.1317;47.13371;6;6;0;1.494094;1.483042;418612.4;4.783793e+007
1583.992;0.4718033;-1.480883;457.4537;47.27031;6;6;0;1.485995;1.475062;419825.7;4.797274e+007
1588.992;0.4694461;-1.467089;462.0884;47.74923;6;6;0;1.47857;1.467746;424079.1;4.845524e+007
1593.992;0.4669819;-1.451107;469.2216;48.48632;6;6;0;1.470809;1.460098;430625.6;4.919947e+007
1598.992;0.4643033;-1.431462;478.3051;49.42496;6;6;0;1.462373;1.451783;438961.9;5.014774e+007
1603.992;0.459589;-1.404767;481.3872;49.74344;6;6;0;1.447524;1.437148;441790.5;5.046349e+007
1608.992;0.452839;-1.364938;479.578;49.55649;6;6;0;1.426265;1.416189;440130.1;5.02633e+007
1613.992;0.4461961;-1.319288;480.8294;49.68581;6;6;0;1.405342;1.395559;441278.6;5.038406e+007
1618.992;0.4394462;-1.264951;485.042;50.12111;6;6;0;1.384082;1.374591;445144.7;5.081483e+007
1623.992;0.4309819;-1.20479;483.7843;49.99114;6;6;0;1.357423;1.348293;443990.4;5.066973e+007
1628.992;0.4227319;-1.141008;482.7868;49.88807;6;6;0;1.331439;1.322653;443075;5.05523e+007
1633.992;0.4138926;-1.075555;479.2744;49.52512;6;6;0;1.303599;1.295175;439851.5;5.017073e+007
1638.992;0.3971783;-0.9931301;449.5199;46.45048;6;6;0;1.250955;1.243195;412544.4;4.703155e+007
1643.992;0.3817497;-0.9133334;428.1631;44.24361;6;6;0;1.202361;1.19519;392944.3;4.477557e+007
1648.992;0.3709819;-0.8468525;423.1221;43.72271;6;6;0;1.168447;1.161673;388318.1;4.423358e+007
1653.992;0.3625712;-0.7877708;425.3339;43.95126;6;6;0;1.141956;1.135485;390347.8;4.445316e+007
1658.992;0.3543212;-0.7281579;425.4836;43.96673;6;6;0;1.115972;1.109791;390485.3;4.445739e+007
1663.992;0.3459105;-0.664556;426.8076;44.10354;6;6;0;1.089482;1.08359;391700.4;4.458404e+007
1668.992;0.3376069;-0.5997333;428.1512;44.24238;6;6;0;1.063329;1.057715;392933.5;4.471283e+007
1673.992;0.3304283;-0.5402383;429.434;44.37494;6;6;0;1.040719;1.035341;394110.8;4.483676e+007
1678.992;0.3262498;-0.4950796;437.7384;45.23306;6;6;0;1.027558;1.022315;401732;4.569785e+007
1683.992;0.3220176;-0.4550707;441.5397;45.62586;6;6;0;1.014229;1.00912;405220.7;4.608861e+007
1688.992;0.3177855;-0.4156993;444.8105;45.96385;6;6;0;1.000899;0.9959234;408222.5;4.64239e+007
1693.992;0.3137141;-0.3790274;447.4604;46.23767;6;6;0;0.9880759;0.9832263;410654.4;4.669453e+007
1698.992;0.3095355;-0.3469739;446.883;46.17801;6;6;0;0.974915;0.9701933;410124.5;4.66282e+007
1703.992;0.3058391;-0.3164704;447.2895;46.22001;6;6;0;0.9632728;0.9586628;410497.5;4.666523e+007
1708.992;0.3025177;-0.2897449;447.4822;46.23992;6;6;0;0.9528116;0.948301;410674.3;4.66805e+007
1713.992;0.2991962;-0.2653448;446.6694;46.15593;6;6;0;0.9423503;0.9379379;409928.4;4.659088e+007
1718.992;0.2961962;-0.2435211;445.1673;46.00071;6;6;0;0.9329015;0.9285769;408549.9;4.642986e+007
1723.992;0.2936248;-0.226349;443.5829;45.83699;6;6;0;0.9248026;0.9205525;407095.8;4.626089e+007
1728.992;0.2920177;-0.2128986;443.5429;45.83286;6;6;0;0.9197407;0.9155369;407059.1;4.625441e+007
1733.992;0.2903034;-0.2006621;442.1294;45.6868;6;6;0;0.9143413;0.9101866;405761.9;4.610453e+007
1738.992;0.2891248;-0.191089;440.8285;45.55237;6;6;0;0.9106293;0.9065081;404568;4.596718e+007
1743.992;0.2882677;-0.1836487;439.8089;45.44701;6;6;0;0.9079297;0.9038328;403632.2;4.585964e+007
1748.992;0.2878391;-0.1787561;439.8761;45.45396;6;6;0;0.9065799;0.9024951;403693.9;4.586603e+007
1753.33;0.2875177;-0.173943;438.9305;45.35625;6;6;0;0.9055675;0.9014918;402826.1;4.576698e+007
1757.332;0.2877855;-0.1718033;440.3677;45.50475;7;7;0;0.9064111;0.9023278;404145.1;4.591721e+007
1762.332;0.2882141;-0.1685552;441.8502;45.65795;7;7;0;0.907761;0.9036656;405505.7;4.607241e+007
1767.332;0.2885891;-0.1660352;443.109;45.78802;7;7;0;0.908942;0.904836;406660.9;4.620421e+007
1772.332;0.2890712;-0.1618563;444.5821;45.94024;7;7;0;0.9104606;0.9063409;408012.8;4.635851e+007
1777.332;0.2894998;-0.1591245;445.6514;46.05074;7;7;0;0.9118105;0.9076786;408994.2;4.647063e+007
1782.332;0.2899284;-0.1567052;446.8154;46.17102;7;7;0;0.9131603;0.9090161;410062.4;4.659264e+007
1787.332;0.2902498;-0.1557026;445.8395;46.07018;7;7;0;0.9141727;0.9100194;409166.8;4.649134e+007
1792.332;0.2906784;-0.1538306;445.7292;46.05878;7;7;0;0.9155225;0.911357;409065.6;4.648046e+007
1797.332;0.291107;-0.1530864;445.4145;46.02626;7;7;0;0.9168723;0.9126946;408776.8;4.644826e+007
1802.332;0.2915355;-0.1513417;444.9163;45.97477;7;7;0;0.9182221;0.9140321;408319.5;4.639692e+007
1807.332;0.2919641;-0.150562;443.7707;45.8564;7;7;0;0.9195719;0.9153696;407268.1;4.627808e+007
1812.332;0.2923927;-0.1490421;443.0568;45.78263;7;7;0;0.9209219;0.9167072;406613;4.620425e+007
1817.332;0.2927677;-0.1486497;441.8117;45.65397;7;7;0;0.9221029;0.9178774;405470.3;4.607494e+007
1822.332;0.2932498;-0.1480139;441.0855;45.57893;7;7;0;0.9236215;0.9193822;404803.8;4.599991e+007
1827.332;0.2936248;-0.1468587;439.509;45.41602;7;7;0;0.9248026;0.9205525;403357;4.583603e+007
1832.332;0.294107;-0.1460709;437.6236;45.2212;7;7;0;0.9263211;0.9220571;401626.7;4.564009e+007
1837.332;0.294482;-0.1451297;435.1493;44.96552;7;7;0;0.9275022;0.9232273;399355.9;4.538258e+007
1842.332;0.2951248;-0.1449906;434.1967;44.86708;7;7;0;0.929527;0.9252334;398481.7;4.528413e+007
1847.332;0.2959284;-0.1446376;433.0927;44.753;7;7;0;0.9320579;0.927741;397468.5;4.517013e+007
1852.332;0.2973748;-0.1453415;435.6634;45.01865;7;7;0;0.9366136;0.9322546;399827.8;4.54403e+007
1857.332;0.2998927;-0.1467997;445.4838;46.03342;7;7;0;0.9445438;0.9401109;408840.4;4.646823e+007
1862.332;0.301607;-0.1474717;448.2179;46.31594;7;7;0;0.9499432;0.9454596;411349.5;4.675591e+007
1867.332;0.3019284;-0.1465954;442.1056;45.68434;7;7;0;0.9509555;0.9464624;405740;4.611878e+007
1872.332;0.3026784;-0.1468567;438.9546;45.35873;7;7;0;0.9533178;0.9488023;402848.2;4.579115e+007
1877.332;0.3034284;-0.1472841;436.2536;45.07962;7;7;0;0.95568;0.9511422;400369.3;4.551044e+007
1882.332;0.3047141;-0.1467837;437.7517;45.23443;7;7;0;0.9597294;0.9551532;401744.2;4.566856e+007
1887.332;0.3071784;-0.1482674;445.4891;46.03397;7;7;0;0.967491;0.9628407;408845.3;4.647934e+007
1892.332;0.3095355;-0.14968;453.121;46.82259;7;7;0;0.974915;0.9701933;415849.3;4.727907e+007
1897.332;0.3112498;-0.1492563;455.5118;47.06965;7;7;0;0.9803143;0.9755404;418043.5;4.753108e+007
1902.332;0.3125355;-0.1493288;455.1604;47.03333;7;7;0;0.9843637;0.9795504;417721;4.749631e+007
1907.332;0.3138212;-0.1489411;455.1319;47.03039;7;7;0;0.9884133;0.9835604;417694.8;4.749524e+007
1912.332;0.3151069;-0.1494344;454.8802;47.00438;7;7;0;0.9924628;0.9875702;417463.8;4.747088e+007
1917.332;0.3162855;-0.1490373;454.2219;46.93636;7;7;0;0.9961748;0.9912456;416859.7;4.740392e+007
1922.332;0.3175712;-0.1493321;454.2549;46.93977;7;7;0;1.000224;0.9952552;416890;4.740927e+007
1927.332;0.3188569;-0.1485019;453.9727;46.91061;7;7;0;1.004274;0.9992645;416631;4.738172e+007
1932.332;0.3200355;-0.1495617;453.1315;46.82368;7;7;0;1.007986;1.00294;415859;4.729566e+007
1937.332;0.3213212;-0.148449;453.0553;46.81581;7;7;0;1.012035;1.006949;415789.1;4.72896e+007
1942.332;0.3226069;-0.1486386;452.7514;46.7844;7;7;0;1.016085;1.010957;415510.1;4.725977e+007
1947.332;0.3237855;-0.1477002;451.2843;46.6328;7;7;0;1.019797;1.014632;414163.7;4.710836e+007
1952.332;0.3250712;-0.1473173;450.5926;46.56133;7;7;0;1.023846;1.01864;413528.9;4.703805e+007
1957.332;0.3263569;-0.146372;449.9111;46.49091;7;7;0;1.027896;1.022649;412903.5;4.696878e+007
1962.332;0.3278569;-0.1465749;450.6546;46.56773;7;7;0;1.03262;1.027325;413585.8;4.70486e+007
1967.332;0.3295712;-0.1461019;452.5336;46.7619;7;7;0;1.03802;1.032669;415310.3;4.72473e+007
1972.332;0.3311783;-0.145715;454.0546;46.91907;7;7;0;1.043081;1.037679;416706.2;4.740848e+007
1976.328;0.3306427;-0.1438126;443.2483;45.80241;7;7;0;1.041394;1.036009;406788.7;4.62794e+007
1981.328;0.3291426;-0.1414733;425.5184;43.97033;7;7;0;1.03667;1.031333;390517.3;4.442615e+007
1986.328;0.3283926;-0.1391288;415.1544;42.89938;7;7;0;1.034307;1.028995;381005.8;4.334309e+007
1989.782;0.3283926;-0.1381415;410.8407;42.45362;8;8;0;1.034307;1.028995;377046.8;4.289272e+007
1994.782;0.3284462;-0.1367174;405.2095;41.87173;8;8;0;1.034476;1.029162;371878.8;4.230489e+007
1999.782;0.3286069;-0.1344451;399.9963;41.33303;8;8;0;1.034982;1.029663;367094.4;4.176082e+007
2004.782;0.3290355;-0.1345207;396.323;40.95346;8;8;0;1.036332;1.030999;363723.3;4.137787e+007
2009.782;0.3293033;-0.1322334;391.97;40.50365;8;8;0;1.037176;1.031834;359728.3;4.092374e+007
2014.782;0.3306427;-0.1319619;394.5622;40.77151;8;8;0;1.041394;1.036009;362107.3;4.11961e+007
2019.782;0.3348212;-0.1334692;414.9263;42.8758;8;8;0;1.054555;1.049033;380796.3;4.332795e+007
2024.782;0.3390534;-0.1340248;433.3386;44.77841;8;8;0;1.067885;1.062223;397694.2;4.525659e+007
2029.782;0.3431783;-0.1360874;449.1367;46.41089;8;8;0;1.080877;1.075077;412192.8;4.691253e+007
2034.782;0.3441426;-0.1350508;445.5568;46.04096;8;8;0;1.083914;1.078082;408907.3;4.654001e+007
2039.782;0.3459641;-0.1334322;449.1617;46.41347;8;8;0;1.089651;1.083757;412215.8;4.691922e+007
2044.782;0.3486426;-0.1345553;455.4267;47.06086;8;8;0;1.098087;1.092102;417965.4;4.757762e+007
2049.782;0.3493926;-0.1338452;452.6936;46.77843;8;8;0;1.100449;1.094438;415457.1;4.72932e+007
2054.782;0.3502498;-0.1321291;451.1063;46.61441;8;8;0;1.103149;1.097109;414000.4;4.712864e+007
2059.782;0.3513212;-0.1310252;450.2838;46.52942;8;8;0;1.106524;1.100446;413245.5;4.704428e+007
2064.782;0.3537855;-0.131058;457.4701;47.27201;8;8;0;1.114285;1.108123;419840.8;4.779875e+007
2069.782;0.3556069;-0.1311573;460.3322;47.56775;8;8;0;1.120022;1.113796;422467.3;4.810052e+007
2074.782;0.356464;-0.1298893;458.7907;47.40847;8;8;0;1.122721;1.116466;421052.7;4.794073e+007
2079.782;0.3573212;-0.1277661;457.8177;47.30792;8;8;0;1.125421;1.119135;420159.7;4.784033e+007
2084.782;0.3580712;-0.1270638;456.3008;47.15118;8;8;0;1.127783;1.121471;418767.6;4.768294e+007
2089.782;0.3589283;-0.1263115;455.3663;47.05461;8;8;0;1.130483;1.124141;417909.9;4.758655e+007
2094.782;0.3597855;-0.1258566;455.0998;47.02707;8;8;0;1.133183;1.12681;417665.3;4.755997e+007
2099.782;0.3606426;-0.1236549;454.669;46.98256;8;8;0;1.135882;1.12948;417270;4.751622e+007
2104.782;0.3614998;-0.1230098;453.8703;46.90003;8;8;0;1.138582;1.132149;416537;4.743402e+007
2109.782;0.3622497;-0.1227786;453.4768;46.85936;8;8;0;1.140944;1.134484;416175.9;4.7394e+007
2114.782;0.3631069;-0.1220569;453.585;46.87054;8;8;0;1.143644;1.137154;416275.2;4.740657e+007
2119.782;0.3639641;-0.120381;453.7222;46.88472;8;8;0;1.146343;1.139823;416401.1;4.742218e+007
2124.782;0.3648212;-0.1195218;454.2137;46.93551;8;8;0;1.149043;1.142492;416852.2;4.747482e+007
2129.782;0.3656783;-0.1189795;454.3175;46.94624;8;8;0;1.151743;1.145161;416947.4;4.748694e+007
2134.782;0.3664819;-0.1187604;454.0822;46.92192;8;8;0;1.154274;1.147663;416731.5;4.746353e+007
2139.782;0.3672855;-0.1189294;454.5465;46.9699;8;8;0;1.156805;1.150165;417157.6;4.751325e+007
2144.782;0.3681426;-0.1178163;455.5683;47.07548;8;8;0;1.159504;1.152834;418095.3;4.762132e+007
2149.782;0.3689462;-0.116446;455.9776;47.11778;8;8;0;1.162035;1.155335;418471;4.76653e+007
2154.782;0.3696962;-0.1155745;456.1541;47.13601;8;8;0;1.164397;1.157671;418632.9;4.768487e+007
2159.782;0.3696962;-0.1144687;452.4237;46.75055;8;8;0;1.164397;1.157671;415209.4;4.729491e+007
2164.782;0.3698033;-0.1126048;449.6765;46.46666;8;8;0;1.164735;1.158004;412688.2;4.700788e+007
2169.782;0.370714;-0.1131867;451.4757;46.65259;8;8;0;1.167603;1.160839;414339.4;4.71973e+007
2174.782;0.3715176;-0.1123849;452.1811;46.72547;8;8;0;1.170134;1.163341;414986.7;4.727222e+007
2179.782;0.3723212;-0.1117395;453.7347;46.88602;8;8;0;1.172665;1.165843;416412.6;4.743583e+007
2184.782;0.3731783;-0.1113467;455.0873;47.02578;8;8;0;1.175365;1.168511;417653.9;4.75785e+007
2189.782;0.3753748;-0.113012;463.7598;47.92194;8;8;0;1.182283;1.175348;425613.1;4.848852e+007
2194.782;0.3773569;-0.1149508;470.3167;48.59949;8;8;0;1.188526;1.181518;431630.7;4.917711e+007
2198.592;0.3778926;-0.1148347;469.9748;48.56416;8;8;0;1.190213;1.183186;431316.8;4.914217e+007
2203.592;0.3769283;-0.1129108;461.1334;47.65055;8;8;0;1.187176;1.180184;423202.7;4.821624e+007
2208.592;0.3760712;-0.1102367;452.9512;46.80505;8;8;0;1.184476;1.177516;415693.5;4.735945e+007
2212.466;0.375964;-0.109658;450.4755;46.54922;9;9;0;1.184139;1.177183;413421.4;4.710043e+007
2217.466;0.3772497;-0.1103676;456.6759;47.18993;9;9;0;1.188188;1.181185;419111.8;4.775064e+007
2222.466;0.3785355;-0.1112652;460.7092;47.60671;9;9;0;1.192238;1.185187;422813.4;4.81743e+007
2227.466;0.3786426;-0.1107854;458.7005;47.39915;9;9;0;1.192575;1.18552;420969.9;4.796442e+007
2232.466;0.3786962;-0.1100949;456.1699;47.13765;9;9;0;1.192744;1.185687;418647.4;4.769988e+007
2237.466;0.3787498;-0.1104649;453.5566;46.86761;9;9;0;1.192913;1.185853;416249.1;4.74267e+007
2242.466;0.3788569;-0.1096735;451.4417;46.64907;9;9;0;1.19325;1.186187;414308.2;4.720571e+007
2247.466;0.3789105;-0.1101793;449.4747;46.44582;9;9;0;1.193419;1.186354;412503;4.700011e+007
2252.466;0.3790712;-0.1092195;447.8306;46.27592;9;9;0;1.193925;1.186854;410994.1;4.682842e+007
2257.466;0.379339;-0.109556;447.0921;46.19961;9;9;0;1.194769;1.187688;410316.3;4.675159e+007
2262.466;0.379714;-0.1095637;446.573;46.14597;9;9;0;1.19595;1.188855;409840;4.669786e+007
2267.466;0.3800355;-0.1116183;445.6932;46.05506;9;9;0;1.196962;1.189855;409032.6;4.660632e+007
2272.466;0.3805176;-0.1117443;445.9673;46.08338;9;9;0;1.198481;1.191356;409284.1;4.663568e+007
2277.466;0.3811069;-0.1127397;444.8087;45.96366;9;9;0;1.200337;1.19319;408220.8;4.651538e+007
2282.466;0.3817497;-0.1142734;445.0681;45.99046;9;9;0;1.202361;1.19519;408458.8;4.654343e+007
2287.466;0.3823926;-0.1152229;445.9564;46.08225;9;9;0;1.204386;1.197191;409274.1;4.663726e+007
2292.466;0.3831426;-0.116431;446.5124;46.13971;9;9;0;1.206748;1.199525;409784.4;4.66965e+007
2297.466;0.3838926;-0.1166309;448.3463;46.32921;9;9;0;1.209111;1.201859;411467.4;4.688938e+007
2302.466;0.3846426;-0.1173378;450.4942;46.55117;9;9;0;1.211473;1.204193;413438.7;4.711512e+007
2307.466;0.3850176;-0.1176883;450.612;46.56333;9;9;0;1.212654;1.20536;413546.7;4.712798e+007
2312.466;0.3856069;-0.1184141;451.2711;46.63144;9;9;0;1.21451;1.207194;414151.6;4.719778e+007
2317.466;0.3859283;-0.1187992;451.3735;46.64202;9;9;0;1.215522;1.208194;414245.6;4.720897e+007
2322.466;0.3862497;-0.1186674;451.7886;46.68491;9;9;0;1.216535;1.209194;414626.5;4.725285e+007
2327.466;0.3864641;-0.1188421;451.3793;46.64262;9;9;0;1.21721;1.209861;414250.9;4.721036e+007
2332.466;0.3866783;-0.1188248;452.2437;46.73195;9;9;0;1.217884;1.210528;415044.3;4.730109e+007
2337.466;0.3868926;-0.1194675;452.0361;46.71049;9;9;0;1.218559;1.211195;414853.7;4.727969e+007
2342.466;0.3871069;-0.1190699;452.5871;46.76743;9;9;0;1.219234;1.211861;415359.4;4.733763e+007
2347.466;0.387214;-0.1196321;452.4007;46.74816;9;9;0;1.219572;1.212195;415188.3;4.731829e+007
2352.466;0.3873212;-0.11968;452.2682;46.73447;9;9;0;1.219909;1.212528;415066.7;4.730459e+007
2357.466;0.3875355;-0.1204712;452.6282;46.77168;9;9;0;1.220584;1.213195;415397.1;4.734256e+007
2362.466;0.3876962;-0.121769;453.1284;46.82336;9;9;0;1.22109;1.213695;415856.1;4.739511e+007
2367.466;0.3878569;-0.1217091;453.1184;46.82233;9;9;0;1.221596;1.214195;415847;4.739431e+007
2372.466;0.3880712;-0.1226347;453.7966;46.89241;9;9;0;1.222272;1.214862;416469.3;4.746556e+007
2377.466;0.3881248;-0.1227519;453.3973;46.85115;9;9;0;1.22244;1.215029;416102.9;4.742387e+007
2382.466;0.3882319;-0.1225428;453.5761;46.86963;9;9;0;1.222778;1.215362;416267;4.744274e+007
2387.466;0.3882854;-0.1231906;453.0927;46.81967;9;9;0;1.222946;1.215529;415823.3;4.739225e+007
2392.466;0.3883926;-0.1232124;453.34;46.84522;9;9;0;1.223284;1.215862;416050.3;4.741827e+007
2395.666;0.3883926;-0.1233956;452.6082;46.76961;9;9;0;1.223284;1.215862;415378.7;4.734173e+007
2400.666;0.3839997;-0.1177918;421.617;43.56718;9;9;0;1.209448;1.202193;386936.8;4.40941e+007
2405.666;0.3755355;-0.1061203;374.3645;38.68441;9;9;0;1.182789;1.175849;343571;3.914197e+007
2410.666;0.3673391;-0.0944252;339.0204;35.03217;9;9;0;1.156973;1.150332;311134.1;3.543749e+007
2415.666;0.3588747;-0.08192739;305.9002;31.60975;9;9;0;1.130314;1.123974;280738.3;3.196704e+007
2420.666;0.3506783;-0.07098213;275.6166;28.48044;9;9;0;1.104499;1.098444;252945.7;2.879501e+007
2425.666;0.3422141;-0.0617307;246.5915;25.48117;9;9;0;1.07784;1.072072;226308;2.575581e+007
2430.666;0.3339641;-0.05275035;220.7943;22.81546;9;9;0;1.051855;1.046362;202632.8;2.305545e+007
2435.666;0.3256069;-0.04545826;195.7713;20.22974;9;9;0;1.025534;1.020311;179668;2.04372e+007
2440.666;0.3172498;-0.03942391;172.0526;17.7788;9;9;0;0.999212;0.9942528;157900.3;1.795645e+007
2445.666;0.3089462;-0.03343157;151.5477;15.65996;9;9;0;0.9730589;0.9683552;139082.1;1.581235e+007
2450.666;0.3006427;-0.02891834;133.0004;13.74341;9;9;0;0.946906;0.942451;122060.4;1.387354e+007
2455.666;0.2923391;-0.02412403;116.1948;12.00682;9;9;0;0.9207531;0.91654;106637.2;1.211738e+007
2460.666;0.2838748;-0.020252;101.6722;10.50615;9;9;0;0.8940939;0.8901206;93309.13;1.060009e+007
2465.666;0.2756784;-0.01679569;89.85569;9.285106;9;9;0;0.8682783;0.8645305;82464.57;9365727
2470.666;0.2671605;-0.01376888;79.52324;8.217419;9;9;0;0.8414505;0.8379301;72982.02;8286564
2475.666;0.2589641;-0.01066048;70.7835;7.31431;9;9;0;0.815635;0.8123267;64961.18;7373968
2480.666;0.250607;-0.008710608;63.14907;6.525417;9;9;0;0.7893133;0.7862145;57954.72;6576923
2485.666;0.2422498;-0.007716015;56.66581;5.855479;9;9;0;0.7629916;0.7600956;52004.74;5900156
2490.666;0.2339463;-0.006201516;51.29902;5.300909;9;9;0;0.7368387;0.7341373;47079.39;5339968
2495.666;0.2255891;-0.005650482;50.1055;5.177579;9;9;0;0.710517;0.7080047;45984.05;5214366
2500.666;0.2172856;-0.004306766;49.798;5.145803;9;9;0;0.684364;0.6820329;45701.84;5181019
2502.444;0.2143927;-0.00441428;49.77967;5.14391;9;9;0;0.6752526;0.672983;45685.02;5178644