File: Ensayos/Resistencia/comp/Clavo6/Clavo6c.raw
"Test Type";"Manual"
"Method Name:";"C:\INSTRON\user\template\CYCLE.MTM"
"Name:";""
"Operator ID:";""
"Company:";""
"Lab name:";""
"Test date:";"06/06/2017"
"Temperature:";""
"Humidity:";""
"Note 1:";""
"Note 2:";""
"Note 3:";""
"Geometry:";"Rectangular"
"Specimen";1
"Specimen name:";""
"Width:";0.250000;"in"
"Thickness:";0.060000;"in"
"Length:";1.250000;"in"
"Diameter:";0.039370;"in"
"Inner diameter:";0.019685;"in"
"Outer diameter:";0.039370;"in"
"Wall thickness:";0.019685;"in"
"Area:";0.015000;"in*in"
"Linear density:";1.000000;"den"
"Sled weight:";2.204623;"lbf"
"Loading span:";0.000000;"mm"
"Support span:";1.000000;"mm"
"Span ratio:";"2"
"Fixture type:";"3-point"
"Comment:";""
"Included"
"Final Width:";0.250000;"in"
"Final Thickness:";0.060000;"in"
"Final Length:";1.250000;"in"
"Final Diameter:";0.039370;"in"
"Final Inner diameter:";0.019685;"in"
"Final Outer diameter:";0.039370;"in"
"Final Wall thickness:";0.019685;"in"
"Final Area:";0.015000;"in*in"
"Final Linear density:";1.000000;"den"
"Time sec";"Extension mm";"Strain 1 %";"Load N";"Stress MPa";"Cycle Count ";"Total Cycle Count ";"Repetitions Count ";"Strain [Exten.] %";"True strain %";"Tenacity gf/tex";"True stress Pa"
0;-2.021249;-0.01910349;8.682603;0.8972041;0;0;0;-6.366139;-6.57781;7968.412;840086.9
5;-2.021088;-0.01813885;8.721981;0.9012731;0;0;0;-6.365633;-6.57727;8004.55;843901.4
10;-2.021088;-0.01774916;8.765411;0.9057609;0;0;0;-6.365633;-6.57727;8044.409;848103.5
15;-2.020927;-0.01805698;8.625078;0.8912598;0;0;0;-6.365126;-6.576729;7915.619;834530
20;-2.020874;-0.01796294;8.761594;0.9053665;0;0;0;-6.364957;-6.576548;8040.905;847740.3
25;-2.020767;-0.01844565;8.521686;0.880576;0;0;0;-6.36462;-6.576189;7820.731;824530.7
30;-2.020713;-0.01857489;8.662371;0.8951135;0;0;0;-6.364451;-6.576008;7949.844;838144.4
35;-2.02066;-0.0179728;8.654266;0.894276;0;0;0;-6.364283;-6.575828;7942.406;837361.7
40;-2.020553;-0.01836868;8.511878;0.8795624;0;0;0;-6.363945;-6.575468;7811.729;823587.6
45;-2.020445;-0.0172145;8.736428;0.902766;0;0;0;-6.363607;-6.575107;8017.81;845317.5
50;-2.020392;-0.01718795;8.763179;0.9055303;0;0;0;-6.363439;-6.574927;8042.36;847907.5
55;-2.020285;-0.01736061;8.519983;0.8804;0;0;0;-6.363101;-6.574567;7819.168;824379.2
60;-2.020178;-0.01808067;8.597886;0.88845;0;0;0;-6.362764;-6.574206;7890.664;831920.1
65;-2.020124;-0.01713564;8.824697;0.9118872;0;0;0;-6.362596;-6.574026;8098.818;853867.5
70;-2.020017;-0.01692872;8.684658;0.8974165;0;0;0;-6.362258;-6.573666;7970.298;840320.5
75;-2.019963;-0.01737275;8.657232;0.8945825;0;0;0;-6.36209;-6.573486;7945.128;837668.3
80;-2.019802;-0.01779376;8.792543;0.9085646;0;0;0;-6.361583;-6.572944;8069.309;850765.5
85.00001;-2.019802;-0.01675316;8.640553;0.8928589;0;0;0;-6.361583;-6.572944;7929.821;836059
90.00001;-2.019749;-0.01795311;8.894057;0.9190544;0;0;0;-6.361414;-6.572764;8162.472;860589.5
95.00001;-2.019642;-0.01699231;8.764383;0.9056548;0;0;0;-6.361077;-6.572404;8043.465;848045.4
100;-2.019588;-0.0173354;8.622112;0.8909534;0;0;0;-6.360908;-6.572224;7912.896;834280.6
105;-2.019428;-0.01762822;8.764295;0.9056457;0;0;0;-6.360402;-6.571684;8043.384;848042.9
110;-2.019428;-0.016999;8.770314;0.9062676;0;0;0;-6.360402;-6.571684;8048.909;848625.4
115;-2.019321;-0.01727816;8.712877;0.9003325;0;0;0;-6.360065;-6.571323;7996.196;843070.7
120;-2.019213;-0.01713737;8.871299;0.9167027;0;0;0;-6.359727;-6.570963;8141.586;858402.9
125;-2.01916;-0.0168992;8.705419;0.8995618;0;0;0;-6.359558;-6.570783;7989.352;842353.6
130;-2.019053;-0.01743031;8.720806;0.9011518;0;0;0;-6.359221;-6.570422;8003.473;843845.5
135;-2.018999;-0.01694532;8.603407;0.8890205;0;0;0;-6.359052;-6.570242;7895.73;832487.2
140;-2.018892;-0.01658257;8.657555;0.8946158;0;0;0;-6.358715;-6.569882;7945.424;837729.8
145;-2.018785;-0.01684188;8.703188;0.8993312;0;0;0;-6.358377;-6.569522;7987.303;842148.3
150;-2.018731;-0.01712499;8.70815;0.899844;0;0;0;-6.358209;-6.569342;7991.858;842630
155;-2.018678;-0.01665524;8.531083;0.881547;0;0;0;-6.35804;-6.569161;7829.355;825497.9
160;-2.01857;-0.01723924;8.581502;0.886757;0;0;0;-6.357702;-6.5688;7875.626;830379.6
165;-2.018463;-0.01640024;8.888448;0.9184748;0;0;0;-6.357365;-6.56844;8157.325;860084
170;-2.018356;-0.01677403;8.60235;0.8889112;0;0;0;-6.357028;-6.56808;7894.76;832402.9
175;-2.018303;-0.01664377;8.741655;0.9033062;0;0;0;-6.356859;-6.5679;8022.607;845884.3
180;-2.018196;-0.01677661;8.97939;0.9278721;0;0;0;-6.356521;-6.567539;8240.786;868891.7
185;-2.018142;-0.01722616;8.911675;0.920875;0;0;0;-6.356353;-6.567359;8178.642;862340.9
190;-2.018035;-0.01665278;8.771783;0.9064194;0;0;0;-6.356015;-6.566999;8050.256;848807.2
195;-2.017927;-0.01608823;9.066808;0.9369053;0;0;0;-6.355677;-6.566638;8321.014;877358.7
200;-2.017874;-0.01691655;8.807079;0.9100666;0;0;0;-6.355508;-6.566458;8082.649;852227.3
205;-2.017767;-0.01670712;8.784174;0.9076998;0;0;0;-6.355171;-6.566098;8061.628;850013.9
210;-2.017713;-0.01673813;8.926386;0.9223951;0;0;0;-6.355002;-6.565917;8192.143;863776.9
215;-2.01766;-0.01686588;8.739511;0.9030846;0;0;0;-6.354834;-6.565737;8020.639;845695.1
220;-2.017553;-0.01678546;8.86246;0.9157894;0;0;0;-6.354496;-6.565377;8133.475;857595.6
225;-2.017446;-0.01665908;8.968407;0.9267372;0;0;0;-6.354159;-6.565017;8230.707;867850.9
230;-2.017392;-0.01629731;8.772399;0.9064831;0;0;0;-6.35399;-6.564836;8050.822;848885.2
235;-2.017285;-0.01691283;8.796801;0.9090046;0;0;0;-6.353652;-6.564476;8073.217;851249.6
240;-2.017178;-0.01675015;9.125096;0.9429285;0;0;0;-6.353315;-6.564116;8374.508;883021.3
245;-2.017124;-0.0163661;8.991429;0.9291162;0;0;0;-6.353147;-6.563936;8251.835;870088.1
250;-2.017071;-0.01716317;8.78946;0.908246;0;0;0;-6.352978;-6.563755;8066.479;850545.4
255;-2.016963;-0.01626156;8.744297;0.9035792;0;0;0;-6.352641;-6.563395;8025.032;846178.1
260;-2.016856;-0.0164632;9.023818;0.932463;0;0;0;-6.352304;-6.563035;8281.561;873230.2
265;-2.016749;-0.01646496;8.864428;0.9159927;0;0;0;-6.351965;-6.562674;8135.28;857809.1
270;-2.016749;-0.01563082;8.681487;0.8970888;0;0;0;-6.351965;-6.562674;7967.388;840106
275;-2.016642;-0.01584106;8.820704;0.9114745;0;0;0;-6.351628;-6.562314;8095.153;853581.1
280;-2.016535;-0.01605284;8.90081;0.9197522;0;0;0;-6.35129;-6.561954;8168.67;861336.1
285;-2.016428;-0.01588124;8.896464;0.9193031;0;0;0;-6.350953;-6.561593;8164.682;860918.6
290;-2.016428;-0.01627636;8.966704;0.9265613;0;0;0;-6.350953;-6.561593;8229.145;867715.8
295;-2.016321;-0.01621258;9.174076;0.9479898;0;0;0;-6.350616;-6.561233;8419.459;887786.6
300;-2.016213;-0.01661707;9.22238;0.9529812;0;0;0;-6.350278;-6.560873;8463.789;892464.2
305;-2.016106;-0.01639065;8.928443;0.9226076;0;0;0;-6.349941;-6.560512;8194.03;864022.5
310;-2.015999;-0.01633212;8.962887;0.9261668;0;0;0;-6.349603;-6.560152;8225.641;867358.9
315;-2.015999;-0.01554578;9.009723;0.9310066;0;0;0;-6.349603;-6.560152;8268.624;871891.3
320;-2.015892;-0.0160389;8.895143;0.9191666;0;0;0;-6.349266;-6.559792;8163.469;860806.3
325;-2.015785;-0.0166249;9.268747;0.9577724;0;0;0;-6.348928;-6.559432;8506.343;896964.1
330;-2.015678;-0.01638348;9.008313;0.9308609;0;0;0;-6.348591;-6.559072;8267.331;871764.4
335;-2.015678;-0.01615021;9.004378;0.9304543;0;0;0;-6.348591;-6.559072;8263.72;871383.5
340;-2.01557;-0.01575191;9.022496;0.9323265;0;0;0;-6.348253;-6.55871;8280.347;873140
345;-2.015463;-0.01645204;8.950524;0.9248894;0;0;0;-6.347916;-6.55835;8214.296;866178.2
350;-2.015356;-0.01624892;8.725446;0.9016312;0;0;0;-6.347579;-6.55799;8007.731;844399.5
355;-2.015249;-0.01649617;9.176748;0.9482659;0;0;0;-6.347241;-6.55763;8421.91;888077.1
360;-2.015249;-0.01585571;9.005876;0.9306091;0;0;0;-6.347241;-6.55763;8265.095;871541.1
365;-2.015142;-0.01575234;8.867775;0.9163386;0;0;0;-6.346904;-6.55727;8138.353;858179.5
370;-2.015035;-0.01628337;8.89206;0.918848;0;0;0;-6.346566;-6.556909;8160.64;860532.7
375;-2.014981;-0.01600089;9.003262;0.930339;0;0;0;-6.346398;-6.556729;8262.695;871296
380;-2.014874;-0.0156803;9.165149;0.9470673;0;0;0;-6.346059;-6.556368;8411.267;886965.9
385;-2.01482;-0.01508053;9.223203;0.9530662;0;0;0;-6.345891;-6.556188;8464.544;892585.6
390;-2.014713;-0.0154062;9.102103;0.9405525;0;0;0;-6.345553;-6.555828;8353.406;880869.3
395;-2.014606;-0.01561425;8.975601;0.9274806;0;0;0;-6.345216;-6.555468;8237.31;868630
400;-2.014553;-0.01491973;9.103425;0.9406891;0;0;0;-6.345047;-6.555288;8354.619;881002
405;-2.014445;-0.01551152;8.938338;0.9236301;0;0;0;-6.34471;-6.554927;8203.111;865028.4
410;-2.014392;-0.01575238;8.956573;0.9255145;0;0;0;-6.344542;-6.554747;8219.847;866794.8
415;-2.014285;-0.01549903;9.095878;0.9399093;0;0;0;-6.344204;-6.554387;8347.693;880279.5
420;-2.014178;-0.01535017;9.022819;0.9323599;0;0;0;-6.343866;-6.554026;8280.644;873212.2
425;-2.01407;-0.01463145;8.958424;0.9257056;0;0;0;-6.343529;-6.553666;8221.545;866983.2
430;-2.01407;-0.01511831;9.080991;0.9383709;0;0;0;-6.343529;-6.553666;8334.03;878845.1
435;-2.013963;-0.0147998;9.044726;0.9346235;0;0;0;-6.343192;-6.553306;8300.748;875338.6
440;-2.013856;-0.01490132;9.311032;0.9621419;0;0;0;-6.342854;-6.552946;8545.149;901114.6
445;-2.013856;-0.01479413;8.959803;0.9258482;0;0;0;-6.342854;-6.552946;8222.811;867123
450;-2.013749;-0.01473653;9.08428;0.9387107;0;0;0;-6.342517;-6.552586;8337.049;879172.9
455;-2.013642;-0.01371876;9.279436;0.9588769;0;0;0;-6.342179;-6.552225;8516.151;898063.2
460;-2.013535;-0.01523674;9.020734;0.9321444;0;0;0;-6.341842;-6.551864;8278.73;873029.3
465;-2.013481;-0.01412328;9.050686;0.9352395;0;0;0;-6.341673;-6.551684;8306.219;875929.6
470;-2.013374;-0.01436364;9.098139;0.9401429;0;0;0;-6.341336;-6.551325;8349.769;880525.3
475;-2.01332;-0.01429289;9.015067;0.9315588;0;0;0;-6.341167;-6.551144;8273.529;872487.1
480;-2.013213;-0.01357895;9.060671;0.9362712;0;0;0;-6.340829;-6.550784;8315.382;876903.8
485;-2.01316;-0.01404181;9.187906;0.9494188;0;0;0;-6.340661;-6.550604;8432.151;889219.4
490;-2.012999;-0.01433408;9.212543;0.9519647;0;0;0;-6.340155;-6.550063;8454.762;891608.6
495;-2.012999;-0.01391589;9.028075;0.932903;0;0;0;-6.340155;-6.550063;8285.468;873755.5
500;-2.012892;-0.01275549;9.057558;0.9359495;0;0;0;-6.339817;-6.549703;8312.524;876612
505;-2.012838;-0.0143672;9.207493;0.9514428;0;0;0;-6.339648;-6.549523;8450.127;891124.7
510;-2.012731;-0.01401452;9.110942;0.9414659;0;0;0;-6.339311;-6.549163;8361.518;881783.4
515;-2.012678;-0.01376195;9.126975;0.9431226;0;0;0;-6.339142;-6.548983;8376.231;883336.7
520;-2.012571;-0.01249603;9.230103;0.9537792;0;0;0;-6.338805;-6.548622;8470.877;893321
525;-2.012463;-0.01272894;9.036562;0.93378;0;0;0;-6.338467;-6.548261;8293.256;874592.6
530;-2.01241;-0.01376911;9.035476;0.9336677;0;0;0;-6.338298;-6.548081;8292.259;874489.1
535;-2.012303;-0.0129058;9.087539;0.9390476;0;0;0;-6.337961;-6.547721;8340.04;879531.1
540;-2.012249;-0.01322841;8.995658;0.9295532;0;0;0;-6.337792;-6.547541;8255.716;870640
545;-2.012142;-0.01240061;9.191078;0.9497467;0;0;0;-6.337455;-6.547181;8435.063;889556.9
550;-2.012088;-0.01287154;8.982531;0.9281967;0;0;0;-6.337286;-6.547001;8243.669;869374.3
555;-2.011981;-0.01293203;9.19513;0.9501653;0;0;0;-6.336949;-6.546641;8438.781;889953.9
560;-2.011874;-0.01246709;9.101663;0.9405071;0;0;0;-6.336611;-6.546279;8353.002;880910.8
565;-2.01182;-0.0125479;9.043815;0.9345294;0;0;0;-6.336442;-6.546099;8299.912;875313.5
570;-2.011713;-0.01292576;9.143625;0.9448432;0;0;0;-6.336105;-6.54574;8391.513;884976.9
575;-2.01166;-0.01186915;8.960332;0.9259028;0;0;0;-6.335936;-6.545559;8223.297;867238.2
580;-2.011553;-0.01235288;9.091856;0.9394936;0;0;0;-6.335598;-6.545199;8344.001;879971.1
585;-2.011445;-0.01163177;9.159658;0.9464999;0;0;0;-6.335261;-6.544839;8406.227;886536.7
590;-2.011392;-0.01166713;9.11106;0.9414781;0;0;0;-6.335093;-6.544659;8361.626;881834.6
595;-2.011285;-0.01160597;9.072563;0.9375001;0;0;0;-6.334755;-6.544299;8326.296;878111.7
600;-2.011178;-0.01089563;9.053446;0.9355246;0;0;0;-6.334417;-6.543938;8308.752;876264.6
605;-2.01107;-0.0116961;9.279406;0.9588739;0;0;0;-6.33408;-6.543578;8516.125;898138
610;-2.01107;-0.01164516;9.109914;0.9413597;0;0;0;-6.33408;-6.543578;8360.574;881733.2
615;-2.010963;-0.01115215;9.115142;0.9418998;0;0;0;-6.333743;-6.543218;8365.372;882242.3
620;-2.010856;-0.01018027;9.007374;0.9307638;0;0;0;-6.333405;-6.542858;8266.469;871814.8
625;-2.010803;-0.0105124;9.022819;0.9323599;0;0;0;-6.333237;-6.542678;8280.644;873311.3
630;-2.010696;-0.0105642;9.161977;0.9467396;0;0;0;-6.3329;-6.542317;8408.355;886783.5
635;-2.010642;-0.009381087;8.952492;0.9250926;0;0;0;-6.33273;-6.542136;8216.101;866509
640;-2.010535;-0.009519453;8.912292;0.9209387;0;0;0;-6.332393;-6.541776;8179.208;862621.2
645.0001;-2.010481;-0.009831616;9.154431;0.9459597;0;0;0;-6.332224;-6.541596;8401.43;886059.5
650.0001;-2.010374;-0.0106259;9.092031;0.9395118;0;0;0;-6.331887;-6.541236;8344.162;880022.9
655.0001;-2.010267;-0.009180704;9.049277;0.9350939;0;0;0;-6.331549;-6.540876;8304.925;875887.9
660.0001;-2.010213;-0.008989405;9.383738;0.9696549;0;0;0;-6.331381;-6.540696;8611.875;908262.3
665.0001;-2.01016;-0.009161402;9.061111;0.9363166;0;0;0;-6.331212;-6.540516;8315.785;877036.4
670.0001;-2.009999;-0.009337667;9.013804;0.9314283;0;0;0;-6.330706;-6.539975;8272.37;872462.3
675.0001;-2.009999;-0.008640556;9.063754;0.9365897;0;0;0;-6.330706;-6.539975;8318.211;877297
680.0001;-2.009892;-0.009209012;9.08469;0.9387532;0;0;0;-6.330368;-6.539615;8337.425;879326.6
685.0001;-2.009785;-0.01076568;9.217329;0.9524593;0;0;0;-6.330031;-6.539255;8459.154;892168.3
690.0001;-2.009785;-0.01112667;9.197186;0.9503778;0;0;0;-6.330031;-6.539255;8440.667;890218.5
695.0001;-2.009678;-0.01215086;9.149498;0.94545;0;0;0;-6.329693;-6.538895;8396.902;885605.9
700.0001;-2.009571;-0.01224964;9.028017;0.932897;0;0;0;-6.329356;-6.538535;8285.414;873850.6
705.0001;-2.009463;-0.01317078;9.233891;0.9541707;0;0;0;-6.329019;-6.538174;8474.354;893781
710.0001;-2.009356;-0.01593256;9.115905;0.9419787;0;0;0;-6.328681;-6.537813;8366.072;882363.9
715.0001;-2.009249;-0.01870202;9.334816;0.9645996;0;0;0;-6.328343;-6.537453;8566.978;903556.5
720.0001;-2.009249;-0.02406467;9.09532;0.9398516;0;0;0;-6.328343;-6.537453;8347.181;880374.6
725.0001;-2.009142;-0.03169852;9.228811;0.9536456;0;0;0;-6.328006;-6.537093;8469.691;893298.9
730.0001;-2.009035;-0.04150514;9.131938;0.9436355;0;0;0;-6.327669;-6.536733;8380.786;883925.3
735.0001;-2.008928;-0.05325169;9.208462;0.951543;0;0;0;-6.327332;-6.536373;8451.016;891335.7
740.0001;-2.008928;-0.06504526;9.254211;0.9562704;0;0;0;-6.327332;-6.536373;8493.002;895764
745.0001;-2.00882;-0.08024844;9.25794;0.9566557;0;0;0;-6.326993;-6.536012;8496.425;896128.2
750.0001;-2.008713;-0.1012107;9.314614;0.9625121;0;0;0;-6.326656;-6.535652;8548.437;901617.2
755.0001;-2.00866;-0.1207638;9.328063;0.9639018;0;0;0;-6.326487;-6.535472;8560.779;902920.6
760.0001;-2.008553;-0.1457322;9.183707;0.948985;0;0;0;-6.32615;-6.535112;8428.298;888950.8
765.0001;-2.008499;-0.17472;9.34483;0.9656344;0;0;0;-6.325981;-6.534931;8576.167;904548.5
770.0001;-2.008392;-0.2022957;9.183003;0.9489122;0;0;0;-6.325644;-6.534571;8427.651;888887.4
775.0001;-2.008285;-0.2336471;9.118283;0.9422244;0;0;0;-6.325306;-6.534211;8368.255;882625.9
780.0001;-2.008178;-0.2621935;9.146738;0.9451648;0;0;0;-6.324969;-6.533851;8394.369;885383.4
785.0001;-2.008178;-0.287433;9.118959;0.9422943;0;0;0;-6.324969;-6.533851;8368.875;882694.5
790.0001;-2.00807;-0.3120748;9.248749;0.955706;0;0;0;-6.324631;-6.533491;8487.989;895261.1
795.0001;-2.007963;-0.3323177;9.224407;0.9531906;0;0;0;-6.324294;-6.53313;8465.649;892908
800.0001;-2.007856;-0.3528796;9.151641;0.9456715;0;0;0;-6.323956;-6.53277;8398.869;885867.6
805.0001;-2.007749;-0.3733275;9.182885;0.9489;0;0;0;-6.323619;-6.53241;8427.543;888895.2
810.0001;-2.007696;-0.3945899;9.051244;0.9352971;0;0;0;-6.323451;-6.53223;8306.73;876154.1
815.0001;-2.007642;-0.4097618;9.052947;0.9354731;0;0;0;-6.323282;-6.53205;8308.293;876320.5
820.0001;-2.007588;-0.4260485;9.255709;0.9564251;0;0;0;-6.323112;-6.531869;8494.377;895949.3
825.0001;-2.007481;-0.4440368;9.059172;0.9361163;0;0;0;-6.322775;-6.531509;8314.007;876927.8
830.0001;-2.007374;-0.4602059;9.205466;0.9512334;0;0;0;-6.322438;-6.531149;8448.267;891092.3
835.0001;-2.007267;-0.4760896;9.206847;0.951376;0;0;0;-6.322101;-6.530789;8449.533;891229.1
840.0001;-2.007213;-0.4892414;9.164033;0.946952;0;0;0;-6.321932;-6.530609;8410.242;887086.4
845.0001;-2.007106;-0.502139;9.230837;0.9538551;0;0;0;-6.321594;-6.530249;8471.551;893556.2
850.0001;-2.006999;-0.512547;9.322219;0.9632979;0;0;0;-6.321257;-6.529889;8555.416;902405.4
855.0001;-2.006892;-0.5236154;9.079552;0.9382222;0;0;0;-6.32092;-6.529528;8332.709;878917.9
860.0001;-2.006892;-0.5335059;9.372931;0.9685382;0;0;0;-6.32092;-6.529528;8601.957;907317.7
865.0001;-2.006785;-0.5419202;9.075;0.9377519;0;0;0;-6.320582;-6.529168;8328.532;878480.5
870.0001;-2.006678;-0.5485434;9.242671;0.9550779;0;0;0;-6.320245;-6.528808;8482.412;894714.7
875.0001;-2.006678;-0.5548164;9.128884;0.9433199;0;0;0;-6.320245;-6.528808;8377.983;883699.7
880.0001;-2.006571;-0.5602019;9.067571;0.9369842;0;0;0;-6.319907;-6.528448;8321.714;877767.7
885.0001;-2.006463;-0.5663371;9.120456;0.942449;0;0;0;-6.31957;-6.528088;8370.249;882890.3
890.0001;-2.006356;-0.5705668;9.088038;0.9390992;0;0;0;-6.319232;-6.527727;8340.498;879755.3
895.0001;-2.006303;-0.5748696;9.131761;0.9436172;0;0;0;-6.319063;-6.527547;8380.625;883989.5
900.0001;-2.006249;-0.5788074;9.213395;0.9520527;0;0;0;-6.318894;-6.527367;8455.543;891893.5
905.0001;-2.006088;-0.5824678;9.091386;0.9394451;0;0;0;-6.318388;-6.526826;8343.57;880087.3
910.0001;-2.006088;-0.5854899;9.306832;0.9617079;0;0;0;-6.318388;-6.526826;8541.295;900943.5
915.0001;-2.005928;-0.588014;9.030072;0.9331093;0;0;0;-6.317883;-6.526286;8287.3;874156.6
920.0001;-2.005928;-0.5902374;9.197303;0.9503899;0;0;0;-6.317883;-6.526286;8440.775;890345.4
925.0001;-2.005821;-0.5930146;9.177365;0.9483296;0;0;0;-6.317545;-6.525926;8422.478;888418.5
930.0001;-2.005713;-0.5967379;9.278143;0.9587434;0;0;0;-6.317207;-6.525565;8514.966;898177.6
935.0001;-2.00566;-0.5962019;8.980094;0.927945;0;0;0;-6.317038;-6.525385;8241.433;869326.3
940.0001;-2.005499;-0.5980758;9.271037;0.9580091;0;0;0;-6.316532;-6.524845;8508.444;897496.1
945.0001;-2.005499;-0.5979001;9.327535;0.9638472;0;0;0;-6.316532;-6.524845;8560.295;902965.5
950.0001;-2.005392;-0.6006795;9.23765;0.9545591;0;0;0;-6.316195;-6.524485;8477.804;894267.3
955.0001;-2.005285;-0.6012025;9.25847;0.9567105;0;0;0;-6.315857;-6.524125;8496.91;896286
960.0001;-2.005231;-0.6028613;9.331763;0.9642841;0;0;0;-6.315689;-6.523945;8564.175;903382.9
965.0001;-2.005178;-0.6035862;9.288421;0.9598054;0;0;0;-6.31552;-6.523765;8524.398;899188.7
970.0001;-2.00507;-0.6034297;9.301459;0.9611527;0;0;0;-6.315182;-6.523404;8536.363;900454.1
975.0001;-2.004963;-0.6030636;9.282695;0.9592137;0;0;0;-6.314845;-6.523044;8519.144;898640.9
980.0001;-2.004856;-0.6051975;9.343949;0.9655433;0;0;0;-6.314508;-6.522684;8575.358;904574
985.0001;-2.004803;-0.6049712;9.175573;0.9481445;0;0;0;-6.314339;-6.522504;8420.833;888275.4
990.0001;-2.004749;-0.6050377;9.222204;0.952963;0;0;0;-6.31417;-6.522324;8463.628;892791.3
995.0001;-2.004642;-0.6067124;9.253095;0.9561551;0;0;0;-6.313833;-6.521964;8491.979;895785.1
1000;-2.004535;-0.606385;9.240293;0.9548322;0;0;0;-6.313495;-6.521603;8480.229;894548.9
1005;-2.004428;-0.6072921;9.310003;0.9620356;0;0;0;-6.313158;-6.521243;8544.205;901300.8
1010;-2.004428;-0.6076327;9.250394;0.955876;0;0;0;-6.313158;-6.521243;8489.499;895530
1015;-2.00432;-0.6058506;9.217329;0.9524593;0;0;0;-6.31282;-6.520883;8459.154;892332.2
1020;-2.004213;-0.6068693;9.210722;0.9517766;0;0;0;-6.312483;-6.520523;8453.091;891695.8
1025;-2.004106;-0.6061731;9.699552;1.002289;0;0;0;-6.312146;-6.520163;8901.712;939023.1
1030;-2.004053;-0.6085851;9.230162;0.9537854;0;0;0;-6.311977;-6.519983;8470.932;893582.6
1035;-2.003946;-0.6066199;9.263373;0.9572171;0;0;0;-6.311639;-6.519622;8501.41;896801
1040;-2.003892;-0.6059992;9.364592;0.9676765;0;0;0;-6.311471;-6.519442;8594.304;906601.9
1045;-2.003731;-0.6068413;9.339926;0.9651276;0;0;0;-6.310965;-6.518902;8571.666;904218.7
1050;-2.003731;-0.6066247;9.273004;0.9582124;0;0;0;-6.310965;-6.518902;8510.249;897739.9
1055;-2.003624;-0.6055671;9.1448;0.9449645;0;0;0;-6.310627;-6.518542;8392.59;885331.3
1060;-2.003517;-0.6072742;9.287628;0.9597235;0;0;0;-6.31029;-6.518182;8523.671;899162.2
1065;-2.003463;-0.605386;9.344683;0.9656192;0;0;0;-6.310121;-6.518002;8576.033;904687.5
1070;-2.003356;-0.6053122;9.315965;0.9626517;0;0;0;-6.309784;-6.517642;8549.677;901910.4
1075;-2.003303;-0.605749;9.199858;0.9506539;0;0;0;-6.309614;-6.517461;8443.12;890671.3
1080;-2.003195;-0.6057139;9.401033;0.971442;0;0;0;-6.309277;-6.517101;8627.748;910151.1
1085;-2.003142;-0.6046579;9.344389;0.9655888;0;0;0;-6.309108;-6.516921;8575.763;904668.8
1090;-2.003035;-0.6034007;9.406701;0.9720277;0;0;0;-6.308771;-6.516561;8632.949;910704.7
1095;-2.002981;-0.604221;9.404088;0.9717577;0;0;0;-6.308602;-6.516381;8630.551;910453.3
1100;-2.002928;-0.6037056;9.262727;0.9571503;0;0;0;-6.308434;-6.516201;8500.817;896769.2
1105;-2.002821;-0.6037357;9.38456;0.9697399;0;0;0;-6.308096;-6.515841;8612.63;908567.7
1110;-2.002713;-0.6026322;9.287804;0.9597417;0;0;0;-6.307759;-6.515481;8523.832;899203.5
1115;-2.00266;-0.6022428;9.402942;0.9716393;0;0;0;-6.30759;-6.5153;8629.499;910352.3
1120;-2.002553;-0.6025449;9.284574;0.9594079;0;0;0;-6.307252;-6.51494;8520.867;898895.6
1125;-2.002499;-0.6027679;9.475296;0.9791159;0;0;0;-6.307083;-6.51476;8695.902;917362.2
1130;-2.002392;-0.6028043;9.306862;0.961711;0;0;0;-6.306746;-6.514399;8541.322;901058.3
1135;-2.002285;-0.6013424;9.290329;0.9600027;0;0;0;-6.306409;-6.51404;8526.149;899460.9
1140;-2.002231;-0.6017315;9.505219;0.9822079;0;0;0;-6.30624;-6.513859;8723.363;920267.5
1145;-2.002178;-0.6012113;9.365033;0.9677221;0;0;0;-6.306071;-6.513679;8594.709;906696.8
1150;-2.00207;-0.6009334;9.573433;0.9892567;0;0;0;-6.305734;-6.513319;8785.966;926876.8
1155;-2.001963;-0.6008043;9.288244;0.9597872;0;0;0;-6.305396;-6.512959;8524.236;899268.8
1160;-2.001856;-0.6015101;9.385647;0.9698521;0;0;0;-6.305059;-6.512599;8613.626;908702.3
1165;-2.001803;-0.6011043;9.458764;0.9774076;0;0;0;-6.30489;-6.512419;8680.729;915783.1
1170;-2.001749;-0.6012354;9.451746;0.9766824;0;0;0;-6.304721;-6.512239;8674.288;915105.2
1175;-2.001642;-0.600623;9.374195;0.9686688;0;0;0;-6.304384;-6.511879;8603.116;907600.1
1180;-2.001535;-0.5999207;9.399829;0.9713176;0;0;0;-6.304047;-6.511519;8626.643;910085.3
1185;-2.001481;-0.5993403;9.323071;0.9633859;0;0;0;-6.303878;-6.511339;8556.198;902655.3
1190;-2.001374;-0.5989743;9.412956;0.9726741;0;0;0;-6.30354;-6.510978;8638.689;911361.2
1195;-2.00132;-0.599135;9.166998;0.9472584;0;0;0;-6.303371;-6.510798;8412.963;887549.2
1200;-2.001213;-0.5992705;9.270567;0.9579605;0;0;0;-6.303034;-6.510438;8508.013;897580
1205;-2.001106;-0.5991183;9.626934;0.9947852;0;0;0;-6.302697;-6.510078;8835.067;932086.9
1210;-2.000999;-0.5977537;9.186937;0.9493187;0;0;0;-6.302359;-6.509718;8431.262;889489.2
1215;-2.000946;-0.5970893;9.296467;0.9606368;0;0;0;-6.302191;-6.509538;8531.782;900095.6
1220;-2.000892;-0.5973725;9.398009;0.9711295;0;0;0;-6.302022;-6.509358;8624.972;909928.7
1225;-2.000785;-0.5963152;9.478467;0.9794436;0;0;0;-6.301684;-6.508997;8698.813;917722.1
1230;-2.000678;-0.5960206;9.416157;0.9730048;0;0;0;-6.301347;-6.508637;8641.627;911692.4
1235;-2.000678;-0.596272;9.589494;0.9909164;0;0;0;-6.301347;-6.508637;8800.707;928475.3
1240;-2.000517;-0.5954958;9.457648;0.9772922;0;0;0;-6.300841;-6.508097;8679.705;915714.6
1245;-2.00041;-0.5962144;9.492738;0.9809183;0;0;0;-6.300504;-6.507737;8711.909;919115.5
1250;-2.000356;-0.5960871;9.40074;0.9714118;0;0;0;-6.300335;-6.507557;8627.479;910209.6
1255;-2.000356;-0.5952432;9.428225;0.9742519;0;0;0;-6.300335;-6.507557;8652.702;912870.7
1260;-2.000249;-0.5958211;9.399155;0.9712479;0;0;0;-6.299997;-6.507196;8626.023;910059.3
1265;-2.000142;-0.5950053;9.483607;0.9799746;0;0;0;-6.299659;-6.506836;8703.528;918239.6
1270;-2.000035;-0.595043;9.404734;0.9718244;0;0;0;-6.299322;-6.506476;8631.144;910606.1
1275;-1.999928;-0.5946698;9.34897;0.9660622;0;0;0;-6.298985;-6.506116;8579.967;905210.1
1280;-1.999874;-0.5948487;9.595455;0.9915323;0;0;0;-6.298816;-6.505936;8806.177;929077.6
1285;-1.999821;-0.5950134;9.268629;0.9577603;0;0;0;-6.298647;-6.505756;8506.234;897434.3
1290;-1.999713;-0.5943414;9.545888;0.9864104;0;0;0;-6.29831;-6.505396;8760.688;924283.3
1295;-1.999606;-0.5943975;9.491534;0.9807938;0;0;0;-6.297972;-6.505035;8710.805;919023.7
1300;-1.999552;-0.5944612;9.326507;0.963741;0;0;0;-6.297803;-6.504855;8559.352;903046.5
1305;-1.999445;-0.5941771;9.388613;0.9701586;0;0;0;-6.297466;-6.504495;8616.349;909063.2
1310;-1.999445;-0.5941658;9.560747;0.9879459;0;0;0;-6.297466;-6.504495;8774.324;925730.3
1315;-1.999285;-0.5946845;9.404439;0.971794;0;0;0;-6.29696;-6.503955;8630.873;910600.5
1320;-1.999178;-0.5948087;9.394573;0.9707745;0;0;0;-6.296622;-6.503595;8621.818;909648.5
1325;-1.999178;-0.5945043;9.484869;0.9801051;0;0;0;-6.296622;-6.503595;8704.688;918391.6
1330;-1.999071;-0.5942661;9.4622;0.9777626;0;0;0;-6.296285;-6.503235;8683.883;916199.9
1335;-1.998963;-0.5937164;9.384883;0.9697732;0;0;0;-6.295947;-6.502874;8612.926;908716.8
1340;-1.99891;-0.5944332;9.398214;0.9711508;0;0;0;-6.295779;-6.502695;8625.16;910009.2
1345;-1.998803;-0.5946841;9.329325;0.9640322;0;0;0;-6.295441;-6.502335;8561.938;903342.1
1350;-1.998749;-0.5942105;9.493502;0.9809972;0;0;0;-6.295273;-6.502155;8712.61;919240.8
1355;-1.998642;-0.5938872;9.486455;0.980269;0;0;0;-6.294935;-6.501795;8706.143;918561.6
1360;-1.998588;-0.5936105;9.261905;0.9570655;0;0;0;-6.294766;-6.501614;8500.063;896820.4
1365;-1.998481;-0.593584;9.480611;0.9796651;0;0;0;-6.294429;-6.501255;8700.779;918000.8
1370;-1.998374;-0.593644;9.418711;0.9732687;0;0;0;-6.294091;-6.500894;8643.971;912010.3
1375;-1.99832;-0.5945956;9.344595;0.9656101;0;0;0;-6.293922;-6.500714;8575.952;904835.4
1380;-1.998213;-0.5937841;9.549383;0.9867715;0;0;0;-6.293585;-6.500354;8763.895;924668.2
1385;-1.99816;-0.5944246;9.377806;0.9690419;0;0;0;-6.293417;-6.500174;8606.431;908056
1390;-1.998053;-0.5943654;9.511914;0.9828997;0;0;0;-6.293079;-6.499814;8729.508;921045.1
1395;-1.997946;-0.5953172;9.580686;0.9900061;0;0;0;-6.292742;-6.499454;8792.622;927707.6
1400;-1.997892;-0.5942305;9.451629;0.9766703;0;0;0;-6.292573;-6.499274;8674.181;915212.6
1405;-1.997785;-0.5943242;9.578189;0.9897482;0;0;0;-6.292235;-6.498913;8790.331;927470.9
1410;-1.997731;-0.5941774;9.599449;0.991945;0;0;0;-6.292067;-6.498733;8809.842;929531.2
1415;-1.997624;-0.5937912;9.501372;0.9818104;0;0;0;-6.291729;-6.498373;8719.833;920037.5
1420;-1.997517;-0.5941922;9.305012;0.9615198;0;0;0;-6.291392;-6.498013;8539.624;901026.8
1425;-1.997463;-0.5938123;9.502429;0.9819196;0;0;0;-6.291224;-6.497833;8720.803;920144.9
1430;-1.997356;-0.5934239;9.589436;0.9909104;0;0;0;-6.290886;-6.497473;8800.653;928573.3
1435;-1.997303;-0.5933159;9.571318;0.9890382;0;0;0;-6.290717;-6.497293;8784.025;926820.6
1440;-1.997196;-0.5934113;9.562596;0.9881369;0;0;0;-6.29038;-6.496933;8776.021;925979.4
1445;-1.997088;-0.593567;9.468425;0.9784058;0;0;0;-6.290042;-6.496572;8689.596;916863.7
1450;-1.997035;-0.5939743;9.65163;0.997337;0;0;0;-6.289873;-6.496392;8857.73;934605.8
1455;-1.996928;-0.5926225;9.480201;0.9796227;0;0;0;-6.289536;-6.496032;8700.402;918009
1460;-1.996928;-0.593492;9.48945;0.9805785;0;0;0;-6.289536;-6.496032;8708.892;918904.7
1465;-1.996821;-0.5934497;9.452773;0.9767885;0;0;0;-6.289198;-6.495673;8675.231;915356.4
1470;-1.996713;-0.5936316;9.45894;0.9774258;0;0;0;-6.288861;-6.495313;8680.892;915956.8
1475;-1.996606;-0.5927913;9.286747;0.9596325;0;0;0;-6.288524;-6.494953;8522.862;899285.7
1480;-1.996499;-0.5931459;9.224524;0.9532027;0;0;0;-6.288186;-6.494592;8465.757;893263.5
1485;-1.996499;-0.59243;9.357574;0.9669513;0;0;0;-6.288186;-6.494592;8587.863;906147.6
1490;-1.996392;-0.5924676;9.48158;0.9797652;0;0;0;-6.287848;-6.494232;8701.669;918159.1
1495;-1.996285;-0.5914718;9.488951;0.9805269;0;0;0;-6.287511;-6.493872;8708.434;918876.2
1500;-1.996178;-0.5912339;9.325949;0.9636833;0;0;0;-6.287174;-6.493512;8558.839;903094.9
1505;-1.99607;-0.5905045;9.450483;0.9765519;0;0;0;-6.286836;-6.493152;8673.13;915157.7
1510;-1.99607;-0.5907211;9.405555;0.9719093;0;0;0;-6.286836;-6.493152;8631.897;910807
1515;-1.995963;-0.5913898;9.470157;0.9785849;0;0;0;-6.286499;-6.492792;8691.186;917066.1
1520;-1.995856;-0.5906905;9.427697;0.9741973;0;0;0;-6.286161;-6.492431;8652.218;912957.7
1525;-1.995749;-0.5906354;9.37628;0.9688842;0;0;0;-6.285824;-6.492071;8605.03;907981.8
1530;-1.995749;-0.5908313;9.4913;0.9807696;0;0;0;-6.285824;-6.492071;8710.589;919120.1
1535;-1.995642;-0.5907498;9.389699;0.9702708;0;0;0;-6.285486;-6.491711;8617.345;909284.6
1540;-1.995535;-0.5902776;9.361245;0.9673306;0;0;0;-6.285149;-6.491352;8591.231;906532.4
1545;-1.995428;-0.5904467;9.407171;0.9720762;0;0;0;-6.284812;-6.490992;8633.38;910983.1
1550;-1.995428;-0.590277;9.248251;0.9556544;0;0;0;-6.284812;-6.490992;8487.532;895593.4
1555;-1.99532;-0.5883395;9.138779;0.9443424;0;0;0;-6.284473;-6.490631;8387.065;884995.5
1560;-1.995213;-0.5898209;9.224465;0.9531966;0;0;0;-6.284136;-6.490271;8465.703;893296.5
1565;-1.995106;-0.5891124;9.296055;0.9605943;0;0;0;-6.283799;-6.489911;8531.404;900232.5
1570;-1.994999;-0.5889489;9.184236;0.9490396;0;0;0;-6.283462;-6.489551;8428.782;889407
1575;-1.994999;-0.5880747;8.964942;0.9263792;0;0;0;-6.283462;-6.489551;8227.527;868170.5
1580;-1.994892;-0.5890829;8.88789;0.9184171;0;0;0;-6.283124;-6.489191;8156.813;860711.8
1585;-1.994785;-0.5885264;9.363007;0.9675126;0;0;0;-6.282787;-6.488831;8592.849;906725.9
1590;-1.994678;-0.588006;9.239852;0.9547866;0;0;0;-6.282449;-6.48847;8479.824;894802.6
1595;-1.994678;-0.5881186;9.023612;0.9324418;0;0;0;-6.282449;-6.48847;8281.371;873861.6
1600;-1.99457;-0.5874938;9.137605;0.9442211;0;0;0;-6.282112;-6.488111;8385.987;884904.1
1605;-1.994463;-0.587851;9.226109;0.9533665;0;0;0;-6.281775;-6.487751;8467.212;893478.2
1610;-1.994356;-0.5874255;9.030307;0.9331336;0;0;0;-6.281437;-6.487391;8287.516;874519.4
1615;-1.994303;-0.5868294;9.157867;0.9463148;0;0;0;-6.281269;-6.487211;8404.583;886874.2
1620;-1.994249;-0.586985;9.143419;0.9448219;0;0;0;-6.2811;-6.487031;8391.323;885476.7
1625;-1.994142;-0.5851325;9.141305;0.9446034;0;0;0;-6.280763;-6.486671;8389.384;885275.1
1630;-1.994035;-0.5855599;9.028956;0.932994;0;0;0;-6.280424;-6.48631;8286.276;874398
1635;-1.993981;-0.5845422;9.11103;0.941475;0;0;0;-6.280255;-6.48613;8361.599;882348
1640;-1.993874;-0.5836793;9.149791;0.9454803;0;0;0;-6.279918;-6.48577;8397.171;886104.9
1645;-1.99382;-0.5823684;9.213835;0.9520982;0;0;0;-6.279749;-6.48559;8455.947;892308.8
1650;-1.99366;-0.5810265;9.118988;0.9422973;0;0;0;-6.279243;-6.48505;8368.901;883128.1
1655;-1.99366;-0.5820129;9.38961;0.9702617;0;0;0;-6.279243;-6.48505;8617.265;909336.6
1660;-1.993499;-0.5810937;9.194278;0.9500773;0;0;0;-6.278737;-6.484509;8437.999;890424.5
1665;-1.993499;-0.5781592;9.174927;0.9480777;0;0;0;-6.278737;-6.484509;8420.24;888550.4
1670;-1.993392;-0.5761852;8.978009;0.9277295;0;0;0;-6.278399;-6.484149;8239.52;869482.9
1675;-1.993285;-0.5738664;9.208021;0.9514974;0;0;0;-6.278062;-6.483789;8450.611;891761.8
1680;-1.993178;-0.5730028;9.196539;0.950311;0;0;0;-6.277725;-6.483429;8440.074;890653.1
1685;-1.99307;-0.5709384;9.206259;0.9513153;0;0;0;-6.277387;-6.48307;8448.994;891597.6
1690;-1.99307;-0.5680648;9.031776;0.9332854;0;0;0;-6.277387;-6.48307;8288.863;874699.4
1695;-1.992963;-0.5632687;9.116404;0.9420303;0;0;0;-6.27705;-6.48271;8366.53;882898.6
1700;-1.992856;-0.5593951;9.137605;0.9442211;0;0;0;-6.276712;-6.482349;8385.987;884955
1705;-1.992749;-0.5561603;9.236886;0.9544801;0;0;0;-6.276375;-6.481989;8477.103;894573.4
1710;-1.992749;-0.5518439;9.188024;0.9494311;0;0;0;-6.276375;-6.481989;8432.26;889841.2
1715;-1.992642;-0.5465857;9.254358;0.9562856;0;0;0;-6.276038;-6.481629;8493.137;896268.7
1720;-1.992535;-0.5416229;9.301488;0.9611557;0;0;0;-6.2757;-6.481269;8536.391;900836.4
1725;-1.992481;-0.5369416;9.18036;0.9486391;0;0;0;-6.275532;-6.481089;8425.226;889106.9
1730;-1.992428;-0.5295191;9.059936;0.9361953;0;0;0;-6.275363;-6.48091;8314.707;877445.6
1735;-1.992321;-0.5223142;9.244609;0.9552782;0;0;0;-6.275025;-6.48055;8484.189;895334.2
1740;-1.992213;-0.5135253;9.044197;0.9345689;0;0;0;-6.274687;-6.480189;8300.263;875927.6
1745;-1.992106;-0.5008075;9.233597;0.9541402;0;0;0;-6.27435;-6.479829;8474.084;894274.2
1750;-1.991999;-0.4847789;9.324246;0.9635073;0;0;0;-6.274013;-6.479469;8557.276;903056.7
1755;-1.991999;-0.4670095;9.188376;0.9494674;0;0;0;-6.274013;-6.479469;8432.582;889897.7
1760;-1.991892;-0.443352;9.20018;0.9506872;0;0;0;-6.273675;-6.479109;8443.416;891044.2
1765;-1.991785;-0.4144488;9.135755;0.9440299;0;0;0;-6.273338;-6.478749;8384.29;884807.7
1770;-1.991678;-0.3797242;9.19052;0.949689;0;0;0;-6.273001;-6.478389;8434.55;890115
1775;-1.991678;-0.3388574;9.255885;0.9564434;0;0;0;-6.273001;-6.478389;8494.538;896445.7
1780;-1.99157;-0.2925147;9.018386;0.9319017;0;0;0;-6.272663;-6.478028;8276.574;873446.7
1785;-1.991463;-0.2399331;9.296408;0.9606308;0;0;0;-6.272326;-6.477669;8531.729;900376.9
1790;-1.99141;-0.1812186;9.254476;0.9562978;0;0;0;-6.272157;-6.477489;8493.245;896317.3
1795;-1.991303;-0.1239815;9.241203;0.9549262;0;0;0;-6.27182;-6.477129;8481.063;895034.9
1800;-1.991249;-0.07965696;9.161772;0.9467183;0;0;0;-6.271651;-6.476949;8408.167;887343.5
1805;-1.991142;-0.04852923;9.194543;0.9501047;0;0;0;-6.271314;-6.476589;8438.242;890520.6
1810;-1.991035;-0.02653214;9.023025;0.9323812;0;0;0;-6.270975;-6.476228;8280.833;873911.8
1815;-1.990928;-0.01349293;9.295967;0.9605852;0;0;0;-6.270638;-6.475868;8531.323;900350.4
1820;-1.990874;-0.009215041;9.242935;0.9551052;0;0;0;-6.270469;-6.475688;8482.653;895215.6
1825;-1.990767;-0.005893886;9.150643;0.9455684;0;0;0;-6.270132;-6.475329;8397.953;886280
1830;-1.99066;-0.00243695;9.451629;0.9766703;0;0;0;-6.269794;-6.474969;8674.181;915435
1835;-1.990606;-0.002178425;9.236622;0.9544529;0;0;0;-6.269626;-6.474789;8476.86;894612.3
1840;-1.990553;-0.001914968;9.229751;0.9537429;0;0;0;-6.269457;-6.474609;8470.554;893948.3
1845;-1.990446;-0.0009330998;9.01912;0.9319776;0;0;0;-6.26912;-6.474249;8277.248;873550.8
1850;-1.990338;-0.0008277794;9.264518;0.9573355;0;0;0;-6.268782;-6.473888;8502.462;897322.2
1855;-1.990231;0.001042225;9.224553;0.9532058;0;0;0;-6.268445;-6.473528;8465.784;893454.6
1860;-1.990231;5.976995e-005;9.127298;0.943156;0;0;0;-6.268445;-6.473528;8376.528;884034.8
1865;-1.990178;0.001334656;9.201384;0.9508116;0;0;0;-6.268276;-6.473348;8444.521;891212.1
1870;-1.99007;0.00146985;9.312911;0.9623361;0;0;0;-6.267939;-6.472988;8546.874;902017.4
1875;-1.989963;0.001519456;9.365092;0.9677281;0;0;0;-6.267601;-6.472628;8594.763;907074.7
1880;-1.989856;0.0002911224;9.405468;0.9719003;0;0;0;-6.267264;-6.472268;8631.817;910988.7
1885;-1.989803;0.001375962;9.227313;0.953491;0;0;0;-6.267095;-6.472088;8468.316;893734.8
1890;-1.989749;0.00135893;9.206142;0.9513032;0;0;0;-6.266926;-6.471908;8448.887;891685.8
1895;-1.989642;0.001119277;9.323541;0.9634345;0;0;0;-6.266589;-6.471548;8556.629;903060
1900;-1.989535;0.0009465755;9.217594;0.9524866;0;0;0;-6.266251;-6.471188;8459.396;892801.4
1905;-1.989428;0.0005713373;9.075;0.9377519;0;0;0;-6.265914;-6.470828;8328.532;878993.2
1910;-1.989374;0.0007589956;9.255562;0.95641;0;0;0;-6.265745;-6.470649;8494.242;896483.8
1915;-1.989213;0.001298048;9.233127;0.9540917;0;0;0;-6.265238;-6.470108;8473.652;894315.6
1920;-1.989213;-0.0004880918;9.109121;0.9412777;0;0;0;-6.265238;-6.470108;8359.847;882304.5
1925;-1.989106;-1.133114e-005;9.413954;0.9727772;0;0;0;-6.264901;-6.469748;8639.605;911833.6
1930;-1.988999;-0.00112808;9.447694;0.9762636;0;0;0;-6.264564;-6.469388;8670.569;915105
1935;-1.988999;-0.001631268;9.457795;0.9773074;0;0;0;-6.264564;-6.469388;8679.84;916083.4
1940;-1.988892;-0.001994173;9.381448;0.9694182;0;0;0;-6.264226;-6.469028;8609.772;908691.7
1945;-1.988785;-0.0021879;9.247075;0.955533;0;0;0;-6.263889;-6.468668;8486.453;895679.5
1950;-1.988731;-0.00249376;9.383004;0.969579;0;0;0;-6.263721;-6.468488;8611.201;908847.3
1955;-1.988678;-0.004169412;9.370788;0.9683167;0;0;0;-6.263552;-6.468308;8599.99;907665.7
1960;-1.98857;-0.003676676;9.251862;0.9560276;0;0;0;-6.263214;-6.467948;8490.846;896149.6
1965;-1.988463;-0.004672953;9.327152;0.9638076;0;0;0;-6.262877;-6.467588;8559.943;903445.6
1970;-1.98841;-0.003895539;9.233715;0.9541525;0;0;0;-6.262708;-6.467408;8474.192;894396.7
1975;-1.988303;-0.003873457;9.203118;0.9509907;0;0;0;-6.262371;-6.467048;8446.111;891436.1
1980;-1.988249;-0.006097518;9.204673;0.9511515;0;0;0;-6.262202;-6.466868;8447.539;891588.5
1985;-1.988142;-0.002952902;9.290799;0.9600512;0;0;0;-6.261865;-6.466509;8526.581;899934.1
1990;-1.988088;-0.005128689;9.365268;0.9677463;0;0;0;-6.261696;-6.466329;8594.924;907149
1995;-1.987981;-0.005607955;9.315201;0.9625727;0;0;0;-6.261358;-6.465968;8548.976;902302.6
2000;-1.987874;-0.006523224;9.336901;0.9648151;0;0;0;-6.261021;-6.465608;8568.891;904407.8
2005;-1.98782;-0.00726219;9.392753;0.9705864;0;0;0;-6.260852;-6.465428;8620.148;909819.4
2010;-1.987713;-0.008799123;9.511386;0.9828451;0;0;0;-6.260514;-6.465068;8729.022;921314
2015;-1.98766;-0.0092567;9.418535;0.9732506;0;0;0;-6.260346;-6.464888;8643.81;912321.7
2020;-1.987553;-0.01062735;9.230544;0.9538248;0;0;0;-6.260008;-6.464528;8471.281;894115.3
2025;-1.987446;-0.01007076;9.551291;0.9869688;0;0;0;-6.259671;-6.464168;8765.646;925187.7
2030;-1.987392;-0.0103767;9.164209;0.9469702;0;0;0;-6.259502;-6.463989;8410.403;887694.5
2035;-1.987285;-0.01095099;9.100782;0.940416;0;0;0;-6.259164;-6.463628;8352.193;881553.9
2040;-1.987178;-0.01175882;9.205789;0.9512668;0;0;0;-6.258827;-6.463268;8448.563;891728.6
2045;-1.98707;-0.01226315;9.312441;0.9622875;0;0;0;-6.25849;-6.462908;8546.442;902062.8
2050;-1.98707;-0.01299346;9.33602;0.9647241;0;0;0;-6.25849;-6.462908;8568.082;904346.9
2055;-1.986963;-0.0127356;9.229633;0.9537306;0;0;0;-6.258152;-6.462548;8470.446;894044.7
2060;-1.986856;-0.0140346;9.508273;0.9825235;0;0;0;-6.257815;-6.462188;8726.166;921039
2065;-1.986749;-0.01457949;9.444493;0.9759329;0;0;0;-6.257477;-6.461828;8667.632;914864.1
2070;-1.986695;-0.01407947;9.274708;0.9583884;0;0;0;-6.257308;-6.461648;8511.813;898419.1
2075;-1.986642;-0.0140395;9.072152;0.9374576;0;0;0;-6.25714;-6.461468;8325.918;878799.6
2080;-1.986535;-0.01407403;9.232012;0.9539765;0;0;0;-6.256803;-6.461108;8472.629;894288
2085;-1.986481;-0.01566711;9.238854;0.9546835;0;0;0;-6.256634;-6.460928;8478.908;894952.5
2090;-1.986374;-0.01473152;9.261905;0.9570655;0;0;0;-6.256297;-6.460569;8500.063;897188.6
2095;-1.986267;-0.0147242;9.381741;0.9694485;0;0;0;-6.255959;-6.460209;8610.042;908800.2
2100;-1.986213;-0.01363235;9.149879;0.9454894;0;0;0;-6.25579;-6.460029;8397.252;886341.6
2105;-1.986106;-0.01409267;9.207581;0.9514519;0;0;0;-6.255452;-6.459668;8450.208;891934.3
2110;-1.986053;-0.01374386;9.15402;0.9459172;0;0;0;-6.255283;-6.459488;8401.052;886747.4
2115;-1.985892;-0.01431055;9.22652;0.953409;0;0;0;-6.254777;-6.458948;8467.589;893775.4
2120;-1.985892;-0.01311789;9.347267;0.9658862;0;0;0;-6.254777;-6.458948;8578.403;905472.2
2125;-1.985785;-0.01404396;9.121308;0.942537;0;0;0;-6.25444;-6.458588;8371.03;883586.6
2130;-1.985678;-0.01516263;9.098697;0.9402006;0;0;0;-6.254103;-6.458229;8350.28;881399.5
2135;-1.985678;-0.01440957;9.369878;0.9682227;0;0;0;-6.254103;-6.458229;8599.155;907669
2140;-1.985571;-0.01665747;9.417301;0.9731231;0;0;0;-6.253766;-6.457869;8642.678;912266.2
2145;-1.985463;-0.01684102;9.069245;0.9371572;0;0;0;-6.253428;-6.457508;8323.25;878552.7
2150;-1.985356;-0.01698436;9.354726;0.966657;0;0;0;-6.25309;-6.457149;8585.249;906211
2155;-1.985303;-0.01753116;9.31805;0.9628671;0;0;0;-6.252922;-6.456969;8551.59;902659.8
2160;-1.985249;-0.01666519;9.615629;0.993617;0;0;0;-6.252753;-6.456789;8824.691;931488.6
2165;-1.985142;-0.01845113;9.620826;0.994154;0;0;0;-6.252416;-6.456429;8829.461;931995.4
2170;-1.985035;-0.01923066;9.387232;0.9700159;0;0;0;-6.252079;-6.456069;8615.081;909369.8
2175;-1.984981;-0.01945246;9.362742;0.9674853;0;0;0;-6.25191;-6.455889;8592.605;906999
2180;-1.984874;-0.01972508;9.297612;0.9607552;0;0;0;-6.251572;-6.455528;8532.833;900692.9
2185;-1.98482;-0.02007412;9.418241;0.9732202;0;0;0;-6.251403;-6.455349;8643.54;912380.2
2190;-1.984713;-0.02087969;9.301664;0.9611739;0;0;0;-6.251066;-6.454989;8536.552;901090.3
2195;-1.984606;-0.02048973;9.434039;0.9748526;0;0;0;-6.250728;-6.454629;8658.038;913917.3
2200;-1.984499;-0.02039913;9.429722;0.9744066;0;0;0;-6.250391;-6.454269;8654.076;913502.4
2205;-1.984499;-0.02185862;9.417977;0.9731929;0;0;0;-6.250391;-6.454269;8643.298;912364.6
2210;-1.984392;-0.02238389;9.278701;0.958801;0;0;0;-6.250053;-6.453909;8515.478;898875.5
2215;-1.984285;-0.02151188;9.503163;0.9819955;0;0;0;-6.249715;-6.453548;8721.477;920623.6
2220;-1.984231;-0.02271171;9.126535;0.9430771;0;0;0;-6.249547;-6.453369;8375.828;884139.1
2225;-1.984178;-0.02245338;9.264665;0.9573507;0;0;0;-6.249378;-6.453189;8502.597;897522.2
2230;-1.98407;-0.02237982;9.457678;0.9772953;0;0;0;-6.249041;-6.452829;8679.732;916223.7
2235;-1.983963;-0.02297161;9.269334;0.9578331;0;0;0;-6.248703;-6.452469;8506.881;897980.9
2240;-1.983856;-0.02287052;9.405555;0.9719093;0;0;0;-6.248366;-6.452109;8631.897;911180.9
2245;-1.983749;-0.02326055;9.451452;0.976652;0;0;0;-6.248029;-6.451749;8674.02;915630.5
2250;-1.983749;-0.02295755;9.289801;0.9599481;0;0;0;-6.248029;-6.451749;8525.665;899970.2
2255;-1.983642;-0.02347182;9.413484;0.9727286;0;0;0;-6.247691;-6.451389;8639.174;911955.6
2260;-1.983535;-0.02286723;9.264635;0.9573476;0;0;0;-6.247354;-6.451029;8502.569;897538.7
2265;-1.983535;-0.0229045;9.276587;0.9585825;0;0;0;-6.247354;-6.451029;8513.537;898696.5
2270;-1.983321;-0.02345972;9.352053;0.9663808;0;0;0;-6.246679;-6.45031;8582.797;906014.1
2275;-1.983321;-0.02342249;9.167293;0.9472888;0;0;0;-6.246679;-6.45031;8413.233;888114.7
2280;-1.983213;-0.02286037;9.385177;0.9698036;0;0;0;-6.246342;-6.44995;8613.195;909226.3
2285;-1.983106;-0.02297615;9.287364;0.9596962;0;0;0;-6.246004;-6.44959;8523.428;899753.5
2290;-1.983106;-0.02269656;9.457325;0.9772589;0;0;0;-6.246004;-6.44959;8679.409;916219.2
2295;-1.982999;-0.02291135;9.458118;0.9773408;0;0;0;-6.245666;-6.449229;8680.137;916299.3
2300;-1.982892;-0.02320621;9.453714;0.9768857;0;0;0;-6.245328;-6.448869;8676.095;915876
2305;-1.982785;-0.02401099;9.38321;0.9696003;0;0;0;-6.244991;-6.44851;8611.39;909048.8
2310;-1.982678;-0.02219474;9.258498;0.9567134;0;0;0;-6.244654;-6.44815;8496.937;896970
2315;-1.982624;-0.02294021;9.391549;0.970462;0;0;0;-6.244485;-6.44797;8619.043;909861.6
2320;-1.982517;-0.0225109;9.515526;0.983273;0;0;0;-6.244148;-6.44761;8732.822;921876
2325;-1.982463;-0.02182495;9.323834;0.9634648;0;0;0;-6.243979;-6.44743;8556.898;903306.3
2330;-1.98241;-0.02254817;9.458147;0.9773439;0;0;0;-6.24381;-6.44725;8680.164;916320.4
2335;-1.982303;-0.02275905;9.458882;0.9774197;0;0;0;-6.243473;-6.44689;8680.838;916394.8
2340;-1.982249;-0.02239724;9.661731;0.9983808;0;0;0;-6.243304;-6.44671;8867.001;936048.9
2345;-1.982142;-0.02177585;9.507979;0.9824931;0;0;0;-6.242967;-6.44635;8725.896;921156.4
2350;-1.982035;-0.02226067;9.124743;0.942892;0;0;0;-6.24263;-6.445991;8374.184;884030.8
2355;-1.981981;-0.0224757;9.309035;0.9619355;0;0;0;-6.242461;-6.445811;8543.316;901887.1
2360;-1.981874;-0.02164183;9.349705;0.9661381;0;0;0;-6.242124;-6.445451;8580.641;905830.6
2365;-1.98182;-0.02101848;9.495763;0.9812308;0;0;0;-6.241954;-6.44527;8714.686;919982.8
2370;-1.981713;-0.0209955;9.461407;0.9776806;0;0;0;-6.241617;-6.44491;8683.155;916657.6
2375;-1.98166;-0.02097682;9.30974;0.9620084;0;0;0;-6.241448;-6.44473;8543.963;901965.1
2380;-1.981553;-0.02049364;9.505806;0.9822685;0;0;0;-6.241111;-6.444371;8723.901;920964.1
2385;-1.981446;-0.02031808;9.256708;0.9565284;0;0;0;-6.240773;-6.444011;8495.293;896833.6
2390;-1.981392;-0.02097522;9.588173;0.9907799;0;0;0;-6.240605;-6.443831;8799.494;928949.2
2395;-1.981285;-0.02017858;9.384736;0.969758;0;0;0;-6.240267;-6.443471;8612.791;909242.5
2400;-1.981231;-0.01968181;9.30463;0.9614804;0;0;0;-6.240098;-6.44329;8539.274;901483.1
2405;-1.981124;-0.01952642;9.471332;0.9787063;0;0;0;-6.23976;-6.44293;8692.264;917637.4
2410;-1.98107;-0.02025469;9.458412;0.9773712;0;0;0;-6.239592;-6.442751;8680.406;916387.2
2415;-1.980963;-0.01971854;9.402179;0.9715604;0;0;0;-6.239254;-6.442391;8628.799;910942.3
2420;-1.98091;-0.02019432;9.393546;0.9706683;0;0;0;-6.239086;-6.442211;8620.876;910107.5
2425;-1.980803;-0.01924605;9.25336;0.9561824;0;0;0;-6.238749;-6.441851;8492.221;896528.6
2430;-1.980696;-0.01901595;9.277527;0.9586797;0;0;0;-6.238411;-6.441491;8514.4;898873.3
2435;-1.980642;-0.01882132;9.352171;0.966393;0;0;0;-6.238243;-6.441311;8582.904;906107
2440;-1.980535;-0.01821766;9.347209;0.9658802;0;0;0;-6.237905;-6.440951;8578.35;905629.5
2445;-1.980428;-0.01932063;9.53241;0.9850177;0;0;0;-6.237567;-6.440591;8748.318;923576.5
2450;-1.980374;-0.01881928;9.538078;0.9856033;0;0;0;-6.237399;-6.440412;8753.52;924127.3
2452.338;-1.980374;-0.01889144;9.496468;0.9813037;0;0;0;-6.237399;-6.440412;8715.333;920095.9