File: Ensayos/Resistencia/comp/Clavo6/Clavo6i.raw
"Test Type";"Manual"
"Method Name:";"C:\INSTRON\user\template\CYCLE.MTM"
"Name:";""
"Operator ID:";""
"Company:";""
"Lab name:";""
"Test date:";"12/06/2017"
"Temperature:";""
"Humidity:";""
"Note 1:";""
"Note 2:";""
"Note 3:";""
"Geometry:";"Rectangular"
"Specimen";1
"Specimen name:";""
"Width:";0.250000;"in"
"Thickness:";0.060000;"in"
"Length:";1.250000;"in"
"Diameter:";0.039370;"in"
"Inner diameter:";0.019685;"in"
"Outer diameter:";0.039370;"in"
"Wall thickness:";0.019685;"in"
"Area:";0.015000;"in*in"
"Linear density:";1.000000;"den"
"Sled weight:";2.204623;"lbf"
"Loading span:";0.000000;"mm"
"Support span:";1.000000;"mm"
"Span ratio:";"2"
"Fixture type:";"3-point"
"Comment:";""
"Included"
"Final Width:";0.250000;"in"
"Final Thickness:";0.060000;"in"
"Final Length:";1.250000;"in"
"Final Diameter:";0.039370;"in"
"Final Inner diameter:";0.019685;"in"
"Final Outer diameter:";0.039370;"in"
"Final Wall thickness:";0.019685;"in"
"Final Area:";0.015000;"in*in"
"Final Linear density:";1.000000;"den"
"Time sec";"Extension mm";"Strain 1 %";"Load N";"Stress MPa";"Cycle Count ";"Total Cycle Count ";"Repetitions Count ";"Strain [Exten.] %";"True strain %";"Tenacity gf/tex";"True stress Pa"
0;0;-0.001233079;54.91204;5.674255;0;0;0;0;0;50395.23;5674255
28;0.0932678;-0.004491825;93.99893;9.713243;0;0;0;0.2937568;0.2933262;86267.01;9741776
56;0.186857;-0.04123948;394.7981;40.79589;0;0;0;0.588526;0.586801;362323.8;4.103598e+007
84.00001;0.2800177;-0.09667888;763.0358;78.84719;0;0;0;0.8819455;0.878079;700271.9;7.954258e+007
112;0.3734462;-0.1749834;1167.67;120.6595;0;0;0;1.176208;1.169345;1071623;1.220787e+008
140;0.5491604;-0.4700973;2096.712;216.6607;0;0;0;1.729639;1.714851;1924246;2.204081e+008
168;0.7357495;-1.003496;2899.202;299.5848;0;0;0;2.317321;2.290879;2660727;3.065272e+008
196;0.922553;-1.710737;3494.632;361.1127;0;0;0;2.905679;2.864264;3207180;3.716054e+008
224;1.109249;-2.485504;3969.598;410.1926;0;0;0;3.493699;3.434054;3643077;4.245235e+008
250.192;1.172731;-2.856109;3601.093;372.1137;0;0;0;3.693642;3.627062;3304884;3.858583e+008
278.192;0.9860351;-2.001275;2528.591;261.2882;0;0;0;3.105622;3.058374;2320601;2.694029e+008
306.192;0.7993923;-1.014682;1730.821;178.8519;0;0;0;2.517771;2.486597;1588452;1.83355e+008
334.192;0.6126424;-0.3864805;848.8212;87.7117;0;0;0;1.929582;1.911202;779001.1;8.940417e+007
362.192;0.4260533;-0.09871168;161.131;16.65024;0;0;0;1.3419;1.332976;147877.1;1.687367e+007
390.192;0.2392499;-0.05769452;53.58623;5.537255;0;0;0;0.7535428;0.7507179;49178.47;5578980
416.54;0.4103033;-0.1154023;371.0284;38.33968;1;1;0;1.292294;1.284015;340509.3;3.883514e+007
444.54;0.596946;-0.3759009;1345.751;139.0612;1;1;0;1.880145;1.862689;1235056;1.416758e+008
472.54;0.7836959;-0.8656456;2355.573;243.4097;1;1;0;2.468334;2.438363;2161814;2.494179e+008
500.54;0.9702315;-1.634514;3205.433;331.2288;1;1;0;3.055847;3.010086;2941769;3.413506e+008
528.5401;1.157089;-2.554351;3886.594;401.6155;1;1;0;3.644373;3.579537;3566901;4.162519e+008
555.5241;1.258338;-3.004075;4109.526;424.6519;1;1;0;3.963271;3.886748;3771495;4.41482e+008
583.5241;1.154624;-2.657859;3165.991;327.153;1;1;0;3.636612;3.572048;2905571;3.390503e+008
611.5241;0.9681423;-1.734852;2247.295;232.221;1;1;0;3.049267;3.003701;2062443;2.39302e+008
639.5241;0.7813924;-0.8550819;1400.619;144.7309;1;1;0;2.461078;2.431282;1285411;1.482929e+008
667.5241;0.5948032;-0.3251163;567.1623;58.60688;1;1;0;1.873396;1.856064;520510.1;5.970482e+007
695.5241;0.4081604;-0.1007667;54.84224;5.667043;1;1;0;1.285545;1.277352;50331.17;5739895
721.718;0.2465891;-0.09448039;53.54025;5.532504;2;2;0;0.7766587;0.7736582;49136.27;5575472
749.718;0.4333926;-0.142587;301.1472;31.11861;2;2;0;1.365016;1.355784;276376.2;3.154338e+007
777.718;0.6201425;-0.4126949;1254.733;129.656;2;2;0;1.953205;1.934374;1151525;1.321885e+008
805.718;0.8067316;-0.9083654;2261.258;233.6637;2;2;0;2.540887;2.509143;2075257;2.396009e+008
833.718;0.9935351;-1.671136;3142.725;324.7489;2;2;0;3.129244;3.081281;2884219;3.349111e+008
861.718;1.180285;-2.585555;3852.286;398.0703;2;2;0;3.717433;3.650002;3535415;4.128684e+008
888.15;1.163839;-2.656074;3228.457;333.6079;2;2;0;3.665633;3.600047;2962899;3.458368e+008
916.15;0.9772494;-1.752721;2257.996;233.3267;2;2;0;3.077951;3.031532;2072263;2.405084e+008
944.15;0.7904459;-0.8878031;1384.223;143.0367;2;2;0;2.489594;2.459108;1270364;1.465977e+008
972.15;0.6037496;-0.3541201;550.1587;56.84984;2;2;0;1.901574;1.88372;504905.2;5.793089e+007
1000.15;0.417214;-0.12612;53.94897;5.574738;2;2;0;1.31406;1.305501;49511.38;5647994
1026.722;0.3201426;-0.1201325;53.82323;5.561745;3;3;0;1.008323;1.003274;49395.98;5617825
1054.722;0.506839;-0.2332324;554.6527;57.31422;3;3;0;1.596343;1.583736;509029.5;5.822915e+007
1082.722;0.6933745;-0.5817043;1554.33;160.6144;3;3;0;2.183857;2.160352;1426478;1.64122e+008
1110.722;0.8800709;-1.17341;2549.175;263.4153;3;3;0;2.771877;2.734156;2339492;2.707168e+008
1138.722;1.06666;-2.007761;3377.841;349.0443;3;3;0;3.359559;3.304359;3099995;3.607706e+008
1166.722;1.253356;-2.897798;4081.061;421.7105;3;3;0;3.947579;3.871654;3745372;4.383578e+008
1192.392;1.139731;-2.541289;2979.057;307.8365;3;3;0;3.589705;3.526777;2734014;3.188869e+008
1220.392;0.9529816;-1.605721;2076.318;214.5533;3;3;0;3.001517;2.957353;1905530;2.209931e+008
1248.392;0.7662852;-0.8019509;1197.305;123.7218;3;3;0;2.413497;2.384832;1098820;1.267078e+008
1276.392;0.579696;-0.3175469;405.3474;41.88598;3;3;0;1.825814;1.809346;372005.4;4.265074e+007
1304.392;0.3928926;-0.1478403;53.88927;5.568569;3;3;0;1.237457;1.229863;49456.59;5637478
1331.336;0.3467141;-0.1433528;54.36075;5.617289;4;4;0;1.092013;1.086093;49889.29;5678630
1359.336;0.5334103;-0.2811548;629.0421;65.00114;4;4;0;1.680033;1.666076;577299.9;6.609318e+007
1387.336;0.7199995;-0.6586497;1627.922;168.2189;4;4;0;2.267715;2.242385;1494017;1.720337e+008
1415.336;0.9066959;-1.279254;2615.783;270.2981;4;4;0;2.855735;2.815719;2400621;2.780171e+008
1443.336;1.093285;-2.124986;3435.418;354.994;4;4;0;3.443417;3.385459;3152837;3.672179e+008
1471.334;1.280035;-2.998039;4148.06;428.6338;4;4;0;4.031606;3.952457;3806860;4.459146e+008
1497.762;1.103731;-2.350332;2769.934;286.2271;4;4;0;3.47632;3.41726;2542092;2.961772e+008
1525.762;0.9172494;-1.419312;1881.645;194.437;4;4;0;2.888974;2.84803;1726870;2.000543e+008
1553.762;0.7304995;-0.6903749;993.2963;102.6408;4;4;0;2.300786;2.274717;911592.3;1.050024e+008
1581.762;0.5439104;-0.2674555;258.3859;26.69993;4;4;0;1.713104;1.698595;237132.3;2.715733e+007
1609.762;0.3572676;-0.1643862;53.99628;5.579627;4;4;0;1.125252;1.118968;49554.79;5642411
1636.336;0.3800355;-0.160963;54.85366;5.668223;5;5;0;1.196962;1.189855;50341.65;5736069
1664.336;0.5666246;-0.3432486;761.1642;78.65379;5;5;0;1.784644;1.768907;698554.3;8.005748e+007
1692.336;0.7533745;-0.7583795;1763.314;182.2095;5;5;0;2.372833;2.345119;1618272;1.86533e+008
1720.336;0.9399101;-1.414517;2733.874;282.5009;5;5;0;2.960347;2.917375;2508998;2.908639e+008
1748.336;1.126767;-2.279106;3537.135;365.5047;5;5;0;3.548873;3.487352;3246187;3.78476e+008
1774.768;1.257053;-2.931139;3833.361;396.1148;5;5;0;3.959221;3.882853;3518047;4.117979e+008
1802.768;1.070571;-2.171609;2587.145;267.3389;5;5;0;3.371876;3.316275;2374339;2.763532e+008
1830.768;0.8838745;-1.26026;1697.126;175.37;5;5;0;2.783857;2.745812;1557528;1.80252e+008
1858.768;0.6972317;-0.5980065;818.8237;84.61195;5;5;0;2.196005;2.17224;751471;8.647003e+007
1886.768;0.5105354;-0.2319707;150.0124;15.50131;5;5;0;1.607985;1.595194;137673;1.575057e+007
1914.768;0.3238926;-0.1774412;53.7172;5.550788;5;5;0;1.020134;1.014966;49298.67;5607414
1941.336;0.4133033;-0.1768189;63.35945;6.547156;6;6;0;1.301743;1.293343;58147.79;6632383
1969.336;0.6000532;-0.4113133;910.1484;94.04886;6;6;0;1.889931;1.872294;835283.8;9.582631e+007
1997.336;0.7866423;-0.8627427;1907.819;197.1417;6;6;0;2.477614;2.447419;1750890;2.020261e+008
2025.336;0.9734458;-1.555;2862.429;295.7849;6;6;0;3.065971;3.019909;2626979;3.048536e+008
2053.336;1.160142;-2.430931;3648.139;376.9752;6;6;0;3.653991;3.588816;3348060;3.907498e+008
2079.034;1.245856;-2.89782;3663.699;378.583;6;6;0;3.923957;3.848926;3362340;3.934384e+008
2107.034;1.059267;-2.10427;2503.492;258.6946;6;6;0;3.336275;3.281829;2297566;2.673254e+008
2135.034;0.8724637;-1.208476;1611.469;166.5188;6;6;0;2.747917;2.71084;1478917;1.710946e+008
2160.062;0.7641423;-0.8033162;1097.59;113.4178;7;7;0;2.406747;2.378242;1007307;1.161475e+008
2188.062;0.5773925;-0.3354353;328.8939;33.98577;7;7;0;1.818559;1.802221;301840.6;3.460382e+007
2216.062;0.3908033;-0.1933466;53.92977;5.572753;7;7;0;1.230877;1.223363;49493.75;5641347
2242.666;0.3467141;-0.1891121;54.63231;5.64535;8;8;0;1.092013;1.086093;50138.51;5706998
2270.666;0.5334103;-0.3077475;531.7596;54.9486;8;8;0;1.680033;1.666076;488019.5;5.587175e+007
2298.666;0.7199995;-0.6813692;1516.536;156.709;8;8;0;2.267715;2.242385;1391793;1.602627e+008
2326.666;0.9066959;-1.288156;2513.859;259.766;8;8;0;2.855735;2.815719;2307081;2.671842e+008
2354.666;1.093285;-2.108754;3363.768;347.59;8;8;0;3.443417;3.385459;3087080;3.59559e+008
2382.666;1.280035;-2.966164;4110.146;424.7159;8;8;0;4.031606;3.952457;3772064;4.418388e+008
2408.32;1.124946;-2.414594;2832.82;292.7253;8;8;0;3.543136;3.481811;2599805;3.03097e+008
2436.32;0.9384102;-1.49949;1913.628;197.742;8;8;0;2.955622;2.912786;1756222;2.035865e+008
2464.32;0.7517138;-0.7654279;1016.822;105.0718;8;8;0;2.367603;2.34001;933182.6;1.075595e+008
2492.32;0.5650175;-0.3216981;275.1434;28.43155;8;8;0;1.779583;1.763933;252511.4;2.893751e+007
2520.32;0.3783212;-0.2039895;54.19164;5.599814;8;8;0;1.191563;1.18452;49734.08;5666539
2547.06;0.3601069;-0.2001829;54.53761;5.635564;9;9;0;1.134195;1.127811;50051.6;5699483
2575.06;0.5466961;-0.3345983;579.9482;59.9281;9;9;0;1.721877;1.707221;532244.4;6.095999e+007
2603.06;0.7333388;-0.723502;1566.295;161.8508;9;9;0;2.309729;2.283458;1437459;1.655892e+008
2631.06;0.919928;-1.343097;2558.442;264.3728;9;9;0;2.897411;2.856229;2347996;2.720328e+008
2659.06;1.106678;-2.171617;3402.927;351.6365;9;9;0;3.4856;3.426228;3123018;3.638932e+008
2686.258;1.288017;-2.994091;4135.109;427.2955;9;9;0;4.056746;3.97662;3794974;4.446298e+008
2712.728;1.111714;-2.345656;2754.17;284.5981;9;9;0;3.50146;3.441553;2527625;2.945632e+008
2740.728;0.9249637;-1.435934;1836.872;189.8104;9;9;0;2.913271;2.871642;1685779;1.953401e+008
2768.728;0.7382673;-0.7280973;941.487;97.28719;9;9;0;2.325251;2.298629;864044.6;9.954936e+007
2796.728;0.5515711;-0.3067236;225.0494;23.25515;9;9;0;1.737232;1.722314;206537.9;2.365915e+007
2824.728;0.3649819;-0.2135571;54.05762;5.585965;9;9;0;1.149549;1.142992;49611.09;5650178
2851.46;0.3733926;-0.2099435;54.58544;5.640507;10;10;0;1.17604;1.169178;50095.5;5706842
2879.46;0.5599818;-0.3618611;632.5391;65.3625;10;10;0;1.763722;1.748349;580509.3;6.651532e+007
2907.46;0.7465709;-0.7654319;1619.539;167.3527;10;10;0;2.351405;2.324185;1486323;1.712879e+008
2935.46;0.9333744;-1.39914;2607.634;269.4561;10;10;0;2.939762;2.897379;2393142;2.773774e+008
2963.46;1.120071;-2.233503;3446.347;356.1232;10;10;0;3.527782;3.466981;3162866;3.686865e+008
2991.46;1.30666;-3.072322;4200.627;434.0656;10;10;0;4.115464;4.033033;3855103;4.519294e+008
3017.014;1.178946;-2.667846;3007.549;310.7806;10;10;0;3.713215;3.645935;2760162;3.223206e+008
3045.014;0.9923564;-1.759577;2085.688;215.5216;10;10;0;3.125532;3.077682;1914129;2.222578e+008
3073.014;0.8057673;-0.9563937;1200.701;124.0727;10;10;0;2.53785;2.506181;1101937;1.272215e+008
3101.014;0.619071;-0.4355183;422.0546;43.6124;10;10;0;1.94983;1.931064;387338.4;4.446277e+007
3129.014;0.4323747;-0.2336508;54.47034;5.628613;10;10;0;1.36181;1.352621;49989.86;5705264
3155.86;0.3066427;-0.2279248;54.29782;5.610786;11;11;0;0.9658036;0.9611696;49831.53;5664975
3183.86;0.4934997;-0.2817465;286.1749;29.57147;11;11;0;1.55433;1.542374;262635.5;3.00311e+007
3211.86;0.6801424;-0.6059231;1228.369;126.9317;11;11;0;2.142181;2.119559;1127329;1.296508e+008
3239.86;0.8667316;-1.152042;2227.873;230.214;11;11;0;2.729863;2.693267;2044619;2.364986e+008
3267.86;1.053374;-1.914087;3132.889;323.7325;11;11;0;3.317714;3.263866;2875192;3.344731e+008
3295.86;1.240017;-2.781261;3895.752;402.5619;11;11;0;3.905566;3.831228;3575306;4.182842e+008
3322.112;1.168821;-2.595586;3032.224;313.3304;11;11;0;3.681325;3.615183;2782807;3.248652e+008
3350.112;0.9822315;-1.700514;2064.705;213.3533;11;11;0;3.093642;3.046754;1894872;2.199536e+008
3378.112;0.7956423;-0.9221571;1158.801;119.743;11;11;0;2.50596;2.475076;1063483;1.227437e+008
3406.112;0.608946;-0.4208928;383.1796;39.5953;11;11;0;1.91794;1.89978;351661;4.035472e+007
3434.112;0.4221962;-0.2414898;54.38553;5.61985;11;11;0;1.329752;1.320988;49912.03;5694580
3460.434;0.3134998;-0.2363207;54.57141;5.639057;12;12;0;0.9874009;0.982558;50082.61;5694737
3488.434;0.500089;-0.2960644;306.3443;31.65565;12;12;0;1.575083;1.562808;281145.9;3.215425e+007
3516.434;0.6868388;-0.6279873;1253.065;129.4836;12;12;0;2.163272;2.140205;1149994;1.322847e+008
3544.434;0.8734281;-1.181548;2253.19;232.8301;12;12;0;2.750955;2.713796;2067853;2.392352e+008
3572.434;1.060071;-1.94794;3154.555;325.9713;12;12;0;3.338805;3.284278;2895076;3.368549e+008
3600.434;1.246606;-2.809353;3920.86;405.1563;12;12;0;3.926319;3.851199;3598348;4.210641e+008
3626.696;1.162178;-2.562822;2993.916;309.3719;12;12;0;3.660403;3.595001;2747650;3.206962e+008
3654.696;0.9754815;-1.665996;2028.457;209.6076;12;12;0;3.072383;3.02613;1861605;2.160475e+008
3682.696;0.7888387;-0.9019804;1120.403;115.7753;12;12;0;2.484531;2.454169;1028244;1.186517e+008
3710.696;0.6021961;-0.4127419;353.3031;36.50806;12;12;0;1.89668;1.878918;324242;3.72005e+007
3738.696;0.4155533;-0.2482131;54.47309;5.628898;12;12;0;1.308829;1.300338;49992.39;5702570
3765.006;0.3201426;-0.243548;54.53103;5.634884;13;13;0;1.008323;1.003274;50045.56;5691702
3793.006;0.506839;-0.3095482;328.6579;33.96138;13;13;0;1.596343;1.583736;301624;3.450352e+007
3821.006;0.6933745;-0.6490357;1277.316;131.9896;13;13;0;2.183857;2.160352;1172250;1.34872e+008
3849.006;0.8800709;-1.20976;2278.471;235.4425;13;13;0;2.771877;2.734156;2091054;2.419686e+008
3877.006;1.06666;-1.979542;3176.796;328.2696;13;13;0;3.359559;3.304359;2915488;3.39298e+008
3905.006;1.253356;-2.837166;3946.5;407.8058;13;13;0;3.947579;3.871654;3621879;4.239043e+008
3931.268;1.155428;-2.52974;2954.137;305.2614;13;13;0;3.639143;3.57449;2711144;3.163704e+008
3959.268;0.9688923;-1.633602;1992.453;205.8872;13;13;0;3.051629;3.005993;1828563;2.121701e+008
3987.268;0.7821959;-0.8825037;1083.018;111.9121;13;13;0;2.463609;2.433752;993933.8;1.146691e+008
4015.268;0.5954996;-0.4044468;324.6884;33.5512;13;13;0;1.875589;1.858217;297981.1;3.418049e+007
4043.268;0.4087497;-0.254724;54.68388;5.650678;13;13;0;1.287401;1.279184;50185.83;5723425
4069.582;0.3266783;-0.2499236;54.91124;5.674173;14;14;0;1.028908;1.023651;50394.5;5732555
4097.582;0.5134282;-0.3222857;350.5044;36.21886;14;14;0;1.617097;1.604161;321673.5;3.680456e+007
4125.582;0.700071;-0.6697358;1303.292;134.6737;14;14;0;2.204948;2.18099;1196089;1.376432e+008
4153.582;0.8866601;-1.237599;2304.003;238.0808;14;14;0;2.79263;2.754347;2114486;2.447295e+008
4181.582;1.073303;-2.01168;3199.229;330.5876;14;14;0;3.380481;3.324599;2936075;3.417631e+008
4209.582;1.259999;-2.864603;3971.64;410.4036;14;14;0;3.968502;3.89178;3644951;4.266905e+008
4235.852;1.148785;-2.497734;2914.261;301.1409;14;14;0;3.618221;3.5543;2674547;3.120368e+008
4263.852;0.9621423;-1.600959;1954.7;201.9861;14;14;0;3.03037;2.985361;1793916;2.08107e+008
4291.852;0.7754995;-0.8632206;1046.209;108.1085;14;14;0;2.442518;2.413166;960152.8;1.107491e+008
4319.852;0.5888567;-0.3963059;297.6722;30.75952;14;14;0;1.854667;1.837678;273187.1;3.133001e+007
4347.852;0.4020533;-0.2603688;54.8349;5.666284;14;14;0;1.26631;1.258359;50324.43;5738037
4374.158;0.3335355;-0.2561626;54.90399;5.673424;15;15;0;1.050506;1.045026;50387.84;5733023
4402.158;0.5200711;-0.3351716;373.4211;38.58693;15;15;0;1.638019;1.624748;342705.2;3.921899e+007
4430.158;0.7067674;-0.6900479;1330.753;137.5115;15;15;0;2.226039;2.201624;1221292;1.405725e+008
4458.158;0.8933566;-1.264677;2331.917;240.9653;15;15;0;2.813722;2.774864;2140105;2.477454e+008
4486.158;1.080053;-2.043857;3223.413;333.0867;15;15;0;3.401741;3.345162;2958270;3.444174e+008
4514.158;1.266642;-2.890686;3998.569;413.1863;15;15;0;3.989423;3.911901;3669665;4.2967e+008
4540.425;1.142196;-2.465071;2876.309;297.2192;15;15;0;3.597467;3.534269;2639717;3.079116e+008
4568.425;0.9554994;-1.569559;1918.182;198.2126;15;15;0;3.009447;2.965052;1760402;2.041777e+008
4596.425;0.7688566;-0.8436966;1009.523;104.3176;15;15;0;2.421596;2.39274;926484.7;1.068438e+008
4624.425;0.5821603;-0.3881243;271.2268;28.02683;15;15;0;1.833576;1.816969;248917;2.854072e+007
4652.425;0.3955176;-0.2656541;55.08238;5.691857;15;15;0;1.245725;1.238029;50551.55;5762762
4678.737;0.3401783;-0.2614351;54.96436;5.679662;16;16;0;1.071428;1.065729;50443.25;5740516
4706.737;0.5268211;-0.3480111;397.6113;41.08658;16;16;0;1.659279;1.645663;364905.6;4.176832e+007
4734.737;0.7133567;-0.7104717;1357.619;140.2876;16;16;0;2.246793;2.221924;1245948;1.434395e+008
4762.737;0.8999994;-1.291935;2359.133;243.7776;16;16;0;2.834644;2.795211;2165082;2.506878e+008
4790.737;1.086642;-2.075314;3246.738;335.4969;16;16;0;3.422495;3.365231;2979676;3.469793e+008
4818.737;1.273392;-2.918413;4026.939;416.1178;16;16;0;4.010684;3.932343;3695701;4.32807e+008
4844.974;1.148731;-2.494237;2897.619;299.4212;16;16;0;3.618051;3.554137;2659274;3.102544e+008
4872.974;0.9621423;-1.599674;1939.421;200.4072;16;16;0;3.03037;2.985361;1779893;2.064803e+008
4900.974;0.7754995;-0.8668683;1031.025;106.5395;16;16;0;2.442518;2.413166;946217.6;1.091417e+008
4928.974;0.5888032;-0.4030828;286.9422;29.65076;16;16;0;1.854498;1.837512;263339.7;3.020063e+007
4956.974;0.4020533;-0.2713284;54.9683;5.680069;16;16;0;1.26631;1.258359;50446.86;5751996
4983.281;0.3334819;-0.2669261;55.20433;5.704459;17;17;0;1.050337;1.044859;50663.47;5764375
5011.281;0.5200711;-0.3430888;359.8112;37.18056;17;17;0;1.638019;1.624748;330214.8;3.778959e+007
5039.281;0.7067138;-0.697863;1314.288;135.81;17;17;0;2.22587;2.201459;1206180;1.38833e+008
5067.281;0.8933566;-1.269836;2315.881;239.3081;17;17;0;2.813722;2.774864;2125387;2.460416e+008
5095.281;1.079999;-2.044131;3212.765;331.9864;17;17;0;3.401572;3.344998;2948498;3.432792e+008
5123.281;1.266588;-2.887876;3993.744;412.6877;17;17;0;3.989255;3.911739;3665237;4.291509e+008
5149.704;1.157035;-2.527863;2938.902;303.6872;17;17;0;3.644205;3.579374;2697162;3.147542e+008
5177.704;0.9703387;-1.635678;1972.093;203.7833;17;17;0;3.056185;3.010414;1809878;2.100113e+008
5205.704;0.7836959;-0.8951233;1061.236;109.6612;17;17;0;2.468334;2.438363;973943.3;1.12368e+008
5233.704;0.5968925;-0.4208201;308.0644;31.83338;17;17;0;1.879976;1.862523;282724.4;3.243184e+007
5261.704;0.4103033;-0.2770087;55.04838;5.688344;17;17;0;1.292294;1.284015;50520.35;5761854
5288.251;0.3266783;-0.272244;55.22967;5.707078;18;18;0;1.028908;1.023651;50686.73;5765798
5316.251;0.5134818;-0.3388547;324.3201;33.51314;18;18;0;1.617265;1.604327;297643;3.405514e+007
5344.251;0.700071;-0.6851713;1271.131;131.3504;18;18;0;2.204948;2.18099;1166573;1.342466e+008
5372.251;0.8866601;-1.248668;2272.273;234.802;18;18;0;2.79263;2.754347;2085366;2.413592e+008
5400.251;1.073356;-2.014154;3177.149;328.3061;18;18;0;3.38065;3.324762;2915812;3.39405e+008
5428.251;1.259999;-2.859738;3960.883;409.2921;18;18;0;3.968502;3.89178;3635079;4.255348e+008
5454.669;1.163731;-2.555739;2975.486;307.4675;18;18;0;3.665296;3.599721;2730737;3.187371e+008
5482.669;0.9771421;-1.667209;2001.911;206.8645;18;18;0;3.077613;3.031204;1837243;2.13231e+008
5510.669;0.7902852;-0.9182391;1085.866;112.2064;18;18;0;2.489087;2.458614;996547.4;1.149993e+008
5538.669;0.6036425;-0.4365319;326.7794;33.76727;18;18;0;1.901236;1.883389;299900;3.440926e+007
5566.669;0.4171069;-0.2822282;55.17635;5.701567;18;18;0;1.313722;1.305168;50637.79;5776470
5593.219;0.3201426;-0.2772377;55.22844;5.70695;19;19;0;1.008323;1.003274;50685.6;5764494
5621.219;0.506839;-0.3343992;289.4174;29.90653;19;19;0;1.596343;1.583736;265611.3;3.038394e+007
5649.219;0.6933745;-0.6726115;1229.46;127.0445;19;19;0;2.183857;2.160352;1128330;1.298189e+008
5677.219;0.8800709;-1.227792;2229.219;230.3531;19;19;0;2.771877;2.734156;2045854;2.367382e+008
5705.219;1.06666;-1.984757;3142.899;324.7669;19;19;0;3.359559;3.304359;2884379;3.356777e+008
5733.219;1.253356;-2.830846;3930.219;406.1235;19;19;0;3.947579;3.871654;3606938;4.221555e+008
5759.363;1.167535;-2.570114;3002.744;310.2841;19;19;0;3.677276;3.611277;2755752;3.216942e+008
5787.363;0.9808387;-1.683846;2018.84;208.6139;19;19;0;3.089256;3.042499;1852779;2.150585e+008
5815.363;0.7943031;-0.9332539;1100.682;113.7374;19;19;0;2.501742;2.470961;1010145;1.165828e+008
5843.363;0.6074996;-0.4468265;337.4394;34.86881;19;19;0;1.913385;1.89531;309683.2;3.553598e+007
5871.363;0.4209104;-0.2866512;55.39761;5.724431;19;19;0;1.325702;1.316992;50840.86;5800320
5897.494;0.3134998;-0.2816932;55.45631;5.730496;20;20;0;0.9874009;0.982558;50894.73;5787079
5925.494;0.5000353;-0.3296783;255.6505;26.41727;20;20;0;1.574914;1.562641;234621.9;2.683332e+007
5953.494;0.6868388;-0.6606443;1189.894;122.956;20;20;0;2.163272;2.140205;1092019;1.256158e+008
5981.494;0.8734281;-1.206697;2186.942;225.9845;20;20;0;2.750955;2.713796;2007054;2.322012e+008
6009.494;1.060017;-1.95527;3109.233;321.2881;20;20;0;3.338637;3.284114;2853482;3.320147e+008
6037.494;1.246606;-2.801085;3899.391;402.9379;20;20;0;3.926319;3.851199;3578646;4.187585e+008
6063.928;1.177017;-2.609525;3054.125;315.5935;20;20;0;3.70714;3.640078;2802906;3.27293e+008
6091.928;0.9903208;-1.727623;2060.582;212.9272;20;20;0;3.119121;3.071465;1891088;2.195687e+008
6119.928;0.803678;-0.966071;1140.019;117.8022;20;20;0;2.53127;2.499763;1046246;1.207841e+008
6147.928;0.6168211;-0.4670822;365.8922;37.80894;20;20;0;1.942743;1.924113;335795.6;3.854347e+007
6175.928;0.4301783;-0.2910898;55.53858;5.738998;20;20;0;1.354892;1.345796;50970.23;5816756
6202.467;0.3066427;-0.2861601;55.25575;5.709772;21;21;0;0.9658036;0.9611696;50710.66;5764917
6230.467;0.4934997;-0.3258047;223.9192;23.13836;21;21;0;1.55433;1.542374;205500.6;2.349801e+007
6258.467;0.6801424;-0.6485255;1149.469;118.7787;21;21;0;2.142181;2.119559;1054919;1.213232e+008
6286.467;0.8667316;-1.185927;2144.423;221.5909;21;21;0;2.729863;2.693267;1968033;2.2764e+008
6314.467;1.053374;-1.925651;3074.751;317.7249;21;21;0;3.317714;3.263866;2821836;3.282661e+008
6342.467;1.240017;-2.771918;3869.367;399.8354;21;21;0;3.905566;3.831228;3551091;4.154512e+008
6370.467;1.426713;-3.622778;4515.046;466.5557;21;21;0;4.493586;4.39555;4143660;4.875208e+008
6395.943;1.435178;-3.817192;3855.46;398.3983;21;21;0;4.520244;4.421059;3538327;4.164069e+008
6423.943;1.248481;-3.082356;2732.737;282.3834;21;21;0;3.932225;3.856881;2507954;2.934873e+008
6451.943;1.061785;-2.147588;1946.882;201.1782;21;21;0;3.344205;3.289503;1786740;2.07906e+008
6479.943;0.8751423;-1.288815;1146.683;118.4908;21;21;0;2.756354;2.71905;1052362;1.217568e+008
6507.943;0.6882853;-0.674618;427.2198;44.14614;21;21;0;2.167828;2.144664;392078.7;4.510315e+007
6535.943;0.5016425;-0.4019771;55.5735;5.742606;21;21;0;1.579976;1.567625;51002.28;5833338
6563.943;0.3151069;-0.3920126;54.82562;5.665325;21;21;0;0.9924628;0.9875702;50315.91;5721551
6590.2;0.4199462;-0.3889631;55.92032;5.778445;22;22;0;1.322665;1.313994;51320.57;5854875
6618.2;0.6066961;-0.5420174;575.8564;59.50528;22;22;0;1.910854;1.892826;528489.1;6.064234e+007
6646.2;0.7934459;-0.9659854;1513.659;156.4117;22;22;0;2.499042;2.468327;1389152;1.603205e+008
6674.2;0.9799815;-1.607493;2489.37;257.2354;22;22;0;3.086556;3.03988;2284606;2.651752e+008
6702.2;1.166839;-2.42019;3349.712;346.1377;22;22;0;3.675082;3.609161;3074181;3.588585e+008
6730.2;1.353428;-3.282882;4087.191;422.3439;22;22;0;4.262765;4.174411;3750998;4.403475e+008
6756.025;1.494374;-3.950723;4426.329;457.3882;22;22;0;4.70669;4.599282;4062239;4.789161e+008
6783.879;1.308803;-3.331164;2997.806;309.7739;22;22;0;4.122213;4.039515;2751220;3.225434e+008
6811.879;1.122214;-2.455265;2147.622;221.9214;22;22;0;3.534531;3.4735;1970968;2.297652e+008
6839.879;0.9355173;-1.563616;1342.563;138.7317;22;22;0;2.946511;2.903936;1232130;1.428195e+008
6867.879;0.7487673;-0.8744361;584.2594;60.37359;22;22;0;2.358322;2.330944;536200.9;6.179739e+007
6895.879;0.562071;-0.4761747;69.21419;7.152148;22;22;0;1.770303;1.754815;63520.95;7278762
6923.879;0.3754819;-0.4509094;55.36906;5.721481;22;22;0;1.18262;1.175682;50814.66;5789145
6950.189;0.3601605;-0.4460607;55.58671;5.743972;23;23;0;1.134364;1.127978;51014.41;5809129
6978.189;0.5466961;-0.4940658;251.1431;25.95151;23;23;0;1.721877;1.707221;230485.2;2.639836e+007
7006.189;0.7333388;-0.8407755;1139.486;117.7471;23;23;0;2.309729;2.283458;1045757;1.204668e+008
7034.189;0.919928;-1.408499;2108.495;217.8782;23;23;0;2.897411;2.856229;1935060;2.24191e+008
7062.189;1.106678;-2.160752;3020.913;312.1616;23;23;0;3.4856;3.426228;2772426;3.230423e+008
7090.189;1.293428;-3.012977;3791.894;391.8299;23;23;0;4.073788;3.992996;3479991;4.077922e+008
7118.189;1.480017;-3.849508;4514.361;466.4849;23;23;0;4.661471;4.556087;4143031;4.8823e+008
7143.425;1.392428;-3.656549;3447.012;356.192;23;23;0;4.385599;4.292154;3163477;3.718131e+008
7171.425;1.205785;-2.862568;2458.579;254.0537;23;23;0;3.797748;3.727409;2256348;2.63702e+008
7199.425;1.019249;-1.951774;1648.921;170.3889;23;23;0;3.210234;3.159783;1513289;1.758587e+008
7227.425;0.8325531;-1.170731;857.0709;88.56418;23;23;0;2.622214;2.588424;786572.3;9.088652e+007
7255.425;0.6459103;-0.6392635;230.7103;23.84012;23;23;0;2.034363;2.013946;211733.2;2.432511e+007
7283.425;0.4592676;-0.4989301;55.4731;5.732232;23;23;0;1.446512;1.43615;50910.14;5815149
7310.299;0.2799641;-0.4911651;55.2001;5.704022;24;24;0;0.8817767;0.8779117;50659.59;5754319
7338.299;0.4667676;-0.4896873;56.67179;5.856097;24;24;0;1.470134;1.459432;52010.23;5942189
7366.299;0.6533567;-0.6949479;699.8982;72.32296;24;24;0;2.057816;2.036929;642327.8;7.381124e+007
7394.299;0.8402138;-1.159751;1630.162;168.4504;24;24;0;2.646343;2.611933;1496072;1.729081e+008
7422.299;1.026803;-1.831069;2587.605;267.3864;24;24;0;3.234025;3.182831;2374761;2.760337e+008
7450.299;1.213338;-2.651322;3422.403;353.649;24;24;0;3.821538;3.750326;3140892;3.671638e+008
7478.299;1.399928;-3.506148;4163.07;430.1848;24;24;0;4.409221;4.314781;3820635;4.491526e+008
7503.963;1.48907;-3.954049;4169.534;430.8527;24;24;0;4.689986;4.583328;3826568;4.510597e+008
7531.963;1.302374;-3.295571;2872.043;296.7784;24;24;0;4.101966;4.020067;2635802;3.089522e+008
7559.963;1.115678;-2.423913;2027.383;209.4967;24;24;0;3.513946;3.453616;1860620;2.168583e+008
7587.963;0.9289815;-1.560992;1222.628;126.3385;24;24;0;2.925926;2.883938;1122060;1.300351e+008
7615.963;0.7423924;-0.8954034;495.9561;51.24891;24;24;0;2.338244;2.311326;455161.1;5.244723e+007
7643.963;0.5555354;-0.5436367;56.12305;5.799394;24;24;0;1.749718;1.734586;51506.63;5900867
7671.963;0.3688926;-0.5306938;55.33656;5.718122;24;24;0;1.161867;1.155169;50784.82;5784559
7698.304;0.3666962;-0.526678;55.92411;5.778836;25;25;0;1.154949;1.14833;51324.05;5845579
7726.304;0.5533389;-0.5646663;216.3712;22.3584;25;25;0;1.7428;1.727787;198573.5;2.274807e+007
7754.304;0.7399281;-0.9058565;1082.834;111.893;25;25;0;2.330482;2.303741;993764.7;1.145007e+008
7782.304;0.9267315;-1.468991;2039.845;210.7844;25;25;0;2.918839;2.877052;1872056;2.169368e+008
7810.304;1.113321;-2.210234;2953.569;305.2028;25;25;0;3.506522;3.446444;2710623;3.159048e+008
7838.304;1.300071;-3.052573;3733.879;385.835;25;25;0;4.09471;4.013098;3426748;4.016338e+008
7866.304;1.48682;-3.867998;4485.683;463.5215;25;25;0;4.682899;4.576558;4116712;4.852278e+008
7891.99;1.402124;-3.68075;3447.012;356.192;25;25;0;4.416139;4.321406;3163477;3.719219e+008
7919.99;1.215428;-2.895905;2443.94;252.541;25;25;0;3.828119;3.756664;2242913;2.622085e+008
7947.99;1.028892;-2.003182;1624.358;167.8506;25;25;0;3.240605;3.189205;1490746;1.7329e+008
7975.99;0.8421423;-1.229079;834.6353;86.24583;25;25;0;2.652417;2.61785;765982.1;8.853342e+007
8003.99;0.6554995;-0.6975248;219.2615;22.65707;25;25;0;2.064565;2.043542;201226.1;2.312484e+007
8031.99;0.468964;-0.5643844;55.9666;5.783227;25;25;0;1.477052;1.46625;51363.05;5868648
8059.99;0.2822677;-0.5566112;55.56431;5.741657;25;25;0;0.889032;0.8851034;50993.84;5792702
8086.311;0.4533747;-0.5553092;56.76455;5.865682;26;26;0;1.427952;1.417853;52095.36;5949441
8114.311;0.6401246;-0.7143187;573.9897;59.31239;26;26;0;2.01614;1.996085;526775.9;6.050821e+007
8142.311;0.8267138;-1.152805;1482.514;153.1935;26;26;0;2.603823;2.570501;1360570;1.571823e+008
8170.311;1.013517;-1.801866;2443.71;252.5172;26;26;0;3.19218;3.142289;2242702;2.60578e+008
8198.311;1.200106;-2.600191;3299.445;340.9433;26;26;0;3.779862;3.710176;3028048;3.538305e+008
8226.311;1.386696;-3.446193;4056.436;419.1659;26;26;0;4.367545;4.274857;3722772;4.374732e+008
8252.021;1.501928;-3.972293;4277.534;442.0128;26;26;0;4.730481;4.622001;3925684;4.629221e+008
8280.021;1.315446;-3.333733;2917.215;301.4462;26;26;0;4.143136;4.059607;2677258;3.139355e+008
8308.021;1.128749;-2.479089;2048.058;211.6331;26;26;0;3.555116;3.49338;1879594;2.191569e+008
8336.021;0.9421066;-1.624306;1234.367;127.5515;26;26;0;2.967265;2.924093;1132834;1.313363e+008
8364.021;0.7554102;-0.9541705;503.3544;52.01339;26;26;0;2.379245;2.351382;461950.8;5.325092e+007
8392.021;0.5687675;-0.5958775;56.32065;5.819812;26;26;0;1.791394;1.775537;51687.97;5924068
8420.021;0.3819641;-0.5834261;55.97518;5.784113;26;26;0;1.203036;1.195857;51370.92;5853698
8446.32;0.3534641;-0.5793141;56.18786;5.80609;27;27;0;1.113273;1.107121;51566.11;5870728
8474.32;0.5399996;-0.5945103;131.9222;13.63199;27;27;0;1.700786;1.686485;121070.9;1.386384e+007
8502.32;0.7266424;-0.9073402;966.0241;99.82269;27;27;0;2.288637;2.262841;886563.4;1.021073e+008
8530.32;0.9132852;-1.446261;1910.097;197.3771;27;27;0;2.876489;2.835894;1752982;2.030547e+008
8558.32;1.100089;-2.167381;2837.39;293.1976;27;27;0;3.464846;3.406172;2604000;3.033564e+008
8586.32;1.286678;-2.995504;3634.482;375.5639;27;27;0;4.052528;3.972567;3335526;3.907837e+008
8614.32;1.473481;-3.807711;4399.275;454.5927;27;27;0;4.640885;4.536416;4037411;4.756898e+008
8640.032;1.41541;-3.711166;3525.107;364.2618;27;27;0;4.457983;4.361473;3235148;3.805005e+008
8668.032;1.22866;-2.942438;2483.056;256.5829;27;27;0;3.869795;3.796795;2278811;2.665122e+008
8696.032;1.04191;-2.06146;1650.152;170.516;27;27;0;3.281606;3.228912;1514418;1.761117e+008
8724.032;0.8553745;-1.288985;855.5854;88.41068;27;27;0;2.694093;2.658441;785208.9;9.079254e+007
8752.032;0.6685709;-0.7495116;232.3752;24.01215;27;27;0;2.105735;2.083871;213261.1;2.451778e+007
8780.032;0.4820354;-0.6076154;56.14599;5.801764;27;27;0;1.518222;1.506812;51527.68;5889848
8808.032;0.2954462;-0.600406;55.8453;5.770692;27;27;0;0.9305393;0.9262364;51251.72;5824391
8834.328;0.4399283;-0.5991447;57.09684;5.900019;28;28;0;1.385601;1.376089;52400.32;5981769
8862.328;0.6267317;-0.7217367;475.679;49.1536;28;28;0;1.973958;1.954728;436551.9;5.012387e+007
8890.328;0.8134816;-1.138663;1370.421;141.6105;28;28;0;2.562147;2.529874;1257697;1.452388e+008
8918.328;1.000071;-1.767244;2328.9;240.6534;28;28;0;3.149829;3.10124;2137335;2.482336e+008
8946.328;1.186821;-2.547702;3204.007;331.0814;28;28;0;3.738018;3.669848;2940460;3.434573e+008
8974.328;1.37341;-3.385596;3973.728;410.6194;28;28;0;4.3257;4.234755;3646868;4.283816e+008
9000.229;1.514088;-3.988208;4414.549;456.171;28;28;0;4.768782;4.658566;4051429;4.779248e+008
9028.062;1.328463;-3.373075;2976.917;307.6153;28;28;0;4.184137;4.098969;2732049;3.204864e+008
9056.062;1.141928;-2.531998;2085.402;215.492;28;28;0;3.596623;3.533455;1913867;2.232424e+008
9084.062;0.9552315;-1.680981;1261.643;130.37;28;28;0;3.008603;2.964232;1157866;1.342923e+008
9112.062;0.7685888;-1.00667;522.9372;54.03695;28;28;0;2.420752;2.391916;479922.8;5.534505e+007
9140.062;0.5818925;-0.6340089;57.55904;5.947779;28;28;0;1.832732;1.81614;52824.49;6056786
9168.062;0.3952497;-0.6207149;56.15404;5.802595;28;28;0;1.244881;1.237196;51535.06;5874831
9194.332;0.3401783;-0.6166274;56.26503;5.814065;29;29;0;1.071428;1.065729;51636.93;5876359
9222.332;0.5268211;-0.6186133;70.81247;7.317303;29;29;0;1.659279;1.645663;64987.76;7438718
9250.332;0.7133567;-0.9012262;866.0879;89.49593;29;29;0;2.246793;2.221924;794847.4;9.150671e+007
9278.332;0.8999994;-1.419712;1800.529;186.0551;29;29;0;2.834644;2.795211;1652426;1.91329e+008
9306.332;1.086642;-2.122687;2736.826;282.8059;29;29;0;3.422495;3.365231;2511708;2.92485e+008
9334.332;1.273446;-2.939498;3551.548;366.994;29;29;0;4.010852;3.932506;3259414;3.817136e+008
9362.332;1.459981;-3.749319;4322.858;446.6962;29;29;0;4.598366;4.495774;3967279;4.672369e+008
9388.064;1.428588;-3.744015;3614.137;373.4616;29;29;0;4.499491;4.401202;3316855;3.902655e+008
9416.064;1.241946;-2.993327;2532.988;261.7426;29;29;0;3.91164;3.837073;2324636;2.719811e+008
9444.064;1.055196;-2.120401;1689.297;174.561;29;29;0;3.323451;3.269418;1550343;1.803625e+008
9472.064;0.8684459;-1.345022;886.3148;91.58604;29;29;0;2.735263;2.698523;813410.6;9.409116e+007
9500.064;0.6818567;-0.7951234;252.9758;26.14089;29;29;0;2.14758;2.124845;232167.2;2.670228e+007
9528.064;0.4951068;-0.6395449;56.71108;5.860157;29;29;0;1.559391;1.547358;52046.29;5951539
9556.064;0.3085177;-0.6327564;56.27707;5.815309;29;29;0;0.9717092;0.9670184;51647.98;5871817
9582.337;0.4266962;-0.6311079;57.05077;5.895258;30;30;0;1.343925;1.334974;52358.03;5974486
9610.337;0.6132318;-0.723637;389.6102;40.2598;30;30;0;1.931439;1.913023;357562.7;4.10374e+007
9638.337;0.8000887;-1.120636;1271.095;131.3468;30;30;0;2.519964;2.488737;1166541;1.346567e+008
9666.337;0.9867851;-1.731776;2228.398;230.2683;30;30;0;3.107985;3.060665;2045101;2.37425e+008
9694.337;1.173374;-2.495671;3116.415;322.0302;30;30;0;3.695667;3.629014;2860073;3.339314e+008
9722.337;1.360124;-3.326744;3897.751;402.7684;30;30;0;4.283855;4.194637;3577140;4.200224e+008
9750.337;1.54666;-4.075356;4698.237;485.4854;30;30;0;4.871369;4.756436;4311782;5.091352e+008
9778.337;1.733356;-4.834424;5219.088;539.3068;30;30;0;5.459389;5.315576;4789790;5.687497e+008
9802.748;1.665053;-4.753799;4045.37;418.0224;30;30;0;5.24426;5.111375;3712616;4.399446e+008
9830.748;1.478517;-4.136785;2881.957;297.8028;30;30;0;4.656746;4.551573;2644900;3.116707e+008
9858.748;1.291821;-3.317115;2090.888;216.0589;30;30;0;4.068726;3.988132;1918901;2.248497e+008
9886.748;1.105178;-2.411726;1399.711;144.6371;30;30;0;3.480875;3.421663;1284577;1.496717e+008
9914.748;0.9184816;-1.58918;716.6528;74.05427;30;30;0;2.892855;2.851802;657704.2;7.619655e+007
9942.748;0.7318924;-0.9955484;188.3013;19.45784;30;30;0;2.305173;2.279005;172812.5;1.990637e+007
9970.748;0.5450889;-0.8499341;56.61456;5.850183;30;30;0;1.716815;1.702245;51957.7;5950619
9998.748;0.3583926;-0.8407624;56.15586;5.802783;30;30;0;1.128796;1.122472;51536.73;5868285
10025.51;0.3800355;-0.8374845;56.49199;5.837517;31;31;0;1.196962;1.189855;51845.22;5907390
10053.51;0.5666246;-0.836573;58.54547;6.049711;31;31;0;1.784644;1.768907;53729.79;6157677
10081.51;0.7533745;-1.076668;743.808;76.86031;31;31;0;2.372833;2.345119;682625.8;7.868408e+007
10109.51;0.9399637;-1.58041;1641.91;169.6644;31;31;0;2.960516;2.917539;1506854;1.746873e+008
10137.51;1.126767;-2.270778;2568.233;265.3846;31;31;0;3.548873;3.487352;2356982;2.748028e+008
10165.51;1.313517;-3.071586;3382.895;349.5665;31;31;0;4.137062;4.053774;3104633;3.640282e+008
10193.51;1.500053;-3.896675;4131.999;426.9741;31;31;0;4.724575;4.616362;3792120;4.471468e+008
10221.51;1.686856;-4.657984;4897.593;506.0857;31;31;0;5.312932;5.176604;4494740;5.329737e+008
10246.62;1.701963;-4.832817;4332.728;447.7161;31;31;0;5.360514;5.221775;3976338;4.71716e+008
10274.62;1.515106;-4.254443;3015.239;311.5753;31;31;0;4.771988;4.661626;2767219;3.264436e+008
10302.62;1.328463;-3.480238;2165.425;223.761;31;31;0;4.184137;4.098969;1987307;2.331235e+008
10330.62;1.141928;-2.598316;1453.592;150.2048;31;31;0;3.596623;3.533455;1334026;1.556071e+008
10358.62;0.9552315;-1.769812;764.8636;79.03606;31;31;0;3.008603;2.964232;701949.5;8.141395e+007
10386.62;0.7685888;-1.143857;223.3305;23.07753;31;31;0;2.420752;2.391916;204960.4;2.363618e+007
10414.62;0.581946;-0.9625497;56.8609;5.875638;31;31;0;1.832901;1.816306;52183.78;5983332
10442.62;0.3953033;-0.9523077;56.37782;5.82572;31;31;0;1.24505;1.237363;51740.44;5898253
10468.9;0.3401783;-0.9468731;56.466;5.834832;32;32;0;1.071428;1.065729;51821.37;5897348
10496.9;0.5268211;-0.9460859;57.94007;5.987153;32;32;0;1.659279;1.645663;53174.19;6086496
10524.9;0.7133567;-1.075589;483.6025;49.97235;32;32;0;2.246793;2.221924;443823.5;5.109513e+007
10552.9;0.8999994;-1.508958;1341.499;138.6219;32;32;0;2.834644;2.795211;1231154;1.425513e+008
10580.9;1.086642;-2.14955;2262.464;233.7884;32;32;0;3.422495;3.365231;2076364;2.417898e+008
10608.9;1.273446;-2.913357;3109.648;321.3309;32;32;0;4.010852;3.932506;2853862;3.34219e+008
10636.9;1.459981;-3.743781;3873.844;400.298;32;32;0;4.598366;4.495774;3555199;4.187052e+008
10664.9;1.646785;-4.508826;4644.014;479.8824;32;32;0;5.186723;5.05669;4262019;5.047726e+008
10690.08;1.741499;-4.920973;4708.51;486.547;32;32;0;5.485036;5.339892;4321210;5.132343e+008
10718.08;1.554749;-4.383282;3209.169;331.6147;32;32;0;4.896847;4.780728;2945197;3.478534e+008
10746.08;1.367999;-3.653428;2295.986;237.2524;32;32;0;4.308659;4.218419;2107129;2.474748e+008
10774.08;1.181464;-2.786983;1556.704;160.8598;32;32;0;3.721145;3.653581;1428657;1.668456e+008
10802.08;0.9946065;-1.947641;857.3009;88.58794;32;32;0;3.132619;3.084553;786783.3;9.136306e+007
10830.08;0.8079637;-1.285107;285.5965;29.51169;32;32;0;2.544768;2.512927;262104.6;3.02627e+007
10858.08;0.6214282;-1.039984;57.16608;5.907174;32;32;0;1.957254;1.938346;52463.86;6022792
10886.08;0.4347854;-1.028628;56.61555;5.850286;32;32;0;1.369403;1.360111;51958.62;5930400
10912.28;0.3001069;-1.020664;56.77779;5.86705;33;33;0;0.9452187;0.9407795;52107.51;5922507
10940.28;0.4868033;-1.020309;57.40197;5.931548;33;33;0;1.533239;1.521603;52680.34;6022493
10968.28;0.6733389;-1.075151;276.7583;28.59842;33;33;0;2.120752;2.098577;253993.5;2.920492e+007
10996.28;0.8601423;-1.440069;1088.831;112.5128;33;33;0;2.70911;2.673063;999269;1.155609e+008
11024.28;1.046731;-2.027805;1993.448;205.99;33;33;0;3.296792;3.243614;1829476;2.127811e+008
11052.28;1.233374;-2.760389;2869.911;296.5581;33;33;0;3.884643;3.81109;2633846;3.080783e+008
11080.28;1.419963;-3.580481;3654.459;377.6281;33;33;0;4.472326;4.375202;3353860;3.945169e+008
11108.28;1.60666;-4.354744;4417.225;456.4475;33;33;0;5.060345;4.936472;4053884;4.795453e+008
11134.69;1.773588;-4.98177;5135.996;530.7206;33;33;0;5.586104;5.435659;4713533;5.603673e+008
11161.49;1.594606;-4.506651;3436.22;355.0768;33;33;0;5.022382;4.90033;3153573;3.729101e+008
11189.49;1.408017;-3.819973;2450.993;253.2698;33;33;0;4.434699;4.33918;2249386;2.645016e+008
11217.49;1.221321;-2.971218;1680.128;173.6136;33;33;0;3.846679;3.774538;1541929;1.802919e+008
11245.49;1.034571;-2.125895;972.5438;100.4964;33;33;0;3.258491;3.206528;892546.9;1.037711e+008
11273.49;0.8478208;-1.424501;365.868;37.80643;33;33;0;2.670302;2.635272;335773.3;3.881598e+007
11301.49;0.6612853;-1.098798;57.20663;5.911364;33;33;0;2.082788;2.061395;52501.08;6034485
11329.49;0.4744283;-1.085731;56.81987;5.871399;33;33;0;1.494262;1.483208;52146.13;5959133
11357.49;0.2878391;-1.073848;45.37308;4.688561;33;33;0;0.9065799;0.9024951;41640.9;4731067
11383.67;0.4467319;-1.07525;57.33492;5.924621;34;34;0;1.40703;1.397223;52618.82;6007982
11411.67;0.633321;-1.084714;117.6916;12.16149;34;34;0;1.994712;1.975078;108010.9;1.240408e+007
11439.67;0.8201245;-1.372516;855.9137;88.4446;34;34;0;2.583069;2.550272;785510.2;9.072918e+007
11467.67;1.006821;-1.910173;1747.652;180.591;34;34;0;3.171089;3.121848;1603898;1.863177e+008
11495.67;1.193356;-2.613599;2647.024;273.5263;34;34;0;3.758603;3.689689;2429292;2.838071e+008
11523.67;1.379999;-3.414052;3452.515;356.7606;34;34;0;4.346454;4.254646;3168527;3.72267e+008
11551.67;1.566642;-4.20055;4213.931;435.4404;34;34;0;4.934305;4.81643;3867312;4.569263e+008
11579.67;1.753338;-4.896644;5076.659;524.5892;34;34;0;5.522325;5.375235;4659077;5.535587e+008
11604.88;1.63457;-4.625105;3703.162;382.6609;34;34;0;5.148253;5.02011;3398557;4.023612e+008
11632.88;1.448035;-3.977014;2623.395;271.0847;34;34;0;4.56074;4.459795;2407607;2.834482e+008
11660.88;1.261338;-3.153159;1818.434;187.9052;34;34;0;3.97272;3.895837;1668858;1.953702e+008
11688.88;1.074696;-2.30644;1102.998;113.9767;34;34;0;3.384869;3.328843;1012270;1.178346e+008
11716.88;0.8879995;-1.570219;461.3948;47.67756;34;34;0;2.796849;2.758451;423442.6;4.901103e+007
11744.88;0.7014102;-1.147129;58.8553;6.081727;34;34;0;2.209166;2.185118;54014.13;6216082
11772.88;0.5146068;-1.13049;56.94608;5.88444;34;34;0;1.620809;1.607814;52261.96;5979816
11800.88;0.3278569;-1.121301;54.45739;5.627275;34;34;0;1.03262;1.027325;49977.97;5685383
11827.07;0.406714;-1.11771;57.15745;5.906281;35;35;0;1.280989;1.272854;52455.94;5981940
11855.07;0.5932496;-1.117278;59.11688;6.108757;35;35;0;1.868503;1.851261;54254.2;6222899
11883.07;0.7800531;-1.314553;642.5753;66.39958;35;35;0;2.45686;2.427165;589720;6.803093e+007
11911.07;0.966803;-1.80028;1516.534;156.7088;35;35;0;3.045049;2.999607;1391791;1.614807e+008
11939.07;1.153339;-2.471578;2427.46;250.838;35;35;0;3.632562;3.56814;2227788;2.599499e+008
11967.07;1.340195;-3.246627;3254.369;336.2855;35;35;0;4.221088;4.13443;2986680;3.504804e+008
11995.07;1.526785;-4.046372;4024.559;415.8719;35;35;0;4.808771;4.696727;3693517;4.358703e+008
12023.07;1.71332;-4.75603;4860.692;502.2725;35;35;0;5.396285;5.25572;4460874;5.293765e+008
12048.3;1.674427;-4.733446;4014.163;414.7977;35;35;0;5.273787;5.139427;3683977;4.366732e+008
12076.3;1.487838;-4.122477;2810.527;290.4217;35;35;0;4.686105;4.579621;2579346;3.040311e+008
12104.3;1.300981;-3.330162;1964.051;202.9524;35;35;0;4.097579;4.015853;1802497;2.112685e+008
12132.3;1.114392;-2.482387;1236.537;127.7758;35;35;0;3.509896;3.449704;1134825;1.322606e+008
12160.3;0.9278566;-1.717741;568.1193;58.70577;35;35;0;2.922383;2.880495;521388.4;6.042138e+007
12188.3;0.7411602;-1.210463;98.24985;10.1525;35;35;0;2.334363;2.307533;90168.27;1.03895e+007
12216.3;0.5545175;-1.167299;57.35293;5.926481;35;35;0;1.746512;1.731436;52635.34;6029988
12244.3;0.3678212;-1.157522;56.6547;5.854331;35;35;0;1.158492;1.151833;51994.54;5922152
12270.46;0.3666962;-1.152373;57.13965;5.904443;36;36;0;1.154949;1.14833;52439.61;5972636
12298.46;0.5533389;-1.152693;58.55387;6.050579;36;36;0;1.7428;1.727787;53737.5;6156028
12326.46;0.7399816;-1.268582;454.6097;46.97643;36;36;0;2.330651;2.303906;417215.6;4.807129e+007
12354.46;0.9267315;-1.697148;1300.41;134.3759;36;36;0;2.918839;2.877052;1193444;1.382982e+008
12382.46;1.113321;-2.33021;2210.021;228.3693;36;36;0;3.506522;3.446444;2028235;2.363771e+008
12410.46;1.300071;-3.078034;3057.663;315.9591;36;36;0;4.09471;4.013098;2806154;3.288967e+008
12438.46;1.48682;-3.882918;3839.282;396.7266;36;36;0;4.682899;4.576558;3523480;4.153049e+008
12466.46;1.673356;-4.611574;4655.826;481.103;36;36;0;5.270413;5.136222;4272860;5.064591e+008
12491.69;1.714445;-4.830498;4376.447;452.2338;36;36;0;5.399828;5.259082;4016461;4.766536e+008
12519.69;1.527803;-4.260292;3017.086;311.7662;36;36;0;4.811977;4.699786;2768915;3.267683e+008
12547.69;1.340999;-3.504251;2121.849;219.2582;36;36;0;4.223619;4.136859;1947316;2.285188e+008
12575.69;1.154249;-2.656917;1374.94;142.0775;36;36;0;3.635431;3.570908;1261844;1.472426e+008
12603.69;0.9677673;-1.86832;683.9055;70.67038;36;36;0;3.048086;3.002555;627650.6;7.282447e+007
12631.69;0.7809637;-1.298281;162.8223;16.825;36;36;0;2.459728;2.429964;149429.3;1.723885e+007
12659.69;0.5944282;-1.197667;57.39413;5.930738;36;36;0;1.872215;1.854904;52673.15;6041774
12687.69;0.407839;-1.18739;57.14952;5.905462;36;36;0;1.284532;1.276352;52448.66;5981320
12713.85;0.3266783;-1.180717;57.43823;5.935296;37;37;0;1.028908;1.023651;52713.63;5996365
12741.85;0.5134818;-1.181428;58.10075;6.003756;37;37;0;1.617265;1.604327;53321.65;6100853
12769.85;0.700071;-1.236125;283.3557;29.28015;37;37;0;2.204948;2.18099;260048.2;2.992576e+007
12797.85;0.8866601;-1.604021;1092.838;112.9268;37;37;0;2.79263;2.754347;1002946;1.160804e+008
12825.85;1.073303;-2.192751;1991.265;205.7644;37;37;0;3.380481;3.324599;1827472;2.127202e+008
12853.85;1.259999;-2.916109;2859.946;295.5283;37;37;0;3.968502;3.89178;2624700;3.072564e+008
12881.85;1.446803;-3.717346;3657.048;377.8957;37;37;0;4.556859;4.456084;3356236;3.951159e+008
12909.85;1.633338;-4.46133;4453.996;460.2472;37;37;0;5.144372;5.01642;4087631;4.83924e+008
12935.24;1.753392;-4.919177;4799.531;495.9525;37;37;0;5.522493;5.375395;4404743;5.233414e+008
12963.09;1.567767;-4.390757;3241.493;334.9549;37;37;0;4.937849;4.819807;2974862;3.514945e+008
12991.09;1.381124;-3.676132;2291.908;236.831;37;37;0;4.349998;4.258042;2103387;2.471332e+008
13019.09;1.194428;-2.833082;1520.052;157.0723;37;37;0;3.761977;3.692941;1395019;1.629814e+008
13047.09;1.007785;-2.025805;810.7834;83.78112;37;37;0;3.174126;3.124792;744092.1;8.644044e+007
13075.09;0.820928;-1.400744;243.6402;25.17621;37;37;0;2.5856;2.552739;223599.5;2.582716e+007
13103.09;0.6342317;-1.224805;57.89579;5.982576;37;37;0;1.99758;1.97789;53133.54;6102083
13131.09;0.4477497;-1.212934;57.31117;5.922166;37;37;0;1.410235;1.400384;52597.02;6005682
13157.24;0.2864998;-1.203504;46.3178;4.786182;38;38;0;0.9023617;0.8983147;42507.91;4829371
13185.24;0.473464;-1.205644;58.11717;6.005453;38;38;0;1.491225;1.480216;53336.71;6095007
13213.24;0.6601602;-1.21896;138.2526;14.28613;38;38;0;2.079245;2.057924;126880.5;1.458317e+007
13241.24;0.8466959;-1.514645;880.7702;91.0131;38;38;0;2.666759;2.631821;808322.1;9.34402e+007
13269.24;1.033446;-2.058091;1770.188;182.9198;38;38;0;3.254947;3.203096;1624580;1.888737e+008
13297.24;1.219981;-2.758042;2660.365;274.9049;38;38;0;3.842461;3.770477;2441535;2.85468e+008
13325.24;1.406678;-3.547783;3473.354;358.914;38;38;0;4.43048;4.335141;3187652;3.748156e+008
13353.24;1.593213;-4.30606;4257.1;439.9012;38;38;0;5.017994;4.896153;3906930;4.619754e+008
13380.94;1.778034;-4.960282;5167.443;533.9702;38;38;0;5.600109;5.448921;4742393;5.638731e+008
13406.5;1.60757;-4.513991;3488.495;360.4786;38;38;0;5.063214;4.939202;3201548;3.787304e+008
13434.5;1.420981;-3.837872;2467.685;254.9947;38;38;0;4.475532;4.378271;2264705;2.66407e+008
13462.5;1.234392;-3.007936;1667.662;172.3254;38;38;0;3.887849;3.814175;1530488;1.790251e+008
13490.5;1.047696;-2.188663;947.051;97.86214;38;38;0;3.299829;3.246554;869150.9;1.010914e+008
13518.5;0.8609994;-1.51564;338.2849;34.95618;38;38;0;2.711809;2.675691;310459.2;3.590412e+007
13546.5;0.6742495;-1.248582;58.08809;6.002449;38;38;0;2.123621;2.101386;53310.04;6129918
13574.5;0.487714;-1.235206;57.38543;5.92984;38;38;0;1.536107;1.524428;52665.17;6020929
13602.5;0.300857;-1.225224;46.01029;4.754406;38;38;0;0.9475809;0.9431196;42225.7;4799458
13628.64;0.433339;-1.227136;57.88933;5.981909;39;39;0;1.364847;1.355617;53127.62;6063553
13656.64;0.6200889;-1.226909;60.1787;6.218478;39;39;0;1.953036;1.934209;55228.68;6339927
13684.64;0.8066781;-1.438309;679.663;70.23199;39;39;0;2.540718;2.508979;623757.1;7.201639e+007
13712.64;0.9934815;-1.933541;1554.395;160.6211;39;39;0;3.129076;3.081118;1426538;1.656471e+008
13740.64;1.180178;-2.60682;2461.52;254.3575;39;39;0;3.717095;3.649677;2259046;2.638122e+008
13768.64;1.366713;-3.376479;3288.785;339.8417;39;39;0;4.304609;4.214537;3018264;3.544706e+008
13796.64;1.553356;-4.15117;4073.183;420.8965;39;39;0;4.89246;4.776545;3738142;4.414887e+008
13824.64;1.739999;-4.831084;4955.541;512.0736;39;39;0;5.480311;5.335413;4547921;5.401368e+008
13849.9;1.647428;-4.63016;3771.293;389.701;39;39;0;5.188748;5.058615;3461084;4.099216e+008
13877.9;1.460731;-3.989623;2652.808;274.1241;39;39;0;4.600729;4.498033;2434601;2.867358e+008
13905.9;1.274196;-3.182276;1821.036;188.1741;39;39;0;4.013214;3.934777;1671246;1.957259e+008
13933.9;1.087499;-2.356304;1089.256;112.5567;39;39;0;3.425195;3.367841;999658.6;1.164119e+008
13961.9;0.9009102;-1.642756;443.988;45.87885;39;39;0;2.837512;2.798001;407467.6;4.718067e+007
13989.9;0.7142674;-1.270392;58.58711;6.054014;39;39;0;2.249661;2.22473;53768.01;6190209
14017.9;0.5275711;-1.255152;57.73604;5.96607;39;39;0;1.661641;1.647987;52986.94;6065204
14045.9;0.3408212;-1.2473;52.97266;5.473853;39;39;0;1.073453;1.067732;48615.37;5532612
14072.02;0.3933212;-1.245674;57.90786;5.983824;40;40;0;1.238807;1.231196;53144.62;6057952
14100.02;0.5800711;-1.245544;59.4918;6.147499;40;40;0;1.826995;1.810506;54598.28;6259813
14128.02;0.7665531;-1.376984;496.2144;51.27559;40;40;0;2.41434;2.385656;455398.1;5.251355e+007
14156.02;0.9534101;-1.81963;1347.28;139.2192;40;40;0;3.002867;2.958663;1236459;1.433998e+008
14184.02;1.140106;-2.459708;2258.135;233.341;40;40;0;3.590886;3.527917;2072391;2.4172e+008
14212.02;1.326695;-3.204996;3101.301;320.4684;40;40;0;4.178568;4.093625;2846202;3.338594e+008
14240.02;1.513499;-3.992254;3892.187;402.1934;40;40;0;4.766926;4.656794;3572033;4.213657e+008
14268.02;1.700088;-4.692532;4742.007;490.0084;40;40;0;5.354609;5.21617;4351952;5.162464e+008
14293.31;1.687499;-4.738201;4102.243;423.8993;40;40;0;5.314957;5.178527;3764812;4.464294e+008
14321.31;1.500695;-4.135785;2851.476;294.6531;40;40;0;4.7266;4.618295;2616926;3.085801e+008
14349.31;1.31416;-3.357985;1980.2;204.621;40;40;0;4.139086;4.055718;1817318;2.130905e+008
14377.31;1.127303;-2.52638;1233.046;127.415;40;40;0;3.55056;3.488981;1131622;1.31939e+008
14405.31;0.9407137;-1.778995;556.406;57.49541;40;40;0;2.962878;2.919833;510638.6;5.919892e+007
14433.31;0.754178;-1.304104;89.34655;9.232495;40;40;0;2.375364;2.347591;81997.31;9451800
14461.31;0.5674818;-1.274305;57.96459;5.989686;40;40;0;1.787344;1.771559;53196.69;6096742
14489.31;0.380839;-1.266428;57.07426;5.897685;40;40;0;1.199493;1.192356;52379.59;5968427
14515.42;0.3535176;-1.262355;58.2644;6.020667;41;41;0;1.113441;1.107288;53471.84;6087703
14526.43;0.4268033;-1.262682;58.1897;6.012948;41;41;0;1.344262;1.335307;53403.28;6093777