File: Ensayos/Compresion/EspAAmb.raw
"Test Type";"Manual"
"Method Name:";"C:\INSTRON\user\template\CYCLE.MTM"
"Name:";""
"Operator ID:";""
"Company:";""
"Lab name:";""
"Test date:";"27/03/2017"
"Temperature:";""
"Humidity:";""
"Note 1:";""
"Note 2:";""
"Note 3:";""
"Geometry:";"Rectangular"
"Specimen";1
"Specimen name:";""
"Width:";0.250000;"in"
"Thickness:";0.060000;"in"
"Length:";1.250000;"in"
"Diameter:";0.039370;"in"
"Inner diameter:";0.019685;"in"
"Outer diameter:";0.039370;"in"
"Wall thickness:";0.019685;"in"
"Area:";0.015000;"in*in"
"Linear density:";1.000000;"den"
"Sled weight:";2.204623;"lbf"
"Loading span:";0.000000;"mm"
"Support span:";1.000000;"mm"
"Span ratio:";"2"
"Fixture type:";"3-point"
"Comment:";""
"Included"
"Final Width:";0.250000;"in"
"Final Thickness:";0.060000;"in"
"Final Length:";1.250000;"in"
"Final Diameter:";0.039370;"in"
"Final Inner diameter:";0.019685;"in"
"Final Outer diameter:";0.039370;"in"
"Final Wall thickness:";0.019685;"in"
"Final Area:";0.015000;"in*in"
"Final Linear density:";1.000000;"den"
"Time sec";"Extension mm";"Strain 1 %";"Load N";"Stress MPa";"Cycle Count ";"Total Cycle Count ";"Repetitions Count ";"Strain [Exten.] %";"True strain %";"Tenacity gf/tex";"True stress Pa"
0;0;0.0005504227;94.31127;9.745517;0;0;0;0;0;86553.66;9745517
6;0.00996428;-0.001864724;149.2665;15.42423;0;0;0;0.03138356;0.03137863;136988.5;1.542907e+007
12;0.01998213;-0.004860576;203.1218;20.9893;0;0;0;0.06293584;0.06291604;186414;2.100251e+007
18;0.03005355;-0.008349036;248.0504;25.63193;0;0;0;0.09465685;0.09461209;227646.9;2.565619e+007
24;0.0400714;-0.01165127;296.2146;30.6089;0;0;0;0.1262091;0.1261296;271849.3;3.064753e+007
30;0.05008926;-0.01462702;352.6912;36.44482;0;0;0;0.1577614;0.1576371;323680.4;3.650232e+007
36;0.06005353;-0.0178564;410.5952;42.42825;0;0;0;0.189145;0.1889663;376821.5;4.25085e+007
42;0.07012495;-0.02159441;469.9188;48.55837;0;0;0;0.220866;0.2206224;431265.4;4.866562e+007
48;0.08008924;-0.02533674;529.7746;54.74348;0;0;0;0.2522496;0.251932;486197.8;5.488158e+007
54;0.09010709;-0.0299542;591.1586;61.08651;0;0;0;0.2838019;0.2833999;542532.6;6.125988e+007
60;0.1001249;-0.03517709;653.6267;67.54156;0;0;0;0.3153541;0.3148579;599862.4;6.775455e+007
66;0.1100892;-0.04040515;715.6993;73.95573;0;0;0;0.3467377;0.3461379;656829.1;7.421217e+007
72;0.1200535;-0.04410798;774.707;80.05322;0;0;0;0.3781212;0.3774082;710983.2;8.035592e+007
78;0.1300178;-0.04969305;838.23;86.61727;0;0;0;0.4095048;0.4086686;769281.1;8.697197e+007
84.00001;0.139982;-0.05532339;899.1164;92.90888;0;0;0;0.4408883;0.4399193;825159.3;9.331851e+007
90.00001;0.1499999;-0.05266296;939.1132;97.04189;0;0;0;0.4724407;0.4713281;861866.1;9.750036e+007
96.00001;0.1600178;-0.05439747;997.5437;103.0797;0;0;0;0.5039929;0.5027271;915490.3;1.035992e+008
102;0.169982;-0.05901677;1058.703;109.3996;0;0;0;0.5353765;0.5339484;971619.3;1.099853e+008
108;0.1799999;-0.06383711;1119.34;115.6653;0;0;0;0.5669287;0.5653278;1027268;1.163211e+008
114;0.1899642;-0.06864127;1178.928;121.8228;0;0;0;0.5983123;0.5965295;1081955;1.225516e+008
120;0.199982;-0.07473529;1240.372;128.172;0;0;0;0.6298646;0.6278893;1138344;1.289793e+008
126;0.2100534;-0.08157266;1302.863;134.6295;0;0;0;0.6615856;0.6594068;1195696;1.355201e+008
132;0.2200177;-0.08918065;1364.085;140.9557;0;0;0;0.6929692;0.6905792;1251881;1.419325e+008
138;0.2300356;-0.09689941;1424.127;147.1601;0;0;0;0.7245215;0.7219094;1306985;1.482263e+008
144;0.2400534;-0.1074094;1486.868;153.6433;0;0;0;0.7560738;0.7532298;1364565;1.54805e+008
150;0.2500713;-0.119183;1550.614;160.2304;0;0;0;0.787626;0.7845404;1423068;1.614924e+008
156;0.2600355;-0.1314865;1614.678;166.8504;0;0;0;0.8190096;0.8156739;1481862;1.682169e+008
162;0.2699998;-0.1441127;1677.849;173.3781;0;0;0;0.8503931;0.8467977;1539837;1.748525e+008
168;0.2800177;-0.1574651;1741.264;179.931;0;0;0;0.8819455;0.878079;1598036;1.815178e+008
174;0.289982;-0.1712234;1803.751;186.388;0;0;0;0.913329;0.9091834;1655383;1.880903e+008
180;0.2999998;-0.185094;1867.63;192.9888;0;0;0;0.9448813;0.9404452;1714008;1.948124e+008
186;0.3099641;-0.1991466;1932.689;199.7116;0;0;0;0.9762648;0.9715302;1773715;2.016614e+008
192;0.319982;-0.2137505;1998.375;206.4992;0;0;0;1.007817;1.002773;1833998;2.085803e+008
198;0.3300533;-0.2286593;2063.315;213.2097;0;0;0;1.039538;1.034172;1893596;2.154261e+008
204;0.3400176;-0.2437113;2127.832;219.8764;0;0;0;1.070922;1.065228;1952807;2.222311e+008
210;0.3500355;-0.2589945;2191.33;226.4379;0;0;0;1.102474;1.096441;2011081;2.289343e+008
216;0.3600533;-0.274515;2254.072;232.9212;0;0;0;1.134026;1.127644;2068662;2.355626e+008
222;0.3700712;-0.2903365;2316.487;239.3708;0;0;0;1.165579;1.158838;2125944;2.421609e+008
228;0.380089;-0.3065949;2378.423;245.7709;0;0;0;1.197131;1.190022;2182785;2.487131e+008
234;0.3900533;-0.3231226;2440.113;252.1455;0;0;0;1.228514;1.221029;2239401;2.552432e+008
240;0.4000711;-0.3400119;2500.701;258.4063;0;0;0;1.260067;1.252194;2295005;2.616624e+008
246;0.410089;-0.3501514;2530.096;261.4438;0;0;0;1.291619;1.283349;2321982;2.648206e+008
252;0.4201069;-0.3652884;2593.717;268.018;0;0;0;1.323171;1.314494;2380370;2.715643e+008
258;0.4300712;-0.3820205;2651.902;274.0304;0;0;0;1.354555;1.345463;2433768;2.777423e+008
264;0.4400354;-0.3991204;2709.137;279.9447;0;0;0;1.385938;1.376422;2486296;2.838246e+008
270;0.4500533;-0.4165386;2766.221;285.8434;0;0;0;1.417491;1.407538;2538685;2.898952e+008
276;0.459964;-0.4343832;2823.512;291.7635;0;0;0;1.448705;1.438312;2591263;2.959903e+008
282;0.4699283;-0.4525786;2880.266;297.6281;0;0;0;1.480089;1.469243;2643349;3.020333e+008
288;0.4799997;-0.4708994;2935.935;303.3805;0;0;0;1.51181;1.500496;2694438;3.079671e+008
294;0.489964;-0.4895553;2992.74;309.2504;0;0;0;1.543194;1.531407;2746571;3.140227e+008
300;0.4999818;-0.5085756;3049.272;315.092;0;0;0;1.574746;1.562475;2798453;3.200539e+008
306;0.5099996;-0.5279633;3105.918;320.9455;0;0;0;1.606298;1.593534;2850440;3.261009e+008
312;0.5200175;-0.5475735;3160.864;326.6233;0;0;0;1.637851;1.624582;2900866;3.319729e+008
318;0.5300354;-0.5672492;3215.532;332.2723;0;0;0;1.669403;1.655621;2951037;3.378192e+008
324;0.5400533;-0.5871703;3270.402;337.9422;0;0;0;1.700955;1.686651;3001394;3.436904e+008
330;0.5501246;-0.6072122;3324.137;343.4948;0;0;0;1.732676;1.717836;3050708;3.494464e+008
336;0.5600889;-0.62857;3378.123;349.0734;0;0;0;1.76406;1.748681;3100254;3.552313e+008
342;0.5700532;-0.6491008;3430.119;354.4464;0;0;0;1.795443;1.779515;3147973;3.608102e+008
348;0.5801246;-0.6699497;3483.285;359.9402;0;0;0;1.827164;1.810672;3196766;3.665169e+008
354;0.5900889;-0.691271;3534.439;365.2261;0;0;0;1.858548;1.841488;3243713;3.72014e+008
360;0.6001068;-0.7128035;3585.761;370.5294;0;0;0;1.8901;1.87246;3290813;3.775328e+008
366;0.6100711;-0.7343689;3635.654;375.685;0;0;0;1.921484;1.903256;3336602;3.829038e+008
372;0.6200354;-0.7559546;3684.531;380.7356;0;0;0;1.952867;1.934043;3381458;3.881709e+008
378;0.6299996;-0.7777549;3734.142;385.8622;0;0;0;1.984251;1.964821;3426989;3.935186e+008
384;0.6399639;-0.7998651;3782.967;390.9073;0;0;0;2.015634;1.995589;3471797;3.987866e+008
390;0.6499817;-0.8218767;3831.205;395.892;0;0;0;2.047187;2.026513;3516068;4.039966e+008
396;0.659946;-0.8434458;3878.34;400.7626;0;0;0;2.07857;2.057263;3559326;4.090927e+008
402;0.6699638;-0.8655318;3925.378;405.6232;0;0;0;2.110122;2.088168;3602494;4.141823e+008
408;0.6799817;-0.8879574;3972.536;410.4962;0;0;0;2.141675;2.119063;3645774;4.192877e+008
414;0.689946;-0.9108363;4019.12;415.3099;0;0;0;2.173058;2.149784;3688526;4.243348e+008
420;0.7000174;-0.9338405;4065.866;420.1404;0;0;0;2.204779;2.180825;3731427;4.294035e+008
426;0.7099817;-0.9568381;4112.445;424.9535;0;0;0;2.236163;2.211527;3774174;4.344561e+008
432;0.7200531;-0.9799838;4157.114;429.5693;0;0;0;2.267884;2.24255;3815169;4.393115e+008
436.824;0.724821;-0.9950429;4151.285;428.9669;0;0;0;2.282901;2.257233;3809819;4.387598e+008
442.824;0.7146959;-0.9865385;3965.565;409.7758;0;0;0;2.251011;2.226049;3639376;4.189999e+008
448.824;0.7046781;-0.9768771;3804.007;393.0815;0;0;0;2.219459;2.195187;3491107;4.018058e+008
454.824;0.6946603;-0.9667549;3651.756;377.3489;0;0;0;2.187906;2.164315;3351380;3.856049e+008
460.824;0.6846424;-0.9565409;3505.776;362.2643;0;0;0;2.156354;2.133434;3217407;3.70076e+008
466.824;0.6746781;-0.9463365;3367.105;347.9349;0;0;0;2.12497;2.102708;3090143;3.553284e+008
472.824;0.6646067;-0.9360663;3232.342;334.0093;0;0;0;2.09325;2.071642;2966464;3.41001e+008
478.824;0.654696;-0.9256799;3102.39;320.5809;0;0;0;2.062035;2.041062;2847202;3.271914e+008
484.824;0.6446781;-0.9156144;2974.745;307.3909;0;0;0;2.030482;2.010143;2730056;3.136324e+008
490.824;0.6347674;-0.905944;2850.616;294.5642;0;0;0;1.999267;1.979545;2616137;3.004533e+008
496.824;0.6247496;-0.8963249;2728.58;281.9539;0;0;0;1.967715;1.948606;2504140;2.875019e+008
502.824;0.6147853;-0.8865982;2610.24;269.7253;0;0;0;1.936332;1.917823;2395534;2.749481e+008
508.824;0.6047675;-0.8769868;2494.744;257.7908;0;0;0;1.904779;1.886866;2289538;2.627011e+008
514.824;0.5948032;-0.8671903;2383.786;246.3251;0;0;0;1.873396;1.856064;2187707;2.509397e+008
520.824;0.5847854;-0.857457;2274.743;235.0573;0;0;0;1.841844;1.825087;2087633;2.393867e+008
526.8241;0.5747675;-0.8475138;2168.357;224.064;0;0;0;1.810291;1.794101;1989998;2.281202e+008
532.8241;0.5648032;-0.8374491;2065.348;213.4198;0;0;0;1.778908;1.76327;1895462;2.172163e+008
538.8241;0.5547854;-0.827328;1964.016;202.9487;0;0;0;1.747355;1.732265;1802465;2.064949e+008
544.8241;0.5447675;-0.8168379;1865.331;192.7512;0;0;0;1.715803;1.701249;1711897;1.960585e+008
550.8241;0.5347497;-0.8060084;1769.171;182.8147;0;0;0;1.684251;1.670225;1623647;1.858938e+008
556.8241;0.5247318;-0.7951936;1675.183;173.1026;0;0;0;1.652699;1.63919;1537390;1.759635e+008
562.8241;0.5147675;-0.7838815;1583.018;163.5788;0;0;0;1.621315;1.608312;1452806;1.66231e+008
568.8241;0.5046961;-0.7725461;1493.42;154.3204;0;0;0;1.589594;1.577092;1370578;1.567735e+008
574.8241;0.4947318;-0.7608984;1406.481;145.3366;0;0;0;1.55821;1.546195;1290790;1.476013e+008
580.8241;0.4847676;-0.7490908;1320.651;136.4675;0;0;0;1.526827;1.515288;1212020;1.385511e+008
586.8241;0.4748033;-0.7369638;1237.012;127.8249;0;0;0;1.495443;1.484372;1135261;1.297364e+008
592.8241;0.464839;-0.7248467;1156.104;119.4643;0;0;0;1.46406;1.453446;1061008;1.212134e+008
598.8241;0.4548211;-0.7125572;1077.188;111.3096;0;0;0;1.432508;1.422344;988583.1;1.129041e+008
604.8241;0.4448033;-0.7000106;1000.136;103.3476;0;0;0;1.400955;1.391233;917869.6;1.047955e+008
610.8241;0.4347854;-0.6874472;925.0725;95.59102;0;0;0;1.369403;1.360111;848980.3;9.690005e+007
616.8241;0.4247676;-0.6747574;851.8216;88.02174;0;0;0;1.337851;1.328981;781754.6;8.919934e+007
622.8241;0.4147497;-0.6620838;781.6974;80.77555;0;0;0;1.306298;1.29784;717398.5;8.183072e+007
628.8241;0.4047319;-0.6494217;714.0201;73.78223;0;0;0;1.274746;1.26669;655288.1;7.472276e+007
634.8241;0.3947676;-0.6364664;647.8634;66.94601;0;0;0;1.243363;1.235696;594573.1;6.77784e+007
640.8241;0.3846962;-0.6233965;584.1071;60.35786;0;0;0;1.211642;1.20436;536061.1;6.108918e+007
646.8241;0.3746783;-0.6102447;522.7334;54.0159;0;0;0;1.180089;1.173181;479735.8;5.465333e+007
652.8241;0.3646605;-0.5968692;463.4601;47.89098;0;0;0;1.148537;1.141991;425338;4.844102e+007
658.8241;0.3546962;-0.5833297;406.3847;41.99317;0;0;0;1.117153;1.110959;372957.4;4.24623e+007
664.8241;0.3446783;-0.5701301;351.4536;36.31695;0;0;0;1.085601;1.079751;322544.7;3.671121e+007
670.8241;0.3346605;-0.5579837;299.1327;30.91045;0;0;0;1.054049;1.048532;274527.5;3.123626e+007
676.8241;0.3246962;-0.5479888;249.7017;25.80256;0;0;0;1.022665;1.017471;229162.4;2.606643e+007
682.8241;0.3146784;-0.5396406;203.5493;21.03346;0;0;0;0.9911129;0.9862336;186806.2;2.124193e+007
688.8241;0.3047677;-0.532358;161.6553;16.70441;0;0;0;0.9598981;0.9553204;148358.3;1.686476e+007
694.8241;0.2948034;-0.5265624;124.3962;12.8543;0;0;0;0.9285146;0.9242304;114163.9;1.297365e+007
700.8241;0.2847855;-0.5217675;91.41216;9.445942;0;0;0;0.8969623;0.8929635;83893.01;9530668
706.8241;0.2747677;-0.5181354;63.85575;6.598441;0;0;0;0.86541;0.8616868;58603.27;6655544
711.1461;0.2707498;-0.5165814;57.09766;5.900104;1;1;0;0.8527554;0.8491399;52401.07;5950417
717.1461;0.2808748;-0.5174318;107.1227;11.06936;1;1;0;0.884645;0.880755;98311.25;1.116729e+007
723.1461;0.2908927;-0.5189244;166.8366;17.23982;1;1;0;0.9161974;0.9120258;153113.4;1.739777e+007
729.1461;0.3009105;-0.5208664;232.3044;24.00484;1;1;0;0.9477497;0.9432867;213196.1;2.423234e+007
735.1461;0.3108748;-0.523041;302.6914;31.27817;1;1;0;0.9791332;0.9743707;277793.4;3.158443e+007
741.1461;0.3208391;-0.5262014;378.9349;39.15668;1;1;0;1.010517;1.005445;347765.5;3.955237e+007
747.1461;0.3308033;-0.5297287;457.878;47.31415;1;1;0;1.0419;1.03651;420215;4.780712e+007
753.1461;0.3408212;-0.5338472;542.3413;56.04205;1;1;0;1.073453;1.067732;497730.8;5.664363e+007
759.1461;0.350839;-0.5391533;629.3353;65.03145;1;1;0;1.105005;1.098944;577569.1;6.575005e+007
765.1461;0.3608569;-0.54672;718.2903;74.22348;1;1;0;1.136557;1.130147;659207.1;7.506707e+007
771.1461;0.3708748;-0.5555407;808.9128;83.58782;1;1;0;1.16811;1.16134;742375.3;8.456422e+007
777.1461;0.380839;-0.5650439;901.0608;93.10981;1;1;0;1.199493;1.192356;826943.8;9.422665e+007
783.1461;0.3909105;-0.5750275;994.0004;102.7136;1;1;0;1.231214;1.223696;912238.5;1.039782e+008
789.1461;0.4009283;-0.5853493;1089.546;112.5867;1;1;0;1.262766;1.25486;999925.4;1.140084e+008
795.1461;0.4108926;-0.5959427;1185.74;122.5267;1;1;0;1.29415;1.285847;1088207;1.241124e+008
801.1461;0.4209104;-0.606944;1282.826;132.559;1;1;0;1.325702;1.316992;1177307;1.343163e+008
807.1461;0.4309283;-0.6181914;1380.334;142.6348;1;1;0;1.357255;1.348126;1266794;1.445707e+008
813.1461;0.4409462;-0.6296483;1477.981;152.725;1;1;0;1.388807;1.379251;1356409;1.548461e+008
819.1461;0.4509104;-0.6412147;1576.77;162.9332;1;1;0;1.42019;1.4102;1447072;1.652472e+008
825.1461;0.4609283;-0.652739;1674.882;173.0715;1;1;0;1.451743;1.441306;1537114;1.75584e+008
831.1461;0.4708926;-0.6642883;1773.73;183.2858;1;1;0;1.483126;1.472235;1627831;1.860041e+008
837.1461;0.4809104;-0.6760965;1872.202;193.4612;1;1;0;1.514678;1.503322;1718203;1.963915e+008
843.1461;0.4908747;-0.6878574;1970.416;203.6101;1;1;0;1.546062;1.534232;1808339;2.06758e+008
849.1461;0.500839;-0.6998494;2069.392;213.8376;1;1;0;1.577446;1.565133;1899174;2.172108e+008
855.1461;0.5108033;-0.7120062;2167.687;223.9948;1;1;0;1.608829;1.596025;1989383;2.275985e+008
861.1461;0.5207675;-0.7240131;2266.615;234.2174;1;1;0;1.640213;1.626907;2080174;2.38059e+008
867.1461;0.5308389;-0.7360626;2364.279;244.3093;1;1;0;1.671934;1.658111;2169804;2.48394e+008
873.1461;0.5408568;-0.7481213;2461.845;254.3912;1;1;0;1.703486;1.689139;2259345;2.587247e+008
879.1461;0.5508211;-0.7603574;2559.772;264.5103;1;1;0;1.73487;1.719993;2349217;2.690992e+008
885.1461;0.5608925;-0.7727505;2657.982;274.6587;1;1;0;1.766591;1.751168;2439349;2.795108e+008
891.1461;0.5709103;-0.7850872;2755.994;284.7867;1;1;0;1.798143;1.782167;2529299;2.899075e+008
897.1461;0.5809282;-0.7973832;2852.465;294.7553;1;1;0;1.829695;1.813158;2617835;3.001485e+008
903.1461;0.5908925;-0.8097063;2948.425;304.6712;1;1;0;1.861079;1.843972;2705902;3.103414e+008
909.1461;0.6009639;-0.8219922;3044.497;314.5987;1;1;0;1.8928;1.875109;2794071;3.205534e+008
915.1461;0.6109282;-0.8343;3139.223;324.3871;1;1;0;1.924183;1.905905;2881005;3.306289e+008
921.1461;0.6208925;-0.8466943;3232.584;334.0343;1;1;0;1.955567;1.936691;2966686;3.405666e+008
927.1461;0.6309103;-0.8595282;3326.948;343.7853;1;1;0;1.987119;1.967634;3053289;3.506167e+008
933.1461;0.6409281;-0.8724891;3419.45;353.3439;1;1;0;2.018671;1.998566;3138182;3.604768e+008
939.1461;0.6508924;-0.8855774;3510.944;362.7983;1;1;0;2.050055;2.029324;3222150;3.702359e+008
945.1461;0.6608567;-0.8991487;3602.428;372.2517;1;1;0;2.081438;2.060072;3306109;3.799999e+008
951.1461;0.670821;-0.9128221;3691.181;381.4228;1;1;0;2.112822;2.090811;3387561;3.894816e+008
957.1461;0.6808388;-0.9269655;3780.795;390.6829;1;1;0;2.144374;2.121706;3469804;3.990606e+008
963.1461;0.6908031;-0.9415485;3868.756;399.7722;1;1;0;2.175758;2.152426;3550530;4.084703e+008
969.1461;0.700821;-0.9567633;3954.951;408.679;1;1;0;2.20731;2.183302;3629635;4.176999e+008
975.1461;0.7108388;-0.9725228;4037.956;417.2563;1;1;0;2.238862;2.214168;3705812;4.265981e+008
981.1461;0.7208031;-0.9890921;4116.156;425.3369;1;1;0;2.270246;2.244859;3777580;4.349931e+008
987.1461;0.7307674;-1.007003;4188.544;432.8171;1;1;0;2.30163;2.275542;3844014;4.427789e+008
991.6101;0.7249817;-1.004316;4061.801;419.7203;1;1;0;2.283407;2.257727;3727696;4.293042e+008
997.6101;0.7149103;-0.994932;3890.489;402.018;1;1;0;2.251686;2.22671;3570475;4.110702e+008
1003.61;0.704946;-0.9852362;3732.926;385.7365;1;1;0;2.220302;2.196013;3425873;3.94301e+008
1009.61;0.6948745;-0.9752238;3582.306;370.1724;1;1;0;2.188581;2.164976;3287642;3.782739e+008
1015.61;0.6849103;-0.9652211;3437.883;355.2487;1;1;0;2.157198;2.134259;3155099;3.629121e+008
1021.61;0.6748924;-0.9551658;3298.184;340.813;1;1;0;2.125645;2.103369;3026891;3.480575e+008
1027.61;0.6649282;-0.9450017;3163.201;326.8647;1;1;0;2.094262;2.072634;2903011;3.337101e+008
1033.61;0.6549639;-0.9348666;3031.913;313.2982;1;1;0;2.062878;2.041889;2782521;3.197612e+008
1039.61;0.6449996;-0.9245764;2904.061;300.0869;1;1;0;2.031495;2.011135;2665186;3.061832e+008
1045.61;0.6349817;-0.9145944;2779.515;287.2171;1;1;0;1.999942;1.980206;2550885;2.929613e+008
1051.61;0.6250174;-0.9048434;2657.799;274.6398;1;1;0;1.968559;1.949433;2439181;2.800462e+008
1057.61;0.6150531;-0.8952673;2539.249;262.3896;1;1;0;1.937175;1.918651;2330382;2.674726e+008
1063.61;0.6050353;-0.8857645;2424.096;250.4905;1;1;0;1.905623;1.887694;2224702;2.552639e+008
1069.61;0.5950174;-0.8763205;2313.002;239.0107;1;1;0;1.874071;1.856726;2122746;2.4349e+008
1075.61;0.5850532;-0.8667741;2203.398;227.6849;1;1;0;1.842687;1.825915;2022157;2.318804e+008
1081.61;0.5749818;-0.8571129;2098.237;216.8182;1;1;0;1.810966;1.794764;1925645;2.207447e+008
1087.61;0.5650175;-0.8472258;1994.62;206.1112;1;1;0;1.779583;1.763933;1830552;2.097791e+008
1093.61;0.5549461;-0.8372799;1892.334;195.5415;1;1;0;1.747862;1.732762;1736679;1.989593e+008
1099.61;0.5449818;-0.8272593;1793.439;185.3224;1;1;0;1.716478;1.701913;1645919;1.885035e+008
1105.61;0.5349639;-0.8169213;1696.664;175.3223;1;1;0;1.684926;1.670888;1557104;1.782763e+008
1111.61;0.5249461;-0.8063529;1602.634;165.6059;1;1;0;1.653373;1.639854;1470809;1.68344e+008
1117.61;0.5149818;-0.7956528;1509.645;155.997;1;1;0;1.62199;1.608976;1385469;1.585272e+008
1123.61;0.5049639;-0.7845696;1419.601;146.6924;1;1;0;1.590438;1.577923;1302831;1.490254e+008
1129.61;0.4949997;-0.7733569;1331.941;137.6341;1;1;0;1.559054;1.547026;1222381;1.397799e+008
1135.61;0.4850354;-0.7619661;1246.167;128.7709;1;1;0;1.527671;1.516119;1143663;1.307381e+008
1141.61;0.4750176;-0.7503804;1162.303;120.1049;1;1;0;1.496118;1.485037;1066697;1.219018e+008
1147.61;0.4650533;-0.7387009;1080.874;111.6906;1;1;0;1.464735;1.454111;991966.5;1.133265e+008
1153.61;0.4550354;-0.7268584;1001.95;103.5351;1;1;0;1.433182;1.42301;919534.3;1.050189e+008
1159.61;0.4450176;-0.7148401;924.363;95.5177;1;1;0;1.40163;1.391898;848329.1;9.68565e+007
1165.61;0.4350533;-0.7024776;848.4505;87.67339;1;1;0;1.370247;1.360944;778660.9;8.887473e+007
1171.61;0.4249818;-0.6900533;775.6912;80.15492;1;1;0;1.338526;1.329646;711886.4;8.122781e+007
1177.61;0.414964;-0.6777804;705.7388;72.92648;1;1;0;1.306973;1.298506;647687.9;7.387961e+007
1183.61;0.4049997;-0.6653045;637.8061;65.90676;1;1;0;1.27559;1.267523;585343.1;6.674746e+007
1189.61;0.3949819;-0.6528459;571.4213;59.04699;1;1;0;1.244038;1.236363;524418.8;5.978156e+007
1195.61;0.3849105;-0.6403614;507.9405;52.48729;1;1;0;1.212316;1.205027;466159.7;5.312361e+007
1201.61;0.3749462;-0.6279657;447.173;46.20797;1;1;0;1.180933;1.174014;410390.6;4.675365e+007
1207.61;0.3649283;-0.6155832;389.3837;40.23639;1;1;0;1.14938;1.142825;357354.8;4.069886e+007
1213.61;0.3549105;-0.6032588;333.2902;34.44006;1;1;0;1.117828;1.111627;305875.3;3.482504e+007
1219.61;0.3449462;-0.5920522;279.9695;28.93024;1;1;0;1.086445;1.080585;256940.5;2.924455e+007
1225.61;0.3349819;-0.5834838;229.8631;23.75257;1;1;0;1.055061;1.049534;210955.6;2.400317e+007
1231.61;0.3249105;-0.576157;183.1985;18.93055;1;1;0;1.02334;1.01814;168129.4;1.912427e+007
1237.61;0.3149998;-0.5700263;141.4333;14.6148;1;1;0;0.9921254;0.9872362;129799.6;1.47598e+007
1243.61;0.3049819;-0.5651737;104.534;10.80187;1;1;0;0.9605731;0.9559889;95935.52;1.090563e+007
1249.61;0.2950177;-0.5613599;72.35269;7.47646;1;1;0;0.9291895;0.9248991;66401.29;7545930
1255.61;0.2850534;-0.5584821;51.27798;5.298735;1;1;0;0.897806;0.8937996;47060.09;5346307
1259.7;0.2848391;-0.5579497;53.43168;5.521285;2;2;0;0.897131;0.8931307;49036.63;5570818
1265.7;0.2949105;-0.5586072;96.07071;9.927327;2;2;0;0.928852;0.9245647;88168.38;1.001954e+007
1271.7;0.3049284;-0.5599561;154.4796;15.96293;2;2;0;0.9604043;0.9558218;141772.8;1.611624e+007
1277.7;0.3148926;-0.5618304;219.6944;22.7018;2;2;0;0.9917879;0.9869019;201623.3;2.292695e+007
1283.7;0.3249105;-0.5639956;290.0445;29.97132;2;2;0;1.02334;1.01814;266186.8;3.027803e+007
1289.7;0.3349284;-0.5670986;365.2717;37.74482;2;2;0;1.054893;1.049367;335226.1;3.814298e+007
1295.7;0.3448927;-0.5705692;444.143;45.89487;2;2;0;1.086276;1.080418;407609.8;4.639341e+007
1301.7;0.3548569;-0.5743605;527.6988;54.52898;2;2;0;1.11766;1.11146;484292.7;5.513843e+007
1307.7;0.3648212;-0.5799444;614.1804;63.46544;2;2;0;1.149043;1.142492;563660.8;6.419468e+007
1313.7;0.3747854;-0.5874219;703.1973;72.66386;2;2;0;1.180427;1.173514;645355.5;7.35216e+007
1319.7;0.3848033;-0.5959514;794.6298;82.11191;2;2;0;1.211979;1.204693;729267.2;8.310709e+007
1325.7;0.3947676;-0.6053986;887.7575;91.73512;2;2;0;1.243363;1.235696;814734.6;9.287572e+007
1331.7;0.4047855;-0.6153611;981.9851;101.472;2;2;0;1.274915;1.266856;901211.5;1.027657e+008
1337.7;0.4147497;-0.6255693;1078.103;111.4042;2;2;0;1.306298;1.29784;989423.6;1.128595e+008
1343.7;0.4247676;-0.6360258;1175.538;121.4725;2;2;0;1.337851;1.328981;1078844;1.230977e+008
1349.7;0.4347854;-0.6468434;1273.021;131.5458;2;2;0;1.369403;1.360111;1168309;1.333472e+008
1355.7;0.4448033;-0.65799;1371.989;141.7725;2;2;0;1.400955;1.391233;1259136;1.437587e+008
1361.7;0.4548211;-0.6691893;1471.455;152.0507;2;2;0;1.432508;1.422344;1350420;1.542288e+008
1367.7;0.464839;-0.6803734;1571.566;162.3955;2;2;0;1.46406;1.453446;1442296;1.647731e+008
1373.7;0.4748568;-0.6917844;1671.508;172.7228;2;2;0;1.495612;1.484538;1534017;1.753061e+008
1379.7;0.4848211;-0.703233;1771.424;183.0475;2;2;0;1.526996;1.515454;1625715;1.858426e+008
1385.7;0.4948389;-0.7148314;1871.604;193.3994;2;2;0;1.558548;1.546527;1717654;1.964137e+008
1391.7;0.5048032;-0.7263966;1971.623;203.7347;2;2;0;1.589931;1.577424;1809446;2.06974e+008
1397.7;0.5147675;-0.7381424;2072.615;214.1706;2;2;0;1.621315;1.608312;1902131;2.17643e+008
1403.7;0.5247854;-0.7498629;2172.851;224.5284;2;2;0;1.652867;1.639356;1994122;2.282395e+008
1409.7;0.5347497;-0.7615892;2272.615;234.8373;2;2;0;1.684251;1.670225;2085680;2.387926e+008
1415.7;0.5447675;-0.7735573;2373.057;245.2164;2;2;0;1.715803;1.701249;2177860;2.494238e+008
1421.7;0.5547854;-0.7854769;2473.515;255.597;2;2;0;1.747355;1.732265;2270055;2.600632e+008
1427.7;0.5648032;-0.7974874;2573.677;265.9472;2;2;0;1.778908;1.76327;2361978;2.706781e+008
1433.7;0.574821;-0.8092675;2673.691;276.2819;2;2;0;1.81046;1.794266;2453765;2.812839e+008
1439.7;0.5848389;-0.8212362;2773.543;286.6;2;2;0;1.842012;1.825253;2545404;2.918792e+008
1445.7;0.5948568;-0.8330807;2872.622;296.8382;2;2;0;1.873565;1.85623;2636334;3.023997e+008
1451.7;0.6048746;-0.8450194;2971.835;307.0902;2;2;0;1.905117;1.887197;2727385;3.129406e+008
1457.7;0.6148389;-0.8571734;3070.76;317.3125;2;2;0;1.9365;1.917989;2818173;3.234572e+008
1463.7;0.6249102;-0.8691216;3168.56;327.4185;2;2;0;1.968221;1.949102;2907929;3.338629e+008
1469.7;0.6348745;-0.8812732;3265.795;337.4661;2;2;0;1.999605;1.979875;2997166;3.442141e+008
1475.7;0.6448924;-0.8936096;3362.927;347.5032;2;2;0;2.031157;2.010804;3086308;3.545615e+008
1481.7;0.6549103;-0.9061316;3459.125;357.4436;2;2;0;2.06271;2.041724;3174593;3.648166e+008
1487.7;0.6648745;-0.9188284;3554.84;367.3342;2;2;0;2.094093;2.072468;3262435;3.750265e+008
1493.7;0.6748388;-0.9315524;3649.26;377.091;2;2;0;2.125477;2.103203;3349089;3.85106e+008
1499.7;0.6848031;-0.9444974;3743.829;386.8631;2;2;0;2.15686;2.133929;3435879;3.952072e+008
1505.7;0.6947674;-0.9577971;3839.955;396.7962;2;2;0;2.188244;2.164645;3524098;4.054791e+008
1511.7;0.7047853;-0.9714849;3933.911;406.5049;2;2;0;2.219796;2.195517;3610326;4.155285e+008
1517.7;0.7147495;-0.9854184;4027.376;416.163;2;2;0;2.25118;2.226215;3696102;4.255316e+008
1523.7;0.7247674;-0.9999181;4117.879;425.515;2;2;0;2.282732;2.257067;3779162;4.352284e+008
1529.7;0.7347853;-1.015364;4203.083;434.3194;2;2;0;2.314284;2.287911;3857357;4.443708e+008
1535.7;0.7448031;-1.032714;4277.957;442.0565;2;2;0;2.345837;2.318745;3926072;4.524264e+008
1541.7;0.7547674;-1.051267;4339.956;448.463;2;2;0;2.37722;2.349404;3982972;4.59124e+008
1547.7;0.7648388;-1.071299;4396.551;454.3111;2;2;0;2.408941;2.380384;4034911;4.652552e+008
1553.7;0.7748566;-1.091506;4446.731;459.4965;2;2;0;2.440493;2.411189;4080964;4.707104e+008
1559.7;0.7848745;-1.113218;4495.524;464.5384;2;2;0;2.472046;2.441985;4125743;4.76022e+008
1565.7;0.7948388;-1.135561;4542.212;469.3629;2;2;0;2.503429;2.472607;4168591;4.81113e+008
1571.7;0.8049102;-1.158106;4586.736;473.9637;2;2;0;2.53515;2.503548;4209453;4.859794e+008
1577.7;0.8149281;-1.180687;4630.392;478.4748;2;2;0;2.566703;2.534316;4249518;4.907558e+008
1583.7;0.8248923;-1.203444;4670.887;482.6593;2;2;0;2.598086;2.564909;4286682;4.951992e+008
1589.7;0.8349102;-1.226109;4713.255;487.0373;2;2;0;2.629638;2.595658;4325565;4.998446e+008
1595.7;0.8448744;-1.248638;4753.532;491.1992;2;2;0;2.661022;2.626233;4362528;5.042702e+008
1601.7;0.8548387;-1.271317;4793.519;495.3313;2;2;0;2.692405;2.656798;4399227;5.086676e+008
1607.7;0.864803;-1.294049;4833.169;499.4285;2;2;0;2.723789;2.687354;4435615;5.130318e+008
1613.7;0.8747673;-1.317223;4873.292;503.5745;2;2;0;2.755172;2.717901;4472438;5.174489e+008
1619.7;0.8847852;-1.340335;4913.087;507.6867;2;2;0;2.786725;2.748602;4508959;5.218345e+008
1625.7;0.8947495;-1.363693;4952.159;511.7241;2;2;0;2.818109;2.77913;4544817;5.261451e+008
1631.7;0.9047673;-1.38702;4992.032;515.8444;2;2;0;2.849661;2.809813;4581411;5.305442e+008
1637.7;0.9147316;-1.410601;5031.562;519.9291;2;2;0;2.881044;2.840323;4617689;5.349085e+008
1643.7;0.9247495;-1.434555;5071.287;524.0341;2;2;0;2.912597;2.870987;4654147;5.392971e+008
1649.7;0.9347673;-1.458451;5111.27;528.1656;2;2;0;2.944149;2.901641;4690841;5.437156e+008
1655.7;0.9447851;-1.482499;5151.089;532.2802;2;2;0;2.975701;2.932286;4727384;5.481193e+008
1661.7;0.9548565;-1.507481;5186.493;535.9387;2;2;0;3.007422;2.963086;4759876;5.520566e+008
1667.7;0.9648743;-1.531945;5229.021;540.3333;2;2;0;3.038974;2.993712;4798906;5.567538e+008
1673.7;0.9748386;-1.556774;5269.906;544.5581;2;2;0;3.070358;3.024166;4836428;5.61278e+008
1679.7;0.9848565;-1.581972;5310.883;548.7924;2;2;0;3.10191;3.054773;4874034;5.658154e+008
1685.7;0.9948743;-1.607289;5351.071;552.9451;2;2;0;3.133462;3.085371;4910917;5.702715e+008
1691.7;1.004839;-1.633151;5390.982;557.0693;2;2;0;3.164846;3.115797;4947545;5.746997e+008
1697.7;1.014803;-1.659154;5431.301;561.2356;2;2;0;3.196229;3.146213;4984548;5.79174e+008
1703.7;1.024767;-1.684777;5470.887;565.3262;2;2;0;3.227613;3.17662;5020878;5.835727e+008
1709.7;1.034785;-1.710365;5511.927;569.567;2;2;0;3.259166;3.207181;5058541;5.881301e+008
1715.7;1.044749;-1.736049;5552.026;573.7106;2;2;0;3.290549;3.237569;5095343;5.925888e+008
1721.7;1.054767;-1.762221;5592.707;577.9142;2;2;0;3.322101;3.268112;5132677;5.971131e+008
1727.7;1.064839;-1.788424;5632.707;582.0475;2;2;0;3.353822;3.298809;5169387;6.015684e+008
1733.7;1.074856;-1.814797;5673.749;586.2886;2;2;0;3.385375;3.329332;5207053;6.061366e+008
1739.7;1.084821;-1.841338;5713.178;590.3629;2;2;0;3.416758;3.359684;5243239;6.105342e+008
1745.7;1.094839;-1.868147;5754.108;594.5923;2;2;0;3.448311;3.390189;5280802;6.150958e+008
1751.7;1.104856;-1.894794;5794.3;598.7455;2;2;0;3.479863;3.420684;5317687;6.19581e+008
1757.7;1.114874;-1.920967;5833.874;602.8349;2;2;0;3.511415;3.451171;5354007;6.240029e+008
1763.7;1.124892;-1.946724;5872.502;606.8264;2;2;0;3.542967;3.481648;5389457;6.283261e+008
1769.7;1.13491;-1.97201;5911.947;610.9024;2;2;0;3.574519;3.512116;5425657;6.327392e+008
1775.7;1.144928;-1.99733;5951.535;614.9932;2;2;0;3.606072;3.542575;5461989;6.371703e+008
1779.82;1.138446;-1.995261;5804.435;599.7928;2;2;0;3.585656;3.522868;5326989;6.212993e+008
1785.82;1.128428;-1.986765;5617.385;580.4642;2;2;0;3.554103;3.492403;5155325;6.010946e+008
1791.82;1.118464;-1.977748;5440.683;562.205;2;2;0;3.52272;3.462092;4993157;5.820099e+008
1797.82;1.108392;-1.96835;5272.838;544.861;2;2;0;3.490999;3.431446;4839119;5.638821e+008
1803.82;1.098374;-1.958708;5111.586;528.1983;2;2;0;3.459446;3.400953;4691131;5.46471e+008
1809.82;1.08841;-1.948759;4952.704;511.7804;2;2;0;3.428063;3.370614;4545317;5.293246e+008
1815.82;1.078392;-1.938702;4798.507;495.8467;2;2;0;3.396511;3.340103;4403804;5.126882e+008
1821.82;1.068321;-1.928441;4647.939;480.288;2;2;0;3.36479;3.309419;4265621;4.964486e+008
1827.82;1.058303;-1.918217;4501.651;465.1715;2;2;0;3.333237;3.278889;4131366;4.806768e+008
1833.82;1.048339;-1.907949;4359.069;450.438;2;2;0;3.301854;3.248514;4000512;4.653109e+008
1839.82;1.038267;-1.897546;4221.349;436.2069;2;2;0;3.270133;3.217802;3874120;4.504715e+008
1845.82;1.028303;-1.887409;4087.557;422.3817;2;2;0;3.238749;3.187407;3751333;4.360616e+008
1851.82;1.018285;-1.877097;3955.69;408.7555;2;2;0;3.207197;3.15684;3630313;4.218651e+008
1857.82;1.008267;-1.866927;3826.421;395.3976;2;2;0;3.175645;3.126264;3511677;4.07954e+008
1863.82;0.9983029;-1.856829;3700.732;382.4098;2;2;0;3.144261;3.095842;3396327;3.944337e+008
1869.82;0.9883387;-1.846967;3579.783;369.9117;2;2;0;3.112878;3.06541;3285327;3.814265e+008
1875.82;0.9783744;-1.83702;3461.423;357.6811;2;2;0;3.081494;3.034969;3176702;3.68703e+008
1881.82;0.9684101;-1.827042;3345.073;345.6582;2;2;0;3.050111;3.004519;3069923;3.562012e+008
1887.82;0.9583923;-1.816985;3233.291;334.1075;2;2;0;3.018558;2.973896;2967336;3.441927e+008
1893.82;0.948428;-1.806893;3124.101;322.8244;2;2;0;2.987175;2.943428;2867127;3.324677e+008
1899.82;0.9384102;-1.796927;3017.967;311.8572;2;2;0;2.955622;2.912786;2769723;3.210745e+008
1905.82;0.9283923;-1.786893;2915.358;301.2543;2;2;0;2.92407;2.882135;2675554;3.100632e+008
1911.82;0.9183744;-1.776997;2815.614;290.9474;2;2;0;2.892518;2.851474;2584015;2.993631e+008
1917.82;0.9083566;-1.766934;2717.579;280.8171;2;2;0;2.860966;2.820804;2494044;2.888511e+008
1923.82;0.8983387;-1.756867;2622.298;270.9713;2;2;0;2.829413;2.790125;2406600;2.786382e+008
1929.82;0.8882672;-1.746819;2528.377;261.2662;2;2;0;2.797692;2.759272;2320405;2.685756e+008
1935.82;0.878303;-1.736727;2436.505;251.7727;2;2;0;2.766309;2.728738;2236089;2.587375e+008
1941.82;0.8683387;-1.726438;2345.265;242.3445;2;2;0;2.734925;2.698194;2152354;2.489725e+008
1947.82;0.8582673;-1.716132;2255.967;233.1171;2;2;0;2.703204;2.667313;2070402;2.394187e+008
1953.82;0.848303;-1.705874;2169.254;224.1567;2;2;0;2.671821;2.636751;1990821;2.301458e+008
1959.82;0.8382852;-1.695191;2083.679;215.314;2;2;0;2.640268;2.606015;1912286;2.209988e+008
1965.82;0.8283209;-1.684505;1998.795;206.5426;2;2;0;2.608885;2.575434;1834384;2.119311e+008
1971.82;0.8183566;-1.673437;1914.788;197.8618;2;2;0;2.577501;2.544844;1757286;2.029617e+008
1977.82;0.8083924;-1.662131;1830.473;189.1493;2;2;0;2.546118;2.514244;1679907;1.939653e+008
1983.82;0.7983745;-1.65046;1748.429;180.6714;2;2;0;2.514565;2.48347;1604612;1.852145e+008
1989.82;0.7884103;-1.638616;1666.55;172.2106;2;2;0;2.483182;2.452852;1529468;1.764869e+008
1995.82;0.7783924;-1.626655;1587.112;164.0019;2;2;0;2.451629;2.422059;1456564;1.680226e+008
2001.82;0.7684281;-1.614371;1508.165;155.8441;2;2;0;2.420246;2.391422;1384111;1.596159e+008
2007.82;0.7584102;-1.602045;1430.22;147.7897;2;2;0;2.388694;2.360611;1312577;1.5132e+008
2013.82;0.748446;-1.589141;1353.385;139.8501;2;2;0;2.35731;2.329955;1242062;1.431468e+008
2019.82;0.7383745;-1.576159;1278.123;132.073;2;2;0;2.325589;2.298959;1172991;1.351445e+008
2025.82;0.7283567;-1.562897;1203.707;124.3833;2;2;0;2.294037;2.268119;1104696;1.272367e+008
2031.82;0.7183388;-1.549529;1131.712;116.9438;2;2;0;2.262484;2.23727;1038622;1.195896e+008
2037.82;0.7083209;-1.535947;1060.483;109.5835;2;2;0;2.230932;2.206411;973252.4;1.120282e+008
2043.82;0.6983567;-1.52206;990.9742;102.4009;2;2;0;2.199548;2.175707;909461.2;1.046532e+008
2049.82;0.6883388;-1.507971;923.2658;95.40432;2;2;0;2.167996;2.14483;847322.2;9.747269e+007
2055.82;0.6783746;-1.49425;858.0529;88.66564;2;2;0;2.136613;2.114107;787473.4;9.056009e+007
2061.82;0.6683567;-1.48044;794.2681;82.07454;2;2;0;2.105061;2.08321;728935.3;8.380226e+007
2067.82;0.6583925;-1.466728;731.6035;75.59918;2;2;0;2.073677;2.052469;671425.2;7.716686e+007
2073.82;0.6484282;-1.453117;671.2114;69.35865;2;2;0;2.042294;2.021718;616000.6;7.077516e+007
2079.82;0.6384103;-1.439275;611.4687;63.18522;2;2;0;2.010741;1.990793;561172.1;6.445571e+007
2085.82;0.628446;-1.425035;553.2695;57.1713;2;2;0;1.979357;1.960023;507760.1;5.830292e+007
2091.82;0.6184282;-1.41036;495.8585;51.23881;2;2;0;1.947805;1.929078;455071.4;5.223684e+007
2097.82;0.6084103;-1.395332;440.3751;45.50552;2;2;0;1.916253;1.898124;404151.8;4.637752e+007
2103.82;0.5983925;-1.37981;386.9762;39.98762;2;2;0;1.884701;1.86716;355145.3;4.074127e+007
2109.82;0.5883746;-1.364264;335.4732;34.66563;2;2;0;1.853148;1.836187;307878.7;3.530803e+007
2115.82;0.5783568;-1.349357;285.5521;29.5071;2;2;0;1.821596;1.805204;262063.8;3.00446e+007
2121.82;0.5683389;-1.3343;238.4815;24.64313;2;2;0;1.790044;1.774211;218865.1;2.508426e+007
2127.82;0.5582675;-1.319368;193.639;20.0094;2;2;0;1.758323;1.743043;177711.1;2.036123e+007
2133.82;0.5483032;-1.30564;154.3301;15.94747;2;2;0;1.726939;1.712197;141635.6;1.622288e+007
2139.82;0.5383389;-1.293919;117.3068;12.12173;2;2;0;1.695556;1.681341;107657.7;1.232726e+007
2145.82;0.5282675;-1.285311;84.32545;8.713648;2;2;0;1.663835;1.650145;77389.23;8858628
2151.82;0.5183032;-1.278528;57.94256;5.98741;2;2;0;1.632451;1.61927;53176.47;6085151
2156.174;0.5210354;-1.276926;75.45845;7.797389;3;3;0;1.641056;1.627736;69251.58;7925348
2162.174;0.5310532;-1.278702;134.5585;13.9044;3;3;0;1.672609;1.658775;123490.3;1.413697e+007
2168.174;0.5410711;-1.281277;201.3791;20.80922;3;3;0;1.704161;1.689803;184814.6;2.116384e+007
2174.174;0.5510353;-1.284299;274.1054;28.32428;3;3;0;1.735544;1.720656;251558.7;2.881586e+007
2180.174;0.5610532;-1.288664;351.8822;36.36124;3;3;0;1.767097;1.751665;322938;3.700377e+007
2186.174;0.5711246;-1.294464;434.7574;44.92502;3;3;0;1.798818;1.78283;398996.3;4.573314e+007
2192.174;0.5811425;-1.301255;521.4978;53.88821;3;3;0;1.83037;1.81382;478601.8;5.487457e+007
2198.174;0.5911068;-1.308569;611.2732;63.16502;3;3;0;1.861754;1.844635;560992.7;6.4341e+007
2204.174;0.6011246;-1.316531;702.757;72.61837;3;3;0;1.893306;1.875606;644951.4;7.399326e+007
2210.174;0.611196;-1.325318;796.4185;82.29675;3;3;0;1.925027;1.906733;730908.8;8.388098e+007
2216.174;0.6211603;-1.334564;891.673;92.13972;3;3;0;1.95641;1.937519;818328.1;9.394236e+007
2222.174;0.6311781;-1.344307;987.6925;102.0618;3;3;0;1.987963;1.968461;906449.4;1.040907e+008
2228.174;0.641196;-1.354228;1084.208;112.035;3;3;0;2.019515;1.999393;995025.8;1.142976e+008
2234.174;0.6511603;-1.364299;1181.296;122.0675;3;3;0;2.050899;2.030151;1084128;1.24571e+008
2240.174;0.6611246;-1.374672;1278.419;132.1036;3;3;0;2.082282;2.060899;1173262;1.348543e+008
2246.174;0.6710889;-1.385156;1376.121;142.1995;3;3;0;2.113666;2.091638;1262928;1.452051e+008
2252.174;0.6810531;-1.395771;1474.073;152.3212;3;3;0;2.145049;2.122367;1352823;1.555886e+008
2258.174;0.691071;-1.406382;1573.093;162.5532;3;3;0;2.176601;2.153252;1443697;1.660914e+008
2264.174;0.7010352;-1.417008;1672.66;172.8418;3;3;0;2.207985;2.183962;1535074;1.766582e+008
2270.174;0.7110531;-1.42801;1772.11;183.1184;3;3;0;2.239537;2.214828;1626344;1.872194e+008
2276.174;0.721071;-1.439281;1871.966;193.4368;3;3;0;2.27109;2.245684;1717986;1.978299e+008
2282.174;0.7310353;-1.450705;1971.801;203.7532;3;3;0;2.302473;2.276366;1809610;2.084446e+008
2288.174;0.7410531;-1.462318;2071.928;214.0997;3;3;0;2.334025;2.307204;1901501;2.190968e+008
2294.174;0.7510709;-1.473913;2171.863;224.4263;3;3;0;2.365578;2.338031;1993215;2.297353e+008
2300.174;0.7610887;-1.485488;2271.048;234.6754;3;3;0;2.39713;2.36885;2084242;2.403009e+008
2306.174;0.7711602;-1.497129;2370.698;244.9726;3;3;0;2.428851;2.399823;2175695;2.509226e+008
2312.174;0.7811245;-1.508959;2469.075;255.1382;3;3;0;2.460235;2.430458;2265980;2.614152e+008
2318.174;0.7910888;-1.520901;2566.481;265.2036;3;3;0;2.491618;2.461083;2355374;2.718115e+008
2324.174;0.8011066;-1.532887;2664.241;275.3055;3;3;0;2.52317;2.491864;2445093;2.822519e+008
2330.174;0.8111245;-1.544915;2761.286;285.3334;3;3;0;2.554723;2.522635;2534155;2.926229e+008
2336.174;0.8210888;-1.556926;2857.513;295.2769;3;3;0;2.586106;2.553232;2622467;3.029131e+008
2342.174;0.831053;-1.568919;2952.66;305.1089;3;3;0;2.61749;2.58382;2709788;3.13095e+008
2348.174;0.8410173;-1.58093;3047.854;314.9455;3;3;0;2.648873;2.614398;2797151;3.23288e+008
2354.174;0.8510351;-1.592716;3141.313;324.603;3;3;0;2.680426;2.645132;2882923;3.333037e+008
2360.174;0.861053;-1.604689;3234.461;334.2283;3;3;0;2.711978;2.675856;2968410;3.432925e+008
2366.174;0.8710709;-1.616758;3327.724;343.8654;3;3;0;2.74353;2.70657;3054000;3.532995e+008
2372.174;0.8810888;-1.628707;3422.273;353.6356;3;3;0;2.775083;2.737275;3140773;3.634493e+008
2378.174;0.8910531;-1.640817;3515.275;363.2458;3;3;0;2.806466;2.767807;3226125;3.734402e+008
2384.174;0.9011244;-1.652967;3608.988;372.9295;3;3;0;2.838187;2.798657;3312129;3.835139e+008
2390.174;0.9111423;-1.665142;3701.477;382.4867;3;3;0;2.86974;2.829334;3397010;3.934631e+008
2396.174;0.9211065;-1.67771;3796.563;392.3123;3;3;0;2.901123;2.859837;3484275;4.036938e+008
2402.174;0.9311244;-1.690263;3891.09;402.08;3;3;0;2.932675;2.890495;3571027;4.138718e+008
2408.174;0.9411423;-1.70289;3985.332;411.8184;3;3;0;2.964228;2.921144;3657517;4.240257e+008
2414.174;0.9511601;-1.715793;4081.605;421.7667;3;3;0;2.99578;2.951783;3745871;4.344019e+008
2420.174;0.9611244;-1.728851;4179.08;431.8391;3;3;0;3.027164;2.982249;3835328;4.449116e+008
2426.174;0.9711958;-1.742119;4276.801;441.937;3;3;0;3.058885;3.013033;3925011;4.554553e+008
2432.174;0.9811601;-1.755391;4374.193;452.0008;3;3;0;3.090268;3.043481;4014392;4.659688e+008
2438.174;0.9911243;-1.768914;4472.14;462.122;3;3;0;3.121651;3.073919;4104282;4.765479e+008
2444.174;1.001089;-1.782583;4570.16;472.2508;3;3;0;3.153035;3.104348;4194240;4.871411e+008
2450.174;1.011053;-1.796579;4669.498;482.5158;3;3;0;3.184418;3.134767;4285407;4.978811e+008
2456.174;1.021071;-1.81059;4768.128;492.7075;3;3;0;3.215971;3.165341;4375924;5.085528e+008
2462.174;1.031035;-1.824617;4866.276;502.8496;3;3;0;3.247354;3.195742;4465999;5.191789e+008
2468.174;1.041053;-1.838877;4964.207;512.9691;3;3;0;3.278907;3.226298;4555874;5.297889e+008
2474.174;1.051071;-1.853531;5063.46;523.2252;3;3;0;3.310459;3.256844;4646963;5.405464e+008
2480.174;1.061035;-1.868398;5162.133;533.4214;3;3;0;3.341842;3.287217;4737520;5.512476e+008
2486.174;1.071053;-1.88346;5261.532;543.6927;3;3;0;3.373395;3.317744;4828742;5.620336e+008
2492.174;1.081124;-1.898931;5360.163;553.8846;3;3;0;3.405116;3.348425;4919261;5.72745e+008
2498.174;1.091142;-1.914725;5457.557;563.9487;3;3;0;3.436668;3.378934;5008644;5.833298e+008
2504.174;1.10116;-1.930852;5552.259;573.7346;3;3;0;3.46822;3.409433;5095556;5.93633e+008
2510.174;1.111124;-1.947257;5644.883;583.3057;3;3;0;3.499604;3.43976;5180561;6.037191e+008
2516.174;1.121196;-1.963837;5733.247;592.4367;3;3;0;3.531325;3.470404;5261656;6.133576e+008
2522.174;1.13116;-1.980872;5815.803;600.9675;3;3;0;3.562709;3.500712;5337422;6.223782e+008
2528.174;1.141178;-1.998874;5894.178;609.0662;3;3;0;3.594261;3.531175;5409350;6.309577e+008
2534.174;1.151196;-2.018275;5965.043;616.389;3;3;0;3.625813;3.561628;5474386;6.387381e+008
2538.48;1.158267;-2.033048;6011.438;621.1832;3;3;0;3.648086;3.583118;5516965;6.438445e+008
2544.48;1.148303;-2.026853;5801.139;599.4523;3;3;0;3.616702;3.552835;5323964;6.211327e+008
2550.48;1.138339;-2.018204;5615.238;580.2424;3;3;0;3.585319;3.522542;5153355;6.01046e+008
2556.48;1.128321;-2.009099;5439.506;562.0834;3;3;0;3.553766;3.492077;4992077;5.820585e+008
2562.48;1.118303;-1.999853;5272.575;544.8338;3;3;0;3.522214;3.461603;4838877;5.64024e+008
2568.48;1.108339;-1.990424;5111.628;528.2026;3;3;0;3.49083;3.431282;4691169;5.466413e+008
2574.48;1.098321;-1.980827;4953.353;511.8474;3;3;0;3.459278;3.40079;4545913;5.295537e+008
2580.48;1.088303;-1.970995;4797.72;495.7654;3;3;0;3.427725;3.370288;4403081;5.127588e+008
2586.48;1.078285;-1.961017;4645.655;480.052;3;3;0;3.396173;3.339777;4263525;4.963554e+008
2592.48;1.068267;-1.951076;4496.844;464.6748;3;3;0;3.364621;3.309256;4126954;4.803093e+008
2598.48;1.058196;-1.94092;4352.597;449.7692;3;3;0;3.3329;3.278563;3994572;4.647596e+008
2604.48;1.048231;-1.930898;4212.451;435.2875;3;3;0;3.301517;3.248187;3865955;4.496586e+008
2610.48;1.038214;-1.920813;4075.981;421.1855;3;3;0;3.269964;3.217638;3740710;4.349582e+008
2616.48;1.028196;-1.910746;3942.545;407.3971;3;3;0;3.238412;3.187081;3618249;4.205903e+008
2622.48;1.018178;-1.900674;3812.483;393.9574;3;3;0;3.206859;3.156513;3498886;4.06591e+008
2628.48;1.008214;-1.890608;3684.089;380.6899;3;3;0;3.175476;3.1261;3381052;3.927786e+008
2634.48;0.9981958;-1.880616;3560.974;367.9681;3;3;0;3.143924;3.095514;3268065;3.795367e+008
2640.48;0.9882315;-1.870985;3441.416;355.6136;3;3;0;3.11254;3.065083;3158341;3.666823e+008
2646.48;0.9783207;-1.861287;3324.976;343.5815;3;3;0;3.081325;3.034806;3051479;3.541684e+008
2652.48;0.968303;-1.851622;3209.967;331.6972;3;3;0;3.049773;3.004192;2945930;3.418133e+008
2658.48;0.9583387;-1.841971;3099.384;320.2703;3;3;0;3.01839;2.973733;2844443;3.299373e+008
2664.48;0.9483208;-1.832171;2991.684;309.1413;3;3;0;2.986837;2.9431;2745602;3.183748e+008
2670.48;0.9383565;-1.822418;2887.014;298.3253;3;3;0;2.955454;2.912622;2649541;3.071422e+008
2676.48;0.9283387;-1.812679;2784.657;287.7484;3;3;0;2.923901;2.881971;2555604;2.961619e+008
2682.48;0.9182673;-1.802952;2685.124;277.4634;3;3;0;2.89218;2.851146;2464258;2.854881e+008
2688.48;0.908303;-1.793115;2587.868;267.4136;3;3;0;2.860797;2.82064;2375002;2.750637e+008
2694.48;0.8982851;-1.783311;2493.191;257.6303;3;3;0;2.829245;2.789961;2288113;2.649193e+008
2700.48;0.8882137;-1.773473;2399.757;247.9754;3;3;0;2.797523;2.759108;2202364;2.549126e+008
2706.48;0.8781959;-1.763461;2307.37;238.4287;3;3;0;2.765971;2.728409;2117577;2.450236e+008
2712.48;0.8682316;-1.753398;2217.178;229.1089;3;3;0;2.734588;2.697866;2034803;2.35374e+008
2718.48;0.8582138;-1.74332;2127.689;219.8616;3;3;0;2.703035;2.667149;1952675;2.258046e+008
2724.48;0.8481959;-1.73315;2040.624;210.8649;3;3;0;2.671483;2.636422;1872772;2.164981e+008
2730.48;0.8382316;-1.722877;1954.139;201.9281;3;3;0;2.6401;2.605851;1793401;2.072593e+008
2736.48;0.8282674;-1.712502;1869.634;193.1959;3;3;0;2.608716;2.57527;1715847;1.982358e+008
2742.48;0.8182495;-1.701804;1785.547;184.5069;3;3;0;2.577164;2.544515;1638676;1.892619e+008
2748.48;0.8082852;-1.690776;1702.202;175.8946;3;3;0;2.54578;2.513915;1562187;1.803725e+008
2754.48;0.7983209;-1.679505;1619.39;167.3373;3;3;0;2.514397;2.483306;1486186;1.715448e+008
2760.48;0.7883031;-1.668137;1537.864;158.9129;3;3;0;2.482844;2.452523;1411367;1.628585e+008
2766.48;0.7783388;-1.656735;1457.883;150.6482;3;3;0;2.451461;2.421895;1337964;1.543413e+008
2772.48;0.7683209;-1.645017;1380.212;142.6221;3;3;0;2.419908;2.391093;1266682;1.460735e+008
2778.48;0.7583566;-1.633089;1302.834;134.6265;3;3;0;2.388525;2.360446;1195669;1.378421e+008
2784.48;0.7482852;-1.620788;1226.032;126.6902;3;3;0;2.356804;2.32946;1125184;1.296761e+008
2790.48;0.738321;-1.608269;1151.367;118.9748;3;3;0;2.32542;2.298794;1056661;1.217415e+008
2796.48;0.7283031;-1.595475;1077.651;111.3575;3;3;0;2.293868;2.267954;989008.3;1.139119e+008
2802.48;0.7182852;-1.582502;1005.379;103.8894;3;3;0;2.262316;2.237105;922681.4;1.062397e+008
2808.48;0.7082674;-1.569454;934.8552;96.6019;3;3;0;2.230763;2.206246;857958.3;9.875685e+007
2814.48;0.6982496;-1.55633;866.7794;89.56738;3;3;0;2.199211;2.175378;795482.1;9.153716e+007
2820.48;0.6882853;-1.543228;799.5217;82.61741;3;3;0;2.167828;2.144664;733756.7;8.440841e+007
2826.48;0.6782675;-1.530089;734.4929;75.89775;3;3;0;2.136276;2.113777;674076.9;7.751913e+007
2832.48;0.6683032;-1.517104;671.8941;69.4292;3;3;0;2.104892;2.083045;616627.2;7.089061e+007
2838.48;0.6583389;-1.50396;609.986;63.03201;3;3;0;2.073508;2.052304;559811.4;6.433899e+007
2844.48;0.648321;-1.490803;549.6417;56.79642;3;3;0;2.041956;2.021388;504430.7;5.795618e+007
2850.48;0.6383567;-1.477124;491.1262;50.74981;3;3;0;2.010572;1.990627;450728.4;5.177017e+007
2856.48;0.6283389;-1.462815;433.7819;44.82421;3;3;0;1.97902;1.959692;398101;4.57113e+007
2862.48;0.618321;-1.448234;378.2695;39.08793;3;3;0;1.947468;1.928747;347154.8;3.984915e+007
2868.48;0.6083032;-1.433757;324.6112;33.54323;3;3;0;1.915916;1.897793;297910.2;3.418589e+007
2874.48;0.5983389;-1.419576;273.4648;28.25809;3;3;0;1.884532;1.866995;250970.9;2.879062e+007
2880.48;0.5883211;-1.405426;225.6905;23.32139;3;3;0;1.85298;1.836021;207126.2;2.375353e+007
2886.48;0.5783032;-1.391498;179.9785;18.59782;3;3;0;1.821427;1.805038;165174.3;1.893657e+007
2892.48;0.5682317;-1.378981;139.5718;14.42245;3;3;0;1.789706;1.77388;128091.3;1.468057e+007
2898.48;0.5582675;-1.369186;101.7153;10.5106;3;3;0;1.758323;1.743043;93348.67;1.069541e+007
2904.48;0.5481961;-1.361821;69.99161;7.232481;3;3;0;1.726602;1.711865;64234.42;7357357
2909.538;0.5398925;-1.35786;54.42364;5.623787;3;3;0;1.700449;1.686153;49947;5719417