File: Ensayos/Compresion/EspAPruebaExtCorto.raw
"Test Type";"Manual"
"Method Name:";"C:\INSTRON\user\template\Pablor.mtM"
"Name:";""
"Operator ID:";""
"Company:";""
"Lab name:";""
"Test date:";"31/03/2017"
"Temperature:";""
"Humidity:";""
"Note 1:";""
"Note 2:";""
"Note 3:";""
"Geometry:";"Rectangular"
"Specimen";1
"Specimen name:";""
"User Input 1:";"No definido"
"User Input 2:";"No definido"
"User Input 3:";"No definido"
"User Input 4:";"No definido"
"User Input 5:";"No definido"
"User Input 6:";"No definido"
"User Input 7:";"No definido"
"User Input 8:";"No definido"
"User Input 9:";"No definido"
"User Input 10:";"No definido"
"Width:";0.250000;"in"
"Thickness:";0.060000;"in"
"Length:";1.250000;"in"
"Diameter:";0.039370;"in"
"Inner diameter:";0.019685;"in"
"Outer diameter:";0.039370;"in"
"Wall thickness:";0.019685;"in"
"Area:";0.015000;"in*in"
"Linear density:";1.000000;"den"
"Sled weight:";2.204623;"lbf"
"Loading span:";0.000000;"mm"
"Support span:";1.000000;"mm"
"Span ratio:";"2"
"Fixture type:";"3-point"
"Comment:";""
"Included"
"Final Width:";0.250000;"in"
"Final Thickness:";0.060000;"in"
"Final Length:";1.250000;"in"
"Final Diameter:";0.039370;"in"
"Final Inner diameter:";0.019685;"in"
"Final Outer diameter:";0.039370;"in"
"Final Wall thickness:";0.019685;"in"
"Final Area:";0.015000;"in*in"
"Final Linear density:";1.000000;"den"
"Time sec";"Extension mm";"Strain 1 %";"Load N";"Stress MPa";"Cycle Count ";"Total Cycle Count ";"Repetitions Count ";"Strain [Exten.] %";"True strain %";"Tenacity gf/tex";"True stress Pa"
0;-0.004392855;-0.0006829684;55.75256;5.761109;0;0;0;-0.01383576;-0.01383672;51166.61;5760312
1;-0.001017857;-0.0009905637;55.81267;5.767321;0;0;0;-0.003205848;-0.003205899;51221.78;5767136
2;0.002357141;-0.0009730854;56.72433;5.861526;0;0;0;0.007424067;0.007423791;52058.45;5861961
3;0.005624996;-0.00137399;60.85234;6.288088;0;0;0;0.01771652;0.01771495;55846.91;6289202
4;0.009053566;-0.001174831;69.477;7.179305;0;0;0;0.02851517;0.0285111;63762.14;7181352
5;0.01237499;-0.001888504;81.47744;8.419352;0;0;0;0.03897635;0.03896876;74775.48;8422633
6;0.01558928;-0.001344442;94.87178;9.803437;0;0;0;0.04910008;0.04908803;87068.06;9808250
7;0.01901785;-0.0013223;109.913;11.3577;0;0;0;0.05989873;0.05988079;100872;1.13645e+007
8;0.02233927;-0.001447274;125.4139;12.95946;0;0;0;0.07035992;0.07033517;115097.9;1.296858e+007
9;0.02560713;-0.001214216;141.2322;14.59402;0;0;0;0.08065236;0.08061986;129615.1;1.460579e+007
10;0.0290357;-0.0009519233;158.601;16.38881;0;0;0;0.09145101;0.09140922;145555.3;1.64038e+007
11;0.03230355;-0.001298002;175.8345;18.16961;0;0;0;0.1017435;0.1016917;161371.2;1.818809e+007
12;0.0355714;-0.001136935;193.4176;19.98653;0;0;0;0.1120359;0.1119732;177508;2.000892e+007
13;0.0389464;-0.001154413;212.8126;21.99068;0;0;0;0.1226658;0.1225907;195307.6;2.201765e+007
14;0.04226783;-0.0008586924;232.4718;24.02213;0;0;0;0.133127;0.1330385;213349.7;2.405411e+007
15;0.04553568;-0.0005203334;252.2349;26.06433;0;0;0;0.1434195;0.1433167;231487.2;2.610171e+007
16;0.04891068;-0.0008198951;272.7912;28.18848;0;0;0;0.1540494;0.1539308;250352.7;2.823191e+007
17;0.05223211;-0.0007133398;293.8801;30.36767;0;0;0;0.1645106;0.1643754;269706.9;3.041763e+007
18;0.05555354;-0.0004967416;315.1979;32.57051;0;0;0;0.1749718;0.1748189;289271.2;3.26275e+007
19;0.05892854;-0.0006274765;337.3751;34.86216;0;0;0;0.1856017;0.1854297;309624.2;3.492687e+007
20;0.06219639;-0.0003120824;358.9741;37.09406;0;0;0;0.1958941;0.1957025;329446.5;3.716673e+007
21;0.06557138;-0.0003379864;381.3972;39.41113;0;0;0;0.206524;0.2063111;350025.3;3.949252e+007
22;0.06889281;-0.0002272381;404.0308;41.74993;0;0;0;0.2169852;0.2167502;370797;4.184052e+007
23;0.07221424;-0.0001071625;427.1991;44.14399;0;0;0;0.2274464;0.2271882;392059.7;4.42444e+007
24;0.07558924;8.219926e-005;451.0075;46.6042;0;0;0;0.2380763;0.2377934;413909.7;4.671515e+007
25;0.07885709;-0.0002329989;474.5071;49.0325;0;0;0;0.2483688;0.2480609;435476.3;4.915428e+007
26;0.08217852;0.0003965353;498.8254;51.5454;0;0;0;0.25883;0.2584956;457794.3;5.167881e+007
27;0.08560709;0.0005275053;524.4142;54.18958;0;0;0;0.2696286;0.2692658;481278.3;5.433569e+007
28;0.08882137;0.0005695944;548.5243;56.68095;0;0;0;0.2797523;0.2793618;503405.2;5.683952e+007
29;0.09219637;0.0007249009;574.104;59.3242;0;0;0;0.2903823;0.2899615;526880.9;5.949647e+007
30;0.09562494;0.0007994386;600.2436;62.02529;0;0;0;0.3011809;0.3007283;550870.3;6.22121e+007
31;0.09883923;0.000884871;625.0303;64.58659;0;0;0;0.3113047;0.3108211;573618.2;6.478766e+007
32;0.1022142;0.001385865;651.6283;67.33505;0;0;0;0.3219346;0.3214174;598028.3;6.755183e+007
33;0.1055892;0.001201323;678.2323;70.08414;0;0;0;0.3325644;0.3320127;622444;7.031721e+007
34;0.1088571;0.001363449;703.8729;72.73368;0;0;0;0.3428569;0.3422705;645975.6;7.298305e+007
35;0.1122856;0.001437947;731.4461;75.58292;0;0;0;0.3536556;0.3530317;671280.7;7.585022e+007
36;0.1156071;0.001745033;759.3489;78.46621;0;0;0;0.3641168;0.3634555;696888.4;7.875192e+007
37;0.1188214;0.001704747;786.0343;81.2237;0;0;0;0.3742405;0.3735419;721378.7;8.152767e+007
38;0.1223035;0.001797742;815.3065;84.2485;0;0;0;0.3852078;0.3844678;748243.1;8.457304e+007
39;0.1256785;0.001753694;844.3847;87.25326;0;0;0;0.3958378;0.3950564;774929.5;8.759864e+007
40;0.1288928;0.002026333;872.5026;90.15878;0;0;0;0.4059615;0.4051397;800734.5;9.052479e+007
41;0.1323213;0.002373195;902.4354;93.25185;0;0;0;0.4167601;0.4158941;828205.3;9.364048e+007
42;0.1356428;0.002315705;932.3076;96.33865;0;0;0;0.4272213;0.4263113;855620.3;9.675022e+007
43;0.1389106;0.002476459;961.2857;99.33305;0;0;0;0.4375138;0.4365594;882214.8;9.976765e+007
44;0.1423392;0.002831395;992.2776;102.5356;0;0;0;0.4483124;0.4473105;910657.4;1.029952e+008
45;0.1456606;0.00303604;1022.619;105.6709;0;0;0;0.4587736;0.4577245;938503.2;1.061556e+008
46;0.1489285;0.0028959;1051.938;108.7005;0;0;0;0.4690661;0.4679694;965410.5;1.092104e+008
47;0.152357;0.002349094;1083.245;111.9356;0;0;0;0.4798647;0.478717;994142.6;1.124727e+008
48;0.1556785;0.00109657;1113.851;115.0981;0;0;0;0.4903259;0.4891277;1022230;1.156625e+008
49;0.1589463;-0.0005224497;1143.507;118.1626;0;0;0;0.5006183;0.4993694;1049448;1.187542e+008
50;0.1623749;-0.002258841;1174.777;121.3939;0;0;0;0.511417;0.5101137;1078145;1.220147e+008
51;0.1656963;-0.003846354;1205.643;124.5834;0;0;0;0.5218782;0.5205211;1106473;1.252336e+008
52;0.1689642;-0.005458555;1235.534;127.6721;0;0;0;0.5321707;0.5307596;1133904;1.283515e+008
53;0.1723927;-0.007583899;1267.704;130.9963;0;0;0;0.5429692;0.5415005;1163428;1.317076e+008
54;0.1757142;-0.01083687;1298.725;134.2018;0;0;0;0.5534305;0.5519047;1191898;1.349445e+008
55;0.1789285;-0.01453903;1328.256;137.2534;0;0;0;0.5635542;0.5619722;1219000;1.380269e+008
56;0.182357;-0.01840151;1360.717;140.6078;0;0;0;0.5743529;0.5727097;1248791;1.414153e+008
57;0.185732;-0.02245186;1391.856;143.8254;0;0;0;0.5849828;0.5832784;1277369;1.446668e+008
58;0.1889463;-0.02639401;1421.524;146.8911;0;0;0;0.5951065;0.5933427;1304596;1.477653e+008
59;0.1923749;-0.03043907;1453.409;150.1859;0;0;0;0.6059051;0.6040769;1333859;1.510959e+008
60;0.1956963;-0.03428741;1484.016;153.3486;0;0;0;0.6163663;0.6144745;1361948;1.542938e+008
61;0.1989106;-0.0382631;1513.854;156.4319;0;0;0;0.6264901;0.6245357;1389332;1.57412e+008
62;0.2023391;-0.04219327;1545.605;159.7129;0;0;0;0.6372886;0.6352665;1418471;1.607307e+008
63;0.205607;-0.04600127;1575.042;162.7547;0;0;0;0.6475812;0.6454933;1445487;1.638087e+008
64;0.2088749;-0.04973521;1604.708;165.8202;0;0;0;0.6578736;0.655719;1472712;1.66911e+008
65;0.2123034;-0.0528337;1635.919;169.0453;0;0;0;0.6686722;0.6664465;1501356;1.701756e+008
66;0.2155713;-0.05598196;1665.419;172.0937;0;0;0;0.6789647;0.6766701;1528429;1.732621e+008
67;0.2188927;-0.0590516;1695.529;175.205;0;0;0;0.6894259;0.6870603;1556062;1.764129e+008
68;0.2222677;-0.06224266;1726.45;178.4002;0;0;0;0.7000558;0.6976168;1584440;1.796491e+008
69;0.2255356;-0.06615683;1756.833;181.5398;0;0;0;0.7103482;0.7078372;1612324;1.828294e+008
70;0.2289106;-0.07026792;1788.286;184.7899;0;0;0;0.7209782;0.7183916;1641190;1.861222e+008
71;0.232232;-0.07458421;1819.27;187.9916;0;0;0;0.7314394;0.7287773;1669625;1.893667e+008
72;0.2354998;-0.07886076;1850.809;191.2507;0;0;0;0.7417318;0.7389945;1698570;1.926692e+008
73;0.2389284;-0.08313199;1883.082;194.5855;0;0;0;0.7525305;0.7497131;1728188;1.960498e+008
74;0.2421963;-0.08720515;1914.399;197.8216;0;0;0;0.7628229;0.7599281;1756930;1.993307e+008
75;0.2455177;-0.09141751;1946.593;201.1483;0;0;0;0.7732841;0.7703096;1786475;2.027038e+008
76;0.2488927;-0.09517379;1979.708;204.5703;0;0;0;0.783914;0.7808574;1816867;2.061739e+008
77;0.2521605;-0.09850204;2011.077;207.8117;0;0;0;0.7942064;0.7910692;1845655;2.094622e+008
78;0.2555355;-0.1013004;2044.316;211.2464;0;0;0;0.8048363;0.8016148;1876160;2.129466e+008
79;0.2589105;-0.1040712;2077.391;214.6641;0;0;0;0.8154662;0.8121593;1906514;2.164146e+008
80;0.2621784;-0.1067419;2109.423;217.9741;0;0;0;0.8257588;0.822368;1935911;2.19774e+008
81.00001;0.2655534;-0.1092367;2143.123;221.4565;0;0;0;0.8363886;0.8329103;1966840;2.233087e+008
82.00001;0.2689284;-0.1119605;2176.715;224.9277;0;0;0;0.8470186;0.8434515;1997668;2.268328e+008
83.00001;0.2721962;-0.1142341;2208.81;228.2442;0;0;0;0.857311;0.853657;2027124;2.30201e+008
84.00001;0.2755713;-0.1166881;2242.81;231.7575;0;0;0;0.867941;0.864196;2058327;2.33769e+008
85.00001;0.2789462;-0.1191835;2277.173;235.3084;0;0;0;0.8785709;0.8747339;2089864;2.373757e+008
86.00001;0.2822141;-0.1215305;2309.897;238.6899;0;0;0;0.8888633;0.8849362;2119896;2.408115e+008
87.00001;0.2855891;-0.1238149;2345.04;242.3213;0;0;0;0.8994932;0.8954719;2152148;2.44501e+008
88.00001;0.2889641;-0.126112;2379.653;245.898;0;0;0;0.9101232;0.9060065;2183914;2.481359e+008
89.00001;0.2922319;-0.1283016;2412.755;249.3185;0;0;0;0.9204156;0.9162056;2214293;2.516133e+008
90.00001;0.2956069;-0.130634;2447.774;252.9372;0;0;0;0.9310455;0.9267379;2246432;2.552921e+008
91.00001;0.298982;-0.1329231;2482.717;256.548;0;0;0;0.9416755;0.9372693;2278500;2.589638e+008
92.00001;0.3022498;-0.1352621;2516.581;260.0472;0;0;0;0.9519679;0.9474652;2309579;2.625228e+008
93.00001;0.3056248;-0.1375086;2552.523;263.7613;0;0;0;0.9625977;0.9579943;2342564;2.663002e+008
94.00001;0.3089998;-0.1400168;2587.857;267.4124;0;0;0;0.9732276;0.9685223;2374992;2.700149e+008
95.00001;0.3122141;-0.1421558;2622.098;270.9507;0;0;0;0.9833514;0.978548;2406417;2.736151e+008
96.00001;0.3156962;-0.144517;2658.748;274.7379;0;0;0;0.9943188;0.989408;2440052;2.774697e+008
97.00001;0.3190176;-0.146795;2694.678;278.4506;0;0;0;1.00478;0.9997656;2473026;2.812484e+008
98.00001;0.3222319;-0.1487643;2729.922;282.0925;0;0;0;1.014904;1.009788;2505371;2.849555e+008
99.00001;0.3257141;-0.1507813;2767.254;285.9501;0;0;0;1.025871;1.020645;2539632;2.888836e+008
100;0.3290355;-0.1523517;2803.388;289.684;0;0;0;1.036332;1.030999;2572794;2.926861e+008
101;0.3323034;-0.1538154;2839.268;293.3916;0;0;0;1.046625;1.041186;2605723;2.964623e+008
101.154;0.3327319;-0.1540456;2844.505;293.9328;0;0;0;1.047974;1.042521;2610529;2.970131e+008
101.156;0.3327319;-0.1540543;2844.564;293.9389;0;0;0;1.047974;1.042521;2610584;2.970193e+008
102.156;0.3296783;-0.1535822;2801.784;289.5182;0;0;0;1.038357;1.033003;2571322;2.925245e+008
103.156;0.3261962;-0.152651;2750.63;284.2323;0;0;0;1.02739;1.022148;2524376;2.871525e+008
104.156;0.3228212;-0.1516185;2702.138;279.2215;0;0;0;1.01676;1.011626;2479873;2.820605e+008
105.156;0.3195534;-0.1504848;2656.532;274.5089;0;0;0;1.006467;1.001436;2438018;2.772717e+008
106.156;0.3161248;-0.1492542;2609.947;269.695;0;0;0;0.9956686;0.9907445;2395265;2.723803e+008
107.156;0.3128033;-0.1478524;2563.921;264.939;0;0;0;0.9852074;0.9803859;2353024;2.675492e+008
108.156;0.3095355;-0.1466085;2520.067;260.4074;0;0;0;0.974915;0.9701933;2312778;2.629462e+008
109.156;0.306107;-0.1452665;2474.853;255.7353;0;0;0;0.9641164;0.9594985;2271283;2.582009e+008
110.156;0.3027855;-0.1439679;2431.156;251.22;0;0;0;0.9536552;0.9491366;2231181;2.536158e+008
111.156;0.2995177;-0.14279;2389.405;246.9057;0;0;0;0.9433628;0.9389409;2192863;2.492349e+008
112.156;0.2960891;-0.1415269;2346.078;242.4286;0;0;0;0.9325641;0.9282426;2153101;2.446894e+008
113.156;0.2927677;-0.1402181;2303.937;238.074;0;0;0;0.9221029;0.9178774;2114426;2.402693e+008
114.156;0.2894998;-0.1393067;2263.233;233.8678;0;0;0;0.9118105;0.9076786;2077069;2.360003e+008
115.156;0.2860712;-0.1380852;2221.22;229.5265;0;0;0;0.9010118;0.8969768;2038513;2.315946e+008
116.156;0.2826963;-0.1370804;2180.831;225.353;0;0;0;0.8903819;0.8864414;2001446;2.273595e+008
117.156;0.279482;-0.1365377;2142.422;221.3841;0;0;0;0.8802581;0.8764064;1966197;2.233328e+008
118.156;0.2760534;-0.135985;2102.181;217.2258;0;0;0;0.8694595;0.8657014;1929265;2.191145e+008
119.156;0.2726784;-0.1349664;2063.307;213.2088;0;0;0;0.8588296;0.8551626;1893589;2.150399e+008
120.156;0.2694641;-0.1335294;2026.411;209.3962;0;0;0;0.8487058;0.8451246;1859728;2.111733e+008
121.156;0.2660355;-0.1317884;1986.884;205.3118;0;0;0;0.8379072;0.8344162;1823452;2.070321e+008
122.156;0.2626605;-0.1301176;1949.396;201.438;0;0;0;0.8272772;0.8238741;1789048;2.031045e+008
123.156;0.2594462;-0.1284757;1913.749;197.7545;0;0;0;0.8171535;0.8138329;1756333;1.993705e+008
124.156;0.2560177;-0.1268017;1875.871;193.8403;0;0;0;0.8063549;0.8031213;1721570;1.954034e+008
125.156;0.2526962;-0.1251261;1839.555;190.0877;0;0;0;0.7958937;0.7927432;1688242;1.916006e+008
126.156;0.249482;-0.1234893;1805.062;186.5234;0;0;0;0.7857699;0.7826989;1656586;1.879891e+008
127.156;0.2459998;-0.1218543;1768.147;182.7089;0;0;0;0.7748026;0.7718165;1622708;1.841246e+008
128.156;0.242732;-0.120909;1733.846;179.1645;0;0;0;0.7645102;0.7616026;1591228;1.805342e+008
129.156;0.2394641;-0.1211519;1700.201;175.6878;0;0;0;0.7542177;0.7513877;1560350;1.770128e+008
130.156;0.2360356;-0.1212555;1665.438;172.0956;0;0;0;0.7434191;0.7406693;1528447;1.73375e+008
131.156;0.2327677;-0.1214968;1632.262;168.6674;0;0;0;0.7331266;0.7304523;1497999;1.699039e+008
132.156;0.2294999;-0.1217616;1599.571;165.2893;0;0;0;0.7228342;0.7202343;1467998;1.664841e+008
133.156;0.2260713;-0.1219518;1565.951;161.8153;0;0;0;0.7120355;0.7095125;1437143;1.629675e+008
134.156;0.2228034;-0.1221638;1533.519;158.464;0;0;0;0.7017431;0.6992923;1407379;1.59576e+008
135.156;0.2195356;-0.1223223;1502.09;155.2163;0;0;0;0.6914507;0.6890711;1378535;1.562896e+008
136.156;0.216107;-0.1225163;1469.622;151.8612;0;0;0;0.680652;0.678346;1348737;1.528949e+008
137.156;0.2127856;-0.1227216;1438.331;148.6278;0;0;0;0.6701908;0.667955;1320021;1.496239e+008
138.156;0.2095177;-0.1229105;1408.006;145.4942;0;0;0;0.6598983;0.6577306;1292190;1.464543e+008
139.156;0.2061427;-0.123124;1376.325;142.2205;0;0;0;0.6492684;0.6471697;1263115;1.431439e+008
140.156;0.2028213;-0.1233791;1346.093;139.0966;0;0;0;0.6388072;0.6367755;1235370;1.399851e+008
141.156;0.1995535;-0.1235052;1316.134;136.0007;0;0;0;0.6285148;0.6265479;1207875;1.368555e+008
142.156;0.1961784;-0.1237375;1285.323;132.817;0;0;0;0.6178849;0.6159838;1179598;1.336376e+008
143.156;0.192857;-0.123943;1256.062;129.7933;0;0;0;0.6074237;0.6055863;1152744;1.305817e+008
144.156;0.1895892;-0.1242277;1227;126.7902;0;0;0;0.5971312;0.5953554;1126072;1.275473e+008
145.156;0.1861606;-0.1243962;1197.054;123.6959;0;0;0;0.5863326;0.5846203;1098590;1.244211e+008
146.156;0.1828392;-0.1246223;1168.522;120.7476;0;0;0;0.5758713;0.5742196;1072405;1.214429e+008
147.156;0.1795177;-0.1249114;1139.704;117.7697;0;0;0;0.5654102;0.5638178;1045957;1.184355e+008
148.156;0.1761963;-0.1251152;1111.384;114.8432;0;0;0;0.554949;0.5534149;1019966;1.154805e+008
149.156;0.1728749;-0.1254145;1083.604;111.9726;0;0;0;0.5444878;0.5430108;994471.4;1.125823e+008
150.156;0.1694999;-0.1256569;1055.246;109.0423;0;0;0;0.5338579;0.532438;968446.7;1.096245e+008
151.156;0.1661785;-0.1258864;1028.308;106.2587;0;0;0;0.5233967;0.5220317;943723.9;1.068148e+008
152.156;0.1628035;-0.1261386;1000.682;103.404;0;0;0;0.5127668;0.5114566;918370.8;1.039343e+008
153.156;0.159482;-0.1264357;973.2378;100.5681;0;0;0;0.5023056;0.5010482;893183.7;1.010733e+008
154.156;0.1562142;-0.1266507;946.2162;97.77586;0;0;0;0.4920132;0.4908067;868384.8;9.825694e+007
155.156;0.1527856;-0.1270603;918.1921;94.88004;0;0;0;0.4812145;0.4800604;842665.9;9.533662e+007
156.156;0.1494642;-0.1272737;890.6728;92.03638;0;0;0;0.4707534;0.4696488;817410.2;9.246964e+007
157.156;0.1461963;-0.1274814;863.2888;89.20668;0;0;0;0.4604609;0.459404;792278.6;8.961744e+007
158.156;0.1427678;-0.1278708;835.3511;86.31979;0;0;0;0.4496623;0.4486543;766639;8.670794e+007
159.156;0.1394463;-0.1281517;807.9524;83.48858;0;0;0;0.4392011;0.4382394;741493.9;8.385526e+007
160.156;0.1361785;-0.1284867;781.4362;80.74857;0;0;0;0.4289086;0.4279914;717158.8;8.10949e+007
161.156;0.1327499;-0.1287901;753.887;77.90182;0;0;0;0.41811;0.4172383;691875.8;7.822753e+007
162.156;0.1294285;-0.1290359;727.1502;75.139;0;0;0;0.4076488;0.4068202;667338.1;7.54453e+007
163.156;0.1261606;-0.1293743;701.4825;72.48667;0;0;0;0.3973563;0.3965689;643781.8;7.27747e+007
164.156;0.1227321;-0.1296933;675.3435;69.78563;0;0;0;0.3865577;0.3858125;619792.8;7.005539e+007
165.156;0.1194106;-0.1299968;650.2553;67.19318;0;0;0;0.3760965;0.375391;596768.3;6.744589e+007
166.156;0.1161428;-0.1302887;626.1899;64.70641;0;0;0;0.365804;0.3651366;574682.4;6.494311e+007
167.156;0.1127142;-0.1305536;600.9034;62.09348;0;0;0;0.3550054;0.3543767;551475.8;6.231391e+007
168.156;0.1093928;-0.1309118;576.5666;59.57867;0;0;0;0.3445442;0.343952;529140.9;5.978395e+007
169.156;0.1061249;-0.1311541;553.7866;57.22473;0;0;0;0.3342518;0.3336944;508234.7;5.7416e+007
170.156;0.1026964;-0.1314988;530.0792;54.77496;0;0;0;0.3234531;0.3229311;486477.3;5.495213e+007
171.156;0.09937494;-0.1318176;507.2509;52.41603;0;0;0;0.3129919;0.3125031;465526.8;5.258009e+007
172.156;0.09610708;-0.1320603;485.0895;50.12602;0;0;0;0.3026994;0.3022422;445188.3;5.027775e+007
173.156;0.09267851;-0.1323732;462.3811;47.77947;0;0;0;0.2919008;0.2914756;424347.7;4.791894e+007
174.156;0.08935709;-0.1327437;440.5178;45.52026;0;0;0;0.2814397;0.2810444;404282.8;4.564838e+007
175.156;0.0861428;-0.1330135;419.3896;43.33701;0;0;0;0.2713159;0.2709485;384892.6;4.345459e+007
176.156;0.08271423;-0.1332738;397.5416;41.07938;0;0;0;0.2605173;0.2601785;364841.7;4.11864e+007
177.156;0.0793928;-0.1335299;376.5803;38.91338;0;0;0;0.2500561;0.249744;345604.5;3.901068e+007
178.156;0.07612496;-0.1338713;356.3216;36.81997;0;0;0;0.2397636;0.2394767;327012.2;3.690825e+007
179.156;0.07269638;-0.1341467;335.5177;34.67023;0;0;0;0.228965;0.2287033;307919.5;3.474961e+007
180.156;0.06942853;-0.1343994;315.8621;32.63914;0;0;0;0.2186725;0.2184338;289880.7;3.271052e+007
181.156;0.06616067;-0.1346786;296.8571;30.6753;0;0;0;0.2083801;0.2081633;272439;3.073922e+007
182.156;0.0627321;-0.1350012;277.3338;28.65789;0;0;0;0.1975814;0.1973865;254521.6;2.871451e+007
183.156;0.05946425;-0.1353385;258.6202;26.72415;0;0;0;0.187289;0.1871138;237347.3;2.67742e+007
184.156;0.05619639;-0.1355388;240.5535;24.85725;0;0;0;0.1769965;0.1768401;220766.7;2.490124e+007
185.156;0.05276782;-0.1359595;222.0824;22.94856;0;0;0;0.1661979;0.1660599;203814.9;2.29867e+007
186.156;0.04944639;-0.1361343;204.1661;21.09721;0;0;0;0.1557367;0.1556155;187372.4;2.113007e+007
187.156;0.04623211;-0.1364211;187.1682;19.34075;0;0;0;0.145613;0.145507;171772.6;1.936891e+007
188.156;0.04280354;-0.136789;170.152;17.58241;0;0;0;0.1348143;0.1347235;156156.1;1.760611e+007
189.156;0.03948212;-0.1369934;153.9162;15.90471;0;0;0;0.1243531;0.1242759;141255.8;1.592448e+007
190.156;0.03621426;-0.1372999;138.472;14.3088;0;0;0;0.1140607;0.1139957;127081.9;1.432512e+007
191.156;0.03283926;-0.1376047;123.3621;12.74744;0;0;0;0.1034308;0.1033773;113214.9;1.276062e+007
192.156;0.02951784;-0.1376904;109.5603;11.32126;0;0;0;0.09296957;0.09292638;100548.4;1.133178e+007
193.156;0.02624998;-0.1379229;97.06842;10.03042;0;0;0;0.08267711;0.08264296;89084.02;1.003872e+007
193.934;0.02357141;-0.1381165;87.57507;9.049441;0;0;0;0.07424067;0.07421313;80371.55;9056160
193.936;0.02357141;-0.1381236;87.56802;9.048714;1;1;0;0.07424067;0.07421313;80365.08;9055431
194.936;0.02667855;-0.1380326;102.1279;10.55323;1;1;0;0.08402694;0.08399166;93727.29;1.05621e+007
195.936;0.03021427;-0.1378398;119.391;12.33709;1;1;0;0.09516305;0.09511779;109570.4;1.234883e+007
196.936;0.03358926;-0.1376139;137.1895;14.17628;1;1;0;0.105793;0.105737;125904.9;1.419127e+007
197.936;0.03680355;-0.1372939;155.5117;16.06958;1;1;0;0.1159167;0.1158496;142720;1.60882e+007
198.936;0.04023212;-0.1370021;175.8718;18.17345;1;1;0;0.1267153;0.1266351;161405.4;1.819648e+007
199.936;0.04360712;-0.1368843;196.4347;20.2983;1;1;0;0.1373452;0.137251;180276.9;2.032617e+007
200.936;0.0468214;-0.136569;216.772;22.39982;1;1;0;0.147469;0.1473603;198941.4;2.243285e+007
201.936;0.05030354;-0.1362802;238.594;24.65477;1;1;0;0.1584363;0.158311;218968.4;2.469383e+007
202.936;0.05362497;-0.1359922;260.0125;26.86801;1;1;0;0.1688975;0.1687551;238625;2.691339e+007
203.936;0.05689282;-0.1357156;281.3783;29.07581;1;1;0;0.17919;0.1790296;258233.4;2.912791e+007
204.936;0.06026782;-0.1354744;303.973;31.4106;1;1;0;0.1898199;0.18964;278969.5;3.147023e+007
205.936;0.06358925;-0.1351116;326.1055;33.69763;1;1;0;0.2002811;0.2000808;299281.5;3.376512e+007
206.936;0.0668571;-0.1349405;348.1251;35.973;1;1;0;0.2105736;0.2103522;319490;3.604875e+007
207.936;0.07028567;-0.1345311;371.5764;38.39631;1;1;0;0.2213722;0.2211275;341012.3;3.848131e+007
208.936;0.07360709;-0.1341919;394.8482;40.80106;1;1;0;0.2318334;0.231565;362369.8;4.089565e+007
209.936;0.07687495;-0.1338944;417.8114;43.17393;1;1;0;0.2421258;0.2418332;383444.1;4.327846e+007
210.936;0.08030352;-0.1337211;442.2454;45.69878;1;1;0;0.2529245;0.2526051;405868.3;4.581436e+007
211.936;0.08357137;-0.1332939;466.6207;48.21758;1;1;0;0.2632169;0.2628711;428238.7;4.834449e+007
212.936;0.08683923;-0.1330255;490.8731;50.72366;1;1;0;0.2735094;0.273136;450496.2;5.086239e+007
213.936;0.09026779;-0.1326607;516.6018;53.3823;1;1;0;0.284308;0.2839046;474108.5;5.353407e+007
214.936;0.09353565;-0.1323715;541.8363;55.98987;1;1;0;0.2946005;0.2941674;497267.4;5.615481e+007
215.936;0.09680351;-0.1321298;566.8866;58.5784;1;1;0;0.3048929;0.3044291;520257.1;5.8757e+007
216.936;0.1002321;-0.1317491;594.1043;61.3909;1;1;0;0.3156916;0.3151943;545236;6.158471e+007
217.936;0.1035535;-0.1314011;619.9443;64.06104;1;1;0;0.3261528;0.325622;568950.5;6.426997e+007
218.936;0.1068214;-0.1310987;646.0121;66.75471;1;1;0;0.3364452;0.3358805;592874.1;6.697931e+007
219.936;0.1101964;-0.1308107;673.4376;69.58869;1;1;0;0.3470752;0.3464742;618043.7;6.983021e+007
220.936;0.1135178;-0.1304491;700.1561;72.34961;1;1;0;0.3575363;0.3568987;642564.5;7.260829e+007
221.936;0.1167856;-0.1301819;727.3566;75.16034;1;1;0;0.3678288;0.367154;667527.6;7.54368e+007
222.936;0.1201606;-0.1299053;756.0114;78.12134;1;1;0;0.3784587;0.3777444;693825.4;7.841699e+007
223.936;0.1234821;-0.1295912;783.9392;81.00722;1;1;0;0.3889198;0.3881655;719456;8.132227e+007
224.936;0.1268035;-0.129219;813.4195;84.05352;1;1;0;0.3993811;0.3985857;746511.4;8.438921e+007
225.936;0.1301249;-0.1290359;842.6378;87.07274;1;1;0;0.4098423;0.4090047;773326.3;8.74296e+007
226.936;0.1334463;-0.1286366;872.0106;90.10794;1;1;0;0.4203035;0.4194226;800283;9.048667e+007
227.936;0.1368213;-0.1283997;902.3098;93.23886;1;1;0;0.4309334;0.4300075;828089.9;9.364066e+007
228.936;0.1401428;-0.1282019;932.1504;96.3224;1;1;0;0.4413945;0.4404232;855476;9.674756e+007
229.936;0.1434642;-0.12789;962.406;99.44881;1;1;0;0.4518557;0.4508379;883242.9;9.989818e+007
230.936;0.1468392;-0.127633;993.4536;102.6571;1;1;0;0.4624856;0.4614194;911736.6;1.031318e+008
231.936;0.1501071;-0.1273921;1023.3;105.7412;1;1;0;0.4727781;0.471664;939127.8;1.062411e+008
232.936;0.1534285;-0.12719;1054.307;108.9453;1;1;0;0.4832393;0.4820754;967584.7;1.094718e+008
233.936;0.156857;-0.1268076;1086.005;112.2207;1;1;0;0.4940379;0.4928216;996675.2;1.127752e+008
234.936;0.1600713;-0.1265832;1115.877;115.3076;1;1;0;0.5041617;0.502895;1024090;1.158889e+008
235.936;0.1634999;-0.1262781;1147.837;118.6101;1;1;0;0.5149602;0.5136389;1053422;1.192209e+008
236.936;0.1668749;-0.126068;1179.38;121.8695;1;1;0;0.5255902;0.5242138;1082370;1.225101e+008
237.936;0.1700892;-0.1258693;1209.24;124.9551;1;1;0;0.5357139;0.5342841;1109774;1.256245e+008
238.936;0.1735177;-0.1252911;1241.728;128.3122;1;1;0;0.5465126;0.5450246;1139590;1.290134e+008
239.936;0.1768927;-0.1250513;1274.11;131.6583;1;1;0;0.5571425;0.5555962;1169307;1.323918e+008
240.936;0.180107;-0.1247836;1304.754;134.8248;1;1;0;0.5672662;0.5656634;1197431;1.355896e+008
241.936;0.1835356;-0.124304;1337.663;138.2254;1;1;0;0.5780649;0.5764005;1227633;1.390244e+008
242.936;0.1869106;-0.1242131;1369.943;141.5611;1;1;0;0.5886948;0.5869688;1257258;1.423944e+008
243.936;0.1901249;-0.1239297;1400.391;144.7074;1;1;0;0.5988185;0.5970327;1285201;1.455739e+008
244.936;0.1935534;-0.1237425;1432.718;148.0479;1;1;0;0.6096171;0.6077665;1314870;1.489504e+008
245.936;0.1968749;-0.1235276;1463.896;151.2696;1;1;0;0.6200784;0.6181638;1343483;1.522076e+008
246.936;0.2001427;-0.1231808;1494.377;154.4193;1;1;0;0.6303708;0.6283923;1371456;1.553927e+008
247.936;0.2035713;-0.1230673;1526.435;157.732;1;1;0;0.6411694;0.6391227;1400878;1.587433e+008
248.936;0.2069463;-0.1228702;1557.354;160.9269;1;1;0;0.6517994;0.6496843;1429253;1.619758e+008
249.936;0.2101606;-0.1226657;1586.807;163.9704;1;1;0;0.6619231;0.659742;1456284;1.650558e+008
250.936;0.2135892;-0.1224133;1618.126;167.2067;1;1;0;0.6727217;0.6704691;1485027;1.683316e+008
251.936;0.2169641;-0.1222122;1648.955;170.3924;1;1;0;0.6833516;0.6810274;1513320;1.715568e+008
252.936;0.2201784;-0.1219629;1678.509;173.4462;1;1;0;0.6934754;0.6910819;1540442;1.746491e+008
253.936;0.223607;-0.1223266;1710.678;176.7704;1;1;0;0.704274;0.7018056;1569965;1.780153e+008
254.936;0.226982;-0.1238186;1742.154;180.0229;1;1;0;0.714904;0.7123606;1598852;1.813099e+008
255.936;0.2301963;-0.1252343;1772.898;183.1999;1;1;0;0.7250277;0.722412;1627068;1.845281e+008
256.936;0.2336784;-0.1266382;1805.886;186.6086;1;1;0;0.7359951;0.7332999;1657342;1.879821e+008
257.936;0.2369463;-0.1280829;1837.686;189.8945;1;1;0;0.7462875;0.7435166;1686526;1.913117e+008
258.936;0.2402141;-0.1294473;1869.043;193.1349;1;1;0;0.75658;0.7537323;1715304;1.945961e+008
259.936;0.2436427;-0.1309525;1902.504;196.5925;1;1;0;0.7673786;0.7644493;1746013;1.981011e+008
260.012;0.243857;-0.1310452;1904.768;196.8264;1;1;0;0.7680535;0.765119;1748091;1.983382e+008
"Specimen";2
"Specimen name:";""
"User Input 1:";"No definido"
"User Input 2:";"No definido"
"User Input 3:";"No definido"
"User Input 4:";"No definido"
"User Input 5:";"No definido"
"User Input 6:";"No definido"
"User Input 7:";"No definido"
"User Input 8:";"No definido"
"User Input 9:";"No definido"
"User Input 10:";"No definido"
"Width:";0.250000;"in"
"Thickness:";0.060000;"in"
"Length:";1.250000;"in"
"Diameter:";0.039370;"in"
"Inner diameter:";0.019685;"in"
"Outer diameter:";0.039370;"in"
"Wall thickness:";0.019685;"in"
"Area:";0.015000;"in*in"
"Linear density:";1.000000;"den"
"Sled weight:";2.204623;"lbf"
"Loading span:";0.000000;"mm"
"Support span:";1.000000;"mm"
"Span ratio:";"2"
"Fixture type:";"3-point"
"Comment:";""
"Included"
"Final Width:";0.250000;"in"
"Final Thickness:";0.060000;"in"
"Final Length:";1.250000;"in"
"Final Diameter:";0.039370;"in"
"Final Inner diameter:";0.019685;"in"
"Final Outer diameter:";0.039370;"in"
"Final Wall thickness:";0.019685;"in"
"Final Area:";0.015000;"in*in"
"Final Linear density:";1.000000;"den"
"Time sec";"Extension mm";"Strain 1 %";"Load N";"Stress MPa";"Cycle Count ";"Total Cycle Count ";"Repetitions Count ";"Strain [Exten.] %";"True strain %";"Tenacity gf/tex";"True stress Pa"
0;0;0.01245164;81.19121;8.389775;0;0;0;0;0;74512.79;8389775
1;0.003321426;0.01184676;98.90039;10.21973;0;0;0;0.01046119;0.01046064;90765.3;1.02208e+007
2;0.006749996;0.01023389;117.468;12.13838;0;0;0;0.02125983;0.02125757;107805.6;1.214096e+007
3;0.00996428;0.008658843;134.4067;13.88872;0;0;0;0.03138356;0.03137863;123351.1;1.389308e+007
4;0.01339285;0.006911949;152.2293;15.7304;0;0;0;0.0421822;0.04217331;139707.6;1.573703e+007
5;0.01676785;0.004728958;170.3918;17.60719;0;0;0;0.05281211;0.05279818;156376.2;1.761649e+007
6;0.01998213;0.003010593;188.1371;19.44088;0;0;0;0.06293584;0.06291604;172661.8;1.945311e+007
7;0.0234107;0.001387106;206.8142;21.37084;0;0;0;0.07373448;0.07370731;189802.6;2.13866e+007
8;0.0267857;-0.0002942645;225.4451;23.29604;0;0;0;0.0843644;0.08432883;206901;2.33157e+007
9;0.03005355;-0.002272414;243.2079;25.13153;0;0;0;0.09465685;0.09461209;223202.7;2.515532e+007
10;0.03348212;-0.003965933;261.9558;27.06882;0;0;0;0.1054555;0.1053999;240408.5;2.709736e+007
11;0.03680355;-0.006096645;280.3371;28.96822;0;0;0;0.1159167;0.1158496;257277.8;2.90018e+007
12;0.04001783;-0.00773769;298.17;30.81096;0;0;0;0.1260404;0.125961;273643.9;3.084979e+007
13;0.0434464;-0.00981922;316.8105;32.73715;0;0;0;0.1368391;0.1367455;290751.1;3.278195e+007
14;0.0468214;-0.0117097;335.3228;34.65009;0;0;0;0.147469;0.1473603;307740.7;3.470119e+007
15;0.05003568;-0.01356002;352.7554;36.45146;0;0;0;0.1575927;0.1574687;323739.3;3.65089e+007
16;0.05351782;-0.01531957;372.1647;38.45709;0;0;0;0.1685601;0.1684182;341552.1;3.852192e+007
17;0.05678568;-0.01667387;390.6392;40.36613;0;0;0;0.1788525;0.1786928;358507.1;4.043833e+007
18;0.06005353;-0.01830598;409.0378;42.26732;0;0;0;0.189145;0.1889663;375392.2;4.234727e+007
19;0.06353567;-0.02018098;428.5666;44.2853;0;0;0;0.2001124;0.1999124;393314.7;4.437392e+007
20;0.06680353;-0.02158411;447.8981;46.2829;0;0;0;0.2104048;0.2101838;411056.1;4.638028e+007
21;0.07001781;-0.02326622;467.5368;48.31223;0;0;0;0.2205285;0.2202857;429079.3;4.841877e+007
22;0.07344639;-0.02455982;488.886;50.51832;0;0;0;0.2313272;0.23106;448672.4;5.063518e+007
23;0.0767678;-0.02591255;509.4239;52.64057;0;0;0;0.2417884;0.2414965;467521;5.276785e+007
24;0.08003566;-0.02701752;530.011;54.76792;0;0;0;0.2520808;0.2517636;486414.8;5.490598e+007
25;0.08346423;-0.02854092;550.8336;56.91959;0;0;0;0.2628795;0.2625345;505524.6;5.706922e+007
26;0.08673208;-0.02986238;571.6065;59.06612;0;0;0;0.2731719;0.2727995;524588.8;5.922747e+007
27;0.08999994;-0.03113364;591.5459;61.12653;0;0;0;0.2834644;0.2830634;542888.1;6.12998e+007
28;0.09342851;-0.03264395;612.9405;63.33731;0;0;0;0.294263;0.2938309;562522.9;6.352369e+007
29;0.09669637;-0.03370143;633.3511;65.44641;0;0;0;0.3045555;0.3040927;581254.6;6.564574e+007
30;0.1000178;-0.0349583;653.7144;67.55062;0;0;0;0.3150167;0.3145215;599942.8;6.776341e+007
31;0.1033392;-0.03607507;674.4033;69.68848;0;0;0;0.3254779;0.3249493;618930;6.991531e+007
32;0.1066606;-0.03720885;694.6747;71.7832;0;0;0;0.335939;0.335376;637533.9;7.202434e+007
33;0.1099821;-0.03862577;715.6206;73.94762;0;0;0;0.3464002;0.3458016;656756.9;7.420377e+007
34;0.1133571;-0.03948308;736.4388;76.09882;0;0;0;0.3570302;0.3563943;675862.7;7.637052e+007
35;0.1166249;-0.04065056;756.7271;78.19529;0;0;0;0.3673226;0.3666496;694482.2;7.848252e+007
36;0.1199999;-0.04137603;777.8847;80.38158;0;0;0;0.3779525;0.3772401;713899.5;8.068538e+007
37;0.1233213;-0.04259967;799.1638;82.58043;0;0;0;0.3884137;0.3876613;733428.3;8.290118e+007
38;0.1266428;-0.04364892;820.2829;84.76274;0;0;0;0.3988749;0.3980815;752810.3;8.510084e+007
39;0.1300178;-0.04536372;842.2483;87.03249;0;0;0;0.4095048;0.4086686;772968.8;8.73889e+007
40;0.1332856;-0.04659265;863.6966;89.24883;0;0;0;0.4197972;0.4189185;792652.9;8.962349e+007
41;0.1366071;-0.04788671;885.3759;91.48903;0;0;0;0.4302584;0.4293355;812548.9;9.188267e+007
42;0.1400356;-0.04950628;907.8219;93.80845;0;0;0;0.4410571;0.4400873;833148.6;9.42222e+007
43;0.1432499;-0.05122171;928.9508;95.99178;0;0;0;0.4511808;0.4501661;852539.6;9.642488e+007
44;0.1466785;-0.05402216;952.2813;98.4026;0;0;0;0.4619794;0.4609156;873951;9.88572e+007
45;0.1500535;-0.05727219;976.0794;100.8617;0;0;0;0.4726094;0.4714961;895791.6;1.013384e+008
46;0.1532678;-0.06012908;999.0571;103.2361;0;0;0;0.4827331;0.4815717;916879.3;1.037345e+008
47;0.1566427;-0.06320433;1023.005;105.7107;0;0;0;0.493363;0.4921499;938857.3;1.062323e+008
48;0.1600713;-0.06653556;1046.971;108.1873;0;0;0;0.5041617;0.502895;960852.3;1.087327e+008
49;0.1632856;-0.06960113;1070.296;110.5975;0;0;0;0.5142854;0.5129674;982258.3;1.111663e+008
50;0.1667142;-0.07273199;1094.848;113.1345;0;0;0;0.525084;0.5237103;1004791;1.137285e+008
51;0.1700892;-0.07581045;1119.445;115.6762;0;0;0;0.5357139;0.5342841;1027365;1.162959e+008
52;0.1733035;-0.0788935;1142.33;118.041;0;0;0;0.5458376;0.5443533;1048368;1.186854e+008
53;0.176732;-0.08276413;1167.589;120.6511;0;0;0;0.5566363;0.5550928;1071548;1.213227e+008
54;0.180107;-0.08652735;1191.939;123.1673;0;0;0;0.5672662;0.5656634;1093896;1.23866e+008
55;0.1833213;-0.09041933;1215.524;125.6044;0;0;0;0.57739;0.5757295;1115541;1.263297e+008
56;0.1867499;-0.09478077;1240.834;128.2198;0;0;0;0.5881886;0.5864655;1138769;1.289739e+008
57;0.1901249;-0.09879558;1265.153;130.7327;0;0;0;0.5988185;0.5970327;1161087;1.315156e+008
58;0.1933391;-0.1029226;1289.403;133.2385;0;0;0;0.6089422;0.6070956;1183342;1.340499e+008
59;0.1967677;-0.1070142;1315.684;135.9543;0;0;0;0.6197408;0.6178284;1207462;1.367969e+008
60;0.2001427;-0.1112281;1341.433;138.615;0;0;0;0.6303708;0.6283923;1231093;1.394888e+008
61;0.203357;-0.1149993;1366.492;141.2044;0;0;0;0.6404945;0.6384521;1254091;1.421088e+008
62;0.2068392;-0.1193941;1393.443;143.9894;0;0;0;0.6514619;0.6493491;1278825;1.449274e+008
63;0.210107;-0.1235559;1419.155;146.6464;0;0;0;0.6617544;0.6595744;1302422;1.476168e+008
64;0.2133749;-0.1275625;1444.427;149.2578;0;0;0;0.6720468;0.6697986;1325615;1.502608e+008
65;0.2168034;-0.1319392;1471.674;152.0733;0;0;0;0.6828455;0.6805246;1350621;1.531118e+008
66;0.2201249;-0.136212;1497.64;154.7564;0;0;0;0.6933066;0.6909143;1374451;1.558294e+008
67;0.2233927;-0.1403604;1522.907;157.3673;0;0;0;0.7035991;0.7011354;1397640;1.584746e+008
68;0.2268213;-0.1448982;1549.403;160.1053;0;0;0;0.7143977;0.711858;1421957;1.612491e+008
69;0.2301427;-0.1493997;1575.367;162.7882;0;0;0;0.7248589;0.7222444;1445784;1.639682e+008
70;0.233357;-0.1536018;1600.121;165.3462;0;0;0;0.7349826;0.7322948;1468503;1.665615e+008
71;0.2368391;-0.1581102;1627.125;168.1366;0;0;0;0.74595;0.7431816;1493286;1.693908e+008
71.542;0.2384463;-0.1604932;1638.976;169.3611;0;0;0;0.7510119;0.7482059;1504161;1.706331e+008
71.54401;0.2384463;-0.1605033;1639.024;169.3662;0;0;0;0.7510119;0.7482059;1504206;1.706381e+008
72.54401;0.235232;-0.1580777;1598.276;165.1555;0;0;0;0.7408882;0.7381571;1466809;1.663791e+008
73.54401;0.2319106;-0.1543499;1557.851;160.9783;0;0;0;0.730427;0.7277723;1429709;1.621541e+008
74.54401;0.2284284;-0.1501754;1518.114;156.872;0;0;0;0.7194596;0.7168838;1393241;1.580007e+008
75.54401;0.225107;-0.1461197;1481.642;153.1033;0;0;0;0.7089984;0.7064968;1359769;1.541888e+008
76.54401;0.2218927;-0.1418882;1447.171;149.5413;0;0;0;0.6988747;0.6964439;1328133;1.505864e+008
77.54401;0.2184106;-0.1373804;1411.462;145.8513;0;0;0;0.6879073;0.685552;1295361;1.468547e+008
78.54401;0.2150891;-0.1331226;1377.912;142.3845;0;0;0;0.6774461;0.6751618;1264571;1.433491e+008
79.54401;0.2118749;-0.1288309;1346.484;139.137;0;0;0;0.6673224;0.6651057;1235728;1.400655e+008
80.54401;0.2083927;-0.1241482;1312.295;135.604;0;0;0;0.656355;0.6542104;1204351;1.364941e+008
81.54401;0.2050713;-0.1197282;1281.296;132.4008;0;0;0;0.6458939;0.6438169;1175902;1.33256e+008
82.54401;0.201857;-0.1152089;1251.423;129.314;0;0;0;0.6357701;0.6337576;1148487;1.301361e+008
83.54401;0.1984284;-0.1104768;1219.759;126.042;0;0;0;0.6249714;0.6230266;1119427;1.268297e+008
84.54401;0.195107;-0.1059228;1190.591;123.0279;0;0;0;0.6145102;0.6126298;1092658;1.23784e+008
85.54401;0.1918927;-0.10156;1163.187;120.1962;0;0;0;0.6043866;0.6025675;1067508;1.209226e+008
86.54401;0.1884642;-0.09642887;1135.729;117.3589;0;0;0;0.5935879;0.5918331;1042309;1.180555e+008
87.54401;0.1851427;-0.09167743;1109.52;114.6506;0;0;0;0.5831267;0.5814331;1018256;1.153192e+008
88.54401;0.1818749;-0.08701839;1084.711;112.0871;0;0;0;0.5728343;0.5711998;995487.9;1.127291e+008
89.54401;0.1784999;-0.08207256;1059.42;109.4736;0;0;0;0.5622044;0.5606299;972277.2;1.100891e+008
90.54401;0.1751784;-0.07731289;1035.13;106.9636;0;0;0;0.5517431;0.5502266;949984.8;1.075538e+008
91.54401;0.1719106;-0.07274813;1012.078;104.5816;0;0;0;0.5414507;0.5399901;928829.4;1.051479e+008
92.54401;0.1685356;-0.06769215;988.6231;102.1579;0;0;0;0.5308208;0.5294169;907303.5;1.027002e+008
93.54401;0.1652142;-0.06289803;965.9022;99.8101;0;0;0;0.5203596;0.5190104;886451.6;1.003295e+008
94.54401;0.1619463;-0.05806029;944.3495;97.58298;0;0;0;0.5100672;0.5087707;866671.6;9.808071e+007
95.54401;0.1585177;-0.05308409;922.0182;95.27541;0;0;0;0.4992685;0.4980263;846177.2;9.575108e+007
96.54401;0.1552499;-0.04835546;901.6328;93.16891;0;0;0;0.488976;0.4877844;827468.6;9.362448e+007
97.54401;0.151982;-0.0434199;881.7456;91.11389;0;0;0;0.4786836;0.4775416;809217.3;9.155004e+007
98.54401;0.1485535;-0.03849461;860.8434;88.95399;0;0;0;0.467885;0.4667938;790034.3;8.937019e+007
99.54401;0.145232;-0.03358782;841.5239;86.95764;0;0;0;0.4574237;0.4563808;772304;8.735541e+007
100.544;0.1419642;-0.02884186;822.2535;84.96637;0;0;0;0.4471313;0.4461347;754618.8;8.534628e+007
101.544;0.1385892;-0.02396967;802.583;82.93374;0;0;0;0.4365014;0.4355515;736566.2;8.329575e+007
102.544;0.1352678;-0.01933967;784.0622;81.01993;0;0;0;0.4260402;0.4251352;719568.9;8.13651e+007
103.544;0.1319463;-0.01457913;765.8772;79.1408;0;0;0;0.415579;0.4147179;702879.6;7.946969e+007
104.544;0.1285713;-0.009973625;747.6298;77.25523;0;0;0;0.4049491;0.4041314;686133.2;7.756808e+007
105.544;0.1252499;-0.005456648;730.0349;75.43709;0;0;0;0.3944879;0.3937119;669985.6;7.573468e+007
106.544;0.1219285;-0.0007370624;712.7068;73.64651;0;0;0;0.3840268;0.3832913;654082.8;7.392934e+007
107.544;0.1185535;0.003803664;695.521;71.87064;0;0;0;0.3733968;0.3727014;638310.6;7.213901e+007
108.544;0.1152321;0.008473165;678.8675;70.14978;0;0;0;0.3629357;0.3622786;623027;7.040438e+007
109.544;0.1119106;0.01307832;662.0374;68.41067;0;0;0;0.3524745;0.3518547;607581.2;6.865179e+007
110.544;0.1085892;0.01758138;645.8251;66.7354;0;0;0;0.3420133;0.3414298;592702.5;6.696364e+007
111.544;0.1052142;0.02214539;629.5337;65.05195;0;0;0;0.3313834;0.3308355;577751.2;6.526752e+007
112.544;0.1018928;0.02651721;613.3187;63.37639;0;0;0;0.3209222;0.3204083;562869.9;6.357978e+007
113.544;0.09857136;0.03076241;598.0671;61.80039;0;0;0;0.310461;0.3099801;548872.9;6.199226e+007
114.544;0.09519636;0.03475896;582.041;60.14436;0;0;0;0.2998311;0.2993825;534164.9;6.032469e+007
115.544;0.09182137;0.03876357;566.8802;58.57774;0;0;0;0.2892011;0.2887838;520251.2;5.874714e+007
116.544;0.08860708;0.04259552;552.0178;57.04195;0;0;0;0.2790774;0.2786887;506611.3;5.720114e+007
117.544;0.08517852;0.04653431;536.9459;55.48452;0;0;0;0.2682788;0.2679196;492779.2;5.563337e+007
118.544;0.08180352;0.05039451;522.0216;53.94234;0;0;0;0.2576489;0.2573175;479082.5;5.408133e+007
119.544;0.07858923;0.05405352;507.9776;52.49112;0;0;0;0.2475251;0.2472193;466193.7;5.262105e+007
120.544;0.07516066;0.05772723;493.2711;50.97145;0;0;0;0.2367265;0.2364467;452696.9;5.109212e+007
121.544;0.07178567;0.06130943;479.4008;49.53819;0;0;0;0.2260966;0.2258414;439967.5;4.965019e+007
122.544;0.06857138;0.06490797;466.2109;48.17522;0;0;0;0.2159729;0.21574;427862.5;4.827927e+007
123.544;0.06514281;0.06854805;452.3786;46.74588;0;0;0;0.2051742;0.204964;415168;4.684179e+007
124.544;0.06182139;0.07192329;439.2475;45.389;0;0;0;0.194713;0.1945237;403117.1;4.547738e+007
125.544;0.05855354;0.07517199;426.4314;44.06467;0;0;0;0.1844206;0.1842507;391355.1;4.414593e+007
126.544;0.0550714;0.07871351;413.6128;42.74007;0;0;0;0.1734532;0.173303;379590.9;4.281421e+007
127.544;0.05174997;0.08193129;400.8171;41.41785;0;0;0;0.162992;0.1628593;367847.7;4.148536e+007
128.544;0.04853568;0.08523191;388.3597;40.13058;0;0;0;0.1528683;0.1527516;356415;4.019193e+007
129.544;0.04510711;0.08858467;375.6523;38.81749;0;0;0;0.1420697;0.1419688;344752.9;3.887263e+007
130.544;0.04178568;0.09178575;363.6122;37.57334;0;0;0;0.1316085;0.1315219;333703.2;3.762279e+007
[...]
99.00001;0.2454105;-0.3403059;2015.395;208.2579;0;0;0;0.7729466;0.7699746;1849618;2.098676e+008
100;0.248732;-0.3446306;2038.289;210.6236;0;0;0;0.7834079;0.7803551;1870628;2.122736e+008
101;0.2521605;-0.3490781;2061.727;213.0455;0;0;0;0.7942064;0.7910692;1892139;2.147376e+008
102;0.2553748;-0.3532866;2083.635;215.3094;0;0;0;0.8043301;0.8011126;1912245;2.170412e+008
103;0.2588034;-0.3581655;2107.309;217.7557;0;0;0;0.8151288;0.8118246;1933971;2.195306e+008
104;0.2621784;-0.3626668;2129.824;220.0822;0;0;0;0.8257588;0.822368;1954634;2.218996e+008
105;0.2653927;-0.3666947;2151.198;222.291;0;0;0;0.8358825;0.8324083;1974251;2.24149e+008
106;0.2688213;-0.371112;2174.493;224.698;0;0;0;0.8466811;0.8431169;1995629;2.266005e+008
107;0.2721962;-0.3756816;2197.001;227.0238;0;0;0;0.857311;0.853657;2016285;2.289701e+008
108;0.2754105;-0.3799607;2218.652;229.2612;0;0;0;0.8674348;0.8636942;2036156;2.312499e+008
109;0.2788391;-0.3846579;2241.607;231.6331;0;0;0;0.8782335;0.8743994;2057222;2.336674e+008
110;0.2822141;-0.388959;2264.362;233.9845;0;0;0;0.8888633;0.8849362;2078106;2.360643e+008
111;0.2854284;-0.3932879;2285.705;236.19;0;0;0;0.8989871;0.8949702;2097693;2.383133e+008
112;0.288857;-0.3980782;2307.895;238.483;0;0;0;0.9097857;0.9056721;2118058;2.406527e+008
113;0.2922319;-0.4024058;2330.53;240.8219;0;0;0;0.9204156;0.9162056;2138831;2.430385e+008
114;0.2954462;-0.4068917;2352.222;243.0634;0;0;0;0.9305393;0.9262364;2158739;2.453252e+008
115;0.2988748;-0.4115531;2374.42;245.3572;0;0;0;0.9413379;0.936935;2179111;2.476668e+008
116;0.3022498;-0.4160478;2396.213;247.6091;0;0;0;0.9519679;0.9474652;2199111;2.499663e+008
117;0.3054641;-0.4205133;2417.07;249.7643;0;0;0;0.9620916;0.957493;2218253;2.521673e+008
118;0.3088927;-0.4254667;2439.218;252.053;0;0;0;0.9728903;0.9681882;2238579;2.545052e+008
119;0.3122677;-0.4299907;2461.324;254.3373;0;0;0;0.9835202;0.9787151;2258867;2.568388e+008
120;0.3154819;-0.434795;2481.693;256.4421;0;0;0;0.9936438;0.9887397;2277560;2.589902e+008
121;0.3189105;-0.4398887;2504.043;258.7516;0;0;0;1.004442;0.9994314;2298072;2.613507e+008
122;0.3222319;-0.4445954;2525.667;260.9861;0;0;0;1.014904;1.009788;2317917;2.636348e+008
122.652;0.3242676;-0.4476144;2537.798;262.2397;0;0;0;1.021315;1.016135;2329051;2.64918e+008
122.654;0.3242676;-0.4476219;2537.825;262.2424;0;0;0;1.021315;1.016135;2329075;2.649207e+008
123.654;0.3210534;-0.4460584;2491.491;257.4546;0;0;0;1.011192;1.006113;2286552;2.600579e+008
124.654;0.3176248;-0.4431018;2443.701;252.5162;0;0;0;1.000393;0.9954223;2242693;2.550424e+008
125.654;0.3143569;-0.4401382;2399.89;247.9891;0;0;0;0.9901005;0.9852311;2202486;2.504444e+008
126.654;0.3109283;-0.436919;2356.225;243.4771;0;0;0;0.9793019;0.9745378;2162413;2.458615e+008
127.654;0.3076069;-0.4336618;2314.788;239.1953;0;0;0;0.9688407;0.9641776;2124384;2.415127e+008
128.654;0.3043927;-0.4303961;2275.911;235.1779;0;0;0;0.958717;0.9541505;2088705;2.374326e+008
129.654;0.3009641;-0.4267833;2235.124;230.9633;0;0;0;0.9479184;0.9434538;2051273;2.331526e+008
130.654;0.2976427;-0.4233834;2196.737;226.9966;0;0;0;0.9374573;0.9330904;2016044;2.291246e+008
131.654;0.2943748;-0.4201074;2159.345;223.1328;0;0;0;0.9271647;0.9228929;1981727;2.252016e+008
132.654;0.2909998;-0.4162701;2121.386;219.2103;0;0;0;0.9165348;0.9123601;1946891;2.212195e+008
133.654;0.2876784;-0.4129392;2084.574;215.4064;0;0;0;0.9060737;0.9019935;1913106;2.173581e+008
134.654;0.2844105;-0.4092491;2048.725;211.702;0;0;0;0.8957812;0.8917929;1880206;2.135984e+008
135.654;0.2810355;-0.4057755;2011.859;207.8925;0;0;0;0.8851513;0.8812568;1846372;2.097326e+008
136.654;0.2777141;-0.4021651;1976.376;204.2259;0;0;0;0.8746901;0.8708869;1813808;2.060123e+008
137.654;0.2744462;-0.3986386;1941.673;200.6399;0;0;0;0.8643976;0.8606831;1781960;2.023743e+008
138.654;0.2710177;-0.3947691;1906.247;196.9792;0;0;0;0.853599;0.8499764;1749448;1.986606e+008
139.654;0.2677498;-0.3911158;1872.23;193.4642;0;0;0;0.8433066;0.8397706;1718229;1.950957e+008
140.654;0.2644284;-0.3875151;1838.568;189.9857;0;0;0;0.8328453;0.8293963;1687336;1.91568e+008
141.654;0.2610534;-0.3837665;1804.566;186.4722;0;0;0;0.8222154;0.8188536;1656130;1.880054e+008
142.654;0.257732;-0.3798302;1771.828;183.0893;0;0;0;0.8117542;0.8084772;1626086;1.845755e+008
143.654;0.2544106;-0.3759334;1739.126;179.7101;0;0;0;0.8012931;0.7980998;1596074;1.8115e+008
144.654;0.2510356;-0.3722622;1706.841;176.3739;0;0;0;0.7906632;0.7875538;1566444;1.777685e+008
145.654;0.2477141;-0.3683975;1675.335;173.1183;0;0;0;0.7802019;0.7771741;1537530;1.744689e+008
146.654;0.2443927;-0.3645024;1644.605;169.9428;0;0;0;0.7697408;0.7667934;1509327;1.712509e+008
147.654;0.2410713;-0.3604906;1614.697;166.8523;0;0;0;0.7592796;0.7564116;1481879;1.681192e+008
148.654;0.2377498;-0.3562171;1585.011;163.7848;0;0;0;0.7488184;0.7460287;1454635;1.650112e+008
149.654;0.2343749;-0.3522233;1555.762;160.7623;0;0;0;0.7381885;0.7354772;1427792;1.619491e+008
150.654;0.2310534;-0.3484995;1527.745;157.8673;0;0;0;0.7277273;0.7250921;1402080;1.590162e+008
151.654;0.2276784;-0.3444586;1499.202;154.9178;0;0;0;0.7170974;0.7145385;1375884;1.560287e+008
152.654;0.224357;-0.3404547;1471.295;152.0341;0;0;0;0.7066362;0.7041512;1350273;1.531084e+008
153.654;0.2210891;-0.336403;1444.742;149.2903;0;0;0;0.6963437;0.6939305;1325905;1.503299e+008
154.654;0.2176606;-0.3323223;1417.221;146.4465;0;0;0;0.6855451;0.6832059;1300647;1.474505e+008
155.654;0.2143392;-0.3282673;1390.706;143.7065;0;0;0;0.675084;0.6728155;1276313;1.446767e+008
156.654;0.2110713;-0.3245242;1365.077;141.0582;0;0;0;0.6647915;0.6625915;1252792;1.41996e+008
157.654;0.2076427;-0.3203882;1338.814;138.3444;0;0;0;0.6539929;0.6518637;1228689;1.392491e+008
158.654;0.2043213;-0.3163053;1313.51;135.7297;0;0;0;0.6435316;0.6414698;1205467;1.366031e+008
159.654;0.2010534;-0.3125739;1288.831;133.1794;0;0;0;0.6332392;0.6312427;1182817;1.340228e+008
160.654;0.1976249;-0.3078681;1263.159;130.5267;0;0;0;0.6224405;0.6205114;1159258;1.313392e+008
161.654;0.1943034;-0.303857;1238.611;127.9901;0;0;0;0.6119794;0.6101144;1136729;1.287734e+008
162.654;0.1910356;-0.2998887;1214.817;125.5313;0;0;0;0.6016868;0.599884;1114892;1.262867e+008
163.654;0.187607;-0.2957221;1190.167;122.9842;0;0;0;0.5908883;0.5891494;1092269;1.237109e+008
164.654;0.184232;-0.2915883;1166.655;120.5546;0;0;0;0.5802584;0.5785813;1070691;1.212541e+008
165.654;0.1810177;-0.2878737;1143.711;118.1837;0;0;0;0.5701346;0.5685155;1049635;1.188575e+008
166.654;0.1775892;-0.2836069;1120.491;115.7843;0;0;0;0.5593359;0.5577774;1028324;1.164319e+008
167.654;0.1742142;-0.2793591;1097.101;113.3673;0;0;0;0.5487061;0.5472061;1006859;1.139894e+008
168.654;0.1709999;-0.2752663;1075.744;111.1604;0;0;0;0.5385823;0.5371371;987257.9;1.117591e+008
169.654;0.1675713;-0.2710739;1052.999;108.8101;0;0;0;0.5277837;0.5263958;966384.4;1.093844e+008
170.654;0.1642499;-0.2669552;1031.045;106.5416;0;0;0;0.5173225;0.515989;946236.3;1.070927e+008
171.654;0.160982;-0.2629605;1010.101;104.3773;0;0;0;0.50703;0.505749;927014.4;1.049065e+008
172.654;0.1575535;-0.2587047;988.0989;102.1038;0;0;0;0.4962314;0.4950042;906822.4;1.026104e+008
173.654;0.154232;-0.2542622;967.1422;99.93822;0;0;0;0.4857702;0.4845941;887589.6;1.004237e+008
174.654;0.1510178;-0.2503703;946.9448;97.85117;0;0;0;0.4756465;0.4745189;869053.5;9.831659e+007
175.654;0.1437856;-0.2410119;903.9157;93.40481;0;0;0;0.4528681;0.4518458;829563.7;9.382781e+007
176.654;0.1355892;-0.2300552;855.752;88.42788;0;0;0;0.4270526;0.4261433;785361.8;8.880551e+007
177.654;0.1272321;-0.218629;807.7499;83.46766;0;0;0;0.4007309;0.3999301;741308.1;8.380214e+007
178.654;0.1189821;-0.2073521;762.3362;78.77489;0;0;0;0.3747467;0.3740462;699629.9;7.90701e+007
179.654;0.1106785;-0.1959968;718.2395;74.21822;0;0;0;0.3485937;0.3479875;659160.4;7.447695e+007
180.654;0.1021606;-0.1841347;673.8102;69.62719;0;0;0;0.3217658;0.3212493;618385.6;6.985123e+007
181.654;0.09396423;-0.1722868;632.7743;65.38681;0;0;0;0.2959503;0.2955132;580725.3;6.558033e+007
182.654;0.08549994;-0.1593179;590.531;61.02165;0;0;0;0.2692912;0.2689292;541956.6;6.118598e+007
183.654;0.07735709;-0.1475081;551.483;56.98669;0;0;0;0.2436444;0.243348;506120.5;5.712553e+007
184.654;0.06894639;-0.1353575;512.5092;52.95939;0;0;0;0.217154;0.2169185;470352.6;5.30744e+007
185.654;0.06064282;-0.1236593;475.6025;49.14569;0;0;0;0.191001;0.1908188;436481.7;4.923956e+007
186.654;0.05217854;-0.1120208;439.1976;45.38385;0;0;0;0.1643419;0.164207;403071.3;4.545843e+007
187.654;0.04392854;-0.1006458;405.6095;41.91306;0;0;0;0.1383576;0.138262;372245.9;4.197105e+007
188.654;0.03551783;-0.09007174;373.1774;38.56174;0;0;0;0.1118672;0.1118047;342481.5;3.860488e+007
189.654;0.02732141;-0.0790605;342.2321;35.36406;0;0;0;0.08605169;0.08601469;314081.7;3.539449e+007
190.654;0.01901785;-0.06787529;312.3226;32.2734;0;0;0;0.05989873;0.05988079;286632.4;3.229273e+007
191.654;0.01044642;-0.05651388;281.9682;29.13677;0;0;0;0.03290211;0.0328967;258774.8;2.914636e+007
192.654;0.00230357;-0.04618857;254.3224;26.28004;0;0;0;0.007255339;0.007255075;233403;2.628194e+007
193.654;-0.006214282;-0.0358755;227.1213;23.46925;0;0;0;-0.01957254;-0.01957446;208439.3;2.346465e+007
194.654;-0.01435714;-0.02644033;201.5595;20.82786;0;0;0;-0.04521932;-0.04522955;184980.1;2.081844e+007
195.654;-0.02271428;-0.0170158;175.6609;18.15166;0;0;0;-0.07154103;-0.07156663;161211.8;1.813868e+007
196.654;-0.03107141;-0.007443257;152.3473;15.74258;0;0;0;-0.09786272;-0.09791064;139815.9;1.572718e+007
197.654;-0.03948212;0.001664207;130.411;13.47583;0;0;0;-0.1243531;-0.1244305;119684;1.345907e+007
198.654;-0.04778569;0.01112208;110.5628;11.42484;0;0;0;-0.1505061;-0.1506195;101468.4;1.140765e+007
199.654;-0.05603569;0.02010989;92.30629;9.538336;0;0;0;-0.1764904;-0.1766463;84713.59;9521501
200.654;-0.06433926;0.02959983;75.41074;7.792459;0;0;0;-0.2026433;-0.2028489;69207.8;7776668
201.654;-0.07264282;0.03763025;60.80946;6.283657;0;0;0;-0.2287963;-0.2290584;55807.56;6269280
201.728;-0.07328568;0.03803662;59.84906;6.184415;0;0;0;-0.230821;-0.2310878;54926.15;6170140
201.73;-0.07333925;0.03806605;59.81244;6.180632;1;1;0;-0.2309898;-0.231257;54892.55;6166355
202.73;-0.06503568;0.03422657;91.99012;9.505664;1;1;0;-0.2048368;-0.2050469;84423.43;9486193
203.73;-0.05678569;0.02862831;126.5275;13.07454;1;1;0;-0.1788526;-0.1790127;116120;1.305115e+007
204.73;-0.04826783;0.02222818;163.7047;16.91619;1;1;0;-0.1520247;-0.1521403;150239.1;1.689047e+007
205.73;-0.04017856;0.01555521;200.0694;20.67387;1;1;0;-0.1265466;-0.1266268;183612.6;2.064771e+007
206.73;-0.03171427;0.00881727;240.322;24.83332;1;1;0;-0.09988747;-0.09993739;220554.2;2.480852e+007
207.73;-0.02330356;0.002272373;282.3856;29.1799;1;1;0;-0.07339704;-0.07342399;259157.8;2.915848e+007
208.73;-0.01499999;-0.004825454;324.1949;33.50021;1;1;0;-0.04724407;-0.04725523;297528.1;3.348438e+007
209.73;-0.006642854;-0.01269095;366.7934;37.90206;1;1;0;-0.02092237;-0.02092456;336622.7;3.789413e+007
210.73;0.00155357;-0.02059537;409.9432;42.36088;1;1;0;0.004893135;0.004893015;376223.1;4.236295e+007
211.73;0.009910708;-0.02872496;454.9284;47.00936;1;1;0;0.03121483;0.03120996;417508;4.702403e+007
212.73;0.01826785;-0.03756882;500.0482;51.67176;1;1;0;0.05753652;0.05751997;458916.6;5.170149e+007
213.73;0.02673213;-0.04662426;546.8404;56.50696;1;1;0;0.08419567;0.08416025;501859.9;5.655454e+007
214.73;0.03487498;-0.05550751;592.5181;61.227;1;1;0;0.1098425;0.1097822;543780.3;6.129425e+007
215.73;0.04339283;-0.06470848;641.8242;66.32196;1;1;0;0.1366703;0.136577;589030.7;6.641261e+007
216.73;0.05148211;-0.07372007;688.9496;71.1916;1;1;0;0.1621484;0.1620171;632279.8;7.130704e+007
217.73;0.05994639;-0.08332825;739.5619;76.42155;1;1;0;0.1888075;0.1886295;678728.9;7.656583e+007
218.73;0.0683571;-0.09421568;791.9856;81.83868;1;1;0;0.215298;0.2150665;726840.5;8.201487e+007
219.73;0.07660709;-0.104879;843.2012;87.13097;1;1;0;0.2412822;0.2409916;773843.4;8.73412e+007
220.73;0.0850178;-0.116246;896.4099;92.62921;1;1;0;0.2677726;0.2674147;822675.3;9.287724e+007
221.73;0.09321422;-0.1277981;949.5336;98.11867;1;1;0;0.2935881;0.293158;871429.3;9.840673e+007
222.73;0.1016249;-0.1400476;1004.54;103.8027;1;1;0;0.3200786;0.3195674;921911.2;1.041349e+008
223.73;0.1099285;-0.1520864;1058.953;109.4253;1;1;0;0.3462315;0.3456335;971848.1;1.098042e+008
224.73;0.1184464;-0.1642131;1115.265;115.2443;1;1;0;0.3730594;0.3723652;1023529;1.156742e+008
225.73;0.1265892;-0.1760294;1169.854;120.8852;1;1;0;0.3987062;0.3979135;1073628;1.213672e+008
226.73;0.1350535;-0.1879619;1227.987;126.8922;1;1;0;0.4253653;0.4244632;1126978;1.27432e+008
227.73;0.1431963;-0.1994358;1284.165;132.6973;1;1;0;0.4510121;0.4499981;1178535;1.332958e+008
228.73;0.151607;-0.2107628;1343.402;138.8185;1;1;0;0.4775025;0.4763661;1232900;1.394814e+008
229.73;0.1600178;-0.2222261;1403.399;145.0182;1;1;0;0.5039929;0.5027271;1287962;1.457491e+008
230.73;0.1682677;-0.2333129;1461.351;151.0065;1;1;0;0.5299771;0.5285777;1341147;1.518068e+008
231.73;0.1766785;-0.2444574;1523.109;157.3883;1;1;0;0.5564676;0.554925;1397825;1.582641e+008
232.73;0.1848213;-0.2549483;1581.004;163.3708;1;1;0;0.5821143;0.5804266;1450958;1.643218e+008
233.73;0.1932856;-0.2659947;1643.116;169.789;1;1;0;0.6087735;0.606928;1507961;1.708226e+008
234.73;0.2015892;-0.2768398;1703.612;176.0403;1;1;0;0.6349265;0.6329193;1563481;1.77158e+008
235.73;0.2100534;-0.2879992;1764.44;182.3259;1;1;0;0.6615856;0.6594068;1619306;1.835321e+008
236.73;0.2182499;-0.2988425;1822.445;188.3197;1;1;0;0.6874011;0.6850493;1672539;1.896142e+008
237.73;0.2267141;-0.3099729;1882.907;194.5675;1;1;0;0.7140603;0.711523;1728028;1.959568e+008
238.73;0.234857;-0.3208948;1940.293;200.4973;1;1;0;0.7397071;0.7369847;1780693;2.019804e+008
239.73;0.2432677;-0.3317153;2000.607;206.7298;1;1;0;0.7661975;0.7632771;1836047;2.083138e+008
240.73;0.251732;-0.3428585;2062.188;213.0931;1;1;0;0.7928566;0.78973;1892562;2.147827e+008
241.73;0.2599284;-0.3537345;2121.268;219.1982;1;1;0;0.8186721;0.8153392;1946783;2.209927e+008
242.73;0.2683927;-0.3650134;2183.184;225.5962;1;1;0;0.8453313;0.8417783;2003606;2.275032e+008
243.73;0.276482;-0.3757072;2241.121;231.583;1;1;0;0.8708094;0.8670397;2056777;2.335996e+008
244.73;0.2849462;-0.3869445;2302.622;237.9381;1;1;0;0.8974684;0.8934651;2113219;2.400735e+008
245.73;0.2933034;-0.3979235;2362.871;244.1638;1;1;0;0.9237901;0.9195493;2168512;2.464194e+008
246.73;0.3017141;-0.4087203;2423.577;250.4368;1;1;0;0.9502805;0.9457938;2224224;2.528166e+008
247.73;0.3099641;-0.4199055;2482.664;256.5424;1;1;0;0.9762648;0.9715302;2278451;2.59047e+008
248.73;0.3183212;-0.4313143;2542.385;262.7136;1;1;0;1.002586;0.997594;2333260;2.653476e+008
249.73;0.3265177;-0.442725;2598.714;268.5343;1;1;0;1.028402;1.02315;2384956;2.712959e+008
250.73;0.3348748;-0.454848;2653.832;274.2299;1;1;0;1.054724;1.0492;2435540;2.771222e+008
250.868;0.3361069;-0.4565331;2661.805;275.0537;1;1;0;1.058604;1.053041;2442857;2.779654e+008
250.87;0.3361069;-0.4565527;2661.922;275.0658;1;1;0;1.058604;1.053041;2442965;2.779777e+008
251.552;0.3305891;-0.4533697;2586.654;267.2881;1;1;0;1.041225;1.035842;2373888;2.700712e+008
252.224;0.3249105;-0.4478769;2511.46;259.5181;1;1;0;1.02334;1.01814;2304879;2.621738e+008
252.942;0.3189105;-0.4415695;2436.339;251.7556;1;1;0;1.004442;0.9994314;2235937;2.542843e+008
253.702;0.3125891;-0.4352124;2361.256;243.9969;1;1;0;0.9845325;0.9797176;2167030;2.463992e+008
254.452;0.3062141;-0.4282656;2286.222;236.2434;1;1;0;0.9644539;0.9598327;2098168;2.385218e+008
255.252;0.2995177;-0.421044;2211.055;228.4762;1;1;0;0.9433628;0.9389409;2029184;2.306315e+008
256.092;0.2926605;-0.4134963;2135.981;220.7185;1;1;0;0.9217654;0.9175431;1960285;2.22753e+008
256.924;0.2856427;-0.40578;2060.871;212.9571;1;1;0;0.8996619;0.8956391;1891353;2.14873e+008
257.796;0.2784105;-0.3978705;1985.829;205.2027;1;1;0;0.8768836;0.8730613;1822484;2.070021e+008
258.694;0.2710177;-0.3894355;1910.675;197.4368;1;1;0;0.853599;0.8499764;1753512;1.991221e+008
259.6;0.2634641;-0.3809893;1835.668;189.6861;1;1;0;0.8298082;0.8263843;1684674;1.912601e+008
260.51;0.2556427;-0.3717307;1760.513;181.92;1;1;0;0.8051739;0.8019496;1615701;1.833848e+008
261.51;0.2474998;-0.3618785;1686.192;174.2402;1;1;0;0.779527;0.7765044;1547493;1.755984e+008
262.51;0.2390356;-0.3516005;1612.387;166.6136;1;1;0;0.7528679;0.750048;1479759;1.67868e+008
263.51;0.2308927;-0.3417841;1544.303;159.5783;1;1;0;0.7272211;0.7245896;1417276;1.607388e+008
264.51;0.222482;-0.3316412;1475.631;152.4821;1;1;0;0.7007307;0.698287;1354252;1.535506e+008
265.51;0.2140713;-0.321556;1409.05;145.6022;1;1;0;0.6742403;0.6719775;1293148;1.465839e+008
266.51;0.2057677;-0.3117497;1346.037;139.0908;1;1;0;0.6480873;0.6459962;1235319;1.399922e+008
267.51;0.197357;-0.3009249;1282.751;132.5512;1;1;0;0.6215969;0.6196729;1177238;1.333751e+008
268.51;0.1891606;-0.2909207;1223.159;126.3934;1;1;0;0.5957814;0.5940136;1122548;1.271464e+008
269.51;0.180857;-0.2809134;1164.222;120.3032;1;1;0;0.5696284;0.5680122;1068459;1.209885e+008
270.51;0.1724999;-0.2709124;1107.503;114.4422;1;1;0;0.5433067;0.5418361;1016405;1.15064e+008
271.51;0.163982;-0.2605477;1051.389;108.6438;1;1;0;0.5164789;0.5151497;964906.8;1.092049e+008
272.51;0.1558392;-0.2501154;998.2713;103.1549;1;1;0;0.490832;0.4896314;916158.1;1.036612e+008
273.51;0.1473749;-0.2396418;945.4158;97.69315;1;1;0;0.4641729;0.463099;867650.2;9.814662e+007
274.51;0.1392321;-0.2287864;895.9754;92.58431;1;1;0;0.4385262;0.4375675;822276.6;9.299032e+007
275.51;0.1308749;-0.2177368;846.9478;87.51812;1;1;0;0.4122044;0.4113572;777281.8;8.787887e+007
276.51;0.1224106;-0.2062533;798.8183;82.54472;1;1;0;0.3855453;0.384804;733111.2;8.286297e+007
277.51;0.1141606;-0.1950415;753.5823;77.87032;1;1;0;0.3595611;0.3589162;691596.1;7.815031e+007
278.51;0.1056964;-0.1829129;707.9847;73.15857;1;1;0;0.3329019;0.332349;649749.1;7.340211e+007
279.51;0.09749994;-0.1713158;664.8586;68.70219;1;1;0;0.3070864;0.3066159;610170.4;6.891317e+007
280.51;0.0891428;-0.158771;621.9013;64.26327;1;1;0;0.2807647;0.2803713;570746.6;6.44437e+007
281.51;0.08083924;-0.1464299;580.3329;59.96785;1;1;0;0.2546118;0.2542882;532597.4;6.012054e+007
282.51;0.07237496;-0.1339066;539.0108;55.6979;1;1;0;0.2279526;0.2276932;494674.3;5.582486e+007
283.51;0.06412496;-0.1221403;500.3112;51.69893;1;1;0;0.2019684;0.2017647;459157.9;5.180334e+007
284.51;0.05571425;-0.1101773;462.181;47.7588;1;1;0;0.175478;0.1753242;424164.2;4.784261e+007
285.51;0.04751782;-0.09916944;426.8918;44.11224;1;1;0;0.1496624;0.1495506;391777.6;4.417826e+007
286.51;0.03916069;-0.0887244;392.2834;40.53604;1;1;0;0.1233407;0.1232647;360016;4.058603e+007
287.51;0.03074998;-0.07791111;358.4944;37.04449;1;1;0;0.09685033;0.09680346;329006.3;3.708037e+007
288.51;0.02249998;-0.06733607;326.8419;33.77373;1;1;0;0.07086609;0.070841;299957.4;3.379766e+007
289.51;0.01398213;-0.05649634;295.022;30.48566;1;1;0;0.04403822;0.04402852;270754.8;3.049909e+007
290.51;0.005892853;-0.04661226;266.1251;27.49965;1;1;0;0.01856017;0.01855845;244234.9;2.750475e+007
291.51;-0.002517856;-0.03684164;237.0064;24.49071;1;1;0;-0.007930255;-0.007930569;217511.4;2.448877e+007
292.51;-0.01082142;-0.02761314;208.9214;21.58858;1;1;0;-0.03408322;-0.03408903;191736.5;2.158123e+007
293.51;-0.01928571;-0.01867275;181.0415;18.70766;1;1;0;-0.06074238;-0.06076084;166149.9;1.86963e+007
294.51;-0.0275357;-0.009883917;155.5085;16.06924;1;1;0;-0.08672661;-0.08676424;142717.1;1.60553e+007
295.51;-0.03589284;-0.001403743;132.8188;13.72464;1;1;0;-0.1130483;-0.1131123;121893.8;1.370912e+007
296.51;-0.04414284;0.007437891;111.1119;11.48159;1;1;0;-0.1390326;-0.1391293;101972.3;1.146562e+007
297.51;-0.0524464;0.01561521;91.17084;9.421006;1;1;0;-0.1651855;-0.1653221;83671.55;9405444
298.51;-0.06101783;0.0237137;71.84256;7.423747;1;1;0;-0.1921821;-0.192367;65933.13;7409479
299.51;-0.06916068;0.03027563;56.16248;5.803468;1;1;0;-0.2178289;-0.2180665;51542.82;5790827
300.51;-0.07767854;0.03454107;47.12126;4.869207;1;1;0;-0.2446568;-0.2449566;43245.29;4857294
300.806;-0.07998211;0.03501126;46.91615;4.848012;1;1;0;-0.2519121;-0.25223;43057.05;4835799