File: Ensayos/Graficos/EspCu/EspCu.raw
"Test Type";"Manual"
"Method Name:";"C:\INSTRON\user\template\CYCLE.MTM"
"Name:";""
"Operator ID:";""
"Company:";""
"Lab name:";""
"Test date:";"04/05/2017"
"Temperature:";""
"Humidity:";""
"Note 1:";""
"Note 2:";""
"Note 3:";""
"Geometry:";"Rectangular"
"Specimen";1
"Specimen name:";""
"Width:";0.250000;"in"
"Thickness:";0.060000;"in"
"Length:";1.250000;"in"
"Diameter:";0.039370;"in"
"Inner diameter:";0.019685;"in"
"Outer diameter:";0.039370;"in"
"Wall thickness:";0.019685;"in"
"Area:";0.015000;"in*in"
"Linear density:";1.000000;"den"
"Sled weight:";2.204623;"lbf"
"Loading span:";0.000000;"mm"
"Support span:";1.000000;"mm"
"Span ratio:";"2"
"Fixture type:";"3-point"
"Comment:";""
"Included"
"Final Width:";0.250000;"in"
"Final Thickness:";0.060000;"in"
"Final Length:";1.250000;"in"
"Final Diameter:";0.039370;"in"
"Final Inner diameter:";0.019685;"in"
"Final Outer diameter:";0.039370;"in"
"Final Wall thickness:";0.019685;"in"
"Final Area:";0.015000;"in*in"
"Final Linear density:";1.000000;"den"
"Time sec";"Extension mm";"Load N";"Stress MPa";"Cycle Count ";"Total Cycle Count ";"Repetitions Count ";"Strain [Exten.] %";"True strain %";"Tenacity gf/tex";"True stress Pa"
0;0;0.2073546;0.02142669;0;0;0;0;0;190.2986;21426.69
7.79;0.06487496;34.22685;3.536781;0;0;0;0.2043306;0.2041221;31411.5;3544008
15.79;0.1316785;34.00402;3.513756;0;0;0;0.4147354;0.4138777;31207;3528328
23.79;0.1983213;34.79178;3.595158;0;0;0;0.624634;0.6226912;31929.97;3617614
31.79;0.2649105;34.63796;3.579263;0;0;0;0.8343639;0.8309024;31788.8;3609127
39.79;0.3317141;34.81219;3.597267;0;0;0;1.044769;1.039349;31948.7;3634850
47.79;0.3982497;37.30054;3.854397;0;0;0;1.25433;1.246528;34232.37;3902744
55.79;0.4649461;41.73416;4.312538;0;0;0;1.464397;1.453779;38301.3;4375691
63.79;0.5315889;41.48643;4.286939;0;0;0;1.674296;1.660434;38073.94;4358715
71.79;0.5981782;41.54771;4.293272;0;0;0;1.884026;1.866498;38130.19;4374158
79.79;0.6649282;42.37418;4.378674;0;0;0;2.094262;2.072634;38888.67;4470375
87.79;0.7315174;42.75616;4.418146;0;0;0;2.303992;2.277851;39239.24;4519940
95.79;0.7981602;42.56394;4.398282;0;0;0;2.51389;2.482812;39062.82;4508850
102.672;0.8557495;90.63489;9.365623;0;0;0;2.695274;2.659591;83179.68;9618053
107.134;0.8928744;170.8801;17.65764;0;0;0;2.812203;2.773386;156824.3;1.815421e+007
110.514;0.9208387;251.0839;25.94539;0;0;0;2.90028;2.859017;230430.9;2.669788e+007
115.092;0.9590887;331.2141;34.22552;0;0;0;3.020752;2.976026;303969.9;3.525939e+007
119.98;0.9998565;411.4129;42.51275;0;0;0;3.149154;3.100586;377572;4.385155e+007
125.768;1.048071;491.525;50.79102;0;0;0;3.30101;3.247697;451094.4;5.246764e+007
127.324;1.053214;474.8251;49.06536;0;0;0;3.317208;3.263376;435768.2;5.069296e+007
128.152;1.045874;394.1895;40.733;0;0;0;3.294092;3.241;361765.3;4.207478e+007
129.126;1.037731;313.2472;32.36894;0;0;0;3.268445;3.216168;287480.9;3.34269e+007
130.252;1.02841;232.7926;24.05529;0;0;0;3.239087;3.187735;213644.2;2.483446e+007
131.556;1.017535;152.1733;15.72461;0;0;0;3.204835;3.154551;139656.3;1.622856e+007
133.256;1.003232;71.95997;7.435878;0;0;0;3.159784;3.11089;66040.87;7670836
134.69;1.008964;109.5381;11.31896;1;1;0;3.177838;3.12839;100528;1.167865e+007
136.028;1.020053;190.202;19.65424;1;1;0;3.212765;3.162235;174556.8;2.028569e+007
137.23;1.030124;270.6358;27.96576;1;1;0;3.244486;3.192964;248374.5;2.88731e+007
138.356;1.039606;351.3793;36.30927;1;1;0;3.274351;3.221886;322476.4;3.749816e+007
139.456;1.048714;432.0377;44.64398;1;1;0;3.303035;3.249657;396500.2;4.611859e+007
140.628;1.05841;512.5933;52.96808;1;1;0;3.333575;3.279216;470429.7;5.473381e+007
144.656;1.091999;592.7234;61.24821;1;1;0;3.439368;3.381543;543968.8;6.335476e+007
152.15;1.154464;665.3869;68.75678;1;1;0;3.636106;3.571559;610655.2;7.125685e+007
160.15;1.220999;712.0329;73.57688;1;1;0;3.845666;3.773563;653464.3;7.64064e+007
168.15;1.287696;752.3489;77.74287;1;1;0;4.055734;3.975648;690464.1;8.089592e+007
176.15;1.354446;787.8345;81.40972;1;1;0;4.26597;4.177485;723030.8;8.488264e+007
184.15;1.420981;821.3387;84.87184;1;1;0;4.475532;4.378271;753779.2;8.86703e+007
192.15;1.487892;864.7136;89.35391;1;1;0;4.686274;4.579782;793586.2;9.354128e+007
200.15;1.55432;903.0058;93.31079;1;1;0;4.895497;4.77944;828728.8;9.787882e+007
208.15;1.621231;938.8837;97.01817;1;1;0;5.10624;4.980146;861655.4;1.019722e+008
216.15;1.687767;970.6032;100.2959;1;1;0;5.315801;5.179328;890765.8;1.056274e+008
222.064;1.734695;979.6614;101.2319;1;1;0;5.463608;5.319576;899079;1.067628e+008
222.688;1.728535;898.376;92.83237;1;1;0;5.444204;5.301175;824479.8;9.788636e+007
223.43;1.722267;817.6584;84.49154;1;1;0;5.424462;5.282451;750401.6;8.907475e+007
224.24;1.715517;736.8582;76.14217;1;1;0;5.403202;5.262283;676247.6;8.025628e+007
225.08;1.708499;655.81;67.76717;1;1;0;5.381099;5.241311;601866.1;7.141379e+007
225.958;1.701106;574.8109;59.39724;1;1;0;5.357814;5.219213;527529.6;6.257963e+007
226.888;1.693445;494.2117;51.06864;1;1;0;5.333686;5.196309;453560.1;5.379248e+007
227.864;1.685303;413.3572;42.71367;1;1;0;5.30804;5.171958;379356.3;4.498092e+007
228.89;1.67657;332.6614;34.37508;1;1;0;5.280537;5.145838;305298.3;3.619027e+007
230.04;1.667088;252.1273;26.05321;1;1;0;5.250671;5.117467;231388.5;2.742118e+007
231.304;1.656535;171.7177;17.7442;1;1;0;5.217432;5.085881;157593;1.866999e+007
232.856;1.643731;91.24522;9.428691;1;1;0;5.177106;5.047546;83739.8;9916825
234.054;1.648392;127.7043;13.19614;2;2;0;5.191785;5.061502;117199.9;1.388125e+007
235.216;1.658195;208.3636;21.53095;2;2;0;5.222662;5.090852;191224.6;2.265544e+007
236.33;1.667356;289.0378;29.8673;2;2;0;5.251515;5.118268;265262.9;3.143579e+007
237.364;1.675874;369.5922;38.19127;2;2;0;5.278343;5.143754;339191.2;4.020713e+007
238.336;1.68407;450.1056;46.51101;2;2;0;5.304159;5.168273;413082;4.897802e+007
239.268;1.691999;530.9342;54.86331;2;2;0;5.329131;5.191984;487262;5.778705e+007
240.216;1.69982;611.463;63.18463;2;2;0;5.353765;5.215369;561166.8;6.656739e+007
241.168;1.707642;692.069;71.51394;2;2;0;5.378399;5.238749;635142.6;7.536024e+007
242.096;1.715463;772.8183;79.85806;2;2;0;5.403034;5.262123;709249.9;8.417281e+007
243.02;1.723231;853.3292;88.17752;2;2;0;5.427499;5.285332;783138.2;9.296336e+007
244.034;1.731535;933.7597;96.48869;2;2;0;5.453653;5.310136;856952.9;1.017508e+008
247.316;1.758856;1003.331;103.6777;2;2;0;5.539704;5.391704;920801.5;1.094212e+008
255.316;1.82566;1030.468;106.4819;2;2;0;5.750109;5.590866;945706.6;1.126047e+008
263.316;1.892356;1061.93;109.733;2;2;0;5.960176;5.789314;974580.3;1.162732e+008
271.316;1.958945;1089.909;112.6241;2;2;0;6.169906;5.987051;1000258;1.195729e+008
279.316;2.025695;1120.707;115.8066;2;2;0;6.380142;6.184874;1028523;1.231953e+008
287.316;2.092284;1148.139;118.6413;2;2;0;6.589872;6.381831;1053698;1.264596e+008
295.316;2.158927;1176.338;121.5552;2;2;0;6.79977;6.578559;1079578;1.298207e+008
303.316;2.225623;1204.033;124.417;2;2;0;7.009838;6.775059;1104995;1.331384e+008
311.316;2.292213;1230.231;127.1241;2;2;0;7.219568;6.970858;1129038;1.363019e+008
319.316;2.358963;1256.14;129.8014;2;2;0;7.429804;7.166746;1152816;1.394454e+008
327.316;2.425552;1280.324;132.3004;2;2;0;7.639534;7.361781;1175011;1.424076e+008
335.316;2.492195;1302.784;134.6213;2;2;0;7.849432;7.556592;1195623;1.451883e+008
336.462;2.493427;1244.488;128.5973;2;2;0;7.853312;7.56019;1142122;1.386965e+008
337.1;2.487802;1163.446;120.223;2;2;0;7.835596;7.543762;1067746;1.296432e+008
337.766;2.48207;1082.43;111.8513;2;2;0;7.817543;7.527019;993394.5;1.205954e+008
338.496;2.475909;1001.027;103.4396;2;2;0;7.798139;7.509021;918686.8;1.11506e+008
339.26;2.469748;920.4096;95.10918;2;2;0;7.778735;7.491019;844700.9;1.025075e+008
340.034;2.463266;839.6852;86.76765;2;2;0;7.758318;7.472074;770616.6;9.349935e+007
340.838;2.45657;758.7741;78.40681;2;2;0;7.737227;7.452499;696360.8;8.447332e+007
341.692;2.449499;677.8694;70.04665;2;2;0;7.714956;7.431826;622111;7.545072e+007
342.562;2.442052;597.066;61.69694;2;2;0;7.691502;7.410049;547954.1;6.644236e+007
343.48;2.434445;516.5214;53.37398;2;2;0;7.667543;7.387799;474034.7;5.746645e+007
344.47;2.426302;435.9735;45.05069;2;2;0;7.641896;7.363976;400112.3;4.849341e+007
345.492;2.417784;355.2916;36.71354;2;2;0;7.615068;7.339049;326066.9;3.95093e+007
346.604;2.408516;274.842;28.4004;2;2;0;7.585878;7.311921;252234.8;3.055482e+007
347.828;2.398338;194.3535;20.08324;2;2;0;7.55382;7.282118;178366.9;2.160029e+007
349.062;2.391802;148.6701;15.36261;3;3;0;7.533235;7.262977;136441.2;1.651991e+007
349.99;2.40032;229.2889;23.69323;3;3;0;7.560062;7.287922;210428.6;2.548445e+007
350.986;2.408731;310.0147;32.03492;3;3;0;7.586553;7.312548;284514.3;3.446526e+007
351.944;2.416873;390.6124;40.36337;3;3;0;7.612199;7.336383;358482.4;4.34359e+007
352.882;2.424534;471.1574;48.68636;3;3;0;7.636328;7.358803;432402.2;5.240421e+007
353.788;2.432088;551.7925;57.01868;3;3;0;7.660119;7.380903;506404.6;6.138637e+007
354.654;2.439373;632.5883;65.36759;3;3;0;7.683066;7.402215;580554.5;7.038983e+007
355.514;2.446552;713.7063;73.74979;3;3;0;7.705676;7.42321;655000.1;7.943271e+007
356.36;2.453677;794.5317;82.10178;3;3;0;7.728116;7.444042;729177.2;8.84467e+007
357.216;2.460695;874.8713;90.40354;3;3;0;7.75022;7.464558;802908.4;9.741002e+007
358.044;2.467713;955.294;98.71391;3;3;0;7.772323;7.48507;876715.9;1.063863e+008
358.882;2.474677;1035.859;107.039;3;3;0;7.794258;7.50542;950654.4;1.153819e+008
359.762;2.481802;1116.506;115.3725;3;3;0;7.816699;7.526236;1024667;1.243908e+008
360.626;2.489141;1197.393;123.7308;3;3;0;7.839815;7.547674;1098901;1.334311e+008
361.656;2.497766;1277.878;132.0477;3;3;0;7.86698;7.572861;1172766;1.424358e+008
367.678;2.547856;1321.111;136.5151;3;3;0;8.024742;7.719011;1212443;1.474701e+008
375.678;2.614445;1340.212;138.4889;3;3;0;8.234472;7.912972;1229972;1.498927e+008
383.678;2.681302;1361.367;140.6749;3;3;0;8.445045;8.107336;1249387;1.525549e+008
391.678;2.74773;1380.056;142.6061;3;3;0;8.654268;8.30008;1266539;1.549476e+008
399.678;2.814695;1402.851;144.9615;3;3;0;8.86518;8.494005;1287459;1.578126e+008
407.678;2.881123;1422.981;147.0417;3;3;0;9.074404;8.686007;1305933;1.603849e+008
415.678;2.94798;1443.393;149.151;3;3;0;9.284977;8.878875;1324667;1.629996e+008
423.678;3.014623;1465.649;151.4507;3;3;0;9.494876;9.070757;1345092;1.658308e+008
431.678;3.081266;1485.554;153.5076;3;3;0;9.704774;9.262269;1363360;1.684052e+008
439.678;3.148016;1508.212;155.8489;3;3;0;9.91501;9.453725;1384154;1.713013e+008
447.678;3.214552;1527.3;157.8213;3;3;0;10.12457;9.644201;1401671;1.738e+008
455.678;3.281248;1548.413;160.003;3;3;0;10.33464;9.834774;1421048;1.765388e+008
463.678;3.347891;1569.346;162.1661;3;3;0;10.54454;10.02483;1440259;1.792658e+008
471.678;3.414534;1591.058;164.4096;3;3;0;10.75444;10.21453;1460185;1.820909e+008
479.678;3.48123;1613.576;166.7366;3;3;0;10.9645;10.40402;1480851;1.850184e+008
487.678;3.547819;1635.085;168.9591;3;3;0;11.17423;10.59285;1500591;1.87839e+008
494.864;3.607819;1656.402;171.1618;3;3;0;11.36321;10.76268;1520154;1.906113e+008
495.454;3.603373;1585.692;163.8551;3;3;0;11.34921;10.75011;1455260;1.824514e+008
496.022;3.598069;1504.579;155.4734;3;3;0;11.3325;10.7351;1380819;1.730925e+008
496.684;3.592765;1423.548;147.1003;3;3;0;11.3158;10.7201;1306454;1.637458e+008
497.318;3.587301;1342.585;138.734;3;3;0;11.29859;10.70464;1232150;1.54409e+008
498.006;3.581623;1261.346;130.3393;3;3;0;11.2807;10.68857;1157593;1.450425e+008
498.698;3.575891;1180.55;121.9904;3;3;0;11.26265;10.67234;1083443;1.357297e+008
499.42;3.569944;1099.392;113.6041;3;3;0;11.24392;10.65551;1008961;1.263777e+008
500.132;3.563784;1018.409;105.2358;3;3;0;11.22451;10.63806;934639.6;1.17048e+008
500.896;3.557408;937.6742;96.8932;3;3;0;11.20444;10.62001;860545.4;1.077495e+008
501.716;3.550766;856.9029;88.54681;3;3;0;11.18351;10.60119;786418;9.844946e+007
502.538;3.543748;776.0308;80.19002;3;3;0;11.16141;10.58131;712198.1;8.914035e+007
503.406;3.536516;695.3473;71.85269;3;3;0;11.13863;10.56082;638151.2;7.98561e+007
504.342;3.528908;614.3319;63.48109;3;3;0;11.11467;10.53926;563799.8;7.053681e+007
505.284;3.521034;533.5175;55.13025;3;3;0;11.08987;10.51693;489632.8;6.124413e+007
506.238;3.512944;453.0513;46.8154;3;3;0;11.06439;10.49399;415785.4;5.199523e+007
507.286;3.504373;372.5292;38.49476;3;3;0;11.03739;10.46968;341886.7;4.274358e+007
508.39;3.495105;292.0166;30.17511;3;3;0;11.0082;10.44339;267996.7;3.349685e+007
509.43;3.491891;268.1521;27.7091;4;4;0;10.99808;10.43427;246095.1;3.075657e+007
510.228;3.499337;348.9661;36.0599;4;4;0;11.02153;10.4554;320261.8;4.003426e+007
511.118;3.506676;429.8014;44.4129;4;4;0;11.04465;10.47622;394447.9;4.931815e+007
511.99;3.513962;510.5798;52.76002;4;4;0;11.0676;10.49688;468581.8;5.859928e+007
512.838;3.521087;591.367;61.10805;4;4;0;11.09004;10.51708;542723.9;6.788495e+007
513.67;3.528051;672.2518;69.46616;4;4;0;11.11197;10.53683;616955.5;7.718522e+007
514.4981;3.534962;752.653;77.7743;4;4;0;11.13374;10.55641;690743.2;8.643349e+007
515.322;3.541766;833.1847;86.09592;4;4;0;11.15517;10.57569;764650.8;9.570007e+007
516.1281;3.548569;914.1337;94.46067;4;4;0;11.1766;10.59497;838941.3;1.050182e+008
516.924;3.555159;994.8167;102.7979;4;4;0;11.19735;10.61364;912987.6;1.143086e+008
517.708;3.561641;1075.657;111.1514;4;4;0;11.21777;10.63199;987178.3;1.236201e+008
518.488;3.568069;1156.46;119.5011;4;4;0;11.23801;10.6502;1061335;1.329307e+008
519.27;3.574551;1237.092;127.8331;4;4;0;11.25843;10.66855;1135335;1.422251e+008
520.026;3.581033;1317.976;136.1911;4;4;0;11.27884;10.6869;1209565;1.515519e+008
520.812;3.587569;1398.735;144.5363;4;4;0;11.29943;10.7054;1283682;1.608681e+008
521.632;3.594212;1479.697;152.9024;4;4;0;11.32035;10.72419;1357984;1.702115e+008
522.446;3.60123;1560.466;161.2485;4;4;0;11.34246;10.74405;1432110;1.795381e+008
523.562;3.610605;1640.949;169.565;4;4;0;11.37198;10.77056;1505972;1.88848e+008
530.588;3.669051;1680.939;173.6974;4;4;0;11.55607;10.93571;1542673;1.9377e+008
538.588;3.73564;1705.642;176.2501;4;4;0;11.7658;11.12354;1565344;1.969873e+008
546.588;3.802283;1731.591;178.9314;4;4;0;11.9757;11.31117;1589158;2.003597e+008
554.588;3.869033;1757.564;181.6153;4;4;0;12.18593;11.49874;1612995;2.037468e+008
562.588;3.935623;1785.147;184.4655;4;4;0;12.39566;11.68552;1638309;2.073312e+008
570.588;4.002265;1809.278;186.9591;4;4;0;12.60556;11.87209;1660455;2.105263e+008
578.588;4.069069;1834.938;189.6107;4;4;0;12.81596;12.05877;1684005;2.139111e+008
586.588;4.135551;1858.571;192.0527;4;4;0;13.02536;12.2442;1705693;2.170682e+008
594.588;4.202461;1884.515;194.7336;4;4;0;13.2361;12.43048;1729503;2.205087e+008
602.588;4.268944;1911.08;197.4786;4;4;0;13.44549;12.61523;1753883;2.240306e+008
610.588;4.335747;1938.765;200.3395;4;4;0;13.6559;12.80052;1779291;2.276976e+008
618.588;4.402443;1966.868;203.2434;4;4;0;13.86596;12.98518;1805082;2.314251e+008
626.588;4.469033;1990.994;205.7364;4;4;0;14.07569;13.1692;1827224;2.346953e+008
634.588;4.535783;2018.977;208.628;4;4;0;14.28593;13.35333;1852905;2.384325e+008
642.588;4.602319;2042.146;211.0222;4;4;0;14.49549;13.53653;1874169;2.416109e+008
649.8621;4.662961;2066.919;213.582;4;4;0;14.68649;13.70321;1896903;2.449497e+008
650.408;4.658783;1995.635;206.216;4;4;0;14.67333;13.69173;1831484;2.364748e+008
650.994;4.653693;1913.956;197.7758;4;4;0;14.6573;13.67775;1756523;2.267644e+008
651.578;4.648658;1833.129;189.4238;4;4;0;14.64144;13.66392;1682345;2.171581e+008
652.2201;4.643408;1752.095;181.0502;4;4;0;14.62491;13.64949;1607976;2.075286e+008
652.838;4.638158;1671.023;172.6727;4;4;0;14.60837;13.63507;1533572;1.978974e+008
653.5001;4.632693;1589.945;164.2946;4;4;0;14.59116;13.62005;1459163;1.882671e+008
654.1521;4.627283;1509.234;155.9545;4;4;0;14.57412;13.60518;1385091;1.786835e+008
654.8341;4.621604;1428.442;147.606;4;4;0;14.55623;13.58956;1310945;1.690918e+008
655.5241;4.615765;1347.179;139.2087;4;4;0;14.53784;13.57351;1236366;1.594467e+008
656.254;4.609765;1265.869;130.8068;4;4;0;14.51894;13.55701;1161745;1.497985e+008
656.9821;4.603711;1184.921;122.442;4;4;0;14.49988;13.54036;1087455;1.40196e+008
657.734;4.597336;1104.053;114.0857;4;4;0;14.4798;13.52282;1013238;1.30605e+008
658.526;4.590854;1022.782;105.6876;4;4;0;14.45938;13.50498;938652.2;1.209694e+008
659.3001;4.584212;942.1555;97.35627;4;4;0;14.43846;13.4867;864658.1;1.11413e+008
660.1281;4.577354;861.2539;88.99641;4;4;0;14.41686;13.46783;790411.1;1.018269e+008
660.9981;4.570282;780.347;80.63602;4;4;0;14.39459;13.44836;716159.2;9.224324e+007
661.8621;4.562997;699.5955;72.29168;4;4;0;14.37164;13.4283;642050;8.268118e+007
662.7721;4.555443;618.6551;63.92783;4;4;0;14.34785;13.4075;567767.4;7.31001e+007
663.69;4.547676;538.0758;55.60128;4;4;0;14.32339;13.3861;493816.2;6.356527e+007
664.674;4.53964;457.5165;47.27679;4;4;0;14.29808;13.36396;419883.3;5.403647e+007
665.708;4.531015;376.8602;38.9423;4;4;0;14.27091;13.34019;345861.4;4.449972e+007
666.7981;4.521908;296.4039;30.62846;4;4;0;14.24223;13.31508;272023.1;3.499064e+007
667.864;4.518211;266.6113;27.54989;5;5;0;14.23059;13.30489;244681;3.14704e+007
668.64;4.52539;347.3948;35.89753;5;5;0;14.2532;13.32468;318819.7;4.101408e+007
669.51;4.532569;428.1725;44.24458;5;5;0;14.27581;13.34447;392953;5.056085e+007
670.348;4.539693;508.9587;52.59251;5;5;0;14.29825;13.3641;467094.1;6.011231e+007
671.194;4.546711;589.6824;60.93397;5;5;0;14.32035;13.38344;541177.8;6.965992e+007
672.03;4.553515;670.3031;69.26479;5;5;0;14.34178;13.40218;615167.1;7.919859e+007
672.814;4.560211;750.8581;77.58882;5;5;0;14.36287;13.42063;689095.9;8.873281e+007
673.616;4.566908;831.7283;85.94543;5;5;0;14.38396;13.43907;763314.1;9.830778e+007
674.4201;4.573497;912.6993;94.31245;5;5;0;14.40471;13.45721;837624.8;1.078979e+008
675.182;4.579979;993.6311;102.6754;5;5;0;14.42513;13.47505;911899.6;1.174865e+008
675.952;4.586408;1074.09;110.9895;5;5;0;14.44538;13.49275;985740.3;1.270224e+008
676.7301;4.592783;1155.241;119.3751;5;5;0;14.46546;13.51029;1060216;1.366433e+008
677.486;4.599104;1235.921;127.7121;5;5;0;14.48537;13.52768;1134260;1.462116e+008
678.2641;4.605426;1316.939;136.084;5;5;0;14.50528;13.54507;1208614;1.558234e+008
678.9981;4.611693;1397.687;144.4279;5;5;0;14.52502;13.56231;1282720;1.654061e+008
679.752;4.618015;1478.652;152.7944;5;5;0;14.54493;13.57969;1357025;1.750182e+008
680.512;4.624283;1559.624;161.1614;5;5;0;14.56467;13.59693;1431336;1.846341e+008
681.254;4.630604;1640.626;169.5317;5;5;0;14.58458;13.61431;1505676;1.942572e+008
682.018;4.636872;1721.251;177.863;5;5;0;14.60432;13.63153;1579669;2.038387e+008
682.7821;4.643193;1802.098;186.2172;5;5;0;14.62423;13.6489;1653866;2.1345e+008
683.5681;4.649729;1882.65;194.5409;5;5;0;14.64482;13.66686;1727792;2.230311e+008
684.3961;4.656586;1963.45;202.8902;5;5;0;14.66641;13.6857;1801946;2.32647e+008
685.4641;4.665479;2044.138;211.228;5;5;0;14.69442;13.71012;1875997;2.422668e+008
691.78;4.71814;2090.76;216.0456;5;5;0;14.86028;13.85463;1918783;2.481506e+008
699.78;4.784944;2113.116;218.3558;5;5;0;15.07069;14.03764;1939301;2.512635e+008
707.78;4.85164;2139.16;221.047;5;5;0;15.28076;14.22003;1963202;2.548246e+008
715.78;4.918175;2162.026;223.4098;5;5;0;15.49032;14.40165;1984187;2.580166e+008
723.78;4.984979;2188.304;226.1252;5;5;0;15.70072;14.58367;2008304;2.616285e+008
731.78;5.051515;2211.77;228.5501;5;5;0;15.91028;14.76463;2029840;2.64913e+008
739.78;5.118211;2238.947;231.3583;5;5;0;16.12035;14.9457;2054781;2.686541e+008
747.78;5.184854;2267.046;234.2619;5;5;0;16.33025;15.12629;2080570;2.725175e+008
755.78;5.251496;2295.44;237.1959;5;5;0;16.54015;15.30656;2106627;2.764284e+008
763.78;5.318193;2324.9;240.2402;5;5;0;16.75021;15.48665;2133665;2.804809e+008
771.78;5.384889;2353.467;243.1921;5;5;0;16.96028;15.66642;2159882;2.844381e+008
779.78;5.451425;2380.35;245.97;5;5;0;17.16984;15.84543;2184554;2.882027e+008
787.78;5.518336;2409.458;248.9779;5;5;0;17.38059;16.02513;2211267;2.922517e+008
795.78;5.584764;2434.562;251.5719;5;5;0;17.58981;16.20322;2234306;2.958229e+008
803.78;5.651675;2464.24;254.6386;5;5;0;17.80055;16.38228;2261543;2.999657e+008
811.78;5.718157;2493.233;257.6346;5;5;0;18.00994;16.55987;2288151;3.040344e+008
819.78;5.78496;2523.393;260.7512;5;5;0;18.22035;16.738;2315831;3.082609e+008
827.78;5.851657;2555.04;264.0213;5;5;0;18.43042;16.91554;2344874;3.126816e+008
835.78;5.918192;2579.896;266.5898;5;5;0;18.63998;17.09233;2367686;3.162821e+008
836.53;5.917603;2520.225;260.4238;5;5;0;18.63812;17.09077;2312923;3.089619e+008
837.03;5.912943;2438.988;252.0292;5;5;0;18.62344;17.07839;2238368;2.989657e+008
837.5861;5.908228;2357.371;243.5955;5;5;0;18.60859;17.06588;2163465;2.889252e+008
838.142;5.903514;2275.966;235.1836;5;5;0;18.59374;17.05335;2088756;2.789131e+008
838.7381;5.898639;2195.226;226.8405;5;5;0;18.57839;17.04041;2014657;2.689838e+008
839.3081;5.89371;2113.934;218.4403;5;5;0;18.56287;17.02732;1940052;2.589891e+008
839.9361;5.888675;2032.676;210.0436;5;5;0;18.54701;17.01394;1865478;2.490004e+008
840.5241;5.883586;1951.824;201.6889;5;5;0;18.53098;17.00042;1791276;2.390638e+008
841.1701;5.878336;1871.176;193.3552;5;5;0;18.51444;16.98647;1717261;2.291538e+008
841.7901;5.873032;1789.954;184.9623;5;5;0;18.49774;16.97237;1642721;2.191761e+008
842.4561;5.867621;1708.721;176.5682;5;5;0;18.4807;16.95799;1568169;2.091992e+008
843.1121;5.862156;1627.608;168.1865;5;5;0;18.46348;16.94346;1493729;1.992396e+008
843.7901;5.856478;1546.301;159.7847;5;5;0;18.4456;16.92836;1419109;1.89258e+008
844.4701;5.850799;1465.215;151.4058;5;5;0;18.42772;16.91326;1344693;1.793065e+008
845.176;5.845014;1384.672;143.083;5;5;0;18.40949;16.89787;1270775;1.694239e+008
845.874;5.839014;1303.409;134.6859;5;5;0;18.3906;16.88191;1196197;1.594554e+008
846.6021;5.832907;1222.369;126.3118;5;5;0;18.37136;16.86566;1121823;1.49517e+008
847.382;5.826585;1141.283;117.9328;5;5;0;18.35145;16.84884;1047406;1.395752e+008
848.1641;5.819996;1060.153;109.5494;5;5;0;18.3307;16.8313;972949.9;1.296306e+008
848.9621;5.813353;979.4889;101.2141;5;5;0;18.30977;16.81362;898920.6;1.197461e+008
849.7981;5.806443;898.5628;92.85168;5;5;0;18.28801;16.79522;824651.2;1.098324e+008
850.6381;5.799318;817.7403;84.49999;5;5;0;18.26557;16.77625;750476.7;9.99344e+007
851.5081;5.791978;736.933;76.14989;5;5;0;18.24245;16.7567;676316.3;9.004151e+007
852.442;5.784425;656.477;67.83609;5;5;0;18.21866;16.73658;602478.2;8.019492e+007
853.382;5.77655;575.6838;59.48744;5;5;0;18.19386;16.7156;528330.6;7.03105e+007
854.338;5.768461;495.0973;51.16016;5;5;0;18.16838;16.69404;454372.9;6.045513e+007
855.3761;5.759943;414.3679;42.8181;5;5;0;18.14155;16.67133;380283.9;5.058597e+007
856.4461;5.750836;333.7662;34.48924;5;5;0;18.11287;16.64705;306312.1;4.073623e+007
857.53;5.745639;289.9491;29.96147;6;6;0;18.0965;16.63319;266099.2;3.538344e+007
858.2761;5.752871;371.019;38.33871;6;6;0;18.11928;16.65248;340500.7;4.528541e+007
859.1101;5.759835;451.9139;46.69786;6;6;0;18.14121;16.67105;414741.5;5.516942e+007
859.95;5.766746;532.5902;55.03442;6;6;0;18.16298;16.68947;488781.7;6.503032e+007
860.7581;5.773603;613.0643;63.35011;6;6;0;18.18458;16.70774;562636.4;7.487005e+007
861.5741;5.780407;694.2447;71.73875;6;6;0;18.20601;16.72587;637139.3;8.479952e+007
862.3881;5.78705;775.1912;80.10325;6;6;0;18.22693;16.74357;711427.6;9.470361e+007
863.168;5.79364;855.9266;88.44592;6;6;0;18.24768;16.76113;785522;1.045853e+008
863.96;5.800175;937.0066;96.82421;6;6;0;18.26827;16.77853;859932.8;1.145123e+008
864.726;5.80655;1017.643;105.1566;6;6;0;18.28835;16.79551;933936.2;1.24388e+008
865.486;5.812818;1098.12;113.4726;6;6;0;18.30809;16.81219;1007793;1.342473e+008
866.244;5.819032;1178.818;121.8115;6;6;0;18.32766;16.82874;1081854;1.441367e+008
866.9541;5.825246;1260.105;130.2111;6;6;0;18.34723;16.84528;1156454;1.541012e+008
867.6821;5.831353;1341.25;138.5961;6;6;0;18.36647;16.86153;1230925;1.640513e+008
868.416;5.837246;1421.97;146.9372;6;6;0;18.38503;16.87721;1305005;1.739516e+008
869.1261;5.843139;1502.801;155.2897;6;6;0;18.40359;16.89288;1379188;1.838686e+008
869.832;5.849032;1583.931;163.6732;6;6;0;18.42215;16.90856;1453644;1.938253e+008
870.5241;5.854979;1664.861;172.0359;6;6;0;18.44088;16.92437;1527917;2.037609e+008
871.2501;5.860871;1745.837;180.4035;6;6;0;18.45944;16.94004;1602232;2.13705e+008
871.9381;5.866711;1826.835;188.7733;6;6;0;18.47783;16.95557;1676568;2.236545e+008
872.6381;5.87255;1907.634;197.1226;6;6;0;18.49622;16.97109;1750721;2.335828e+008
873.3581;5.878496;1988.15;205.4426;6;6;0;18.51495;16.98689;1824614;2.434802e+008
874.0701;5.884389;2069.148;213.8124;6;6;0;18.53351;17.00255;1898950;2.534394e+008
874.7861;5.890228;2150.021;222.1693;6;6;0;18.5519;17.01807;1973171;2.63386e+008
875.4641;5.896175;2230.505;230.486;6;6;0;18.57063;17.03386;2047034;2.732887e+008
876.202;5.902228;2311.47;238.8524;6;6;0;18.58969;17.04994;2121339;2.832543e+008
876.942;5.908282;2392.469;247.2223;6;6;0;18.60876;17.06602;2195676;2.932273e+008
877.7221;5.914817;2473.524;255.598;6;6;0;18.62935;17.08337;2270064;3.032143e+008
878.6721;5.922853;2554.215;263.9361;6;6;0;18.65466;17.1047;2344117;3.131725e+008
884.5781;5.971871;2601.241;268.7955;6;6;0;18.80904;17.23473;2387275;3.193533e+008
892.5781;6.038782;2628.774;271.6405;6;6;0;19.01978;17.41196;2412543;3.233059e+008
900.5781;6.105211;2654.44;274.2927;6;6;0;19.22901;17.58759;2436098;3.270365e+008
908.5781;6.172121;2681.927;277.133;6;6;0;19.43975;17.76419;2461324;3.31007e+008
916.5781;6.238603;2707.938;279.8208;6;6;0;19.64915;17.93935;2485196;3.348032e+008
924.5781;6.305407;2734.286;282.5434;6;6;0;19.85955;18.11504;2509376;3.386553e+008
932.5781;6.372049;2764.781;285.6946;6;6;0;20.06945;18.29001;2537363;3.430319e+008
940.5781;6.438692;2791.847;288.4915;6;6;0;20.27935;18.46467;2562203;3.469957e+008
948.5781;6.505388;2824.187;291.8333;6;6;0;20.48941;18.63917;2591883;3.516282e+008
956.5781;6.571924;2853.956;294.9094;6;6;0;20.69897;18.81294;2619203;3.559526e+008
964.5781;6.638621;2894.022;299.0496;6;6;0;20.90904;18.98684;2655974;3.61578e+008
972.5781;6.705317;2938.427;303.6381;6;6;0;21.11911;19.16042;2696726;3.677637e+008
980.5781;6.771907;2980.676;308.0038;6;6;0;21.32884;19.33344;2735500;3.736975e+008
988.5781;6.838603;3023.751;312.455;6;6;0;21.53891;19.50642;2775032;3.797543e+008
996.5781;6.905353;3062.548;316.4639;6;6;0;21.74914;19.67925;2810637;3.852921e+008
1004.578;6.971888;3100.974;320.4347;6;6;0;21.9587;19.85123;2845902;3.907979e+008
1012.578;7.038799;3145.727;325.0591;6;6;0;22.16945;20.02388;2886974;3.971229e+008
1020.578;7.105174;3183.962;329.0101;6;6;0;22.3785;20.19485;2922064;4.026376e+008
1028.578;7.172138;3227.925;333.5529;6;6;0;22.58941;20.36705;2962411;4.089005e+008
1036.578;7.23862;3268.824;337.7791;6;6;0;22.7988;20.53771;2999945;4.147887e+008
1044.578;7.305424;3311.239;342.162;6;6;0;23.00921;20.7089;3038872;4.208908e+008
1052.578;7.372067;3354.636;346.6464;6;6;0;23.21911;20.87939;3078699;4.271346e+008
1060.578;7.438656;3392.892;350.5995;6;6;0;23.42884;21.04946;3113808;4.327409e+008
1068.578;7.505406;3438.292;355.2909;6;6;0;23.63907;21.21964;3155474;4.392784e+008
1076.578;7.571995;3481.392;359.7445;6;6;0;23.8488;21.38913;3195028;4.455393e+008
1082.37;7.62037;3553.312;367.1764;6;6;0;24.00117;21.51208;3261033;4.55303e+008
1088.066;7.667781;3633.498;375.4622;6;6;0;24.15049;21.63243;3334623;4.661382e+008
1092.424;7.702924;3682.666;380.5429;6;6;0;24.26118;21.72154;3379747;4.728671e+008
1092.86;7.698692;3600.931;372.0969;6;6;0;24.24785;21.71082;3304735;4.623224e+008
1093.34;7.694352;3519.7;363.703;6;6;0;24.23418;21.69981;3230186;4.518435e+008
1093.83;7.690067;3438.662;355.3291;6;6;0;24.22068;21.68895;3155814;4.413923e+008
1094.358;7.685727;3357.277;346.9193;6;6;0;24.20702;21.67795;3081123;4.308981e+008
1094.904;7.681227;3276.166;338.5378;6;6;0;24.19284;21.66653;3006684;4.204397e+008
1095.426;7.676781;3194.829;330.1329;6;6;0;24.17884;21.65526;2932037;4.099553e+008
1095.978;7.672334;3113.651;321.7446;6;6;0;24.16483;21.64398;2857536;3.994936e+008
1096.526;7.667728;3031.972;313.3044;6;6;0;24.15032;21.63229;2782576;3.889684e+008
1097.072;7.663174;2951.234;304.9615;6;6;0;24.13598;21.62074;2708479;3.785669e+008
1097.62;7.658566;2869.949;296.562;6;6;0;24.12147;21.60905;2633880;3.680971e+008
1098.196;7.653852;2788.875;288.1844;6;6;0;24.10662;21.59709;2559475;3.576559e+008
1098.74;7.649138;2707.431;279.7684;6;6;0;24.09177;21.58512;2484730;3.471696e+008
1099.322;7.644424;2626.739;271.4303;6;6;0;24.07693;21.57316;2410676;3.367823e+008
1099.904;7.639495;2545.374;263.0225;6;6;0;24.0614;21.56064;2336003;3.263094e+008
1100.484;7.634674;2464.343;254.6493;6;6;0;24.04622;21.5484;2261638;3.158828e+008
1101.086;7.629692;2383.179;246.2624;6;6;0;24.03053;21.53575;2187150;3.054405e+008
1101.678;7.624709;2301.91;237.8645;6;6;0;24.01483;21.5231;2112565;2.949872e+008
1102.31;7.61946;2220.71;229.4739;6;6;0;23.9983;21.50977;2038045;2.845437e+008
1102.938;7.614209;2139.63;221.0956;6;6;0;23.98176;21.49643;1963634;2.741182e+008
1103.58;7.608852;2058.716;212.7344;6;6;0;23.96489;21.48282;1889375;2.63716e+008
1104.244;7.603441;1978.132;204.4074;6;6;0;23.94785;21.46907;1815420;2.533586e+008
1104.892;7.59787;1896.91;196.0145;6;6;0;23.9303;21.45491;1740879;2.429213e+008
1105.592;7.592192;1815.674;187.62;6;6;0;23.91241;21.44048;1666325;2.324845e+008
1106.274;7.586513;1734.714;179.2541;6;6;0;23.89453;21.42604;1592024;2.22086e+008
1106.972;7.580674;1653.665;170.8791;6;6;0;23.87614;21.4112;1517642;2.116784e+008
1107.664;7.574781;1572.711;162.5138;6;6;0;23.85758;21.39622;1443348;2.012857e+008
1108.4;7.568781;1491.769;154.1498;6;6;0;23.83868;21.38096;1369063;1.908971e+008
1109.134;7.562674;1410.466;145.7484;6;6;0;23.81945;21.36542;1294447;1.804649e+008
1109.868;7.556513;1329.59;137.3913;6;6;0;23.80004;21.34975;1220224;1.700904e+008
1110.644;7.550085;1248.64;129.0264;6;6;0;23.77979;21.3334;1145932;1.597086e+008
1111.402;7.543602;1167.561;120.6482;6;6;0;23.75938;21.3169;1071523;1.493135e+008
1112.194;7.537013;1086.955;112.3189;6;6;0;23.73862;21.30013;997546.9;1.389818e+008
1113.026;7.530209;1006.119;103.9658;6;6;0;23.71719;21.28281;923360.3;1.286236e+008
1113.844;7.523299;925.4081;95.62569;6;6;0;23.69543;21.26521;849288.3;1.182846e+008
1114.7;7.51612;844.7469;87.29069;6;6;0;23.67282;21.24693;775261.9;1.079548e+008
1115.612;7.508728;764.106;78.95778;6;6;0;23.64954;21.22811;701254.2;9.763093e+007
1116.54;7.50096;683.149;70.5922;6;6;0;23.62507;21.20832;626956.3;8.726966e+007
1117.466;7.493084;602.1979;62.22724;6;6;0;23.60027;21.18825;552663.9;7.691303e+007
1118.468;7.484835;521.1952;53.85694;6;6;0;23.57428;21.16723;478324.1;6.655333e+007
1119.488;7.476263;440.6558;45.53453;6;6;0;23.54729;21.14538;404409.5;5.625667e+007
1120.558;7.467477;361.2932;37.33371;6;6;0;23.51961;21.12298;331574.9;4.611445e+007
1121.34;7.473745;432.0916;44.64955;7;7;0;23.53935;21.13896;396549.7;5.515977e+007
1122.106;7.480228;512.7887;52.98827;7;7;0;23.55977;21.15548;470609;6.547219e+007
1122.882;7.48671;593.4338;61.32162;7;7;0;23.58019;21.17201;544620.7;7.578137e+007
1123.664;7.493192;674.0795;69.65502;7;7;0;23.6006;21.18852;618632.8;8.609403e+007
1124.418;7.499566;754.8935;78.00581;7;7;0;23.62068;21.20477;692799.4;9.643132e+007
1125.196;7.505995;836.1827;86.40572;7;7;0;23.64093;21.22115;767402.1;1.068328e+008
1125.958;7.512317;917.0635;94.76341;7;7;0;23.66084;21.23725;841630.1;1.171852e+008
1126.682;7.518531;997.8219;103.1085;7;7;0;23.68041;21.25307;915745.6;1.27525e+008
1127.428;7.524638;1078.559;111.4513;7;7;0;23.69965;21.26862;989841.8;1.378649e+008
1128.148;7.530638;1159.613;119.8269;7;7;0;23.71855;21.2839;1064228;1.482481e+008
1128.854;7.536531;1240.671;128.2029;7;7;0;23.73711;21.2989;1138619;1.586346e+008
1129.57;7.542477;1321.652;136.571;7;7;0;23.75583;21.31404;1212939;1.690146e+008
1130.268;7.548316;1402.517;144.927;7;7;0;23.77423;21.3289;1287152;1.793823e+008
1130.97;7.553995;1483.389;153.2838;7;7;0;23.79211;21.34334;1361372;1.897533e+008
1131.622;7.559673;1564.127;161.6268;7;7;0;23.81;21.35779;1435470;2.001102e+008
1132.314;7.565352;1644.857;169.9689;7;7;0;23.82788;21.37224;1509559;2.104689e+008
1132.972;7.57087;1725.792;178.3322;7;7;0;23.84526;21.38627;1583837;2.20856e+008
1133.496;7.576656;1807.5;186.7753;7;7;0;23.86348;21.40098;1658823;2.313465e+008
1133.824;7.582174;1889.688;195.2681;7;7;0;23.88086;21.41501;1734251;2.418998e+008
1134.156;7.587692;1971.773;203.7502;7;7;0;23.89824;21.42904;1809584;2.52443e+008
1134.496;7.593424;2053.291;212.1739;7;7;0;23.9163;21.44361;1884397;2.62918e+008
1134.834;7.598996;2135.357;220.654;7;7;0;23.93384;21.45777;1959712;2.734649e+008
1135.168;7.604513;2217.033;229.0938;7;7;0;23.95122;21.47179;2034670;2.839646e+008
1135.496;7.610138;2298.439;237.5058;7;7;0;23.96894;21.48609;2109380;2.944334e+008
1135.836;7.615602;2380.112;245.9454;7;7;0;23.98615;21.49997;2184335;3.049383e+008
1136.154;7.62112;2462.773;254.4871;7;7;0;24.00353;21.51398;2260197;3.15573e+008
1136.496;7.626691;2544.855;262.9689;7;7;0;24.02107;21.52813;2335527;3.261368e+008
1136.81;7.631995;2626.743;271.4307;7;7;0;24.03778;21.5416;2410680;3.366766e+008
1137.144;7.63762;2708.437;279.8724;7;7;0;24.0555;21.55588;2485654;3.471971e+008
1137.47;7.642977;2790.097;288.3106;7;7;0;24.07237;21.56948;2560597;3.577138e+008
1137.798;7.648495;2872.121;296.7864;7;7;0;24.08975;21.58349;2635873;3.682815e+008
1138.134;7.654066;2954.201;305.268;7;7;0;24.1073;21.59763;2711202;3.788599e+008
1138.462;7.659477;3036.298;313.7514;7;7;0;24.12434;21.61136;2786546;3.894418e+008
1138.796;7.665102;3117.931;322.1869;7;7;0;24.14205;21.62563;2861464;3.999694e+008
1139.134;7.670674;3199.801;330.6468;7;7;0;24.1596;21.63977;2936600;4.105297e+008
1139.47;7.676191;3281.605;339.0998;7;7;0;24.17698;21.65376;3011675;4.210839e+008
1139.802;7.681977;3364.027;347.6168;7;7;0;24.1952;21.66844;3087317;4.317234e+008
1140.16;7.687709;3445.238;356.0087;7;7;0;24.21326;21.68297;3161849;4.4221e+008
1140.498;7.693495;3526.966;364.4539;7;7;0;24.23148;21.69764;3236854;4.527665e+008
1140.894;7.700031;3608.653;372.8949;7;7;0;24.25207;21.71421;3311822;4.633296e+008
1141.44;7.709191;3689.51;381.2502;7;7;0;24.28092;21.73743;3386028;4.738212e+008
1143.506;7.743692;3769.984;389.5658;7;7;0;24.38958;21.82482;3459883;4.845793e+008
1146.692;7.796674;3850.48;397.8838;7;7;0;24.55645;21.95889;3533758;4.955899e+008
1149.936;7.850673;3930.784;406.1819;7;7;0;24.72653;22.09534;3607456;5.066166e+008
1153.262;7.906281;4011.023;414.4732;7;7;0;24.90167;22.23566;3681095;5.176839e+008
1157.33;7.973941;4090.851;422.7221;7;7;0;25.11478;22.40613;3754357;5.288878e+008
1162.206;8.055209;4171.223;431.0272;7;7;0;25.37074;22.61051;3828117;5.40382e+008
1167.126;8.13728;4251.547;439.3274;7;7;0;25.62923;22.81648;3901834;5.519236e+008
1172.616;8.228727;4331.865;447.6269;7;7;0;25.91725;23.04548;3975545;5.636395e+008
1177.548;8.310959;4412.393;455.9482;7;7;0;26.17625;23.25095;4049450;5.752984e+008
1182.646;8.395977;4492.867;464.2638;7;7;0;26.44402;23.46295;4123304;5.870339e+008
1187.572;8.478101;4573.216;472.5667;7;7;0;26.70268;23.66731;4197045;5.987546e+008
1193.448;8.575977;4649.144;480.4124;7;7;0;27.01095;23.91031;4266727;6.101764e+008
1198.388;8.658316;4729.494;488.7153;7;7;0;27.27029;24.11429;4340467;6.219894e+008
1203.41;8.741994;4810.102;497.0448;7;7;0;27.53384;24.32116;4414445;6.339003e+008
1207.738;8.814155;4890.441;505.3466;7;7;0;27.76112;24.49921;4488176;6.456365e+008
1212.012;8.885405;4970.843;513.6548;7;7;0;27.98553;24.6747;4561964;6.574038e+008
1216.358;8.957887;5051.455;521.9847;7;7;0;28.21382;24.85291;4635946;6.692566e+008
1220.57;9.027958;5131.959;530.3035;7;7;0;28.43451;25.0249;4709827;6.810927e+008
1224.924;9.100655;5212.322;538.6077;7;7;0;28.66348;25.20301;4783581;6.929915e+008
1229.534;9.177262;5292.806;546.9244;7;7;0;28.90476;25.39037;4857444;7.050116e+008
1233.736;9.247333;5373.182;555.2299;7;7;0;29.12546;25.56143;4931209;7.169431e+008
1237.816;9.31553;5453.625;563.5424;7;7;0;29.34025;25.72764;5005035;7.288871e+008
1242.59;9.394977;5533.984;571.8461;7;7;0;29.59048;25.92091;5078784;7.410581e+008
1247.362;9.474637;5614.648;580.1815;7;7;0;29.84138;26.11433;5152814;7.533157e+008
1251.644;9.54594;5695.12;588.4969;7;7;0;30.06595;26.28715;5226666;7.654341e+008
1255.562;9.611297;5775.533;596.8063;7;7;0;30.2718;26.44529;5300465;7.774703e+008
1259.758;9.681154;5856.05;605.1264;7;7;0;30.49182;26.61404;5374359;7.896405e+008
1263.252;9.739387;5936.544;613.4442;7;7;0;30.67523;26.75449;5448232;8.016196e+008
1267.342;9.807529;6016.775;621.7347;7;7;0;30.88985;26.9186;5521863;8.137876e+008
1271.382;9.874814;6097.25;630.0504;7;7;0;31.10178;27.08038;5595718;8.260073e+008
1275.302;9.940226;6177.762;638.3701;7;7;0;31.3078;27.2374;5669608;8.382296e+008
1279.056;10.00264;6258.24;646.6861;7;7;0;31.50437;27.38699;5743466;8.504205e+008
1283.01;10.06858;6338.701;655.0004;7;7;0;31.71207;27.54481;5817309;8.627147e+008
1286.542;10.12762;6418.901;663.2877;7;7;0;31.89801;27.68588;5890912;8.748633e+008
1289.84;10.18264;6499.218;671.5872;7;7;0;32.07129;27.81717;5964623;8.869739e+008
1293.3;10.24017;6579.654;679.8989;7;7;0;32.25251;27.95429;6038442;8.991834e+008
1296.592;10.29508;6660.299;688.2323;7;7;0;32.42546;28.08497;6112454;9.113948e+008
1299.564;10.34453;6740.962;696.5674;7;7;0;32.5812;28.20251;6186481;9.235174e+008
1302.474;10.39312;6821.497;704.8894;7;7;0;32.73423;28.31787;6260392;9.356295e+008
1305.502;10.44348;6902.153;713.2239;7;7;0;32.89284;28.43729;6334414;9.478236e+008
1308.748;10.49764;6982.727;721.5499;7;7;0;33.06342;28.56557;6408360;9.60119e+008
1311.654;10.54612;7063.039;729.8488;7;7;0;33.21612;28.68026;6482066;9.722763e+008
1314.494;10.59337;7143.39;738.1517;7;7;0;33.36494;28.79191;6555807;9.844356e+008
1317.186;10.63831;7223.758;746.4565;7;7;0;33.5065;28.898;6629565;9.96568e+008
1320.218;10.68889;7304.189;754.7678;7;7;0;33.66578;29.01723;6703381;1.008866e+009
1323.028;10.73565;7384.934;763.1113;7;7;0;33.81308;29.12738;6777483;1.021143e+009
1325.926;10.78398;7465.219;771.4075;7;7;0;33.96527;29.24104;6851165;1.033418e+009
1328.808;10.83203;7545.578;779.7113;7;7;0;34.11662;29.35396;6924914;1.045722e+009
1331.802;10.8818;7626.379;788.0607;7;7;0;34.27338;29.47076;6999068;1.058156e+009
1334.686;10.9299;7706.956;796.387;7;7;0;34.42489;29.58354;7073017;1.070542e+009
1337.348;10.97431;7787.503;804.7103;7;7;0;34.56477;29.68754;7146939;1.082857e+009
1340.094;11.02006;7867.995;813.0277;7;7;0;34.70886;29.79457;7220810;1.09522e+009
1342.82;11.06544;7948.629;821.36;7;7;0;34.85178;29.9006;7294811;1.107619e+009
1345.01;11.10203;8029.135;829.6789;7;7;0;34.96702;29.98603;7368695;1.119793e+009
1347.536;11.14408;8109.608;837.9945;7;7;0;35.09947;30.08411;7442549;1.132126e+009
1349.81;11.18212;8190.327;846.3355;7;7;0;35.21927;30.17275;7516629;1.144409e+009
1352.072;11.21972;8270.756;854.6465;7;7;0;35.33772;30.26031;7590442;1.156659e+009
1354.456;11.25942;8351.563;862.9966;7;7;0;35.46274;30.35265;7664602;1.169039e+009
1356.57;11.29478;8432.024;871.3109;7;7;0;35.5741;30.43482;7738445;1.181272e+009
1359.004;11.33533;8512.647;879.642;7;7;0;35.70183;30.52899;7812436;1.19369e+009
1361.222;11.37219;8593.124;887.9579;7;7;0;35.81792;30.6145;7886294;1.206006e+009
1363.648;11.41264;8673.691;896.2832;7;7;0;35.94531;30.70825;7960233;1.218455e+009
1366.064;11.45276;8754.171;904.5995;7;7;0;36.07169;30.80117;8034094;1.230904e+009
1368.256;11.48946;8834.538;912.9041;7;7;0;36.18727;30.88607;8107850;1.243259e+009
1370.48;11.52647;8915.311;921.2506;7;7;0;36.30386;30.97164;8181978;1.2557e+009
1372.866;11.56633;8995.802;929.5681;7;7;0;36.42939;31.0637;8255849;1.268204e+009
1374.924;11.60067;9076.523;937.9092;7;7;0;36.53755;31.14295;8329930;1.280598e+009
1377.37;11.64139;9157.239;946.2499;7;7;0;36.66578;31.23682;8404006;1.2932e+009
1379.538;11.67733;9237.514;954.545;7;7;0;36.779;31.31963;8477679;1.305617e+009
1381.682;11.71322;9317.99;962.8608;7;7;0;36.89204;31.40224;8551535;1.31808e+009
1383.882;11.74987;9398.772;971.2083;7;7;0;37.00745;31.48652;8625672;1.330628e+009
1385.888;11.7833;9479.434;979.5435;7;7;0;37.11274;31.56333;8699699;1.343079e+009
1387.93;11.81731;9560.159;987.8851;7;7;0;37.21989;31.64145;8773784;1.355575e+009
1389.902;11.85005;9640.667;996.2042;7;7;0;37.32298;31.71655;8847670;1.368017e+009
1391.846;11.88262;9721.212;1004.527;7;7;0;37.42557;31.79123;8921590;1.380477e+009
1393.7;11.91358;9802.009;1012.876;7;7;0;37.52309;31.86216;8995741;1.392939e+009
1395.724;11.94733;9882.439;1021.187;7;7;0;37.62939;31.93943;9069555;1.405454e+009
1397.776;11.98135;9963.26;1029.539;7;7;0;37.73653;32.01725;9143728;1.418051e+009
1399.67;12.0129;10044.03;1037.885;7;7;0;37.83591;32.08938;9217853;1.430578e+009
1401.622;12.04553;10124.9;1046.242;7;7;0;37.93867;32.1639;9292075;1.443172e+009
1403.438;12.0758;10205.22;1054.541;7;7;0;38.034;32.23298;9365782;1.455625e+009
1405.318;12.10714;10285.8;1062.868;7;7;0;38.13271;32.30447;9439734;1.468168e+009
1407.11;12.13697;10366.19;1071.175;7;7;0;38.22669;32.37248;9513511;1.480649e+009
1408.968;12.16794;10446.52;1079.476;7;7;0;38.32422;32.44301;9587236;1.493176e+009
1410.766;12.19783;10526.98;1087.79;7;7;0;38.41837;32.51105;9661080;1.505701e+009
1412.62;12.22874;10607.82;1096.144;7;7;0;38.51572;32.58136;9735272;1.518332e+009
1414.296;12.25676;10688.31;1104.461;7;7;0;38.60397;32.64505;9809138;1.530826e+009
1415.964;12.28462;10769.18;1112.817;7;7;0;38.6917;32.70833;9883355;1.543385e+009
1417.692;12.31333;10849.62;1121.129;7;7;0;38.78215;32.77352;9957177;1.555927e+009
1419.396;12.34178;10930.54;1129.492;7;7;0;38.87174;32.83806;1.003145e+007;1.568545e+009
1421.194;12.37167;11011.09;1137.815;7;7;0;38.96589;32.90583;1.010537e+007;1.581174e+009
1422.882;12.39985;11092.18;1146.194;7;7;0;39.05464;32.96968;1.017979e+007;1.593836e+009
1424.46;12.42615;11172.77;1154.522;7;7;0;39.13749;33.02924;1.025375e+007;1.606373e+009
1426.094;12.45337;11253.46;1162.86;7;7;0;39.2232;33.09082;1.03278e+007;1.618971e+009
1427.732;12.48064;11334.03;1171.186;7;7;0;39.30909;33.15249;1.040175e+007;1.631568e+009
1429.21;12.50539;11414.44;1179.494;7;7;0;39.38704;33.20843;1.047554e+007;1.644062e+009
1430.866;12.53281;11495.15;1187.835;7;7;0;39.47343;33.27039;1.054962e+007;1.656714e+009
1432.43;12.55901;11575.86;1196.174;7;7;0;39.55593;33.32953;1.062368e+007;1.669332e+009
1433.96;12.58435;11656.68;1204.526;7;7;0;39.63574;33.3867;1.069785e+007;1.681949e+009
1435.344;12.60755;11737.64;1212.892;7;7;0;39.70881;33.43901;1.077216e+007;1.694517e+009
1436.762;12.63128;11818.47;1221.244;7;7;0;39.78355;33.4925;1.084634e+007;1.707099e+009
1438.184;12.6549;11899.08;1229.575;7;7;0;39.85796;33.54572;1.092032e+007;1.719658e+009
1439.622;12.6789;11979.72;1237.907;7;7;0;39.93355;33.59975;1.099432e+007;1.732247e+009
1441.02;12.70215;12060.36;1246.239;7;7;0;40.00678;33.65207;1.106833e+007;1.74482e+009
1442.438;12.72583;12141.05;1254.578;7;7;0;40.08136;33.70532;1.114238e+007;1.757429e+009
1443.792;12.74817;12221.7;1262.911;7;7;0;40.15172;33.75553;1.12164e+007;1.769992e+009
1445.074;12.76971;12302.36;1271.247;7;7;0;40.21955;33.80392;1.129043e+007;1.782537e+009
1446.336;12.79081;12383.13;1279.593;7;7;0;40.28603;33.85132;1.136455e+007;1.79509e+009
1447.746;12.81433;12464.07;1287.957;7;7;0;40.3601;33.90411;1.143884e+007;1.807778e+009
1449.058;12.83613;12544.92;1296.311;7;7;0;40.42877;33.95302;1.151304e+007;1.820394e+009
1450.51;12.86019;12625.65;1304.653;7;7;0;40.50453;34.00695;1.158712e+007;1.833096e+009
1451.808;12.88189;12706.68;1313.026;7;7;0;40.57286;34.05558;1.166148e+007;1.845758e+009
1453.074;12.90315;12787.66;1321.394;7;7;0;40.63985;34.10322;1.173581e+007;1.858407e+009
1454.47;12.92635;12868.37;1329.735;7;7;0;40.71291;34.15515;1.180988e+007;1.871108e+009
1455.786;12.94837;12948.71;1338.036;7;7;0;40.78226;34.20442;1.188361e+007;1.883717e+009
1457.168;12.97124;13029.29;1346.362;7;7;0;40.85431;34.25559;1.195756e+007;1.896409e+009
1458.558;12.99449;13110.07;1354.71;7;7;0;40.92754;34.30756;1.20317e+007;1.909159e+009
1459.856;13.01608;13190.79;1363.051;7;7;0;40.99553;34.3558;1.210577e+007;1.921841e+009
1461.198;13.03853;13271.38;1371.378;7;7;0;41.06623;34.40593;1.217974e+007;1.934552e+009
1462.578;13.06146;13352.08;1379.717;7;7;0;41.13844;34.45711;1.22538e+007;1.947311e+009
1463.89;13.08337;13432.65;1388.043;7;7;0;41.20745;34.50599;1.232774e+007;1.96002e+009
1465.284;13.10651;13513.36;1396.383;7;7;0;41.28035;34.5576;1.240181e+007;1.972814e+009
1466.616;13.12879;13593.87;1404.703;7;7;0;41.35054;34.60727;1.24757e+007;1.985555e+009
1467.962;13.15124;13674.19;1413.002;7;7;0;41.42123;34.65727;1.254941e+007;1.998285e+009
1469.318;13.1738;13754.74;1421.326;7;7;0;41.49227;34.70749;1.262334e+007;2.011066e+009
1470.606;13.19522;13835.46;1429.667;7;7;0;41.55976;34.75518;1.269742e+007;2.023834e+009
1471.952;13.21751;13916.31;1438.022;7;7;0;41.62995;34.80475;1.277162e+007;2.036669e+009
1473.214;13.23856;13996.87;1446.346;7;7;0;41.69626;34.85156;1.284555e+007;2.049418e+009
1474.456;13.25935;14077.61;1454.689;7;7;0;41.76173;34.89775;1.291965e+007;2.062193e+009
1475.664;13.27949;14158.24;1463.021;7;7;0;41.82517;34.94249;1.299365e+007;2.074932e+009
1476.894;13.2999;14238.82;1471.348;7;7;0;41.88945;34.98781;1.30676e+007;2.087688e+009
1478.108;13.32015;14319.46;1479.681;7;7;0;41.95324;35.03275;1.314161e+007;2.100455e+009
1479.226;13.33885;14400.2;1488.024;7;7;0;42.01212;35.07422;1.321571e+007;2.113174e+009
1480.412;13.35867;14480.96;1496.369;7;7;0;42.07455;35.11817;1.328982e+007;2.125959e+009
1481.46;13.37619;14561.77;1504.72;7;7;0;42.12973;35.157;1.336399e+007;2.138654e+009
1482.61;13.39531;14642.52;1513.063;7;7;0;42.18996;35.19937;1.343809e+007;2.151424e+009
1483.724;13.41396;14723.09;1521.389;7;7;0;42.24868;35.24066;1.351204e+007;2.164156e+009
1484.9;13.43356;14804.05;1529.755;7;7;0;42.31044;35.28407;1.358634e+007;2.177001e+009
1486.102;13.45349;14884.72;1538.09;7;7;0;42.3732;35.32816;1.366037e+007;2.189829e+009
1487.236;13.47224;14965.22;1546.41;7;7;0;42.43225;35.36963;1.373425e+007;2.202586e+009
1488.346;13.49088;15046.07;1554.764;7;7;0;42.49097;35.41085;1.380845e+007;2.215398e+009
1489.414;13.50878;15126.45;1563.07;7;7;0;42.54733;35.45039;1.388222e+007;2.228114e+009
1490.566;13.5279;15207.02;1571.395;7;7;0;42.60757;35.49264;1.395616e+007;2.240928e+009
1491.64;13.5459;15287.75;1579.738;7;7;0;42.66426;35.53238;1.403025e+007;2.253721e+009
1492.772;13.56455;15368.45;1588.077;7;7;0;42.72298;35.57354;1.410431e+007;2.26655e+009
1493.842;13.58254;15449.3;1596.43;7;7;0;42.77967;35.61325;1.417851e+007;2.279378e+009
1494.896;13.60017;15530.03;1604.773;7;7;0;42.83518;35.65212;1.42526e+007;2.29218e+009
1496.066;13.61956;15610.84;1613.124;7;7;0;42.89626;35.69487;1.432677e+007;2.305094e+009
1497.14;13.63756;15691.63;1621.472;7;7;0;42.95295;35.73454;1.440091e+007;2.317942e+009
1498.272;13.65621;15772.35;1629.813;7;7;0;43.01167;35.77561;1.447499e+007;2.330822e+009
1499.302;13.67356;15853.34;1638.181;7;7;0;43.06634;35.81383;1.454931e+007;2.343686e+009
1500.364;13.69119;15933.8;1646.496;7;7;0;43.12185;35.85262;1.462316e+007;2.356496e+009
1501.43;13.70908;16014.58;1654.843;7;7;0;43.17821;35.89199;1.469729e+007;2.369375e+009
1502.5;13.72676;16095.08;1663.161;7;7;0;43.23389;35.93087;1.477117e+007;2.38221e+009
1503.484;13.74331;16175.47;1671.469;7;7;0;43.28603;35.96726;1.484495e+007;2.394981e+009
1504.546;13.76099;16255.84;1679.773;7;7;0;43.3417;36.00611;1.491871e+007;2.407816e+009
1505.646;13.7791;16336.73;1688.132;7;7;0;43.39874;36.04589;1.499295e+007;2.42076e+009
1506.594;13.79517;16417.86;1696.516;7;7;0;43.44935;36.08118;1.50674e+007;2.433641e+009
1507.664;13.81285;16498.57;1704.855;7;7;0;43.50503;36.11999;1.514147e+007;2.446553e+009
1508.7;13.82999;16579.44;1713.212;7;7;0;43.55903;36.15761;1.521569e+007;2.459471e+009
1509.658;13.84622;16660.26;1721.563;7;7;0;43.61015;36.19322;1.528986e+007;2.47234e+009
1510.648;13.86272;16740.83;1729.889;7;7;0;43.66212;36.2294;1.536381e+007;2.485196e+009
1511.774;13.88126;16821.59;1738.235;7;7;0;43.7205;36.27003;1.543793e+007;2.4982e+009
1512.738;13.89754;16902.47;1746.593;7;7;0;43.77179;36.30571;1.551216e+007;2.511107e+009
1513.808;13.91522;16983.15;1754.929;7;7;0;43.82748;36.34443;1.55862e+007;2.52407e+009
1514.872;13.93301;17064.31;1763.316;7;7;0;43.8835;36.38337;1.566068e+007;2.53712e+009
1515.876;13.94978;17145.05;1771.659;7;7;0;43.93631;36.42007;1.573478e+007;2.55006e+009
1516.836;13.96574;17225.66;1779.988;7;7;0;43.98658;36.455;1.580875e+007;2.562944e+009
1517.888;13.98315;17306.22;1788.313;7;7;0;44.04142;36.49307;1.588269e+007;2.575911e+009
1518.812;13.99874;17387.13;1796.673;7;7;0;44.09052;36.52715;1.595694e+007;2.588836e+009
1519.814;14.01545;17468.11;1805.042;7;7;0;44.14317;36.56368;1.603127e+007;2.601845e+009
1520.848;14.0326;17548.92;1813.392;7;7;0;44.19716;36.60113;1.610543e+007;2.61486e+009
1521.834;14.04904;17629.97;1821.767;7;7;0;44.24896;36.63705;1.617981e+007;2.62788e+009
1522.836;14.06581;17710.69;1830.109;7;7;0;44.30177;36.67366;1.625389e+007;2.640879e+009
1523.74;14.08092;17791.53;1838.462;7;7;0;44.34935;36.70662;1.632808e+007;2.653808e+009
1524.694;14.09678;17872.38;1846.816;7;7;0;44.3993;36.74122;1.640228e+007;2.66679e+009
1525.598;14.11188;17953.18;1855.166;7;7;0;44.44688;36.77416;1.647644e+007;2.679729e+009
1526.546;14.12758;18034.2;1863.537;7;7;0;44.49632;36.80838;1.655079e+007;2.692743e+009
1527.416;14.14215;18115.24;1871.911;7;7;0;44.54221;36.84014;1.662516e+007;2.705702e+009
1528.368;14.15801;18196.56;1880.315;7;7;0;44.59216;36.87469;1.66998e+007;2.718788e+009
1529.204;14.17199;18277.42;1888.671;7;7;0;44.63619;36.90514;1.677401e+007;2.731701e+009
1530.154;14.18763;18358.33;1897.031;7;7;0;44.68546;36.93919;1.684826e+007;2.744728e+009
1531.028;14.20237;18439.34;1905.403;7;7;0;44.73186;36.97126;1.692261e+007;2.757725e+009
1531.978;14.21806;18520.5;1913.788;7;7;0;44.7813;37.00541;1.699708e+007;2.770808e+009
1532.848;14.23269;18601.41;1922.15;7;7;0;44.82736;37.03722;1.707135e+007;2.783799e+009
1533.814;14.2486;18682.2;1930.498;7;7;0;44.87747;37.07182;1.714549e+007;2.796857e+009
1534.672;14.26301;18763;1938.847;7;7;0;44.92287;37.10314;1.721964e+007;2.809833e+009
1535.598;14.27833;18844.08;1947.225;7;7;0;44.97112;37.13643;1.729405e+007;2.822914e+009
1536.492;14.29338;18924.82;1955.569;7;7;0;45.01853;37.16913;1.736815e+007;2.835937e+009
1537.378;14.30806;19005.68;1963.924;7;7;0;45.06476;37.20101;1.744236e+007;2.848962e+009
1538.236;14.32242;19086.53;1972.279;7;7;0;45.10998;37.23218;1.751656e+007;2.861973e+009
1539.162;14.33785;19167.72;1980.668;7;7;0;45.15858;37.26566;1.759107e+007;2.875109e+009
1540.002;14.35188;19248.61;1989.027;7;7;0;45.20278;37.29611;1.76653e+007;2.888122e+009
1540.834;14.36581;19329.5;1997.385;7;7;0;45.24665;37.32632;1.773954e+007;2.901135e+009
1541.78;14.38135;19410.02;2005.706;7;7;0;45.29559;37.36;1.781344e+007;2.914202e+009
1542.608;14.39533;19491.2;2014.095;7;7;0;45.33963;37.39031;1.788794e+007;2.927278e+009
1543.498;14.41006;19572.32;2022.478;7;7;0;45.38602;37.42222;1.796239e+007;2.9404e+009
1544.354;14.42442;19652.79;2030.792;7;7;0;45.43124;37.45332;1.803624e+007;2.953406e+009
1545.248;14.43931;19733.64;2039.147;7;7;0;45.47815;37.48557;1.811044e+007;2.966514e+009
1546.114;14.45372;19814.61;2047.514;7;7;0;45.52354;37.51676;1.818475e+007;2.979614e+009
1546.976;14.46824;19895.72;2055.895;7;7;0;45.56926;37.54818;1.825919e+007;2.992751e+009
1547.924;14.48383;19976.45;2064.238;7;7;0;45.61837;37.58191;1.833328e+007;3.005909e+009
1548.146;14.48758;20000.03;2066.674;7;7;0;45.63017;37.59002;1.835492e+007;3.0097e+009