File: Ensayos/Compresion/EspC/EspCu2.raw
"Test Type";"Manual"
"Method Name:";"C:\INSTRON\user\template\CYCLE.MTM"
"Name:";""
"Operator ID:";""
"Company:";""
"Lab name:";""
"Test date:";"04/05/2017"
"Temperature:";""
"Humidity:";""
"Note 1:";""
"Note 2:";""
"Note 3:";""
"Geometry:";"Rectangular"
"Specimen";1
"Specimen name:";""
"Width:";0.250000;"in"
"Thickness:";0.060000;"in"
"Length:";1.250000;"in"
"Diameter:";0.039370;"in"
"Inner diameter:";0.019685;"in"
"Outer diameter:";0.039370;"in"
"Wall thickness:";0.019685;"in"
"Area:";0.015000;"in*in"
"Linear density:";1.000000;"den"
"Sled weight:";2.204623;"lbf"
"Loading span:";0.000000;"mm"
"Support span:";1.000000;"mm"
"Span ratio:";"2"
"Fixture type:";"3-point"
"Comment:";""
"Included"
"Final Width:";0.250000;"in"
"Final Thickness:";0.060000;"in"
"Final Length:";1.250000;"in"
"Final Diameter:";0.039370;"in"
"Final Inner diameter:";0.019685;"in"
"Final Outer diameter:";0.039370;"in"
"Final Wall thickness:";0.019685;"in"
"Final Area:";0.015000;"in*in"
"Final Linear density:";1.000000;"den"
"Time sec";"Extension mm";"Load N";"Stress MPa";"Cycle Count ";"Total Cycle Count ";"Repetitions Count ";"Strain [Exten.] %";"True strain %";"Tenacity gf/tex";"True stress Pa"
0;14.48753;19457.2;2010.581;0;0;0;45.63;37.5899;1.785674e+007;2.92801e+009
0.242;14.49047;19520.56;2017.128;0;0;0;45.63928;37.59627;1.791488e+007;2.937731e+009
0.354;14.49267;19584.52;2023.738;0;0;0;45.6462;37.60102;1.797359e+007;2.947497e+009
0.466;14.49503;19648.11;2030.309;0;0;0;45.65363;37.60612;1.803195e+007;2.957219e+009
0.596;14.49728;19710.55;2036.761;0;0;0;45.66071;37.61099;1.808925e+007;2.96676e+009
0.7220001;14.49953;19773.93;2043.31;0;0;0;45.6678;37.61585;1.814742e+007;2.976445e+009
0.8660001;14.50188;19836.3;2049.755;0;0;0;45.67523;37.62095;1.820466e+007;2.985985e+009
1.016;14.50446;19898.3;2056.162;0;0;0;45.68332;37.62651;1.826156e+007;2.995485e+009
1.166;14.50697;19960.44;2062.583;0;0;0;45.69125;37.63195;1.831859e+007;3.005003e+009
1.38;14.51056;20022.07;2068.951;0;0;0;45.70256;37.63971;1.837515e+007;3.014515e+009
1.64;14.51485;20084.21;2075.372;0;0;0;45.71606;37.64897;1.843217e+007;3.024151e+009
1.964;14.52037;20145.44;2081.7;0;0;0;45.73344;37.6609;1.848837e+007;3.033733e+009
2.458;14.52862;20206.69;2088.028;0;0;0;45.75942;37.67873;1.854458e+007;3.043498e+009
3.066;14.53874;20267.49;2094.312;0;0;0;45.79131;37.7006;1.860038e+007;3.053324e+009
3.716;14.54962;20328.29;2100.594;0;0;0;45.82556;37.72409;1.865618e+007;3.063204e+009
4.368;14.56049;20388.88;2106.855;0;0;0;45.85981;37.74758;1.871178e+007;3.073055e+009
5.004;14.57104;20449.54;2113.123;0;0;0;45.89305;37.77037;1.876745e+007;3.0829e+009
5.658;14.58187;20510.17;2119.389;0;0;0;45.92714;37.79373;1.88231e+007;3.092763e+009
6.316;14.59285;20571.02;2125.676;0;0;0;45.96173;37.81743;1.887894e+007;3.102674e+009
6.98;14.60388;20631.47;2131.922;0;0;0;45.99648;37.84123;1.893442e+007;3.112532e+009
7.596;14.61417;20692.41;2138.22;0;0;0;46.02888;37.86342;1.899035e+007;3.122418e+009
8.21;14.62435;20753.14;2144.496;0;0;0;46.06094;37.88537;1.904609e+007;3.132271e+009
8.824;14.63463;20813.8;2150.763;0;0;0;46.09333;37.90755;1.910175e+007;3.142122e+009
9.468;14.64535;20874.75;2157.062;0;0;0;46.12708;37.93065;1.915769e+007;3.152051e+009
10.108;14.65595;20935.08;2163.296;0;0;0;46.16049;37.95351;1.921306e+007;3.161884e+009
10.736;14.6664;20995.58;2169.547;0;0;0;46.19339;37.97602;1.926858e+007;3.171735e+009
11.378;14.67706;21056.1;2175.801;0;0;0;46.22697;37.99898;1.932412e+007;3.181608e+009
12.022;14.68794;21116.81;2182.075;0;0;0;46.26122;38.0224;1.937984e+007;3.191529e+009
12.656;14.69854;21177.7;2188.367;0;0;0;46.29462;38.04524;1.943572e+007;3.201464e+009
13.264;14.70867;21238.25;2194.624;0;0;0;46.32652;38.06704;1.949129e+007;3.211317e+009
13.884;14.71901;21298.95;2200.896;0;0;0;46.35908;38.08929;1.9547e+007;3.221212e+009
14.528;14.72967;21360.18;2207.223;0;0;0;46.39266;38.11223;1.960319e+007;3.231213e+009
15.152;14.74022;21420.89;2213.496;0;0;0;46.4259;38.13493;1.965891e+007;3.241132e+009
15.806;14.75099;21481.44;2219.753;0;0;0;46.45981;38.15809;1.971448e+007;3.251046e+009
16.39;14.76085;21542.2;2226.031;0;0;0;46.49086;38.17929;1.977023e+007;3.260932e+009
17.044;14.77162;21602.91;2232.305;0;0;0;46.52477;38.20243;1.982595e+007;3.27088e+009
17.712;14.78271;21663.38;2238.554;0;0;0;46.5597;38.22627;1.988145e+007;3.280818e+009
18.322;14.79288;21724.23;2244.841;0;0;0;46.59176;38.24814;1.993729e+007;3.290752e+009
18.896;14.80247;21785.14;2251.136;0;0;0;46.62196;38.26874;1.99932e+007;3.300659e+009
19.51;14.8127;21845.9;2257.414;0;0;0;46.65419;38.29072;2.004896e+007;3.310592e+009
20.13;14.82304;21906.56;2263.682;0;0;0;46.68675;38.31292;2.010462e+007;3.320522e+009
20.718;14.8329;21967.29;2269.958;0;0;0;46.7178;38.33408;2.016036e+007;3.330432e+009
21.288;14.84244;22028.03;2276.235;0;0;0;46.74783;38.35455;2.021611e+007;3.340325e+009
21.886;14.85235;22088.72;2282.506;0;0;0;46.77905;38.37582;2.02718e+007;3.35024e+009
22.468;14.8621;22149.47;2288.783;0;0;0;46.80975;38.39674;2.032756e+007;3.360157e+009
23.064;14.87206;22210.04;2295.042;0;0;0;46.84114;38.41811;2.038315e+007;3.370067e+009
23.658;14.88187;22270.55;2301.295;0;0;0;46.87202;38.43914;2.043868e+007;3.379959e+009
24.24;14.8914;22331.41;2307.583;0;0;0;46.90205;38.45959;2.049453e+007;3.389887e+009
24.764;14.9003;22392.06;2313.851;0;0;0;46.93006;38.47865;2.055019e+007;3.399743e+009
25.336;14.90983;22453.01;2320.149;0;0;0;46.96009;38.49909;2.060613e+007;3.409693e+009
25.928;14.91969;22513.93;2326.444;0;0;0;46.99114;38.52021;2.066204e+007;3.419666e+009
26.472;14.92874;22574.7;2332.724;0;0;0;47.01966;38.53961;2.071781e+007;3.429563e+009
26.996;14.93763;22635.63;2339.02;0;0;0;47.04766;38.55866;2.077373e+007;3.439475e+009
27.562;14.94712;22696.46;2345.306;0;0;0;47.07753;38.57897;2.082955e+007;3.449418e+009
28.158;14.95697;22757.31;2351.594;0;0;0;47.10858;38.60007;2.08854e+007;3.459396e+009
28.748;14.96672;22817.89;2357.854;0;0;0;47.13929;38.62095;2.0941e+007;3.469329e+009
29.254;14.97524;22878.8;2364.148;0;0;0;47.16611;38.63918;2.09969e+007;3.479225e+009
29.84;14.98494;22939.5;2370.42;0;0;0;47.19665;38.65993;2.10526e+007;3.489179e+009
30.406;14.99437;23000.22;2376.694;0;0;0;47.22635;38.6801;2.110833e+007;3.49912e+009
30.994;15.00406;23060.92;2382.967;0;0;0;47.25689;38.70084;2.116403e+007;3.509082e+009
31.536;15.01301;23121.53;2389.23;0;0;0;47.28506;38.71997;2.121966e+007;3.518979e+009
32.026;15.02137;23182.48;2395.528;0;0;0;47.31139;38.73784;2.127559e+007;3.528885e+009
32.534;15.02988;23242.93;2401.774;0;0;0;47.33822;38.75606;2.133107e+007;3.538731e+009
33.068;15.03883;23303.32;2408.015;0;0;0;47.36639;38.77518;2.13865e+007;3.548604e+009
33.61;15.04778;23364.08;2414.293;0;0;0;47.39457;38.7943;2.144226e+007;3.558536e+009
34.128;15.05645;23425.08;2420.596;0;0;0;47.42191;38.81284;2.149824e+007;3.568489e+009
34.684;15.06556;23485.97;2426.888;0;0;0;47.45059;38.83229;2.155412e+007;3.578461e+009
35.184;15.07392;23546.24;2433.117;0;0;0;47.47691;38.85014;2.160944e+007;3.588285e+009
35.696;15.08254;23607.19;2439.415;0;0;0;47.50408;38.86856;2.166537e+007;3.598236e+009
36.198;15.09101;23667.85;2445.683;0;0;0;47.53074;38.88663;2.172104e+007;3.608133e+009
36.736;15.0999;23728.59;2451.959;0;0;0;47.55874;38.90562;2.177678e+007;3.61808e+009
37.212;15.10783;23789.56;2458.26;0;0;0;47.58372;38.92254;2.183274e+007;3.627991e+009
37.75;15.11678;23850.6;2464.567;0;0;0;47.61189;38.94163;2.188876e+007;3.637994e+009
38.262;15.12513;23911.35;2470.844;0;0;0;47.63822;38.95946;2.194451e+007;3.647911e+009
38.772;15.13376;23972.04;2477.116;0;0;0;47.66538;38.97786;2.200021e+007;3.657842e+009
39.258;15.14195;24033.05;2483.42;0;0;0;47.6912;38.99534;2.20562e+007;3.667792e+009
39.766;15.15037;24093.41;2489.658;0;0;0;47.71769;39.01327;2.21116e+007;3.677665e+009
40.268;15.15872;24154.26;2495.945;0;0;0;47.74401;39.03109;2.216744e+007;3.687609e+009
40.798;15.16745;24215.22;2502.244;0;0;0;47.77151;39.0497;2.222339e+007;3.697604e+009
41.288;15.1757;24275.64;2508.488;0;0;0;47.79749;39.06728;2.227883e+007;3.707482e+009
41.81;15.18444;24336.37;2514.763;0;0;0;47.825;39.08589;2.233457e+007;3.717449e+009
42.29;15.19247;24397.49;2521.079;0;0;0;47.85031;39.10301;2.239066e+007;3.727423e+009
42.822;15.20126;24458.38;2527.371;0;0;0;47.87798;39.12173;2.244655e+007;3.737425e+009
43.302;15.20935;24519.36;2533.672;0;0;0;47.90346;39.13896;2.250251e+007;3.747389e+009
43.854;15.21845;24579.94;2539.932;0;0;0;47.93214;39.15835;2.25581e+007;3.757376e+009
44.34;15.2266;24640.75;2546.216;0;0;0;47.95779;39.17568;2.261392e+007;3.767325e+009
44.83;15.23479;24701.68;2552.512;0;0;0;47.9836;39.19313;2.266984e+007;3.7773e+009
45.326;15.24315;24762.73;2558.821;0;0;0;48.00993;39.21091;2.272586e+007;3.787309e+009
45.838;15.25151;24823.46;2565.096;0;0;0;48.03625;39.2287;2.278159e+007;3.797271e+009
46.342;15.26003;24884.47;2571.4;0;0;0;48.06308;39.24682;2.283759e+007;3.807294e+009
46.886;15.26892;24945.39;2577.695;0;0;0;48.09108;39.26573;2.289349e+007;3.817336e+009
47.376;15.27722;25006.34;2583.994;0;0;0;48.11724;39.28339;2.294944e+007;3.827341e+009
47.842;15.28504;25067.32;2590.295;0;0;0;48.14187;39.30002;2.30054e+007;3.837312e+009
48.358;15.29356;25127.97;2596.562;0;0;0;48.1687;39.31813;2.306105e+007;3.847292e+009
48.836;15.30154;25188.57;2602.824;0;0;0;48.19384;39.3351;2.311667e+007;3.857224e+009
49.372;15.31044;25249.67;2609.138;0;0;0;48.22185;39.35399;2.317275e+007;3.867312e+009
49.884;15.31885;25310.22;2615.395;0;0;0;48.24834;39.37186;2.322832e+007;3.877279e+009
50.348;15.32672;25370.76;2621.651;0;0;0;48.27314;39.3886;2.328388e+007;3.887204e+009
50.732;15.33079;25379.34;2622.538;0;0;0;48.28596;39.39724;2.329176e+007;3.888855e+009
50.84;15.32887;25316.07;2615.999;0;0;0;48.27989;39.39315;2.323369e+007;3.879001e+009
50.938;15.32704;25252.15;2609.394;0;0;0;48.27415;39.38928;2.317502e+007;3.869057e+009
51.034;15.32512;25187.19;2602.682;0;0;0;48.26808;39.38518;2.311541e+007;3.858947e+009
51.138;15.32303;25122.92;2596.04;0;0;0;48.2615;39.38074;2.305642e+007;3.848928e+009
51.238;15.32115;25059.47;2589.484;0;0;0;48.25559;39.37676;2.29982e+007;3.839055e+009
51.346;15.31895;24996.64;2582.991;0;0;0;48.24868;39.37209;2.294053e+007;3.82925e+009
51.462;15.31703;24933.83;2576.501;0;0;0;48.2426;39.36799;2.288289e+007;3.819472e+009
51.586;15.31494;24870.67;2569.975;0;0;0;48.23602;39.36356;2.282492e+007;3.809628e+009
51.712;15.31269;24807.63;2563.46;0;0;0;48.22894;39.35878;2.276707e+007;3.79979e+009
51.838;15.31065;24743.61;2556.845;0;0;0;48.22252;39.35445;2.270832e+007;3.789821e+009
51.956;15.30846;24681.2;2550.395;0;0;0;48.21561;39.34978;2.265103e+007;3.780084e+009
52.094;15.30637;24617.73;2543.837;0;0;0;48.20903;39.34534;2.259279e+007;3.770196e+009
52.226;15.30417;24554.62;2537.315;0;0;0;48.20211;39.34067;2.253487e+007;3.760355e+009
52.348;15.30192;24492.41;2530.887;0;0;0;48.19502;39.33589;2.247778e+007;3.750649e+009
52.482;15.29983;24430.16;2524.455;0;0;0;48.18844;39.33145;2.242065e+007;3.740951e+009
52.604;15.29769;24366.79;2517.907;0;0;0;48.18169;39.3269;2.236249e+007;3.731077e+009
52.746;15.29544;24304.09;2511.428;0;0;0;48.1746;39.32211;2.230495e+007;3.721298e+009
52.88;15.29329;24242.14;2505.027;0;0;0;48.16786;39.31756;2.22481e+007;3.711644e+009
52.998;15.29115;24179.94;2498.599;0;0;0;48.16111;39.31301;2.219101e+007;3.701951e+009
53.136;15.28885;24117.16;2492.112;0;0;0;48.15385;39.30811;2.213339e+007;3.692159e+009
53.266;15.28676;24053.65;2485.549;0;0;0;48.14727;39.30367;2.207511e+007;3.682273e+009
53.406;15.28446;23989.33;2478.902;0;0;0;48.14001;39.29877;2.201608e+007;3.672246e+009
53.542;15.2821;23925.67;2472.324;0;0;0;48.13259;39.29376;2.195765e+007;3.662317e+009
53.676;15.27995;23862.42;2465.788;0;0;0;48.12584;39.2892;2.18996e+007;3.652469e+009
53.802;15.27765;23798.85;2459.219;0;0;0;48.11859;39.2843;2.184127e+007;3.642561e+009
53.942;15.27546;23736.67;2452.794;0;0;0;48.11167;39.27964;2.17842e+007;3.632874e+009
54.078;15.27331;23674.05;2446.324;0;0;0;48.10492;39.27508;2.172673e+007;3.623126e+009
54.202;15.27106;23611.04;2439.813;0;0;0;48.09783;39.27029;2.166891e+007;3.61331e+009
54.344;15.26876;23548.26;2433.325;0;0;0;48.09058;39.26539;2.161129e+007;3.603526e+009
54.47;15.26667;23485.14;2426.803;0;0;0;48.084;39.26095;2.155336e+007;3.593706e+009
54.608;15.26437;23422.26;2420.305;0;0;0;48.07674;39.25605;2.149565e+007;3.583909e+009
54.75;15.26206;23358.72;2413.739;0;0;0;48.06949;39.25115;2.143734e+007;3.574011e+009
54.88;15.25986;23294.87;2407.141;0;0;0;48.06256;39.24647;2.137874e+007;3.564075e+009
55.006;15.25756;23232.7;2400.717;0;0;0;48.05531;39.24158;2.132168e+007;3.554389e+009
55.148;15.25537;23168.74;2394.108;0;0;0;48.04839;39.2369;2.126298e+007;3.544438e+009
55.284;15.25322;23105.79;2387.604;0;0;0;48.04165;39.23235;2.120522e+007;3.534648e+009
55.41;15.25092;23043.49;2381.165;0;0;0;48.03439;39.22744;2.114804e+007;3.524944e+009
55.548;15.24872;22980.47;2374.653;0;0;0;48.02747;39.22277;2.10902e+007;3.515139e+009
55.67;15.24658;22917.92;2368.189;0;0;0;48.02072;39.21821;2.103279e+007;3.505411e+009
55.814;15.24428;22855.42;2361.731;0;0;0;48.01347;39.21331;2.097544e+007;3.49568e+009
55.954;15.24203;22792.54;2355.234;0;0;0;48.00638;39.20852;2.091773e+007;3.485897e+009
56.08;15.23983;22728.36;2348.602;0;0;0;47.99946;39.20385;2.085883e+007;3.475918e+009
56.218;15.23742;22664.6;2342.013;0;0;0;47.99187;39.19872;2.080031e+007;3.465989e+009
56.356;15.23528;22601.96;2335.541;0;0;0;47.98512;39.19416;2.074283e+007;3.456253e+009
56.492;15.23303;22539.1;2329.045;0;0;0;47.97803;39.18937;2.068513e+007;3.446474e+009
56.622;15.23067;22476.45;2322.572;0;0;0;47.97061;39.18435;2.062764e+007;3.436723e+009
56.764;15.22847;22412.65;2315.978;0;0;0;47.96369;39.17967;2.056909e+007;3.426807e+009
56.888;15.22628;22349.44;2309.446;0;0;0;47.95678;39.175;2.051107e+007;3.416982e+009
57.03;15.22397;22287.52;2303.049;0;0;0;47.94952;39.1701;2.045425e+007;3.407349e+009
57.17;15.22178;22224.89;2296.576;0;0;0;47.9426;39.16542;2.039677e+007;3.397615e+009
57.292;15.21963;22162.6;2290.14;0;0;0;47.93585;39.16086;2.033961e+007;3.387939e+009
57.434;15.21722;22099.92;2283.663;0;0;0;47.92826;39.15572;2.028209e+007;3.378183e+009
57.57;15.21503;22037.04;2277.165;0;0;0;47.92134;39.15105;2.022437e+007;3.368413e+009
57.706;15.21283;21975.2;2270.775;0;0;0;47.91442;39.14637;2.016762e+007;3.358803e+009
57.84;15.21042;21911.76;2264.22;0;0;0;47.90683;39.14124;2.01094e+007;3.348936e+009
57.976;15.20828;21849.77;2257.814;0;0;0;47.90008;39.13667;2.005251e+007;3.339309e+009
58.102;15.20597;21786.87;2251.315;0;0;0;47.89283;39.13177;1.999479e+007;3.329533e+009
58.244;15.20372;21724.83;2244.904;0;0;0;47.88574;39.12698;1.993785e+007;3.319892e+009
58.384;15.20153;21663.04;2238.519;0;0;0;47.87882;39.1223;1.988114e+007;3.310295e+009
58.51;15.19928;21599.53;2231.956;0;0;0;47.87174;39.11751;1.982285e+007;3.300431e+009
58.654;15.19687;21536.2;2225.411;0;0;0;47.86414;39.11237;1.976473e+007;3.290586e+009
58.788;15.19472;21474;2218.984;0;0;0;47.8574;39.10781;1.970765e+007;3.280932e+009
58.928;15.19242;21411.45;2212.521;0;0;0;47.85014;39.1029;1.965024e+007;3.271215e+009
59.064;15.19006;21348.72;2206.039;0;0;0;47.84272;39.09788;1.959268e+007;3.261468e+009
59.204;15.18781;21285.69;2199.526;0;0;0;47.83563;39.09308;1.953483e+007;3.251683e+009
59.328;15.18556;21223.68;2193.118;0;0;0;47.82854;39.08829;1.947792e+007;3.242055e+009
59.472;15.18326;21161.89;2186.733;0;0;0;47.82129;39.08338;1.942121e+007;3.232456e+009
59.614;15.18106;21099.29;2180.264;0;0;0;47.81437;39.0787;1.936376e+007;3.222744e+009
59.736;15.17881;21037.57;2173.887;0;0;0;47.80728;39.07391;1.930712e+007;3.213163e+009
59.878;15.17646;20974.99;2167.419;0;0;0;47.79986;39.06889;1.924968e+007;3.203443e+009
60.016;15.17426;20912.18;2160.93;0;0;0;47.79294;39.0642;1.919204e+007;3.193701e+009
60.156;15.17195;20850.23;2154.529;0;0;0;47.78569;39.0593;1.913519e+007;3.184085e+009
60.29;15.16954;20787.67;2148.064;0;0;0;47.77809;39.05416;1.907778e+007;3.174368e+009
60.43;15.16735;20725.53;2141.642;0;0;0;47.77117;39.04948;1.902074e+007;3.164729e+009
60.558;15.1651;20662.83;2135.163;0;0;0;47.76409;39.04468;1.89632e+007;3.155004e+009
60.706;15.16274;20599.59;2128.628;0;0;0;47.75666;39.03966;1.890516e+007;3.14519e+009
60.848;15.16049;20537.18;2122.18;0;0;0;47.74958;39.03486;1.884789e+007;3.135512e+009
60.974;15.15824;20473.75;2115.625;0;0;0;47.74249;39.03006;1.878968e+007;3.125677e+009
61.112;15.15583;20410.62;2109.102;0;0;0;47.7349;39.02493;1.873174e+007;3.115879e+009
61.254;15.15363;20348.34;2102.666;0;0;0;47.72798;39.02024;1.867458e+007;3.106226e+009
61.392;15.15138;20286.11;2096.235;0;0;0;47.72089;39.01544;1.861746e+007;3.096577e+009
61.528;15.14892;20221.78;2089.588;0;0;0;47.71313;39.01019;1.855843e+007;3.086595e+009
61.672;15.14667;20159.74;2083.177;0;0;0;47.70605;39.00539;1.850149e+007;3.076979e+009
61.8;15.14442;20097.24;2076.719;0;0;0;47.69896;39.00059;1.844414e+007;3.067293e+009
61.946;15.14206;20034.71;2070.258;0;0;0;47.69153;38.99557;1.838675e+007;3.057596e+009
62.09;15.13971;19972.05;2063.783;0;0;0;47.68411;38.99054;1.832924e+007;3.047879e+009
62.222;15.13751;19909.27;2057.295;0;0;0;47.67719;38.98586;1.827162e+007;3.038155e+009
62.356;15.1351;19847.38;2050.9;0;0;0;47.6696;38.98072;1.821482e+007;3.028555e+009
62.5;15.13285;19785.71;2044.528;0;0;0;47.66251;38.97592;1.815823e+007;3.019001e+009
62.646;15.13049;19721.75;2037.918;0;0;0;47.65509;38.97089;1.809953e+007;3.00909e+009
62.776;15.12813;19657.54;2031.284;0;0;0;47.64767;38.96586;1.80406e+007;2.999143e+009
62.924;15.12567;19593.87;2024.704;0;0;0;47.6399;38.9606;1.798217e+007;2.989271e+009
63.06;15.12347;19531.79;2018.288;0;0;0;47.63298;38.95592;1.792519e+007;2.97966e+009
63.204;15.12117;19469.26;2011.827;0;0;0;47.62573;38.951;1.786781e+007;2.969975e+009
63.346;15.11865;19405.45;2005.234;0;0;0;47.6178;38.94563;1.780925e+007;2.960082e+009
63.49;15.11635;19342.24;1998.702;0;0;0;47.61055;38.94072;1.775124e+007;2.950295e+009
63.618;15.11404;19280.2;1992.292;0;0;0;47.60329;38.9358;1.76943e+007;2.940688e+009
63.768;15.11169;19217.75;1985.839;0;0;0;47.59586;38.93077;1.763699e+007;2.931016e+009
63.914;15.10933;19155.05;1979.359;0;0;0;47.58844;38.92574;1.757944e+007;2.921305e+009
64.04401;15.10713;19093.03;1972.95;0;0;0;47.58152;38.92105;1.752252e+007;2.91171e+009
64.184;15.10462;19030.36;1966.474;0;0;0;47.57359;38.91568;1.746501e+007;2.901997e+009
64.33;15.10237;18967.97;1960.027;0;0;0;47.56651;38.91088;1.740775e+007;2.892343e+009
64.47401;15.10006;18906.36;1953.661;0;0;0;47.55925;38.90596;1.735121e+007;2.882808e+009
64.608;15.0976;18843.05;1947.119;0;0;0;47.55149;38.9007;1.72931e+007;2.873003e+009
64.756;15.09519;18780.6;1940.666;0;0;0;47.5439;38.89555;1.723579e+007;2.863334e+009
64.894;15.09294;18717.77;1934.173;0;0;0;47.53681;38.89075;1.717813e+007;2.853617e+009
65.04401;15.09053;18655;1927.687;0;0;0;47.52922;38.88561;1.712052e+007;2.843902e+009
65.186;15.08801;18592.76;1921.256;0;0;0;47.52129;38.88023;1.706341e+007;2.834262e+009
65.334;15.08565;18529.41;1914.71;0;0;0;47.51386;38.8752;1.700527e+007;2.824462e+009
65.468;15.08329;18466.1;1908.167;0;0;0;47.50644;38.87016;1.694716e+007;2.814669e+009
65.624;15.08078;18402.75;1901.621;0;0;0;47.49851;38.86479;1.688902e+007;2.804863e+009
65.774;15.07831;18340.15;1895.153;0;0;0;47.49075;38.85953;1.683158e+007;2.795175e+009
65.916;15.07596;18277.05;1888.632;0;0;0;47.48332;38.85449;1.677366e+007;2.785418e+009
66.054;15.07349;18213.62;1882.078;0;0;0;47.47556;38.84923;1.671545e+007;2.775605e+009
66.21001;15.07103;18151.26;1875.634;0;0;0;47.4678;38.84397;1.665822e+007;2.765956e+009
66.362;15.06856;18088.3;1869.128;0;0;0;47.46004;38.8387;1.660044e+007;2.756217e+009
66.498;15.06621;18026.13;1862.704;0;0;0;47.45262;38.83367;1.654338e+007;2.746605e+009
66.64201;15.06369;17963.37;1856.219;0;0;0;47.44468;38.82829;1.648579e+007;2.736896e+009
66.79801;15.06122;17900.92;1849.766;0;0;0;47.43692;38.82303;1.642848e+007;2.727238e+009
66.95001;15.05876;17837.81;1843.244;0;0;0;47.42916;38.81776;1.637055e+007;2.717479e+009
67.08601;15.05635;17774.82;1836.735;0;0;0;47.42157;38.81261;1.631274e+007;2.707743e+009
67.234;15.05383;17712.81;1830.327;0;0;0;47.41364;38.80723;1.625583e+007;2.698151e+009
67.382;15.05147;17650.88;1823.928;0;0;0;47.40621;38.80219;1.6199e+007;2.688583e+009
67.53201;15.04906;17587.98;1817.429;0;0;0;47.39862;38.79704;1.614128e+007;2.678865e+009
67.67001;15.0466;17524.97;1810.917;0;0;0;47.39086;38.79178;1.608345e+007;2.669126e+009
67.82201;15.04408;17463.4;1804.555;0;0;0;47.38293;38.7864;1.602694e+007;2.659605e+009
67.966;15.04178;17401.56;1798.164;0;0;0;47.37568;38.78148;1.597019e+007;2.650057e+009
68.118;15.03926;17339.27;1791.728;0;0;0;47.36774;38.77609;1.591302e+007;2.640429e+009
68.26;15.03674;17277.05;1785.298;0;0;0;47.35981;38.77071;1.585592e+007;2.630812e+009
68.414;15.03428;17214.23;1778.807;0;0;0;47.35205;38.76544;1.579827e+007;2.621109e+009
68.554;15.03192;17151.76;1772.352;0;0;0;47.34463;38.76041;1.574093e+007;2.611465e+009
68.71201;15.02935;17089.11;1765.878;0;0;0;47.33653;38.75491;1.568344e+007;2.601784e+009
68.858;15.02678;17027.15;1759.475;0;0;0;47.32843;38.74941;1.562657e+007;2.592207e+009
69.012;15.02437;16964.65;1753.018;0;0;0;47.32084;38.74426;1.556922e+007;2.58256e+009
69.152;15.02195;16901.49;1746.491;0;0;0;47.31324;38.7391;1.551125e+007;2.572812e+009
69.31001;15.01938;16839.07;1740.041;0;0;0;47.30515;38.73361;1.545397e+007;2.563169e+009
69.46201;15.01676;16775.94;1733.517;0;0;0;47.29688;38.72799;1.539603e+007;2.553417e+009
69.61401;15.01435;16713.72;1727.088;0;0;0;47.28929;38.72284;1.533893e+007;2.543815e+009
69.75601;15.01183;16650.52;1720.557;0;0;0;47.28136;38.71746;1.528092e+007;2.53406e+009
69.914;15.00931;16588.42;1714.14;0;0;0;47.27343;38.71207;1.522393e+007;2.524472e+009
70.066;15.00669;16526.62;1707.755;0;0;0;47.26516;38.70646;1.516722e+007;2.514927e+009
70.22;15.00422;16464.04;1701.288;0;0;0;47.25739;38.70118;1.510978e+007;2.505272e+009
70.36401;15.0017;16401.44;1694.819;0;0;0;47.24946;38.6958;1.505233e+007;2.495612e+009
70.526;14.99913;16339.5;1688.419;0;0;0;47.24136;38.6903;1.499549e+007;2.486051e+009
70.68201;14.99645;16276.97;1681.957;0;0;0;47.23293;38.68457;1.49381e+007;2.476394e+009
70.83801;14.99394;16214.13;1675.464;0;0;0;47.225;38.67918;1.488043e+007;2.466701e+009
70.984;14.99137;16151.62;1669.005;0;0;0;47.2169;38.67368;1.482307e+007;2.457057e+009
71.15;14.98869;16089.41;1662.576;0;0;0;47.20846;38.66795;1.476597e+007;2.447453e+009
71.306;14.98601;16026.94;1656.12;0;0;0;47.20003;38.66222;1.470863e+007;2.437809e+009
71.46201;14.98349;15965.03;1649.723;0;0;0;47.1921;38.65683;1.465182e+007;2.428262e+009
71.61;14.98097;15902.4;1643.251;0;0;0;47.18416;38.65144;1.459434e+007;2.418605e+009
71.776;14.97829;15839.82;1636.784;0;0;0;47.17573;38.64571;1.453691e+007;2.408949e+009
71.928;14.97562;15777.7;1630.366;0;0;0;47.16729;38.63998;1.44799e+007;2.399365e+009
72.08601;14.97304;15715.73;1623.962;0;0;0;47.15919;38.63448;1.442303e+007;2.389809e+009
72.234;14.97063;15654.77;1617.663;0;0;0;47.1516;38.62932;1.436708e+007;2.380417e+009
72.396;14.96796;15592.97;1611.277;0;0;0;47.14317;38.62359;1.431036e+007;2.370884e+009
72.54801;14.96528;15530.46;1604.817;0;0;0;47.13473;38.61785;1.425299e+007;2.361243e+009
72.71001;14.96265;15467.79;1598.341;0;0;0;47.12646;38.61223;1.419548e+007;2.351583e+009
72.86601;14.96008;15405.56;1591.911;0;0;0;47.11836;38.60673;1.413837e+007;2.341994e+009
73.028;14.95745;15342.97;1585.443;0;0;0;47.1101;38.60111;1.408093e+007;2.332347e+009
73.176;14.95483;15280.13;1578.95;0;0;0;47.10183;38.59549;1.402325e+007;2.322664e+009
73.34001;14.9521;15217.48;1572.476;0;0;0;47.09322;38.58964;1.396576e+007;2.313006e+009
73.5;14.94953;15155.41;1566.063;0;0;0;47.08512;38.58413;1.39088e+007;2.303445e+009
73.66;14.94695;15094.16;1559.733;0;0;0;47.07702;38.57862;1.385258e+007;2.294009e+009
73.806;14.94433;15032.02;1553.312;0;0;0;47.06876;38.573;1.379556e+007;2.284437e+009
73.96401;14.94165;14970.25;1546.929;0;0;0;47.06032;38.56726;1.373886e+007;2.274918e+009
74.13001;14.93903;14907.9;1540.486;0;0;0;47.05205;38.56164;1.368165e+007;2.265317e+009
74.288;14.93645;14846.56;1534.147;0;0;0;47.04395;38.55614;1.362535e+007;2.255871e+009
74.43201;14.93394;14784.62;1527.747;0;0;0;47.03602;38.55074;1.35685e+007;2.246338e+009
74.594;14.93115;14720.74;1521.146;0;0;0;47.02725;38.54477;1.350988e+007;2.236499e+009
74.762;14.92847;14658.12;1514.675;0;0;0;47.01881;38.53904;1.345241e+007;2.226858e+009
74.924;14.92585;14595.49;1508.203;0;0;0;47.01054;38.53341;1.339493e+007;2.217218e+009
75.07401;14.92328;14533.4;1501.788;0;0;0;47.00244;38.5279;1.333795e+007;2.207665e+009
75.22801;14.9206;14470.81;1495.32;0;0;0;46.99401;38.52216;1.32805e+007;2.19803e+009
75.396;14.91792;14408.7;1488.902;0;0;0;46.98557;38.51642;1.322351e+007;2.188471e+009
75.55801;14.91524;14346.48;1482.473;0;0;0;46.97713;38.51068;1.316641e+007;2.178896e+009
75.71201;14.91267;14283.66;1475.981;0;0;0;46.96904;38.50517;1.310875e+007;2.169235e+009
75.86401;14.90999;14220.73;1469.479;0;0;0;46.9606;38.49943;1.3051e+007;2.159555e+009
76.03401;14.90731;14158.75;1463.074;0;0;0;46.95217;38.4937;1.299412e+007;2.150019e+009
76.194;14.90458;14096.38;1456.629;0;0;0;46.94356;38.48784;1.293688e+007;2.140423e+009
76.356;14.90196;14033.9;1450.172;0;0;0;46.93529;38.48221;1.287953e+007;2.130815e+009
76.51;14.89928;13971.07;1443.68;0;0;0;46.92685;38.47647;1.282187e+007;2.121153e+009
76.68;14.8966;13909.42;1437.31;0;0;0;46.91842;38.47073;1.27653e+007;2.111673e+009
76.83601;14.89381;13846.91;1430.85;0;0;0;46.90965;38.46475;1.270793e+007;2.102057e+009
77.00201;14.89108;13784.56;1424.407;0;0;0;46.90104;38.4589;1.26507e+007;2.092469e+009
77.162;14.88851;13722.35;1417.979;0;0;0;46.89294;38.45339;1.259361e+007;2.082911e+009
77.332;14.88572;13659.39;1411.474;0;0;0;46.88417;38.44741;1.253584e+007;2.073231e+009
77.486;14.88299;13595.99;1404.922;0;0;0;46.87556;38.44155;1.247764e+007;2.063486e+009
77.65;14.88021;13534.38;1398.555;0;0;0;46.86679;38.43558;1.24211e+007;2.054013e+009
77.82401;14.87747;13472.33;1392.144;0;0;0;46.85818;38.42972;1.236416e+007;2.044477e+009
77.99201;14.87474;13410.64;1385.768;0;0;0;46.84958;38.42386;1.230754e+007;2.034995e+009
78.15401;14.87195;13347.1;1379.203;0;0;0;46.8408;38.41788;1.224923e+007;2.025233e+009
78.31201;14.86922;13284.93;1372.779;0;0;0;46.8322;38.41202;1.219217e+007;2.015681e+009
78.48801;14.86644;13223.28;1366.408;0;0;0;46.82342;38.40605;1.213559e+007;2.006207e+009
78.65401;14.86355;13160.63;1359.934;0;0;0;46.81432;38.39984;1.207809e+007;1.996578e+009
78.82601;14.8607;13097.91;1353.453;0;0;0;46.80537;38.39375;1.202053e+007;1.986942e+009
78.994;14.85797;13035.17;1346.971;0;0;0;46.79676;38.38789;1.196296e+007;1.977309e+009
79.16801;14.85513;12973.1;1340.557;0;0;0;46.78782;38.3818;1.1906e+007;1.967774e+009
79.32601;14.85235;12910.27;1334.063;0;0;0;46.77905;38.37582;1.184833e+007;1.958126e+009
79.498;14.8494;12847.27;1327.554;0;0;0;46.76977;38.3695;1.179051e+007;1.948448e+009
79.676;14.84656;12785.01;1321.12;0;0;0;46.76083;38.3634;1.173337e+007;1.938887e+009
79.846;14.84378;12723.81;1314.796;0;0;0;46.75205;38.35743;1.167721e+007;1.929491e+009
80.01401;14.84099;12661.64;1308.372;0;0;0;46.74328;38.35145;1.162015e+007;1.919948e+009
80.178;14.8382;12599.29;1301.929;0;0;0;46.7345;38.34547;1.156293e+007;1.910379e+009
80.358;14.83526;12537.34;1295.528;0;0;0;46.72522;38.33914;1.150608e+007;1.900866e+009
80.522;14.83242;12475.61;1289.149;0;0;0;46.71628;38.33305;1.144942e+007;1.891391e+009
80.69801;14.82942;12413.63;1282.744;0;0;0;46.70683;38.32661;1.139254e+007;1.881873e+009
80.87601;14.82663;12352.3;1276.407;0;0;0;46.69806;38.32063;1.133625e+007;1.872464e+009
81.05;14.82374;12291.35;1270.109;0;0;0;46.68895;38.31441;1.128032e+007;1.863109e+009
81.222;14.82085;12228.25;1263.589;0;0;0;46.67984;38.30821;1.122241e+007;1.85343e+009
81.39201;14.8179;12165.82;1257.137;0;0;0;46.67056;38.30188;1.116511e+007;1.84385e+009
81.578;14.81495;12104.06;1250.755;0;0;0;46.66127;38.29555;1.110843e+007;1.834373e+009
81.748;14.81195;12041.56;1244.297;0;0;0;46.65182;38.28911;1.105108e+007;1.824784e+009
81.93;14.8089;11979.39;1237.873;0;0;0;46.64221;38.28255;1.099403e+007;1.815245e+009
82.11401;14.80596;11917.43;1231.47;0;0;0;46.63293;38.27622;1.093716e+007;1.805741e+009
82.29401;14.80295;11855.17;1225.037;0;0;0;46.62348;38.26977;1.088002e+007;1.796192e+009
82.468;14.80006;11793.32;1218.646;0;0;0;46.61437;38.26356;1.082326e+007;1.78671e+009
82.64401;14.79711;11730.83;1212.188;0;0;0;46.60509;38.25723;1.07659e+007;1.777129e+009
82.828;14.79411;11669.59;1205.86;0;0;0;46.59564;38.25078;1.070971e+007;1.767739e+009
82.998;14.79112;11607.08;1199.4;0;0;0;46.58619;38.24434;1.065233e+007;1.758155e+009
83.18;14.78806;11544.38;1192.921;0;0;0;46.57657;38.23778;1.059479e+007;1.748543e+009
83.374;14.78496;11481.4;1186.414;0;0;0;46.56679;38.2311;1.0537e+007;1.738889e+009
83.554;14.78185;11419.1;1179.976;0;0;0;46.557;38.22443;1.047982e+007;1.729337e+009
83.73801;14.77879;11356.83;1173.541;0;0;0;46.54739;38.21786;1.042267e+007;1.719794e+009
83.924;14.77579;11294.7;1167.122;0;0;0;46.53794;38.21142;1.036565e+007;1.710276e+009
84.11201;14.77274;11233.04;1160.75;0;0;0;46.52832;38.20485;1.030907e+007;1.700828e+009
84.29;14.76974;11171.36;1154.376;0;0;0;46.51887;38.1984;1.025246e+007;1.691379e+009
84.466;14.76669;11109.63;1147.998;0;0;0;46.50925;38.19184;1.019581e+007;1.681923e+009
84.662;14.76358;11047.49;1141.576;0;0;0;46.49947;38.18516;1.013877e+007;1.672403e+009
84.83401;14.76053;10985.15;1135.134;0;0;0;46.48985;38.17859;1.008156e+007;1.662857e+009
85.01601;14.75742;10923.26;1128.739;0;0;0;46.48006;38.17191;1.002476e+007;1.653378e+009
85.21001;14.75437;10861.61;1122.369;0;0;0;46.47044;38.16535;9968188;1.643939e+009
85.39201;14.7512;10799.62;1115.963;0;0;0;46.46049;38.15855;9911294;1.634445e+009
85.58;14.7481;10737.6;1109.554;0;0;0;46.4507;38.15187;9854373;1.62495e+009
85.774;14.74499;10675.74;1103.162;0;0;0;46.44092;38.14519;9797602;1.61548e+009
85.96201;14.74183;10614.18;1096.801;0;0;0;46.43096;38.13839;9741107;1.606056e+009
86.15;14.73867;10552.01;1090.376;0;0;0;46.42101;38.13159;9684046;1.59654e+009
86.34001;14.73556;10490.16;1083.985;0;0;0;46.41122;38.12491;9627285;1.587076e+009
86.536;14.73235;10428.32;1077.595;0;0;0;46.4011;38.11799;9570532;1.577611e+009
86.718;14.72919;10366.38;1071.195;0;0;0;46.39114;38.11119;9513689;1.568134e+009
86.90601;14.72603;10303.62;1064.709;0;0;0;46.38118;38.10439;9456091;1.558534e+009
87.108;14.72276;10241.84;1058.325;0;0;0;46.37089;38.09736;9399390;1.54908e+009
87.28401;14.7197;10180.79;1052.017;0;0;0;46.36127;38.09079;9343362;1.539745e+009
87.47;14.71655;10119.25;1045.657;0;0;0;46.35132;38.08399;9286882;1.530333e+009
87.67001;14.71338;10057.42;1039.269;0;0;0;46.34137;38.07718;9230142;1.52088e+009
87.854;14.71017;9996.211;1032.944;0;0;0;46.33124;38.07026;9173969;1.51152e+009
88.04401;14.70701;9935.035;1026.622;0;0;0;46.32129;38.06346;9117825;1.502167e+009
88.24201;14.70385;9873.222;1020.235;0;0;0;46.31133;38.05666;9061096;1.492719e+009
88.43401;14.70058;9811.089;1013.815;0;0;0;46.30104;38.04962;9004074;1.483221e+009
88.62601;14.69737;9748.787;1007.377;0;0;0;46.29092;38.0427;8946897;1.473701e+009
88.82401;14.69415;9687.19;1001.012;0;0;0;46.28079;38.03578;8890367;1.464288e+009
89.02001;14.69088;9624.869;994.5718;0;0;0;46.2705;38.02875;8833172;1.454765e+009
89.20801;14.68772;9563.136;988.1926;0;0;0;46.26054;38.02194;8776516;1.445336e+009
89.40401;14.68446;9500.471;981.7173;0;0;0;46.25025;38.0149;8719006;1.435764e+009
89.604;14.68119;9438.426;975.306;0;0;0;46.23996;38.00787;8662065;1.426287e+009
89.788;14.67808;9377.155;968.9746;0;0;0;46.23018;38.00117;8605833;1.416933e+009
89.97601;14.67487;9315.243;962.577;0;0;0;46.22005;37.99425;8549014;1.407481e+009
90.176;14.67165;9254.139;956.2629;0;0;0;46.20992;37.98732;8492936;1.398151e+009
90.36;14.66844;9191.751;949.8162;0;0;0;46.1998;37.9804;8435680;1.388629e+009
90.55;14.66522;9130.035;943.4388;0;0;0;46.18968;37.97347;8379040;1.37921e+009
90.75401;14.66196;9068.584;937.0889;0;0;0;46.17939;37.96644;8322645;1.369831e+009
90.94;14.65874;9006.542;930.6779;0;0;0;46.16927;37.95951;8265706;1.360365e+009
91.136;14.65542;8944.147;924.2303;0;0;0;46.1588;37.95235;8208443;1.350844e+009
91.342;14.65215;8881.998;917.8083;0;0;0;46.14851;37.94531;8151406;1.341363e+009
91.53201;14.64888;8819.67;911.3677;0;0;0;46.13821;37.93827;8094205;1.331857e+009
91.72801;14.64556;8757.077;904.8998;0;0;0;46.12775;37.93111;8036760;1.32231e+009
91.93001;14.64235;8694.855;898.4702;0;0;0;46.11763;37.92418;7979657;1.312823e+009
92.12401;14.63903;8632.751;892.0527;0;0;0;46.10717;37.91702;7922661;1.303353e+009
92.318;14.63576;8570.34;885.6036;0;0;0;46.09688;37.90998;7865383;1.293839e+009
92.51601;14.63254;8508.075;879.1696;0;0;0;46.08675;37.90305;7808240;1.28435e+009
92.71001;14.62933;8445.937;872.7486;0;0;0;46.07663;37.89612;7751214;1.274882e+009
92.90201;14.62612;8383.774;866.3251;0;0;0;46.06651;37.88919;7694164;1.265411e+009
93.09801;14.6229;8322.307;859.9734;0;0;0;46.05638;37.88225;7637753;1.256046e+009
93.29801;14.61958;8259.975;853.5325;0;0;0;46.04592;37.87509;7580548;1.246549e+009
93.49201;14.61631;8197.439;847.0704;0;0;0;46.03563;37.86804;7523155;1.237025e+009
93.69;14.61304;8135.675;840.6882;0;0;0;46.02533;37.86099;7466472;1.227618e+009
93.89201;14.60972;8073.865;834.301;0;0;0;46.01487;37.85383;7409746;1.218204e+009
94.082;14.60651;8012.245;827.9336;0;0;0;46.00475;37.8469;7353194;1.208822e+009
94.27801;14.60324;7950.571;821.5606;0;0;0;45.99446;37.83985;7296594;1.199433e+009
94.484;14.59987;7888.979;815.1962;0;0;0;45.98383;37.83257;7240068;1.190055e+009
94.68001;14.59649;7826.477;808.7375;0;0;0;45.9732;37.82528;7182707;1.18054e+009
94.87801;14.59322;7764.771;802.3613;0;0;0;45.96291;37.81823;7126077;1.17115e+009
95.08601;14.58979;7702.776;795.9551;0;0;0;45.95211;37.81084;7069181;1.161713e+009
95.272;14.58663;7641.841;789.6584;0;0;0;45.94215;37.80401;7013258;1.152445e+009
95.47201;14.58326;7579.999;783.2681;0;0;0;45.93152;37.79673;6956503;1.143035e+009
95.68401;14.57983;7517.85;776.8461;0;0;0;45.92073;37.78933;6899467;1.133579e+009
95.87601;14.57656;7455.736;770.4276;0;0;0;45.91043;37.78228;6842462;1.124134e+009
96.07601;14.57319;7393.738;764.0212;0;0;0;45.8998;37.77499;6785564;1.114705e+009
96.29401;14.5697;7332.104;757.6523;0;0;0;45.88883;37.76747;6728999;1.10533e+009
96.48801;14.56633;7269.891;751.2235;0;0;0;45.8782;37.76019;6671903;1.095871e+009
96.69601;14.56285;7207.325;744.7584;0;0;0;45.86724;37.75267;6614484;1.086359e+009
96.914;14.55937;7145.42;738.3615;0;0;0;45.85627;37.74515;6557670;1.076947e+009
97.108;14.55604;7083.9;732.0045;0;0;0;45.84581;37.73798;6501211;1.067598e+009
97.314;14.55256;7021.862;725.5938;0;0;0;45.83484;37.73046;6444276;1.058169e+009
97.53401;14.54903;6960.397;719.2424;0;0;0;45.82371;37.72282;6387867;1.048826e+009
97.73;14.54565;6898.185;712.8139;0;0;0;45.81308;37.71553;6330772;1.039376e+009
97.938;14.54217;6836.202;706.409;0;0;0;45.80211;37.70801;6273888;1.029959e+009
98.15401;14.53869;6774.363;700.0189;0;0;0;45.79114;37.70049;6217135;1.020566e+009
98.35201;14.53531;6712.633;693.6401;0;0;0;45.78051;37.6932;6160483;1.011192e+009
98.56201;14.53183;6650.844;687.2553;0;0;0;45.76954;37.68567;6103777;1.001809e+009
98.77801;14.52829;6589.404;680.9064;0;0;0;45.75841;37.67803;6047390;9.924784e+008
98.982;14.52481;6527.965;674.5577;0;0;0;45.74744;37.67051;5991005;9.831506e+008
99.19;14.52138;6466.888;668.2465;0;0;0;45.73664;37.6631;5934952;9.738799e+008
99.40801;14.5178;6405.564;661.9096;0;0;0;45.72534;37.65534;5878672;9.6457e+008
99.61401;14.51426;6344.081;655.5564;0;0;0;45.7142;37.6477;5822247;9.552388e+008
99.82601;14.51078;6282.439;649.1867;0;0;0;45.70323;37.64017;5765675;9.45886e+008
100.04;14.50719;6221.526;642.8923;0;0;0;45.69193;37.63241;5709772;9.366422e+008
100.248;14.50371;6159.706;636.5042;0;0;0;45.68096;37.62489;5653037;9.272655e+008
100.464;14.50012;6097.492;630.0754;0;0;0;45.66965;37.61712;5595940;9.178287e+008
100.676;14.49653;6035.783;623.6989;0;0;0;45.65835;37.60936;5539307;9.084694e+008
100.884;14.49304;5973.915;617.3057;0;0;0;45.64738;37.60183;5482528;8.990897e+008
101.102;14.48951;5912.454;610.9548;0;0;0;45.63625;37.59419;5426123;8.897717e+008
101.312;14.48592;5850.113;604.5129;0;0;0;45.62494;37.58642;5368910;8.803216e+008
101.524;14.48233;5788.326;598.1282;0;0;0;45.61364;37.57866;5312206;8.709563e+008
101.746;14.47879;5726.765;591.7669;0;0;0;45.6025;37.57101;5255708;8.616275e+008
101.952;14.47521;5665.292;585.4147;0;0;0;45.5912;37.56325;5199291;8.523123e+008
102.168;14.47156;5603.749;579.0552;0;0;0;45.57972;37.55537;5142811;8.42987e+008
102.398;14.46792;5542.046;572.6793;0;0;0;45.56825;37.54749;5086183;8.336391e+008
102.608;14.46433;5479.647;566.2313;0;0;0;45.55695;37.53972;5028916;8.24189e+008
102.826;14.46069;5417.819;559.8424;0;0;0;45.54547;37.53184;4972174;8.148253e+008
103.058;14.45694;5355.72;553.4255;0;0;0;45.53366;37.52372;4915183;8.054204e+008
103.272;14.45329;5294.095;547.0576;0;0;0;45.52219;37.51584;4858628;7.960902e+008
103.494;14.44965;5231.689;540.6089;0;0;0;45.51071;37.50795;4801354;7.866439e+008
103.718;14.4459;5169.668;534.2001;0;0;0;45.4989;37.49984;4744435;7.772553e+008
103.934;14.44221;5108.021;527.8299;0;0;0;45.48726;37.49183;4687859;7.679253e+008
104.158;14.43856;5046.265;521.4484;0;0;0;45.47579;37.48395;4631183;7.585812e+008
104.374;14.43487;4984.702;515.0869;0;0;0;45.46415;37.47595;4574683;7.492667e+008
104.592;14.43117;4923.189;508.7306;0;0;0;45.4525;37.46794;4518231;7.399614e+008
104.82;14.42753;4861.734;502.3802;0;0;0;45.44103;37.46005;4461830;7.306669e+008
105.034;14.42388;4799.432;495.9423;0;0;0;45.42955;37.45216;4404653;7.212467e+008
105.256;14.42013;4737.567;489.5496;0;0;0;45.41774;37.44404;4347877;7.118919e+008
105.49;14.41644;4676.093;483.1972;0;0;0;45.4061;37.43603;4291459;7.025983e+008
105.704;14.41279;4614.134;476.7947;0;0;0;45.39463;37.42814;4234596;6.93234e+008
105.926;14.4091;4552.622;470.4385;0;0;0;45.38298;37.42013;4178144;6.839375e+008
106.148;14.4054;4491.412;464.1135;0;0;0;45.37135;37.41213;4121969;6.74688e+008
106.364;14.40171;4430.02;457.7696;0;0;0;45.3597;37.40412;4065627;6.654125e+008
106.592;14.39801;4367.762;451.3363;0;0;0;45.34806;37.39611;4008490;6.560086e+008
106.81;14.39426;4306.351;444.9905;0;0;0;45.33625;37.38798;3952130;6.467325e+008
107.028;14.39056;4244.549;438.6042;0;0;0;45.32461;37.37997;3895412;6.373999e+008
107.262;14.38687;4182.545;432.1971;0;0;0;45.31297;37.37196;3838508;6.280385e+008
107.478;14.38312;4120.185;425.7533;0;0;0;45.30116;37.36383;3781277;6.186244e+008
107.704;14.37937;4058.492;419.3783;0;0;0;45.28934;37.3557;3724659;6.09312e+008
107.942;14.37551;3997.252;413.0502;0;0;0;45.27719;37.34734;3668456;6.000677e+008
108.166;14.37176;3934.791;406.5959;0;0;0;45.26538;37.33921;3611134;5.906431e+008
108.394;14.36801;3873.862;400.2999;0;0;0;45.25357;37.33108;3555216;5.814499e+008
108.622;14.3641;3811.626;393.8688;0;0;0;45.24125;37.3226;3498099;5.7206e+008
108.844;14.36035;3750.43;387.5452;0;0;0;45.22944;37.31447;3441937;5.628297e+008
109.08;14.35654;3688.013;381.0955;0;0;0;45.21746;37.30622;3384655;5.534172e+008
109.298;14.35279;3626.314;374.7198;0;0;0;45.20565;37.29808;3328030;5.441144e+008
109.526;14.34894;3565.173;368.402;0;0;0;45.1935;37.28972;3271919;5.348957e+008
109.774;14.34503;3503.611;362.0406;0;0;0;45.18119;37.28123;3215420;5.256148e+008
110.004;14.34112;3441.799;355.6533;0;0;0;45.16887;37.27275;3158692;5.162978e+008
110.242;14.3372;3381.183;349.3896;0;0;0;45.15655;37.26426;3103062;5.071619e+008
110.48;14.33313;3319.388;343.0041;0;0;0;45.14373;37.25543;3046350;4.978489e+008
110.712;14.32917;3257.748;336.6346;0;0;0;45.13124;37.24683;2989781;4.88562e+008
110.962;14.3252;3196.58;330.314;0;0;0;45.11876;37.23822;2933645;4.793475e+008
111.196;14.32119;3134.827;323.9327;0;0;0;45.1061;37.2295;2876970;4.700462e+008
111.446;14.31712;3073.522;317.5979;0;0;0;45.09328;37.22067;2820709;4.608133e+008
111.692;14.31294;3012.089;311.2498;0;0;0;45.08012;37.2116;2764328;4.515616e+008
111.93;14.30887;2950.651;304.9012;0;0;0;45.0673;37.20275;2707944;4.423119e+008
112.186;14.30479;2889.279;298.5594;0;0;0;45.05447;37.19391;2651621;4.330739e+008
112.426;14.30072;2828.245;292.2526;0;0;0;45.04165;37.18507;2595607;4.23888e+008
112.68;14.29654;2766.964;285.9202;0;0;0;45.02848;37.176;2539366;4.146657e+008
112.928;14.29231;2706.152;279.6362;0;0;0;45.01516;37.16681;2483556;4.055149e+008
113.172;14.28819;2644.637;273.2797;0;0;0;45.00217;37.15785;2427102;3.962615e+008
113.442;14.28385;2583.151;266.9261;0;0;0;44.9885;37.14842;2370673;3.870121e+008
113.696;14.27956;2521.325;260.5375;0;0;0;44.975;37.13911;2313933;3.777142e+008
113.96;14.27522;2459.573;254.1564;0;0;0;44.96133;37.12969;2257260;3.684285e+008
114.21;14.27094;2397.979;247.7917;0;0;0;44.94783;37.12037;2200733;3.591687e+008
114.48;14.26649;2336.745;241.4642;0;0;0;44.93383;37.11071;2144536;3.499633e+008
114.748;14.26204;2275.111;235.0953;0;0;0;44.91983;37.10105;2087971;3.406996e+008
115.006;14.2576;2213.655;228.7448;0;0;0;44.90582;37.09138;2031570;3.314645e+008
115.292;14.2531;2152.018;222.3756;0;0;0;44.89165;37.0816;1975003;3.222037e+008
115.562;14.24844;2090.232;215.9911;0;0;0;44.87697;37.07147;1918299;3.129213e+008
115.838;14.24394;2028.859;209.6492;0;0;0;44.86279;37.06169;1861975;3.037037e+008
116.11;14.23933;1967.501;203.3088;0;0;0;44.84829;37.05167;1805663;2.944894e+008
116.394;14.23462;1905.654;196.918;0;0;0;44.83344;37.04142;1748904;2.852031e+008
116.662;14.23006;1844.352;190.5834;0;0;0;44.8191;37.03152;1692644;2.760011e+008
116.95;14.22535;1782.756;184.2184;0;0;0;44.80424;37.02126;1636114;2.667561e+008
117.226;14.22063;1721.248;177.8626;0;0;0;44.7894;37.01101;1579666;2.575262e+008
117.5;14.21608;1660.25;171.5596;0;0;0;44.77505;37.0011;1523686;2.483755e+008
117.796;14.21126;1598.544;165.1832;0;0;0;44.75987;36.99061;1467055;2.39119e+008
118.072;14.20649;1536.588;158.7811;0;0;0;44.74485;36.98024;1410196;2.298275e+008
118.372;14.20172;1475.708;152.4902;0;0;0;44.72984;36.96986;1354323;2.206988e+008
118.652;14.19685;1414.585;146.1741;0;0;0;44.71449;36.95925;1298228;2.115351e+008
118.952;14.19203;1353.423;139.854;0;0;0;44.6993;36.94876;1242097;2.023678e+008
119.238;14.1871;1292.451;133.5535;0;0;0;44.68377;36.93803;1186140;1.932302e+008
119.54;14.18222;1231.112;127.2152;0;0;0;44.66842;36.92742;1129847;1.840402e+008
119.834;14.17724;1170.68;120.9705;0;0;0;44.65273;36.91657;1074385;1.749871e+008
120.136;14.17226;1109.588;114.6576;0;0;0;44.63704;36.90572;1018318;1.658374e+008
120.44;14.16717;1047.985;108.292;0;0;0;44.62101;36.89464;961782.7;1.56613e+008
120.754;14.16197;986.6244;101.9514;0;0;0;44.60464;36.88332;905469.3;1.474264e+008
121.066;14.15672;925.1982;95.604;0;0;0;44.5881;36.87188;849095.7;1.38232e+008
121.39;14.15142;864.0056;89.28076;0;0;0;44.5714;36.86033;792936.5;1.290744e+008
121.714;14.14585;802.5338;82.92866;0;0;0;44.55385;36.84819;736521;1.198766e+008
122.06;14.14028;741.8531;76.6583;0;0;0;44.5363;36.83605;680831.6;1.107991e+008
122.39;14.1346;680.4569;70.31403;0;0;0;44.51842;36.82368;624485.7;1.016167e+008
122.746;14.12865;619.5722;64.02258;0;0;0;44.49969;36.81072;568609;9.251244e+007
123.118;14.12254;558.5725;57.71927;0;0;0;44.48045;36.7974;512626.9;8.339307e+007
123.49;14.11633;497.8165;51.44115;0;0;0;44.46088;36.78386;456868.4;7.431233e+007
123.886;14.10979;436.7769;45.13371;0;0;0;44.4403;36.76961;400849.7;6.519126e+007
124.28;14.10321;376.2117;38.87529;0;0;0;44.41954;36.75524;345266.3;5.614352e+007
124.704;14.09608;315.587;32.61072;0;0;0;44.3971;36.7397;289628.3;4.708894e+007
125.166;14.08837;254.5143;26.29987;0;0;0;44.37281;36.72287;233579.2;3.796986e+007
125.66;14.08022;193.9711;20.04372;0;0;0;44.34716;36.70511;178015.9;2.893253e+007
125.794;14.07787;178.1024;18.40395;0;0;0;44.33974;36.69996;163452.5;2.656421e+007