File: Ensayos/Compresion/EspC/EspC60error.raw
"Test Type";"Manual"
"Method Name:";"C:\INSTRON\user\template\Pablor.mtM"
"Name:";""
"Operator ID:";""
"Company:";""
"Lab name:";""
"Test date:";"31/03/2017"
"Temperature:";""
"Humidity:";""
"Note 1:";""
"Note 2:";""
"Note 3:";""
"Geometry:";"Rectangular"
"Specimen";1
"Specimen name:";""
"User Input 1:";"No definido"
"User Input 2:";"No definido"
"User Input 3:";"No definido"
"User Input 4:";"No definido"
"User Input 5:";"No definido"
"User Input 6:";"No definido"
"User Input 7:";"No definido"
"User Input 8:";"No definido"
"User Input 9:";"No definido"
"User Input 10:";"No definido"
"Width:";0.250000;"in"
"Thickness:";0.060000;"in"
"Length:";1.250000;"in"
"Diameter:";0.039370;"in"
"Inner diameter:";0.019685;"in"
"Outer diameter:";0.039370;"in"
"Wall thickness:";0.019685;"in"
"Area:";0.015000;"in*in"
"Linear density:";1.000000;"den"
"Sled weight:";2.204623;"lbf"
"Loading span:";0.000000;"mm"
"Support span:";1.000000;"mm"
"Span ratio:";"2"
"Fixture type:";"3-point"
"Comment:";""
"Included"
"Final Width:";0.250000;"in"
"Final Thickness:";0.060000;"in"
"Final Length:";1.250000;"in"
"Final Diameter:";0.039370;"in"
"Final Inner diameter:";0.019685;"in"
"Final Outer diameter:";0.039370;"in"
"Final Wall thickness:";0.019685;"in"
"Final Area:";0.015000;"in*in"
"Final Linear density:";1.000000;"den"
"Time sec";"Extension mm";"Strain 1 %";"Load N";"Stress MPa";"Cycle Count ";"Total Cycle Count ";"Repetitions Count ";"Strain [Exten.] %";"True strain %";"Tenacity gf/tex";"True stress Pa"
0;0;-5.614347e-005;53.33132;5.510913;0;0;0;0;0;48944.53;5510914
1;0.003374998;2.591856e-005;57.55353;5.94721;0;0;0;0.01062991;0.01062935;52819.45;5947843
2;0.006589282;8.57604e-005;64.59377;6.674704;0;0;0;0.02075364;0.02075149;59280.59;6676089
3;0.01007142;0.0001900035;78.33208;8.094331;0;0;0;0.03172101;0.03171599;71888.84;8096898
4;0.01339285;0.0003382559;93.65614;9.67782;0;0;0;0.0421822;0.04217331;85952.41;9681903
5;0.01660713;0.0004750652;109.7182;11.33757;0;0;0;0.05230593;0.05229225;100693.3;1.13435e+007
6;0.02008927;0.0006884499;127.6807;13.1937;0;0;0;0.0632733;0.06325329;117178.3;1.320204e+007
7;0.0234107;0.0008801631;145.3091;15.0153;0;0;0;0.07373448;0.07370731;133356.6;1.502638e+007
8;0.02667855;0.001042837;162.4421;16.78572;0;0;0;0.08402694;0.08399166;149080.4;1.679982e+007
9;0.03010712;0.001262061;181.3833;18.74298;0;0;0;0.09482559;0.09478066;166463.6;1.876075e+007
10;0.03342855;0.001427635;200.5742;20.72604;0;0;0;0.1052868;0.1052314;184075.9;2.074787e+007
11;0.03669641;0.001619858;220.3062;22.76502;0;0;0;0.1155792;0.1155125;202184.8;2.279133e+007
12;0.04012497;0.001814079;241.3246;24.93693;0;0;0;0.1263779;0.1262981;221474.3;2.496844e+007
13;0.0434464;0.002086992;262.125;27.0863;0;0;0;0.1368391;0.1367455;240563.8;2.712337e+007
14;0.04671425;0.002345013;283.5102;29.29611;0;0;0;0.1471315;0.1470234;260189.9;2.933921e+007
15;0.05014283;0.002479745;306.6761;31.68993;0;0;0;0.1579302;0.1578056;281450.3;3.173998e+007
16;0.05346425;0.002771038;329.1802;34.01535;0;0;0;0.1683913;0.1682497;302103.3;3.407263e+007
17;0.05673211;0.003050182;352.1121;36.38499;0;0;0;0.1786838;0.1785243;323148.9;3.645e+007
18;0.0601071;0.00333979;376.5333;38.90852;0;0;0;0.1893137;0.1891347;345561.4;3.898218e+007
19;0.06342853;0.003544631;400.9914;41.43587;0;0;0;0.1997749;0.1995756;368007.7;4.151864e+007
20;0.06669638;0.00380375;425.4694;43.96526;0;0;0;0.2100673;0.209847;390472.2;4.405761e+007
21;0.07012495;0.004002164;451.5432;46.65955;0;0;0;0.220866;0.2206224;414401.3;4.676261e+007
22;0.07344639;0.004275117;477.2158;49.3124;0;0;0;0.2313272;0.23106;437962.3;4.942647e+007
23;0.07666066;0.004559591;502.4465;51.91958;0;0;0;0.2414509;0.2411599;461117.6;5.204494e+007
24;0.08008924;0.00481816;530.0556;54.77252;0;0;0;0.2522496;0.251932;486455.6;5.491068e+007
25;0.08341066;0.005059056;556.5241;57.5076;0;0;0;0.2627108;0.2623663;510746.9;5.765868e+007
26;0.08662494;0.005252454;582.895;60.2326;0;0;0;0.2728345;0.2724629;534948.7;6.039694e+007
27;0.09005352;0.005633216;611.4706;63.18542;0;0;0;0.2836331;0.2832316;561173.9;6.336464e+007
28;0.09337494;0.005913614;639.1551;66.04616;0;0;0;0.2940943;0.2936627;586581.1;6.62404e+007
29;0.0966428;0.00605058;666.9892;68.92235;0;0;0;0.3043868;0.3039244;612125.7;6.913214e+007
30;0.1000178;0.006351239;696.4576;71.96743;0;0;0;0.3150167;0.3145215;639170.2;7.219414e+007
31;0.1032856;0.00667404;725.5065;74.96915;0;0;0;0.3253091;0.3247811;665829.7;7.521304e+007
32;0.1066606;0.006915053;755.5075;78.06927;0;0;0;0.335939;0.335376;693362.9;7.833153e+007
33;0.1099821;0.007225666;786.2874;81.24986;0;0;0;0.3464002;0.3458016;721611;8.153131e+007
34;0.1133035;0.007443988;816.656;84.38795;0;0;0;0.3568614;0.3562262;749481.6;8.46891e+007
35;0.1166249;0.007738064;848.0783;87.63493;0;0;0;0.3673226;0.3666496;778319.3;8.795684e+007
36;0.1199464;0.007959874;879.6835;90.90081;0;0;0;0.3777838;0.377072;807324.8;9.124422e+007
37;0.1232678;0.008318493;910.8837;94.12484;0;0;0;0.388245;0.3874932;835958.6;9.449027e+007
38;0.1266428;0.008548377;943.3706;97.48182;0;0;0;0.3988749;0.3980815;865773.3;9.787065e+007
39;0.1299106;0.008750985;974.5979;100.7086;0;0;0;0.4091673;0.4083325;894431.9;1.011207e+008
40;0.1332856;0.009107488;1006.807;104.037;0;0;0;0.4197972;0.4189185;923992.1;1.044737e+008
41;0.1366606;0.009366215;1039.994;107.4663;0;0;0;0.4304272;0.4295035;954448.8;1.079288e+008
42;0.1399285;0.009667109;1071.431;110.7147;0;0;0;0.4407196;0.4397513;983299.6;1.112026e+008
43;0.1433035;0.009888214;1104.471;114.1289;0;0;0;0.4513495;0.450334;1013622;1.14644e+008
44;0.1466785;0.01020349;1137.638;117.5562;0;0;0;0.4619794;0.4609156;1044061;1.180993e+008
45;0.1498928;0.01041072;1168.802;120.7764;0;0;0;0.4721032;0.4709923;1072661;1.213466e+008
46;0.1533213;0.01071726;1202.439;124.2523;0;0;0;0.4829018;0.4817396;1103532;1.248523e+008
47;0.1566963;0.01100056;1236.005;127.7208;0;0;0;0.4935318;0.4923179;1134337;1.283512e+008
48;0.1599106;0.01122158;1268.039;131.031;0;0;0;0.5036555;0.5023914;1163736;1.31691e+008
49;0.1633392;0.01160936;1302.827;134.6257;0;0;0;0.5144541;0.5131353;1195663;1.353183e+008
50;0.1667142;0.01184501;1336.857;138.1421;0;0;0;0.525084;0.5237103;1226893;1.388675e+008
51;0.1699285;0.01205192;1369.557;141.5212;0;0;0;0.5352077;0.5337806;1256904;1.422786e+008
52;0.1734106;0.01227287;1404.916;145.175;0;0;0;0.5461751;0.544689;1289354;1.459679e+008
53;0.176732;0.01263204;1438.616;148.6573;0;0;0;0.5566363;0.5550928;1320282;1.494848e+008
54;0.1799463;0.01286384;1471.663;152.0722;0;0;0;0.56676;0.56516;1350611;1.529341e+008
55;0.1834285;0.01308365;1506.717;155.6944;0;0;0;0.5777274;0.576065;1382782;1.565939e+008
56;0.1867499;0.01337424;1541.678;159.307;0;0;0;0.5881886;0.5864655;1414867;1.602441e+008
57;0.1900177;0.0135629;1574.791;162.7287;0;0;0;0.5984811;0.5966973;1445256;1.637026e+008
58;0.1933927;0.01378965;1610.002;166.3672;0;0;0;0.609111;0.6072634;1477571;1.673806e+008
59;0.1967677;0.01403685;1644.506;169.9326;0;0;0;0.6197408;0.6178284;1509236;1.709857e+008
59.686;0.1989106;0.01412256;1666.229;172.1774;0;0;0;0.6264901;0.6245357;1529173;1.73256e+008
"Specimen";2
"Specimen name:";""
"User Input 1:";"No definido"
"User Input 2:";"No definido"
"User Input 3:";"No definido"
"User Input 4:";"No definido"
"User Input 5:";"No definido"
"User Input 6:";"No definido"
"User Input 7:";"No definido"
"User Input 8:";"No definido"
"User Input 9:";"No definido"
"User Input 10:";"No definido"
"Width:";0.250000;"in"
"Thickness:";0.060000;"in"
"Length:";1.250000;"in"
"Diameter:";0.039370;"in"
"Inner diameter:";0.019685;"in"
"Outer diameter:";0.039370;"in"
"Wall thickness:";0.019685;"in"
"Area:";0.015000;"in*in"
"Linear density:";1.000000;"den"
"Sled weight:";2.204623;"lbf"
"Loading span:";0.000000;"mm"
"Support span:";1.000000;"mm"
"Span ratio:";"2"
"Fixture type:";"3-point"
"Comment:";""
"Included"
"Final Width:";0.250000;"in"
"Final Thickness:";0.060000;"in"
"Final Length:";1.250000;"in"
"Final Diameter:";0.039370;"in"
"Final Inner diameter:";0.019685;"in"
"Final Outer diameter:";0.039370;"in"
"Final Wall thickness:";0.019685;"in"
"Final Area:";0.015000;"in*in"
"Final Linear density:";1.000000;"den"
"Time sec";"Extension mm";"Strain 1 %";"Load N";"Stress MPa";"Cycle Count ";"Total Cycle Count ";"Repetitions Count ";"Strain [Exten.] %";"True strain %";"Tenacity gf/tex";"True stress Pa"
0;0;0.0006301414;54.83797;5.666601;0;0;0;0;0;50327.25;5666601
1;0.003374998;0.0006723873;56.75719;5.864922;0;0;0;0.01062991;0.01062935;52088.61;5865545
2;0.006589282;0.0008373342;60.50438;6.252131;0;0;0;0.02075364;0.02075149;55527.57;6253429
3;0.01001785;0.0009184949;68.04256;7.031078;0;0;0;0.03155228;0.03154731;62445.69;7033297
4;0.01339285;0.001006631;79.83527;8.24966;0;0;0;0.0421822;0.04217331;73268.38;8253141
5;0.0166607;0.001369209;94.1571;9.729587;0;0;0;0.05247466;0.05246089;86412.17;9734692
6;0.0200357;0.001542699;109.753;11.34117;0;0;0;0.06310457;0.06308466;100725.2;1.134832e+007
7;0.0234107;0.001841164;125.6785;12.9868;0;0;0;0.07373448;0.07370731;115340.8;1.299638e+007
8;0.02662498;0.00208735;142.6185;14.73727;0;0;0;0.08385822;0.08382308;130887.3;1.474963e+007
9;0.03005355;0.002373744;161.309;16.66863;0;0;0;0.09465685;0.09461209;148040.4;1.668441e+007
10;0.03342855;0.00267793;179.8154;18.58096;0;0;0;0.1052868;0.1052314;165024.6;1.860053e+007
11;0.03664283;0.003015505;199.3935;20.60404;0;0;0;0.1154105;0.1153439;182992.3;2.062782e+007
12;0.04012497;0.003368795;220.6232;22.79778;0;0;0;0.1263779;0.1262981;202475.8;2.282659e+007
13;0.0434464;0.003638769;241.8422;24.99041;0;0;0;0.1368391;0.1367455;221949.4;2.502461e+007
14;0.04666068;0.004003933;263.1011;27.18717;0;0;0;0.1469628;0.1468549;241459.6;2.722713e+007
15;0.05014283;0.004384185;286.7276;29.62858;0;0;0;0.1579302;0.1578056;263142.7;2.967537e+007
16;0.05341068;0.004725561;309.4286;31.97435;0;0;0;0.1682226;0.1680813;283976.4;3.202814e+007
17;0.05667854;0.005062157;332.79;34.38837;0;0;0;0.1785151;0.1783559;305416.3;3.444976e+007
18;0.06016067;0.005500683;358.0218;36.99567;0;0;0;0.1894824;0.1893031;328572.6;3.706577e+007
19;0.06342853;0.005855344;382.2341;39.49761;0;0;0;0.1997749;0.1995756;350793.3;3.957651e+007
20;0.06669638;0.00621851;406.9898;42.0557;0;0;0;0.2100673;0.209847;373512.7;4.214405e+007
21;0.07012495;0.006646063;433.0673;44.75038;0;0;0;0.220866;0.2206224;397445.2;4.484922e+007
22;0.07344639;0.007063153;458.8977;47.41952;0;0;0;0.2313272;0.23106;421150.9;4.752922e+007
23;0.07666066;0.007415033;484.6038;50.07583;0;0;0;0.2414509;0.2411599;444742.5;5.019674e+007
24;0.08008924;0.007783724;512.3657;52.94456;0;0;0;0.2522496;0.251932;470220.8;5.307811e+007
25;0.08341066;0.00816041;539.0594;55.70291;0;0;0;0.2627108;0.2623663;494718.8;5.584925e+007
26;0.08667852;0.00848419;565.9184;58.47836;0;0;0;0.2730032;0.2726312;519368.6;5.8638e+007
27;0.09005352;0.008992669;594.238;61.40472;0;0;0;0.2836331;0.2832316;545358.8;6.157888e+007
28;0.09337494;0.009340472;621.8063;64.25345;0;0;0;0.2940943;0.2936627;570659.4;6.444242e+007
29;0.0966428;0.009780645;649.0324;67.06682;0;0;0;0.3043868;0.3039244;595646;6.727096e+007
30;0.1000178;0.01025209;678.1384;70.07444;0;0;0;0.3150167;0.3145215;622357.8;7.029519e+007
31;0.1033392;0.01059644;706.5004;73.0052;0;0;0;0.3254779;0.3249493;648386.9;7.324281e+007
32;0.1066071;0.01101734;734.8897;75.93875;0;0;0;0.3357703;0.3352079;674441;7.619373e+007
33;0.1099821;0.01147024;764.697;79.01884;0;0;0;0.3464002;0.3458016;701796.5;7.929256e+007
34;0.1133035;0.0119063;793.8575;82.0321;0;0;0;0.3568614;0.3562262;728558.4;8.232484e+007
35;0.1166249;0.01232778;823.6774;85.1135;0;0;0;0.3673226;0.3666496;755925.4;8.542614e+007
36;0.1199464;0.01272818;854.118;88.25903;0;0;0;0.3777838;0.377072;783862.2;8.859246e+007
37;0.1232678;0.01311858;883.9983;91.34667;0;0;0;0.388245;0.3874932;811284.7;9.170132e+007
38;0.1266428;0.01356608;915.2834;94.57947;0;0;0;0.3988749;0.3980815;839996.4;9.495672e+007
39;0.1299642;0.01399732;946.0414;97.7578;0;0;0;0.4093361;0.4085006;868224.4;9.815796e+007
40;0.1332856;0.01431004;977.545;101.0132;0;0;0;0.4197972;0.4189185;897136.7;1.014372e+008
41;0.1366606;0.01486845;1009.776;104.3437;0;0;0;0.4304272;0.4295035;926716.2;1.047928e+008
42;0.1399285;0.0151862;1041.161;107.5868;0;0;0;0.4407196;0.4397513;955519.6;1.08061e+008
43;0.1432499;0.0155525;1073.407;110.919;0;0;0;0.4511808;0.4501661;985113.6;1.114194e+008
44;0.1466785;0.01598079;1105.916;114.2782;0;0;0;0.4619794;0.4609156;1014948;1.148061e+008
45;0.1499463;0.01635787;1137.363;117.5278;0;0;0;0.4722719;0.4711602;1043809;1.180828e+008
46;0.1533213;0.01678213;1169.782;120.8777;0;0;0;0.4829018;0.4817396;1073561;1.214614e+008
47;0.1566963;0.01713727;1202.321;124.2401;0;0;0;0.4935318;0.4923179;1103423;1.248532e+008
48;0.1599106;0.01777123;1233.568;127.469;0;0;0;0.5036555;0.5023914;1132101;1.28111e+008
49;0.1633392;0.01821152;1266.957;130.9191;0;0;0;0.5144541;0.5131353;1162743;1.315926e+008
50;0.1667142;0.01859059;1299.645;134.2969;0;0;0;0.525084;0.5237103;1192742;1.350021e+008
51;0.1699285;0.01893542;1331.035;137.5406;0;0;0;0.5352077;0.5337806;1221550;1.382767e+008
52;0.173357;0.01936137;1364.691;141.0183;0;0;0;0.5460064;0.5445212;1252438;1.417883e+008
53;0.176732;0.01983646;1398.241;144.4852;0;0;0;0.5566363;0.5550928;1283228;1.452895e+008
54;0.1799463;0.02016263;1429.709;147.7369;0;0;0;0.56676;0.56516;1312108;1.485742e+008
55;0.1833749;0.02061973;1464.23;151.304;0;0;0;0.5775586;0.5758972;1343789;1.521779e+008
56;0.1867499;0.02096867;1498.002;154.7938;0;0;0;0.5881886;0.5864655;1374783;1.557043e+008
57;0.1899642;0.02139571;1530.665;158.1691;0;0;0;0.5983123;0.5965295;1404760;1.591154e+008
58;0.1934463;0.0217568;1565.46;161.7646;0;0;0;0.6092797;0.6074311;1436693;1.627502e+008
59;0.1967677;0.02211189;1598.347;165.1628;0;0;0;0.6197408;0.6178284;1466874;1.661864e+008
60;0.199982;0.02250418;1630.918;168.5285;0;0;0;0.6298646;0.6278893;1496766;1.6959e+008
61;0.2034106;0.02290637;1665.356;172.0871;0;0;0;0.6406633;0.6386197;1528371;1.731896e+008
62;0.2067856;0.0232329;1697.887;175.4487;0;0;0;0.6512932;0.6491814;1558227;1.765914e+008
63;0.2099999;0.02360241;1729.283;178.6929;0;0;0;0.6614169;0.6592392;1587040;1.798748e+008
64;0.2134284;0.02397655;1762.544;182.1299;0;0;0;0.6722155;0.6699662;1617565;1.833542e+008
65;0.2168034;0.02441367;1795.249;185.5094;0;0;0;0.6828455;0.6805246;1647580;1.867761e+008
66;0.2200177;0.02478248;1826.511;188.7399;0;0;0;0.6929692;0.6905792;1676271;1.900478e+008
67;0.2234463;0.02520979;1860.416;192.2434;0;0;0;0.7037678;0.7013029;1707387;1.935963e+008
68;0.2267677;0.02560137;1892.832;195.593;0;0;0;0.714229;0.7116905;1737137;1.9699e+008
69;0.2300356;0.02600659;1925.08;198.9253;0;0;0;0.7245215;0.7219094;1766732;2.003666e+008
70;0.2334641;0.02637038;1959.337;202.4653;0;0;0;0.7353202;0.7326298;1798171;2.03954e+008
71;0.2367856;0.02674197;1992.6;205.9025;0;0;0;0.7457813;0.7430141;1828698;2.07438e+008
72;0.2399999;0.02717246;2025.007;209.2511;0;0;0;0.7559051;0.7530624;1858439;2.108329e+008
73;0.243482;0.02755032;2060.406;212.9091;0;0;0;0.7668724;0.7639469;1890927;2.145418e+008
74;0.2467498;0.02792846;2093.811;216.3609;0;0;0;0.7771649;0.7741605;1921584;2.180424e+008
75;0.2500177;0.02819432;2126.576;219.7466;0;0;0;0.7874572;0.784373;1951654;2.214771e+008
76;0.2534463;0.02865385;2161.649;223.3709;0;0;0;0.7982559;0.7950867;1983842;2.251539e+008
77;0.2567141;0.02900036;2194.872;226.8039;0;0;0;0.8085484;0.8052972;2014332;2.286378e+008
78;0.259982;0.02940765;2228.422;230.2708;0;0;0;0.8188408;0.8155065;2045122;2.321563e+008
79;0.263357;0.02976953;2263.445;233.8898;0;0;0;0.8294708;0.8260495;2077265;2.358298e+008
80;0.2666784;0.03013453;2297.397;237.3982;0;0;0;0.839932;0.8364242;2108424;2.393922e+008
81.00001;0.2699462;0.03043394;2331.164;240.8874;0;0;0;0.8502244;0.8466303;2139413;2.429355e+008
82.00001;0.2733213;0.030916;2366.466;244.5353;0;0;0;0.8608543;0.8571701;2171811;2.466404e+008
83.00001;0.2765891;0.03119225;2399.869;247.987;0;0;0;0.8711468;0.8673742;2202467;2.501473e+008
84.00001;0.2799641;0.03157748;2434.301;251.545;0;0;0;0.8817767;0.8779117;2234067;2.53763e+008
85.00001;0.2832855;0.03197956;2468.918;255.122;0;0;0;0.8922379;0.888281;2265836;2.573983e+008
86.00001;0.286607;0.0323359;2503.223;258.6669;0;0;0;0.9026991;0.8986491;2297319;2.610019e+008
87.00001;0.289982;0.03280026;2538.583;262.3208;0;0;0;0.913329;0.9091834;2329771;2.647166e+008
88.00001;0.2933034;0.03307043;2572.647;265.8408;0;0;0;0.9237901;0.9195493;2361033;2.682966e+008
89.00001;0.2966248;0.03343108;2607.355;269.4272;0;0;0;0.9342514;0.9299143;2392886;2.719443e+008
90.00001;0.2999998;0.03377399;2642.583;273.0674;0;0;0;0.9448813;0.9404452;2425216;2.756476e+008
91.00001;0.3032676;0.03412669;2676.439;276.5659;0;0;0;0.9551737;0.9506407;2456287;2.792076e+008
92.00001;0.3065891;0.03443664;2711.758;280.2156;0;0;0;0.9656349;0.9610025;2488702;2.829215e+008
93.00001;0.3100177;0.03482782;2747.754;283.9352;0;0;0;0.9764336;0.9716973;2521736;2.867076e+008
94.00001;0.3132319;0.03505492;2782.225;287.4972;0;0;0;0.9865573;0.9817226;2553372;2.903335e+008
95.00001;0.3166069;0.03542256;2817.92;291.1857;0;0;0;0.9971872;0.9922481;2586131;2.940893e+008
96.00001;0.3200355;0.0356428;2853.997;294.9136;0;0;0;1.007986;1.00294;2619241;2.978863e+008
97.00001;0.3232498;0.03591752;2888.72;298.5016;0;0;0;1.01811;1.012962;2651107;3.015407e+008
98.00001;0.3266783;0.03621132;2925.365;302.2884;0;0;0;1.028908;1.023651;2684738;3.053986e+008
99.00001;0.3300533;0.03634966;2961.882;306.0618;0;0;0;1.039538;1.034172;2718251;3.092434e+008
100;0.3332676;0.03661038;2996.673;309.6569;0;0;0;1.049662;1.044191;2750181;3.129072e+008
101;0.3366426;0.03673022;3033.921;313.5059;0;0;0;1.060292;1.05471;2784365;3.168299e+008
102;0.3400712;0.03700008;3070.898;317.3267;0;0;0;1.07109;1.065395;2818300;3.207256e+008
103;0.3432855;0.03714629;3105.39;320.891;0;0;0;1.081214;1.075411;2849955;3.243605e+008
104;0.3467141;0.03732244;3143.187;324.7966;0;0;0;1.092013;1.086093;2884643;3.283434e+008
105;0.3500891;0.03749605;3180.326;328.6343;0;0;0;1.102643;1.096608;2918727;3.32258e+008
106;0.3533034;0.03745396;3216.687;332.3917;0;0;0;1.112767;1.106621;2952098;3.360904e+008
107;0.3567319;0.03758572;3255.33;336.3847;0;0;0;1.123565;1.1173;2987561;3.401642e+008
108;0.3600533;0.03754657;3293.328;340.3112;0;0;0;1.134026;1.127644;3022434;3.441705e+008
109;0.3633212;0.03760418;3330.094;344.1104;0;0;0;1.144319;1.137821;3056176;3.480482e+008
110;0.3667497;0.03749903;3369.165;348.1478;0;0;0;1.155117;1.148497;3092033;3.521693e+008
111;0.3701248;0.0375394;3406.459;352.0015;0;0;0;1.165747;1.159005;3126260;3.561049e+008
112;0.3733926;0.03740137;3443.554;355.8346;0;0;0;1.17604;1.169178;3160303;3.600194e+008
113;0.3767676;0.03732174;3482.116;359.8194;0;0;0;1.18667;1.179684;3195693;3.640892e+008
114;0.380089;0.03722851;3520.676;363.804;0;0;0;1.197131;1.190022;3231082;3.681592e+008
115;0.3833569;0.03708163;3557.145;367.5724;0;0;0;1.207423;1.200192;3264550;3.720105e+008
116;0.3867855;0.03684943;3597.05;371.6959;0;0;0;1.218222;1.210861;3301173;3.76224e+008
117;0.3901069;0.03662602;3634.418;375.5573;0;0;0;1.228683;1.221196;3335468;3.801717e+008
118;0.3933748;0.03648141;3670.927;379.3299;0;0;0;1.238976;1.231363;3368973;3.840297e+008
119;0.3968033;0.0362317;3710.628;383.4323;0;0;0;1.249774;1.242029;3405409;3.882244e+008
120;0.4001247;0.0359589;3748.835;387.3804;0;0;0;1.260235;1.252361;3440474;3.922623e+008
121;0.403339;0.03572408;3786.371;391.2591;0;0;0;1.270359;1.262358;3474922;3.962295e+008
122;0.4068212;0.0353655;3827.078;395.4655;0;0;0;1.281327;1.273187;3512280;4.005327e+008
123;0.410089;0.03502126;3864.745;399.3578;0;0;0;1.291619;1.283349;3546849;4.04516e+008
124;0.4133033;0.03462133;3902.3;403.2385;0;0;0;1.301743;1.293343;3581315;4.084876e+008
125;0.4167854;0.03419182;3942.104;407.3515;0;0;0;1.31271;1.304169;3617845;4.126989e+008
126;0.4200533;0.03379154;3980.266;411.295;0;0;0;1.323002;1.314327;3652868;4.167364e+008
127;0.4233212;0.03342254;4017.506;415.1431;0;0;0;1.333295;1.324485;3687045;4.206782e+008
128;0.4267497;0.03286143;4057.155;419.2401;0;0;0;1.344094;1.335141;3723432;4.248751e+008
129;0.4300176;0.03245516;4095.282;423.18;0;0;0;1.354386;1.345296;3758423;4.289114e+008
130;0.4332855;0.03194092;4132.741;427.0508;0;0;0;1.364679;1.355451;3792801;4.328787e+008
131;0.4366604;0.0315473;4172.353;431.144;0;0;0;1.375309;1.365937;3829154;4.370735e+008
132;0.4399818;0.03094716;4210.892;435.1264;0;0;0;1.38577;1.376256;3864524;4.411562e+008
133;0.4433033;0.03043798;4250.471;439.2162;0;0;0;1.396231;1.386573;3900847;4.453487e+008
134;0.4466247;0.02979892;4289.972;443.298;0;0;0;1.406692;1.39689;3937099;4.495339e+008
135;0.4499461;0.02926701;4329.438;447.3762;0;0;0;1.417153;1.407205;3973318;4.537162e+008
136;0.4533211;0.02857908;4369.272;451.4924;0;0;0;1.427783;1.417686;4009876;4.579387e+008
137;0.456589;0.02794715;4408.568;455.5529;0;0;0;1.438076;1.427833;4045940;4.621041e+008
138;0.459964;0.02720178;4448.287;459.6573;0;0;0;1.448705;1.438312;4082392;4.663163e+008
139;0.463339;0.02643955;4488.611;463.8241;0;0;0;1.459335;1.44879;4119399;4.705928e+008
140;0.4666069;0.02557398;4527.467;467.8392;0;0;0;1.469628;1.458934;4155059;4.747147e+008
141;0.4699283;0.02468732;4567.171;471.942;0;0;0;1.480089;1.469243;4191497;4.789271e+008
142;0.4733033;0.02369517;4607.858;476.1462;0;0;0;1.490719;1.479717;4228837;4.832442e+008
143;0.4765711;0.02277211;4646.696;480.1595;0;0;0;1.501011;1.489858;4264480;4.873668e+008
144;0.4799461;0.02172894;4686.498;484.2725;0;0;0;1.511641;1.50033;4301009;4.915929e+008
145;0.4833747;0.02064759;4726.878;488.4451;0;0;0;1.52244;1.510967;4338067;4.958814e+008
146;0.486589;0.01956346;4765.534;492.4395;0;0;0;1.532564;1.520939;4373543;4.999864e+008
147;0.489964;0.01840762;4805.62;496.5817;0;0;0;1.543194;1.531407;4410332;5.042449e+008
148;0.4933925;0.01730613;4846.099;500.7646;0;0;0;1.553992;1.542041;4447482;5.085465e+008
149;0.4966068;0.01611572;4883.785;504.6588;0;0;0;1.564116;1.55201;4482068;5.125523e+008
150;0.5000353;0.01484458;4924.173;508.8322;0;0;0;1.574914;1.562641;4519133;5.168459e+008
151;0.5034104;0.01348229;4964.524;513.0018;0;0;0;1.585544;1.573106;4556165;5.211357e+008
152;0.5066246;0.01235952;5002.724;516.9492;0;0;0;1.595668;1.583071;4591223;5.25198e+008
153;0.5099996;0.01100589;5043.546;521.1675;0;0;0;1.606298;1.593534;4628688;5.29539e+008
154;0.5133747;0.009507849;5084.206;525.369;0;0;0;1.616928;1.603995;4666003;5.338639e+008
155;0.5166425;0.008217704;5122.513;529.3274;0;0;0;1.627221;1.614123;4701159;5.379407e+008
156;0.5200175;0.006696735;5163.434;533.5559;0;0;0;1.637851;1.624582;4738714;5.422947e+008
157;0.5234461;0.005130973;5204.32;537.7808;0;0;0;1.648649;1.635206;4776236;5.466469e+008
158;0.5266604;0.003739446;5242.737;541.7505;0;0;0;1.658773;1.645165;4811494;5.50737e+008
159;0.5300889;0.002095423;5284.508;546.067;0;0;0;1.669571;1.655787;4849829;5.551839e+008
160;0.5334103;0.0005650482;5324.576;550.2073;0;0;0;1.680033;1.666076;4886602;5.59451e+008
161;0.5366782;-0.001034025;5363.61;554.2408;0;0;0;1.690325;1.676198;4922424;5.636093e+008
162;0.5401068;-0.002727191;5405.19;558.5374;0;0;0;1.701124;1.686817;4960584;5.680388e+008
163;0.5434283;-0.004332417;5444.914;562.6422;0;0;0;1.711585;1.697102;4997040;5.722723e+008
164;0.5466961;-0.006005832;5483.889;566.6697;0;0;0;1.721877;1.707221;5032810;5.76427e+008
165;0.5501246;-0.007794306;5525.781;570.9985;0;0;0;1.732676;1.717836;5071256;5.80892e+008
166;0.5534461;-0.009506792;5565.763;575.13;0;0;0;1.743137;1.728119;5107949;5.851553e+008
167;0.5567139;-0.0112899;5604.639;579.1472;0;0;0;1.75343;1.738234;5143628;5.893022e+008
168;0.5601425;-0.01311811;5646.879;583.512;0;0;0;1.764228;1.748847;5182393;5.938065e+008
169;0.5634639;-0.01500891;5686.509;587.6071;0;0;0;1.774689;1.759126;5218763;5.980353e+008
170;0.5666782;-0.01690299;5725.628;591.6494;0;0;0;1.784813;1.769072;5254664;6.022092e+008
171;0.5701603;-0.01889094;5768.26;596.0547;0;0;0;1.795781;1.779847;5293790;6.067586e+008
172;0.5734282;-0.02084934;5807.488;600.1083;0;0;0;1.806073;1.789957;5329791;6.109467e+008
173;0.5766961;-0.0226935;5846.808;604.1714;0;0;0;1.816366;1.800067;5365877;6.151453e+008
174;0.5801246;-0.024788;5888.562;608.486;0;0;0;1.827164;1.810672;5404196;6.19604e+008
175;0.5833925;-0.02687486;5928.158;612.5775;0;0;0;1.837457;1.820779;5440535;6.238334e+008
176;0.5866604;-0.02900844;5967.522;616.6451;0;0;0;1.847749;1.830886;5476661;6.280392e+008
177;0.5900889;-0.03116235;6009.494;620.9823;0;0;0;1.858548;1.841488;5515181;6.325236e+008
178;0.5934103;-0.03334103;6050.241;625.1928;0;0;0;1.869009;1.851758;5552576;6.368777e+008
179;0.5966246;-0.03553358;6088.896;629.1872;0;0;0;1.879133;1.861695;5588052;6.410105e+008
180;0.6000532;-0.03787165;6130.672;633.504;0;0;0;1.889931;1.872294;5626391;6.454768e+008
181;0.603321;-0.04031889;6170.501;637.6198;0;0;0;1.900224;1.882395;5662945;6.49736e+008
182;0.6066425;-0.04271887;6210.924;641.7968;0;0;0;1.910685;1.892661;5700042;6.540595e+008
183;0.6100175;-0.04517497;6252.539;646.097;0;0;0;1.921315;1.903091;5738234;6.585105e+008
184;0.6132853;-0.04766975;6292.581;650.2347;0;0;0;1.931607;1.913189;5774983;6.627947e+008
185;0.6166067;-0.05036949;6333.369;654.4495;0;0;0;1.942068;1.923451;5812416;6.671593e+008
186;0.6199817;-0.05295276;6374.044;658.6525;0;0;0;1.952698;1.933878;5849745;6.71514e+008
187;0.6232496;-0.0556021;6413.922;662.7733;0;0;0;1.962991;1.943973;5886343;6.757835e+008
188;0.6266246;-0.0582978;6455.484;667.0681;0;0;0;1.973621;1.954397;5924486;6.802334e+008
189;0.629946;-0.06100894;6495.47;671.1999;0;0;0;1.984082;1.964656;5961183;6.84517e+008
190;0.6332674;-0.06382551;6535.31;675.3167;0;0;0;1.994543;1.974913;5997745;6.887862e+008
191;0.6366424;-0.0666028;6577.281;679.6537;0;0;0;2.005173;1.985334;6036264;6.932819e+008
192;0.6399639;-0.0694212;6616.184;683.6737;0;0;0;2.015634;1.995589;6071967;6.974541e+008
193;0.6432852;-0.0723346;6657.248;687.917;0;0;0;2.026095;2.005843;6109654;7.018549e+008
194;0.6466603;-0.07529181;6699.016;692.233;0;0;0;2.036725;2.016261;6147986;7.063319e+008
195;0.6499282;-0.0781835;6738.634;696.3268;0;0;0;2.047018;2.026348;6184345;7.105808e+008
196;0.6533031;-0.08121635;6779.598;700.5599;0;0;0;2.057648;2.036764;6221940;7.149749e+008
197;0.6567317;-0.08437949;6820.82;704.8195;0;0;0;2.068446;2.047344;6259771;7.193983e+008
198;0.6598925;-0.08733663;6858.875;708.7518;0;0;0;2.078402;2.057097;6294696;7.234826e+008
199;0.663321;-0.09048791;6900.556;713.0589;0;0;0;2.0892;2.067675;6332948;7.279561e+008
200;0.666696;-0.09365364;6941.255;717.2645;0;0;0;2.09983;2.078087;6370300;7.323258e+008
201;0.6699103;-0.09669436;6979.934;721.2612;0;0;0;2.109954;2.088002;6405796;7.364795e+008
202;0.6733389;-0.09998778;7021.548;725.5613;0;0;0;2.120752;2.098577;6443988;7.409487e+008
203;0.6767139;-0.1032476;7061.698;729.7102;0;0;0;2.131382;2.108986;6480835;7.452631e+008
204;0.6799281;-0.1064472;7100.382;733.7076;0;0;0;2.141506;2.118898;6516337;7.4942e+008
205;0.6834103;-0.1098295;7141.45;737.9513;0;0;0;2.152473;2.129635;6554027;7.538355e+008
206;0.6867317;-0.1131556;7181.438;742.0834;0;0;0;2.162935;2.139875;6590726;7.581341e+008
207;0.689946;-0.1164615;7219.83;746.0506;0;0;0;2.173058;2.149784;6625960;7.622627e+008
208;0.6934282;-0.1200232;7261.227;750.3282;0;0;0;2.184026;2.160518;6663952;7.667156e+008
209;0.6967496;-0.1235746;7300.372;754.3732;0;0;0;2.194487;2.170755;6699877;7.709279e+008
210;0.7000174;-0.12686;7339.114;758.3766;0;0;0;2.204779;2.180825;6735432;7.750972e+008
211;0.703446;-0.1305611;7379.458;762.5455;0;0;0;2.215578;2.191391;6772457;7.794403e+008
212;0.7067674;-0.1340812;7418.853;766.6163;0;0;0;2.226039;2.201624;6808612;7.836815e+008
213;0.7100352;-0.1377098;7457.232;770.5822;0;0;0;2.236331;2.211692;6843834;7.878149e+008
214;0.7134638;-0.1413985;7497.471;774.7402;0;0;0;2.24713;2.222254;6880764;7.921497e+008
215;0.7167852;-0.1449904;7536.025;778.7241;0;0;0;2.257591;2.232485;6916146;7.963045e+008
216;0.7199995;-0.1485148;7573.149;782.5603;0;0;0;2.267715;2.242385;6950217;8.003066e+008
217;0.7234281;-0.1523277;7612.752;786.6526;0;0;0;2.278514;2.252943;6986562;8.045766e+008
218;0.726803;-0.1560676;7651.067;790.6119;0;0;0;2.289144;2.263336;7021726;8.087101e+008
219;0.7300173;-0.1596032;7687.245;794.3502;0;0;0;2.299267;2.273232;7054928;8.126145e+008
220;0.7334995;-0.163499;7727.487;798.5086;0;0;0;2.310235;2.283953;7091860;8.16956e+008
221;0.7367674;-0.1672208;7764.487;802.332;0;0;0;2.320527;2.294012;7125816;8.209503e+008
222;0.7399816;-0.1709256;7800.56;806.0595;0;0;0;2.330651;2.303906;7158922;8.248459e+008
223;0.7434638;-0.1748133;7840.324;810.1685;0;0;0;2.341618;2.314623;7195415;8.291395e+008
224;0.7467317;-0.1786321;7876.846;813.9424;0;0;0;2.351911;2.32468;7228933;8.330856e+008
225;0.7499995;-0.182499;7912.678;817.6451;0;0;0;2.362203;2.334735;7261818;8.369595e+008
226;0.753428;-0.186507;7951.805;821.6881;0;0;0;2.373002;2.345284;7297726;8.411868e+008
227;0.756696;-0.1903407;7988.366;825.4661;0;0;0;2.383294;2.355337;7331280;8.451394e+008
228;0.7599638;-0.1943424;8024.414;829.1911;0;0;0;2.393587;2.36539;7364363;8.490385e+008
229;0.7633923;-0.1985029;8063.169;833.1958;0;0;0;2.404385;2.375935;7399930;8.53229e+008
229.102;0.7638209;-0.19895;8068.382;833.7344;0;0;0;2.405735;2.377253;7404714;8.537919e+008
229.104;0.7638209;-0.198963;8068.477;833.7443;0;0;0;2.405735;2.377253;7404802;8.53802e+008
230.104;0.7605531;-0.1971509;8011.836;827.8914;0;0;0;2.395443;2.367202;7352820;8.477231e+008
231.104;0.757071;-0.194124;7949.325;821.4319;0;0;0;2.384475;2.356491;7295451;8.410188e+008
232.104;0.7537495;-0.1912216;7890.987;815.4036;0;0;0;2.374014;2.346273;7241910;8.347614e+008
233.104;0.7504816;-0.1882933;7833.669;809.4807;0;0;0;2.363722;2.336218;7189307;8.286146e+008
234.104;0.7470531;-0.1853145;7775.455;803.4653;0;0;0;2.352923;2.325669;7135882;8.223702e+008
235.104;0.7437852;-0.1823492;7718.712;797.6018;0;0;0;2.342631;2.315612;7083806;8.162867e+008
236.104;0.7404638;-0.1793728;7662.383;791.7811;0;0;0;2.33217;2.30539;7032111;8.102468e+008
237.104;0.7370888;-0.176385;7605.818;785.936;0;0;0;2.32154;2.295002;6980198;8.041819e+008
238.104;0.7337674;-0.17342;7550.562;780.2263;0;0;0;2.311078;2.284777;6929488;7.98258e+008
239.104;0.730446;-0.1704261;7494.666;774.4503;0;0;0;2.300617;2.274552;6878189;7.922675e+008
240.104;0.7271246;-0.1674223;7439.465;768.7463;0;0;0;2.290156;2.264326;6827529;7.863518e+008
241.104;0.7238031;-0.1644545;7384.179;763.0333;0;0;0;2.279695;2.254098;6776790;7.804281e+008
242.104;0.7204281;-0.1613704;7328.855;757.3165;0;0;0;2.269065;2.243705;6726017;7.745005e+008
243.104;0.7171067;-0.15833;7274.93;751.7443;0;0;0;2.258604;2.233475;6676528;7.687232e+008
244.104;0.7137316;-0.1553144;7219.817;746.0493;0;0;0;2.247974;2.223079;6625949;7.628203e+008
245.104;0.7104102;-0.1521373;7165.829;740.4705;0;0;0;2.237513;2.212848;6576401;7.570386e+008
246.104;0.7070888;-0.1491202;7113.039;735.0155;0;0;0;2.227051;2.202615;6527953;7.513847e+008
247.104;0.7037138;-0.1458845;7060.198;729.5553;0;0;0;2.216421;2.192216;6479459;7.457253e+008
248.104;0.7003924;-0.1426105;7007.885;724.1496;0;0;0;2.20596;2.181981;6431449;7.40124e+008
249.104;0.6971246;-0.1394438;6957.211;718.9132;0;0;0;2.195668;2.17191;6384943;7.346982e+008
250.104;0.693696;-0.1361983;6904.801;713.4975;0;0;0;2.184869;2.161343;6336844;7.290865e+008
251.104;0.6903746;-0.1328359;6853.1;708.1551;0;0;0;2.174408;2.151105;6289396;7.235533e+008
252.104;0.6871067;-0.1296973;6803.141;702.9927;0;0;0;2.164115;2.141031;6243546;7.182062e+008
253.104;0.6836782;-0.1264369;6750.585;697.5618;0;0;0;2.153317;2.130461;6195313;7.125825e+008
254.104;0.6803031;-0.1231103;6699;692.2314;0;0;0;2.142687;2.120054;6147972;7.070638e+008
255.104;0.6770888;-0.1200028;6649.594;687.1262;0;0;0;2.132563;2.110142;6102630;7.017795e+008
256.104;0.6736603;-0.1167492;6597.955;681.7901;0;0;0;2.121765;2.099569;6055238;6.962561e+008
257.104;0.6702853;-0.1135758;6547.933;676.6212;0;0;0;2.111135;2.089159;6009331;6.909055e+008
258.104;0.667071;-0.1105808;6498.752;671.5391;0;0;0;2.101011;2.079244;5964195;6.856482e+008
259.104;0.6636424;-0.1073245;6447.72;666.2657;0;0;0;2.090212;2.068667;5917360;6.801921e+008
260.104;0.6602674;-0.1043403;6398.644;661.1945;0;0;0;2.079582;2.058254;5872321;6.749446e+008
261.104;0.6569995;-0.1012224;6350.331;656.2022;0;0;0;2.06929;2.048171;5827982;6.697809e+008
262.104;0.6536246;-0.09809341;6299.927;650.9938;0;0;0;2.05866;2.037756;5781724;6.643955e+008
263.104;0.6502496;-0.09502922;6250.387;645.8746;0;0;0;2.04803;2.02734;5736259;6.591023e+008
264.104;0.6470353;-0.09202125;6202.906;640.9682;0;0;0;2.037906;2.017419;5692683;6.540305e+008
265.104;0.6436067;-0.08887876;6151.683;635.6751;0;0;0;2.027108;2.006835;5645674;6.48561e+008
266.104;0.6402317;-0.08593989;6102.68;630.6115;0;0;0;2.016478;1.996416;5600701;6.433276e+008
267.104;0.6370174;-0.08309139;6055.682;625.7551;0;0;0;2.006354;1.986492;5557570;6.3831e+008
268.104;0.6335889;-0.08005204;6005.195;620.5381;0;0;0;1.995556;1.975905;5511236;6.329212e+008
269.104;0.6302674;-0.0771562;5957.28;615.5868;0;0;0;1.985094;1.965648;5467261;6.278068e+008
270.104;0.6270532;-0.07448789;5911.117;610.8166;0;0;0;1.974971;1.955721;5424896;6.228801e+008
271.104;0.623571;-0.07146492;5860.888;605.6263;0;0;0;1.964003;1.944966;5378799;6.175208e+008
272.104;0.6203031;-0.06866003;5814.147;600.7964;0;0;0;1.953711;1.934871;5335902;6.125342e+008
273.104;0.6170353;-0.06591727;5767.35;595.9607;0;0;0;1.943418;1.924775;5292954;6.075427e+008
274.104;0.6136068;-0.06306312;5717.994;590.8606;0;0;0;1.93262;1.914182;5247659;6.022797e+008
275.104;0.6103389;-0.06034367;5671.203;586.0255;0;0;0;1.922327;1.904084;5204716;5.972908e+008
276.104;0.6070711;-0.05772991;5624.903;581.2411;0;0;0;1.912035;1.893985;5162225;5.923547e+008
277.104;0.6036961;-0.05494501;5576.446;576.2339;0;0;0;1.901405;1.883554;5117753;5.871904e+008
278.104;0.6003746;-0.05230049;5529.36;571.3684;0;0;0;1.890944;1.873287;5074541;5.821726e+008
279.104;0.5971068;-0.04966883;5483.316;566.6104;0;0;0;1.880651;1.863186;5032284;5.772664e+008
280.104;0.5936782;-0.0470941;5435.273;561.6459;0;0;0;1.869853;1.852586;4988192;5.721479e+008
281.104;0.5904103;-0.0446342;5389.064;556.871;0;0;0;1.85956;1.842482;4945785;5.672264e+008
282.104;0.5871425;-0.04231193;5343.183;552.13;0;0;0;1.849268;1.832377;4903678;5.623404e+008
283.104;0.583714;-0.03975621;5296.003;547.2548;0;0;0;1.838469;1.821774;4860379;5.573159e+008
284.104;0.580446;-0.03749465;5250.266;542.5286;0;0;0;1.828176;1.811666;4818403;5.524469e+008
285.104;0.5771246;-0.0350784;5204.753;537.8256;0;0;0;1.817715;1.801392;4776634;5.476017e+008
286.104;0.5737496;-0.03287597;5158.76;533.0729;0;0;0;1.807085;1.790952;4734424;5.42706e+008
287.104;0.5704282;-0.03068099;5113.96;528.4435;0;0;0;1.796624;1.780676;4693309;5.379377e+008
288.104;0.5671068;-0.02843279;5069.441;523.8433;0;0;0;1.786163;1.770399;4652452;5.332e+008
289.104;0.5637318;-0.02621919;5024.507;519.2001;0;0;0;1.775533;1.759955;4611214;5.284187e+008
290.104;0.5604103;-0.02403095;4980.386;514.6409;0;0;0;1.765072;1.749675;4570723;5.237247e+008
291.104;0.5570889;-0.02183005;4935.942;510.0484;0;0;0;1.754611;1.739395;4529935;5.189978e+008
292.104;0.5537675;-0.01979848;4891.813;505.4884;0;0;0;1.74415;1.729114;4489435;5.143049e+008
293.104;0.5504461;-0.01761706;4848.406;501.003;0;0;0;1.733688;1.718831;4449599;5.096888e+008
294.104;0.5470711;-0.01558671;4804.552;496.4713;0;0;0;1.723058;1.708382;4409351;5.050258e+008
295.104;0.5437497;-0.01359571;4762.173;492.0922;0;0;0;1.712597;1.698098;4370458;5.005197e+008
296.104;0.5404282;-0.01153463;4719.042;487.6353;0;0;0;1.702136;1.687812;4330876;4.959356e+008
297.104;0.5370532;-0.009582622;4675.573;483.1435;0;0;0;1.691506;1.67736;4290982;4.913159e+008
298.104;0.5337318;-0.007647503;4633.718;478.8185;0;0;0;1.681045;1.667072;4252570;4.868677e+008
299.104;0.5303568;-0.005735034;4591.2;474.425;0;0;0;1.670415;1.656617;4213549;4.823498e+008
300.104;0.5270354;-0.003810927;4548.507;470.0133;0;0;0;1.659954;1.646327;4174367;4.778153e+008
301.104;0.5237139;-0.002078258;4507.216;465.7466;0;0;0;1.649493;1.636036;4136473;4.73429e+008
302.104;0.5203925;-0.0002233585;4465.024;461.3867;0;0;0;1.639032;1.625744;4097752;4.68949e+008
303.104;0.5170175;0.001648236;4422.768;457.0203;0;0;0;1.628402;1.615285;4058971;4.644624e+008
304.104;0.5137497;0.003347476;4382.339;452.8426;0;0;0;1.618109;1.605157;4021868;4.601701e+008
305.104;0.5103211;0.005109889;4340.519;448.5212;0;0;0;1.607311;1.59453;3983488;4.557303e+008
306.104;0.5069997;0.006970785;4299.02;444.2329;0;0;0;1.596849;1.584234;3945402;4.513266e+008
307.104;0.5037318;0.008455151;4259.529;440.1522;0;0;0;1.586557;1.574103;3909159;4.471354e+008
308.104;0.5003032;0.01021223;4217.712;435.8311;0;0;0;1.575758;1.563472;3870782;4.426987e+008
309.104;0.4969818;0.01188247;4176.909;431.6148;0;0;0;1.565297;1.553173;3833336;4.383708e+008
310.104;0.493714;0.01339631;4137.901;427.584;0;0;0;1.555005;1.543038;3797536;4.342329e+008
311.104;0.4902854;0.0150941;4096.853;423.3424;0;0;0;1.544206;1.532405;3759865;4.298796e+008
312.104;0.486964;0.01661848;4057.056;419.23;0;0;0;1.533745;1.522102;3723341;4.256599e+008
313.104;0.4836961;0.01791682;4018.45;415.2407;0;0;0;1.523452;1.511964;3687911;4.215667e+008
314.104;0.4802676;0.01959219;3977.827;411.0429;0;0;0;1.512654;1.501327;3650629;4.172606e+008
315.104;0.4769462;0.02091322;3938.918;407.0223;0;0;0;1.502193;1.491021;3614921;4.131366e+008
316.104;0.4736783;0.02219999;3901.092;403.1137;0;0;0;1.4919;1.480881;3580207;4.091277e+008
317.104;0.4702497;0.02358431;3860.807;398.9509;0;0;0;1.481101;1.47024;3543235;4.048598e+008
318.104;0.4669283;0.02475982;3822.383;394.9804;0;0;0;1.47064;1.459931;3507971;4.007891e+008
319.104;0.463714;0.02587891;3784.849;391.1018;0;0;0;1.460516;1.449954;3473525;3.96814e+008
320.104;0.4602319;0.02716498;3744.589;386.9417;0;0;0;1.449549;1.439144;3436577;3.925506e+008
321.104;0.456964;0.02824742;3706.775;383.0341;0;0;0;1.439257;1.428998;3401873;3.88547e+008
322.104;0.4536961;0.02925129;3668.89;379.1194;0;0;0;1.428964;1.418851;3367104;3.845368e+008
323.104;0.4502675;0.03026217;3630.036;375.1045;0;0;0;1.418165;1.408204;3331446;3.804241e+008
324.104;0.4469997;0.03111344;3592.359;371.2112;0;0;0;1.407873;1.398055;3296869;3.764374e+008
325.104;0.4437318;0.03194511;3554.889;367.3393;0;0;0;1.397581;1.387904;3262481;3.724732e+008
326.104;0.4403569;0.03268477;3516.646;363.3875;0;0;0;1.386951;1.377421;3227383;3.684275e+008
327.104;0.4370355;0.03346079;3479.48;359.547;0;0;0;1.37649;1.367102;3193274;3.644961e+008
328.104;0.4337676;0.03407669;3442.71;355.7474;0;0;0;1.366197;1.356949;3159529;3.606077e+008
329.104;0.430339;0.03473463;3404.749;351.8247;0;0;0;1.355398;1.346295;3124690;3.565934e+008
330.104;0.4270712;0.03534344;3368.347;348.0632;0;0;0;1.345106;1.33614;3091282;3.52745e+008
331.104;0.4237497;0.03589185;3332.594;344.3687;0;0;0;1.334645;1.325817;3058470;3.489649e+008
332.104;0.4203747;0.03643979;3294.827;340.4662;0;0;0;1.324015;1.315326;3023810;3.44974e+008
333.104;0.4170533;0.03700423;3258.016;336.6623;0;0;0;1.313554;1.305001;2990026;3.410845e+008
334.104;0.4137855;0.03752713;3222.328;332.9745;0;0;0;1.303261;1.294842;2957274;3.373141e+008
335.104;0.4104104;0.03789006;3184.939;329.1111;0;0;0;1.292631;1.284348;2922961;3.333653e+008
336.104;0.407089;0.03842558;3149.182;325.4162;0;0;0;1.28217;1.27402;2890145;3.295886e+008
337.104;0.4037676;0.03884643;3113.036;321.6811;0;0;0;1.271709;1.263691;2856972;3.257719e+008
338.104;0.4003926;0.03929946;3075.91;317.8447;0;0;0;1.261079;1.253194;2822900;3.21853e+008
339.104;0.3971247;0.03970624;3040.156;314.1501;0;0;0;1.250787;1.243029;2790087;3.180794e+008
340.104;0.3937498;0.04007207;3003.818;310.3952;0;0;0;1.240157;1.23253;2756738;3.142446e+008
341.104;0.3904283;0.04046412;2967.945;306.6883;0;0;0;1.229696;1.222196;2723816;3.104596e+008
342.104;0.3871069;0.0407906;2932.598;303.0357;0;0;0;1.219234;1.211861;2691376;3.067304e+008
343.104;0.3837319;0.0411116;2897.199;299.3779;0;0;0;1.208604;1.201359;2658889;3.029961e+008
344.104;0.3804105;0.04151259;2861.725;295.7122;0;0;0;1.198143;1.191022;2626333;2.992553e+008
345.104;0.377089;0.04175081;2826.169;292.0381;0;0;0;1.187682;1.180684;2593702;2.955066e+008
346.104;0.373714;0.04215607;2790.123;288.3133;0;0;0;1.177052;1.170179;2560620;2.917069e+008
347.104;0.3704462;0.04237055;2755.397;284.7249;0;0;0;1.16676;1.160005;2528751;2.880469e+008
348.104;0.3670712;0.04259781;2719.682;281.0343;0;0;0;1.15613;1.149498;2495973;2.842835e+008
349.104;0.3636962;0.04288209;2683.957;277.3428;0;0;0;1.1455;1.138989;2463187;2.805197e+008
350.104;0.3604283;0.04300922;2649.913;273.8248;0;0;0;1.135207;1.128812;2431943;2.769333e+008
351.104;0.3570534;0.04307388;2615.038;270.2212;0;0;0;1.124578;1.118301;2399937;2.7326e+008
352.104;0.3536784;0.04312463;2579.994;266.5999;0;0;0;1.113948;1.107789;2367776;2.695697e+008
353.104;0.3504105;0.04319113;2546.568;263.1458;0;0;0;1.103655;1.097609;2337099;2.660501e+008
354.104;0.3470355;0.04322903;2511.632;259.5358;0;0;0;1.093025;1.087095;2305037;2.623726e+008
355.104;0.3436605;0.0433109;2478.155;256.0766;0;0;0;1.082395;1.076579;2274314;2.588483e+008
356.104;0.3403926;0.04319407;2444.952;252.6455;0;0;0;1.072103;1.066396;2243841;2.553541e+008
357.104;0.336964;0.04316147;2410.366;249.0717;0;0;0;1.061304;1.055712;2212100;2.517151e+008
358.104;0.3336426;0.04311601;2377.123;245.6365;0;0;0;1.050843;1.04536;2181592;2.482178e+008
359.104;0.3303748;0.04288667;2344.278;242.2425;0;0;0;1.04055;1.035174;2151449;2.447632e+008
360.104;0.3269462;0.04279419;2310.256;238.727;0;0;0;1.029752;1.024486;2120225;2.411853e+008
361.104;0.3236248;0.04267803;2276.814;235.2713;0;0;0;1.019291;1.014131;2089534;2.376694e+008
362.104;0.320357;0.04248792;2244.574;231.9398;0;0;0;1.008998;1.003942;2059946;2.342801e+008
363.104;0.3169284;0.04227289;2211.007;228.4712;0;0;0;0.9981996;0.9932505;2029140;2.307518e+008
364.104;0.3136069;0.04209979;2178.291;225.0905;0;0;0;0.9877383;0.982892;1999115;2.273138e+008
365.104;0.3103391;0.0418551;2146.865;221.8432;0;0;0;0.977446;0.9726999;1970274;2.240116e+008
366.104;0.3069105;0.04166052;2114.096;218.457;0;0;0;0.9666473;0.9620051;1940200;2.205687e+008
367.104;0.3035891;0.04140658;2082.232;215.1644;0;0;0;0.9561861;0.9516436;1910957;2.172217e+008
368.104;0.3003748;0.04106203;2051.639;212.0032;0;0;0;0.9460624;0.9416153;1882881;2.140088e+008
369.104;0.2969462;0.04073609;2019.171;208.648;0;0;0;0.9352638;0.9309172;1853083;2.105994e+008
370.104;0.2936248;0.04040032;1988.287;205.4567;0;0;0;0.9248026;0.9205525;1824739;2.073568e+008
371.104;0.290357;0.03987405;1957.605;202.2863;0;0;0;0.9145101;0.9103538;1796582;2.041362e+008
372.104;0.2869284;0.03957652;1925.591;198.9781;0;0;0;0.9037114;0.8996524;1767201;2.007763e+008
373.104;0.2836605;0.03914172;1894.815;195.798;0;0;0;0.893419;0.8894516;1738957;1.975473e+008
374.104;0.2803927;0.03870594;1864.864;192.703;0;0;0;0.8831266;0.8792498;1711469;1.944049e+008
375.104;0.2770177;0.0382044;1833.176;189.4286;0;0;0;0.8724966;0.8687124;1682388;1.910814e+008
376.104;0.2736427;0.03781172;1802.759;186.2854;0;0;0;0.8618667;0.8581738;1654472;1.87891e+008
377.104;0.2704284;0.03736089;1773.356;183.2472;0;0;0;0.851743;0.8481362;1627488;1.84808e+008
378.104;0.2669998;0.03687585;1742.185;180.0261;0;0;0;0.8409443;0.8374281;1598881;1.8154e+008
379.104;0.2636784;0.03640397;1712.014;176.9085;0;0;0;0.8304832;0.8270537;1571192;1.783777e+008
380.104;0.2604641;0.0358817;1682.706;173.8799;0;0;0;0.8203595;0.8170128;1544294;1.753064e+008
381.104;0.2570356;0.03542122;1652.221;170.7299;0;0;0;0.8095608;0.8063014;1516317;1.72112e+008
382.104;0.2537141;0.03493014;1622.576;167.6665;0;0;0;0.7990996;0.7959237;1489110;1.690063e+008
383.104;0.2504463;0.03441167;1593.234;164.6345;0;0;0;0.7888072;0.7857123;1462182;1.659331e+008
384.104;0.2470713;0.03389622;1562.219;161.4296;0;0;0;0.7781773;0.7751651;1433718;1.626858e+008
385.104;0.2437499;0.0334729;1533.038;158.4143;0;0;0;0.7677161;0.7647841;1406938;1.596305e+008
386.104;0.240482;0.03299511;1503.579;155.3701;0;0;0;0.7574236;0.7545695;1379901;1.565469e+008
387.104;0.2370534;0.03246268;1473.212;152.2323;0;0;0;0.7466249;0.7438515;1352033;1.533689e+008
388.104;0.2337856;0.03199214;1444.447;149.2598;0;0;0;0.7363325;0.7336348;1325633;1.503588e+008
389.104;0.2304641;0.031494;1415.285;146.2464;0;0;0;0.7258713;0.7232495;1298870;1.47308e+008
390.104;0.2270891;0.03095257;1386.161;143.237;0;0;0;0.7152414;0.7126957;1272142;1.442615e+008
391.104;0.2237677;0.03041039;1357.59;140.2846;0;0;0;0.7047802;0.7023083;1245921;1.412733e+008
392.104;0.2204463;0.02989184;1328.871;137.3169;0;0;0;0.694319;0.6919197;1219564;1.382703e+008
393.104;0.2171249;0.02942541;1300.345;134.3692;0;0;0;0.6838578;0.6815301;1193385;1.352881e+008
394.104;0.2137499;0.02897285;1271.813;131.4209;0;0;0;0.6732279;0.6709719;1167199;1.323057e+008
395.104;0.2103749;0.02845363;1243.413;128.4863;0;0;0;0.662598;0.6604124;1141136;1.293376e+008
396.104;0.207107;0.02793352;1215.658;125.6182;0;0;0;0.6523055;0.6501872;1115663;1.264376e+008
397.104;0.203732;0.02736171;1187.285;122.6864;0;0;0;0.6416757;0.6396257;1089625;1.234736e+008
398.104;0.200357;0.02676964;1159.703;119.8362;0;0;0;0.6310458;0.629063;1064311;1.205924e+008
399.104;0.1970892;0.02632782;1132.161;116.9902;0;0;0;0.6207532;0.6188345;1039034;1.177164e+008
400.104;0.1937141;0.02576381;1104.188;114.0996;0;0;0;0.6101233;0.6082695;1013362;1.147958e+008
401.104;0.1903927;0.02523405;1077.074;111.2979;0;0;0;0.5996621;0.5978713;988478.8;1.119653e+008
402.104;0.1870713;0.02476022;1050.115;108.5121;0;0;0;0.589201;0.587472;963737.3;1.091514e+008
403.104;0.1836427;0.02412888;1021.913;105.5979;0;0;0;0.5784023;0.576736;937855.4;1.062087e+008
404.104;0.1803213;0.02358129;994.5969;102.7752;0;0;0;0.5679411;0.5663344;912785.9;1.033589e+008
405.104;0.1770535;0.02301571;967.6836;99.99417;0;0;0;0.5576487;0.5560996;888086.4;1.005518e+008
406.104;0.1736785;0.02256684;940.3357;97.16821;0;0;0;0.5470188;0.545528;862987.9;9.769974e+007
407.104;0.1703035;0.02200267;913.2928;94.37378;0;0;0;0.5363889;0.5349554;838169.5;9.487999e+007
408.104;0.1670356;0.02153283;887.3935;91.69751;0;0;0;0.5260964;0.5247174;814400.6;9.217993e+007
409.104;0.1636606;0.02091059;860.086;88.87572;0;0;0;0.5154665;0.5141425;789339.3;8.933385e+007
410.104;0.1602856;0.02049205;833.3286;86.1108;0;0;0;0.5048366;0.5035665;764782.9;8.654552e+007
411.104;0.1570177;0.01989199;807.8723;83.48031;0;0;0;0.4945441;0.4933252;741420.4;8.389315e+007
412.104;0.1535892;0.01940784;781.1102;80.71488;0;0;0;0.4837455;0.4825792;716859.7;8.110534e+007
413.104;0.1502678;0.01895415;754.8902;78.00548;0;0;0;0.4732843;0.4721678;692796.4;7.837466e+007
414.104;0.1470535;0.01831157;730.1357;75.44751;0;0;0;0.4631606;0.4620913;670078.1;7.579695e+007
415.104;0.1435713;0.01777189;703.9133;72.73785;0;0;0;0.4521932;0.4511739;646012.6;7.306677e+007
416.104;0.1402499;0.0172912;678.8204;70.14491;0;0;0;0.441732;0.4407592;622983.8;7.045477e+007
417.104;0.1370356;0.01679608;654.6016;67.6423;0;0;0;0.4316083;0.4306795;600757.1;6.793425e+007
418.104;0.1336071;0.01628953;629.1451;65.01179;0;0;0;0.4208096;0.4199267;577394.5;6.528537e+007
419.104;0.1302856;0.01584841;605.3953;62.55763;0;0;0;0.4103484;0.4095088;555598.2;6.281434e+007
420.104;0.1270178;0.01528229;581.4787;60.08625;0;0;0;0.400056;0.3992579;533648.9;6.032663e+007
421.104;0.1235892;0.01469504;557.0843;57.56549;0;0;0;0.3892573;0.3885017;511261.1;5.778957e+007
422.104;0.1203213;0.014266;534.5241;55.23426;0;0;0;0.3789649;0.3782486;490556.6;5.544358e+007
423.104;0.1170535;0.01377382;511.803;52.88641;0;0;0;0.3686724;0.3679945;469704.4;5.308139e+007
424.104;0.1136249;0.01330794;488.2458;50.45217;0;0;0;0.3578738;0.3572349;448084.9;5.063272e+007
425.104;0.1103571;0.01278422;465.8023;48.133;0;0;0;0.3475813;0.3469787;427487.6;4.83003e+007
426.104;0.1070892;0.01234444;443.8915;45.86887;0;0;0;0.3372889;0.3367213;407379;4.602359e+007
427.104;0.1036606;0.01186645;421.4692;43.5519;0;0;0;0.3264902;0.3259584;386801;4.369409e+007
428.104;0.1003928;0.01142541;400.0481;41.33838;0;0;0;0.3161978;0.3156989;367141.9;4.146909e+007
429.104;0.09712494;0.01111903;379.1215;39.17596;0;0;0;0.3059053;0.3054384;347936.7;3.929581e+007
430.104;0.09369636;0.01060648;357.3417;36.92538;0;0;0;0.2951066;0.2946721;327948.4;3.703435e+007
431.104;0.09037494;0.01019542;336.5523;34.77714;0;0;0;0.2846455;0.2842411;308869.1;3.487613e+007
432.104;0.08710708;0.009835117;316.4276;32.69758;0;0;0;0.274353;0.2739774;290399.7;3.278729e+007
433.104;0.08373209;0.009397375;295.7607;30.562;0;0;0;0.2637231;0.263376;271432.8;3.06426e+007
434.104;0.08041065;0.008955243;275.9949;28.51953;0;0;0;0.2532619;0.2529417;253292.8;2.859176e+007
435.104;0.0771428;0.008629464;257.0476;26.56164;0;0;0;0.2429695;0.2426748;235904.1;2.662618e+007
436.104;0.07371424;0.008176516;237.9924;24.5926;0;0;0;0.2321708;0.2319017;218416.3;2.464969e+007
437.104;0.07044638;0.007785292;219.657;22.69794;0;0;0;0.2218784;0.2216326;201589;2.27483e+007
438.104;0.06712496;0.007450812;201.6132;20.83341;0;0;0;0.2114172;0.211194;185029.4;2.087745e+007
439.104;0.06374995;0.007059469;184.0299;19.01646;0;0;0;0.2007873;0.2005859;168892.5;1.905464e+007
440.104;0.06042853;0.00670955;167.6022;17.31893;0;0;0;0.1903261;0.1901452;153816;1.735189e+007
441.104;0.0571071;0.006383653;151.6033;15.6657;0;0;0;0.1798649;0.1797033;139133.1;1.569388e+007
442.104;0.05373211;0.006077312;136.0405;14.05755;0;0;0;0.169235;0.169092;124850.5;1.408134e+007
443.104;0.05041068;0.0057676;121.728;12.57858;0;0;0;0.1587738;0.1586479;111715.2;1.259855e+007
444.104;0.04708925;0.005459691;108.2938;11.19038;0;0;0;0.1483126;0.1482027;99386.02;1.120697e+007
445.104;0.04376783;0.005283262;96.16753;9.937331;0;0;0;0.1378514;0.1377565;88257.23;9951030
446.104;0.04039283;0.005005136;84.64892;8.747073;0;0;0;0.1272215;0.1271407;77686.09;8758201
447.104;0.0370714;0.004765456;74.35088;7.68294;0;0;0;0.1167603;0.1166922;68235.12;7691911
448.104;0.03374998;0.004486586;65.43854;6.761996;0;0;0;0.1062991;0.1062427;60055.87;6769184
449.104;0.03037498;0.004305532;59.48277;6.146565;0;0;0;0.09566923;0.0956235;54589.99;6152446
450.104;0.02705355;0.004275239;55.4829;5.733245;0;0;0;0.08520804;0.08517176;50919.14;5738130
451.104;0.02373213;0.004186828;53.14884;5.492058;0;0;0;0.07474685;0.07471894;48777.06;5496163
451.946;0.02083927;0.004164648;52.37267;5.411853;0;0;0;0.0656355;0.06561397;48064.73;5415405