File: Ensayos/Graficos/EspA/EspA60ext125segundo.raw
"Test Type";"Manual"
"Method Name:";"C:\INSTRON\user\template\CYCLE.MTM"
"Name:";""
"Operator ID:";""
"Company:";""
"Lab name:";""
"Test date:";"04/04/2017"
"Temperature:";""
"Humidity:";""
"Note 1:";""
"Note 2:";""
"Note 3:";""
"Geometry:";"Rectangular"
"Specimen";1
"Specimen name:";""
"Width:";0.250000;"in"
"Thickness:";0.060000;"in"
"Length:";1.250000;"in"
"Diameter:";0.039370;"in"
"Inner diameter:";0.019685;"in"
"Outer diameter:";0.039370;"in"
"Wall thickness:";0.019685;"in"
"Area:";0.015000;"in*in"
"Linear density:";1.000000;"den"
"Sled weight:";2.204623;"lbf"
"Loading span:";0.000000;"mm"
"Support span:";1.000000;"mm"
"Span ratio:";"2"
"Fixture type:";"3-point"
"Comment:";""
"Included"
"Final Width:";0.250000;"in"
"Final Thickness:";0.060000;"in"
"Final Length:";1.250000;"in"
"Final Diameter:";0.039370;"in"
"Final Inner diameter:";0.019685;"in"
"Final Outer diameter:";0.039370;"in"
"Final Wall thickness:";0.019685;"in"
"Final Area:";0.015000;"in*in"
"Final Linear density:";1.000000;"den"
"Time sec";"Extension mm";"Strain 1 %";"Load N";"Stress MPa";"Cycle Count ";"Total Cycle Count ";"Repetitions Count ";"Strain [Exten.] %";"True strain %";"Tenacity gf/tex";"True stress Pa"
0;0;-0.0001099804;48.67273;5.029525;0;0;0;0;0;44669.13;5029525
4;0.01339285;-1.812106e-005;48.65291;5.027477;0;0;0;0.0421822;0.04217331;44650.94;5029598
8;0.02673213;0.0002249691;48.71681;5.03408;0;0;0;0.08419567;0.08416025;44709.59;5038318
12;0.03996426;-1.204677e-005;48.58827;5.020798;0;0;0;0.1258717;0.1257925;44591.63;5027118
16;0.05335711;-8.774477e-006;48.87523;5.05045;0;0;0;0.1680539;0.1679128;44854.98;5058938
20;0.06658925;1.372988e-005;48.90879;5.053919;0;0;0;0.2097299;0.2095103;44885.78;5064518
24;0.07992851;-5.856426e-005;49.33891;5.098364;0;0;0;0.2517433;0.251427;45280.52;5111199
28;0.09321422;-0.0001369131;49.13244;5.077029;0;0;0;0.2935881;0.293158;45091.03;5091934
32;0.1065535;0.0001097531;49.387;5.103334;0;0;0;0.3356016;0.3350397;45324.66;5120461
36;0.1199464;2.070556e-005;49.45604;5.110468;0;0;0;0.3777838;0.377072;45388.02;5129775
40;0.1331785;8.091964e-005;49.32135;5.09655;0;0;0;0.4194598;0.4185825;45264.4;5117927
44;0.1466785;-2.689943e-005;49.49425;5.114416;0;0;0;0.4619794;0.4609156;45423.08;5138043
48;0.1600178;-1.495653e-005;49.38052;5.102664;0;0;0;0.5039929;0.5027271;45318.7;5128381
52;0.1733035;-9.856652e-005;49.62002;5.127412;0;0;0;0.5458376;0.5443533;45538.5;5155399
56;0.1867499;-7.118724e-006;49.55242;5.120427;0;0;0;0.5881886;0.5864655;45476.46;5150545
60;0.2000356;0.0001222348;49.39364;5.10402;0;0;0;0.6300333;0.6280569;45330.75;5136177
64;0.2132677;-3.766665e-005;49.33946;5.098421;0;0;0;0.6717094;0.6694634;45281.02;5132668
68;0.2266606;6.533217e-005;49.31145;5.095527;0;0;0;0.7138915;0.7113554;45255.32;5131903
72;0.2398927;1.363191e-005;49.30114;5.094461;0;0;0;0.7555676;0.7527275;45245.86;5132954
76;0.2532855;-1.088087e-005;49.54634;5.119799;0;0;0;0.7977498;0.7945845;45470.89;5160642
80;0.2665177;0.0001816945;49.59776;5.125112;0;0;0;0.8394258;0.8359222;45518.07;5168133
84.00001;0.2799105;1.715893e-005;49.61494;5.126887;0;0;0;0.881608;0.8777445;45533.84;5172086
88.00001;0.2933034;5.717106e-005;49.70597;5.136293;0;0;0;0.9237901;0.9195493;45617.38;5183742
92.00001;0.3065355;2.815148e-005;52.55403;5.430594;0;0;0;0.9654662;0.9608353;48231.18;5483025
96.00001;0.319982;1.73059e-005;56.33832;5.821638;0;0;0;1.007817;1.002773;51704.18;5880309
100;0.3333748;6.187372e-005;56.47023;5.835268;0;0;0;1.049999;1.044525;51825.25;5896539
104;0.3466069;0.0001082247;56.50581;5.838946;0;0;0;1.091675;1.08576;51857.91;5902688
108;0.3600533;6.203049e-005;56.47551;5.835814;0;0;0;1.134026;1.127644;51830.09;5901994
112;0.373339;-3.033827e-005;56.13071;5.800185;0;0;0;1.175871;1.169011;51513.65;5868387
116;0.3866247;7.273891e-005;56.49842;5.838181;0;0;0;1.217716;1.210361;51851.12;5909274
120;0.399964;-7.638548e-005;56.35576;5.82344;0;0;0;1.259729;1.251861;51720.2;5896800
124;0.4132497;6.587688e-006;56.31306;5.819028;0;0;0;1.301574;1.293176;51681.01;5894767
128;0.426589;7.125953e-005;56.37435;5.825361;0;0;0;1.343587;1.334641;51737.25;5903630
132;0.4398747;1.175085e-005;56.26755;5.814325;0;0;0;1.385432;1.375923;51639.24;5894878
136;0.4532676;-9.334457e-005;56.26584;5.814149;0;0;0;1.427614;1.41752;51637.68;5897152
140;0.4666604;7.398317e-005;56.25471;5.812999;0;0;0;1.469797;1.4591;51627.46;5898438
144;0.4798926;0.000149481;56.2815;5.815766;0;0;0;1.511473;1.500164;51652.04;5903670
148;0.4933925;0.0001001615;56.53239;5.841692;0;0;0;1.553992;1.542041;51882.3;5932472
152;0.5067318;0.0001599445;56.19798;5.807137;0;0;0;1.596006;1.583403;51575.39;5899819
156;0.5199639;0.0001162878;56.36648;5.824548;0;0;0;1.637682;1.624416;51730.03;5919935
160;0.5334103;0.0001571915;56.40051;5.828065;0;0;0;1.680033;1.666076;51761.27;5925978
164;0.5466961;0.0001256736;56.18718;5.80602;0;0;0;1.721877;1.707221;51565.48;5905992
168;0.5599282;0.0001095081;56.39229;5.827215;0;0;0;1.763553;1.748183;51753.72;5929981
172;0.5732675;0.0001548695;56.86366;5.875923;0;0;0;1.805567;1.78946;52186.32;5982017
176;0.5865532;-7.268212e-005;57.11591;5.901989;0;0;0;1.847412;1.830554;52417.81;6011023
180;0.599946;0.0001074507;57.22429;5.913189;0;0;0;1.889594;1.871963;52517.29;6024924
184;0.6131782;-1.952209e-005;56.892;5.878851;0;0;0;1.93127;1.912858;52212.32;5992388
188;0.6266246;-1.106702e-005;56.90134;5.879817;0;0;0;1.973621;1.954397;52220.89;5995862
192;0.6399639;0.0001080189;57.12756;5.903193;0;0;0;2.015634;1.995589;52428.51;6022180
196;0.6532495;-2.11778e-005;57.20568;5.911265;0;0;0;2.057479;2.036599;52500.2;6032888
200;0.666696;-2.386623e-006;57.0126;5.891314;0;0;0;2.09983;2.078087;52323;6015021
204;0.6800352;0.0001025324;57.14242;5.904729;0;0;0;2.141843;2.119228;52442.15;6031199
208;0.6932674;0.0001487658;57.00446;5.890473;0;0;0;2.183519;2.160022;52315.54;6019093
212;0.7067138;0.000119325;56.95642;5.885509;0;0;0;2.22587;2.201459;52271.45;6016513
216;0.7199995;0.0002139569;57.34058;5.925205;0;0;0;2.267715;2.242385;52624.01;6059572
220;0.7332316;0.0001322084;57.24209;5.915028;0;0;0;2.309391;2.283128;52533.62;6051629
224;0.7465709;-0.0001240884;71.02575;7.339343;0;0;0;2.351405;2.324185;65183.5;7511920
228;0.7598566;-0.001214163;123.581;12.77007;0;0;0;2.393249;2.36506;113415.8;1.307569e+007
232;0.7732495;-0.002815558;185.2882;19.14648;0;0;0;2.435431;2.406248;170047.2;1.961278e+007
236;0.7865352;-0.004679344;249.0447;25.73467;0;0;0;2.477276;2.447089;228559.4;2.637219e+007
240;0.7999281;-0.007058976;317.1762;32.77494;0;0;0;2.519459;2.488243;291086.8;3.360069e+007
244;0.8133209;-0.009469519;385.973;39.88395;0;0;0;2.561641;2.52938;354224.6;4.090563e+007
248;0.8266066;-0.01247941;452.8593;46.79556;0;0;0;2.603485;2.570172;415609.2;4.801387e+007
252;0.840053;-0.01671045;523.4873;54.0938;0;0;0;2.645836;2.611439;480427.7;5.552503e+007
256;0.8533923;-0.02173616;598.7853;61.8746;0;0;0;2.68785;2.652362;549531.9;6.35377e+007
260;0.8666245;-0.02697988;673.7318;69.61909;0;0;0;2.729526;2.692939;618313.8;7.151937e+007
264;0.8800173;-0.03230544;748.2288;77.31713;0;0;0;2.771708;2.733992;686682.9;7.946014e+007
268;0.8932495;-0.03824765;822.5659;84.99864;0;0;0;2.813384;2.774535;754905.4;8.738998e+007
272;0.9065887;-0.04844747;908.8713;93.91689;0;0;0;2.855397;2.815391;834111.7;9.659859e+007
276;0.9198744;-0.06260508;1000.384;103.3732;0;0;0;2.897242;2.856066;918097.2;1.063682e+008
280;0.9332137;-0.07815276;1091.718;112.8111;0;0;0;2.939256;2.896888;1001918;1.161269e+008
284;0.9466065;-0.09455772;1188.948;122.8582;0;0;0;2.981438;2.937857;1091151;1.265211e+008
288;0.9598387;-0.1103519;1289.943;133.2944;0;0;0;3.023114;2.978319;1183838;1.37324e+008
292;0.9732851;-0.126783;1391.583;143.7972;0;0;0;3.065465;3.019418;1277118;1.482052e+008
296;0.986678;-0.1435395;1490.857;154.0555;0;0;0;3.107647;3.060337;1368226;1.58843e+008
300;0.9999636;-0.1612565;1586.666;163.9558;0;0;0;3.149492;3.100913;1456154;1.691196e+008
304;1.01341;-0.1794775;1681.429;173.748;0;0;0;3.191843;3.141962;1543122;1.792938e+008
308;1.026749;-0.1983995;1771.667;183.0726;0;0;0;3.233856;3.182667;1625938;1.88993e+008
312;1.039928;-0.2174449;1857.886;191.9819;0;0;0;3.275363;3.222866;1705065;1.9827e+008
316;1.053321;-0.2368395;1944.258;200.9071;0;0;0;3.317546;3.263703;1784333;2.075723e+008
320;1.066606;-0.2575597;2027.732;209.5328;0;0;0;3.35939;3.304196;1860940;2.165718e+008
324;1.079892;-0.278665;2110.76;218.1123;0;0;0;3.401235;3.344672;1937139;2.255308e+008
328;1.093231;-0.2997321;2193.058;226.6164;0;0;0;3.443249;3.385295;2012667;2.344194e+008
332;1.106571;-0.3228642;2272.388;234.8139;0;0;0;3.485262;3.425902;2085472;2.429978e+008
336;1.119964;-0.3465136;2351.362;242.9746;0;0;0;3.527445;3.466656;2157950;2.515454e+008
340;1.133196;-0.3692408;2426.784;250.7681;0;0;0;3.56912;3.506903;2227168;2.597184e+008
344;1.146642;-0.3948372;2501.839;258.5239;0;0;0;3.611471;3.547787;2296049;2.678604e+008
348;1.160035;-0.4184642;2575.176;266.102;0;0;0;3.653653;3.58849;2363354;2.758245e+008
352;1.173267;-0.4431612;2646.442;273.4662;0;0;0;3.69533;3.628689;2428758;2.835716e+008
356;1.186713;-0.4706828;2717.82;280.842;0;0;0;3.73768;3.669522;2494265;2.913389e+008
360;1.200053;-0.4962648;2787.539;288.0463;0;0;0;3.779694;3.710014;2558249;2.989336e+008
364;1.213285;-0.5251183;2854.998;295.0171;0;0;0;3.82137;3.750164;2620159;3.062908e+008
368;1.226678;-0.5528942;2923.423;302.0876;0;0;0;3.863552;3.790785;2682956;3.137589e+008
372;1.23991;-0.5817668;2988.053;308.7661;0;0;0;3.905228;3.830903;2742269;3.208241e+008
376;1.253249;-0.611217;3052.701;315.4464;0;0;0;3.947242;3.871329;2801600;3.278978e+008
380;1.266535;-0.6404127;3116.521;322.0411;0;0;0;3.989086;3.911577;2860170;3.348876e+008
384;1.279928;-0.6673934;3178.845;328.4813;0;0;0;4.031269;3.952133;2917368;3.417233e+008
388;1.293321;-0.6947231;3241.28;334.933;0;0;0;4.073451;3.992672;2974668;3.485763e+008
392;1.306553;-0.7217328;3301.65;341.1712;0;0;0;4.115127;4.032709;3030072;3.552108e+008
396;1.319999;-0.7487425;3362.288;347.4371;0;0;0;4.157477;4.073378;3085722;3.618818e+008
400;1.333392;-0.7761683;3422.044;353.6119;0;0;0;4.19966;4.113868;3140563;3.684624e+008
404;1.346624;-0.8037369;3480.094;359.6105;0;0;0;4.241335;4.153856;3193838;3.748628e+008
408;1.36007;-0.8296787;3539.031;365.7006;0;0;0;4.283687;4.194475;3247927;3.813661e+008
412;1.373356;-0.8571013;3595.391;371.5244;0;0;0;4.325532;4.234594;3299650;3.875948e+008
416;1.386588;-0.884112;3650.897;377.2601;0;0;0;4.367208;4.274534;3350591;3.937358e+008
420;1.399981;-0.9107483;3708.081;383.1692;0;0;0;4.409389;4.314942;3403072;4.000646e+008
424;1.413213;-0.9376796;3761.779;388.718;0;0;0;4.451066;4.354851;3452353;4.060201e+008
428;1.426606;-0.9639253;3816.943;394.4182;0;0;0;4.493248;4.395227;3502979;4.121404e+008
432;1.439892;-0.991862;3871.165;400.0212;0;0;0;4.535093;4.435264;3552741;4.181625e+008
436;1.453231;-1.018794;3924.901;405.574;0;0;0;4.577106;4.475447;3602057;4.241375e+008
438.056;1.446856;-1.015732;3820.835;394.8204;0;0;0;4.557027;4.456245;3506551;4.128125e+008
442.056;1.43341;-1.004114;3629.107;375.0085;0;0;0;4.514677;4.415732;3330594;3.919389e+008
446.056;1.42007;-0.9919225;3456.578;357.1804;0;0;0;4.472663;4.375525;3172255;3.731559e+008
450.056;1.406838;-0.9792719;3293.565;340.3357;0;0;0;4.430987;4.335626;3022651;3.554159e+008
454.056;1.393446;-0.9663422;3136.165;324.071;0;0;0;4.388805;4.295225;2878199;3.382939e+008
458.056;1.38016;-0.9531695;2984.979;308.4485;0;0;0;4.34696;4.255131;2739448;3.218566e+008
462.056;1.366928;-0.9393942;2839.565;293.4223;0;0;0;4.305285;4.215184;2605995;3.06055e+008
466.056;1.353535;-0.9254008;2700.107;279.0116;0;0;0;4.263102;4.174735;2478008;2.909061e+008
470.056;1.340195;-0.910768;2566.252;265.1799;0;0;0;4.221088;4.13443;2355164;2.763734e+008
474.056;1.326856;-0.8958919;2435.858;251.7058;0;0;0;4.179075;4.094111;2235496;2.622248e+008
478.056;1.313517;-0.8805794;2311.715;238.8777;0;0;0;4.137062;4.053774;2121565;2.487603e+008
482.056;1.300124;-0.8647275;2191.025;226.4064;0;0;0;4.094879;4.01326;2010802;2.356775e+008
486.056;1.286731;-0.8489953;2075.031;214.4203;0;0;0;4.052697;3.972729;1904348;2.231101e+008
490.056;1.273499;-0.832848;1963.177;202.862;0;0;0;4.011021;3.932668;1801695;2.109988e+008
494.056;1.259999;-0.8157623;1853.848;191.5647;0;0;0;3.968502;3.89178;1701359;1.99167e+008
498.056;1.246713;-0.798173;1748.759;180.7054;0;0;0;3.926656;3.851524;1604914;1.878011e+008
502.056;1.233535;-0.7810632;1646.692;170.1585;0;0;0;3.885149;3.811577;1511243;1.767694e+008
506.056;1.220142;-0.7629985;1546.978;159.8547;0;0;0;3.842968;3.770964;1419730;1.659978e+008
510.056;1.206856;-0.7447811;1451.203;149.958;0;0;0;3.801122;3.73066;1331834;1.556581e+008
514.056;1.193571;-0.7262487;1358.061;140.3332;0;0;0;3.759278;3.690339;1246353;1.456088e+008
518.056;1.180231;-0.7078654;1268.395;131.0677;0;0;0;3.717264;3.64984;1164062;1.359399e+008
522.056;1.166839;-0.689065;1182.545;122.1965;0;0;0;3.675082;3.609161;1085274;1.266874e+008
526.056;1.153499;-0.6703778;1099.465;113.6116;0;0;0;3.633069;3.568629;1009028;1.177392e+008
530.056;1.140214;-0.6514185;1018.88;105.2845;0;0;0;3.591224;3.528243;935071.6;1.090655e+008
534.056;1.126767;-0.6323243;940.082;97.142;0;0;0;3.548873;3.487352;862755.1;1.005894e+008
538.056;1.113428;-0.612754;862.8503;89.16137;0;0;0;3.506859;3.44677;791876.2;9.228814e+007
542.056;1.100142;-0.5915916;788.1765;81.44507;0;0;0;3.465015;3.406335;723344.8;8.426715e+007
546.056;1.086696;-0.5718274;714.8377;73.86671;0;0;0;3.422664;3.365394;656038.4;7.639492e+007
550.056;1.07341;-0.5512212;645.3;66.68114;0;0;0;3.380819;3.324926;592220.6;6.893551e+007
554.056;1.060178;-0.5303476;577.8648;59.71282;0;0;0;3.339143;3.284604;530332.3;6.170672e+007
558.056;1.046785;-0.5087718;512.0026;52.90704;0;0;0;3.296961;3.243777;469887.7;5.465137e+007
562.056;1.033553;-0.4890861;449.9606;46.49603;0;0;0;3.255285;3.203423;412948.9;4.80096e+007
566.056;1.020214;-0.4685857;390.1492;40.3155;0;0;0;3.213271;3.162726;358057.3;4.161094e+007
570.056;1.006874;-0.4482733;334.1911;34.53315;0;0;0;3.171258;3.122012;306702.1;3.562828e+007
574.056;0.9935351;-0.4307992;282.6199;29.20411;0;0;0;3.129244;3.081281;259372.9;3.011798e+007
578.056;0.9801421;-0.4184068;236.031;24.38992;0;0;0;3.087062;3.040371;216616.2;2.514285e+007
582.056;0.9668565;-0.4075817;193.3804;19.98269;0;0;0;3.045218;2.999771;177473.9;2.05912e+007
586.056;0.9534101;-0.398583;155.0059;16.01731;0;0;0;3.002867;2.958663;142255.8;1.649828e+007
590.056;0.9400709;-0.3934429;119.5502;12.35355;0;0;0;2.960853;2.917866;109716.6;1.271932e+007
594.056;0.9268387;-0.3849198;86.77888;8.967169;0;0;0;2.919177;2.87738;79640.84;9228936
597.114;0.9166065;-0.3811719;65.91989;6.811736;0;0;0;2.88695;2.846062;60497.62;7008387
600.116;0.9265708;-0.3816091;114.0528;11.78548;1;1;0;2.918333;2.876561;104671.4;1.212942e+007
604.116;0.9398565;-0.3841859;183.9211;19.00521;1;1;0;2.960178;2.917211;168792.5;1.95678e+007
608.116;0.9532494;-0.387901;254.9627;26.3462;1;1;0;3.00236;2.958172;233990.7;2.713721e+007
612.116;0.9666423;-0.3925479;329.4103;34.03913;1;1;0;3.044543;2.999116;302314.5;3.507547e+007
616.116;0.9798743;-0.3976444;410.1506;42.38231;1;1;0;3.086218;3.039552;376413.4;4.369032e+007
620.116;0.9933207;-0.4040188;493.2177;50.96593;1;1;0;3.128569;3.080627;452647.9;5.256044e+007
624.116;1.006714;-0.4119693;579.2081;59.85162;1;1;0;3.170752;3.121521;531565.1;6.174937e+007
628.116;1.019946;-0.4230656;672.976;69.54099;1;1;0;3.212427;3.161908;617620.1;7.177494e+007
632.116;1.033392;-0.4365465;770.3662;79.60467;1;1;0;3.254779;3.202933;706999.4;8.219563e+007
636.116;1.046678;-0.4508584;870.4428;89.94594;1;1;0;3.296623;3.24345;798844.2;9.291112e+007
640.116;1.05991;-0.4656668;971.585;100.3973;1;1;0;3.3383;3.283788;891666.8;1.037489e+008
644.116;1.073249;-0.4816617;1077.126;111.3033;1;1;0;3.380313;3.324436;988526.9;1.150657e+008
648.116;1.086535;-0.4979753;1182.183;122.1591;1;1;0;3.422158;3.364904;1084942;1.263396e+008
652.116;1.099928;-0.5151278;1287.891;133.0824;1;1;0;3.46434;3.405682;1181956;1.376928e+008
656.116;1.11316;-0.5324126;1391.208;143.7585;1;1;0;3.506016;3.445955;1276774;1.487987e+008
660.116;1.126606;-0.5500378;1495.325;154.5172;1;1;0;3.548367;3.486863;1372326;1.6e+008
664.116;1.139999;-0.5675337;1598.472;165.1758;1;1;0;3.590549;3.527591;1466989;1.711065e+008
668.116;1.153231;-0.5839628;1698.822;175.5453;1;1;0;3.632225;3.567814;1559085;1.819215e+008
672.116;1.166678;-0.601981;1798.285;185.8232;1;1;0;3.674576;3.608673;1650367;1.926514e+008
676.116;1.180017;-0.6201388;1896.942;196.0177;1;1;0;3.716589;3.649189;1740908;2.033029e+008
680.116;1.193249;-0.6385086;1995.074;206.1581;1;1;0;3.758265;3.689364;1830968;2.13906e+008
684.116;1.206696;-0.6576482;2095.482;216.5335;1;1;0;3.800616;3.730172;1923117;2.247631e+008
688.116;1.219981;-0.6772439;2194.745;226.7908;1;1;0;3.842461;3.770477;2014215;2.355051e+008
692.116;1.233213;-0.6972905;2294.12;237.0595;1;1;0;3.884137;3.810602;2105416;2.462672e+008
696.116;1.246553;-0.7168488;2395.311;247.5159;1;1;0;3.92615;3.851037;2198284;2.572338e+008
700.116;1.259838;-0.7367534;2494.727;257.789;1;1;0;3.967995;3.891293;2289523;2.680181e+008
704.116;1.273285;-0.7569347;2595.407;268.1926;1;1;0;4.010346;3.932019;2381921;2.789481e+008
708.116;1.286517;-0.7769176;2694.62;278.4446;1;1;0;4.052022;3.97208;2472973;2.897272e+008
712.116;1.299963;-0.7966086;2795.568;288.876;1;1;0;4.094373;4.012774;2565618;3.007036e+008
716.116;1.313303;-0.8164041;2896.096;299.2638;1;1;0;4.136387;4.053126;2657876;3.116425e+008
720.116;1.326588;-0.8358078;2995.958;309.5829;1;1;0;4.178231;4.093301;2749524;3.22518e+008
724.116;1.340035;-0.8554692;3096.657;319.9885;1;1;0;4.220582;4.133945;2841940;3.334939e+008
728.116;1.353374;-0.8746817;3196.715;330.3279;1;1;0;4.262596;4.174249;2933768;3.444084e+008
732.116;1.366606;-0.8941304;3294.896;340.4733;1;1;0;4.304272;4.214213;3023873;3.551282e+008
736.116;1.380053;-0.9137496;3395.506;350.8696;1;1;0;4.346622;4.254808;3116207;3.661206e+008
740.116;1.393285;-0.9332663;3493.505;360.9962;1;1;0;4.388299;4.29474;3206145;3.768378e+008
744.116;1.406517;-0.9527077;3590.446;371.0135;1;1;0;4.429975;4.334656;3295113;3.874493e+008
748.116;1.419856;-0.9729952;3686.61;380.9505;1;1;0;4.471988;4.374879;3383367;3.979865e+008
752.116;1.433196;-0.9933222;3779.524;390.5516;1;1;0;4.514002;4.415087;3468638;4.081811e+008
756.116;1.446588;-1.014831;3870.75;399.9783;1;1;0;4.556184;4.455439;3552360;4.18202e+008
758.192;1.447017;-1.019657;3844.059;397.2202;1;1;0;4.557534;4.45673;3527864;4.153237e+008
762.192;1.43341;-1.008248;3645.041;376.655;1;1;0;4.514677;4.415732;3345217;3.936598e+008
766.192;1.420124;-0.9964305;3468.559;358.4185;1;1;0;4.472832;4.375687;3183251;3.744499e+008
770.192;1.406892;-0.9840862;3302.158;341.2236;1;1;0;4.431156;4.335787;3030537;3.563438e+008
774.192;1.393499;-0.9716175;3141.79;324.6523;1;1;0;4.388974;4.295387;2883361;3.389012e+008
778.192;1.380213;-0.9584701;2987.323;308.6907;1;1;0;4.347129;4.255293;2741600;3.221099e+008
782.192;1.366981;-0.9447944;2839.274;293.3922;1;1;0;4.305453;4.215346;2605729;3.060241e+008
786.192;1.353588;-0.9312773;2696.678;278.6572;1;1;0;4.263271;4.174896;2474861;2.905371e+008
790.192;1.340249;-0.9168057;2559.996;264.5335;1;1;0;4.221257;4.134593;2349423;2.757001e+008
794.192;1.32691;-0.9021235;2427.191;250.8102;1;1;0;4.179244;4.094273;2227541;2.612922e+008
798.192;1.313571;-0.8873233;2300.783;237.7481;1;1;0;4.13723;4.053936;2111532;2.475843e+008
802.192;1.300178;-0.8719725;2178.18;225.079;1;1;0;4.095048;4.013422;1999013;2.342961e+008
806.192;1.286785;-0.8560544;2060.038;212.871;1;1;0;4.052866;3.972891;1890589;2.214984e+008
810.192;1.273553;-0.8403601;1946.667;201.156;1;1;0;4.01119;3.93283;1786543;2.092247e+008
814.192;1.260106;-0.8234561;1835.844;189.7043;1;1;0;3.968839;3.892104;1684836;1.972333e+008
818.192;1.246821;-0.8064391;1728.666;178.6291;1;1;0;3.926994;3.851849;1586474;1.856439e+008
822.192;1.233588;-0.7892834;1625.274;167.9453;1;1;0;3.885318;3.811739;1491587;1.744705e+008
826.192;1.220196;-0.7714115;1523.651;157.4443;1;1;0;3.843136;3.771127;1398323;1.634951e+008
830.192;1.20691;-0.7534627;1425.968;147.3503;1;1;0;3.801291;3.730822;1308675;1.529516e+008
834.192;1.193624;-0.7354388;1331.375;137.5757;1;1;0;3.759447;3.690502;1221862;1.427477e+008
838.192;1.180285;-0.7170586;1239.734;128.1061;1;1;0;3.717433;3.650002;1137759;1.328684e+008
842.192;1.166892;-0.6992857;1152.675;119.11;1;1;0;3.675251;3.609324;1057861;1.234876e+008
846.192;1.153553;-0.680903;1068.081;110.3686;1;1;0;3.633237;3.568791;980225.3;1.143785e+008
850.192;1.140267;-0.6627917;985.2735;101.8118;1;1;0;3.591393;3.528406;904229.4;1.054683e+008
854.192;1.126821;-0.6430241;904.1316;93.42712;1;1;0;3.549042;3.487514;829761.9;9.674289e+007
858.192;1.113481;-0.6237314;825.8313;85.33607;1;1;0;3.507028;3.446933;757902.3;8.832883e+007
862.192;1.100196;-0.6032975;748.446;77.33957;1;1;0;3.465183;3.406498;686882.3;8.001953e+007
866.192;1.086749;-0.5833575;673.2768;69.57207;1;1;0;3.422832;3.365557;617896.1;7.195341e+007
870.192;1.073464;-0.5627476;601.3845;62.14319;1;1;0;3.380988;3.325089;551917.4;6.424424e+007
874.192;1.060232;-0.543809;531.2637;54.89736;1;1;0;3.339312;3.284768;487564.4;5.673056e+007
878.192;1.046892;-0.5238921;463.2447;47.86871;1;1;0;3.297298;3.244104;425140.3;4.944709e+007
882.192;1.033606;-0.5043363;399.4498;41.27657;1;1;0;3.255453;3.203586;366592.9;4.262031e+007
886.192;1.020267;-0.4852084;338.9717;35.02715;1;1;0;3.21344;3.162889;311089.4;3.615272e+007
890.192;1.006928;-0.4694568;282.4105;29.18248;1;1;0;3.171427;3.122175;259180.7;3.010798e+007
894.192;0.9935351;-0.4576593;233.6304;24.14186;1;1;0;3.129244;3.081281;214413.1;2.489732e+007
898.192;0.9801957;-0.4480356;187.386;19.36326;1;1;0;3.08723;3.040534;171972.5;1.996105e+007
902.192;0.9669102;-0.441101;146.2881;15.11646;1;1;0;3.045386;2.999935;134255.1;1.557682e+007
906.0941;0.9537316;-0.4348703;108.6271;11.22483;1;1;0;3.003879;2.959646;99691.98;1.156201e+007
909.0961;0.9637494;-0.4367578;170.579;17.62653;2;2;0;3.035431;2.990274;156547.9;1.816157e+007
913.0961;0.9771958;-0.4406634;248.5291;25.68139;2;2;0;3.077782;3.031368;228086.2;2.647181e+007
917.0961;0.9904279;-0.4452116;329.8523;34.08481;2;2;0;3.119458;3.071792;302720.2;3.514807e+007
921.0961;1.003874;-0.4510608;415.3208;42.91657;2;2;0;3.161809;3.112853;381158.4;4.427351e+007
925.0961;1.017214;-0.4583706;502.1079;51.88459;2;2;0;3.203822;3.15357;460806.8;5.354688e+007
929.0961;1.030499;-0.4686265;595.6195;61.54747;2;2;0;3.245667;3.194108;546626.6;6.35451e+007
933.0961;1.043946;-0.4814328;695.74;71.89328;2;2;0;3.288018;3.235119;638511.7;7.425715e+007
937.0961;1.057285;-0.4952159;797.6821;82.42732;2;2;0;3.330032;3.275787;732068.5;8.517218e+007
941.0961;1.070517;-0.5093939;901.6661;93.17236;2;2;0;3.371707;3.316112;827499.2;9.631385e+007
945.0961;1.08391;-0.5248896;1009.387;104.3035;2;2;0;3.41389;3.35691;926359.4;1.078643e+008
949.0961;1.097142;-0.5409199;1114.491;115.1643;2;2;0;3.455566;3.397202;1022818;1.191439e+008
953.0961;1.110481;-0.5577545;1221.73;126.2457;2;2;0;3.497579;3.437804;1121236;1.306613e+008
957.0961;1.123767;-0.5751418;1328.003;137.2272;2;2;0;3.539424;3.478226;1218768;1.420843e+008
961.0961;1.137106;-0.5919753;1433.78;148.1575;2;2;0;3.581438;3.518795;1315844;1.534637e+008
965.0961;1.150553;-0.6086539;1540.565;159.192;2;2;0;3.623788;3.559673;1413845;1.649608e+008
969.0961;1.163785;-0.6253611;1644.922;169.9756;2;2;0;3.665464;3.599884;1509619;1.76206e+008
973.0961;1.177231;-0.6431514;1748.76;180.7055;2;2;0;3.707816;3.640729;1604915;1.874058e+008
977.0961;1.190571;-0.6611415;1851.02;191.2725;2;2;0;3.749829;3.681232;1698764;1.984448e+008
981.0961;1.203856;-0.6786864;1953.268;201.8381;2;2;0;3.791673;3.721556;1792601;2.094911e+008
985.0961;1.217303;-0.6977483;2057.154;212.573;2;2;0;3.834024;3.762352;1887942;2.207231e+008
989.0961;1.230589;-0.716081;2160.359;223.2375;2;2;0;3.875869;3.802644;1982658;2.318899e+008
993.0961;1.243821;-0.7347156;2263.491;233.8945;2;2;0;3.917545;3.842756;2077307;2.430575e+008
997.0961;1.257213;-0.7540325;2368.171;244.7115;2;2;0;3.959727;3.88334;2173376;2.544014e+008
1001.096;1.270499;-0.773029;2471.681;255.4075;2;2;0;4.001572;3.923583;2268372;2.656279e+008
1005.096;1.283785;-0.7921997;2575.829;266.1696;2;2;0;4.043417;3.963809;2363954;2.769319e+008
1009.096;1.297124;-0.8105344;2680.477;276.9831;2;2;0;4.08543;4.004182;2459993;2.882991e+008
1013.096;1.310463;-0.8293349;2785.341;287.8191;2;2;0;4.127444;4.044538;2556232;2.996987e+008
1017.096;1.32391;-0.8478498;2892.007;298.8413;2;2;0;4.169795;4.085202;2654124;3.113024e+008
1021.096;1.337088;-0.8659396;2996.757;309.6655;2;2;0;4.211302;4.12504;2750257;3.227064e+008
1025.096;1.350588;-0.8846931;3104.121;320.7599;2;2;0;4.253822;4.165833;2848791;3.344044e+008
1029.096;1.363928;-0.9028915;3209.925;331.6929;2;2;0;4.295835;4.206125;2945891;3.459419e+008
1033.096;1.377213;-0.9209857;3316.133;342.6677;2;2;0;4.33768;4.246237;3043363;3.575315e+008
1037.096;1.390606;-0.9396399;3424.475;353.8632;2;2;0;4.379862;4.286658;3142794;3.693619e+008
1041.096;1.403945;-0.9578599;3530.775;364.8475;2;2;0;4.421875;4.3269;3240350;3.809806e+008
1045.096;1.417124;-0.9754999;3635.565;375.6758;2;2;0;4.463383;4.366642;3336520;3.924436e+008
1049.096;1.430517;-0.9937232;3742.086;386.683;2;2;0;4.505565;4.407014;3434279;4.041053e+008
1053.096;1.443749;-1.012716;3845.894;397.4099;2;2;0;4.547241;4.446885;3529549;4.154811e+008
1057.096;1.457142;-1.032948;3947.307;407.8893;2;2;0;4.589423;4.487225;3622620;4.26609e+008
1061.096;1.470428;-1.054894;4035.645;417.0175;2;2;0;4.631268;4.527225;3703692;4.363307e+008
1065.096;1.48382;-1.07969;4112.342;424.9429;2;2;0;4.67345;4.567532;3774080;4.448024e+008
1069.096;1.497213;-1.104636;4180.754;432.0121;2;2;0;4.715633;4.607823;3836864;4.523842e+008
1073.096;1.510445;-1.129627;4242.045;438.3456;2;2;0;4.757308;4.647614;3893114;4.59199e+008
1077.096;1.523892;-1.156661;4301.973;444.5381;2;2;0;4.799659;4.688034;3948112;4.658744e+008
1081.096;1.537285;-1.183028;4359.684;450.5015;2;2;0;4.841842;4.728276;4001076;4.723141e+008
1085.096;1.550517;-1.21065;4414.44;456.1598;2;2;0;4.883518;4.768019;4051329;4.784364e+008
1089.096;1.563963;-1.23839;4470.769;461.9803;2;2;0;4.925869;4.80839;4103024;4.847369e+008
1093.096;1.577195;-1.266246;4524.056;467.4868;2;2;0;4.967545;4.848102;4151928;4.907094e+008
1097.096;1.590481;-1.29523;4576.665;472.923;2;2;0;5.009389;4.887958;4200210;4.966136e+008
1101.096;1.60382;-1.323057;4631.973;478.6382;2;2;0;5.051403;4.92796;4250969;5.028161e+008
1105.096;1.617106;-1.351997;4684.747;484.0915;2;2;0;5.093247;4.967784;4299402;5.087475e+008
1109.096;1.630499;-1.380298;4739.478;489.747;2;2;0;5.13543;5.007914;4349630;5.148976e+008
1113.096;1.643731;-1.40849;4793.023;495.2801;2;2;0;5.177106;5.047546;4398772;5.209213e+008
1117.096;1.657177;-1.4377;4846.931;500.8505;2;2;0;5.219457;5.087805;4448245;5.269922e+008
1121.096;1.67057;-1.466067;4901.059;506.4438;2;2;0;5.261639;5.127887;4497920;5.33091e+008
1125.096;1.683803;-1.49452;4953.707;511.884;2;2;0;5.303315;5.167472;4546238;5.390309e+008
1129.096;1.697249;-1.52079;5005.855;517.2728;2;2;0;5.345666;5.207681;4594097;5.449244e+008
1133.096;1.710588;-1.550818;5058.978;522.7621;2;2;0;5.387679;5.247555;4642850;5.509269e+008
1137.096;1.723874;-1.575787;5110.606;528.097;2;2;0;5.429524;5.287253;4690231;5.567702e+008
1141.096;1.73732;-1.603662;5164.268;533.6422;2;2;0;5.471875;5.327414;4739480;5.628424e+008
1145.096;1.750499;-1.630824;5214.138;538.7953;2;2;0;5.513382;5.36676;4785247;5.685012e+008
1149.096;1.763785;-1.657703;5265.511;544.1039;2;2;0;5.555227;5.406411;4832394;5.743301e+008
1153.096;1.777124;-1.684892;5317.825;549.5097;2;2;0;5.59724;5.446205;4880405;5.802671e+008
1157.096;1.79041;-1.712439;5368.148;554.7097;2;2;0;5.639085;5.485824;4926589;5.859903e+008
1161.096;1.803856;-1.739129;5421.11;560.1824;2;2;0;5.681436;5.525906;4975194;5.920089e+008
1165.096;1.817088;-1.764732;5471.359;565.3749;2;2;0;5.723113;5.565334;5021310;5.977319e+008
1169.096;1.830535;-1.791303;5522.991;570.7102;2;2;0;5.765463;5.605385;5068695;6.036143e+008
1173.096;1.843927;-1.817244;5574.313;576.0135;2;2;0;5.807645;5.645259;5115796;6.094663e+008
1177.096;1.85716;-1.842469;5623.193;581.0645;2;2;0;5.849322;5.68464;5160655;6.150528e+008
1181.096;1.87066;-1.868165;5674.579;586.3743;2;2;0;5.891841;5.724802;5207814;6.209226e+008
1185.096;1.883945;-1.893746;5724.156;591.4973;2;2;0;5.933686;5.764311;5253313;6.265949e+008
1189.096;1.897177;-1.918979;5771.884;596.4293;2;2;0;5.975362;5.803645;5297116;6.320681e+008
1193.096;1.910624;-1.944814;5822.129;601.6212;2;2;0;6.017713;5.8436;5343227;6.37825e+008
1197.096;1.923802;-1.970249;5867.941;606.3551;2;2;0;6.05922;5.882743;5385271;6.430955e+008
1200.95;1.93666;-1.998544;5911.878;610.8953;2;2;0;6.099715;5.920917;5425594;6.481581e+008
1203.952;1.926749;-1.993293;5731.945;592.3022;2;2;0;6.0685;5.891493;5260462;6.28246e+008
1207.952;1.913249;-1.982249;5515.784;569.9655;2;2;0;6.02598;5.851398;5062082;6.043115e+008
1211.952;1.899963;-1.970974;5315.137;549.2319;2;2;0;5.984136;5.811923;4877938;5.820987e+008
1215.952;1.886731;-1.959177;5124.074;529.4887;2;2;0;5.94246;5.772593;4702592;5.609534e+008
1219.952;1.873392;-1.946996;4936.254;510.0806;2;2;0;5.900446;5.732928;4530221;5.401776e+008
1223.952;1.860106;-1.934271;4753.116;491.1563;2;2;0;5.858602;5.693407;4362147;5.199312e+008
1227.952;1.846767;-1.921281;4575.706;472.8239;2;2;0;5.816588;5.653711;4199329;5.003261e+008
1231.952;1.833427;-1.908463;4404.347;455.1168;2;2;0;5.774574;5.613999;4042066;4.813978e+008
1235.952;1.820088;-1.895068;4238.317;437.9603;2;2;0;5.732561;5.574271;3889693;4.630667e+008
1239.952;1.806695;-1.881649;4075.525;421.1384;2;2;0;5.690379;5.534368;3740291;4.451027e+008
1243.952;1.793409;-1.867653;3918.135;404.8748;2;2;0;5.648534;5.494768;3595847;4.277443e+008
1247.952;1.779963;-1.853453;3764.051;388.9527;2;2;0;5.606184;5.454674;3454437;4.107581e+008
1251.952;1.766624;-1.839155;3615.26;373.5776;2;2;0;5.56417;5.414883;3317886;3.943641e+008
1255.952;1.753392;-1.825151;3473.119;358.8897;2;2;0;5.522493;5.375395;3187436;3.787094e+008
1259.952;1.739945;-1.810014;3334.476;344.5632;2;2;0;5.480143;5.335253;3060197;3.634458e+008
1263.952;1.72666;-1.795764;3200.719;330.7417;2;2;0;5.438298;5.295574;2937443;3.487284e+008
1267.952;1.713427;-1.781335;3072.605;317.5032;2;2;0;5.396622;5.25604;2819867;3.346376e+008
1271.952;1.700035;-1.766009;2945.189;304.3369;2;2;0;5.35444;5.21601;2702932;3.206324e+008
1275.952;1.686803;-1.751545;2823.837;291.7971;2;2;0;5.312764;5.176444;2591561;3.072995e+008
1279.952;1.67341;-1.736471;2703.392;279.3511;2;2;0;5.270582;5.136382;2481024;2.940745e+008
1283.952;1.660124;-1.720914;2586.521;267.2743;2;2;0;5.228736;5.096624;2373765;2.812494e+008
1287.952;1.646731;-1.705244;2472.453;255.4874;2;2;0;5.186554;5.056529;2269081;2.687383e+008
1291.952;1.633338;-1.689551;2361.802;244.0534;2;2;0;5.144372;5.01642;2167531;2.566084e+008
1295.952;1.620106;-1.673851;2255.187;233.0364;2;2;0;5.102696;4.976775;2069685;2.449276e+008
1299.952;1.606606;-1.657806;2151.285;222.2999;2;2;0;5.060177;4.936311;1974330;2.335486e+008
1303.952;1.593267;-1.641807;2050.912;211.928;2;2;0;5.018163;4.896313;1882214;2.225629e+008
1307.952;1.580035;-1.625684;1954.338;201.9487;2;2;0;4.976487;4.856621;1793583;2.119986e+008
1311.952;1.566642;-1.609162;1859.45;192.1436;2;2;0;4.934305;4.81643;1706501;2.016245e+008
1315.952;1.553356;-1.592647;1768.165;182.7108;2;2;0;4.89246;4.776545;1622724;1.916498e+008
1319.952;1.540124;-1.575895;1680.369;173.6385;2;2;0;4.850784;4.736805;1542150;1.820613e+008
1323.952;1.526731;-1.558995;1593.679;164.6805;2;2;0;4.808602;4.696566;1462590;1.725993e+008
1327.952;1.513445;-1.541589;1510.692;156.1051;2;2;0;4.766757;4.656633;1386429;1.635463e+008
1331.952;1.500106;-1.524282;1429.244;147.6888;2;2;0;4.724744;4.616523;1311681;1.546667e+008
1335.952;1.486767;-1.506687;1350.293;139.5306;2;2;0;4.68273;4.576397;1239225;1.460644e+008
1339.952;1.473374;-1.488478;1273.378;131.5827;2;2;0;4.640548;4.536094;1168636;1.376888e+008
1343.952;1.459981;-1.470504;1197.131;123.7038;2;2;0;4.598366;4.495774;1098660;1.293921e+008
1347.952;1.446749;-1.451901;1123.578;116.1033;2;2;0;4.55669;4.455923;1031158;1.213938e+008
1351.952;1.433249;-1.433855;1052.841;108.7938;2;2;0;4.514171;4.415248;966239.1;1.137049e+008
1355.952;1.419963;-1.414299;983.6131;101.6402;2;2;0;4.472326;4.375202;902705.6;1.061859e+008
1359.952;1.406731;-1.3952;916.2323;94.67753;2;2;0;4.430649;4.335302;840867.3;9.887236e+007
1363.952;1.393338;-1.376121;849.6793;87.80037;2;2;0;4.388468;4.294902;779788.6;9.165346e+007
1367.952;1.380053;-1.355248;785.2109;81.13862;2;2;0;4.346622;4.254808;720623.1;8.466541e+007
1371.952;1.366821;-1.334065;722.7757;74.68697;2;2;0;4.304946;4.21486;663323.5;7.790221e+007
1375.952;1.353428;-1.314024;661.6582;68.37148;2;2;0;4.262765;4.174411;607233.2;7.1286e+007
1379.952;1.340088;-1.292391;603.4456;62.35617;2;2;0;4.220751;4.134107;553808.9;6.498807e+007
1383.952;1.326749;-1.27009;546.5079;56.47259;2;2;0;4.178737;4.093786;501554.6;5.883243e+007
1387.952;1.313463;-1.249238;491.4276;50.78096;2;2;0;4.136893;4.053612;451005.1;5.288171e+007
1391.952;1.300017;-1.227719;437.8308;45.2426;2;2;0;4.094542;4.012936;401816.8;4.709508e+007
1395.952;1.286678;-1.205249;386.4333;39.93153;2;2;0;4.052528;3.972567;354647.1;4.154976e+007
1399.952;1.273392;-1.183417;337.2979;34.85419;2;2;0;4.010684;3.932343;309553.3;3.625208e+007
1403.952;1.259946;-1.162172;290.2753;29.99517;2;2;0;3.968333;3.891617;266398.6;3.118548e+007
1407.952;1.246606;-1.141757;247.044;25.52793;2;2;0;3.926319;3.851199;226723.3;2.653024e+007
1411.952;1.233374;-1.123782;207.1869;21.40936;2;2;0;3.884643;3.81109;190144.7;2.224104e+007
1415.952;1.219981;-1.109184;170.7057;17.63963;2;2;0;3.842461;3.770477;156664.3;1.831742e+007
1419.952;1.206749;-1.095162;137.0721;14.16415;2;2;0;3.800785;3.730335;125797.2;1.47025e+007
1423.952;1.193463;-1.081325;106.9268;11.04912;2;2;0;3.75894;3.690014;98131.45;1.146445e+007
1427.952;1.180071;-1.067976;80.41331;8.309392;2;2;0;3.716758;3.649352;73798.88;8618232
1430.06;1.186446;-1.068795;115.6907;11.95473;3;3;0;3.736837;3.668709;106174.5;1.240146e+007
1434.06;1.199731;-1.073183;187.1254;19.33633;3;3;0;3.778682;3.709038;171733.3;2.006699e+007
1438.06;1.212963;-1.0785;264.6522;27.34745;3;3;0;3.820357;3.749189;242883.1;2.839222e+007
1442.06;1.226356;-1.084955;345.3247;35.68362;3;3;0;3.86254;3.789811;316919.9;3.706192e+007
1446.06;1.239588;-1.092293;430.339;44.46845;3;3;0;3.904216;3.829928;394941.3;4.62046e+007
1450.06;1.252981;-1.101244;520.1288;53.74675;3;3;0;3.946398;3.870517;477345.4;5.586781e+007
1454.06;1.266214;-1.112404;613.5792;63.40331;3;3;0;3.988074;3.910603;563108.9;6.593188e+007
1458.06;1.27966;-1.12547;713.5233;73.73089;3;3;0;4.030425;3.951322;654832.2;7.670256e+007
1462.06;1.293053;-1.139337;815.8285;84.30244;3;3;0;4.072607;3.991861;748722.2;8.773575e+007
1466.06;1.306285;-1.154293;916.8942;94.74593;3;3;0;4.114283;4.031898;841474.7;9.864404e+007
1470.06;1.319785;-1.169762;1020.549;105.457;3;3;0;4.156803;4.07273;936603.6;1.098406e+008
1474.06;1.333124;-1.185032;1124.742;116.2236;3;3;0;4.198816;4.113058;1032226;1.211036e+008
1478.06;1.346356;-1.200771;1227.931;126.8865;3;3;0;4.240492;4.153046;1126927;1.322671e+008
1482.06;1.359803;-1.217261;1331.585;137.5974;3;3;0;4.282843;4.193667;1222055;1.434905e+008
1486.06;1.373035;-1.233858;1436.054;148.3925;3;3;0;4.324519;4.233623;1317931;1.548098e+008
1490.06;1.386321;-1.251201;1540.963;159.2331;3;3;0;4.366364;4.273725;1414210;1.661858e+008
1494.06;1.39966;-1.268297;1646.046;170.0917;3;3;0;4.408377;4.313973;1510649;1.7759e+008
1498.06;1.412946;-1.284992;1746.974;180.5211;3;3;0;4.450222;4.354043;1603276;1.885546e+008
1502.06;1.426338;-1.301475;1847.626;190.9217;3;3;0;4.492404;4.394419;1695648;1.994987e+008
1506.06;1.43957;-1.317466;1947.177;201.2087;3;3;0;4.53408;4.434296;1787011;2.103316e+008
1510.06;1.453017;-1.334232;2048.252;211.6531;3;3;0;4.576432;4.474802;1879772;2.213393e+008
1514.06;1.46641;-1.350805;2149.797;222.1462;3;3;0;4.618613;4.51513;1972965;2.324063e+008
1518.06;1.479642;-1.368126;2251.172;232.6215;3;3;0;4.660289;4.554958;2066001;2.434624e+008
1522.06;1.493142;-1.385596;2353.827;243.2293;3;3;0;4.702809;4.595576;2160212;2.546679e+008
1526.06;1.506428;-1.402553;2454.604;253.6429;3;3;0;4.744654;4.635534;2252700;2.656774e+008
1530.06;1.51966;-1.420238;2555.386;264.0571;3;3;0;4.78633;4.675314;2345192;2.766957e+008
1534.06;1.533053;-1.437812;2658.279;274.6894;3;3;0;4.828512;4.715561;2439621;2.879528e+008
1538.06;1.546338;-1.455772;2759.875;285.1876;3;3;0;4.870357;4.755471;2532860;2.990773e+008
1542.06;1.559624;-1.473938;2862.499;295.7921;3;3;0;4.912201;4.795364;2627043;3.10322e+008
1546.06;1.572963;-1.49288;2966.665;306.556;3;3;0;4.954215;4.835402;2722641;3.217435e+008
1550.06;1.586249;-1.511404;3071.175;317.3554;3;3;0;4.99606;4.875264;2818554;3.332106e+008
1554.06;1.599695;-1.530123;3177.068;328.2977;3;3;0;5.038411;4.915591;2915737;3.448387e+008
1558.06;1.612927;-1.548574;3282.625;339.2053;3;3;0;5.080086;4.95526;3012612;3.564372e+008
1562.06;1.626374;-1.566969;3389.767;350.2766;3;3;0;5.122437;4.995555;3110940;3.682193e+008
1566.06;1.639713;-1.585932;3497.931;361.4536;3;3;0;5.164451;5.035514;3210207;3.801207e+008
1570.06;1.652999;-1.60391;3606.16;372.6373;3;3;0;5.206296;5.075296;3309534;3.920379e+008
1574.06;1.666445;-1.62271;3716.412;384.03;3;3;0;5.248647;5.115543;3410717;4.041864e+008
1578.06;1.679785;-1.641158;3826.06;395.3603;3;3;0;5.29066;5.155453;3511346;4.162775e+008
1582.06;1.693017;-1.65954;3934.279;406.543;3;3;0;5.332336;5.195027;3610663;4.282212e+008
1586.06;1.70641;-1.678103;4045.265;418.0115;3;3;0;5.374519;5.235066;3712520;4.404776e+008
1590.06;1.719642;-1.696728;4154.065;429.2542;3;3;0;5.416194;5.274609;3812371;4.525035e+008
1594.06;1.732981;-1.715741;4264.369;440.6523;3;3;0;5.458208;5.314456;3913602;4.647041e+008
1598.06;1.746267;-1.733774;4375.684;452.1549;3;3;0;5.500053;5.354127;4015760;4.770237e+008
1602.06;1.759606;-1.752482;4487.278;463.6863;3;3;0;5.542066;5.393942;4118175;4.893841e+008
1606.06;1.772999;-1.771128;4599.212;475.2528;3;3;0;5.584249;5.433901;4220902;5.017921e+008
1610.06;1.786231;-1.789783;4709.876;486.6882;3;3;0;5.625925;5.473365;4322464;5.140689e+008
1614.06;1.799677;-1.808527;4823.619;498.4416;3;3;0;5.668275;5.513452;4426850;5.266947e+008
1618.06;1.81307;-1.827183;4935.026;509.9537;3;3;0;5.710457;5.553364;4529094;5.390744e+008
1622.06;1.826302;-1.845511;5044.861;521.3034;3;3;0;5.752134;5.592781;4629895;5.512895e+008
1626.06;1.839749;-1.864552;5156.002;532.7879;3;3;0;5.794485;5.63282;4731893;5.636602e+008
1630.06;1.853088;-1.883142;5264.857;544.0363;3;3;0;5.836498;5.672524;4831794;5.75789e+008
1634.06;1.86632;-1.901929;5370.682;554.9716;3;3;0;5.878174;5.711894;4928915;5.875938e+008
1638.06;1.879713;-1.921121;5479.212;566.1863;3;3;0;5.920356;5.751727;5028517;5.997066e+008
1642.06;1.892999;-1.940062;5581.58;576.7643;3;3;0;5.962201;5.791225;5122465;6.111522e+008
1646.06;1.906285;-1.959493;5681.272;587.0659;3;3;0;6.004046;5.830708;5213957;6.223136e+008
1650.06;1.91957;-1.979251;5777.108;596.969;3;3;0;6.04589;5.870174;5301910;6.330611e+008
1654.06;1.932963;-2.000479;5866.704;606.2272;3;3;0;6.088073;5.909944;5384136;6.431348e+008
1656.212;1.926909;-1.997514;5750.99;594.2701;3;3;0;6.069006;5.89197;5277940;6.303364e+008
1660.212;1.91341;-1.986803;5530.561;571.4925;3;3;0;6.026486;5.851875;5075643;6.059334e+008
1664.212;1.900124;-1.975639;5326.586;550.415;3;3;0;5.984642;5.812401;4888446;5.833554e+008
1668.212;1.886945;-1.964123;5131.845;530.2917;3;3;0;5.943135;5.77323;4709723;5.618077e+008
1672.212;1.873552;-1.951912;4940.29;510.4976;3;3;0;5.900952;5.733406;4533924;5.406218e+008
1676.212;1.860267;-1.939515;4753.853;491.2325;3;3;0;5.859108;5.693885;4362823;5.200143e+008
1680.212;1.846927;-1.926922;4572.628;472.5059;3;3;0;5.817094;5.654189;4196505;4.99992e+008
1684.212;1.833588;-1.913999;4398.207;454.4823;3;3;0;5.775081;5.614478;4036431;4.80729e+008
1688.212;1.820195;-1.900741;4228.739;436.9706;3;3;0;5.732899;5.57459;3880902;4.620216e+008
1692.212;1.806802;-1.887688;4063.147;419.8594;3;3;0;5.690716;5.534687;3728932;4.437524e+008
1696.212;1.793517;-1.87394;3903.28;403.3397;3;3;0;5.648871;5.495088;3582214;4.261239e+008
1700.212;1.78007;-1.86011;3746.908;387.1812;3;3;0;5.606521;5.454993;3438704;4.088886e+008
1704.212;1.766731;-1.846038;3596.068;371.5945;3;3;0;5.564507;5.415202;3300272;3.922719e+008
1708.212;1.753552;-1.832014;3451.944;356.7016;3;3;0;5.523;5.375875;3168003;3.764023e+008
1712.212;1.740106;-1.81764;3311.145;342.1523;3;3;0;5.480649;5.335732;3038786;3.609045e+008
1716.212;1.72682;-1.803425;3175.571;328.143;3;3;0;5.438804;5.296054;2914363;3.4599e+008
1720.212;1.713588;-1.788989;3044.806;314.6306;3;3;0;5.397128;5.25652;2794354;3.316116e+008
1724.212;1.700249;-1.774507;2915.895;301.3098;3;3;0;5.355114;5.21665;2676047;3.174453e+008
1728.212;1.68691;-1.759877;2792.097;288.5172;3;3;0;5.313101;5.176764;2562432;3.038464e+008
1732.212;1.67357;-1.744967;2669.502;275.8492;3;3;0;5.271088;5.136863;2449922;2.903894e+008
1736.212;1.660231;-1.72978;2550.885;263.592;3;3;0;5.229074;5.096945;2341061;2.773754e+008
1740.212;1.646838;-1.715097;2435.013;251.6185;3;3;0;5.186892;5.056851;2234720;2.646697e+008
1744.212;1.633499;-1.69941;2322.483;239.9904;3;3;0;5.144879;5.016901;2131447;2.523377e+008
1748.212;1.620213;-1.684323;2214.368;228.8185;3;3;0;5.103034;4.977095;2032224;2.404952e+008
1752.212;1.606767;-1.668157;2108.663;217.8956;3;3;0;5.060683;4.936793;1935214;2.289226e+008
1756.212;1.593428;-1.652436;2006.822;207.372;3;3;0;5.01867;4.896795;1841750;2.177793e+008
1760.212;1.580195;-1.636546;1908.398;197.2015;3;3;0;4.976994;4.857103;1751422;2.070162e+008
1764.212;1.566803;-1.620275;1811.945;187.2347;3;3;0;4.934811;4.816912;1662903;1.964744e+008
1768.212;1.553517;-1.603829;1719.611;177.6935;3;3;0;4.892967;4.777028;1578163;1.863879e+008
1772.212;1.540285;-1.587541;1630.268;168.4614;3;3;0;4.85129;4.737287;1496170;1.766339e+008
1776.212;1.526892;-1.570633;1542.106;159.3512;3;3;0;4.809108;4.697049;1415259;1.670146e+008
1780.212;1.513606;-1.55362;1457.645;150.6237;3;3;0;4.767263;4.657116;1337746;1.578043e+008
1784.212;1.500213;-1.537047;1374.247;142.0058;3;3;0;4.725081;4.616846;1261208;1.487157e+008
1788.212;1.486928;-1.519795;1294.01;133.7146;3;3;0;4.683236;4.576881;1187570;1.399768e+008
1792.212;1.473481;-1.50208;1214.699;125.5191;3;3;0;4.640885;4.536416;1114783;1.313443e+008
1796.212;1.460088;-1.483857;1137.071;117.4976;3;3;0;4.598703;4.496097;1043541;1.22901e+008
1800.212;1.446856;-1.46617;1061.671;109.7062;3;3;0;4.557027;4.456245;974342.4;1.147055e+008
1804.212;1.43341;-1.446902;987.587;102.0509;3;3;0;4.514677;4.415732;906352.6;1.066581e+008
1808.212;1.420124;-1.427853;916.4024;94.6951;3;3;0;4.472832;4.375687;841023.3;9.893065e+007
1812.212;1.406892;-1.409196;846.4151;87.46307;3;3;0;4.431156;4.335787;776792.9;9.133869e+007
1816.212;1.393499;-1.38938;777.9664;80.39002;3;3;0;4.388974;4.295387;713974.4;8.391832e+007
1820.212;1.380213;-1.369656;712.3534;73.61;3;3;0;4.347129;4.255293;653758.5;7.680992e+007
1824.212;1.366981;-1.349637;647.2148;66.879;3;3;0;4.305453;4.215346;593977.9;6.975844e+007
1828.212;1.353535;-1.329885;584.1036;60.35749;3;3;0;4.263102;4.174735;536057.9;6.293059e+007
1832.212;1.340249;-1.309955;524.0528;54.15223;3;3;0;4.221257;4.134593;480946.6;5.643813e+007
1836.212;1.32691;-1.289214;464.1187;47.95903;3;3;0;4.179244;4.094273;425942.4;4.996335e+007
1840.212;1.313571;-1.268819;407.3243;42.09026;3;3;0;4.13723;4.053936;373819.6;4.383163e+007
1844.212;1.300124;-1.248697;351.7929;36.35201;3;3;0;4.094879;4.01326;322856.1;3.784058e+007
1848.212;1.286785;-1.229553;299.1568;30.91293;3;3;0;4.052866;3.972891;274549.6;3.216579e+007
1852.212;1.273553;-1.212152;250.4899;25.88401;3;3;0;4.01119;3.93283;229885.8;2.692227e+007
1856.212;1.260053;-1.197466;205.5589;21.24113;3;3;0;3.96867;3.891942;188650.5;2.208411e+007
1860.212;1.246767;-1.185411;164.0689;16.95382;3;3;0;3.926825;3.851686;150573.3;1.761957e+007
1864.212;1.233535;-1.173373;126.4264;13.06408;3;3;0;3.885149;3.811577;116027.1;1.357164e+007
1868.212;1.220196;-1.162101;93.26035;9.636922;3;3;0;3.843136;3.771127;85589.18;1.000728e+007
1872.146;1.207124;-1.153616;64.47627;6.662562;3;3;0;3.801966;3.731473;59172.75;6915870