File: Ensayos/Graficos/EspA/EspA40Ext125.raw
"Test Type";"Manual"
"Method Name:";"C:\INSTRON\user\template\CYCLE.MTM"
"Name:";""
"Operator ID:";""
"Company:";""
"Lab name:";""
"Test date:";"04/04/2017"
"Temperature:";""
"Humidity:";""
"Note 1:";""
"Note 2:";""
"Note 3:";""
"Geometry:";"Rectangular"
"Specimen";1
"Specimen name:";""
"Width:";0.250000;"in"
"Thickness:";0.060000;"in"
"Length:";1.250000;"in"
"Diameter:";0.039370;"in"
"Inner diameter:";0.019685;"in"
"Outer diameter:";0.039370;"in"
"Wall thickness:";0.019685;"in"
"Area:";0.015000;"in*in"
"Linear density:";1.000000;"den"
"Sled weight:";2.204623;"lbf"
"Loading span:";0.000000;"mm"
"Support span:";1.000000;"mm"
"Span ratio:";"2"
"Fixture type:";"3-point"
"Comment:";""
"Included"
"Final Width:";0.250000;"in"
"Final Thickness:";0.060000;"in"
"Final Length:";1.250000;"in"
"Final Diameter:";0.039370;"in"
"Final Inner diameter:";0.019685;"in"
"Final Outer diameter:";0.039370;"in"
"Final Wall thickness:";0.019685;"in"
"Final Area:";0.015000;"in*in"
"Final Linear density:";1.000000;"den"
"Time sec";"Extension mm";"Strain 1 %";"Load N";"Stress MPa";"Cycle Count ";"Total Cycle Count ";"Repetitions Count ";"Strain [Exten.] %";"True strain %";"Tenacity gf/tex";"True stress Pa"
0;0.008785709;-0.0002606673;43.57435;4.502692;0;0;0;0.02767153;0.0276677;39990.13;4503938
3;0.01874999;-0.0007839988;47.94943;4.954785;0;0;0;0.05905508;0.05903765;44005.34;4957711
6;0.02876784;-0.00376053;93.16071;9.626626;0;0;0;0.09060737;0.09056634;85497.74;9635349
9;0.03878569;-0.007719298;149.395;15.43751;0;0;0;0.1221596;0.1220851;137106.4;1.545637e+007
12;0.04874997;-0.01242901;212.1045;21.91751;0;0;0;0.1535432;0.1534255;194657.7;2.195116e+007
15;0.05876782;-0.01809709;278.3456;28.76244;0;0;0;0.1850955;0.1849244;255450.2;2.881567e+007
18;0.06878567;-0.0240409;346.7482;35.83072;0;0;0;0.2166478;0.2164134;318226.3;3.590835e+007
21;0.07880351;-0.03029376;418.5732;43.25265;0;0;0;0.2482;0.2478925;384143.3;4.336e+007
24;0.08882137;-0.03672877;491.7293;50.81213;0;0;0;0.2797523;0.2793618;451281.9;5.095427e+007
27;0.09883923;-0.04356508;565.9612;58.48277;0;0;0;0.3113047;0.3108211;519407.8;5.866483e+007
30;0.1088571;-0.05057155;640.1885;66.15294;0;0;0;0.3428569;0.3422705;587529.5;6.637975e+007
33;0.1188214;-0.05763154;717.3387;74.12514;0;0;0;0.3742405;0.3735419;658333.7;7.440255e+007
36;0.1287856;-0.06463288;796.407;82.29556;0;0;0;0.405624;0.4048036;730898.2;8.262936e+007
39;0.1387499;-0.07175194;877.2769;90.65212;0;0;0;0.4370076;0.4360555;805116.1;9.104828e+007
42;0.1486606;-0.07955747;959.3036;99.12823;0;0;0;0.4682224;0.4671297;880395.7;9.959237e+007
45;0.1586785;-0.08830758;1044.613;107.9436;0;0;0;0.4997747;0.49853;958688.4;1.084831e+008
48;0.1686963;-0.09781921;1130.516;116.8202;0;0;0;0.5313269;0.5299204;1037525;1.174409e+008
51;0.1786606;-0.1076343;1215.066;125.557;0;0;0;0.5627105;0.5611332;1115120;1.262636e+008
54;0.1886785;-0.1177048;1299.064;134.2369;0;0;0;0.5942628;0.5925041;1192209;1.350346e+008
57;0.1986963;-0.1284714;1372.951;141.8719;0;0;0;0.6258151;0.623865;1260018;1.427597e+008
60;0.2087677;-0.1415099;1441.419;148.947;0;0;0;0.6575361;0.6553838;1322855;1.499264e+008
63;0.218732;-0.1545691;1508.402;155.8685;0;0;0;0.6889197;0.6865574;1384328;1.569423e+008
66;0.2287499;-0.1676244;1575.578;162.81;0;0;0;0.720472;0.717889;1445978;1.63983e+008
69;0.2388213;-0.181156;1643.399;169.8183;0;0;0;0.752193;0.7493782;1508221;1.710956e+008
72;0.2488391;-0.1948007;1711.452;176.8503;0;0;0;0.7837452;0.7806899;1570675;1.782364e+008
75;0.258857;-0.2085619;1778.904;183.8204;0;0;0;0.8152976;0.811992;1632579;1.853191e+008
78;0.2688748;-0.2227293;1845.488;190.7008;0;0;0;0.8468498;0.8432841;1693686;1.923157e+008
81.00001;0.2788391;-0.2365071;1911.066;197.4772;0;0;0;0.8782335;0.8743994;1753871;1.992115e+008
84.00001;0.288857;-0.2502903;1975.262;204.1108;0;0;0;0.9097857;0.9056721;1812786;2.059678e+008
87.00001;0.2988212;-0.2645749;2038.509;210.6464;0;0;0;0.9411693;0.9367678;1870831;2.126289e+008
90.00001;0.3087319;-0.2784875;2099.602;216.9593;0;0;0;0.9723841;0.9676868;1926898;2.19069e+008
93.00001;0.3187498;-0.2924286;2159.835;223.1833;0;0;0;1.003936;0.9989304;1982176;2.25424e+008
96.00001;0.3287141;-0.3068054;2219.469;229.3456;0;0;0;1.03532;1.029997;2036906;2.317201e+008
99.00001;0.3386784;-0.3212261;2278.135;235.4077;0;0;0;1.066704;1.061054;2090746;2.379188e+008
102;0.3486426;-0.3358746;2336.194;241.4072;0;0;0;1.098087;1.092102;2144030;2.440581e+008
105;0.3586605;-0.3507407;2393.387;247.3172;0;0;0;1.129639;1.123307;2196518;2.50111e+008
108;0.3686783;-0.3657148;2450.318;253.2;0;0;0;1.161191;1.154501;2248766;2.561401e+008
111;0.3786426;-0.380735;2506.379;258.993;0;0;0;1.192575;1.18552;2300216;2.620817e+008
114;0.3886604;-0.3960065;2562.206;264.7618;0;0;0;1.224127;1.216696;2351451;2.680028e+008
117;0.3986783;-0.4119382;2617.97;270.5241;0;0;0;1.25568;1.247861;2402628;2.73921e+008
120;0.4086962;-0.428553;2673.411;276.253;0;0;0;1.287232;1.279018;2453508;2.79809e+008
123;0.418714;-0.445118;2727.519;281.8441;0;0;0;1.318784;1.310164;2503166;2.855611e+008
126;0.4287319;-0.4621638;2781.31;287.4026;0;0;0;1.350337;1.341301;2552533;2.912836e+008
129;0.4387497;-0.4788765;2834.481;292.8969;0;0;0;1.381889;1.372428;2601329;2.969444e+008
132;0.4487676;-0.4959339;2885.77;298.1968;0;0;0;1.413441;1.403545;2648400;3.024116e+008
135;0.4587318;-0.5128494;2936.719;303.4616;0;0;0;1.444825;1.434487;2695158;3.078461e+008
138;0.4686961;-0.5299078;2987.652;308.7247;0;0;0;1.476208;1.465418;2741902;3.132821e+008
141;0.4786604;-0.5470438;3037.728;313.8992;0;0;0;1.507592;1.496341;2787859;3.186315e+008
144;0.4886782;-0.5640479;3087.141;319.0052;0;0;0;1.539144;1.527419;2833207;3.239152e+008
147;0.4986961;-0.5814123;3135.961;324.0499;0;0;0;1.570696;1.558489;2878011;3.291397e+008
150;0.508714;-0.5987001;3184.568;329.0727;0;0;0;1.602249;1.589548;2922621;3.343453e+008
153;0.5187318;-0.6164359;3233.217;334.0997;0;0;0;1.633801;1.620598;2967267;3.395583e+008
156;0.5287497;-0.6342745;3281.527;339.0918;0;0;0;1.665353;1.651638;3011604;3.447389e+008
159;0.5387675;-0.6523948;3329.498;344.0488;0;0;0;1.696905;1.682669;3055629;3.49887e+008
162;0.5487854;-0.6704194;3377.118;348.9695;0;0;0;1.728458;1.71369;3099331;3.550013e+008
165;0.5588032;-0.689242;3424.873;353.9042;0;0;0;1.76001;1.744701;3143159;3.60133e+008
168;0.5688211;-0.7081465;3471.789;358.7523;0;0;0;1.791562;1.775703;3186216;3.651796e+008
171;0.5788389;-0.7271662;3519.115;363.6426;0;0;0;1.823115;1.806695;3229649;3.702722e+008
174;0.5888567;-0.7466485;3565.318;368.4169;0;0;0;1.854667;1.837678;3272051;3.752498e+008
177;0.5988746;-0.7663;3611.451;373.184;0;0;0;1.886219;1.868651;3314390;3.802231e+008
180;0.6088389;-0.7863359;3657.142;377.9054;0;0;0;1.917603;1.899449;3356322;3.851521e+008
183;0.6188567;-0.8061357;3701.7;382.5098;0;0;0;1.949155;1.930402;3397215;3.899655e+008
186;0.628821;-0.8259969;3745.36;387.0213;0;0;0;1.980539;1.961181;3437284;3.946864e+008
189;0.6387317;-0.8461488;3788.552;391.4845;0;0;0;2.011754;1.991785;3476923;3.993602e+008
192;0.648696;-0.8665501;3831.464;395.9187;0;0;0;2.043137;2.022545;3516306;4.040079e+008
195;0.6586603;-0.886744;3873.855;400.2992;0;0;0;2.074521;2.053295;3555210;4.086034e+008
198;0.6686781;-0.9068529;3916.909;404.7481;0;0;0;2.106073;2.084202;3594723;4.132724e+008
201;0.6786959;-0.9268775;3959.564;409.1558;0;0;0;2.137625;2.115098;3633869;4.17902e+008
204;0.6887138;-0.9473897;4001.818;413.5221;0;0;0;2.169178;2.145986;3672647;4.224921e+008
207;0.6987317;-0.9674117;4044.456;417.928;0;0;0;2.20073;2.176863;3711778;4.271255e+008
210;0.7087496;-0.9883083;4086.341;422.2561;0;0;0;2.232282;2.207731;3750218;4.316821e+008
213;0.7187674;-1.009426;4127.979;426.5587;0;0;0;2.263834;2.23859;3788430;4.362152e+008
214.9;0.7250888;-1.023335;4154.464;429.2954;0;0;0;2.283744;2.258057;3812737;4.390995e+008
217.9;0.7151246;-1.017889;3988.311;412.1263;0;0;0;2.252361;2.22737;3660251;4.214088e+008
220.9;0.7051067;-1.009406;3838.183;396.613;0;0;0;2.220809;2.196508;3522471;4.05421e+008
223.9;0.6950888;-1.000207;3694.753;381.7919;0;0;0;2.189256;2.165636;3390840;3.901503e+008
226.9;0.6850174;-0.9908717;3556.397;367.4951;0;0;0;2.157535;2.13459;3263864;3.754239e+008
229.9;0.6750532;-0.9814561;3422.179;353.6258;0;0;0;2.126152;2.103864;3140686;3.611445e+008
232.9;0.6649817;-0.9714018;3291.067;340.0776;0;0;0;2.094431;2.072799;3020359;3.472003e+008
235.9;0.6549639;-0.9612472;3163.442;326.8897;0;0;0;2.062878;2.041889;2903232;3.33633e+008
238.9;0.644946;-0.9505853;3039.68;314.1009;0;0;0;2.031326;2.01097;2789650;3.204813e+008
241.9;0.6349817;-0.9397077;2920.094;301.7437;0;0;0;1.999942;1.980206;2679901;3.077784e+008
244.9;0.6250174;-0.9289214;2803.02;289.646;0;0;0;1.968559;1.949433;2572457;2.953478e+008
247.9;0.6150531;-0.9179044;2688.487;277.8109;0;0;0;1.937175;1.918651;2467344;2.831925e+008
250.9;0.6050889;-0.9072;2577.471;266.3392;0;0;0;1.905792;1.887859;2365460;2.714151e+008
253.9;0.5951246;-0.8961594;2468.626;255.0918;0;0;0;1.874408;1.857058;2265568;2.598733e+008
256.9;0.5851603;-0.8849514;2363.136;244.1912;0;0;0;1.843025;1.826247;2168755;2.486917e+008
259.9;0.5751425;-0.8739163;2259.769;233.5099;0;0;0;1.811473;1.795261;2073891;2.377399e+008
262.9;0.5651246;-0.8628999;2158.324;223.0272;0;0;0;1.77992;1.764265;1980790;2.269969e+008
265.9;0.5551068;-0.8516913;2059.83;212.8496;0;0;0;1.748368;1.73326;1890398;2.16571e+008
268.9;0.5451425;-0.8404537;1963.621;202.9079;0;0;0;1.716984;1.702411;1802102;2.063918e+008
271.9;0.5350711;-0.829139;1869.813;193.2144;0;0;0;1.685263;1.67122;1716011;1.964706e+008
274.9;0.5250533;-0.8178802;1778.026;183.7297;0;0;0;1.653711;1.640186;1631773;1.86768e+008
277.9;0.5150354;-0.8066577;1689.473;174.5793;0;0;0;1.622159;1.609142;1550505;1.774112e+008
280.9;0.5050175;-0.7953321;1603.364;165.6813;0;0;0;1.590606;1.578089;1471479;1.683166e+008
283.9;0.4949997;-0.7842325;1518.97;156.9606;0;0;0;1.559054;1.547026;1394027;1.594077e+008
286.9;0.4849819;-0.7727288;1436.519;148.4406;0;0;0;1.527502;1.515953;1318358;1.507081e+008
289.9;0.474964;-0.7612838;1356.341;140.1555;0;0;0;1.49595;1.484871;1244775;1.422522e+008
292.9;0.4649461;-0.7496266;1277.557;132.0145;0;0;0;1.464397;1.453779;1172472;1.339478e+008
295.9;0.4549819;-0.738236;1200.298;124.031;0;0;0;1.433014;1.422843;1101567;1.258084e+008
298.9;0.4450712;-0.7264405;1124.656;116.2147;0;0;0;1.401799;1.392065;1032147;1.178438e+008
301.9;0.4350533;-0.7148013;1050.829;108.5858;0;0;0;1.370247;1.360944;964392.3;1.100737e+008
304.9;0.425089;-0.7028218;978.8535;101.1484;0;0;0;1.338863;1.329979;898337.5;1.025026e+008
307.9;0.4151247;-0.6911483;908.8021;93.90974;0;0;0;1.30748;1.299006;834048.2;9.513759e+007
310.9;0.4051069;-0.6794354;840.0283;86.8031;0;0;0;1.275927;1.267856;770931.4;8.791064e+007
313.9;0.3951426;-0.6674749;773.567;79.93542;0;0;0;1.244544;1.236863;709936.9;8.093025e+007
316.9;0.3851247;-0.6556754;709.4053;73.30536;0;0;0;1.212991;1.205693;651052.9;7.419455e+007
319.9;0.3751605;-0.6437203;646.6958;66.82537;0;0;0;1.181608;1.174681;593501.6;6.761499e+007
322.9;0.3651426;-0.6321402;585.9531;60.54861;0;0;0;1.150056;1.143493;537755.3;6.124495e+007
325.9;0.3551248;-0.6204172;526.6633;54.42199;0;0;0;1.118503;1.112294;483342.4;5.50307e+007
328.9;0.3451069;-0.6090242;468.917;48.45485;0;0;0;1.086951;1.081086;430346;4.898153e+007
331.9;0.3350891;-0.5974991;413.7509;42.75434;0;0;0;1.055399;1.049868;379717.6;4.320557e+007
334.9;0.3250712;-0.5864712;360.2907;37.23011;0;0;0;1.023846;1.01864;330654.8;3.761129e+007
337.9;0.3150534;-0.5761451;308.765;31.90578;0;0;0;0.9922941;0.9874032;283367.4;3.222238e+007
340.9;0.3050891;-0.5669485;259.6263;26.82811;0;0;0;0.9609105;0.9563231;238270.7;2.70859e+007
343.9;0.2950712;-0.5580098;212.8079;21.9902;0;0;0;0.9293582;0.9250662;195303.3;2.219456e+007
346.9;0.2851069;-0.5494551;167.5464;17.31316;0;0;0;0.8979746;0.8939668;153764.8;1.746863e+007
349.9;0.2751427;-0.5408502;125.6886;12.98785;0;0;0;0.8665911;0.8628577;115350.1;1.31004e+007
352.9;0.2651784;-0.5330075;88.95965;9.192516;0;0;0;0.8352075;0.831739;81642.24;9269292
355.9;0.2551605;-0.5265698;56.99113;5.889096;0;0;0;0.8036553;0.8004431;52303.3;5936424
357.776;0.2553748;-0.5250877;66.29941;6.850953;1;1;0;0.8043301;0.8011126;60845.92;6906057
360.776;0.2654998;-0.5275031;132.8245;13.72523;1;1;0;0.8362199;0.832743;121899;1.384e+007
363.776;0.2754641;-0.5311453;203.921;21.07188;1;1;0;0.8676035;0.8638615;187147.4;2.12547e+007
366.776;0.2854819;-0.5354403;279.5049;28.88223;1;1;0;0.8991557;0.8951374;256514.1;2.914192e+007
369.776;0.2954462;-0.5402415;358.2639;37.02068;1;1;0;0.9305393;0.9262364;328794.8;3.736517e+007
372.776;0.3054641;-0.5453957;439.1493;45.37885;1;1;0;0.9620916;0.957493;403026.8;4.581543e+007
375.776;0.3154284;-0.5506404;520.718;53.80764;1;1;0;0.9934752;0.9885727;477886.2;5.43422e+007
378.776;0.3254462;-0.556728;605.0449;62.52143;1;1;0;1.025027;1.01981;555276.8;6.31623e+007
381.776;0.3354105;-0.5643294;691.8903;71.49548;1;1;0;1.056411;1.05087;634978.6;7.225076e+007
384.776;0.3454819;-0.5727574;780.7728;80.68002;1;1;0;1.088132;1.082255;716550;8.155792e+007
387.776;0.3554462;-0.5814274;869.7924;89.87873;1;1;0;1.119516;1.113295;798247.3;9.088494e+007
390.776;0.365464;-0.590449;960.6694;99.26936;1;1;0;1.151068;1.144493;881649.1;1.00412e+008
393.776;0.3755355;-0.5999103;1051.063;108.61;1;1;0;1.182789;1.175849;964607.1;1.098947e+008
396.776;0.3855533;-0.6095186;1142.752;118.0846;1;1;0;1.214341;1.207027;1048755;1.195186e+008
399.776;0.3955176;-0.6196118;1234.475;127.5627;1;1;0;1.245725;1.238029;1132933;1.291517e+008
402.776;0.4055355;-0.6296361;1327.596;137.1852;1;1;0;1.277277;1.269189;1218394;1.389374e+008
405.776;0.4155533;-0.6398172;1420.57;146.7925;1;1;0;1.308829;1.300338;1303720;1.487138e+008
408.776;0.4255712;-0.6501359;1513.471;156.3923;1;1;0;1.340382;1.331478;1388980;1.584886e+008
411.776;0.435589;-0.6604971;1606.364;165.9913;1;1;0;1.371934;1.362608;1474232;1.682686e+008
414.776;0.4456069;-0.6713436;1697.659;175.4251;1;1;0;1.403486;1.393728;1558017;1.778872e+008
417.776;0.4555711;-0.6819582;1788.892;184.8525;1;1;0;1.43487;1.424673;1641746;1.875049e+008
420.776;0.4655354;-0.693187;1880.044;194.2716;1;1;0;1.466253;1.455608;1725400;1.971201e+008
423.776;0.4754997;-0.7039171;1970.771;203.6467;1;1;0;1.497637;1.486533;1808664;2.066966e+008
426.776;0.4854104;-0.7151442;2059.918;212.8586;1;1;0;1.528852;1.517283;1890478;2.161129e+008
429.776;0.4954282;-0.726316;2148.816;222.0448;1;1;0;1.560404;1.548355;1972064;2.255096e+008
432.776;0.5053925;-0.7379829;2237.527;231.2116;1;1;0;1.591787;1.579251;2053479;2.34892e+008
435.776;0.5154104;-0.7498974;2327.352;240.4935;1;1;0;1.62334;1.610305;2135915;2.443976e+008
438.776;0.5254282;-0.76199;2416.967;249.7538;1;1;0;1.654892;1.641348;2218159;2.538869e+008
441.776;0.5354461;-0.7741528;2507.387;259.0971;1;1;0;1.686444;1.672382;2301141;2.634667e+008
444.776;0.545464;-0.7863554;2597.678;268.4273;1;1;0;1.717997;1.703406;2384005;2.730389e+008
447.776;0.5554818;-0.7989483;2687.836;277.7437;1;1;0;1.749549;1.734421;2466747;2.826029e+008
450.776;0.5655532;-0.8114001;2778.535;287.1159;1;1;0;1.78127;1.765591;2549986;2.922302e+008
453.776;0.575571;-0.8239555;2869.303;296.4952;1;1;0;1.812822;1.796586;2633287;3.018701e+008
456.776;0.5855889;-0.8367924;2959.416;305.8069;1;1;0;1.844375;1.827572;2715988;3.114471e+008
459.776;0.5955532;-0.8493099;3048.868;315.0504;1;1;0;1.875758;1.858383;2798083;3.209599e+008
462.776;0.6056246;-0.8623093;3139.408;324.4061;1;1;0;1.907479;1.889515;2881175;3.305941e+008
465.776;0.6155889;-0.8751053;3228.551;333.6176;1;1;0;1.938863;1.920306;2962985;3.40086e+008
468.776;0.6256067;-0.8880111;3317.314;342.7898;1;1;0;1.970415;1.951253;3044447;3.495441e+008
471.776;0.6355174;-0.9009939;3404.983;351.849;1;1;0;2.00163;1.98186;3124905;3.588917e+008
474.776;0.6455353;-0.9143229;3492.541;360.8966;1;1;0;2.033182;2.012789;3205260;3.682343e+008
477.776;0.6554995;-0.9274955;3579.582;369.8908;1;1;0;2.064565;2.043542;3285142;3.775275e+008
480.776;0.6654103;-0.9411225;3665.487;378.7678;1;1;0;2.09578;2.074121;3363981;3.867059e+008
483.776;0.6753745;-0.9543373;3750.956;387.5996;1;1;0;2.127164;2.104856;3442420;3.958445e+008
486.776;0.6853924;-0.967642;3835.119;396.2965;1;1;0;2.158716;2.135746;3519660;4.048514e+008
489.776;0.6953566;-0.9813389;3918.857;404.9493;1;1;0;2.1901;2.166462;3596510;4.138181e+008
492.776;0.7053746;-0.9952394;4000.283;413.3634;1;1;0;2.221652;2.197333;3671238;4.225469e+008
494.506;0.711321;-1.003704;4047.761;418.2694;1;1;0;2.240381;2.215653;3714810;4.276403e+008
497.506;0.7013031;-0.9970982;3884.686;401.4183;1;1;0;2.208829;2.184788;3565149;4.10285e+008
500.506;0.6913389;-0.9887105;3733.712;385.8177;1;1;0;2.177445;2.154078;3426594;3.942187e+008
503.506;0.681321;-0.9799414;3589.601;370.9262;1;1;0;2.145893;2.123193;3294337;3.788859e+008
506.506;0.6713031;-0.9705572;3450.085;356.5096;1;1;0;2.114341;2.092299;3166297;3.640474e+008
509.506;0.6612853;-0.9612317;3314.687;342.5183;1;1;0;2.082788;2.061395;3042036;3.496523e+008
512.506;0.651321;-0.9515178;3182.872;328.8974;1;1;0;2.051405;2.030647;2921064;3.356444e+008
515.506;0.6413031;-0.9415022;3054.453;315.6275;1;1;0;2.019852;1.999724;2803208;3.220027e+008
518.506;0.6312853;-0.9313336;2929.284;302.6933;1;1;0;1.9883;1.968792;2688335;3.087117e+008
521.506;0.6212675;-0.9209166;2807.042;290.0616;1;1;0;1.956748;1.93785;2576148;2.957374e+008
524.5061;0.6112496;-0.9101394;2687.967;277.7571;1;1;0;1.925195;1.906898;2466867;2.831045e+008
527.5061;0.6012853;-0.8996278;2572.038;265.7778;1;1;0;1.893812;1.876103;2360474;2.708111e+008
530.5061;0.591321;-0.8890382;2460.014;254.2019;1;1;0;1.862428;1.845298;2257664;2.589363e+008
533.5061;0.5813032;-0.8782311;2350.66;242.902;1;1;0;1.830876;1.814318;2157305;2.473492e+008
536.5061;0.5713389;-0.8677182;2243.642;231.8434;1;1;0;1.799493;1.783493;2059090;2.360154e+008
539.5061;0.5613747;-0.8568063;2139.595;221.0919;1;1;0;1.768109;1.75266;1963602;2.25001e+008
542.5061;0.5513568;-0.8460011;2037.834;210.5766;1;1;0;1.736557;1.721651;1870212;2.142334e+008
545.5061;0.5413389;-0.8351436;1938.378;200.2995;1;1;0;1.705004;1.690632;1778936;2.037146e+008
548.5061;0.5313211;-0.8243722;1841.53;190.2918;1;1;0;1.673452;1.659604;1690054;1.934762e+008
551.5061;0.5212497;-0.8133534;1747.301;180.5548;1;1;0;1.641731;1.628401;1603576;1.83519e+008
554.5061;0.5112318;-0.8025632;1656.382;171.1599;1;1;0;1.610179;1.597353;1520136;1.739158e+008
557.5061;0.5012675;-0.7917542;1567.838;162.0103;1;1;0;1.578795;1.566462;1438875;1.645681e+008
560.5061;0.4912497;-0.7808688;1481.127;153.0501;1;1;0;1.547243;1.535395;1359296;1.554181e+008
563.5061;0.4811783;-0.7697543;1396.353;144.2901;1;1;0;1.515522;1.504153;1281495;1.464768e+008
566.5061;0.4711604;-0.7587683;1312.999;135.6768;1;1;0;1.48397;1.473067;1204998;1.376902e+008
569.5061;0.4611426;-0.7477082;1231.833;127.2896;1;1;0;1.452417;1.441971;1130508;1.291384e+008
572.5061;0.4511783;-0.7367605;1152.167;119.0575;1;1;0;1.421034;1.411032;1057395;1.207494e+008
575.5061;0.4411604;-0.7255887;1073.767;110.9562;1;1;0;1.389482;1.379917;985444.1;1.124979e+008
578.5061;0.4311961;-0.7144663;997.7968;103.1059;1;1;0;1.358098;1.348959;915722.6;1.045062e+008
581.5061;0.4212319;-0.7031623;923.9287;95.47282;1;1;0;1.326715;1.317991;847930.6;9.673947e+007
584.5061;0.4112676;-0.6921617;851.3851;87.97663;1;1;0;1.295331;1.287013;781354;8.911622e+007
587.5061;0.4013033;-0.6810139;781.713;80.77717;1;1;0;1.263947;1.256026;717412.9;8.179815e+007
590.5061;0.391339;-0.6698145;713.4332;73.72158;1;1;0;1.232564;1.22503;654749.5;7.463025e+007
593.5061;0.3813212;-0.6589213;647.4512;66.90343;1;1;0;1.201012;1.193857;594194.9;6.770694e+007
596.5061;0.3713033;-0.6480307;583.6452;60.31013;1;1;0;1.169459;1.162674;535637.3;6.101543e+007
599.5061;0.3612855;-0.6370623;521.0481;53.84174;1;1;0;1.137907;1.131482;478189.1;5.445441e+007
602.5061;0.3512676;-0.6263454;460.0545;47.53906;1;1;0;1.106355;1.100279;422212.6;4.806501e+007
605.5061;0.3412498;-0.6160183;401.4454;41.48278;1;1;0;1.074802;1.069067;368424.4;4.192864e+007
608.5061;0.3312319;-0.6059049;344.7895;35.62832;1;1;0;1.04325;1.037846;316428.7;3.600002e+007
611.5061;0.3212141;-0.5971178;290.732;30.04236;1;1;0;1.011698;1.006614;266817.7;3.03463e+007
614.5061;0.3111962;-0.5891383;238.5628;24.65154;1;1;0;0.9801456;0.9753734;218939.7;2.489316e+007
617.5061;0.3011784;-0.5814904;188.1379;19.44095;1;1;0;0.9485933;0.9441224;172662.5;1.962537e+007
620.5061;0.2911605;-0.5736148;141.2946;14.60047;1;1;0;0.917041;0.9128617;129672.3;1.473436e+007
623.5061;0.2811427;-0.5665436;99.055;10.2357;1;1;0;0.8854888;0.8815913;90907.19;1.032634e+007
626.5061;0.2711784;-0.5602155;62.7994;6.489285;1;1;0;0.8541052;0.8504784;57633.81;6544710
627.7241;0.267107;-0.5581072;50.71648;5.240714;2;2;0;0.8412817;0.8377627;46544.78;5284803
630.7241;0.2771248;-0.5598928;113.4497;11.72316;2;2;0;0.8728341;0.8690469;104117.9;1.182549e+007
633.7241;0.2870891;-0.5630894;184.7339;19.08921;2;2;0;0.9042176;0.9001541;169538.6;1.926182e+007
636.7241;0.2971069;-0.5673059;259.9961;26.86632;2;2;0;0.9357699;0.9314187;238610;2.711772e+007
639.7241;0.3071248;-0.5721409;339.2903;35.06007;2;2;0;0.9673222;0.9626736;311381.8;3.539921e+007
642.7241;0.3171427;-0.5770792;420.3758;43.43892;2;2;0;0.9988745;0.9939187;385797.7;4.387282e+007
645.7241;0.3271605;-0.5822284;502.7289;51.94876;2;2;0;1.030427;1.025154;461376.7;5.248405e+007
648.7241;0.3371784;-0.5886859;588.5678;60.81879;2;2;0;1.061979;1.05638;540154.9;6.146468e+007
651.7241;0.3471962;-0.5963332;677.2074;69.97823;2;2;0;1.093531;1.087596;621503.4;7.074347e+007
654.7241;0.357214;-0.6044305;766.7247;79.22838;2;2;0;1.125084;1.118802;703657.4;8.011976e+007
657.7241;0.3671783;-0.6131194;857.4595;88.60433;2;2;0;1.156467;1.149831;786928.9;8.962901e+007
660.7241;0.3771962;-0.6220508;948.6286;98.02515;2;2;0;1.18802;1.181018;870598.8;9.918971e+007
663.7241;0.3871605;-0.6311161;1040.214;107.489;2;2;0;1.219403;1.212028;954651.1;1.087998e+008
666.7241;0.3971247;-0.6406326;1132.799;117.0561;2;2;0;1.250787;1.243029;1039620;1.185202e+008
669.7241;0.4071426;-0.6503757;1226.453;126.7337;2;2;0;1.282339;1.274186;1125571;1.283589e+008
672.7241;0.4171604;-0.6601565;1320.965;136.5;2;2;0;1.313891;1.305334;1212309;1.382935e+008
675.7241;0.4271783;-0.6701108;1415.467;146.2653;2;2;0;1.345443;1.336473;1299038;1.482332e+008
678.7241;0.4371961;-0.680224;1509.836;156.0166;2;2;0;1.376996;1.367601;1385643;1.58165e+008
681.7241;0.447214;-0.6906576;1603.623;165.708;2;2;0;1.408548;1.39872;1471716;1.680421e+008
684.7241;0.4572318;-0.7011311;1697.064;175.3636;2;2;0;1.4401;1.429829;1557471;1.77889e+008
687.7241;0.4672497;-0.7117914;1791.181;185.0891;2;2;0;1.471653;1.460929;1643847;1.87813e+008
690.7241;0.477214;-0.7224111;1884.605;194.7429;2;2;0;1.503036;1.491852;1729586;1.976699e+008
693.7241;0.4872854;-0.7332641;1977.482;204.3402;2;2;0;1.534757;1.523099;1814824;2.074764e+008
696.7241;0.4972497;-0.7443569;2069.683;213.8676;2;2;0;1.566141;1.554003;1899440;2.172171e+008
699.7241;0.5072675;-0.7556394;2161.254;223.3301;2;2;0;1.597693;1.585064;1983479;2.268982e+008
702.7241;0.5172854;-0.7669839;2253.385;232.8502;2;2;0;1.629245;1.616115;2068032;2.366439e+008
705.7241;0.5273032;-0.7786077;2346.125;242.4334;2;2;0;1.660797;1.647157;2153144;2.464597e+008
708.7241;0.5372675;-0.7902789;2439.187;252.0499;2;2;0;1.692181;1.678023;2238551;2.56315e+008
711.7241;0.5472318;-0.8021618;2531.809;261.6208;2;2;0;1.723565;1.70888;2323554;2.6613e+008
714.7241;0.557196;-0.8138162;2624.704;271.2199;2;2;0;1.754948;1.739727;2408808;2.759797e+008
717.7241;0.5671603;-0.8258678;2717.61;280.8203;2;2;0;1.786332;1.770564;2494072;2.858367e+008
720.7241;0.5771246;-0.837897;2810.335;290.4019;2;2;0;1.817715;1.801392;2579170;2.956805e+008
723.7241;0.5870889;-0.8498903;2903.362;300.0147;2;2;0;1.849099;1.832211;2664545;3.055622e+008
726.7241;0.5971603;-0.8620849;2996.999;309.6905;2;2;0;1.88082;1.863351;2750479;3.155152e+008
729.7241;0.6071246;-0.8741666;3090.181;319.3193;2;2;0;1.912203;1.894151;2835997;3.254254e+008
732.7241;0.6171424;-0.886322;3183.572;328.9698;2;2;0;1.943756;1.925106;2921707;3.353642e+008
735.7241;0.6272138;-0.8987121;3276.88;338.6116;2;2;0;1.975477;1.956217;3007339;3.453008e+008
738.7241;0.6372317;-0.9109551;3369.744;348.2076;2;2;0;2.007029;1.987154;3092565;3.551962e+008
741.7241;0.6472495;-0.9233962;3462.845;357.828;2;2;0;2.038581;2.01808;3178007;3.651226e+008
744.7241;0.6572674;-0.9360743;3555.898;367.4435;2;2;0;2.070134;2.048998;3263406;3.750501e+008
747.7241;0.6672853;-0.9483543;3648.914;377.0552;2;2;0;2.101686;2.079905;3348771;3.849797e+008
750.7241;0.6773031;-0.9608267;3741.281;386.5999;2;2;0;2.133238;2.110803;3433541;3.94847e+008
753.7241;0.687321;-0.9730667;3834.022;396.183;2;2;0;2.164791;2.141692;3518653;4.047596e+008
756.7241;0.6973388;-0.9853946;3926.293;405.7178;2;2;0;2.196343;2.172571;3603334;4.146287e+008
759.7241;0.7073031;-0.9978592;4016.547;415.044;2;2;0;2.227726;2.203275;3686164;4.2429e+008
762.7241;0.7172674;-1.010752;4104.098;424.0909;2;2;0;2.25911;2.23397;3766514;4.336716e+008
765.7241;0.7272317;-1.024444;4184.496;432.3988;2;2;0;2.290493;2.264655;3840299;4.423029e+008
768.7241;0.737196;-1.040087;4254.677;439.6509;2;2;0;2.321877;2.295332;3904707;4.49859e+008
771.7241;0.7471602;-1.057871;4316.959;446.0866;2;2;0;2.353261;2.325998;3961866;4.565842e+008
774.7241;0.7571245;-1.077126;4372.286;451.8038;2;2;0;2.384644;2.356656;4012642;4.625777e+008
777.7241;0.7670888;-1.097725;4422.258;456.9676;2;2;0;2.416028;2.387303;4058504;4.680081e+008
780.7241;0.7771066;-1.119531;4468.573;461.7535;2;2;0;2.44758;2.418107;4101009;4.730553e+008
783.7241;0.7871244;-1.141919;4513.388;466.3844;2;2;0;2.479132;2.4489;4142138;4.779467e+008
786.7241;0.7970887;-1.164452;4555.76;470.7628;2;2;0;2.510516;2.47952;4181024;4.825814e+008
789.7241;0.8071066;-1.187109;4597.11;475.0356;2;2;0;2.542068;2.510295;4218973;4.871113e+008
792.7241;0.8171245;-1.211098;4638.662;479.3294;2;2;0;2.57362;2.54106;4257108;4.916655e+008
795.7241;0.8271423;-1.235207;4679.373;483.5362;2;2;0;2.605173;2.571816;4294470;4.961332e+008
798.7241;0.8371602;-1.259416;4719.681;487.7013;2;2;0;2.636725;2.602563;4331462;5.005607e+008
801.7241;0.847178;-1.283686;4758.808;491.7445;2;2;0;2.668277;2.6333;4367371;5.048656e+008
804.7241;0.8571959;-1.307727;4797.507;495.7434;2;2;0;2.69983;2.664027;4402887;5.091276e+008
807.7241;0.8672137;-1.332146;4835.692;499.6891;2;2;0;2.731382;2.694745;4437930;5.133375e+008
810.7241;0.877178;-1.357018;4874.798;503.7302;2;2;0;2.762765;2.72529;4473820;5.17647e+008
813.7241;0.8871959;-1.381362;4912.562;507.6324;2;2;0;2.794318;2.755989;4508478;5.218173e+008
816.7241;0.8971601;-1.405922;4951.249;511.6301;2;2;0;2.825701;2.786515;4543982;5.260872e+008
819.7241;0.9071244;-1.430064;4989.894;515.6235;2;2;0;2.857085;2.817031;4579449;5.303553e+008
822.7241;0.9171423;-1.454167;5028.598;519.6228;2;2;0;2.888637;2.847703;4614969;5.346328e+008
825.7241;0.9271601;-1.478368;5067.455;523.638;2;2;0;2.920189;2.878364;4650629;5.389292e+008
828.7241;0.937178;-1.502517;5106.118;527.6332;2;2;0;2.951742;2.909016;4686113;5.432076e+008
831.7241;0.9471958;-1.526835;5144.661;531.616;2;2;0;2.983294;2.939659;4721485;5.474757e+008
834.7241;0.9572136;-1.551353;5183.38;535.617;2;2;0;3.014846;2.970293;4757019;5.51765e+008
837.7241;0.9672315;-1.575874;5222.079;539.6159;2;2;0;3.046399;3.000917;4792535;5.560548e+008
840.7241;0.9772494;-1.600415;5260.833;543.6205;2;2;0;3.077951;3.031532;4828102;5.603529e+008
843.7241;0.9872673;-1.625048;5299.597;547.6261;2;2;0;3.109503;3.062138;4863677;5.646546e+008
846.7241;0.997285;-1.649629;5338.376;551.6334;2;2;0;3.141055;3.092733;4899266;5.689604e+008
849.7241;1.007249;-1.674503;5377.403;555.6661;2;2;0;3.172439;3.123156;4935082;5.732942e+008
852.7241;1.017267;-1.69919;5416.465;559.7025;2;2;0;3.203991;3.153734;4970932;5.776354e+008
855.7241;1.027285;-1.72367;5454.893;563.6734;2;2;0;3.235543;3.184302;5006199;5.819113e+008
858.7241;1.037303;-1.748233;5493.333;567.6456;2;2;0;3.267096;3.214861;5041477;5.861911e+008
861.7241;1.047267;-1.773087;5531.929;571.6339;2;2;0;3.298479;3.245247;5076898;5.90489e+008
864.7241;1.057231;-1.797798;5569.611;575.5276;2;2;0;3.329863;3.275624;5111480;5.946919e+008
867.7241;1.067196;-1.822404;5606.975;579.3886;2;2;0;3.361246;3.305991;5145771;5.988633e+008
870.7241;1.07716;-1.846781;5644.277;583.2432;2;2;0;3.39263;3.33635;5180005;6.030305e+008
873.7241;1.087124;-1.871387;5682.602;587.2034;2;2;0;3.424013;3.366699;5215178;6.073093e+008
876.7241;1.097089;-1.896105;5720.426;591.1119;2;2;0;3.455397;3.397039;5249891;6.115372e+008
879.7241;1.10716;-1.920836;5758.6;595.0566;2;2;0;3.487118;3.427696;5284925;6.158069e+008
882.7241;1.117178;-1.945229;5796.335;598.9557;2;2;0;3.518671;3.45818;5319555;6.200311e+008
885.7241;1.127196;-1.969425;5833.713;602.8182;2;2;0;3.550222;3.488655;5353858;6.242196e+008
888.7241;1.137214;-1.994045;5871.702;606.7437;2;2;0;3.581775;3.519121;5388723;6.284759e+008
890.2201;1.142142;-2.005811;5889.834;608.6174;2;2;0;3.597298;3.534106;5405364;6.305112e+008
893.2201;1.132231;-2.001627;5698.919;588.8895;2;2;0;3.566083;3.503971;5230153;6.098898e+008
896.2201;1.122267;-1.99319;5527.129;571.1378;2;2;0;3.5347;3.473663;5072493;5.913258e+008
899.2201;1.112303;-1.984299;5362.097;554.0845;2;2;0;3.503316;3.443347;4921036;5.734958e+008
902.2201;1.102285;-1.975101;5202.501;537.5928;2;2;0;3.471764;3.412858;4774567;5.562568e+008
905.2201;1.092267;-1.965701;5046.81;521.5048;2;2;0;3.440211;3.382359;4631683;5.394456e+008
908.2201;1.082249;-1.956075;4894.177;505.7327;2;2;0;3.408659;3.351852;4491605;5.229714e+008
911.2201;1.072231;-1.946377;4744.743;490.2911;2;2;0;3.377107;3.321335;4354462;5.068487e+008
914.2201;1.062214;-1.936582;4598.843;475.2148;2;2;0;3.345555;3.290809;4220564;4.911133e+008
917.2201;1.052196;-1.926496;4456.021;460.4564;2;2;0;3.314002;3.260273;4089489;4.757159e+008
920.2201;1.042178;-1.916407;4316.273;446.0158;2;2;0;3.28245;3.229729;3961237;4.606561e+008
923.2201;1.032106;-1.905896;4178.703;431.8002;2;2;0;3.250729;3.199011;3834982;4.458369e+008
926.2201;1.022089;-1.895162;4044.232;417.9048;2;2;0;3.219177;3.168447;3711572;4.313579e+008
929.2201;1.012071;-1.884333;3912.47;404.2894;2;2;0;3.187624;3.137874;3590649;4.171766e+008
932.2201;1.002053;-1.873166;3784.532;391.0691;2;2;0;3.156072;3.107292;3473234;4.034115e+008
935.2201;0.9920886;-1.86223;3659.551;378.1543;2;2;0;3.124689;3.076864;3358533;3.899705e+008
938.2201;0.9821244;-1.851245;3538.766;365.6732;2;2;0;3.093305;3.046427;3247684;3.769847e+008
941.2201;0.9721601;-1.840196;3421.147;353.5193;2;2;0;3.061922;3.01598;3139740;3.643437e+008
944.2201;0.9621958;-1.829174;3306.469;341.6691;2;2;0;3.030538;2.985524;3034494;3.520235e+008
947.2201;0.9522316;-1.818239;3195.538;330.2063;2;2;0;2.999155;2.955059;2932688;3.401097e+008
950.2201;0.9422673;-1.807204;3086.978;318.9884;2;2;0;2.967771;2.924585;2833058;3.284552e+008
953.2201;0.9322494;-1.796194;2979.898;307.9234;2;2;0;2.936219;2.893937;2734785;3.169647e+008
956.2201;0.9222316;-1.785059;2876.211;297.209;2;2;0;2.904666;2.86328;2639627;3.05842e+008
959.2201;0.9122673;-1.773972;2774.305;286.6787;2;2;0;2.873283;2.832778;2546103;2.949158e+008
962.2201;0.9022494;-1.762832;2673.87;276.3005;2;2;0;2.841731;2.802102;2453930;2.841522e+008
965.2201;0.8922315;-1.751908;2576.118;266.1994;2;2;0;2.810178;2.771417;2364219;2.736801e+008
968.2201;0.8821602;-1.740751;2480.184;256.2862;2;2;0;2.778457;2.740558;2276176;2.63407e+008
971.2201;0.8721423;-1.729392;2385.976;246.5513;2;2;0;2.746905;2.709854;2189717;2.533239e+008
974.2201;0.8621244;-1.718133;2294.158;237.0635;2;2;0;2.715353;2.679141;2105451;2.435006e+008
977.2201;0.8521066;-1.706935;2204.53;227.8019;2;2;0;2.6838;2.648418;2023196;2.339157e+008
980.2201;0.8420888;-1.695664;2116.935;218.7504;2;2;0;2.652248;2.617686;1942806;2.245522e+008
983.2201;0.8320709;-1.684506;2030.444;209.8129;2;2;0;2.620696;2.586944;1863429;2.153115e+008
986.2201;0.8221067;-1.673012;1946.057;201.093;2;2;0;2.589312;2.556357;1785984;2.062999e+008
989.2201;0.8121424;-1.661742;1862.498;192.4585;2;2;0;2.557929;2.525761;1709297;1.973814e+008
992.2201;0.802178;-1.650221;1780.529;183.9884;2;2;0;2.526545;2.495155;1634071;1.88637e+008
995.2201;0.7922138;-1.638629;1700.706;175.7399;2;2;0;2.495162;2.464541;1560814;1.801249e+008
998.2201;0.7821959;-1.627159;1622.816;167.6913;2;2;0;2.463609;2.433752;1489331;1.718226e+008
1001.22;0.7722317;-1.615747;1547.35;159.8931;2;2;0;2.432226;2.403118;1420072;1.637821e+008
1004.22;0.7622138;-1.604105;1472.45;152.1535;2;2;0;2.400673;2.37231;1351333;1.558062e+008
1007.22;0.7522495;-1.592537;1398.823;144.5453;2;2;0;2.36929;2.341658;1283762;1.479701e+008
1010.22;0.7422316;-1.580661;1326.429;137.0647;2;2;0;2.337738;2.310831;1217324;1.402689e+008
1013.22;0.7322674;-1.569024;1254.873;129.6705;2;2;0;2.306354;2.28016;1151653;1.326611e+008
1016.22;0.7222495;-1.557105;1184.754;122.4249;2;2;0;2.274802;2.249314;1087302;1.252098e+008
1019.22;0.7122316;-1.545323;1115.725;115.2918;2;2;0;2.243249;2.218458;1023950;1.178781e+008
1022.22;0.7022138;-1.533546;1048.287;108.3232;2;2;0;2.211697;2.187594;962059.4;1.107189e+008
1025.22;0.692196;-1.521582;981.9267;101.466;2;2;0;2.180145;2.156719;901157.9;1.036781e+008
1028.22;0.6821781;-1.509754;916.8903;94.74552;2;2;0;2.148592;2.125836;841471.1;9.678122e+007
1031.22;0.6722139;-1.497584;853.1331;88.15726;2;2;0;2.117209;2.095108;782958.3;9.002374e+007
1034.22;0.662196;-1.48566;790.4376;81.67872;2;2;0;2.085657;2.064205;725419.8;8.338225e+007
1037.22;0.6521781;-1.473617;729.2065;75.35149;2;2;0;2.054104;2.033292;669225.3;7.689929e+007
1040.22;0.6422139;-1.461681;669.9374;69.227;2;2;0;2.022721;2.002536;614831.4;7.062727e+007
1043.22;0.6322496;-1.449868;611.6836;63.20744;2;2;0;1.991337;1.971769;561369.4;6.446611e+007
1046.22;0.6222853;-1.437698;555.1178;57.36229;2;2;0;1.959954;1.940994;509456.4;5.848656e+007
1049.22;0.6122675;-1.426008;499.8942;51.65584;2;2;0;1.928401;1.910043;458775.3;5.265197e+007
1052.22;0.6023032;-1.414366;446.4187;46.13002;2;2;0;1.897018;1.879249;409698.3;4.700512e+007
1055.22;0.5922318;-1.402833;394.1206;40.72588;2;2;0;1.865297;1.848114;361702.1;4.148554e+007
1058.22;0.5822139;-1.39128;343.6058;35.50601;2;2;0;1.833745;1.817134;315342.4;3.61571e+007
1061.22;0.5722497;-1.380051;294.4232;30.42379;2;2;0;1.802361;1.786311;270205.3;3.097214e+007
1064.22;0.5621782;-1.369887;247.415;25.56627;2;2;0;1.77064;1.755147;227063.8;2.601896e+007
1067.22;0.5521604;-1.360883;202.8667;20.96294;2;2;0;1.739088;1.724139;186179.8;2.13275e+007
1070.22;0.5421425;-1.351589;160.2327;16.55741;2;2;0;1.707535;1.693121;147052.7;1.684013e+007
1073.22;0.5321246;-1.342948;120.1948;12.42015;2;2;0;1.675983;1.662094;110308.1;1.262831e+007
1076.22;0.5221068;-1.336036;85.36028;8.82058;2;2;0;1.644431;1.631056;78338.93;8965628
1079.22;0.512089;-1.330317;56.022;5.788951;2;2;0;1.612879;1.60001;51413.89;5882320
1081.906;0.5032496;-1.326524;41.9517;4.335017;2;2;0;1.585038;1.572608;38500.95;4403729
1083.908;0.5098925;-1.32635;63.41437;6.552832;3;3;0;1.605961;1.593202;58198.2;6658067
1086.908;0.5198568;-1.328664;124.5731;12.87258;3;3;0;1.637344;1.624084;114326.3;1.308335e+007
1089.908;0.5314282;-1.331713;202.9486;20.9714;3;3;0;1.67379;1.659936;186255;2.132241e+007
1092.908;0.5464818;-1.337748;315.9348;32.64666;3;3;0;1.721202;1.706557;289947.5;3.320858e+007
1095.908;0.5615354;-1.345278;439.1645;45.38042;3;3;0;1.768615;1.753157;403040.8;4.618303e+007
1098.908;0.5764818;-1.353179;564.9167;58.37484;3;3;0;1.815691;1.799404;518449.3;5.943475e+007
1101.908;0.5915354;-1.364214;699.772;72.30992;3;3;0;1.863104;1.84596;642212;7.365713e+007
1104.908;0.6065889;-1.376562;837.936;86.58689;3;3;0;1.910516;1.892495;769011.2;8.824115e+007
1107.908;0.6214817;-1.38892;974.9309;100.7431;3;3;0;1.957423;1.938512;894737.6;1.02715e+008
1110.908;0.6366424;-1.40203;1117.098;115.4337;3;3;0;2.005173;1.985334;1025211;1.177484e+008
1113.908;0.6515353;-1.41552;1256.972;129.8873;3;3;0;2.05208;2.031308;1153579;1.325527e+008
1116.908;0.6666424;-1.429687;1399.87;144.6535;3;3;0;2.099661;2.077922;1284723;1.476907e+008
1119.908;0.6815888;-1.444048;1540.056;159.1394;3;3;0;2.146736;2.124019;1413378;1.625557e+008
1122.908;0.6965353;-1.458576;1680.686;173.6713;3;3;0;2.193812;2.170094;1542441;1.774813e+008
1125.908;0.7116424;-1.473414;1822.586;188.3342;3;3;0;2.241394;2.216643;1672668;1.925555e+008
1128.908;0.7264281;-1.488419;1960.421;202.5772;3;3;0;2.287963;2.262181;1799166;2.072121e+008
1131.908;0.7416424;-1.503978;2101.156;217.1199;3;3;0;2.335881;2.309017;1928325;2.221916e+008
1134.908;0.7564281;-1.519581;2236.48;231.1033;3;3;0;2.382451;2.354513;2052517;2.366093e+008
1137.908;0.7715352;-1.536054;2375.268;245.4448;3;3;0;2.430032;2.400977;2179889;2.514092e+008
1140.908;0.7864816;-1.552376;2512.245;259.5992;3;3;0;2.477108;2.446925;2305600;2.660297e+008
1143.908;0.8014817;-1.569553;2651.112;273.9488;3;3;0;2.524352;2.493016;2433044;2.808642e+008
1146.908;0.8165352;-1.586439;2791.829;288.4896;3;3;0;2.571764;2.539251;2562186;2.959089e+008
1149.908;0.8315351;-1.603552;2931.019;302.8726;3;3;0;2.619008;2.5853;2689927;3.108048e+008
1152.908;0.8464816;-1.620516;3070.169;317.2515;3;3;0;2.666084;2.631163;2817631;3.257097e+008
1155.908;0.8615352;-1.637641;3210.405;331.7426;3;3;0;2.713496;2.677334;2946332;3.407444e+008
1158.908;0.8764816;-1.655211;3351.535;346.326;3;3;0;2.760572;2.723155;3075854;3.558866e+008
1161.908;0.8916423;-1.672978;3495.96;361.2499;3;3;0;2.808322;2.769612;3208399;3.71395e+008
1164.908;0.9065351;-1.690937;3637.197;375.8444;3;3;0;2.855229;2.815227;3338018;3.865756e+008
1167.908;0.9216423;-1.709202;3782.977;390.9084;3;3;0;2.90281;2.861477;3471807;4.022558e+008
1170.908;0.9365887;-1.7276;3926.522;405.7415;3;3;0;2.949886;2.907214;3603545;4.177104e+008
1173.908;0.9514816;-1.745433;4070.108;420.5786;3;3;0;2.996792;2.952766;3735320;4.331825e+008
1176.908;0.9666423;-1.764638;4218.766;435.94;3;3;0;3.044543;2.999116;3871750;4.492124e+008
1179.908;0.9814279;-1.783476;4362.369;450.7791;3;3;0;3.091111;3.044299;4003541;4.647131e+008
1182.908;0.9966422;-1.802818;4513.54;466.4001;3;3;0;3.13903;3.09077;4142277;4.810406e+008
1185.908;1.011428;-1.82217;4659.816;481.5152;3;3;0;3.1856;3.135912;4276521;4.968544e+008
1188.908;1.026535;-1.841898;4809.729;497.0063;3;3;0;3.233181;3.182014;4414103;5.130754e+008
1191.908;1.041481;-1.861929;4956.107;512.132;3;3;0;3.280256;3.227604;4548440;5.289313e+008
1194.908;1.056428;-1.881973;5101.175;527.1224;3;3;0;3.327332;3.273174;4681576;5.446616e+008
1197.908;1.071535;-1.902586;5247.303;542.2224;3;3;0;3.374914;3.319213;4815685;5.60522e+008
1200.908;1.086481;-1.923271;5389.514;556.9176;3;3;0;3.421989;3.364741;4946198;5.759752e+008
1203.908;1.101481;-1.944483;5529.983;571.4327;3;3;0;3.469233;3.410411;5075112;5.91257e+008
1206.908;1.116589;-1.966981;5666.975;585.5886;3;3;0;3.516814;3.456387;5200836;6.061827e+008
1209.908;1.131481;-1.990205;5791.732;598.4802;3;3;0;3.563721;3.50169;5315331;6.198083e+008
1212.908;1.146642;-2.015864;5909.413;610.6405;3;3;0;3.611471;3.547787;5423332;6.326936e+008
1214.638;1.147553;-2.023867;5865.091;606.0607;3;3;0;3.61434;3.550555;5382656;6.279657e+008
1217.112;1.134856;-2.013692;5639.889;582.7897;3;3;0;3.574351;3.511953;5175978;6.036206e+008
1219.828;1.121464;-2.001932;5414.673;559.5173;3;3;0;3.532169;3.471219;4969287;5.792804e+008
1222.6;1.107428;-1.989308;5189.396;536.2386;3;3;0;3.487962;3.428511;4762540;5.549424e+008
1225.526;1.09291;-1.975973;4964.068;512.9548;3;3;0;3.442236;3.384317;4555747;5.306119e+008
1228.494;1.078124;-1.962044;4741.156;489.9204;3;3;0;3.395667;3.339287;4351170;5.065565e+008
1231.482;1.063017;-1.947364;4520.414;467.1104;3;3;0;3.348086;3.293258;4148586;4.827496e+008
1234.482;1.048231;-1.932736;4310.804;445.4506;3;3;0;3.301517;3.248187;3956217;4.601572e+008
1237.482;1.033071;-1.917904;4103.206;423.9988;3;3;0;3.253766;3.201952;3765695;4.377947e+008
1240.482;1.018178;-1.902291;3904.213;403.4361;3;3;0;3.206859;3.156513;3583070;4.163737e+008
1243.482;1.003178;-1.885984;3711.011;383.472;3;3;0;3.159615;3.110726;3405761;3.955882e+008
1246.482;0.988178;-1.869814;3524.143;364.1622;3;3;0;3.112372;3.064919;3234264;3.754963e+008
1249.482;0.9732315;-1.853817;3346.544;345.8103;3;3;0;3.065296;3.019254;3071273;3.564104e+008
1252.482;0.958178;-1.837844;3174.398;328.0218;3;3;0;3.017884;2.973241;2913287;3.379211e+008
1255.482;0.943178;-1.821626;3009.353;310.9671;3;3;0;2.970639;2.927371;2761818;3.202048e+008
1258.482;0.9282315;-1.805499;2849.86;294.4862;3;3;0;2.923564;2.881643;2615444;3.030957e+008
1261.482;0.9130708;-1.789191;2693.109;278.2885;3;3;0;2.875814;2.835238;2471587;2.862916e+008
1264.482;0.8982315;-1.773331;2545.718;263.058;3;3;0;2.829076;2.789796;2336319;2.705001e+008
1267.482;0.8830173;-1.756838;2397.734;247.7664;3;3;0;2.781157;2.743185;2200508;2.546572e+008
1270.482;0.868178;-1.740642;2258.831;233.413;3;3;0;2.734419;2.697702;2073030;2.397954e+008
1273.482;0.8531244;-1.724323;2121.944;219.268;3;3;0;2.687006;2.65154;1947403;2.251598e+008
1276.482;0.8380709;-1.707988;1990.078;205.6418;3;3;0;2.639593;2.605357;1826384;2.1107e+008
1279.482;0.8231781;-1.691583;1861.54;192.3595;3;3;0;2.592687;2.559647;1708418;1.973468e+008
1282.482;0.8080174;-1.67462;1733.189;179.0966;3;3;0;2.544937;2.513092;1590625;1.836545e+008
1285.482;0.7932316;-1.658071;1613.107;166.688;3;3;0;2.498367;2.467668;1480420;1.708525e+008
1288.482;0.7781244;-1.641354;1494.793;154.4623;3;3;0;2.450786;2.421236;1371839;1.582478e+008
1291.482;0.7631781;-1.624855;1381.564;142.7619;3;3;0;2.403711;2.375276;1267923;1.461935e+008
1294.482;0.7481781;-1.608265;1270.327;131.2674;3;3;0;2.356466;2.32913;1165836;1.343607e+008
1297.482;0.7331781;-1.591449;1160.279;119.8958;3;3;0;2.309222;2.282964;1064840;1.226644e+008
1300.482;0.7181781;-1.574454;1055.447;109.0631;3;3;0;2.261978;2.236775;968631.1;1.115301e+008
1303.482;0.7031781;-1.557776;951.7148;98.34406;3;3;0;2.214734;2.190565;873431.1;1.005221e+008
1306.482;0.6881246;-1.540829;851.7905;88.01853;3;3;0;2.167321;2.144169;781726.1;8.992617e+007
1309.482;0.6732317;-1.524279;755.0508;78.02207;3;3;0;2.120415;2.098247;692943.8;7.967646e+007
1312.482;0.658071;-1.507162;659.3655;68.13457;3;3;0;2.072664;2.051477;605129.1;6.954677e+007
1315.482;0.6432317;-1.49081;570.3705;58.9384;3;3;0;2.025927;2.005678;523454.4;6.013245e+007
1318.482;0.6280174;-1.474711;481.4253;49.74738;3;3;0;1.978008;1.958699;441825.5;5.073139e+007
1321.482;0.6131782;-1.458735;399.456;41.2772;3;3;0;1.93127;1.912858;366598.6;4.207438e+007
1324.482;0.5981246;-1.443295;319.0423;32.96777;3;3;0;1.883857;1.866332;292799.3;3.358883e+007
1327.482;0.5830711;-1.429739;243.379;25.14921;3;3;0;1.836444;1.819785;223359.7;2.561106e+007
1330.482;0.5681782;-1.417602;173.2995;17.90765;3;3;0;1.789538;1.773714;159044.7;1.822812e+007
1333.482;0.5530175;-1.406323;108.3814;11.19943;3;3;0;1.741787;1.726792;99466.43;1.13945e+007
1336.482;0.5381782;-1.39769;58.46993;6.041905;3;3;0;1.69505;1.680844;53660.46;6144318
1336.588;0.5376425;-1.397418;56.96156;5.88604;3;3;0;1.693362;1.679185;52276.17;5985712