File: Ensayos/Graficos/EspA/EspA60Ext25.raw
"Test Type";"Manual"
"Method Name:";"C:\INSTRON\user\template\CYCLE.MTM"
"Name:";""
"Operator ID:";""
"Company:";""
"Lab name:";""
"Test date:";"28/03/2017"
"Temperature:";""
"Humidity:";""
"Note 1:";""
"Note 2:";""
"Note 3:";""
"Geometry:";"Rectangular"
"Specimen";1
"Specimen name:";""
"Width:";0.250000;"in"
"Thickness:";0.060000;"in"
"Length:";1.250000;"in"
"Diameter:";0.039370;"in"
"Inner diameter:";0.019685;"in"
"Outer diameter:";0.039370;"in"
"Wall thickness:";0.019685;"in"
"Area:";0.015000;"in*in"
"Linear density:";1.000000;"den"
"Sled weight:";2.204623;"lbf"
"Loading span:";0.000000;"mm"
"Support span:";1.000000;"mm"
"Span ratio:";"2"
"Fixture type:";"3-point"
"Comment:";""
"Included"
"Final Width:";0.250000;"in"
"Final Thickness:";0.060000;"in"
"Final Length:";1.250000;"in"
"Final Diameter:";0.039370;"in"
"Final Inner diameter:";0.019685;"in"
"Final Outer diameter:";0.039370;"in"
"Final Wall thickness:";0.019685;"in"
"Final Area:";0.015000;"in*in"
"Final Linear density:";1.000000;"den"
"Time sec";"Extension mm";"Strain 1 %";"Load N";"Stress MPa";"Cycle Count ";"Total Cycle Count ";"Repetitions Count ";"Strain [Exten.] %";"True strain %";"Tenacity gf/tex";"True stress Pa"
0;-5.35714e-005;1.316068e-005;52.62771;5.438208;0;0;0;-0.0001687288;-0.000168729;48298.8;5438199
4;0.01333928;-0.0004895378;71.28934;7.36658;0;0;0;0.04201347;0.04200465;65425.41;7369675
8;0.02673213;-0.002066567;113.8783;11.76745;0;0;0;0.08419567;0.08416025;104511.2;1.177735e+007
12;0.03996426;-0.004361561;168.4316;17.40463;0;0;0;0.1258717;0.1257925;154577.1;1.742654e+007
16;0.05324997;-0.00664658;223.9522;23.14178;0;0;0;0.1677164;0.167576;205531;2.318059e+007
20;0.06658925;-0.009209412;278.4729;28.77559;0;0;0;0.2097299;0.2095103;255567;2.883595e+007
24;0.07992851;-0.01207802;338.3309;34.96093;0;0;0;0.2517433;0.251427;310501.4;3.504895e+007
28;0.09332137;-0.01527922;400.2993;41.36434;0;0;0;0.2939256;0.2934945;367372.5;4.148592e+007
32;0.1065535;-0.01895953;462.2746;47.76847;0;0;0;0.3356016;0.3350397;424250;4.792878e+007
36;0.1199999;-0.02295958;527.8758;54.54727;0;0;0;0.3779525;0.3772401;484455.1;5.475344e+007
40;0.1333928;-0.02693022;593.6264;61.34151;0;0;0;0.4201347;0.4192546;544797.4;6.159923e+007
44;0.1466249;-0.03058108;661.1275;68.31664;0;0;0;0.4618107;0.4607477;606746.2;6.863214e+007
48;0.1600713;-0.03428673;736.2732;76.08172;0;0;0;0.5041617;0.502895;675710.8;7.64653e+007
52;0.1734106;-0.03889216;817.9935;84.52616;0;0;0;0.5461751;0.544689;750709.1;8.498782e+007
56;0.1866427;-0.04505396;905.3023;93.54809;0;0;0;0.5878512;0.58613;830836.3;9.409801e+007
60;0.2000892;-0.05192826;995.3152;102.8494;0;0;0;0.6302021;0.6282246;913445.2;1.034976e+008
64;0.2132677;-0.05960814;1084.756;112.0916;0;0;0;0.6717094;0.6694634;995528.5;1.128446e+008
68;0.226607;-0.06765403;1174.526;121.3679;0;0;0;0.7137229;0.7111879;1077915;1.222342e+008
72;0.2398927;-0.07671628;1264.868;130.7033;0;0;0;0.7555676;0.7527275;1160826;1.316909e+008
76;0.253232;-0.08684954;1355.651;140.0842;0;0;0;0.797581;0.7944172;1244141;1.412015e+008
80;0.2666784;-0.09765925;1449.028;149.7332;0;0;0;0.839932;0.8364242;1329837;1.509908e+008
84.00001;0.2799105;-0.1086404;1540.897;159.2263;0;0;0;0.881608;0.8777445;1414150;1.606301e+008
88.00001;0.293357;-0.1199687;1633.827;168.8292;0;0;0;0.9239589;0.9197165;1499436;1.703891e+008
92.00001;0.3066962;-0.1315912;1725.225;178.2736;0;0;0;0.9659723;0.9613366;1583316;1.799956e+008
96.00001;0.319982;-0.1432338;1813.72;187.4181;0;0;0;1.007817;1.002773;1664531;1.893069e+008
100;0.3334284;-0.1559443;1900.945;196.4314;0;0;0;1.050168;1.044692;1744582;1.984942e+008
104;0.3467676;-0.1689196;1987.329;205.3577;0;0;0;1.092182;1.08626;1823860;2.076006e+008
108;0.3599462;-0.1825065;2070.046;213.9052;0;0;0;1.133689;1.127311;1899774;2.163302e+008
112;0.373339;-0.196663;2153.326;222.5108;0;0;0;1.175871;1.169011;1976203;2.251272e+008
116;0.3866247;-0.2109952;2232.481;230.6901;0;0;0;1.217716;1.210361;2048847;2.334993e+008
120;0.399964;-0.2259363;2311.037;238.8076;0;0;0;1.259729;1.251861;2120942;2.418159e+008
124;0.4132497;-0.241533;2388.24;246.7853;0;0;0;1.301574;1.293176;2191795;2.499974e+008
128;0.426589;-0.2570465;2462.151;254.4228;0;0;0;1.343587;1.334641;2259626;2.578411e+008
132;0.4399818;-0.2731664;2536.43;262.0983;0;0;0;1.38577;1.376256;2327795;2.657304e+008
136;0.4532676;-0.2895743;2608.196;269.5141;0;0;0;1.427614;1.41752;2393658;2.733617e+008
140;0.466714;-0.306805;2679.467;276.8788;0;0;0;1.469965;1.459266;2459066;2.809488e+008
144;0.4800533;-0.3249281;2748.606;284.0232;0;0;0;1.511979;1.500662;2522519;2.883176e+008
148;0.493339;-0.3431399;2816.236;291.0117;0;0;0;1.553824;1.541875;2584586;2.955335e+008
152;0.5067854;-0.3622104;2883.705;297.9835;0;0;0;1.596174;1.583569;2646505;3.027398e+008
156;0.5201246;-0.381568;2947.731;304.5995;0;0;0;1.638188;1.624914;2705264;3.095894e+008
160;0.5333032;-0.4003271;3009.662;310.999;0;0;0;1.679695;1.665744;2762101;3.162229e+008
164;0.5466425;-0.4194009;3071.7;317.4096;0;0;0;1.721709;1.707055;2819036;3.228745e+008
168;0.5599282;-0.4385016;3130.44;323.4795;0;0;0;1.763553;1.748183;2872945;3.291842e+008
172;0.5732675;-0.4577677;3189.689;329.6019;0;0;0;1.805567;1.78946;2927320;3.35553e+008
176;0.5865532;-0.4770752;3248.728;335.7025;0;0;0;1.847412;1.830554;2981502;3.419043e+008
180;0.599946;-0.4967262;3306.511;341.6734;0;0;0;1.889594;1.871963;3034532;3.481297e+008
184;0.6133389;-0.5166388;3364.68;347.6843;0;0;0;1.931776;1.913354;3087917;3.544008e+008
188;0.6266246;-0.536695;3420.83;353.4865;0;0;0;1.973621;1.954397;3139449;3.60463e+008
192;0.6400175;-0.5571866;3478.043;359.3985;0;0;0;2.015803;1.995755;3191955;3.666432e+008
196;0.6534102;-0.5779392;3534.561;365.2387;0;0;0;2.057985;2.037095;3243824;3.727552e+008
200;0.6666424;-0.5991715;3590.521;371.0213;0;0;0;2.099661;2.077922;3295182;3.788115e+008
204;0.6800889;-0.6213015;3646.609;376.817;0;0;0;2.142012;2.119393;3346656;3.848885e+008
208;0.6933745;-0.642821;3701.442;382.4832;0;0;0;2.183857;2.160352;3396979;3.90836e+008
212;0.7066067;-0.6647925;3755.253;388.0436;0;0;0;2.225533;2.201129;3446363;3.966796e+008
216;0.719946;-0.6874598;3811.596;393.8658;0;0;0;2.267546;2.24222;3498072;4.027968e+008
220;0.7332853;-0.710536;3864.627;399.3456;0;0;0;2.30956;2.283293;3546741;4.085687e+008
224;0.7466245;-0.7334585;3918.47;404.9094;0;0;0;2.351573;2.32435;3596155;4.144312e+008
228;0.7599103;-0.7571387;3972.304;410.4723;0;0;0;2.393418;2.365225;3645561;4.202966e+008
232;0.773303;-0.7807897;4026.228;416.0444;0;0;0;2.4356;2.406412;3695049;4.261776e+008
236;0.7866959;-0.8047341;4080.851;421.6888;0;0;0;2.477782;2.447583;3745179;4.321373e+008
240;0.7999281;-0.8285949;4134.044;427.1854;0;0;0;2.519459;2.488243;3793996;4.379481e+008
244;0.8134281;-0.8531047;4189.34;432.8993;0;0;0;2.561978;2.529709;3844744;4.439901e+008
248;0.8267138;-0.877133;4241.538;438.2932;0;0;0;2.603823;2.570501;3892649;4.497056e+008
252;0.8399994;-0.9011453;4292.696;443.5795;0;0;0;2.645668;2.611275;3939599;4.553151e+008
256;0.8533923;-0.9255957;4345.935;449.0808;0;0;0;2.68785;2.652362;3988458;4.611515e+008
260;0.866678;-0.9504731;4396.249;454.28;0;0;0;2.729695;2.693103;4034634;4.666804e+008
264;0.8799101;-0.9752398;4446.15;459.4364;0;0;0;2.771371;2.733663;4080430;4.721691e+008
268;0.893303;-1.000871;4498.838;464.8809;0;0;0;2.813553;2.774699;4128784;4.779605e+008
270.948;0.903053;-1.01998;4535.811;468.7014;0;0;0;2.844261;2.804563;4162716;4.820325e+008
274.948;0.8898209;-1.01087;4304.011;444.7487;0;0;0;2.802585;2.764032;3949983;4.572132e+008
278.948;0.8763745;-0.9991474;4102.63;423.9392;0;0;0;2.760235;2.722827;3765166;4.35641e+008
282.948;0.8630887;-0.9874135;3919.398;405.0053;0;0;0;2.71839;2.682098;3597006;4.160149e+008
286.948;0.8498566;-0.9753865;3750.265;387.5281;0;0;0;2.676714;2.641516;3441785;3.979011e+008
290.948;0.8365174;-0.9624775;3591.293;371.101;0;0;0;2.6347;2.60059;3295889;3.808784e+008
294.948;0.8232316;-0.9493759;3439.598;355.4258;0;0;0;2.592855;2.559811;3156672;3.646415e+008
298.948;0.8098924;-0.935915;3292.461;340.2216;0;0;0;2.550842;2.518851;3021638;3.489001e+008
302.948;0.7965531;-0.9218197;3149.64;325.4634;0;0;0;2.508829;2.477874;2890565;3.336287e+008
306.948;0.7831602;-0.9074149;3012.239;311.2654;0;0;0;2.466646;2.436716;2764466;3.189432e+008
310.948;0.7698209;-0.8928692;2879.774;297.5772;0;0;0;2.424633;2.395705;2642897;3.047924e+008
314.948;0.7565352;-0.878538;2754.516;284.6339;0;0;0;2.382788;2.354843;2527942;2.914161e+008
318.948;0.7430352;-0.863922;2634.148;272.1958;0;0;0;2.340268;2.313304;2417475;2.785659e+008
322.948;0.7297495;-0.8495747;2519.316;260.3299;0;0;0;2.298424;2.272408;2312089;2.663133e+008
326.948;0.7164638;-0.8353189;2409.701;249.0029;0;0;0;2.256579;2.231495;2211490;2.546219e+008
330.948;0.703071;-0.8209025;2303.579;238.0369;0;0;0;2.214397;2.190235;2114097;2.43308e+008
334.948;0.6897853;-0.8066068;2202.117;227.5526;0;0;0;2.172552;2.149289;2020981;2.324963e+008
338.948;0.6766067;-0.7924545;2104.672;217.4832;0;0;0;2.131045;2.108656;1931552;2.221179e+008
342.948;0.6631602;-0.7778046;2008.454;207.5406;0;0;0;2.088694;2.06718;1843248;2.118755e+008
346.948;0.6498746;-0.7633694;1917.371;198.1287;0;0;0;2.046849;2.026183;1759657;2.021841e+008
350.948;0.6365353;-0.7487673;1828.877;188.9843;0;0;0;2.004835;1.985003;1678442;1.927732e+008
354.948;0.623196;-0.7342224;1743.949;180.2085;0;0;0;1.962822;1.943807;1600500;1.837456e+008
358.948;0.6098032;-0.7194699;1661.855;171.7254;0;0;0;1.92064;1.902429;1525159;1.750236e+008
362.948;0.5964639;-0.704734;1581.855;163.4587;0;0;0;1.878626;1.861198;1451739;1.665294e+008
366.948;0.5831782;-0.6903123;1504.635;155.4793;0;0;0;1.836782;1.820117;1380871;1.583351e+008
370.948;0.5697317;-0.6753519;1428.564;147.6185;0;0;0;1.794431;1.778521;1311057;1.502674e+008
374.948;0.5563925;-0.6603113;1354.476;139.9628;0;0;0;1.752417;1.737239;1243063;1.424156e+008
378.948;0.5431604;-0.6456115;1282.615;132.5371;0;0;0;1.710741;1.696273;1177113;1.348045e+008
382.948;0.5297139;-0.6302084;1211.345;125.1726;0;0;0;1.66839;1.654626;1111706;1.27261e+008
386.948;0.5164818;-0.614752;1141.213;117.9256;0;0;0;1.626714;1.613625;1047342;1.198439e+008
390.948;0.5032496;-0.5987845;1071.71;110.7436;0;0;0;1.585038;1.572608;983556.4;1.12499e+008
394.948;0.4898568;-0.5826731;1002.629;103.6052;0;0;0;1.542856;1.531075;920156.9;1.052036e+008
398.948;0.4765711;-0.5664951;935.4614;96.66454;0;0;0;1.501011;1.489858;858514.6;9.811548e+007
402.948;0.4631783;-0.5499054;867.8587;89.67891;0;0;0;1.458829;1.448291;796472.6;9.098717e+007
406.948;0.4498926;-0.5334121;801.883;82.8614;0;0;0;1.416984;1.407039;735923.8;8.403554e+007
410.948;0.4364461;-0.5170973;736.6077;76.11629;0;0;0;1.374634;1.365271;676017.8;7.716261e+007
414.948;0.4231069;-0.5012883;673.6868;69.61444;0;0;0;1.33262;1.323819;618272.4;7.054214e+007
418.948;0.4098212;-0.4861686;612.7113;63.31362;0;0;0;1.290775;1.282516;562312.4;6.413086e+007
422.948;0.3963747;-0.4711909;552.635;57.10573;0;0;0;1.248424;1.240696;507177.8;5.781865e+007
426.948;0.383089;-0.4562834;495.1951;51.17027;0;0;0;1.20658;1.199358;454462.7;5.178768e+007
430.948;0.3698569;-0.4418846;439.9439;45.46096;0;0;0;1.164904;1.158171;403756.2;4.599054e+007
434.948;0.3564105;-0.4282425;387.5015;40.0419;0;0;0;1.122553;1.116299;355627.4;4.049139e+007
438.948;0.3431783;-0.4153152;337.5588;34.88114;0;0;0;1.080877;1.075077;309792.8;3.525816e+007
442.948;0.3298926;-0.4031892;290.2758;29.99522;0;0;0;1.039032;1.033671;266399;3.030688e+007
446.948;0.3164998;-0.3913203;245.7436;25.39355;0;0;0;0.9968497;0.991914;225529.8;2.564669e+007
450.948;0.3031605;-0.3815166;206.4984;21.33821;0;0;0;0.9548363;0.9503065;189512.8;2.154195e+007
454.948;0.2898212;-0.3724036;170.3735;17.6053;0;0;0;0.9128228;0.9086817;156359.4;1.7766e+007
458.948;0.2765355;-0.3634812;135.0645;13.9567;0;0;0;0.870978;0.8672069;123954.8;1.407826e+007
462.948;0.2630891;-0.3554315;105.6832;10.92062;0;0;0;0.8286271;0.8252129;96990.17;1.101111e+007
466.948;0.2497498;-0.3482223;79.05944;8.169492;0;0;0;0.7866137;0.783536;72556.38;8233754
469.462;0.2414999;-0.3439794;64.44718;6.659555;1;1;0;0.7606295;0.7577513;59146.05;6710210
473.462;0.2548391;-0.3456861;125.8681;13.0064;1;1;0;0.8026429;0.7994389;115514.8;1.311079e+007
477.462;0.2680713;-0.3481243;190.0614;19.63972;1;1;0;0.8443189;0.8407745;174427.8;1.980554e+007
481.462;0.2814641;-0.3507141;256.8375;26.53993;1;1;0;0.8865011;0.8825948;235711.3;2.677521e+007
485.462;0.2946963;-0.353974;326.9091;33.78068;1;1;0;0.9281772;0.9238961;300019.1;3.409422e+007
489.462;0.3080355;-0.3571886;401.5894;41.49765;1;1;0;0.9701906;0.9655145;368556.5;4.190026e+007
493.462;0.3213748;-0.3606473;477.0656;49.29688;1;1;0;1.012204;1.007116;437824.4;4.979587e+007
497.462;0.3347141;-0.3649442;557.4707;57.60542;1;1;0;1.054217;1.048699;511615.7;5.82127e+007
501.462;0.3481069;-0.3708789;647.7778;66.93717;1;1;0;1.0964;1.090433;594494.6;6.767107e+007
505.462;0.3613391;-0.3771137;740.2709;76.49481;1;1;0;1.138076;1.131648;679379.6;7.736538e+007
509.462;0.374839;-0.3835779;837.342;86.52551;1;1;0;1.180595;1.173681;768466.1;8.754703e+007
513.462;0.3881783;-0.3904283;935.2377;96.64142;1;1;0;1.222609;1.215195;858309.3;9.782297e+007
517.462;0.401464;-0.3984358;1035.494;107.0013;1;1;0;1.264454;1.256526;950319.2;1.083543e+008
521.462;0.4148569;-0.4082223;1137.298;117.5211;1;1;0;1.306636;1.298173;1043750;1.190566e+008
525.4621;0.4281426;-0.4192346;1238.198;127.9474;1;1;0;1.348481;1.33947;1136349;1.296727e+008
529.4621;0.4413747;-0.4311223;1337.088;138.166;1;1;0;1.390157;1.380583;1227105;1.400867e+008
533.4621;0.4547676;-0.4437537;1436.782;148.4678;1;1;0;1.432339;1.422178;1318599;1.505943e+008
537.4621;0.4679997;-0.456766;1532.861;158.3959;1;1;0;1.474015;1.463257;1406775;1.607307e+008
541.4621;0.4813926;-0.4701846;1629.108;168.3415;1;1;0;1.516197;1.504818;1495105;1.708939e+008
545.4621;0.4946782;-0.4837916;1721.893;177.9294;1;1;0;1.558042;1.546029;1580258;1.807016e+008
549.4621;0.5080711;-0.4977939;1814.822;187.532;1;1;0;1.600224;1.587555;1665544;1.90533e+008
553.4621;0.5214639;-0.5120138;1905.739;196.9267;1;1;0;1.642406;1.629064;1748981;2.00161e+008
557.4621;0.5346961;-0.5265713;1994.843;206.1342;1;1;0;1.684082;1.670059;1830756;2.096056e+008
561.4621;0.5481425;-0.541285;2083.901;215.3369;1;1;0;1.726433;1.7117;1912489;2.190545e+008
565.4621;0.5615354;-0.556141;2171.903;224.4304;1;1;0;1.768615;1.753157;1993252;2.283997e+008
569.4621;0.5747675;-0.5710961;2257.974;233.3245;1;1;0;1.810291;1.794101;2072244;2.375483e+008
573.4621;0.5881604;-0.5863882;2346.151;242.4361;1;1;0;1.852474;1.835524;2153168;2.469272e+008
577.4621;0.601446;-0.6016149;2433.007;251.4113;1;1;0;1.894318;1.876599;2232880;2.561738e+008
581.4621;0.6147318;-0.6169327;2519.157;260.3134;1;1;0;1.936163;1.917658;2311943;2.653535e+008
585.4621;0.628071;-0.632914;2607.787;269.4719;1;1;0;1.978176;1.958865;2393282;2.748025e+008
589.4621;0.6413567;-0.6498586;2696.158;278.6035;1;1;0;2.020021;1.999889;2474384;2.842314e+008
593.4621;0.6547495;-0.6669415;2785.772;287.8637;1;1;0;2.062203;2.041228;2556628;2.938e+008
597.4621;0.6679817;-0.684201;2875.415;297.1268;1;1;0;2.103879;2.082054;2638897;3.03378e+008
601.4621;0.6814281;-0.7017834;2967.188;306.6101;1;1;0;2.14623;2.123523;2723121;3.131906e+008
605.4621;0.694821;-0.7193577;3058.626;316.0587;1;1;0;2.188413;2.164811;2807038;3.229754e+008
609.4621;0.7081067;-0.7369318;3149.653;325.4648;1;1;0;2.230257;2.205751;2890577;3.327235e+008
613.4621;0.7215531;-0.7551628;3243.584;335.171;1;1;0;2.272608;2.247169;2976782;3.427881e+008
617.4621;0.7348924;-0.7733675;3337.636;344.8897;1;1;0;2.314622;2.288241;3063097;3.528726e+008
621.4621;0.7481245;-0.7913278;3430.411;354.4766;1;1;0;2.356298;2.328966;3148242;3.628291e+008
625.4621;0.7615174;-0.8095247;3525.83;364.3365;1;1;0;2.39848;2.370168;3235811;3.73075e+008
629.4621;0.7747495;-0.8279325;3619.977;374.0651;1;1;0;2.440156;2.41086;3322215;3.831929e+008
633.4621;0.7880888;-0.8465257;3715.637;383.95;1;1;0;2.482169;2.451864;3410006;3.934802e+008
637.4621;0.8013745;-0.8653532;3812.518;393.961;1;1;0;2.524014;2.492687;3498918;4.039046e+008
641.4621;0.8147137;-0.8843179;3908.51;403.8801;1;1;0;2.566027;2.533658;3587014;4.142438e+008
645.4621;0.8281066;-0.9032252;4004.528;413.802;1;1;0;2.60821;2.574776;3675134;4.245949e+008
649.4621;0.8413388;-0.9217383;4097.736;423.4336;1;1;0;2.649886;2.615385;3760675;4.346541e+008
653.4621;0.8547852;-0.9409827;4191.746;433.1479;1;1;0;2.692237;2.656634;3846952;4.448093e+008
657.4621;0.868178;-0.9604988;4284.659;442.7489;1;1;0;2.734419;2.697702;3932222;4.548555e+008
661.4621;0.8814102;-0.9803437;4373.589;451.9384;1;1;0;2.776095;2.73826;4013838;4.644847e+008
665.0061;0.8931959;-0.9984665;4450.484;459.8843;1;1;0;2.813215;2.774371;4084408;4.728218e+008
668.0081;0.883178;-0.9917629;4275.936;441.8476;1;1;0;2.781663;2.743678;3924217;4.541383e+008
672.0081;0.8699459;-0.9805263;4073.838;420.9641;1;1;0;2.739987;2.703121;3738743;4.324984e+008
676.0081;0.8566066;-0.968934;3885.665;401.5195;1;1;0;2.697974;2.66222;3566048;4.123524e+008
680.0081;0.8433209;-0.9572171;3712.765;383.6531;1;1;0;2.656129;2.621466;3407370;3.938434e+008
684.0081;0.8300351;-0.9444898;3552.099;367.051;1;1;0;2.614284;2.580696;3259920;3.766468e+008
688.0081;0.8166424;-0.9311392;3397.187;351.0434;1;1;0;2.572102;2.53958;3117750;3.600725e+008
692.0081;0.803303;-0.9175124;3247.753;335.6018;1;1;0;2.530088;2.498611;2980608;3.440928e+008
696.0081;0.7899102;-0.9037406;3102.93;320.6368;1;1;0;2.487906;2.457462;2847698;3.286139e+008
700.0081;0.7766245;-0.8896467;2964.765;306.3597;1;1;0;2.446061;2.416624;2720897;3.138534e+008
704.0081;0.7631781;-0.8754671;2831.022;292.5396;1;1;0;2.403711;2.375276;2598156;2.995714e+008
708.0081;0.7498388;-0.8613598;2704.734;279.4897;1;1;0;2.361697;2.33424;2482255;2.860904e+008
712.0081;0.7366066;-0.8474372;2584.843;267.101;1;1;0;2.320021;2.293517;2372226;2.732978e+008
716.0081;0.7231066;-0.8331208;2468.801;255.1099;1;1;0;2.277501;2.251953;2265729;2.609201e+008
720.0081;0.7098745;-0.8192319;2358.527;243.7149;1;1;0;2.235825;2.211197;2164525;2.49164e+008
724.0081;0.6966425;-0.8052347;2253.889;232.9023;1;1;0;2.194149;2.170424;2068494;2.380125e+008
728.0081;0.6832495;-0.79097;2151.329;222.3044;1;1;0;2.151967;2.129139;1974370;2.270883e+008
732.0081;0.6699638;-0.7767312;2053.035;212.1474;1;1;0;2.110122;2.088168;1884162;2.166239e+008
736.0081;0.6566782;-0.7623583;1958.085;202.3359;1;1;0;2.068278;2.047179;1797022;2.065207e+008
740.0081;0.6432852;-0.7480325;1866.364;192.858;1;1;0;2.026095;2.005843;1712845;1.967655e+008
744.0081;0.629946;-0.7335845;1778.225;183.7503;1;1;0;1.984082;1.964656;1631957;1.873961e+008
748.0081;0.6166067;-0.7192668;1693.466;174.9918;1;1;0;1.942068;1.923451;1554169;1.783902e+008
752.0081;0.603321;-0.7051245;1611.504;166.5224;1;1;0;1.900224;1.882395;1478949;1.696867e+008
756.0081;0.5898747;-0.6906294;1531.023;158.206;1;1;0;1.857873;1.840825;1405088;1.611453e+008
760.0081;0.5765353;-0.6761488;1452.873;150.1305;1;1;0;1.815859;1.79957;1333366;1.528566e+008
764.0081;0.5632496;-0.6616914;1376.623;142.2513;1;1;0;1.774015;1.758463;1263389;1.447749e+008
768.0081;0.5498032;-0.6468283;1301.308;134.4688;1;1;0;1.731664;1.716841;1194269;1.367973e+008
772.0081;0.5365175;-0.6322381;1228.715;126.9675;1;1;0;1.689819;1.6757;1127647;1.29113e+008
776.0081;0.5233389;-0.6172545;1157.1;119.5673;1;1;0;1.648312;1.634874;1061923;1.215381e+008
780.0081;0.5099461;-0.6017777;1084.479;112.063;1;1;0;1.606129;1.593368;995274.6;1.138629e+008
784.0081;0.4966604;-0.5864056;1013.824;104.762;1;1;0;1.564285;1.552176;930431.1;1.064008e+008
788.0081;0.4833211;-0.5708065;943.0438;97.44805;1;1;0;1.522271;1.510801;865473.3;9.893148e+007
792.0081;0.4699819;-0.5551863;873.2054;90.2314;1;1;0;1.480258;1.469409;801379.5;9.156706e+007
796.0081;0.456589;-0.5393889;803.5637;83.03508;1;1;0;1.438076;1.427833;737466.2;8.422919e+007
800.0081;0.4432497;-0.5239938;734.7025;75.91941;1;1;0;1.396062;1.386407;674269.3;7.69793e+007
804.0081;0.429964;-0.5094098;668.0164;69.0285;1;1;0;1.354217;1.34513;613068.5;6.99633e+007
808.0081;0.4165176;-0.4949755;602.162;62.22353;1;1;0;1.311866;1.303336;552630.9;6.303982e+007
812.0081;0.4031783;-0.4809957;538.6526;55.66088;1;1;0;1.269853;1.261858;494345.5;5.636769e+007
816.0081;0.3899462;-0.4678993;478.3625;49.43089;1;1;0;1.228177;1.220696;439014.6;5.003799e+007
820.0081;0.3764997;-0.4556237;420.055;43.40577;1;1;0;1.185826;1.17885;385503.2;4.392049e+007
824.0081;0.3632141;-0.4442054;364.6475;37.68032;1;1;0;1.143981;1.137487;334653.3;3.811138e+007
828.0081;0.3499819;-0.433723;311.9885;32.23888;1;1;0;1.102305;1.096274;286325.8;3.259425e+007
832.0081;0.336589;-0.4237595;261.9037;27.06344;1;1;0;1.060123;1.054543;240360.7;2.735034e+007
836.0081;0.3233034;-0.4156039;218.1641;22.54366;1;1;0;1.018278;1.013129;200218.9;2.277322e+007
840.0081;0.3099641;-0.408466;177.4149;18.33291;1;1;0;0.9762648;0.9715302;162821.6;1.851189e+007
844.0081;0.2966248;-0.4015671;138.2504;14.2859;1;1;0;0.9342514;0.9299143;126878.5;1.441936e+007
848.0081;0.283232;-0.3951822;104.1727;10.76453;1;1;0;0.8920692;0.8881138;95603.93;1.086056e+007
852.0081;0.2698927;-0.3899075;73.56755;7.601995;1;1;0;0.8500557;0.8464631;67516.23;7666617
856.0081;0.256607;-0.3856501;50.99016;5.268994;1;1;0;0.8082109;0.8049624;46795.95;5311579
858.5341;0.2482498;-0.3849332;49.40268;5.104954;2;2;0;0.7818893;0.7788483;45339.04;5144869
862.5341;0.2616427;-0.3852523;68.50796;7.07917;2;2;0;0.8240715;0.8206945;62872.8;7137507
866.5341;0.2748748;-0.3873225;124.8222;12.89832;2;2;0;0.8657475;0.8620214;114554.9;1.300998e+007
870.5341;0.288107;-0.3896791;186.5886;19.28086;2;2;0;0.9074235;0.9033312;171240.7;1.945582e+007
874.5341;0.3014463;-0.3922286;250.442;25.87906;2;2;0;0.949437;0.9449582;229841.8;2.612477e+007
878.5341;0.3147319;-0.3953432;321.0527;33.17551;2;2;0;0.9912816;0.9864007;294644.4;3.350437e+007
882.5341;0.3281248;-0.398452;395.9269;40.91253;2;2;0;1.033464;1.02816;363359.8;4.133535e+007
886.5341;0.3414105;-0.4017913;470.9944;48.66952;2;2;0;1.075309;1.069568;432252.6;4.919287e+007
890.5341;0.3548033;-0.4060437;553.5222;57.19741;2;2;0;1.117491;1.111293;507992;5.783659e+007
894.5341;0.3681962;-0.4117675;643.459;66.4909;2;2;0;1.159673;1.153;590531;6.726197e+007
898.5341;0.3814819;-0.4178217;736.4776;76.10284;2;2;0;1.201518;1.194357;675898.3;7.701723e+007
902.5341;0.3949283;-0.4241527;833.8763;86.16739;2;2;0;1.243869;1.236196;765285.5;8.72392e+007
906.5341;0.4082676;-0.4311832;932.6938;96.37856;2;2;0;1.285882;1.277685;855974.7;9.761787e+007
910.5341;0.4214997;-0.4397792;1032.975;106.741;2;2;0;1.327558;1.318823;948007.4;1.08158e+008
914.5341;0.4349461;-0.4500589;1135.828;117.3691;2;2;0;1.369909;1.360611;1042400;1.18977e+008
918.5341;0.4481783;-0.4613131;1236.586;127.7808;2;2;0;1.411585;1.401715;1134870;1.295845e+008
922.5341;0.461464;-0.4733193;1335.682;138.0207;2;2;0;1.45343;1.442969;1225815;1.400267e+008
926.5341;0.4748033;-0.4860114;1433.937;148.1738;2;2;0;1.495443;1.484372;1315988;1.503896e+008
930.5341;0.488089;-0.4990287;1530.744;158.1772;2;2;0;1.537288;1.525592;1404832;1.606089e+008
934.5341;0.5014818;-0.5125367;1627.094;168.1334;2;2;0;1.57947;1.567126;1493257;1.70789e+008
938.5341;0.5147675;-0.5260596;1720.309;177.7657;2;2;0;1.621315;1.608312;1578805;1.806478e+008
942.5341;0.5281604;-0.5399938;1813.006;187.3443;2;2;0;1.663497;1.649813;1663877;1.904608e+008
946.5341;0.5415532;-0.5538921;1903.586;196.7043;2;2;0;1.705679;1.691296;1747006;2.000594e+008
950.5341;0.5548389;-0.568033;1993.103;205.9544;2;2;0;1.747524;1.732431;1829160;2.095535e+008
954.5341;0.5682854;-0.5825303;2082.829;215.2261;2;2;0;1.789875;1.774045;1911505;2.190784e+008
958.5341;0.5816246;-0.5970555;2172.248;224.466;2;2;0;1.831889;1.815312;1993568;2.28578e+008
962.5341;0.5948032;-0.6114952;2260.574;233.5932;2;2;0;1.873396;1.856064;2074630;2.379693e+008
966.5341;0.6082496;-0.6263584;2350.781;242.9146;2;2;0;1.915747;1.897628;2157417;2.475682e+008
970.5341;0.6214817;-0.6412373;2439.97;252.1307;2;2;0;1.957423;1.938512;2239269;2.57066e+008
974.5341;0.6347674;-0.6569268;2530.653;261.5014;2;2;0;1.999267;1.979545;2322493;2.667295e+008
978.5341;0.6481067;-0.673099;2622.206;270.9618;2;2;0;2.041281;2.020726;2406515;2.764929e+008
982.5341;0.661446;-0.6898009;2714.444;280.4931;2;2;0;2.083295;2.061891;2491166;2.863366e+008
986.5341;0.6748388;-0.706635;2809.801;290.3466;2;2;0;2.125477;2.103203;2578679;2.965179e+008
990.5341;0.688071;-0.7233495;2903.477;300.0266;2;2;0;2.167153;2.144004;2664651;3.065286e+008
994.5341;0.7015173;-0.7402815;2999.091;309.9066;2;2;0;2.209503;2.185448;2752399;3.16754e+008
998.5341;0.7149103;-0.7575484;3095.368;319.8553;2;2;0;2.251686;2.22671;2840758;3.270575e+008
1002.534;0.7281424;-0.7748082;3192.499;329.8922;2;2;0;2.293362;2.26746;2929899;3.374579e+008
1006.534;0.7416424;-0.7924221;3291.908;340.1646;2;2;0;2.335881;2.309017;3021131;3.481104e+008
1010.534;0.754928;-0.8095099;3389.34;350.2325;2;2;0;2.377726;2.349898;3110548;3.585601e+008
1014.534;0.7681602;-0.8268497;3488.065;360.4341;2;2;0;2.419402;2.390598;3201153;3.691544e+008
1018.534;0.7814995;-0.8445194;3590.843;371.0545;2;2;0;2.461416;2.431611;3295477;3.801877e+008
1022.534;0.7947852;-0.8621897;3692.366;381.5452;2;2;0;2.50326;2.472442;3388649;3.910963e+008
1026.534;0.8081245;-0.880114;3796.436;392.2991;2;2;0;2.545274;2.513421;3484158;4.022842e+008
1030.534;0.8214102;-0.8978437;3900.864;403.0901;2;2;0;2.587119;2.554219;3579997;4.135185e+008
1034.534;0.834803;-0.9153984;4003.535;413.6995;2;2;0;2.629301;2.595329;3674223;4.245769e+008
1038.534;0.8481959;-0.9331511;4107.354;424.4275;2;2;0;2.671483;2.636422;3769502;4.35766e+008
1042.534;0.861428;-0.9507576;4209.728;435.0061;2;2;0;2.713159;2.677005;3863456;4.468085e+008
1046.534;0.8748745;-0.9691427;4313.965;445.7773;2;2;0;2.75551;2.718229;3959118;4.580607e+008
1050.534;0.8882672;-0.9873451;4415.514;456.2707;2;2;0;2.797692;2.759272;4052314;4.690358e+008
1054.534;0.9014994;-1.006482;4511.757;466.2159;2;2;0;2.839368;2.799805;4140641;4.794534e+008
1058.534;0.9149458;-1.027073;4601.432;475.4822;2;2;0;2.881719;2.840979;4222940;4.891843e+008
1062.534;0.9282315;-1.048622;4680.953;483.6995;2;2;0;2.923564;2.881643;4295920;4.978407e+008
1066.534;0.9414637;-1.071176;4752.598;491.1028;2;2;0;2.96524;2.922127;4361671;5.056652e+008
1070.534;0.9548565;-1.094692;4821.118;498.1832;2;2;0;3.007422;2.963086;4424555;5.131656e+008
1074.534;0.9680886;-1.11875;4882.759;504.5527;2;2;0;3.049098;3.003537;4481126;5.19937e+008
1078.534;0.9814815;-1.14369;4943.309;510.8096;2;2;0;3.09128;3.044463;4536695;5.266002e+008
1082.534;0.9947136;-1.168562;5000.434;516.7125;2;2;0;3.132956;3.084881;4589121;5.329009e+008
1086.534;1.008107;-1.193618;5055.456;522.3982;2;2;0;3.175139;3.125773;4639618;5.38985e+008
1090.534;1.021499;-1.218589;5108.436;527.8727;2;2;0;3.21732;3.166649;4688239;5.448561e+008
1094.534;1.034785;-1.243623;5159.542;533.1537;2;2;0;3.259166;3.207181;4735142;5.505301e+008
1098.534;1.048231;-1.269211;5210.655;538.4355;2;2;0;3.301517;3.248187;4782051;5.56212e+008
1102.534;1.061571;-1.294467;5259.256;543.4575;2;2;0;3.34353;3.288849;4826654;5.616282e+008
1106.534;1.074803;-1.319617;5308.495;548.5456;2;2;0;3.385206;3.329169;4871843;5.67115e+008
1110.534;1.088249;-1.344886;5358.574;553.7204;2;2;0;3.427557;3.370125;4917803;5.726995e+008
1114.534;1.101535;-1.369903;5406.649;558.6882;2;2;0;3.469401;3.410574;4961924;5.780714e+008
1118.534;1.114767;-1.394947;5452.415;563.4174;2;2;0;3.511078;3.450845;5003925;5.831994e+008
1122.534;1.12816;-1.420663;5501.934;568.5344;2;2;0;3.55326;3.491588;5049371;5.887359e+008
1126.534;1.141446;-1.445792;5548.45;573.3409;2;2;0;3.595105;3.531989;5092060;5.939532e+008
1130.534;1.154838;-1.470763;5595.134;578.165;2;2;0;3.637286;3.572699;5134905;5.991946e+008
1134.534;1.168071;-1.495762;5641.688;582.9756;2;2;0;3.678963;3.612904;5177629;6.044231e+008
1138.534;1.181517;-1.521275;5689.399;587.9058;2;2;0;3.721314;3.653744;5221415;6.097835e+008
1142.534;1.194856;-1.546103;5734.515;592.5677;2;2;0;3.763327;3.694242;5262820;6.14868e+008
1146.534;1.208142;-1.571028;5782.235;597.4988;2;2;0;3.805172;3.734561;5306615;6.202346e+008
1150.534;1.221588;-1.596801;5829.688;602.4023;2;2;0;3.847523;3.775351;5350165;6.255798e+008
1154.534;1.234928;-1.621861;5876.157;607.2041;2;2;0;3.889536;3.8158;5392812;6.308215e+008
1158.534;1.24816;-1.647112;5922.497;611.9926;2;2;0;3.931212;3.855907;5435340;6.360513e+008
1162.534;1.261606;-1.673005;5969.534;616.853;2;2;0;3.973563;3.896648;5478508;6.413641e+008
1166.534;1.274838;-1.699015;6012.681;621.3116;2;2;0;4.015239;3.936723;5518105;6.462587e+008
1170.534;1.288124;-1.72435;6057.006;625.8918;2;2;0;4.057084;3.976944;5558785;6.512848e+008
1174.534;1.301463;-1.749781;6103.726;630.7195;2;2;0;4.099098;4.017312;5601661;6.565734e+008
1178.534;1.314749;-1.774695;6145.881;635.0756;2;2;0;4.140942;4.057501;5640349;6.613737e+008
1182.534;1.328142;-1.799829;6191.394;639.7787;2;2;0;4.183124;4.097997;5682119;6.665414e+008
1186.534;1.341428;-1.824776;6235.406;644.3266;2;2;0;4.224969;4.138155;5722511;6.715492e+008
1190.534;1.354874;-1.850163;6281.284;649.0673;2;2;0;4.26732;4.17878;5764614;6.767651e+008
1194.534;1.368213;-1.875376;6325.537;653.6401;2;2;0;4.309334;4.219066;5805227;6.818076e+008
1198.534;1.381499;-1.900351;6369.414;658.1741;2;2;0;4.351178;4.259174;5845495;6.868124e+008
1202.534;1.394946;-1.926001;6414.536;662.8367;2;2;0;4.393529;4.299751;5886906;6.919587e+008
1206.534;1.408285;-1.950962;6458.453;667.3748;2;2;0;4.435543;4.339988;5927210;6.969765e+008
1210.534;1.421517;-1.976465;6500.942;671.7653;2;2;0;4.477219;4.379886;5966205;7.018417e+008
1213.014;1.429767;-1.99237;6528.613;674.6246;2;2;0;4.503203;4.404753;5991599;7.050044e+008
1217.014;1.416374;-1.985046;6274.64;648.3807;2;2;0;4.461021;4.364381;5758517;6.773051e+008
1221.014;1.403035;-1.974878;6057.017;625.893;2;2;0;4.419007;4.324153;5558795;6.535512e+008
1225.014;1.389803;-1.96437;5856.193;605.1412;2;2;0;4.377331;4.284233;5374490;6.316302e+008
1229.014;1.376303;-1.953306;5662.588;585.1352;2;2;0;4.334812;4.243488;5196809;6.104997e+008
1233.014;1.36307;-1.942387;5479.948;566.2625;2;2;0;4.293135;4.203536;5029193;5.905729e+008
1237.014;1.349838;-1.93034;5306.462;548.3354;2;2;0;4.25146;4.163568;4869977;5.716477e+008
1241.014;1.336446;-1.917771;5137.411;530.8668;2;2;0;4.209277;4.123097;4714831;5.532125e+008
1245.014;1.32316;-1.905048;4973.734;513.9535;2;2;0;4.167432;4.082935;4564617;5.353722e+008
1249.014;1.309821;-1.892167;4815.457;497.5982;2;2;0;4.125419;4.042594;4419359;5.181262e+008
1253.014;1.296481;-1.879124;4660.352;481.5707;2;2;0;4.083406;4.002237;4277013;5.012352e+008
1257.014;1.283142;-1.865655;4508.519;465.8812;2;2;0;4.041392;3.961864;4137669;4.847093e+008
1261.014;1.269749;-1.852001;4359.567;450.4895;2;2;0;3.99921;3.921311;4000969;4.685055e+008
1265.014;1.256463;-1.838142;4214.57;435.5065;2;2;0;3.957365;3.881068;3867899;4.52741e+008
1269.014;1.243017;-1.824029;4071.793;420.7527;2;2;0;3.915014;3.840321;3736866;4.372253e+008
1273.014;1.229678;-1.809952;3934.353;406.5506;2;2;0;3.873001;3.799882;3610731;4.222963e+008
1277.014;1.216446;-1.795997;3802.287;392.9038;2;2;0;3.831325;3.759752;3489529;4.079572e+008
1281.014;1.202999;-1.781987;3673.396;379.585;2;2;0;3.788974;3.718956;3371239;3.939674e+008
1285.014;1.189714;-1.767957;3549.675;366.8005;2;2;0;3.747129;3.67863;3257696;3.80545e+008
1289.014;1.176535;-1.753712;3429.966;354.4306;2;2;0;3.705622;3.638614;3147833;3.675644e+008
1293.014;1.163142;-1.739389;3312.051;342.246;2;2;0;3.66344;3.597931;3039617;3.547839e+008
1297.014;1.149856;-1.725014;3199.268;330.5917;2;2;0;3.621595;3.557557;2936111;3.425644e+008
1301.014;1.136517;-1.710252;3087.94;319.0878;2;2;0;3.579582;3.517004;2833941;3.305098e+008
1305.014;1.123178;-1.695217;2979.118;307.8428;2;2;0;3.537568;3.476434;2734069;3.187329e+008
1309.014;1.109785;-1.67965;2871.494;296.7217;2;2;0;3.495386;3.435684;2635298;3.070932e+008
1313.014;1.096392;-1.664008;2766.669;285.8897;2;2;0;3.453204;3.394919;2539095;2.95762e+008
1317.014;1.08316;-1.648296;2665.27;275.4118;2;2;0;3.411527;3.354625;2446037;2.848076e+008
1321.014;1.06966;-1.632244;2565.62;265.1146;2;2;0;3.369008;3.3135;2354584;2.740463e+008
1325.014;1.056321;-1.61619;2468.713;255.1009;2;2;0;3.326994;3.272848;2265649;2.635881e+008
1329.014;1.043142;-1.600191;2374.809;245.3974;2;2;0;3.285487;3.232669;2179468;2.534599e+008
1333.014;1.029696;-1.583403;2280.989;235.7027;2;2;0;3.243136;3.191657;2093366;2.433469e+008
1337.014;1.01641;-1.56689;2191.336;226.4385;2;2;0;3.201292;3.151118;2011087;2.336874e+008
1341.014;1.003178;-1.550042;2103.262;217.3375;2;2;0;3.159615;3.110726;1930257;2.242045e+008
1345.014;0.9897851;-1.532809;2014.737;208.1899;2;2;0;3.117433;3.069828;1849014;2.146801e+008
1349.014;0.9764994;-1.515535;1929.928;199.4263;2;2;0;3.075588;3.02924;1771181;2.055598e+008
1353.014;0.9631601;-1.498174;1845.288;190.6801;2;2;0;3.033575;2.988472;1693503;1.964646e+008
1357.014;0.9498208;-1.480866;1762.423;182.1174;2;2;0;2.991562;2.947687;1617454;1.875656e+008
1361.014;0.936428;-1.463242;1682.197;173.8273;2;2;0;2.949379;2.906722;1543827;1.789542e+008
1365.014;0.9230351;-1.445616;1603.431;165.6882;2;2;0;2.907197;2.86574;1471541;1.705051e+008
1369.014;0.909803;-1.428223;1526.639;157.753;2;2;0;2.865521;2.825233;1401065;1.622735e+008
1373.014;0.896303;-1.410286;1451.767;150.0162;2;2;0;2.823002;2.783889;1332351;1.542511e+008
1377.014;0.8830173;-1.39278;1379.259;142.5237;2;2;0;2.781157;2.743185;1265807;1.464875e+008
1381.014;0.8697851;-1.375353;1310.042;135.3712;2;2;0;2.739481;2.702629;1202284;1.390797e+008
1385.014;0.8563923;-1.357666;1241.439;128.2822;2;2;0;2.697299;2.661563;1139324;1.317424e+008
1389.014;0.8431066;-1.340294;1175.887;121.5085;2;2;0;2.655454;2.620809;1079164;1.247351e+008
1393.014;0.8298745;-1.322877;1112.165;114.9239;2;2;0;2.613778;2.580203;1020683;1.179278e+008
1397.014;0.8164816;-1.305014;1048.356;108.3303;2;2;0;2.571596;2.539086;962122.9;1.111161e+008
1401.014;0.8031423;-1.286929;986.5634;101.9451;2;2;0;2.529582;2.498118;905413.3;1.045239e+008
1405.014;0.7898031;-1.268548;924.5538;95.53741;2;2;0;2.487569;2.457133;848504.2;9.791397e+007
1409.014;0.7765173;-1.250056;863.9105;89.27093;2;2;0;2.445724;2.416295;792849.2;9.145425e+007
1413.014;0.7630709;-1.231624;805.0521;83.18889;2;2;0;2.403373;2.374947;738832.3;8.518823e+007
1417.014;0.7497316;-1.213695;747.957;77.28904;2;2;0;2.361359;2.333911;686433.4;7.911411e+007
1421.014;0.7364459;-1.196018;693.2743;71.63849;2;2;0;2.319515;2.293023;636248.8;7.330015e+007
1425.014;0.7229995;-1.177959;638.8839;66.01814;2;2;0;2.277164;2.251624;586332.3;6.752148e+007
1429.014;0.7096603;-1.160359;586.4269;60.59757;2;2;0;2.235151;2.210537;538190.2;6.195202e+007
1433.014;0.6964817;-1.143263;536.4387;55.43211;2;2;0;2.193643;2.169929;492313.7;5.664809e+007
1437.014;0.6830888;-1.126241;486.7011;50.29255;2;2;0;2.151461;2.128644;446667.3;5.137457e+007
1441.014;0.6698031;-1.109445;440.0317;45.47003;2;2;0;2.109616;2.087672;403836.7;4.642928e+007
1445.014;0.6565174;-1.093603;394.6867;40.78437;2;2;0;2.067771;2.046683;362221.6;4.16277e+007
1449.014;0.6431781;-1.078236;350.4748;36.2158;2;2;0;2.025758;2.005513;321646.3;3.694944e+007
1453.014;0.6298389;-1.063449;308.5549;31.88407;2;2;0;1.983745;1.964325;283174.6;3.251657e+007
1457.014;0.616446;-1.049536;269.5739;27.85603;2;2;0;1.941562;1.922954;247400;2.839687e+007
1461.014;0.6031603;-1.037279;231.8901;23.96202;2;2;0;1.899717;1.881898;212815.8;2.441723e+007
1465.014;0.5897139;-1.02673;197.2406;20.38157;2;2;0;1.857367;1.840328;181016.5;2.076013e+007
1469.014;0.5763747;-1.017998;164.0236;16.94914;2;2;0;1.815353;1.799072;150531.8;1.725683e+007
1473.014;0.5630889;-1.009795;133.1559;13.75947;2;2;0;1.773508;1.757965;122203.1;1.40035e+007
1477.014;0.5496425;-1.002682;104.8016;10.82952;2;2;0;1.731157;1.716344;96181.14;1.1017e+007
1481.014;0.5363568;-0.9974667;80.21613;8.289017;2;2;0;1.689313;1.675203;73617.92;8429044
1485.014;0.5231247;-0.9932949;58.20408;6.014434;2;2;0;1.647637;1.63421;53416.48;6113530
1489.014;0.5097318;-0.990742;49.16385;5.080275;2;2;0;1.605455;1.592703;45119.86;5161836
1493.014;0.4964997;-0.9898683;49.1127;5.074989;2;2;0;1.563779;1.551677;45072.91;5154350
1497.014;0.4831604;-0.9893478;48.96939;5.060181;2;2;0;1.521765;1.510302;44941.39;5137185
1500.4;0.4718568;-0.9891737;49.25717;5.089918;2;2;0;1.486163;1.475228;45205.5;5165562
1503.402;0.481714;-0.9889875;49.38838;5.103476;3;3;0;1.517209;1.505815;45325.92;5180906
1507.402;0.4950532;-0.9887317;49.84427;5.150585;3;3;0;1.559223;1.547192;45744.31;5230894
1511.402;0.5083925;-0.9887262;51.68368;5.340658;3;3;0;1.601236;1.588552;47432.42;5426174
1515.402;0.5217854;-0.9893505;87.02951;8.993068;3;3;0;1.643418;1.630061;79870.86;9140861
1519.402;0.5350711;-0.9904729;143.9417;14.87401;3;3;0;1.685263;1.67122;132101.7;1.512467e+007
1523.402;0.5485175;-0.9916019;206.2806;21.3157;3;3;0;1.727614;1.712861;189312.9;2.168396e+007
1527.402;0.5618568;-0.9929721;272.4075;28.14883;3;3;0;1.769628;1.754152;250000.5;2.864696e+007
1531.402;0.5751425;-0.9946718;346.7623;35.83218;3;3;0;1.811473;1.795261;318239.2;3.648127e+007
1535.402;0.5885889;-0.9966442;425.9776;44.01777;3;3;0;1.853823;1.836849;390938.6;4.483378e+007
1539.402;0.6019281;-0.999102;506.6396;52.35286;3;3;0;1.895837;1.87809;464965.7;5.334538e+007
1543.402;0.6151067;-1.002075;589.7402;60.93994;3;3;0;1.937344;1.918816;541230.9;6.212056e+007
1547.402;0.6284996;-1.006514;679.5986;70.22533;3;3;0;1.979526;1.960189;623697.9;7.161545e+007
1551.402;0.6417853;-1.012149;772.6571;79.84139;3;3;0;2.021371;2.001213;709101.9;8.145528e+007
1555.402;0.655071;-1.018555;867.9124;89.68446;3;3;0;2.063216;2.04222;796521.9;9.153484e+007
1559.402;0.6823924;-1.033897;1067.867;110.3464;3;3;0;2.149267;2.126496;980028.8;1.127181e+008
1563.402;0.715821;-1.058029;1318.842;136.2806;3;3;0;2.254554;2.229515;1210360;1.393531e+008
1567.402;0.7490352;-1.087699;1571.408;162.3792;3;3;0;2.359166;2.331768;1442151;1.6621e+008
1571.402;0.7825709;-1.120609;1821.018;188.1722;3;3;0;2.46479;2.434904;1671229;1.928102e+008
1575.402;0.8157852;-1.155762;2065.231;213.4076;3;3;0;2.569402;2.536948;1895354;2.188909e+008
1579.402;0.8491066;-1.191896;2304.144;238.0954;3;3;0;2.674351;2.639216;2114616;2.444629e+008
1583.402;0.8823209;-1.229403;2541.463;262.6184;3;3;0;2.778963;2.741051;2332414;2.699165e+008
1587.402;0.9158565;-1.2697;2782.93;287.5701;3;3;0;2.884588;2.843766;2554019;2.958653e+008
1591.402;0.9492852;-1.311654;3024.114;312.4925;3;3;0;2.989875;2.946049;2775365;3.218356e+008
1595.402;0.9823922;-1.355109;3264.301;337.3118;3;3;0;3.094149;3.047245;2995795;3.477487e+008
1599.402;1.01566;-1.399299;3503.486;362.0276;3;3;0;3.198929;3.148829;3215306;3.736087e+008
1603.402;1.049089;-1.446218;3744.559;386.9385;3;3;0;3.304216;3.2508;3436549;3.997238e+008
1607.402;1.082571;-1.493127;3985.793;411.8661;3;3;0;3.409672;3.352831;3657940;4.259093e+008
1611.402;1.115785;-1.539915;4227.279;436.8196;3;3;0;3.514283;3.453942;3879562;4.521707e+008
1615.402;1.149106;-1.586535;4472.548;462.1642;3;3;0;3.619233;3.555277;4104657;4.78891e+008
1619.402;1.182428;-1.633402;4718.856;487.6161;3;3;0;3.724182;3.656509;4330705;5.057758e+008
1623.402;1.215856;-1.680273;4968.919;513.4559;3;3;0;3.829469;3.757965;4560199;5.331186e+008
1627.402;1.249071;-1.727313;5220.099;539.4113;3;3;0;3.934081;3.858667;4790718;5.606322e+008
1631.402;1.282553;-1.774495;5473.077;565.5525;3;3;0;4.039536;3.96008;5022887;5.883982e+008
1635.402;1.315821;-1.821228;5719.001;590.9646;3;3;0;4.144317;4.060741;5248582;6.15456e+008
1639.402;1.349088;-1.868507;5962.242;616.0996;3;3;0;4.249097;4.161302;5471816;6.422783e+008
1643.402;1.382303;-1.916444;6194.892;640.1401;3;3;0;4.353709;4.261599;5685329;6.680099e+008
1647.402;1.415838;-1.967346;6415.281;662.9136;3;3;0;4.459333;4.362766;5887589;6.924752e+008
1650.538;1.441928;-2.010171;6563.861;678.267;3;3;0;4.541504;4.441398;6023948;7.090705e+008
1651.986;1.429981;-2.003673;6338.334;654.9625;3;3;0;4.503878;4.405399;5816972;6.844612e+008
1654.216;1.411392;-1.989011;6037.91;623.9186;3;3;0;4.445329;4.349358;5541259;6.516538e+008
1656.656;1.391035;-1.972424;5737.648;592.8915;3;3;0;4.381212;4.287951;5265696;6.188673e+008
1659.3;1.368963;-1.953144;5437.094;561.8342;3;3;0;4.311696;4.221331;4989864;5.860588e+008
1662.12;1.345285;-1.931055;5136.631;530.7863;3;3;0;4.237118;4.149809;4714116;5.532763e+008
1665.112;1.320481;-1.90678;4836.449;499.7674;3;3;0;4.158996;4.074835;4438625;5.205527e+008
1668.254;1.294178;-1.880689;4536.096;468.7308;3;3;0;4.07615;3.995266;4162977;4.87837e+008
1671.562;1.266803;-1.852396;4235.716;437.6915;3;3;0;3.98993;3.912388;3887305;4.551551e+008
1675.046;1.237821;-1.82128;3935.45;406.6639;3;3;0;3.898647;3.824569;3611738;4.225183e+008
1678.788;1.206588;-1.787727;3635.269;375.6452;3;3;0;3.800279;3.729847;3336249;3.899208e+008
1682.736;1.173749;-1.751987;3341.387;345.2773;3;3;0;3.696848;3.630153;3066540;3.580417e+008
1686.736;1.140267;-1.714643;3062.027;316.4101;3;3;0;3.591393;3.528406;2810159;3.277736e+008
1690.736;1.106839;-1.676278;2798.718;289.2014;3;3;0;3.486106;3.426717;2568508;2.992833e+008
1694.736;1.073678;-1.637112;2552.449;263.7536;3;3;0;3.381663;3.325742;2342496;2.726728e+008
1698.736;1.040357;-1.597109;2320.022;239.7361;3;3;0;3.276713;3.224174;2129188;2.475915e+008
1702.736;1.007035;-1.555205;2098.834;216.88;3;3;0;3.171764;3.122502;1926194;2.237589e+008
1706.736;0.9736065;-1.512306;1885.63;194.8488;3;3;0;3.066477;3.0204;1730527;2.008238e+008
1710.736;0.9403387;-1.468637;1683.552;173.9674;3;3;0;2.961697;2.918685;1545071;1.791198e+008
1714.736;0.9069101;-1.424179;1491.504;154.1224;3;3;0;2.85641;2.816375;1368820;1.585248e+008
1718.736;0.8736958;-1.380147;1313.567;135.7356;3;3;0;2.751798;2.714616;1205520;1.394707e+008
1722.736;0.8403209;-1.336522;1146.575;118.4797;3;3;0;2.64668;2.612261;1052263;1.216154e+008
1726.736;0.807053;-1.293267;986.8086;101.9704;3;3;0;2.541899;2.51013;905638.3;1.045624e+008
1730.736;0.7735173;-1.248682;829.2898;85.69345;3;3;0;2.436275;2.407071;761076.3;8.778118e+007
1734.736;0.740196;-1.206102;682.0269;70.47625;3;3;0;2.331326;2.304566;625926.4;7.211928e+007
1738.736;0.7070352;-1.165342;543.7689;56.18956;3;3;0;2.226882;2.20245;499040.9;5.744084e+007
1742.736;0.6737139;-1.129102;414.2682;42.8078;3;3;0;2.121933;2.099734;380192.4;4.371616e+007
1746.736;0.6402853;-1.098033;294.1276;30.39325;3;3;0;2.016647;1.996582;269934;3.100617e+007
1750.736;0.6068568;-1.075778;190.9411;19.73062;3;3;0;1.91136;1.893323;175235.1;2.010774e+007
1754.736;0.5736961;-1.061604;102.6387;10.60602;3;3;0;1.806917;1.790786;94196.16;1.079767e+007
1757.802;0.5480889;-1.055014;51.4687;5.318442;3;3;0;1.726264;1.711534;47235.12;5410253