File: Ensayos/Resistencia/comp/ClavoCu/ClavoCub.raw
"Test Type";"Manual"
"Method Name:";"C:\INSTRON\user\template\CYCLE.MTM"
"Name:";""
"Operator ID:";""
"Company:";""
"Lab name:";""
"Test date:";"24/05/2017"
"Temperature:";""
"Humidity:";""
"Note 1:";""
"Note 2:";""
"Note 3:";""
"Geometry:";"Rectangular"
"Specimen";1
"Specimen name:";""
"Width:";0.250000;"in"
"Thickness:";0.060000;"in"
"Length:";1.250000;"in"
"Diameter:";0.039370;"in"
"Inner diameter:";0.019685;"in"
"Outer diameter:";0.039370;"in"
"Wall thickness:";0.019685;"in"
"Area:";0.015000;"in*in"
"Linear density:";1.000000;"den"
"Sled weight:";2.204623;"lbf"
"Loading span:";0.000000;"mm"
"Support span:";1.000000;"mm"
"Span ratio:";"2"
"Fixture type:";"3-point"
"Comment:";""
"Included"
"Final Width:";0.250000;"in"
"Final Thickness:";0.060000;"in"
"Final Length:";1.250000;"in"
"Final Diameter:";0.039370;"in"
"Final Inner diameter:";0.019685;"in"
"Final Outer diameter:";0.039370;"in"
"Final Wall thickness:";0.019685;"in"
"Final Area:";0.015000;"in*in"
"Final Linear density:";1.000000;"den"
"Time sec";"Extension mm";"Strain 1 %";"Load N";"Stress MPa";"Cycle Count ";"Total Cycle Count ";"Repetitions Count ";"Strain [Exten.] %";"True strain %";"Tenacity gf/tex";"True stress Pa"
0;0;0.0001997294;36.63322;3.78544;0;0;0;0;0;33619.94;3785440
6;0.01007142;4.163128e-005;45.2982;4.680823;0;0;0;0.03172101;0.03171599;41572.18;4682308
12;0.02008927;-3.565568e-005;45.82946;4.73572;0;0;0;0.0632733;0.06325329;42059.74;4738717
18;0.03010712;-0.000187098;45.74789;4.727291;0;0;0;0.09482559;0.09478066;41984.88;4731774
24;0.04483926;-0.0002631321;46.00456;4.753814;0;0;0;0.141226;0.1411264;42220.44;4760528
30;0.07489281;-0.0003558456;45.89119;4.742099;0;0;0;0.2358829;0.2356051;42116.39;4753284
36;0.1049464;-0.0005780754;45.76662;4.729227;0;0;0;0.3305397;0.3299947;42002.07;4744859
42;0.1348928;-0.0006309315;46.19455;4.773446;0;0;0;0.4248591;0.4239591;42394.8;4793727
48;0.164732;-0.0007896559;46.20665;4.774696;0;0;0;0.518841;0.5174997;42405.9;4799469
54;0.1947856;-0.0009270813;46.18668;4.772633;0;0;0;0.6134979;0.6116237;42387.57;4801913
60;0.2248392;-0.0009745342;46.02611;4.756041;0;0;0;0.7081548;0.7056592;42240.21;4789721
66;0.2548927;-0.00102739;45.88185;4.741134;0;0;0;0.8028116;0.7996062;42107.82;4779196
72;0.2849462;-0.001038745;46.00068;4.753414;0;0;0;0.8974684;0.8934651;42216.88;4796074
78;0.3147855;-0.001206787;46.06033;4.759576;0;0;0;0.9914504;0.9865678;42271.61;4806765
84.00001;0.3447319;-0.001201854;46.13594;4.76739;0;0;0;1.08577;1.079918;42341.01;4819153
90.00001;0.3747319;-0.001254162;46.41094;4.795806;0;0;0;1.180258;1.173347;42593.39;4852409
96.00001;0.4047855;-0.001417976;48.33492;4.994618;0;0;0;1.274915;1.266856;44359.11;5058296
102;0.4331247;-0.00133372;54.57222;5.639141;0;0;0;1.364172;1.354951;50083.36;5716069
108;0.4430354;-0.001336382;56.82145;5.871562;0;0;0;1.395387;1.385741;52147.58;5953493
114;0.4530533;-0.001355254;57.74667;5.967167;0;0;0;1.426939;1.416855;52996.69;6052315
120;0.4713747;-0.001416019;57.98922;5.992231;0;0;0;1.484645;1.473732;53219.29;6081195
126;0.4913032;-0.001362928;57.76881;5.969456;0;0;0;1.547412;1.535561;53017.01;6061828
132;0.5112854;-0.001525567;58.00511;5.993873;0;0;0;1.610348;1.597519;53233.87;6090395
138;0.5339461;-0.001634333;57.86935;5.979845;0;0;0;1.68172;1.667736;53109.29;6080410
144;0.5639461;-0.001657903;57.99212;5.992532;0;0;0;1.776208;1.760618;53221.96;6098971
150;0.5938389;-0.001827199;58.20205;6.014224;0;0;0;1.870359;1.853083;53414.62;6126712
156;0.6237318;-0.00182438;58.47858;6.042799;0;0;0;1.964509;1.945462;53668.4;6161510
162;0.6537853;-0.002073547;58.53484;6.048612;0;0;0;2.059166;2.038252;53720.03;6173163
168;0.6838924;-0.0019759;58.51637;6.046704;0;0;0;2.153992;2.131121;53703.08;6176949
174;0.713946;-0.002138383;58.83856;6.079997;0;0;0;2.248649;2.223739;53998.77;6216714
180;0.7439459;-0.002209876;59.19428;6.116755;0;0;0;2.343137;2.316107;54325.23;6260078
186;0.7713209;-0.002728804;74.12783;7.659892;0;0;0;2.429357;2.400318;68030.42;7845978
192;0.7812852;-0.002902876;83.52827;8.631272;0;0;0;2.460741;2.430952;76657.62;8843665
198;0.7912495;-0.003180155;92.71588;9.58066;0;0;0;2.492124;2.461577;85089.49;9819422
204;0.8012138;-0.003442398;102.2956;10.57057;0;0;0;2.523508;2.492193;93881.25;1.083732e+007
210;0.8112317;-0.003758908;112.5883;11.63414;0;0;0;2.55506;2.522964;103327.3;1.19314e+007
216;0.8212495;-0.004212999;123.1711;12.72771;0;0;0;2.586612;2.553726;113039.6;1.305692e+007
222;0.8312138;-0.004520034;134.3364;13.88146;0;0;0;2.617996;2.584313;123286.5;1.424487e+007
228;0.8465352;-0.004838422;154.2525;15.93946;0;0;0;2.666253;2.631327;141564.4;1.636444e+007
234;0.8665173;-0.003684674;180.4902;18.65069;0;0;0;2.729188;2.69261;165643.9;1.91597e+007
240;0.8864459;-0.004972559;207.2611;21.41702;0;0;0;2.791955;2.753691;190212.7;2.201497e+007
246;0.9063745;-0.006180102;235.4515;24.33004;0;0;0;2.854723;2.814735;216084.4;2.502459e+007
252;0.926303;-0.007309732;267.8682;27.67977;0;0;0;2.91749;2.875741;245834.6;2.848733e+007
258;0.9462851;-0.00845189;302.6643;31.27537;0;0;0;2.980426;2.936874;277768.5;3.220751e+007
264;0.9663208;-0.01000867;339.5967;35.09174;0;0;0;3.04353;2.998134;311663.1;3.615976e+007
270;0.9863565;-0.01158417;379.3967;39.2044;0;0;0;3.106635;3.059356;348189.3;4.042234e+007
276;1.006392;-0.01286235;422.751;43.68436;0;0;0;3.169739;3.12054;387977.4;4.506904e+007
282;1.026428;-0.01477613;469.5584;48.52113;0;0;0;3.232844;3.181687;430934.6;5.008974e+007
288;1.046356;-0.0167549;518.8421;53.61379;0;0;0;3.295611;3.24247;476164.5;5.538069e+007
294;1.066339;-0.01910742;571.2987;59.03431;0;0;0;3.358547;3.30338;524306.3;6.101701e+007
300;1.086374;-0.02146237;626.4959;64.73804;0;0;0;3.421651;3.364415;574963.3;6.695315e+007
306;1.10641;-0.0240404;683.8168;70.66122;0;0;0;3.484756;3.425413;627569.2;7.312359e+007
312;1.126446;-0.02611064;741.8082;76.65367;0;0;0;3.547861;3.486374;680790.5;7.937323e+007
318;1.146481;-0.0289647;801.4803;82.8198;0;0;0;3.610965;3.547298;735554.3;8.581039e+007
324;1.166463;-0.03196911;861.0878;88.97925;0;0;0;3.673901;3.608022;790258.6;9.224826e+007
330;1.186499;-0.03380592;922.1175;95.28567;0;0;0;3.737006;3.668872;846268.4;9.88465e+007
336;1.206481;-0.03732072;985.7096;101.8569;0;0;0;3.799941;3.729522;904629.6;1.057274e+008
342;1.22641;-0.04162868;1053.363;108.8477;0;0;0;3.862709;3.789973;966717.8;1.130522e+008
348;1.246285;-0.04631297;1124.111;116.1584;0;0;0;3.925307;3.850225;1031647;1.20718e+008
354;1.266321;-0.05111785;1195.92;123.5786;0;0;0;3.988411;3.910928;1097549;1.285074e+008
360;1.286356;-0.0560127;1268.545;131.0832;0;0;0;4.051516;3.971594;1164200;1.363941e+008
366;1.306445;-0.06065072;1339.65;138.4308;0;0;0;4.114789;4.032384;1229457;1.44127e+008
372;1.326481;-0.06573334;1410.988;145.8024;0;0;0;4.177894;4.092977;1294927;1.518939e+008
378;1.346517;-0.07042257;1480.215;152.9559;0;0;0;4.240998;4.153532;1358460;1.594428e+008
384;1.366499;-0.07398435;1527.577;157.85;0;0;0;4.303934;4.213889;1401926;1.646437e+008
390;1.386428;-0.07894091;1599.257;165.2569;0;0;0;4.366701;4.274048;1467710;1.724732e+008
396;1.406356;-0.08394493;1668.864;172.4496;0;0;0;4.429468;4.334171;1531591;1.800882e+008
402;1.426285;-0.08893648;1739.948;179.7949;0;0;0;4.492235;4.394258;1596828;1.878717e+008
408;1.446321;-0.09398043;1812.991;187.3428;0;0;0;4.55534;4.454632;1663863;1.958769e+008
414;1.466303;-0.09929813;1887.816;195.0747;0;0;0;4.618276;4.514807;1732533;2.040838e+008
420;1.486338;-0.104667;1963.551;202.9007;0;0;0;4.68138;4.575108;1802038;2.123992e+008
426;1.506428;-0.1100508;2040.852;210.8885;0;0;0;4.744654;4.635534;1872981;2.208944e+008
432;1.52641;-0.1155953;2119.679;219.034;0;0;0;4.80759;4.6956;1945324;2.295642e+008
438;1.546338;-0.1209831;2200.753;227.4116;0;0;0;4.870357;4.755471;2019729;2.384873e+008
444;1.56632;-0.12591;2287.966;236.4236;0;0;0;4.933293;4.815465;2099768;2.480871e+008
450;1.586356;-0.1301288;2382.837;246.227;0;0;0;4.996397;4.875585;2186836;2.585295e+008
456;1.606392;-0.1339395;2484.308;256.7123;0;0;0;5.059502;4.935669;2279960;2.697007e+008
462;1.626427;-0.1372801;2591.61;267.8002;0;0;0;5.122606;4.995716;2378436;2.815186e+008
468;1.646463;-0.140684;2707.776;279.8041;0;0;0;5.185711;5.055728;2485047;2.943139e+008
474;1.666499;-0.1441439;2828.402;292.2688;0;0;0;5.248816;5.115703;2595750;3.076094e+008
480;1.686481;-0.1477259;2952.578;305.1004;0;0;0;5.311751;5.175482;2709713;3.213065e+008
486;1.706463;-0.1512489;3079.365;318.2016;0;0;0;5.374687;5.235226;2826070;3.35304e+008
492;1.726392;-0.1549602;3208.006;331.4947;0;0;0;5.437454;5.294774;2944131;3.495195e+008
498;1.74632;-0.1587418;3340.145;345.149;0;0;0;5.500222;5.354287;3065400;3.641329e+008
504;1.766356;-0.1627806;3477.271;359.3188;0;0;0;5.563326;5.414083;3191247;3.793088e+008
509.568;1.785106;-0.1664191;3613.782;373.4248;0;0;0;5.622381;5.47001;3316529;3.944202e+008
514.57;1.768338;-0.1581168;3334.614;344.5774;0;0;0;5.569569;5.419997;3060324;3.637689e+008
520.57;1.748356;-0.1493084;3050.348;315.2033;0;0;0;5.506633;5.360364;2799441;3.325604e+008
526.57;1.728374;-0.140937;2784.333;287.7149;0;0;0;5.443697;5.300695;2555306;3.033773e+008
532.57;1.708338;-0.133227;2534.856;261.9357;0;0;0;5.380593;5.24083;2326351;2.760294e+008
538.57;1.688302;-0.1255542;2302.933;237.9702;0;0;0;5.317488;5.18093;2113505;2.506243e+008
544.57;1.66832;-0.1179073;2093.407;216.3191;0;0;0;5.254552;5.121154;1921213;2.276857e+008
550.57;1.648338;-0.110628;1902.191;196.5601;0;0;0;5.191617;5.061342;1745726;2.067648e+008
556.57;1.628356;-0.1037134;1724.456;178.1941;0;0;0;5.128681;5.001494;1582610;1.873331e+008
562.57;1.608374;-0.09724943;1560.083;161.2089;0;0;0;5.065745;4.941611;1431758;1.693753e+008
568.57;1.588338;-0.0899088;1408.166;145.5108;0;0;0;5.00264;4.88153;1292337;1.527902e+008
574.57;1.568303;-0.08158935;1266.039;130.8243;0;0;0;4.939536;4.821415;1161901;1.372864e+008
580.57;1.548267;-0.07351335;1129.905;116.7571;0;0;0;4.876431;4.761262;1036964;1.224507e+008
586.57;1.528231;-0.06569489;1000.779;103.414;0;0;0;4.813326;4.701074;918459.1;1.083916e+008
592.57;1.508195;-0.05826687;878.2435;90.75201;0;0;0;4.750222;4.640849;806003.3;9.506293e+007
598.57;1.488267;-0.05130069;763.7281;78.91872;0;0;0;4.687455;4.58091;700907.3;8.2618e+007
604.57;1.468338;-0.04459848;656.6221;67.85108;0;0;0;4.624688;4.520936;602611.4;7.098899e+007
610.57;1.448356;-0.03856381;560.563;57.92496;0;0;0;4.561752;4.460764;514453.6;6.056735e+007
616.57;1.428321;-0.03331001;475.1025;49.09402;0;0;0;4.498647;4.400394;436022.7;5.130259e+007
622.57;1.408338;-0.02850701;397.457;41.07064;0;0;0;4.435711;4.34015;364764;4.289241e+007
628.57;1.388249;-0.02425606;328.9904;33.99575;0;0;0;4.372438;4.279545;301929.2;3.548219e+007
634.57;1.368213;-0.02057313;269.4144;27.83955;0;0;0;4.309334;4.219066;247253.6;2.903925e+007
640.57;1.344321;-0.01735111;208.5343;21.54859;0;0;0;4.234081;4.146896;191381.2;2.246097e+007
646.57;1.314321;-0.01427215;145.2761;15.01189;0;0;0;4.139592;4.056205;133326.3;1.563332e+007
652.57;1.284428;-0.0121995;96.94083;10.01724;0;0;0;4.045442;3.965756;88966.92;1.042248e+007
658.57;1.254481;-0.01090652;64.07344;6.620935;0;0;0;3.951122;3.875062;58803.05;6882537
662.616;1.264231;-0.01237811;93.89797;9.702809;1;1;0;3.981831;3.904599;86174.35;1.008916e+007
668.616;1.294124;-0.01543279;160.714;16.60715;1;1;0;4.075981;3.995103;147494.4;1.728405e+007
674.616;1.324071;-0.01963559;238.9149;24.68793;1;1;0;4.170301;4.085689;219262.9;2.571749e+007
680.616;1.354071;-0.02474969;332.9564;34.40556;1;1;0;4.264789;4.176353;305568.9;3.587288e+007
686.616;1.384178;-0.03157547;448.9689;46.39355;1;1;0;4.359615;4.267258;412038.8;4.841613e+007
692.616;1.414178;-0.03954012;585.7815;60.53088;1;1;0;4.454103;4.357758;537597.8;6.322699e+007
698.616;1.444178;-0.04884582;746.3959;77.12773;1;1;0;4.548591;4.448176;685000.8;8.063596e+007
704.616;1.474178;-0.05942218;930.8919;96.19235;1;1;0;4.643079;4.538513;854321;1.006586e+008
710.616;1.504178;-0.07115104;1130.658;116.8349;1;1;0;4.737567;4.628768;1037656;1.223701e+008
716.616;1.534285;-0.08335654;1343.686;138.8478;1;1;0;4.832393;4.719263;1233160;1.455575e+008
722.616;1.564285;-0.09443812;1573.541;162.5995;1;1;0;4.926881;4.809355;1444109;1.706106e+008
728.616;1.594231;-0.1040118;1814.667;187.516;1;1;0;5.0212;4.899205;1665401;1.969315e+008
734.616;1.624178;-0.1131171;2061.865;213.0599;1;1;0;5.11552;4.988975;1892266;2.23959e+008
740.616;1.654124;-0.122861;2321.971;239.9375;1;1;0;5.209839;5.078664;2130977;2.524379e+008
746.616;1.684178;-0.1326221;2594.678;268.1172;1;1;0;5.304496;5.168593;2381251;2.823395e+008
752.616;1.714285;-0.1428253;2879.024;297.4998;1;1;0;5.399322;5.258601;2642209;3.135627e+008
758.616;1.744285;-0.1528373;3169.178;327.4824;1;1;0;5.49381;5.348209;2908496;3.454736e+008
764.616;1.774231;-0.1626687;3461.61;357.7004;1;1;0;5.58813;5.437577;3176874;3.776891e+008
770.616;1.804124;-0.1714214;3741.589;386.6316;1;1;0;5.68228;5.526704;3433823;4.086011e+008
776.616;1.83407;-0.1785235;3995.085;412.8262;1;1;0;5.776599;5.615913;3666467;4.366736e+008
782.616;1.86407;-0.1846763;4243.045;438.4489;1;1;0;5.871087;5.705201;3894032;4.641906e+008
788.616;1.894231;-0.1906921;4493.456;464.3247;1;1;0;5.966082;5.794887;4123845;4.920267e+008
794.616;1.924177;-0.1965991;4740.109;489.8122;1;1;0;6.060401;5.883857;4350210;5.194968e+008
800.616;1.954177;-0.2027814;4986.746;515.2981;1;1;0;6.154889;5.972905;4576559;5.470141e+008
806.616;1.984177;-0.2095596;5238.588;541.3219;1;1;0;6.249377;6.061876;4807686;5.751511e+008
812.616;2.014231;-0.2166889;5495.395;567.8586;1;1;0;6.344034;6.150925;5043369;6.038838e+008
818.616;2.044284;-0.2246289;5752.83;594.4603;1;1;0;6.438691;6.239896;5279629;6.327357e+008
824.616;2.074284;-0.2331638;6005.13;620.5314;1;1;0;6.533179;6.328629;5511176;6.610718e+008
830.616;2.104231;-0.2423603;6254.754;646.3258;1;1;0;6.627498;6.417125;5740267;6.891611e+008
836.616;2.134124;-0.2524519;6502.553;671.9318;1;1;0;6.721649;6.505385;5967683;7.170967e+008
842.616;2.164124;-0.2631249;6747.656;697.2592;1;1;0;6.816137;6.593883;6192625;7.447853e+008
848.616;2.194231;-0.2750179;6988.725;722.1697;1;1;0;6.910963;6.682618;6413865;7.720786e+008
854.616;2.224338;-0.287083;7226.956;746.7869;1;1;0;7.005788;6.771274;6632500;7.991052e+008
860.616;2.254231;-0.299917;7455.947;770.4494;1;1;0;7.099939;6.859222;6842655;8.251508e+008
866.616;2.284177;-0.313214;7680.686;793.6725;1;1;0;7.194259;6.947251;7048908;8.507713e+008
872.616;2.31407;-0.3279913;7901.683;816.5089;1;1;0;7.288409;7.035043;7251727;8.760194e+008
878.616;2.34407;-0.3429487;8115.276;838.5801;1;1;0;7.382898;7.123075;7447750;9.004917e+008
884.616;2.374177;-0.3593849;8325.863;860.3409;1;1;0;7.477723;7.211341;7641016;9.246748e+008
890.616;2.404177;-0.3770299;8530.27;881.4631;1;1;0;7.572211;7.299217;7828610;9.482093e+008
896.616;2.434123;-0.3960842;8727.754;901.8698;1;1;0;7.66653;7.386858;8009850;9.710119e+008
902.616;2.464123;-0.417098;8921.295;921.869;1;1;0;7.761018;7.474579;8187471;9.934155e+008
908.616;2.494177;-0.4399507;9110.449;941.415;1;1;0;7.855675;7.56238;8361066;1.015369e+009
914.616;2.524231;-0.4649388;9293.626;960.3433;1;1;0;7.950332;7.650105;8529175;1.036694e+009
920.616;2.554284;-0.4936964;9473.845;978.9659;1;1;0;8.044989;7.737752;8694570;1.057724e+009
924.3581;2.554605;-0.5003063;9304.641;961.4815;1;1;0;8.046001;7.738689;8539284;1.038842e+009
928.6181;2.53323;-0.4896701;8854.102;914.9257;1;1;0;7.978678;7.67636;8125804;9.879246e+008
933.296;2.509873;-0.4783124;8403.4;868.3531;1;1;0;7.905113;7.608207;7712175;9.369974e+008
938.1961;2.485445;-0.4666523;7952.781;821.789;1;1;0;7.828172;7.536878;7298622;8.861201e+008
943.3581;2.459516;-0.4547257;7502.157;775.2245;1;1;0;7.746508;7.461113;6885065;8.352773e+008
948.8441;2.432141;-0.4420253;7051.679;728.675;1;1;0;7.660287;7.381059;6471641;7.844936e+008
954.554;2.403588;-0.4292643;6601.246;682.1301;1;1;0;7.570355;7.297492;6058258;7.337698e+008
960.408;2.374284;-0.4164936;6155.04;636.0221;1;1;0;7.478061;7.211655;5648755;6.835842e+008
966.408;2.344177;-0.4037362;5715.661;590.6194;1;1;0;7.383235;7.123389;5245517;6.342263e+008
972.408;2.314124;-0.391512;5298.852;547.5491;1;1;0;7.288578;7.035201;4862993;5.874577e+008
978.408;2.284231;-0.3797801;4899.014;506.2324;1;1;0;7.194427;6.947408;4496044;5.426529e+008
984.408;2.254338;-0.3682506;4521.643;467.2374;1;1;0;7.100276;6.859537;4149714;5.004126e+008
990.408;2.224284;-0.3566599;4159.801;429.847;1;1;0;7.00562;6.771117;3817635;4.599604e+008
996.408;2.194231;-0.3454743;3810.321;393.7339;1;1;0;6.910963;6.682618;3496901;4.209447e+008
1002.408;2.164177;-0.3347072;3470.951;358.6657;1;1;0;6.816306;6.594041;3185447;3.831135e+008
1008.408;2.134124;-0.3237995;3140.638;324.5332;1;1;0;6.721649;6.505385;2882304;3.463472e+008
1014.408;2.104231;-0.3132991;2821.046;291.5086;1;1;0;6.627498;6.417125;2588999;3.108283e+008
1020.408;2.074284;-0.3029324;2509.209;259.2855;1;1;0;6.533179;6.328629;2302814;2.762251e+008
1026.408;2.044338;-0.2930564;2207.623;228.1215;1;1;0;6.438859;6.240055;2026035;2.4281e+008
1032.408;2.014338;-0.2832609;1915.013;197.8851;1;1;0;6.344371;6.151243;1757493;2.104396e+008
1038.408;1.984284;-0.2738396;1635.92;169.0454;1;1;0;6.249714;6.062193;1501357;1.796103e+008
1044.408;1.954284;-0.2653115;1375.957;142.1825;1;1;0;6.155226;5.973223;1262777;1.509342e+008
1050.408;1.924338;-0.2571985;1138.464;117.6415;1;1;0;6.060907;5.884334;1044819;1.247717e+008
1056.408;1.894285;-0.2496325;921.3014;95.20133;1;1;0;5.96625;5.795047;845519.3;1.008813e+008
1062.408;1.864231;-0.242635;722.9939;74.70951;1;1;0;5.871594;5.705679;663523.7;7.909615e+007
1068.408;1.834178;-0.2360111;548.9708;56.7271;1;1;0;5.776937;5.616232;503815;6.000418e+007
1074.408;1.804124;-0.2306044;400.2303;41.35722;1;1;0;5.68228;5.526704;367309.2;4.370725e+007
1080.408;1.774285;-0.2272758;284.4188;29.39;1;1;0;5.588298;5.437736;261023.8;3.10324e+007
1086.408;1.744338;-0.2255449;201.4663;20.81823;1;1;0;5.493978;5.348369;184894.7;2.196198e+007
1092.408;1.714285;-0.2242721;145.0968;14.99337;1;1;0;5.399322;5.258601;133161.8;1.580291e+007
1098.408;1.684231;-0.2230537;104.227;10.77015;1;1;0;5.304665;5.168753;95653.8;1.134147e+007
1103.344;1.669499;-0.222377;97.48625;10.0736;2;2;0;5.258264;5.12468;89467.48;1.06033e+007
1109.344;1.699553;-0.2241778;172.7727;17.85321;2;2;0;5.352921;5.214568;158561.2;1.880888e+007
1115.344;1.729499;-0.2257546;274.7851;28.39452;2;2;0;5.447241;5.304055;252182.6;2.994124e+007
1121.344;1.759552;-0.2280478;417.6728;43.15961;2;2;0;5.541897;5.393782;383316.9;4.555147e+007
1127.344;1.789606;-0.2317643;600.1944;62.02021;2;2;0;5.636554;5.483428;550825.1;6.551601e+007
1133.344;1.81966;-0.23791;819.2808;84.65919;2;2;0;5.731211;5.572994;751890.5;8.951118e+007
1139.344;1.849713;-0.2451491;1066.999;110.2568;2;2;0;5.825868;5.66248;979232.3;1.166802e+008
1145.344;1.879552;-0.2532821;1335.751;138.0279;2;2;0;5.91985;5.751249;1225878;1.461989e+008
1151.344;1.909499;-0.2613189;1622.603;167.6694;2;2;0;6.01417;5.840257;1489136;1.777533e+008
1157.344;1.939499;-0.2698604;1923.393;198.751;2;2;0;6.108657;5.929345;1765184;2.108921e+008
1163.344;1.969606;-0.2788415;2236.114;231.0655;2;2;0;6.203482;6.018671;2052181;2.453996e+008
1169.344;1.999713;-0.2883453;2562.704;264.8133;2;2;0;6.298309;6.107919;2351908;2.81492e+008
1175.344;2.029659;-0.2982728;2898.085;299.4694;2;2;0;6.392628;6.19661;2659702;3.186134e+008
1181.344;2.059552;-0.3085322;3237.475;334.5398;2;2;0;6.486779;6.285065;2971175;3.562406e+008
1187.344;2.089499;-0.3190296;3584.304;370.3788;2;2;0;6.581098;6.373599;3289476;3.947538e+008
1193.344;2.119445;-0.3298257;3934.169;406.5316;2;2;0;6.675417;6.462055;3610563;4.336693e+008
1199.344;2.149552;-0.3408644;4290.55;443.3577;2;2;0;6.770243;6.550908;3937629;4.733741e+008
1205.344;2.179552;-0.3518506;4647.113;480.2026;2;2;0;6.864731;6.639365;4264863;5.131672e+008
1211.344;2.209499;-0.3630883;5004.188;517.1005;2;2;0;6.959051;6.727587;4592567;5.530858e+008
1217.344;2.239552;-0.3745993;5364.48;554.3307;2;2;0;7.053708;6.816046;4923223;5.934315e+008
1223.344;2.269606;-0.3861203;5728.404;591.9363;2;2;0;7.148364;6.904427;5257212;6.3425e+008
1229.344;2.299659;-0.397797;6097.378;630.0637;2;2;0;7.243021;6.99273;5595836;6.756993e+008
1235.344;2.329713;-0.4097354;6467.89;668.3499;2;2;0;7.337678;7.080955;5935871;7.173913e+008
1241.344;2.359659;-0.4220513;6837.713;706.5651;2;2;0;7.431998;7.168788;6275275;7.59077e+008
1247.344;2.389499;-0.4342222;7206.21;744.6432;2;2;0;7.52598;7.25623;6613461;8.006849e+008
1253.344;2.419498;-0.4466477;7579.853;783.2531;2;2;0;7.620468;7.344066;6956369;8.429406e+008
1259.344;2.449552;-0.4595225;7952.33;821.7424;2;2;0;7.715125;7.431982;7298208;8.851408e+008
1265.344;2.479659;-0.4726087;8327.313;860.4907;2;2;0;7.80995;7.519977;7642347;9.276946e+008
1271.344;2.509659;-0.4864292;8695.216;898.5074;2;2;0;7.904438;7.607582;7979987;9.695294e+008
1277.344;2.539605;-0.501541;9047.445;934.9045;2;2;0;7.998757;7.694954;8303244;1.009685e+009
1283.344;2.569498;-0.5192409;9366.909;967.9158;2;2;0;8.092908;7.782093;8596430;1.046248e+009
1289.344;2.599498;-0.5435183;9632.072;995.3161;2;2;0;8.187396;7.869469;8839782;1.076807e+009
1295.344;2.629498;-0.5772227;9845.419;1017.362;2;2;0;8.281884;7.956768;9035580;1.101619e+009
1301.344;2.659498;-0.619201;10027.66;1036.194;2;2;0;8.376372;8.043991;9202834;1.122989e+009
1307.344;2.689552;-0.670436;10190.51;1053.022;2;2;0;8.471028;8.131293;9352289;1.142224e+009
1313.344;2.719498;-0.7301133;10340.97;1068.569;2;2;0;8.565349;8.21821;9490366;1.160095e+009
1319.344;2.749552;-0.7996195;10478.97;1082.829;2;2;0;8.660006;8.305361;9617014;1.176602e+009
1325.344;2.779605;-0.8805592;10606.09;1095.965;2;2;0;8.754663;8.392435;9733683;1.191913e+009
1331.344;2.809659;-0.9734368;10722.23;1107.965;2;2;0;8.849319;8.479434;9840264;1.206013e+009
1337.344;2.839712;-1.079653;10825.5;1118.638;2;2;0;8.943975;8.566358;9935047;1.218688e+009
1343.344;2.869605;-1.196841;10909.8;1127.349;2;2;0;9.038127;8.652743;1.001241e+007;1.22924e+009
1346.426;2.861355;-1.216434;10618.25;1097.221;2;2;0;9.012143;8.628909;9744837;1.196104e+009
1350.538;2.840784;-1.206963;10167.47;1050.641;2;2;0;8.947351;8.569456;9331141;1.144645e+009
1354.892;2.819034;-1.195969;9716.946;1004.086;2;2;0;8.878847;8.506558;8917675;1.093238e+009
1359.364;2.796587;-1.184698;9266.339;957.5236;2;2;0;8.808149;8.441605;8504133;1.041864e+009
1364.042;2.77307;-1.1731;8815.936;910.9818;2;2;0;8.734077;8.373506;8090777;9.905477e+008
1369.01;2.74848;-1.160416;8365.423;864.4288;2;2;0;8.656631;8.302255;7677322;9.392592e+008
1374.126;2.722713;-1.147672;7914.826;817.867;2;2;0;8.575473;8.227534;7263789;8.880029e+008
1379.478;2.696034;-1.134708;7464.413;771.3243;2;2;0;8.491446;8.150114;6850425;8.368208e+008
1385.016;2.668391;-1.122044;7014.01;724.7825;2;2;0;8.404382;8.069832;6437070;7.856959e+008
1390.706;2.639838;-1.1089;6563.889;678.2699;2;2;0;8.314449;7.986838;6023974;7.346643e+008
1396.58;2.61048;-1.095483;6118.254;632.2208;2;2;0;8.221985;7.901435;5614995;6.842019e+008
1402.58;2.580587;-1.082708;5683.315;587.2771;2;2;0;8.127834;7.814399;5215832;6.3501e+008
1408.58;2.550641;-1.070084;5275.775;545.1645;2;2;0;8.033516;7.727133;4841814;5.889603e+008
1414.58;2.520588;-1.057731;4893.11;505.6223;2;2;0;7.938859;7.639476;4490625;5.45763e+008
1420.58;2.49048;-1.046033;4526.278;467.7163;2;2;0;7.844032;7.551585;4153967;5.044042e+008
1426.58;2.460427;-1.034738;4174.189;431.3337;2;2;0;7.749376;7.463775;3830840;4.647594e+008
1432.58;2.430481;-1.023571;3837.772;396.5705;2;2;0;7.655057;7.376202;3522094;4.269282e+008
1438.58;2.400588;-1.012932;3513.086;363.0196;2;2;0;7.560906;7.288707;3224115;3.904671e+008
1444.58;2.370588;-1.002416;3197.255;330.3837;2;2;0;7.466418;7.200822;2934264;3.550515e+008
1450.58;2.340588;-0.9923946;2891.003;298.7375;2;2;0;7.37193;7.11286;2653202;3.207603e+008
1456.58;2.310534;-0.9824988;2594.378;268.0863;2;2;0;7.277274;7.024664;2380977;2.875957e+008
1462.58;2.280534;-0.9727491;2307.45;238.437;2;2;0;7.182785;6.936546;2117650;2.555634e+008
1468.58;2.250588;-0.9636518;2033.354;210.1137;2;2;0;7.088466;6.848509;1866100;2.250075e+008
1474.58;2.220641;-0.9549347;1771.691;183.0751;2;2;0;6.994146;6.760394;1625960;1.958796e+008
1480.58;2.190588;-0.9464253;1522.618;157.3375;2;2;0;6.899489;6.671885;1397374;1.68193e+008
1486.58;2.160481;-0.9385863;1289.438;133.2422;2;2;0;6.804664;6.583141;1183375;1.423088e+008
1492.58;2.130427;-0.931114;1070.085;110.5757;2;2;0;6.710007;6.494475;982064.7;1.179953e+008
1498.58;2.100481;-0.9245716;870.4367;89.9453;2;2;0;6.615687;6.406048;798838.6;9.589581e+007
1504.58;2.070534;-0.9192943;690.1536;71.31601;2;2;0;6.521368;6.317541;633384.7;7.596679e+007
1510.58;2.040588;-0.9153966;530.6633;54.83532;2;2;0;6.427048;6.228957;487013.4;5.835961e+007
1516.58;2.010534;-0.9124214;392.5772;40.56639;2;2;0;6.332392;6.139977;360285.6;4.313522e+007
1522.58;1.980427;-0.9106411;281.1486;29.05208;2;2;0;6.237566;6.050759;258022.7;3.086423e+007
1528.58;1.950427;-0.910005;196.1198;20.26575;2;2;0;6.143078;5.961779;179987.9;2.151069e+007
1534.58;1.920534;-0.9097517;137.3892;14.19692;2;2;0;6.048927;5.873038;126088.2;1.505568e+007
1540.58;1.890588;-0.909517;100.2486;10.35905;2;2;0;5.954608;5.784059;92002.63;1.097589e+007
1546.416;1.861392;-0.9092709;75.22929;7.773709;2;2;0;5.862651;5.697232;69041.27;8229455
1551.418;1.886356;-0.9098158;131.8039;13.61976;3;3;0;5.941279;5.771478;120962.3;1.442895e+007
1557.418;1.916249;-0.9097141;220.6721;22.80283;3;3;0;6.035429;5.860309;202520.6;2.417908e+007
1563.418;1.946249;-0.910382;348.0597;35.96624;3;3;0;6.129918;5.949379;319429.9;3.817094e+007
1569.418;1.976249;-0.9122014;511.3961;52.84436;3;3;0;6.224405;6.03837;469331;5.613361e+007
1575.418;2.006356;-0.915193;707.0352;73.06046;3;3;0;6.319231;6.127599;648877.8;7.767731e+007
1581.418;2.036302;-0.9196058;931.8342;96.28973;3;3;0;6.41355;6.216273;855185.8;1.024653e+008
1587.418;2.066302;-0.9248868;1178.874;121.8172;3;3;0;6.508038;6.305027;1081906;1.297452e+008
1593.418;2.096356;-0.9312125;1444.645;149.2803;3;3;0;6.602695;6.393861;1325816;1.591368e+008
1599.418;2.126409;-0.9385286;1723.56;178.1015;3;3;0;6.697352;6.482615;1581788;1.900296e+008
1605.418;2.156463;-0.9466394;2011.716;207.8778;3;3;0;6.792008;6.571291;1846242;2.219968e+008
1611.418;2.186463;-0.9551138;2306.336;238.3219;3;3;0;6.886497;6.659731;2116628;2.547339e+008
1617.418;2.216356;-0.9636861;2610.62;269.7646;3;3;0;6.980648;6.747777;2395883;2.88596e+008
1623.418;2.246249;-0.9728458;2923.569;302.1027;3;3;0;7.074799;6.835746;2683090;3.234759e+008
1629.418;2.276302;-0.9824257;3249.099;335.7409;3;3;0;7.169456;6.924109;2981843;3.598117e+008
1635.418;2.306356;-0.9923102;3583.413;370.2867;3;3;0;7.264112;7.012394;3288658;3.971848e+008
1641.418;2.336463;-1.002395;3921.862;405.2599;3;3;0;7.358938;7.100759;3599268;4.350827e+008
1647.418;2.366409;-1.012732;4265.828;440.8031;3;3;0;7.453257;7.188575;3914940;4.736573e+008
1653.418;2.396302;-1.023398;4612.085;476.583;3;3;0;7.547409;7.276157;4232716;5.125527e+008
1659.418;2.426249;-1.03427;4964.658;513.0157;3;3;0;7.641727;7.363819;4556288;5.522189e+008
1665.418;2.456248;-1.045396;5323.008;550.0452;3;3;0;7.736215;7.45156;4885162;5.925979e+008
1671.418;2.486302;-1.056994;5688.205;587.7824;3;3;0;7.830873;7.539382;5220320;6.338109e+008
1677.418;2.516356;-1.068635;6056.445;625.8339;3;3;0;7.925529;7.627126;5558270;6.754345e+008
1683.418;2.546302;-1.080769;6433.289;664.7745;3;3;0;8.019849;7.714481;5904116;7.180884e+008
1689.418;2.576302;-1.093438;6824.857;705.2366;3;3;0;8.114336;7.801915;6263476;7.624619e+008
1695.418;2.606355;-1.106832;7225.887;746.6765;3;3;0;8.208993;7.889429;6631519;8.079711e+008
1701.418;2.636355;-1.120096;7627.318;788.1578;3;3;0;8.303481;7.976711;6999930;8.536023e+008
1707.418;2.666463;-1.1336;8028.383;829.6012;3;3;0;8.398308;8.064229;7368005;8.992737e+008
1713.418;2.696463;-1.147208;8425.144;870.6;3;3;0;8.492796;8.151359;7732131;9.445382e+008
1719.418;2.726302;-1.161524;8823.781;911.7925;3;3;0;8.586777;8.237945;8097978;9.900861e+008
1725.418;2.756302;-1.175523;9225.815;953.3361;3;3;0;8.681266;8.324924;8466941;1.036098e+009
1731.418;2.786355;-1.191254;9626.196;994.7089;3;3;0;8.775922;8.411981;8834389;1.082004e+009
1737.418;2.816409;-1.208842;10020.92;1035.497;3;3;0;8.870579;8.498964;9196647;1.127352e+009
1743.418;2.846462;-1.231142;10392.98;1073.944;3;3;0;8.965236;8.585871;9538103;1.170225e+009
1749.418;2.876462;-1.265078;10702.08;1105.884;3;3;0;9.059724;8.672547;9821775;1.206074e+009
1755.418;2.906248;-1.330141;10908.98;1127.263;3;3;0;9.153538;8.758531;1.001166e+007;1.230448e+009
1761.418;2.936248;-1.446079;11022.21;1138.964;3;3;0;9.248026;8.845058;1.011557e+007;1.244296e+009
1767.418;2.966248;-1.59723;11089.71;1145.939;3;3;0;9.342514;8.93151;1.017752e+007;1.252999e+009
1773.418;2.996355;-1.763521;11142.52;1151.396;3;3;0;9.437339;9.018195;1.022599e+007;1.260058e+009
1779.418;3.026355;-1.937949;11186.47;1155.938;3;3;0;9.531827;9.104498;1.026632e+007;1.266119e+009
1783.204;3.034284;-2.028238;11054.73;1142.325;3;3;0;9.5568;9.127295;1.014542e+007;1.251494e+009
1787.306;3.013659;-2.022247;10604.33;1095.783;3;3;0;9.491838;9.067982;9732069;1.199793e+009
1791.716;2.991373;-2.01159;10153.88;1049.236;3;3;0;9.421648;9.003856;9318668;1.148092e+009
1796.354;2.968337;-2.000307;9703.188;1002.665;3;3;0;9.349093;8.937527;8905048;1.096405e+009
1801.1;2.944659;-1.988641;9252.504;956.0941;3;3;0;9.274516;8.869303;8491436;1.044767e+009
1806.06;2.919641;-1.976222;8801.809;909.5221;3;3;0;9.19572;8.797168;8077813;9.931592e+008
1811.314;2.893605;-1.963312;8351.17;862.956;3;3;0;9.113717;8.722043;7664242;9.416034e+008
1816.616;2.867087;-1.950366;7900.518;816.3885;3;3;0;9.030196;8.645469;7250658;8.9011e+008
1821.972;2.840302;-1.937183;7450.149;769.8503;3;3;0;8.945832;8.568062;6837335;8.387198e+008
1827.45;2.812873;-1.923985;6999.426;723.2755;3;3;0;8.859444;8.488735;6423685;7.873536e+008
1833.136;2.784427;-1.910393;6549.04;676.7355;3;3;0;8.769848;8.406397;6010347;7.360842e+008
1839.06;2.754855;-1.897197;6101.527;630.4924;3;3;0;8.67671;8.320732;5599644;6.851984e+008
1845.06;2.724802;-1.884092;5672.235;586.1321;3;3;0;8.582053;8.233595;5205663;6.364343e+008
1851.06;2.694695;-1.871122;5265.321;544.0843;3;3;0;8.487227;8.146226;4832220;5.902619e+008
1857.06;2.664695;-1.858331;4876;503.8544;3;3;0;8.392739;8.059092;4474923;5.461416e+008
1863.06;2.634802;-1.846135;4500.98;465.1022;3;3;0;8.298589;7.972193;4130750;5.036991e+008
1869.06;2.604855;-1.834185;4135.798;427.3666;3;3;0;8.204269;7.885063;3795606;4.624289e+008
1875.06;2.574855;-1.82254;3781.118;390.7163;3;3;0;8.109781;7.797702;3470101;4.224026e+008
1881.06;2.544856;-1.811143;3443.547;355.8339;3;3;0;8.015293;7.710263;3160297;3.84355e+008
1887.06;2.514802;-1.800496;3125.485;322.9674;3;3;0;7.920635;7.622591;2868397;3.485484e+008
1893.06;2.484855;-1.790259;2819.699;291.3695;3;3;0;7.826316;7.535156;2587764;3.14173e+008
1899.06;2.454909;-1.780436;2526.016;261.0222;3;3;0;7.731997;7.447645;2318238;2.812044e+008
1905.06;2.424855;-1.771006;2244.71;231.9539;3;3;0;7.63734;7.359743;2060071;2.49669e+008
1911.06;2.394748;-1.761789;1974.998;204.0835;3;3;0;7.542515;7.271607;1812544;2.194766e+008
1917.06;2.364695;-1.75311;1719.456;177.6775;3;3;0;7.447858;7.18355;1578022;1.909107e+008
1923.06;2.334695;-1.745254;1479.191;152.85;3;3;0;7.35337;7.095573;1357520;1.640897e+008
1929.06;2.304748;-1.737846;1255.501;129.7354;3;3;0;7.25905;7.007675;1152230;1.391529e+008
1935.06;2.274856;-1.731362;1045.927;108.0793;3;3;0;7.1649;6.919859;959893.9;1.158231e+008
1941.06;2.244856;-1.725928;855.3139;88.38261;3;3;0;7.070412;6.831649;784959.8;9.463163e+007
1947.06;2.214749;-1.721639;681.8808;70.46116;3;3;0;6.975586;6.743046;625792.4;7.537623e+007
1953.06;2.184695;-1.718235;529.0419;54.66777;3;3;0;6.880929;6.654521;485525.4;5.842943e+007
1959.06;2.154695;-1.716059;398.2684;41.15448;3;3;0;6.786441;6.566078;365508.7;4.394741e+007
1965.06;2.124749;-1.714908;289.3621;29.90081;3;3;0;6.692122;6.477714;265560.5;3.190181e+007
1971.06;2.094856;-1.714136;202.7811;20.95408;3;3;0;6.597971;6.389429;186101.2;2.233663e+007
1977.06;2.064856;-1.71415;137.6023;14.21893;3;3;0;6.503483;6.30075;126283.7;1.514365e+007
1983.06;2.034856;-1.713865;96.70492;9.992862;3;3;0;6.408995;6.211993;88750.42;1.06333e+007
1987.94;2.040481;-1.714191;128.9279;13.32257;4;4;0;6.426711;6.22864;118322.9;1.417878e+007
1993.94;2.070427;-1.714509;247.6833;25.59399;4;4;0;6.52103;6.317225;227310;2.726298e+007
1999.94;2.10032;-1.714913;388.6017;40.15559;4;4;0;6.615181;6.405573;356637.1;4.281195e+007
2005.94;2.130267;-1.716575;559.0072;57.76419;4;4;0;6.709501;6.494001;513025.8;6.163988e+007
2011.94;2.160267;-1.719551;758.7755;78.40695;4;4;0;6.803989;6.582509;696362.1;8.374176e+007
2017.94;2.190374;-1.723523;982.2831;101.5028;4;4;0;6.898815;6.671254;901484.9;1.085053e+008
2023.94;2.220427;-1.728425;1225.795;126.6657;4;4;0;6.993471;6.759763;1124967;1.35524e+008
2029.94;2.250374;-1.734074;1483.906;153.3373;4;4;0;7.087791;6.847879;1361847;1.642055e+008
2035.94;2.280374;-1.740595;1758.239;181.685;4;4;0;7.182279;6.936074;1613614;1.947342e+008
2041.94;2.310427;-1.748003;2044.231;211.2376;4;4;0;7.276936;7.024349;1876082;2.266092e+008
2047.94;2.340481;-1.756017;2336.333;241.4216;4;4;0;7.371593;7.112546;2144158;2.592182e+008
2053.94;2.370481;-1.764631;2639.382;272.7367;4;4;0;7.466081;7.200508;2422279;2.930994e+008
2059.94;2.400427;-1.773632;2952.532;305.0956;4;4;0;7.5604;7.288237;2709670;3.28162e+008
2065.94;2.430373;-1.782743;3272.886;338.1989;4;4;0;7.654719;7.375888;3003674;3.640871e+008
2071.94;2.46032;-1.79254;3606.034;372.6243;4;4;0;7.749038;7.463462;3309418;4.014991e+008
2077.94;2.490373;-1.802681;3947.867;407.9471;4;4;0;7.843695;7.551272;3623134;4.399452e+008
2083.94;2.52048;-1.813179;4294.622;443.7785;4;4;0;7.938521;7.639163;3941366;4.790079e+008
2089.94;2.55048;-1.824015;4654.389;480.9545;4;4;0;8.03301;7.726664;4271541;5.195897e+008
2095.94;2.580427;-1.835677;5026.046;519.3591;4;4;0;8.127329;7.813931;4612627;5.615691e+008
2101.94;2.61032;-1.847472;5406.012;558.6224;4;4;0;8.221479;7.900967;4961338;6.045494e+008
2107.94;2.64032;-1.859536;5791.581;598.4646;4;4;0;8.315968;7.988239;5315193;6.482327e+008
2113.94;2.67032;-1.871944;6179.965;638.5977;4;4;0;8.410456;8.075436;5671629;6.923066e+008
2119.94;2.700373;-1.884656;6571.701;679.0771;4;4;0;8.505113;8.162711;6031143;7.368334e+008
2125.94;2.730373;-1.897703;6970.521;720.2886;4;4;0;8.599601;8.249755;6397158;7.822306e+008
2131.94;2.76032;-1.911041;7374.12;761.9939;4;4;0;8.69392;8.336567;6767559;8.282411e+008
2137.94;2.790373;-1.924634;7783.881;804.336;4;4;0;8.788577;8.423615;7143615;8.750257e+008
2143.94;2.820427;-1.938821;8196.587;846.9823;4;4;0;8.883234;8.510588;7522373;9.222217e+008
2149.94;2.85048;-1.952973;8607.592;889.453;4;4;0;8.977891;8.597484;7899572;9.693071e+008
2155.94;2.88048;-1.967397;9011.845;931.2258;4;4;0;9.072379;8.68415;8270572;1.01571e+009
2161.94;2.910427;-1.982506;9407.204;972.0797;4;4;0;9.166698;8.770587;8633411;1.061187e+009
2167.94;2.94032;-1.998311;9796.931;1012.352;4;4;0;9.260849;8.856795;8991081;1.106104e+009
2173.94;2.970319;-2.016276;10186.81;1052.639;4;4;0;9.355337;8.943237;9348891;1.151117e+009
2179.94;3.000427;-2.038506;10562.79;1091.49;4;4;0;9.450163;9.029913;9693940;1.194638e+009
2185.94;3.030427;-2.073931;10902.49;1126.593;4;4;0;9.544651;9.116205;1.00057e+007;1.234122e+009
2191.94;3.060534;-2.152037;11138.37;1150.968;4;4;0;9.639477;9.202731;1.022218e+007;1.261915e+009
2197.94;3.090426;-2.305779;11226.2;1160.043;4;4;0;9.733626;9.288566;1.030279e+007;1.272957e+009
2203.94;3.120266;-2.499285;11253.5;1162.864;4;4;0;9.827609;9.374176;1.032784e+007;1.277145e+009
2209.94;3.150266;-2.700089;11271.97;1164.772;4;4;0;9.922097;9.460172;1.034479e+007;1.280342e+009
2215.94;3.180373;-2.903375;11289.8;1166.615;4;4;0;10.01692;9.546401;1.036116e+007;1.283474e+009
2219.852;3.194677;-3.028993;11226.33;1160.056;4;4;0;10.06197;9.587342;1.03029e+007;1.27678e+009
2223.836;3.174266;-3.027822;10775.68;1113.489;4;4;0;9.997687;9.528916;9889323;1.224812e+009
2228.364;3.151658;-3.017287;10325.23;1066.942;4;4;0;9.926483;9.464162;9475920;1.172852e+009
2233.04;3.128409;-3.005939;9874.733;1020.391;4;4;0;9.853255;9.397525;9062483;1.120933e+009
2237.83;3.104355;-2.994104;9424.231;973.8392;4;4;0;9.777496;9.328537;8649037;1.069056e+009
2242.774;3.079552;-2.981516;8973.634;927.2774;4;4;0;9.699375;9.257349;8235505;1.017218e+009
2247.99;3.053623;-2.968588;8522.957;880.7073;4;4;0;9.617709;9.182876;7821898;9.654112e+008
2253.314;3.026998;-2.955201;8072.347;834.1442;4;4;0;9.533852;9.106347;7408353;9.136702e+008
2258.796;2.999569;-2.941963;7621.873;787.5952;4;4;0;9.447463;9.027446;6994933;8.620029e+008
2264.396;2.971551;-2.928382;7171.386;741.0447;4;4;0;9.359217;8.946785;6581501;8.104007e+008
2270.19;2.942623;-2.915052;6721.766;694.5839;4;4;0;9.268105;8.863435;6168865;7.589586e+008
2276.176;2.912623;-2.901635;6279.112;648.8428;4;4;0;9.173616;8.776924;5762621;7.083652e+008
2282.176;2.882676;-2.888533;5857.379;605.2637;4;4;0;9.079296;8.690492;5375578;6.602173e+008
2288.176;2.85273;-2.875521;5449.899;563.1573;4;4;0;8.984978;8.603987;5001616;6.137569e+008
2294.176;2.82273;-2.862175;5049.568;521.7897;4;4;0;8.89049;8.517251;4634214;5.681794e+008
2300.176;2.792623;-2.84894;4657.547;481.2808;4;4;0;8.795664;8.430129;4274439;5.236126e+008
2306.176;2.76257;-2.837169;4282.264;442.5015;4;4;0;8.701007;8.343087;3930025;4.810036e+008
2312.176;2.732516;-2.825176;3922.561;405.3322;4;4;0;8.606349;8.255968;3599910;4.402164e+008
2318.176;2.702623;-2.813685;3578.242;369.7524;4;4;0;8.512199;8.169242;3283912;4.012264e+008
2324.176;2.672677;-2.802606;3247.743;335.6008;4;4;0;8.41788;8.082283;2980599;3.638513e+008
2330.176;2.642677;-2.791958;2927.801;302.54;4;4;0;8.323392;7.995094;2686973;3.277216e+008
2336.176;2.612623;-2.781356;2615.261;270.2442;4;4;0;8.228735;7.907671;2400142;2.924819e+008
2342.176;2.58257;-2.771181;2313.293;239.0407;4;4;0;8.134078;7.820173;2123012;2.584845e+008
2348.176;2.552516;-2.761925;2030.392;209.8075;4;4;0;8.039421;7.732599;1863381;2.266749e+008
2354.176;2.522623;-2.753218;1769.718;182.8712;4;4;0;7.945271;7.645416;1624149;1.974008e+008
2360.176;2.492677;-2.745186;1526.687;157.758;4;4;0;7.850951;7.558001;1401109;1.701435e+008
2366.176;2.46273;-2.738103;1299.107;134.2414;4;4;0;7.756631;7.470508;1192249;1.44654e+008
2372.176;2.432731;-2.731807;1087.069;112.3307;4;4;0;7.662143;7.382784;997652;1.209377e+008
2378.176;2.402624;-2.726801;892.8839;92.26485;4;4;0;7.567318;7.294668;819439.3;9.924682e+007
2384.176;2.372623;-2.722881;718.1478;74.20875;4;4;0;7.47283;7.206788;659076.3;7.975425e+007
2390.176;2.342784;-2.719756;563.1125;58.18841;4;4;0;7.378848;7.119303;516793.5;6.248204e+007
2396.176;2.312677;-2.717383;428.0892;44.23597;4;4;0;7.284022;7.030954;392876.6;4.745813e+007
2402.176;2.282623;-2.71629;314.5989;32.50862;4;4;0;7.189365;6.942685;288721.5;3.484578e+007
2408.176;2.25257;-2.715413;223.0371;23.04721;4;4;0;7.094708;6.854338;204691.1;2.468235e+007
2414.176;2.222516;-2.714945;152.3497;15.74284;4;4;0;7.000051;6.765913;139818.1;1.684484e+007
2420.176;2.192624;-2.714772;103.793;10.7253;4;4;0;6.905901;6.677883;95255.44;1.146597e+007
2426.176;2.162677;-2.714388;75.94432;7.847595;4;4;0;6.811582;6.589618;69697.48;8382141
2430.888;2.17907;-2.714885;121.1326;12.51706;5;5;0;6.863213;6.637944;111168.8;1.337613e+007
2436.888;2.209016;-2.715412;226.594;23.41476;5;5;0;6.957532;6.726167;207955.4;2.504385e+007
2442.888;2.239123;-2.716106;355.4717;36.73214;5;5;0;7.052357;6.814785;326232.2;3.932263e+007
2448.888;2.269124;-2.717361;512.361;52.94407;5;5;0;7.146846;6.90301;470216.5;5.672791e+007
2454.888;2.299177;-2.719303;696.6881;71.99125;5;5;0;7.241502;6.991314;639381.8;7.720449e+007
2460.888;2.329177;-2.722466;908.3489;93.86291;5;5;0;7.335991;7.079383;833632.3;1.007487e+008
2466.888;2.35907;-2.726673;1140.521;117.8541;5;5;0;7.430141;7.16706;1046707;1.266108e+008
2472.888;2.388963;-2.731517;1390.962;143.733;5;5;0;7.524292;7.254661;1276547;1.545479e+008
2478.888;2.41907;-2.73755;1659.443;171.4761;5;5;0;7.619118;7.342812;1522945;1.845411e+008
2484.888;2.449123;-2.74413;1937.555;200.2145;5;5;0;7.713775;7.430729;1778181;2.156585e+008
2490.888;2.47923;-2.751597;2224.913;229.9081;5;5;0;7.8086;7.518725;2041902;2.478607e+008
2496.888;2.50907;-2.759835;2520.728;260.4757;5;5;0;7.902582;7.605861;2313385;2.810601e+008
2502.888;2.539016;-2.768378;2828.334;292.2617;5;5;0;7.996901;7.693235;2595688;3.156336e+008
2508.888;2.568963;-2.777721;3155.545;326.0737;5;5;0;8.091222;7.780533;2895985;3.52457e+008
2514.888;2.599016;-2.787692;3504.21;362.1024;5;5;0;8.185878;7.868066;3215970;3.917437e+008
2520.888;2.62907;-2.798035;3859.811;398.8479;5;5;0;8.280535;7.955522;3542320;4.318746e+008
2526.888;2.65907;-2.808629;4218.398;435.902;5;5;0;8.375023;8.042746;3871412;4.724089e+008
2532.888;2.689016;-2.819667;4580.696;473.3395;5;5;0;8.469342;8.129739;4203909;5.134283e+008
2538.888;2.719016;-2.830952;4951.806;511.6877;5;5;0;8.56383;8.216811;4544494;5.555077e+008
2544.888;2.749123;-2.84295;5331.371;550.9094;5;5;0;8.658656;8.304119;4892837;5.986108e+008
2550.888;2.779177;-2.854968;5718.661;590.9294;5;5;0;8.753313;8.391195;5248270;6.426553e+008
2556.888;2.809177;-2.867674;6112.344;631.6102;5;5;0;8.847801;8.47804;5609571;6.874938e+008
2562.888;2.839177;-2.880567;6509.367;672.636;5;5;0;8.942289;8.56481;5973937;7.32785e+008
2568.888;2.869016;-2.893519;6903.566;713.3699;5;5;0;9.036271;8.65104;6335711;7.77832e+008
2574.888;2.899016;-2.906621;7298.829;754.2139;5;5;0;9.130759;8.73766;6698461;8.230793e+008
2580.888;2.929069;-2.919758;7693.907;795.0386;5;5;0;9.225415;8.824359;7061042;8.683842e+008
2586.888;2.959176;-2.933462;8093.484;836.3284;5;5;0;9.320241;8.911138;7427752;9.142762e+008
2592.888;2.989176;-2.947442;8494.389;877.7552;5;5;0;9.414729;8.997533;7795680;9.603935e+008
2598.888;3.019123;-2.961941;8892.683;918.9125;5;5;0;9.509049;9.0837;8161212;1.006292e+009
2604.888;3.049016;-2.976822;9290.617;960.0323;5;5;0;9.6032;9.169638;8526413;1.052226e+009
2610.888;3.078962;-2.992896;9687.317;1001.025;5;5;0;9.697519;9.255657;8890483;1.098099e+009
2616.888;3.108962;-3.010363;10080.64;1041.668;5;5;0;9.792007;9.341755;9251453;1.143668e+009
2622.888;3.139069;-3.030548;10462.97;1081.176;5;5;0;9.886832;9.428085;9602338;1.18807e+009
2628.888;3.16907;-3.059387;10825.95;1118.684;5;5;0;9.981321;9.514036;9935459;1.230343e+009
2634.888;3.199016;-3.114738;11124.99;1149.584;5;5;0;10.07564;9.599759;1.02099e+007;1.265412e+009
2640.888;3.229016;-3.246234;11272.37;1164.814;5;5;0;10.17013;9.685561;1.034516e+007;1.283277e+009
2646.888;3.259123;-3.449058;11298.53;1167.517;5;5;0;10.26495;9.771596;1.036916e+007;1.287362e+009
2652.888;3.289123;-3.665619;11303.4;1168.021;5;5;0;10.35944;9.857251;1.037364e+007;1.289021e+009
2658.888;3.319177;-3.886263;11307.96;1168.492;5;5;0;10.4541;9.942986;1.037782e+007;1.290647e+009
2662.87;3.334016;-4.026049;11235.44;1160.998;5;5;0;10.50084;9.985291;1.031127e+007;1.282913e+009
2666.808;3.313712;-4.02524;10784.81;1114.433;5;5;0;10.43689;9.927403;9897705;1.230745e+009
2671.31;3.291426;-4.01428;10334.38;1067.888;5;5;0;10.3667;9.863825;9484317;1.178592e+009
2675.992;3.267962;-4.002457;9883.617;1021.309;5;5;0;10.29279;9.796841;9070636;1.12643e+009
2680.814;3.243855;-3.990489;9432.913;974.7363;5;5;0;10.21687;9.727975;8657005;1.074324e+009
2685.806;3.218837;-3.978207;8982.397;928.1829;5;5;0;10.13807;9.656457;8243547;1.022283e+009
2691.082;3.192427;-3.964787;8531.911;881.6326;5;5;0;10.05489;9.580903;7830115;9.702797e+008
2696.5;3.16532;-3.951249;8081.394;835.079;5;5;0;9.96951;9.503296;7416656;9.183323e+008
2702.056;3.137623;-3.937788;7631.029;788.5412;5;5;0;9.882277;9.423939;7003335;8.66467e+008
2707.722;3.10923;-3.923992;7180.729;742.0101;5;5;0;9.79285;9.342523;6590076;8.146741e+008
2713.546;3.080141;-3.910505;6734.677;695.918;5;5;0;9.701232;9.259041;6180713;7.634306e+008
2719.546;3.050194;-3.897006;6294.324;650.4147;5;5;0;9.606912;9.173025;5776582;7.128995e+008
2725.546;3.020194;-3.883651;5873.26;606.9048;5;5;0;9.512424;9.086781;5390153;6.646361e+008
2731.546;2.990141;-3.870439;5469.515;565.1843;5;5;0;9.417767;9.000309;5019618;6.184121e+008
2737.546;2.960087;-3.857604;5078.786;524.8089;5;5;0;9.32311;8.913762;4661028;5.737374e+008
2743.546;2.92998;-3.845067;4700.345;485.7032;5;5;0;9.228285;8.826986;4313716;5.305253e+008
2749.546;2.900141;-3.833267;4340.334;448.5021;5;5;0;9.134303;8.740907;3983318;4.894696e+008
2755.546;2.870194;-3.821536;3988.966;412.1939;5;5;0;9.039983;8.654444;3660852;4.494562e+008
2761.546;2.840195;-3.80985;3640.35;376.1703;5;5;0;8.945495;8.567752;3340912;4.098206e+008
2767.546;2.810195;-3.798425;3299.99;340.9996;5;5;0;8.851007;8.480985;3028548;3.711815e+008
2773.546;2.780195;-3.78739;2971.1;307.0143;5;5;0;8.756518;8.394142;2726711;3.338981e+008
2779.546;2.750195;-3.776788;2654.821;274.3321;5;5;0;8.66203;8.307224;2436448;2.980948e+008
2785.546;2.720248;-3.766937;2354.505;243.2994;5;5;0;8.56771;8.220385;2160835;2.641445e+008
2791.546;2.690195;-3.757512;2069.271;213.8251;5;5;0;8.473054;8.13316;1899062;2.319426e+008
2797.546;2.660141;-3.748622;1798.551;185.8506;5;5;0;8.378397;8.045859;1650610;2.014219e+008
2803.546;2.630088;-3.740392;1542.445;159.3863;5;5;0;8.28374;7.958482;1415570;1.725894e+008
2809.546;2.600034;-3.733076;1304.347;134.7828;5;5;0;8.189084;7.871028;1197057;1.458202e+008
2815.546;2.570141;-3.726949;1082.698;111.879;5;5;0;8.094932;7.783965;993639.9;1.209355e+008
2821.546;2.540195;-3.721837;883.6769;91.31346;5;5;0;8.000613;7.696672;810989.7;9.86191e+007
2827.546;2.510141;-3.717718;707.4942;73.10788;5;5;0;7.905957;7.608989;649299;7.888776e+007
2833.546;2.480088;-3.714704;550.6426;56.89985;5;5;0;7.811299;7.521229;505349.3;6.134447e+007
2839.546;2.450034;-3.712802;414.6455;42.84679;5;5;0;7.716643;7.433392;380538.7;4.615313e+007
2845.546;2.420034;-3.711566;304.6476;31.48032;5;5;0;7.622155;7.345634;279588.7;3.38798e+007
2851.546;2.390141;-3.71047;214.952;22.21175;5;5;0;7.528005;7.258114;197271;2.388385e+007
2857.546;2.360195;-3.70977;144.7566;14.95821;5;5;0;7.433685;7.170359;132849.6;1.607016e+007
2863.546;2.330195;-3.709445;96.64185;9.986344;5;5;0;7.339197;7.08237;88692.53;1.071926e+007
2868.694;2.304267;-3.708802;72.75927;7.518473;5;5;0;7.257533;7.00626;66774.43;8064129