File: Ensayos/Graficos/EspC/EspC30ext125.raw
"Test Type";"Manual"
"Method Name:";"C:\INSTRON\user\template\CYCLE.MTM"
"Name:";""
"Operator ID:";""
"Company:";""
"Lab name:";""
"Test date:";"04/04/2017"
"Temperature:";""
"Humidity:";""
"Note 1:";""
"Note 2:";""
"Note 3:";""
"Geometry:";"Rectangular"
"Specimen";1
"Specimen name:";""
"Width:";0.250000;"in"
"Thickness:";0.060000;"in"
"Length:";1.250000;"in"
"Diameter:";0.039370;"in"
"Inner diameter:";0.019685;"in"
"Outer diameter:";0.039370;"in"
"Wall thickness:";0.019685;"in"
"Area:";0.015000;"in*in"
"Linear density:";1.000000;"den"
"Sled weight:";2.204623;"lbf"
"Loading span:";0.000000;"mm"
"Support span:";1.000000;"mm"
"Span ratio:";"2"
"Fixture type:";"3-point"
"Comment:";""
"Included"
"Final Width:";0.250000;"in"
"Final Thickness:";0.060000;"in"
"Final Length:";1.250000;"in"
"Final Diameter:";0.039370;"in"
"Final Inner diameter:";0.019685;"in"
"Final Outer diameter:";0.039370;"in"
"Final Wall thickness:";0.019685;"in"
"Final Area:";0.015000;"in*in"
"Final Linear density:";1.000000;"den"
"Time sec";"Extension mm";"Strain 1 %";"Load N";"Stress MPa";"Cycle Count ";"Total Cycle Count ";"Repetitions Count ";"Strain [Exten.] %";"True strain %";"Tenacity gf/tex";"True stress Pa"
0;0.5882139;-0.01366995;109.6712;11.33272;0;0;0;1.852642;1.83569;100650.2;1.154267e+007
4;0.6013925;-0.01370208;109.7619;11.34208;0;0;0;1.89415;1.876434;100733.4;1.155692e+007
8;0.6148389;-0.01367281;109.8052;11.34655;0;0;0;1.9365;1.917989;100773.1;1.156628e+007
12;0.6281782;-0.01358847;109.8997;11.35633;0;0;0;1.978514;1.959196;100859.9;1.158101e+007
16;0.6414638;-0.01362711;109.7044;11.33615;0;0;0;2.020359;2.00022;100680.6;1.156518e+007
20;0.6549103;-0.01352165;109.7946;11.34546;0;0;0;2.06271;2.041724;100763.4;1.157949e+007
24;0.6682496;-0.01373919;109.6934;11.33501;0;0;0;2.104723;2.08288;100670.5;1.157358e+007
28;0.6814817;-0.01356825;110.0052;11.36723;0;0;0;2.146399;2.123688;100956.7;1.161121e+007
32;0.6949281;-0.01371654;109.8397;11.35012;0;0;0;2.18875;2.165141;100804.8;1.159855e+007
36;0.7081603;-0.01369895;109.805;11.34654;0;0;0;2.230426;2.205916;100773;1.159962e+007
40;0.721446;-0.01374915;110.3377;11.40159;0;0;0;2.272271;2.246839;101261.8;1.166066e+007
44;0.7347853;-0.01377682;110.4421;11.41237;0;0;0;2.314284;2.287911;101357.6;1.167648e+007
48;0.7480709;-0.01387734;110.5314;11.4216;0;0;0;2.356129;2.3288;101439.6;1.169071e+007
52;0.7615174;-0.01389164;110.6059;11.4293;0;0;0;2.39848;2.370168;101508;1.170343e+007
56;0.7747495;-0.01379947;110.6593;11.43482;0;0;0;2.440156;2.41086;101557;1.171384e+007
60;0.7881424;-0.01379069;110.5853;11.42717;0;0;0;2.482338;2.452029;101489;1.171083e+007
64;0.8015352;-0.01377207;110.8546;11.455;0;0;0;2.52452;2.493181;101736.2;1.174419e+007
68;0.8148209;-0.01371008;110.5176;11.42017;0;0;0;2.566365;2.533987;101426.9;1.171326e+007
72;0.8282674;-0.01372846;110.4428;11.41245;0;0;0;2.608716;2.57527;101358.3;1.171017e+007
76;0.841553;-0.01366074;110.5551;11.42405;0;0;0;2.650561;2.616042;101461.4;1.172685e+007
80;0.8548387;-0.01372505;110.6769;11.43663;0;0;0;2.692405;2.656798;101573.1;1.174455e+007
84.00001;0.8682316;-0.01380801;110.6497;11.43382;0;0;0;2.734588;2.697866;101548.1;1.174649e+007
88.00001;0.8815173;-0.01392029;110.7616;11.44539;0;0;0;2.776432;2.738588;101650.9;1.176317e+007
92.00001;0.8947495;-0.01432491;115.9957;11.98624;0;0;0;2.818109;2.77913;106454.4;1.232403e+007
96.00001;0.9081422;-0.0177384;167.1725;17.27453;0;0;0;2.860291;2.820148;153421.7;1.776863e+007
100;0.921428;-0.02217379;234.1161;24.19204;0;0;0;2.902135;2.860821;214858.8;2.489413e+007
104;0.9348209;-0.0273725;313.0705;32.35069;0;0;0;2.944318;2.901805;287318.8;3.330319e+007
108;0.948053;-0.03244432;403.288;41.67318;0;0;0;2.985994;2.942281;370115.4;4.291754e+007
112;0.9614994;-0.03809316;502.5019;51.9253;0;0;0;3.028345;2.983395;461168.4;5.349778e+007
116;0.9748922;-0.04414455;605.8219;62.60172;0;0;0;3.070527;3.024329;555989.8;6.452392e+007
120;0.9881243;-0.05039443;713.1886;73.6963;0;0;0;3.112203;3.064756;654525;7.598989e+007
124;1.001571;-0.05735015;825.7657;85.32929;0;0;0;3.154553;3.10582;757842;8.802105e+007
128;1.01491;-0.06446281;941.7142;97.31066;0;0;0;3.196567;3.14654;864253.1;1.004213e+008
132;1.028142;-0.07224667;1058.653;109.3943;0;0;0;3.238243;3.186917;971572.9;1.129368e+008
136;1.041535;-0.08105769;1178.726;121.8019;0;0;0;3.280425;3.227768;1081769;1.257975e+008
140;1.054767;-0.09023871;1295.037;133.8207;0;0;0;3.322101;3.268112;1188513;1.382664e+008
144;1.068106;-0.1002508;1409.713;145.6706;0;0;0;3.364115;3.308766;1293756;1.505711e+008
148;1.081446;-0.1109625;1522.769;157.3531;0;0;0;3.406128;3.349404;1397513;1.627127e+008
152;1.094785;-0.1222605;1636.221;169.0765;0;0;0;3.448142;3.390025;1501633;1.749065e+008
156;1.108178;-0.1339488;1749.314;180.7628;0;0;0;3.490324;3.430793;1605424;1.87072e+008
160;1.12141;-0.1463448;1860.104;192.2111;0;0;0;3.532;3.471056;1707100;1.99e+008
164;1.134856;-0.1598932;1973.606;203.9397;0;0;0;3.574351;3.511953;1811267;2.112293e+008
168;1.148249;-0.1734703;2086.008;215.5546;0;0;0;3.616533;3.552672;1914422;2.233502e+008
172;1.161481;-0.1872635;2197.831;227.1096;0;0;0;3.658209;3.592885;2017047;2.354178e+008
176;1.174981;-0.2017868;2313.955;239.1091;0;0;0;3.700729;3.633896;2123620;2.479579e+008
180;1.188267;-0.2156614;2433.784;251.4916;0;0;0;3.742574;3.674239;2233593;2.609038e+008
184;1.201446;-0.2303037;2553.921;263.9057;0;0;0;3.784081;3.714241;2343847;2.738921e+008
188;1.214838;-0.244589;2678.955;276.8259;0;0;0;3.826263;3.754877;2458597;2.87418e+008
192;1.228071;-0.2598343;2804.404;289.789;0;0;0;3.867939;3.795009;2573727;3.009979e+008
196;1.241463;-0.2752124;2936.539;303.4429;0;0;0;3.910121;3.835612;2694993;3.153079e+008
200;1.254696;-0.2897634;3069.692;317.2022;0;0;0;3.951797;3.875711;2817194;3.297374e+008
204;1.268142;-0.3056917;3207.692;331.4622;0;0;0;3.994148;3.916444;2943842;3.447013e+008
208;1.281535;-0.32292;3348.28;345.9896;0;0;0;4.036331;3.956998;3072866;3.599549e+008
212;1.294767;-0.3403474;3488.325;360.4609;0;0;0;4.078006;3.997049;3201391;3.751605e+008
216;1.308213;-0.3582202;3630.296;375.1313;0;0;0;4.120357;4.037732;3331684;3.905881e+008
220;1.321606;-0.376832;3773.395;389.9182;0;0;0;4.162539;4.078237;3463013;4.061487e+008
224;1.334838;-0.3960285;3913.98;404.4454;0;0;0;4.204216;4.11824;3592034;4.214491e+008
228;1.348285;-0.4169158;4055.181;419.0362;0;0;0;4.246566;4.158874;3721621;4.368309e+008
232;1.361517;-0.4383035;4193.387;433.3176;0;0;0;4.288242;4.198844;3848459;4.518993e+008
236;1.374803;-0.4597951;4330.74;447.5107;0;0;0;4.330087;4.23896;3974513;4.668883e+008
240;1.388142;-0.4825152;4468.078;461.7023;0;0;0;4.372101;4.279222;4100554;4.818884e+008
244;1.401428;-0.5068398;4602.43;475.5854;0;0;0;4.413945;4.319305;4223855;4.965774e+008
248;1.414767;-0.5326369;4737.192;489.5109;0;0;0;4.455959;4.359535;4347533;5.113233e+008
252;1.428053;-0.5586695;4867.711;502.9978;0;0;0;4.497804;4.399587;4467316;5.256217e+008
256;1.441445;-0.5856667;4996.861;516.3433;0;0;0;4.539986;4.439945;4585842;5.397853e+008
260;1.454892;-0.6141677;5126.67;529.757;0;0;0;4.582337;4.480449;4704974;5.540322e+008
264;1.468071;-0.643435;5248.949;542.3925;0;0;0;4.623844;4.52013;4817195;5.674719e+008
268;1.481571;-0.674118;5371.176;555.0226;0;0;0;4.666364;4.560762;4929368;5.80922e+008
272;1.49491;-0.7048798;5489.281;567.2269;0;0;0;4.708377;4.600894;5037758;5.93934e+008
276;1.508195;-0.7357138;5602.94;578.9716;0;0;0;4.750222;4.640849;5142068;6.06474e+008
280;1.521642;-0.7677353;5716.349;590.6906;0;0;0;4.792573;4.681272;5246149;6.189999e+008
284;1.534874;-0.8001441;5823.925;601.8068;0;0;0;4.834249;4.721034;5344876;6.308996e+008
288;1.548106;-0.8324777;5928.762;612.6399;0;0;0;4.875925;4.76078;5441089;6.425118e+008
292;1.561499;-0.8654905;6033.586;623.4718;0;0;0;4.918108;4.800993;5537291;6.541348e+008
296;1.574731;-0.8986591;6134.474;633.897;0;0;0;4.959783;4.840707;5629881;6.653369e+008
300;1.588124;-0.9316019;6235.051;644.2899;0;0;0;5.001965;4.880888;5722184;6.76517e+008
304;1.601356;-0.964019;6329.894;654.0903;0;0;0;5.043642;4.920571;5809226;6.870803e+008
308;1.614803;-0.9979373;6425.064;663.9246;0;0;0;5.085992;4.96088;5896568;6.976917e+008
310.794;1.610892;-0.9991127;6333.228;654.4349;0;0;0;5.073675;4.949158;5812286;6.876388e+008
314.794;1.597552;-0.9844321;6126.473;633.0701;0;0;0;5.031662;4.909166;5622538;6.649241e+008
318.794;1.58416;-0.9679191;5931.311;612.9034;0;0;0;4.98948;4.868996;5443429;6.434841e+008
322.794;1.570767;-0.9505577;5743.427;593.4886;0;0;0;4.947298;4.828811;5270999;6.228503e+008
326.794;1.557481;-0.9327589;5562.431;574.7857;0;0;0;4.905452;4.78893;5104891;6.029815e+008
330.794;1.544035;-0.912864;5386.99;556.6567;0;0;0;4.863101;4.748552;4943881;5.837275e+008
334.794;1.530695;-0.8919922;5223.795;539.7932;0;0;0;4.821088;4.708479;4794110;5.658171e+008
338.794;1.517463;-0.8705528;5066.29;523.5177;0;0;0;4.779412;4.668711;4649561;5.485388e+008
342.794;1.504124;-0.848168;4910.71;507.4411;0;0;0;4.737398;4.628606;4506778;5.314806e+008
346.794;1.490838;-0.8251363;4757.754;491.6355;0;0;0;4.695554;4.588646;4366403;5.147205e+008
350.794;1.477553;-0.801959;4608.97;476.2612;0;0;0;4.653709;4.54867;4229858;4.98425e+008
354.794;1.46416;-0.7780592;4460.493;460.9185;0;0;0;4.611526;4.508356;4093593;4.821739e+008
358.794;1.450874;-0.7534232;4313.971;445.7779;0;0;0;4.569682;4.468348;3959124;4.661485e+008
362.794;1.437481;-0.7283326;4168.105;430.7051;0;0;0;4.5275;4.428001;3825256;4.502053e+008
366.794;1.424196;-0.7034312;4025.478;415.9669;0;0;0;4.485655;4.38796;3694360;4.346257e+008
370.794;1.410803;-0.6781512;3881.445;401.0834;0;0;0;4.443473;4.347581;3562175;4.189055e+008
374.794;1.39741;-0.653056;3739.665;386.4328;0;0;0;4.401291;4.307185;3432057;4.034408e+008
378.794;1.384124;-0.6285518;3601.137;372.1182;0;0;0;4.359446;4.267097;3304924;3.883405e+008
382.794;1.370678;-0.6037048;3461.955;357.7361;0;0;0;4.317095;4.226506;3177191;3.731799e+008
386.794;1.357392;-0.580049;3324.294;343.511;0;0;0;4.27525;4.186385;3050853;3.58197e+008
390.794;1.34416;-0.5570909;3190.487;329.6844;0;0;0;4.233574;4.14641;2928053;3.436418e+008
394.794;1.330821;-0.5343376;3054.516;315.6339;0;0;0;4.191561;4.106095;2803265;3.288639e+008
398.794;1.317535;-0.5125244;2920.326;301.7677;0;0;0;4.149716;4.065925;2680114;3.142902e+008
402.794;1.304249;-0.4909594;2786.108;287.8984;0;0;0;4.107872;4.02574;2556936;2.997249e+008
406.794;1.290856;-0.4699707;2651.405;273.979;0;0;0;4.065689;3.985214;2433312;2.851182e+008
410.794;1.277517;-0.4497782;2517.408;260.1326;0;0;0;4.023675;3.944834;2310337;2.705995e+008
414.794;1.264178;-0.4305692;2383.687;246.3148;0;0;0;3.981662;3.904437;2187616;2.561222e+008
418.794;1.250839;-0.4123846;2252.665;232.7759;0;0;0;3.939649;3.864025;2067371;2.419464e+008
422.794;1.237446;-0.3950681;2125.816;219.668;0;0;0;3.897466;3.823433;1950956;2.282295e+008
426.794;1.224053;-0.3769621;2006.901;207.3801;0;0;0;3.855284;3.782824;1841822;2.153752e+008
430.794;1.210821;-0.3590328;1895.282;195.8462;0;0;0;3.813608;3.742688;1739385;2.03315e+008
434.794;1.197374;-0.3410378;1784.309;184.379;0;0;0;3.771257;3.701884;1637540;1.913324e+008
438.794;1.184089;-0.3239563;1676.951;173.2853;0;0;0;3.729413;3.661552;1539013;1.797478e+008
442.794;1.170856;-0.3065852;1574.223;162.67;0;0;0;3.687737;3.621367;1444735;1.686689e+008
446.794;1.157517;-0.2894257;1474.497;152.365;0;0;0;3.645723;3.580839;1353212;1.579198e+008
450.794;1.144231;-0.2725836;1376.954;142.2855;0;0;0;3.603878;3.540458;1263692;1.474133e+008
454.794;1.130892;-0.2559512;1281.92;132.4653;0;0;0;3.561865;3.499898;1176475;1.371835e+008
458.794;1.117553;-0.23958;1188.861;122.8492;0;0;0;3.519852;3.459321;1091071;1.271733e+008
462.794;1.10416;-0.2241957;1097.716;113.4309;0;0;0;3.477669;3.418565;1007423;1.173756e+008
466.794;1.090821;-0.209908;1006.679;104.0237;0;0;0;3.435656;3.377955;923874.3;1.075976e+008
470.794;1.077535;-0.1972884;917.1858;94.77605;0;0;0;3.393811;3.337492;841742.3;9.799257e+007
474.794;1.064089;-0.1848106;828.239;85.58487;0;0;0;3.35146;3.296523;760111.9;8.845321e+007
478.794;1.050696;-0.1737257;741.9986;76.67335;0;0;0;3.309278;3.2557;680965.3;7.921068e+007
482.794;1.037517;-0.1637691;658.5228;68.04749;0;0;0;3.267771;3.215514;604355.7;7.027112e+007
486.794;1.024017;-0.1547952;577.2009;59.64421;0;0;0;3.225251;3.174331;529723.1;6.156789e+007
490.794;1.010785;-0.1465415;500.5219;51.7207;0;0;0;3.183575;3.133949;459351.3;5.336727e+007
494.794;0.9975529;-0.1390353;429.3359;44.3648;0;0;0;3.141899;3.093551;394020.7;4.57587e+007
498.794;0.98416;-0.1320487;359.7425;37.17347;0;0;0;3.099716;3.052646;330151.8;3.832574e+007
502.794;0.9708744;-0.1257669;294.3461;30.41582;0;0;0;3.057872;3.012051;270134.5;3.13459e+007
506.794;0.9575352;-0.1204582;232.2677;24.00105;0;0;0;3.015859;2.971276;213162.5;2.472488e+007
510.794;0.9441958;-0.1129079;177.1354;18.30403;0;0;0;2.973845;2.930484;162565.1;1.884837e+007
514.794;0.930803;-0.1082585;130.1334;13.44714;0;0;0;2.931663;2.889512;119429.2;1.384137e+007
517.65;0.9212137;-0.1078124;109.0587;11.26942;1;1;0;2.90146;2.860165;100088;1.15964e+007
521.65;0.9346066;-0.1110213;156.609;16.18296;1;1;0;2.943643;2.901149;143727;1.665933e+007
525.65;0.9478923;-0.1150408;221.7666;22.91593;1;1;0;2.985487;2.941789;203525.1;2.360008e+007
529.65;0.9613387;-0.1206044;300.7369;31.07621;1;1;0;3.027838;2.982904;275999.6;3.201714e+007
533.65;0.974678;-0.1259543;386.8946;39.97919;1;1;0;3.069852;3.023675;355070.4;4.120649e+007
537.65;0.9879636;-0.131769;478.7788;49.47391;1;1;0;3.111696;3.064265;439396.6;5.101338e+007
541.65;1.00141;-0.1396426;575.2806;59.44578;1;1;0;3.154047;3.105329;527960.6;6.132073e+007
545.65;1.014696;-0.1479159;675.645;69.81679;1;1;0;3.195892;3.145886;620069.6;7.204806e+007
549.65;1.027928;-0.1563172;779.233;80.5209;1;1;0;3.237568;3.186263;715136.9;8.312783e+007
553.65;1.041267;-0.165215;888.8764;91.85075;1;1;0;3.279582;3.226951;815761.5;9.486307e+007
557.65;1.054553;-0.175253;999.9263;103.3259;1;1;0;3.321426;3.267459;917676.9;1.067578e+008
561.65;1.067946;-0.1858064;1113.705;115.0831;1;1;0;3.363609;3.308277;1022097;1.18954e+008
565.65;1.081178;-0.1969475;1227.116;126.8022;1;1;0;3.405284;3.348588;1126179;1.311202e+008
569.65;1.094571;-0.2087742;1342.828;138.7592;1;1;0;3.447467;3.389373;1232373;1.435429e+008
573.65;1.107964;-0.2214816;1458.197;150.6807;1;1;0;3.489649;3.430141;1338253;1.559389e+008
577.65;1.121249;-0.2344428;1572.993;162.5429;1;1;0;3.531494;3.470567;1443606;1.682831e+008
581.65;1.134696;-0.2481734;1692.107;174.8514;1;1;0;3.573845;3.511465;1552922;1.811003e+008
585.65;1.148035;-0.2622848;1811.3;187.168;1;1;0;3.615858;3.55202;1662311;1.939358e+008
589.65;1.161321;-0.276417;1930.97;199.534;1;1;0;3.657703;3.592397;1772137;2.068323e+008
593.65;1.174767;-0.2910497;2053.064;212.1504;1;1;0;3.700054;3.633245;1884188;2.200001e+008
597.65;1.188053;-0.305793;2176.772;224.9336;1;1;0;3.741899;3.673589;1997721;2.333504e+008
601.65;1.201231;-0.3206765;2301.475;237.8196;1;1;0;3.783406;3.713591;2112166;2.468172e+008
605.65;1.214624;-0.3356393;2430.088;251.1096;1;1;0;3.825588;3.754227;2230200;2.60716e+008
609.65;1.227856;-0.3510167;2558.717;264.4013;1;1;0;3.867264;3.794359;2348249;2.746264e+008
613.65;1.241303;-0.3664666;2694.54;278.4364;1;1;0;3.909615;3.835125;2472900;2.893222e+008
617.65;1.254481;-0.3816915;2830.283;292.4632;1;1;0;3.951122;3.875062;2597477;3.040187e+008
621.65;1.267928;-0.3979452;2972.368;307.1454;1;1;0;3.993473;3.915795;2727875;3.194111e+008
625.65;1.281321;-0.4152225;3116.753;322.0651;1;1;0;4.035655;3.956349;2860383;3.350626e+008
629.65;1.294606;-0.4326504;3258.609;336.7236;1;1;0;4.0775;3.996563;2990571;3.504535e+008
633.65;1.307999;-0.4508372;3401.226;351.4608;1;1;0;4.119682;4.037084;3121457;3.659398e+008
637.65;1.321392;-0.4695143;3543.446;366.1568;1;1;0;4.161865;4.077589;3251979;3.813958e+008
641.65;1.334624;-0.4890286;3682.822;380.5591;1;1;0;4.20354;4.117592;3379890;3.96556e+008
645.65;1.348071;-0.5093765;3823.258;395.0708;1;1;0;4.245892;4.158226;3508775;4.118451e+008
649.65;1.361303;-0.5305478;3961.305;409.3357;1;1;0;4.287568;4.198197;3635467;4.268862e+008
653.65;1.374588;-0.5525915;4098.946;423.5586;1;1;0;4.329412;4.238314;3761786;4.418962e+008
657.65;1.387928;-0.5753354;4236.817;437.8053;1;1;0;4.371426;4.278575;3888316;4.569437e+008
661.65;1.401213;-0.5989092;4372.708;451.8474;1;1;0;4.41327;4.318659;4013029;4.717886e+008
665.65;1.414606;-0.6238743;4509.738;466.0072;1;1;0;4.455453;4.35905;4138788;4.867699e+008
669.65;1.427838;-0.6490119;4643.341;479.8128;1;1;0;4.497128;4.398941;4261401;5.013906e+008
673.65;1.441285;-0.6744284;4777.809;493.7079;1;1;0;4.539479;4.439461;4384808;5.161196e+008
677.65;1.454678;-0.7005253;4911.488;507.5215;1;1;0;4.581662;4.479804;4507492;5.307744e+008
681.65;1.46791;-0.7261422;5040.733;520.8768;1;1;0;4.623338;4.519646;4626105;5.449586e+008
685.65;1.48141;-0.7525153;5170.072;534.2419;1;1;0;4.665857;4.560278;4744806;5.591688e+008
689.65;1.494695;-0.7786302;5295.652;547.2184;1;1;0;4.707702;4.600249;4860056;5.729798e+008
693.65;1.507981;-0.8046482;5419.227;559.9879;1;1;0;4.749547;4.640205;4973466;5.865848e+008
697.65;1.521374;-0.8305486;5543.417;572.8209;1;1;0;4.791729;4.680466;5087441;6.002689e+008
701.65;1.53466;-0.8562741;5663.797;585.2602;1;1;0;4.833574;4.72039;5197919;6.135492e+008
705.65;1.547892;-0.8822852;5782.932;597.5708;1;1;0;4.87525;4.760136;5307254;6.267039e+008
709.65;1.561231;-0.9078796;5902.727;609.9496;1;1;0;4.917264;4.800189;5417196;6.399425e+008
713.65;1.574517;-0.934163;6020.306;622.0995;1;1;0;4.959108;4.840064;5525103;6.529501e+008
717.65;1.587963;-0.9601574;6137.805;634.2411;1;1;0;5.001459;4.880406;5632937;6.659624e+008
721.65;1.601195;-0.9870142;6247.987;645.6266;1;1;0;5.043135;4.920089;5734057;6.781865e+008
725.65;1.614642;-1.016615;6356.249;656.8137;1;1;0;5.085486;4.960399;5833414;6.902159e+008
728.194;1.609874;-1.015624;6261.731;647.0469;1;1;0;5.070469;4.946107;5746670;6.798552e+008
732.194;1.596481;-1.000732;6055.809;625.7682;1;1;0;5.028287;4.905953;5557686;6.572336e+008
736.194;1.583195;-0.9842338;5863.998;605.9477;1;1;0;4.986442;4.866103;5381653;6.361629e+008
740.194;1.569856;-0.9667975;5677.224;586.6476;1;1;0;4.944428;4.826077;5210242;6.15654e+008
744.194;1.556517;-0.9486093;5495.891;567.9099;1;1;0;4.902415;4.786035;5043824;5.957512e+008
748.194;1.543124;-0.9294205;5319.377;549.67;1;1;0;4.860233;4.745817;4881829;5.763853e+008
752.194;1.529731;-0.9084297;5156.211;532.8096;1;1;0;4.818051;4.705581;4732085;5.584806e+008
756.194;1.516445;-0.8870715;4999.118;516.5766;1;1;0;4.776206;4.665652;4587914;5.412493e+008
760.194;1.503053;-0.8645371;4843.796;500.5266;1;1;0;4.734024;4.625385;4445368;5.242216e+008
764.194;1.48966;-0.8414634;4691.31;484.7697;1;1;0;4.691842;4.585101;4305425;5.075143e+008
768.194;1.476428;-0.8181378;4544.798;469.6301;1;1;0;4.650166;4.545285;4170964;4.914687e+008
772.194;1.463035;-0.7940277;4397.607;454.4203;1;1;0;4.607984;4.504969;4035880;4.753599e+008
776.194;1.449749;-0.7697521;4252.696;439.4462;1;1;0;4.566139;4.464959;3902889;4.595119e+008
780.194;1.436517;-0.745474;4110.225;424.7241;1;1;0;4.524463;4.425095;3772137;4.439405e+008
784.194;1.423124;-0.7205901;3967.57;409.983;1;1;0;4.48228;4.384731;3641216;4.283596e+008
788.194;1.409838;-0.6960182;3826.042;395.3585;1;1;0;4.440436;4.344673;3511329;4.129141e+008
792.194;1.396499;-0.6710733;3685.557;380.8417;1;1;0;4.398423;4.304438;3382400;3.975927e+008
796.194;1.38316;-0.6467363;3548.597;366.6891;1;1;0;4.356409;4.264186;3256706;3.826636e+008
800.194;1.369767;-0.6224249;3411.361;352.508;1;1;0;4.314227;4.223757;3130758;3.67716e+008
804.194;1.356374;-0.5985603;3275.217;338.4398;1;1;0;4.272045;4.183311;3005813;3.528981e+008
808.194;1.343142;-0.5761406;3142.523;324.728;1;1;0;4.230368;4.143334;2884033;3.384652e+008
812.194;1.329696;-0.5531048;3007.501;310.7757;1;1;0;4.188017;4.102694;2760118;3.237911e+008
816.194;1.316356;-0.5311807;2873.668;296.9463;1;1;0;4.146004;4.062362;2637294;3.092577e+008
820.194;1.303124;-0.5102807;2741.837;283.3238;1;1;0;4.104328;4.022336;2516307;2.949523e+008
824.194;1.289731;-0.4894892;2608.221;269.5167;1;1;0;4.062146;3.981809;2393681;2.804648e+008
828.194;1.276446;-0.4695006;2474.885;255.7386;1;1;0;4.020301;3.94159;2271312;2.660201e+008
832.194;1.263213;-0.4504005;2343.596;242.172;1;1;0;3.978625;3.901516;2150822;2.518072e+008
836.194;1.24982;-0.4316191;2211.904;228.5638;1;1;0;3.936442;3.86094;2029963;2.375611e+008
840.194;1.236535;-0.4138353;2084.852;215.4352;1;1;0;3.894598;3.820672;1913362;2.238255e+008
844.194;1.223142;-0.3968247;1962.563;202.7985;1;1;0;3.852416;3.780063;1801131;2.106112e+008
848.194;1.209856;-0.3793189;1848.575;191.0198;1;1;0;3.810571;3.739762;1696520;1.982987e+008
852.194;1.19641;-0.3616024;1738.625;179.6583;1;1;0;3.76822;3.698957;1595614;1.864282e+008
856.194;1.183071;-0.3434933;1631.28;168.5659;1;1;0;3.726207;3.658462;1497098;1.74847e+008
860.194;1.169785;-0.3262016;1528.362;157.931;1;1;0;3.684362;3.618112;1402646;1.637498e+008
864.194;1.156338;-0.3084459;1428.28;147.5892;1;1;0;3.642011;3.577257;1310796;1.529644e+008
868.194;1.142999;-0.2912877;1329.962;137.4297;1;1;0;3.599998;3.536712;1220566;1.423772e+008
872.194;1.129767;-0.2745541;1236.223;127.7433;1;1;0;3.558322;3.496476;1134537;1.322888e+008
876.194;1.116374;-0.2580718;1143.313;118.1425;1;1;0;3.51614;3.455735;1049269;1.222966e+008
880.194;1.103142;-0.2426523;1053.322;108.8435;1;1;0;3.474464;3.415467;966680.5;1.126252e+008
884.194;1.089856;-0.2277635;964.0867;99.6225;1;1;0;3.432619;3.375019;884785.4;1.030422e+008
888.194;1.076517;-0.214297;875.3919;90.45735;1;1;0;3.390605;3.334391;803386.3;9.35244e+007
892.194;1.063178;-0.2019985;788.6179;81.49068;1;1;0;3.348592;3.293747;723749.8;8.421947e+007
896.194;1.049785;-0.1905356;703.3978;72.68459;1;1;0;3.30641;3.252924;645539.5;7.508784e+007
900.194;1.036499;-0.1804392;621.4679;64.21848;1;1;0;3.264565;3.21241;570348.8;6.631494e+007
904.194;1.023053;-0.1711611;541.8639;55.99271;1;1;0;3.222214;3.171389;497292.7;5.779692e+007
908.194;1.009714;-0.1624847;467.2232;48.27983;1;1;0;3.180201;3.130679;428791.6;4.981522e+007
912.194;0.9964815;-0.1552142;397.9313;41.11965;1;1;0;3.138525;3.09028;365199.3;4.24102e+007
916.194;0.9829815;-0.1475851;330.8249;34.1853;1;1;0;3.096005;3.049045;303612.7;3.524368e+007
920.194;0.9696958;-0.142719;267.8275;27.67556;1;1;0;3.05416;3.008449;245797.2;2.852081e+007
924.194;0.9564637;-0.135438;209.9585;21.69576;1;1;0;3.012484;2.968;192688.3;2.234934e+007
928.194;0.9431244;-0.1275358;158.3176;16.35951;1;1;0;2.97047;2.927207;145295.1;1.684547e+007
932.194;0.9298387;-0.123381;115.9993;11.98662;1;1;0;2.928626;2.886561;106457.7;1.233766e+007
936.194;0.916553;-0.1225513;107.9415;11.15397;1;1;0;2.886781;2.845898;99062.7;1.147596e+007
939.0181;0.9204101;-0.12218;108.4317;11.20463;2;2;0;2.898929;2.857705;99512.62;1.152945e+007
943.0181;0.9337494;-0.1263983;138.1138;14.27178;2;2;0;2.940943;2.898527;126753.2;1.469151e+007
947.0181;0.9470352;-0.1310261;200.4741;20.7157;2;2;0;2.982788;2.939168;183984.1;2.133361e+007
951.0181;0.9604816;-0.1353508;275.2542;28.443;2;2;0;3.025139;2.980284;252613.1;2.930344e+007
955.0181;0.9737672;-0.1405704;358.0803;37.0017;2;2;0;3.066983;3.020892;328626.2;3.813654e+007
959.0181;0.9869994;-0.1465834;447.5072;46.2425;2;2;0;3.10866;3.061319;410697.3;4.768002e+007
963.0181;1.000339;-0.154546;541.1766;55.9217;2;2;0;3.150673;3.102058;496661.9;5.768361e+007
967.0181;1.013624;-0.1635881;638.7758;66.00697;2;2;0;3.192518;3.142616;586233.1;6.811425e+007
971.0181;1.027017;-0.1721617;741.9486;76.66818;2;2;0;3.2347;3.183485;680919.4;7.914816e+007
975.0181;1.040249;-0.1812327;848.1891;87.64639;2;2;0;3.276376;3.223847;778421;9.051801e+007
979.0181;1.053696;-0.1911;959.5319;99.15182;2;2;0;3.318727;3.264846;880605.2;1.024424e+008
983.0181;1.067035;-0.2018046;1071.519;110.7239;2;2;0;3.36074;3.305501;983381;1.14445e+008
987.0181;1.080321;-0.2128611;1183.605;122.3061;2;2;0;3.402585;3.345978;1086247;1.264677e+008
991.0181;1.093767;-0.2250149;1297.846;134.1111;2;2;0;3.444936;3.386926;1191092;1.387311e+008
995.0181;1.107106;-0.2373605;1411.917;145.8984;2;2;0;3.486949;3.427533;1295779;1.509858e+008
999.0181;1.120392;-0.2502834;1526.657;157.7549;2;2;0;3.528794;3.467959;1401082;1.633218e+008
1003.018;1.133785;-0.2637468;1645.104;169.9944;2;2;0;3.570976;3.508696;1509785;1.760648e+008
1007.018;1.147017;-0.2778706;1763.823;182.2621;2;2;0;3.612652;3.548926;1618739;1.888465e+008
1011.018;1.160303;-0.2923714;1883.1;194.5874;2;2;0;3.654497;3.589304;1728205;2.016986e+008
1015.018;1.173642;-0.3070077;2004.001;207.0805;2;2;0;3.696511;3.629828;1839161;2.147353e+008
1019.018;1.186928;-0.3218841;2127.775;219.8705;2;2;0;3.738355;3.670173;1952754;2.280901e+008
1023.018;1.200321;-0.3367972;2254.354;232.9504;2;2;0;3.780538;3.710827;2068921;2.417572e+008
1027.018;1.213606;-0.3520422;2379.744;245.9073;2;2;0;3.822382;3.751139;2183997;2.553069e+008
1031.018;1.226999;-0.3679858;2510.048;259.3722;2;2;0;3.864564;3.79176;2303583;2.693958e+008
1035.018;1.240446;-0.3836202;2646.021;273.4228;2;2;0;3.906915;3.832527;2428372;2.841051e+008
1039.018;1.253624;-0.3989417;2782.561;287.5319;2;2;0;3.948423;3.872465;2553681;2.988849e+008
1043.018;1.267124;-0.4158567;2925.949;302.3487;2;2;0;3.990942;3.913362;2685274;3.144152e+008
1047.018;1.280463;-0.4332536;3069.446;317.1768;2;2;0;4.032955;3.953754;2816968;3.299683e+008
1051.018;1.293696;-0.4509204;3210.865;331.79;2;2;0;4.074632;3.993807;2946754;3.453093e+008
1055.018;1.307142;-0.4693845;3352.837;346.4605;2;2;0;4.116982;4.034491;3077048;3.607243e+008
1059.018;1.320374;-0.488338;3493.012;360.9453;2;2;0;4.158659;4.074512;3205693;3.759557e+008
1063.018;1.333606;-0.5073763;3631.601;375.2662;2;2;0;4.200335;4.114516;3332882;3.910286e+008
1067.018;1.346946;-0.5278007;3768.876;389.4513;2;2;0;4.242348;4.154827;3458866;4.059732e+008
1071.018;1.360231;-0.5492932;3906.388;403.6609;2;2;0;4.284193;4.194961;3585067;4.209546e+008
1075.018;1.373678;-0.5719448;4045.3;418.0152;2;2;0;4.326544;4.235564;3712553;4.361008e+008
1079.018;1.38691;-0.5945427;4180.224;431.9574;2;2;0;4.36822;4.275504;3836378;4.508262e+008
1083.018;1.400356;-0.6184822;4316.941;446.0848;2;2;0;4.410571;4.316074;3961850;4.657597e+008
1087.018;1.413749;-0.6435484;4453.453;460.191;2;2;0;4.452753;4.356466;4087132;4.806822e+008
1091.018;1.427035;-0.6684456;4586.858;473.9763;2;2;0;4.494598;4.396519;4209564;4.952796e+008
1095.018;1.440481;-0.6940003;4719.994;487.7336;2;2;0;4.536949;4.437041;4331749;5.098619e+008
1099.018;1.453767;-0.7197232;4852.947;501.4722;2;2;0;4.578794;4.47706;4453766;5.244336e+008
1103.018;1.466999;-0.7453088;4980.701;514.6735;2;2;0;4.620469;4.516904;4571011;5.384538e+008
1107.018;1.480445;-0.7715664;5109.52;527.9847;2;2;0;4.66282;4.557376;4689234;5.526037e+008
1111.018;1.493678;-0.7973866;5233.917;540.8392;2;2;0;4.704496;4.597187;4803399;5.662829e+008
1115.018;1.506963;-0.8232681;5359.036;553.7681;2;2;0;4.746341;4.637144;4918226;5.800519e+008
1119.018;1.520303;-0.8486066;5481.703;566.4437;2;2;0;4.788355;4.677246;5030803;5.935671e+008
1123.018;1.533642;-0.8742486;5604.858;579.1697;2;2;0;4.830368;4.717332;5143828;6.071458e+008
1127.018;1.547035;-0.8996921;5727.981;591.8926;2;2;0;4.87255;4.757562;5256824;6.207328e+008
1131.018;1.560267;-0.9249026;5849.151;604.4135;2;2;0;4.914226;4.797294;5368027;6.341157e+008
1135.018;1.573713;-0.9496439;5971.784;617.0856;2;2;0;4.956577;4.837653;5480572;6.476719e+008
1139.018;1.587106;-0.9744392;6092.771;629.5876;2;2;0;4.998759;4.877835;5591608;6.610592e+008
1143.018;1.600338;-0.9989155;6209.681;641.6683;2;2;0;5.040435;4.917519;5698901;6.740112e+008
1147.018;1.613785;-1.02458;6323.345;653.4136;2;2;0;5.082787;4.95783;5803216;6.866252e+008
1151.018;1.627124;-1.054085;6429.448;664.3776;2;2;0;5.1248;4.997803;5900591;6.984257e+008
1155.018;1.640356;-1.086419;6528.419;674.6046;2;2;0;5.166476;5.037439;5991421;7.094579e+008
1159.018;1.653749;-1.120269;6624.435;684.5264;2;2;0;5.208658;5.077541;6079540;7.20181e+008
1163.018;1.666981;-1.154319;6714.871;693.8714;2;2;0;5.250334;5.117146;6162537;7.30302e+008
1167.018;1.68032;-1.188983;6803.707;703.0511;2;2;0;5.292347;5.157056;6244066;7.40259e+008
1171.018;1.693606;-1.223213;6890.257;711.9946;2;2;0;5.334192;5.196789;6323496;7.499738e+008
1175.018;1.706945;-1.257671;6974.983;720.7497;2;2;0;5.376206;5.236667;6401253;7.594987e+008
1179.018;1.720392;-1.291647;7060.812;729.6187;2;2;0;5.418557;5.276849;6480022;7.691535e+008
1183.018;1.733624;-1.326058;7141.449;737.9512;2;2;0;5.460232;5.316375;6554026;7.782451e+008
1187.018;1.74707;-1.360389;7223.914;746.4727;2;2;0;5.502584;5.356526;6629709;7.875479e+008
1191.018;1.76041;-1.393998;7304.346;754.7839;2;2;0;5.544597;5.39634;6703525;7.966337e+008
1195.018;1.773695;-1.427471;7382.348;762.8442;2;2;0;5.586442;5.435979;6775110;8.0546e+008
1199.018;1.787195;-1.461675;7461.082;770.98;2;2;0;5.628961;5.47624;6847368;8.143782e+008
1203.018;1.800427;-1.495356;7537.134;778.8387;2;2;0;5.670638;5.515688;6917164;8.230039e+008
1207.018;1.81366;-1.528894;7610.241;786.3931;2;2;0;5.712314;5.55512;6984257;8.313143e+008
1211.018;1.827052;-1.562285;7685.229;794.1419;2;2;0;5.754496;5.595014;7053077;8.398408e+008
1215.018;1.840285;-1.595704;7756.64;801.5211;2;2;0;5.796172;5.634415;7118615;8.479786e+008
1219.018;1.853624;-1.628812;7830.086;809.1105;2;2;0;5.838185;5.674119;7186019;8.563479e+008
1223.018;1.866909;-1.660798;7901.28;816.4672;2;2;0;5.88003;5.713647;7251357;8.644757e+008
1227.018;1.880302;-1.694346;7972.789;823.8564;2;2;0;5.922213;5.753479;7316984;8.72647e+008
1231.018;1.893695;-1.727296;8044.342;831.2503;2;2;0;5.964395;5.793295;7382651;8.808294e+008
1235.018;1.906981;-1.759654;8111.783;838.2193;2;2;0;6.006239;5.832777;7444545;8.885647e+008
1239.018;1.920427;-1.792341;8177.147;844.9735;2;2;0;6.04859;5.87272;7504533;8.960825e+008
1243.018;1.933767;-1.824621;8248.275;852.3234;2;2;0;6.090604;5.91233;7569810;9.042351e+008
1247.018;1.947052;-1.856413;8315.777;859.2986;2;2;0;6.132448;5.951764;7631760;9.119947e+008
1251.018;1.960499;-1.889134;8385.03;866.4548;2;2;0;6.174799;5.99166;7695316;9.199567e+008
1255.018;1.973731;-1.92092;8450.235;873.1927;2;2;0;6.216475;6.030904;7755158;9.274745e+008
1259.018;1.986963;-1.95339;8517.789;880.1733;2;2;0;6.258151;6.070133;7817155;9.352559e+008
1263.018;2.000356;-1.986222;8587.401;887.3665;2;2;0;6.300333;6.109824;7881041;9.432736e+008
1265.14;2.007374;-2.004217;8622.219;890.9644;2;2;0;6.322437;6.130615;7912995;9.472951e+008
1269.14;1.994088;-1.993027;8378.609;865.7914;2;2;0;6.280591;6.09125;7689424;9.201682e+008
1273.14;1.980802;-1.978274;8162.526;843.4627;2;2;0;6.238748;6.051871;7491115;8.960842e+008
1277.14;1.967517;-1.962443;7960.107;822.546;2;2;0;6.196903;6.012476;7305345;8.735184e+008
1281.14;1.954177;-1.94665;7765.686;802.4559;2;2;0;6.154889;5.972905;7126917;8.518461e+008
1285.14;1.940838;-1.930334;7578.776;783.1417;2;2;0;6.112876;5.933321;6955381;8.310142e+008
1289.14;1.927445;-1.914042;7397.963;764.4576;2;2;0;6.070694;5.893561;6789440;8.108655e+008
1293.14;1.91416;-1.896499;7231.63;747.27;2;2;0;6.028849;5.854103;6636790;7.923217e+008
1297.14;1.900713;-1.878613;7069.977;730.5657;2;2;0;5.986498;5.814152;6488433;7.74301e+008
1301.14;1.887374;-1.860072;6913.279;714.3736;2;2;0;5.944484;5.774504;6344625;7.568395e+008
1305.14;1.874088;-1.841548;6760.989;698.6369;2;2;0;5.90264;5.735;6204861;7.398749e+008
1309.14;1.860642;-1.822556;6610.752;683.1124;2;2;0;5.860289;5.695001;6066982;7.231447e+008
1313.14;1.847356;-1.803504;6466.738;668.2309;2;2;0;5.818444;5.655465;5934814;7.071115e+008
1317.14;1.830481;-1.779371;6288.869;649.8511;2;2;0;5.765294;5.605225;5771576;6.873169e+008
1321.14;1.810552;-1.750316;6085.978;628.8857;2;2;0;5.702527;5.545861;5585374;6.647481e+008
1325.14;1.79057;-1.720572;5888.82;608.5126;2;2;0;5.639591;5.486303;5404433;6.428302e+008
1329.14;1.770588;-1.689826;5697.676;588.761;2;2;0;5.576655;5.42671;5229012;6.215942e+008
1333.14;1.750606;-1.657832;5513.682;569.7483;2;2;0;5.51372;5.36708;5060152;6.011626e+008
1337.14;1.73057;-1.625484;5333.85;551.1656;2;2;0;5.450615;5.307255;4895112;5.812075e+008
1341.14;1.710535;-1.59232;5156.982;532.8892;2;2;0;5.38751;5.247395;4732793;5.615987e+008
1345.14;1.690552;-1.559181;4986.543;515.2772;2;2;0;5.324574;5.187658;4576373;5.427135e+008
1349.14;1.67057;-1.525702;4821.568;498.2297;2;2;0;5.261639;5.127887;4424969;5.244448e+008
1353.14;1.650588;-1.491601;4659.918;481.5259;2;2;0;5.198703;5.068079;4276615;5.06559e+008
1357.14;1.630606;-1.457109;4499.636;464.9633;2;2;0;5.135767;5.008235;4129517;4.888427e+008
1361.14;1.610624;-1.422796;4350.525;449.5551;2;2;0;5.072832;4.948356;3992671;4.723603e+008
1365.14;1.590535;-1.387728;4203.46;434.3584;2;2;0;5.009558;4.888119;3857702;4.561178e+008
1369.14;1.570499;-1.351459;4056.458;419.1682;2;2;0;4.946454;4.828007;3722793;4.399021e+008
1373.14;1.55041;-1.31437;3910.139;404.0485;2;2;0;4.88318;4.767697;3588509;4.237789e+008
1377.14;1.530428;-1.275313;3766.781;389.2348;2;2;0;4.820244;4.707674;3456943;4.079969e+008
1381.14;1.510445;-1.235224;3625.31;374.6161;2;2;0;4.757308;4.647614;3327109;3.924378e+008
1385.14;1.490517;-1.193751;3483.026;359.9135;2;2;0;4.694541;4.587679;3196529;3.768097e+008
1389.14;1.470588;-1.150695;3341.281;345.2664;2;2;0;4.631774;4.527709;3066442;3.612583e+008
1393.14;1.450606;-1.106384;3197.565;330.4157;2;2;0;4.568839;4.467541;2934548;3.455119e+008
1397.14;1.43057;-1.061826;3051.747;315.3479;2;2;0;4.505733;4.407175;2800725;3.295566e+008
1401.14;1.410535;-1.016858;2903.671;300.0466;2;2;0;4.442629;4.346773;2664828;3.133766e+008
1405.14;1.390499;-0.9728351;2754.965;284.6803;2;2;0;4.379525;4.286335;2528354;2.971479e+008
1409.14;1.37041;-0.9300178;2605.847;269.2714;2;2;0;4.316252;4.225698;2391502;2.808938e+008
1413.14;1.350428;-0.8885335;2458.338;254.0288;2;2;0;4.253316;4.165348;2256127;2.648334e+008
1417.14;1.330499;-0.8493192;2309.688;238.6683;2;2;0;4.190549;4.105124;2119704;2.486698e+008
1421.14;1.310517;-0.8111366;2159.716;223.1711;2;2;0;4.127613;4.0447;1982068;2.323828e+008
1425.14;1.290588;-0.7729191;2007.63;207.4556;2;2;0;4.064846;3.984403;1842492;2.158883e+008
1429.14;1.270606;-0.734193;1853.225;191.5003;2;2;0;4.00191;3.923907;1700787;1.99164e+008
1433.14;1.250624;-0.6963839;1699.707;175.6367;2;2;0;3.938974;3.863375;1559897;1.82555e+008
1437.14;1.230589;-0.6601273;1547.275;159.8855;2;2;0;3.875869;3.802644;1420004;1.660824e+008
1441.14;1.210553;-0.6258532;1404.665;145.149;2;2;0;3.812765;3.741875;1289124;1.506832e+008
1445.14;1.190571;-0.591426;1268.608;131.0898;2;2;0;3.749829;3.681232;1164258;1.360054e+008
1449.14;1.170535;-0.5577173;1137.801;117.573;2;2;0;3.686724;3.62039;1044210;1.219076e+008
1453.14;1.150606;-0.5233826;1013.309;104.7088;2;2;0;3.623957;3.559837;929958.7;1.085034e+008
1457.14;1.130624;-0.4897405;892.3;92.20452;2;2;0;3.561021;3.499083;818903.5;9.548794e+007
1461.14;1.110589;-0.4571861;775.0447;80.08812;2;2;0;3.497917;3.43813;711293.1;8.288953e+007
1465.14;1.090553;-0.4266191;662.86;68.49567;2;2;0;3.434812;3.37714;608336.2;7.084837e+007
1469.14;1.070517;-0.3979304;554.0486;57.2518;2;2;0;3.371707;3.316112;508475.1;5.918217e+007
1473.14;1.050481;-0.3735359;450.3742;46.53876;2;2;0;3.308603;3.255047;413328.4;4.807854e+007
1477.14;1.030446;-0.3532435;355.2019;36.70427;2;2;0;3.245498;3.193944;325984.6;3.789551e+007
1481.14;1.010464;-0.3357007;270.1728;27.91791;2;2;0;3.182563;3.132969;247949.6;2.880642e+007
1485.14;0.990535;-0.3226763;195.7321;20.22569;2;2;0;3.119795;3.072119;179632.1;2.085669e+007
1489.14;0.9706066;-0.3090822;132.1944;13.66012;2;2;0;3.057029;3.011232;121320.7;1.407771e+007
1492.494;0.9538387;-0.3041855;106.595;11.01484;2;2;0;3.004216;2.959974;97827;1.134575e+007
1495.496;0.9686244;-0.3079375;140.8182;14.55124;3;3;0;3.050786;3.005175;129235.1;1.499517e+007
1499.496;0.98866;-0.3141583;238.4453;24.63939;3;3;0;3.11389;3.066392;218831.9;2.540664e+007
1503.496;1.008749;-0.3243969;359.2749;37.12514;3;3;0;3.177163;3.127736;329722.6;3.830467e+007
1507.496;1.028731;-0.3380916;489.5383;50.58572;3;3;0;3.240099;3.188715;449271.1;5.222475e+007
1511.496;1.048714;-0.3528231;633.4595;65.45761;3;3;0;3.303035;3.249657;581354;6.76197e+007
1515.496;1.068696;-0.3700075;785.1709;81.13449;3;3;0;3.365971;3.310562;720586.4;8.386545e+007
1519.496;1.088731;-0.3899417;943.0236;97.44596;3;3;0;3.429075;3.371593;865454.8;1.007875e+008
1523.496;1.108714;-0.4110393;1104.077;114.0882;3;3;0;3.492011;3.432424;1013261;1.180722e+008
1527.496;1.128749;-0.4328547;1269.686;131.2011;3;3;0;3.555116;3.49338;1165248;1.358655e+008
1531.496;1.148785;-0.4559548;1440.87;148.8902;3;3;0;3.618221;3.5543;1322350;1.542773e+008
1535.496;1.168821;-0.480677;1615.415;166.9266;3;3;0;3.681325;3.615183;1482539;1.730717e+008
1539.496;1.188856;-0.5057903;1794.122;185.393;3;3;0;3.744429;3.676028;1646546;1.923349e+008
1543.496;1.208839;-0.531855;1974.123;203.9931;3;3;0;3.807366;3.736674;1811740;2.117598e+008
1547.496;1.228767;-0.5578449;2156.355;222.8237;3;3;0;3.870132;3.797121;1978983;2.314473e+008
1551.496;1.248696;-0.5842919;2345.328;242.3511;3;3;0;3.9329;3.857531;2152413;2.518825e+008
1555.496;1.268678;-0.6124607;2542.629;262.7389;3;3;0;3.995835;3.918067;2333484;2.732375e+008
1559.496;1.288713;-0.6415118;2743.805;283.5271;3;3;0;4.05894;3.978728;2518112;2.950353e+008
1563.496;1.308749;-0.6706221;2942.707;304.0803;3;3;0;4.122045;4.039353;2700653;3.166146e+008
1567.496;1.328785;-0.7014279;3140.347;324.5031;3;3;0;4.185149;4.099941;2882036;3.380841e+008
1571.496;1.348874;-0.7327659;3332.749;344.3848;3;3;0;4.248423;4.160654;3058613;3.590157e+008
1575.496;1.36891;-0.7655593;3525.597;364.3125;3;3;0;4.311527;4.221169;3235598;3.800199e+008
1579.496;1.388838;-0.7997143;3715.505;383.9363;3;3;0;4.374294;4.281324;3409885;4.007308e+008
1583.496;1.408767;-0.8343683;3903.864;403.4001;3;3;0;4.437061;4.341442;3582750;4.212992e+008
1587.496;1.428696;-0.8708248;4090.47;422.6828;3;3;0;4.499828;4.401524;3754007;4.417028e+008
1591.496;1.448624;-0.9078931;4273.665;441.6129;3;3;0;4.562595;4.461571;3922133;4.617619e+008
1595.496;1.468606;-0.9462188;4453.423;460.188;3;3;0;4.625531;4.521742;4087105;4.814741e+008
1599.496;1.488695;-0.9849769;4628.872;478.3177;3;3;0;4.688805;4.5822;4248123;5.007451e+008
1603.496;1.508731;-1.024554;4801.417;496.1474;3;3;0;4.751909;4.64246;4406475;5.197239e+008
1607.496;1.528767;-1.06429;4968.376;513.3998;3;3;0;4.815014;4.702684;4559700;5.381201e+008
1611.496;1.548749;-1.10458;5131.632;530.2697;3;3;0;4.87795;4.76271;4709528;5.56136e+008
1615.496;1.568678;-1.144976;5291.248;546.7634;3;3;0;4.940717;4.82254;4856015;5.737774e+008
1619.496;1.588713;-1.184077;5448.242;562.9862;3;3;0;5.003821;4.882656;5000095;5.91157e+008
1623.496;1.608749;-1.223088;5601.226;578.7946;3;3;0;5.066926;4.942735;5140495;6.081216e+008
1627.496;1.628731;-1.261675;5752.273;594.4027;3;3;0;5.129862;5.002618;5279118;6.248948e+008
1631.496;1.64882;-1.300961;5903.564;610.0361;3;3;0;5.193135;5.062786;5417964;6.417162e+008
1635.496;1.668856;-1.340359;6052.629;625.4395;3;3;0;5.25624;5.122757;5554767;6.583141e+008
1639.496;1.688838;-1.379441;6199.775;640.6447;3;3;0;5.319176;5.182532;5689810;6.747217e+008
1643.496;1.708874;-1.418252;6347.404;655.8997;3;3;0;5.38228;5.242431;5825296;6.912021e+008
1647.496;1.728802;-1.458963;6494.743;671.1248;3;3;0;5.445047;5.301975;5960516;7.076679e+008
1651.496;1.748731;-1.50663;6641.156;686.2542;3;3;0;5.507814;5.361483;6094885;7.240518e+008
1655.496;1.76866;-1.549358;6787.306;701.3563;3;3;0;5.570581;5.420956;6229013;7.40426e+008
1659.496;1.788695;-1.590598;6933.837;716.4979;3;3;0;5.633686;5.480713;6363491;7.568631e+008
1663.496;1.808785;-1.631379;7082.65;731.8753;3;3;0;5.696959;5.540594;6500064;7.735699e+008
1667.496;1.828767;-1.671308;7229.073;747.0057;3;3;0;5.759895;5.600119;6634443;7.900325e+008
1671.496;1.848856;-1.710308;7377.009;762.2925;3;3;0;5.823168;5.659929;6770210;8.06682e+008
1675.496;1.868892;-1.749302;7525.091;777.5943;3;3;0;5.886273;5.719544;6906112;8.233656e+008
1679.496;1.88882;-1.787826;7671.53;792.7263;3;3;0;5.94904;5.778804;7040505;8.39886e+008
1683.496;1.908749;-1.82624;7816.468;807.7032;3;3;0;6.011807;5.838029;7173521;8.562608e+008
1687.496;1.928677;-1.864201;7960.963;822.6345;3;3;0;6.074574;5.897219;7306131;8.72606e+008
1691.496;1.948659;-1.903939;8106.146;837.6368;3;3;0;6.13751;5.956533;7439372;8.890468e+008
1695.496;1.968642;-1.944346;8247.907;852.2855;3;3;0;6.200446;6.015812;7569472;9.051309e+008
1699.496;1.988677;-1.986285;8389.648;866.9321;3;3;0;6.263551;6.075215;7699555;9.212328e+008
1701.68;1.999552;-2.01018;8464.425;874.659;3;3;0;6.297802;6.107442;7768180;9.297433e+008
1705.078;1.98257;-1.994627;8164.116;843.627;3;3;0;6.244316;6.057112;7492573;8.963057e+008
1708.988;1.963124;-1.971997;7864.341;812.6501;3;3;0;6.183067;5.999447;7217456;8.628969e+008
1712.988;1.943142;-1.948068;7576.585;782.9153;3;3;0;6.120131;5.940158;6953370;8.308308e+008
1716.988;1.92316;-1.92332;7303.658;754.7128;3;3;0;6.057196;5.880834;6702893;8.004272e+008
1720.988;1.903231;-1.89727;7051.909;728.6987;3;3;0;5.994429;5.821634;6471852;7.723801e+008
1724.988;1.883195;-1.869841;6814.442;704.1604;3;3;0;5.931324;5.762081;6253918;7.459265e+008
1728.988;1.86316;-1.841533;6585.984;680.553;3;3;0;5.868219;5.702492;6044252;7.204894e+008
1732.988;1.843177;-1.812913;6367.283;657.9539;3;3;0;5.805284;5.643027;5843539;6.961499e+008
1736.988;1.823142;-1.78389;6157.653;636.2921;3;3;0;5.742178;5.583367;5651153;6.728291e+008
1740.988;1.80316;-1.754096;5954.505;615.3;3;3;0;5.679243;5.523831;5464715;6.502445e+008
1744.988;1.783231;-1.723813;5758.281;595.0236;3;3;0;5.616476;5.464419;5284631;6.284429e+008
1748.988;1.763249;-1.692779;5567.579;575.3177;3;3;0;5.55354;5.404812;5109616;6.072682e+008
1752.988;1.743213;-1.661254;5383.521;556.2983;3;3;0;5.490435;5.34501;4940698;5.868415e+008
1756.988;1.723177;-1.62813;5202.864;537.6304;3;3;0;5.42733;5.285172;4774901;5.668093e+008
1760.988;1.703088;-1.594611;5027.35;519.4939;3;3;0;5.364058;5.225138;4613824;5.473598e+008
1764.988;1.683052;-1.561494;4858.132;502.008;3;3;0;5.300952;5.165228;4458524;5.286192e+008
1768.988;1.663017;-1.527862;4693.776;485.0245;3;3;0;5.237848;5.105282;4307688;5.104293e+008
1772.988;1.643035;-1.493856;4531.007;468.205;3;3;0;5.174912;5.045461;4158308;4.924342e+008
1776.988;1.623106;-1.45997;4370.353;451.6041;3;3;0;5.112145;4.985764;4010868;4.746907e+008
1780.988;1.603178;-1.426616;4215.194;435.571;3;3;0;5.049378;4.926032;3868472;4.575646e+008
1784.988;1.583195;-1.392586;4062.599;419.8028;3;3;0;4.986442;4.866103;3728429;4.40736e+008
1788.988;1.56316;-1.357293;3913.563;404.4023;3;3;0;4.923338;4.805978;3591652;4.243124e+008
1792.988;1.543124;-1.320383;3765.577;389.1104;3;3;0;4.860233;4.745817;3455838;4.080221e+008
1796.988;1.523088;-1.281823;3621.414;374.2135;3;3;0;4.797129;4.685619;3323533;3.92165e+008
1800.988;1.503053;-1.241599;3476.108;359.1985;3;3;0;4.734024;4.625385;3190179;3.762031e+008
1804.988;1.483017;-1.200431;3331.158;344.2203;3;3;0;4.670919;4.565114;3057152;3.602986e+008
1808.988;1.463035;-1.158499;3186.819;329.3053;3;3;0;4.607984;4.504969;2924686;3.444796e+008
1812.988;1.44316;-1.115546;3040.411;314.1765;3;3;0;4.545385;4.44511;2790321;3.28457e+008
1816.988;1.423178;-1.072251;2893.395;298.9847;3;3;0;4.482449;4.384892;2655398;3.123866e+008
1820.988;1.403195;-1.028985;2743.908;283.5377;3;3;0;4.419513;4.324638;2518207;2.960687e+008
1824.988;1.383213;-0.9867529;2596.256;268.2803;3;3;0;4.356577;4.264348;2382700;2.799682e+008
1828.988;1.363178;-0.9456023;2447.276;252.8857;3;3;0;4.293473;4.203859;2245974;2.637433e+008
1832.988;1.343142;-0.90617;2299.673;237.6334;3;3;0;4.230368;4.143334;2110513;2.476861e+008
1836.988;1.32316;-0.867542;2151.898;222.3633;3;3;0;4.167432;4.082935;1974893;2.316301e+008
1840.988;1.303178;-0.8295207;2002.386;206.9137;3;3;0;4.104496;4.022498;1837679;2.154064e+008
1844.988;1.283196;-0.7915701;1851.878;191.3612;3;3;0;4.041561;3.962026;1699552;1.990951e+008
1848.988;1.263267;-0.7534219;1699.949;175.6617;3;3;0;3.978794;3.901679;1560119;1.826509e+008
1852.988;1.243231;-0.7159482;1548.972;160.0608;3;3;0;3.915689;3.840971;1421561;1.663283e+008
1856.988;1.223142;-0.6797895;1402.987;144.9756;3;3;0;3.852416;3.780063;1287584;1.505607e+008
1860.988;1.203106;-0.6444345;1267.705;130.9964;3;3;0;3.789311;3.719281;1163429;1.359603e+008
1864.988;1.183071;-0.6092396;1136.07;117.3942;3;3;0;3.726207;3.658462;1042623;1.217685e+008
1868.988;1.162981;-0.5741147;1009.474;104.3126;3;3;0;3.662934;3.597443;926439.6;1.081335e+008
1872.988;1.143053;-0.5395664;889.4049;91.90535;3;3;0;3.600167;3.536875;816246.5;9.52141e+007
1876.988;1.123124;-0.5061084;773.3076;79.90862;3;3;0;3.537399;3.476271;709698.9;8.27353e+007
1880.988;1.103196;-0.4741423;662.528;68.46136;3;3;0;3.474632;3.41563;608031.5;7.084014e+007
1884.988;1.083214;-0.4439922;554.8967;57.33944;3;3;0;3.411696;3.354789;509253.4;5.929569e+007
1888.988;1.063178;-0.4170924;452.1122;46.71836;3;3;0;3.348592;3.293747;414923.6;4.828276e+007
1892.988;1.043142;-0.3942927;355.946;36.78116;3;3;0;3.285487;3.232669;326667.5;3.79896e+007
1896.988;1.023107;-0.3750768;269.6047;27.85921;3;3;0;3.222383;3.171553;247428.2;2.875694e+007
1900.988;1.003017;-0.3593225;195.2973;20.18076;3;3;0;3.159109;3.110236;179233;2.081829e+007
1904.988;0.9830351;-0.3479573;132.8435;13.72719;3;3;0;3.096174;3.049209;121916.4;1.415221e+007
1908.988;0.963053;-0.3415905;106.4151;10.99625;3;3;0;3.033238;2.988145;97661.91;1.132979e+007
1912.166;0.947303;-0.340376;106.4762;11.00256;3;3;0;2.983631;2.939987;97717.94;1.133084e+007