File: Ensayos/Graficos/EspC/EspCamb1.raw
"Test Type";"Manual"
"Method Name:";"C:\INSTRON\user\template\Pablor.mtM"
"Name:";""
"Operator ID:";""
"Company:";""
"Lab name:";""
"Test date:";"31/03/2017"
"Temperature:";""
"Humidity:";""
"Note 1:";""
"Note 2:";""
"Note 3:";""
"Geometry:";"Rectangular"
"Specimen";1
"Specimen name:";""
"User Input 1:";"No definido"
"User Input 2:";"No definido"
"User Input 3:";"No definido"
"User Input 4:";"No definido"
"User Input 5:";"No definido"
"User Input 6:";"No definido"
"User Input 7:";"No definido"
"User Input 8:";"No definido"
"User Input 9:";"No definido"
"User Input 10:";"No definido"
"Width:";0.250000;"in"
"Thickness:";0.060000;"in"
"Length:";1.250000;"in"
"Diameter:";0.039370;"in"
"Inner diameter:";0.019685;"in"
"Outer diameter:";0.039370;"in"
"Wall thickness:";0.019685;"in"
"Area:";0.015000;"in*in"
"Linear density:";1.000000;"den"
"Sled weight:";2.204623;"lbf"
"Loading span:";0.000000;"mm"
"Support span:";1.000000;"mm"
"Span ratio:";"2"
"Fixture type:";"3-point"
"Comment:";""
"Included"
"Final Width:";0.250000;"in"
"Final Thickness:";0.060000;"in"
"Final Length:";1.250000;"in"
"Final Diameter:";0.039370;"in"
"Final Inner diameter:";0.019685;"in"
"Final Outer diameter:";0.039370;"in"
"Final Wall thickness:";0.019685;"in"
"Final Area:";0.015000;"in*in"
"Final Linear density:";1.000000;"den"
"Time sec";"Extension mm";"Strain 1 %";"Load N";"Stress MPa";"Cycle Count ";"Total Cycle Count ";"Repetitions Count ";"Strain [Exten.] %";"True strain %";"Tenacity gf/tex";"True stress Pa"
0;0.0003214284;0.00108946;55.51377;5.736434;0;0;0;0.001012373;0.001012368;50947.46;5736492
2;0.006964281;-0.001164228;90.24712;9.325555;0;0;0;0.02193474;0.02193234;82823.8;9327600
4;0.01360713;-0.003912248;130.8732;13.52359;0;0;0;0.04285712;0.04284794;120108.2;1.352939e+007
6;0.02024999;-0.009062248;170.9653;17.66645;0;0;0;0.06377948;0.06375915;156902.5;1.767772e+007
8;0.02689284;-0.01589409;212.2288;21.93036;0;0;0;0.08470186;0.08466601;194771.9;2.194893e+007
10;0.03358926;-0.02280775;256.2548;26.47971;0;0;0;0.105793;0.105737;235176.4;2.650773e+007
12;0.04023212;-0.03001503;302.8317;31.29268;0;0;0;0.1267153;0.1266351;277922.2;3.133233e+007
14;0.04687497;-0.03735985;351.2772;36.29871;0;0;0;0.1476377;0.1475288;322382.7;3.63523e+007
16;0.05351782;-0.04489161;402.5178;41.59359;0;0;0;0.1685601;0.1684182;369408.6;4.16637e+007
18;0.06026782;-0.05297116;456.2004;47.1408;0;0;0;0.1898199;0.18964;418675.5;4.723029e+007
20;0.06691067;-0.06090593;510.6712;52.76946;0;0;0;0.2107423;0.2105205;468665.7;5.288067e+007
22;0.07355352;-0.06896016;567.035;58.59373;0;0;0;0.2316646;0.2313967;520393.3;5.872947e+007
24;0.08035709;-0.07704778;625.8447;64.67075;0;0;0;0.2530932;0.2527735;574365.6;6.483442e+007
26;0.08699994;-0.08495787;684.4678;70.72849;0;0;0;0.2740156;0.2736408;628166.6;7.092229e+007
28;0.09353565;-0.09290667;743.84;76.86362;0;0;0;0.2946005;0.2941674;682655.2;7.709007e+007
30;0.1003392;-0.1010122;806.685;83.35761;0;0;0;0.316029;0.3155307;740330.8;8.362105e+007
32;0.1070356;-0.1091567;869.5924;89.85806;0;0;0;0.3371201;0.3365532;798063.8;9.0161e+007
34;0.1136249;-0.1170535;931.9742;96.30419;0;0;0;0.3578738;0.3572349;855314.3;9.664884e+007
36;0.1203749;-0.1252557;996.5534;102.9774;0;0;0;0.3791336;0.3784167;914581.5;1.033678e+008
38;0.1270713;-0.1334897;1061.32;109.67;0;0;0;0.4002247;0.3994259;974020.9;1.101089e+008
40;0.1336606;-0.1414612;1125.165;116.2673;0;0;0;0.4209783;0.4200947;1032615;1.167568e+008
42;0.1404106;-0.1498236;1191.308;123.102;0;0;0;0.4422382;0.4412632;1093316;1.236464e+008
44;0.1470535;-0.1580272;1256.665;129.8556;0;0;0;0.4631606;0.4620913;1153297;1.304571e+008
46;0.1536428;-0.1663008;1320.272;136.4284;0;0;0;0.4839142;0.4827471;1211673;1.370886e+008
48;0.1603392;-0.1748559;1385.34;143.1521;0;0;0;0.5050053;0.5037344;1271389;1.43875e+008
50;0.1670356;-0.1836271;1449.565;149.7887;0;0;0;0.5260964;0.5247174;1330331;1.505767e+008
52;0.1735713;-0.1922956;1511.476;156.1862;0;0;0;0.5466813;0.5451924;1387149;1.5704e+008
54;0.1802677;-0.2010088;1575.134;162.7642;0;0;0;0.5677724;0.5661667;1445571;1.636883e+008
56;0.1869642;-0.2100271;1638.192;169.2802;0;0;0;0.5888636;0.5871365;1503442;1.70277e+008
58;0.1935534;-0.2192733;1699.075;175.5714;0;0;0;0.6096171;0.6077665;1559317;1.766417e+008
60;0.2001963;-0.2284604;1759.861;181.8527;0;0;0;0.6305395;0.6285599;1615103;1.829993e+008
62;0.2068927;-0.2378327;1820.337;188.1019;0;0;0;0.6516306;0.6495167;1670604;1.893276e+008
64;0.2136427;-0.2470734;1880.745;194.344;0;0;0;0.6728904;0.6706366;1726044;1.956518e+008
66;0.220232;-0.2560237;1938.408;200.3025;0;0;0;0.6936441;0.6912494;1778963;2.016919e+008
68;0.2268213;-0.2649507;1996.024;206.2562;0;0;0;0.7143977;0.711858;1831840;2.077297e+008
70;0.2336249;-0.2740321;2055.857;212.439;0;0;0;0.7358263;0.7331323;1886752;2.140022e+008
72;0.2402677;-0.2828705;2114.457;218.4943;0;0;0;0.7567487;0.7538997;1940531;2.201478e+008
74;0.246857;-0.2917169;2171.668;224.4061;0;0;0;0.7775023;0.7744953;1993037;2.261509e+008
76;0.2536605;-0.3009993;2232.055;230.6462;0;0;0;0.7989309;0.7957564;2048457;2.324889e+008
78;0.2603034;-0.3103898;2290.452;236.6805;0;0;0;0.8198532;0.8165107;2102050;2.38621e+008
80;0.2669462;-0.3197634;2348.787;242.7084;0;0;0;0.8407755;0.8372607;2155586;2.447491e+008
82.00001;0.2736962;-0.3295854;2408.669;248.8963;0;0;0;0.8620354;0.8583411;2210543;2.510419e+008
84.00001;0.2803391;-0.3392762;2468.153;255.043;0;0;0;0.8829578;0.8790825;2265134;2.572949e+008
86.00001;0.286982;-0.3490305;2526.136;261.0345;0;0;0;0.9038802;0.8998196;2318348;2.63394e+008
88.00001;0.293732;-0.3590964;2585.856;267.2057;0;0;0;0.92514;0.9208868;2373156;2.696777e+008
90.00001;0.3003748;-0.3690761;2645.327;273.351;0;0;0;0.9460624;0.9416153;2427735;2.759371e+008
92.00001;0.3069641;-0.3789199;2703.371;279.3488;0;0;0;0.9668161;0.9621723;2481004;2.820496e+008
94.00001;0.3137141;-0.3890852;2763.826;285.5959;0;0;0;0.9880759;0.9832263;2536486;2.884178e+008
96.00001;0.3204105;-0.3995351;2825.058;291.9232;0;0;0;1.009167;1.004109;2592682;2.948692e+008
98.00001;0.3269462;-0.4097131;2884.995;298.1167;0;0;0;1.029752;1.024486;2647688;3.011866e+008
100;0.3336426;-0.4202388;2948.172;304.6451;0;0;0;1.050843;1.04536;2705669;3.078464e+008
102;0.3403391;-0.4309238;3012.712;311.3142;0;0;0;1.071934;1.06623;2764900;3.146513e+008
104;0.3468748;-0.4413849;3075.709;317.8239;0;0;0;1.092519;1.086594;2822716;3.212962e+008
106;0.3535712;-0.4517831;3139.774;324.4439;0;0;0;1.11361;1.107455;2881510;3.28057e+008
108;0.3602676;-0.4621291;3205.486;331.2342;0;0;0;1.134701;1.128312;2941817;3.349927e+008
110;0.3669105;-0.4725105;3271.143;338.0188;0;0;0;1.155624;1.148997;3002074;3.41925e+008
112;0.3735533;-0.4829731;3337.518;344.8776;0;0;0;1.176546;1.169678;3062989;3.489352e+008
114;0.3801962;-0.4933899;3405.349;351.8868;0;0;0;1.197468;1.190355;3125241;3.561005e+008
116;0.3869462;-0.5040133;3474.864;359.07;0;0;0;1.218728;1.211361;3189038;3.634461e+008
118;0.393589;-0.5144756;3543.391;366.1511;0;0;0;1.23965;1.23203;3251928;3.706901e+008
120;0.4001783;-0.5249363;3611.83;373.2231;0;0;0;1.260404;1.252527;3314737;3.779273e+008
122;0.4069819;-0.5356408;3682.301;380.5052;0;0;0;1.281833;1.273687;3379412;3.853827e+008
124;0.4136247;-0.5460779;3750.785;387.5818;0;0;0;1.302755;1.294342;3442262;3.926311e+008
126;0.420214;-0.5563594;3819.229;394.6545;0;0;0;1.323509;1.314827;3505077;3.998778e+008
128;0.4270176;-0.5671256;3890.856;402.0559;0;0;0;1.344937;1.335973;3570812;4.074633e+008
130;0.4336605;-0.5776162;3960.031;409.204;0;0;0;1.36586;1.356616;3634297;4.147932e+008
132;0.4402497;-0.5881334;4028.824;416.3127;0;0;0;1.386613;1.377088;3697432;4.220853e+008
134;0.4470533;-0.5989999;4100.381;423.7068;0;0;0;1.408042;1.398221;3763102;4.296728e+008
136;0.4537497;-0.6100118;4169.334;430.832;0;0;0;1.429133;1.419017;3826384;4.369892e+008
138;0.4602854;-0.6209528;4237.329;437.8582;0;0;0;1.449718;1.43931;3888786;4.442059e+008
140;0.4670354;-0.6323055;4307.009;445.0584;0;0;0;1.470978;1.460264;3952734;4.516051e+008
142;0.4737854;-0.6438396;4376.016;452.1892;0;0;0;1.492237;1.481213;4016065;4.58937e+008
144;0.4803211;-0.6554619;4441.186;458.9235;0;0;0;1.512823;1.501493;4075875;4.658662e+008
146;0.4870175;-0.6673282;4508.654;465.8952;0;0;0;1.533913;1.522268;4137793;4.730416e+008
148;0.493714;-0.6791645;4575.543;472.807;0;0;0;1.555005;1.543038;4199180;4.801592e+008
150;0.5002497;-0.6909408;4639.143;479.3791;0;0;0;1.57559;1.563306;4257549;4.869321e+008
152;0.5069461;-0.703067;4705.43;486.2287;0;0;0;1.596681;1.584068;4318383;4.939922e+008
154;0.5136425;-0.715522;4771.377;493.0433;0;0;0;1.617772;1.604825;4378906;5.010196e+008
156;0.5202318;-0.7280247;4835.102;499.6281;0;0;0;1.638525;1.625246;4437389;5.078147e+008
158;0.5268747;-0.7407288;4899.263;506.2582;0;0;0;1.659448;1.645829;4496272;5.146593e+008
160;0.5335711;-0.7535259;4963.991;512.9468;0;0;0;1.680539;1.666574;4555677;5.215671e+008
162;0.5402675;-0.7664606;5028.741;519.6376;0;0;0;1.70163;1.687314;4615100;5.284799e+008
164;0.5468568;-0.7790865;5091.652;526.1384;0;0;0;1.722384;1.707719;4672836;5.352006e+008
166;0.5534996;-0.7917994;5155.15;532.6999;0;0;0;1.743306;1.728285;4731111;5.419865e+008
168;0.5603032;-0.8048525;5221.833;539.5905;0;0;0;1.764735;1.749344;4792309;5.491128e+008
170;0.5669461;-0.8176223;5286.045;546.2258;0;0;0;1.785657;1.769901;4851240;5.559795e+008
172;0.5735353;-0.8302204;5349.587;552.7917;0;0;0;1.80641;1.790289;4909555;5.627774e+008
174;0.5803389;-0.8433077;5415.417;559.5942;0;0;0;1.827839;1.811335;4969970;5.698227e+008
176;0.5869818;-0.8561447;5478.111;566.0726;0;0;0;1.848761;1.83188;5027507;5.765379e+008
178;0.5935711;-0.8689646;5540.343;572.5033;0;0;0;1.869515;1.852255;5084620;5.832063e+008
180;0.6003746;-0.8825625;5604.777;579.1614;0;0;0;1.890944;1.873287;5143754;5.901131e+008
182;0.6070711;-0.8963323;5668.134;585.7084;0;0;0;1.912035;1.893985;5201900;5.969073e+008
184;0.6136068;-0.9098744;5727.997;591.8942;0;0;0;1.93262;1.914182;5256839;6.033333e+008
186;0.6204103;-0.9242398;5790.266;598.3287;0;0;0;1.954048;1.935202;5313986;6.100203e+008
188;0.6270532;-0.9384105;5849.166;604.415;0;0;0;1.974971;1.955721;5368041;6.163521e+008
190;0.6336424;-0.9526862;5906.625;610.3525;0;0;0;1.995724;1.976071;5420773;6.225334e+008
192;0.6403924;-0.967583;5965.789;616.4661;0;0;0;2.016984;1.996912;5475070;6.289001e+008
194;0.6470888;-0.9825936;6023.84;622.4648;0;0;0;2.038075;2.017584;5528347;6.351511e+008
196;0.6536246;-0.9976634;6078.221;628.0841;0;0;0;2.05866;2.037756;5578255;6.410142e+008
196.51;0.6552317;-1.001399;6091.479;629.4541;0;0;0;2.063722;2.042716;5590422;6.424443e+008
198.51;0.6486424;-0.9954296;5975.098;617.4281;0;0;0;2.042968;2.022379;5483615;6.300419e+008
200.51;0.6419996;-0.9870045;5862.889;605.8331;0;0;0;2.022046;2.001874;5380635;6.180833e+008
202.51;0.6352496;-0.978111;5753.321;594.511;0;0;0;2.000786;1.981033;5280079;6.064059e+008
204.51;0.6285532;-0.9692249;5648.445;583.6738;0;0;0;1.979695;1.960354;5183830;5.952288e+008
206.51;0.6220175;-0.9603225;5547.423;573.2349;0;0;0;1.95911;1.940167;5091118;5.844651e+008
208.51;0.6152139;-0.9509651;5444.535;562.603;0;0;0;1.937681;1.919147;4996693;5.735045e+008
210.51;0.6085174;-0.9415032;5344.394;552.2551;0;0;0;1.91659;1.898455;4904789;5.628396e+008
212.51;0.6019818;-0.9321699;5248.403;542.336;0;0;0;1.896006;1.878255;4816693;5.526187e+008
214.51;0.5952853;-0.9226469;5150.457;532.215;0;0;0;1.874915;1.857555;4726805;5.421936e+008
216.51;0.5885889;-0.9131974;5056.08;522.4626;0;0;0;1.853823;1.836849;4640190;5.321482e+008
218.51;0.5820532;-0.9038224;4963.86;512.9332;0;0;0;1.833238;1.816637;4555556;5.223365e+008
220.51;0.5753568;-0.894203;4870.126;503.2473;0;0;0;1.812147;1.795924;4469532;5.123669e+008
222.51;0.5686603;-0.8845042;4777.552;493.6813;0;0;0;1.791056;1.775206;4384572;5.025234e+008
224.51;0.562071;-0.8746497;4686.043;484.2254;0;0;0;1.770303;1.754815;4300591;4.927977e+008
226.51;0.5553747;-0.8648422;4594.654;474.7819;0;0;0;1.749212;1.734089;4216720;4.830868e+008
228.51;0.5486782;-0.855103;4504.873;465.5045;0;0;0;1.72812;1.713358;4134323;4.73549e+008
230.51;0.5420889;-0.8453183;4417.475;456.4733;0;0;0;1.707367;1.692955;4054114;4.64267e+008
232.51;0.5353925;-0.8355445;4330.83;447.52;0;0;0;1.686276;1.672216;3974596;4.550664e+008
234.51;0.5287497;-0.8256917;4245.162;438.6676;0;0;0;1.665353;1.651638;3895974;4.45973e+008
236.51;0.5219997;-0.8156823;4160.617;429.9313;0;0;0;1.644094;1.630725;3818384;4.369998e+008
238.51;0.5153568;-0.8057057;4078.324;421.4276;0;0;0;1.623171;1.610138;3742860;4.282681e+008
240.51;0.508714;-0.7957013;3997.398;413.0652;0;0;0;1.602249;1.589548;3668590;4.196836e+008
242.51;0.501964;-0.7854609;3916.795;404.7362;0;0;0;1.580989;1.568621;3594617;4.111351e+008
244.51;0.4953211;-0.7752278;3839.529;396.7521;0;0;0;1.560066;1.548023;3523707;4.029417e+008
246.51;0.4887319;-0.7651424;3762.846;388.8282;0;0;0;1.539313;1.527586;3453332;3.948135e+008
248.51;0.4819283;-0.7547256;3685.474;380.833;0;0;0;1.517884;1.50648;3382324;3.866136e+008
250.51;0.4752854;-0.7443751;3609.51;372.9834;0;0;0;1.496962;1.485868;3312608;3.785669e+008
252.51;0.4686961;-0.7343172;3535.511;365.3369;0;0;0;1.476208;1.465418;3244697;3.7073e+008
254.51;0.4618926;-0.723948;3458.976;357.4282;0;0;0;1.45478;1.444299;3174457;3.62628e+008
256.51;0.4551961;-0.7136972;3384.527;349.7352;0;0;0;1.433689;1.423508;3106132;3.547493e+008
258.51;0.4486604;-0.7039045;3312.125;342.2536;0;0;0;1.413104;1.403212;3039685;3.4709e+008
260.51;0.4419104;-0.6939019;3237.911;334.5848;0;0;0;1.391844;1.382247;2971576;3.392417e+008
262.51;0.435214;-0.683934;3164.873;327.0375;0;0;0;1.370753;1.361443;2904545;3.315204e+008
264.51;0.4286783;-0.6743033;3093.704;319.6834;0;0;0;1.350168;1.341134;2839231;3.239997e+008
266.51;0.4219819;-0.6644432;3020.645;312.1339;0;0;0;1.329077;1.320322;2772180;3.162824e+008
268.51;0.4152855;-0.6548632;2949.137;304.7448;0;0;0;1.307986;1.299506;2706555;3.087308e+008
270.51;0.4087497;-0.6454857;2879.915;297.5918;0;0;0;1.287401;1.279184;2643026;3.01423e+008
272.51;0.4019997;-0.6359898;2808.699;290.2328;0;0;0;1.266141;1.258192;2577668;2.939076e+008
274.51;0.3953569;-0.626528;2737.402;282.8655;0;0;0;1.245219;1.23753;2512236;2.863878e+008
276.51;0.3887676;-0.6171405;2667.857;275.6791;0;0;0;1.224465;1.217029;2448411;2.790547e+008
278.51;0.3820712;-0.6077879;2597.777;268.4375;0;0;0;1.203374;1.196191;2384096;2.716678e+008
280.51;0.3753748;-0.5985193;2527.886;261.2155;0;0;0;1.182283;1.175348;2319954;2.643037e+008
282.51;0.3687319;-0.5892015;2460.156;254.2166;0;0;0;1.16136;1.154668;2257795;2.57169e+008
284.51;0.3620355;-0.57969;2394.201;247.4013;0;0;0;1.140269;1.133817;2197266;2.502224e+008
286.51;0.3553926;-0.5702706;2329.551;240.7207;0;0;0;1.119347;1.113129;2137933;2.434152e+008
288.51;0.3486962;-0.5604332;2265.147;234.0656;0;0;0;1.098256;1.092269;2078826;2.366362e+008
290.51;0.3419998;-0.550567;2202.274;227.5688;0;0;0;1.077165;1.071405;2021125;2.300201e+008
292.51;0.3354105;-0.5404804;2140.79;221.2154;0;0;0;1.056411;1.05087;1964698;2.235523e+008
294.51;0.3286605;-0.5300841;2080.191;214.9535;0;0;0;1.035151;1.02983;1909084;2.171786e+008
296.51;0.3219641;-0.519651;2022.321;208.9736;0;0;0;1.01406;1.008953;1855974;2.110927e+008
298.51;0.3153748;-0.5095168;1966.741;203.2303;0;0;0;0.9933065;0.9884057;1804966;2.05249e+008
300.51;0.3085712;-0.4991036;1910.414;197.4098;0;0;0;0.9718779;0.9671855;1753272;1.993284e+008
302.51;0.3019284;-0.4889395;1855.558;191.7414;0;0;0;0.9509555;0.9464624;1702929;1.935648e+008
304.51;0.2953391;-0.4788589;1801.912;186.1979;0;0;0;0.9302019;0.9259022;1653695;1.879299e+008
306.51;0.2885891;-0.4685504;1747.153;180.5395;0;0;0;0.908942;0.904836;1603440;1.821805e+008
308.51;0.2818927;-0.4584041;1692.727;174.9155;0;0;0;0.8878509;0.8839327;1553491;1.764685e+008
310.51;0.275357;-0.4485502;1640.387;169.507;0;0;0;0.867266;0.8635269;1505456;1.70977e+008
312.51;0.2685534;-0.438512;1585.622;163.8479;0;0;0;0.8458375;0.8422803;1455196;1.652338e+008
314.51;0.2619106;-0.4286052;1532.119;158.3192;0;0;0;0.8249151;0.8215313;1406094;1.596252e+008
316.51;0.2553748;-0.4189755;1480.077;152.9416;0;0;0;0.8043301;0.8011126;1358332;1.541717e+008
318.51;0.2486248;-0.4091955;1427.071;147.4643;0;0;0;0.7830703;0.7800202;1309687;1.486191e+008
320.51;0.241982;-0.3994499;1375.024;142.0861;0;0;0;0.762148;0.7592583;1261921;1.43169e+008
322.51;0.2354463;-0.3900062;1324.016;136.8153;0;0;0;0.7415631;0.738827;1215109;1.378299e+008
324.51;0.2286963;-0.3803488;1272.356;131.477;0;0;0;0.7203032;0.7177215;1167698;1.32424e+008
326.51;0.2220534;-0.3706975;1221.363;126.2078;0;0;0;0.6993809;0.6969465;1120900;1.270905e+008
328.51;0.2154106;-0.3612555;1171.297;121.0343;0;0;0;0.6784585;0.6761674;1074952;1.218555e+008
330.51;0.2087677;-0.3517912;1121.174;115.8549;0;0;0;0.6575361;0.6553838;1028951;1.166167e+008
332.51;0.2020713;-0.3422549;1071.422;110.7138;0;0;0;0.636445;0.6344283;983291.6;1.114184e+008
334.51;0.1953749;-0.3328658;1022.25;105.6327;0;0;0;0.6153539;0.6134683;938164.5;1.062827e+008
336.51;0.188732;-0.3234772;973.3756;100.5823;0;0;0;0.5944315;0.5926718;893310.1;1.011802e+008
338.51;0.1820892;-0.3142404;925.1227;95.59621;0;0;0;0.5735092;0.5718709;849026.4;9.614446e+007
340.51;0.1753392;-0.3048927;877.1816;90.64228;0;0;0;0.5522494;0.5507301;805028.7;9.114285e+007
342.51;0.1686427;-0.2954742;830.3664;85.8047;0;0;0;0.5311583;0.5297526;762064.3;8.626046e+007
344.51;0.1620535;-0.2861115;784.4975;81.0649;0;0;0;0.5104046;0.5091065;719968.4;8.147867e+007
346.51;0.1553035;-0.2768183;737.9379;76.25374;0;0;0;0.4891447;0.4879523;677238.6;7.662673e+007
348.51;0.148607;-0.2679183;692.2797;71.53571;0;0;0;0.4680537;0.4669617;635335.9;7.187053e+007
350.51;0.1420178;-0.2593;647.474;66.90578;0;0;0;0.4473;0.4463026;594215.8;6.720505e+007
352.51;0.1352678;-0.2504856;601.38;62.14272;0;0;0;0.4260402;0.4251352;551913.3;6.240748e+007
354.51;0.1285713;-0.2422204;556.4126;57.49609;0;0;0;0.4049491;0.4041314;510644.7;5.772892e+007
356.51;0.1219821;-0.2346628;512.901;52.99988;0;0;0;0.3841955;0.3834593;470712.1;5.32035e+007
358.51;0.1152321;-0.2270463;468.8083;48.44363;0;0;0;0.3629357;0.3622786;430246.3;4.861944e+007
360.51;0.1085356;-0.2200104;425.897;44.00945;0;0;0;0.3418445;0.3412616;390864.7;4.415989e+007
362.51;0.1019999;-0.2135465;384.7826;39.76095;0;0;0;0.3212596;0.3207447;353132.2;3.988868e+007
364.51;0.09530351;-0.2074954;344.0339;35.55024;0;0;0;0.3001685;0.2997189;315735.3;3.565695e+007
366.51;0.08860708;-0.2018219;303.9591;31.40917;0;0;0;0.2790774;0.2786887;278956.8;3.149683e+007
368.51;0.08207137;-0.1966193;266.1206;27.49919;0;0;0;0.2584925;0.258159;244230.8;2.757027e+007
370.51;0.07537495;-0.1914364;228.6462;23.62682;0;0;0;0.2374014;0.2371201;209838.8;2.368291e+007
372.51;0.06867853;-0.1864621;192.6544;19.90766;0;0;0;0.2163103;0.2160767;176807.5;1.995072e+007
374.51;0.06208925;-0.1817591;159.1788;16.44851;0;0;0;0.1955567;0.1953657;146085.5;1.648067e+007
376.51;0.05539282;-0.177577;127.9998;13.22668;0;0;0;0.1744656;0.1743136;117471.2;1.324975e+007
378.51;0.0486964;-0.174536;100.797;10.41572;0;0;0;0.1533745;0.153257;92505.95;1.043169e+007
380.304;0.0426964;-0.1723419;79.00597;8.163966;0;0;0;0.1344768;0.1343865;72507.3;8174945
381.306;0.04591068;-0.1731697;97.13346;10.03714;1;1;0;0.1446006;0.1444961;89143.71;1.005166e+007
383.306;0.05266068;-0.1756238;137.4519;14.20339;1;1;0;0.1658604;0.165723;126145.8;1.422695e+007
385.306;0.05941068;-0.1786646;180.5571;18.6576;1;1;0;0.1871202;0.1869454;165705.3;1.869252e+007
387.306;0.06605353;-0.1828919;226.4467;23.39954;1;1;0;0.2080426;0.2078265;207820.2;2.344822e+007
389.306;0.07264281;-0.1875715;274.6523;28.38079;1;1;0;0.2287963;0.2285349;252060.7;2.844573e+007
391.306;0.07944637;-0.1927045;325.4298;33.62782;1;1;0;0.2502248;0.2499123;298661.5;3.371196e+007
393.306;0.08608923;-0.1981187;377.1564;38.97291;1;1;0;0.2711472;0.2707802;346133.3;3.907858e+007
395.306;0.09267851;-0.2035771;429.2668;44.35765;1;1;0;0.2919008;0.2914756;393957.3;4.448713e+007
397.306;0.09942851;-0.2093964;484.2983;50.04426;1;1;0;0.3131607;0.3126713;444462.2;5.020098e+007
399.306;0.1061249;-0.215512;540.5381;55.85572;1;1;0;0.3342518;0.3336944;496075.9;5.604241e+007
401.306;0.1126606;-0.2218485;596.0865;61.59573;1;1;0;0.3548366;0.3542086;547055.2;6.18143e+007
403.306;0.1193571;-0.2284295;653.8807;67.56781;1;1;0;0.3759278;0.3752229;600095.5;6.782181e+007
405.306;0.1260535;-0.235377;712.2613;73.60048;1;1;0;0.3970189;0.3962328;653673.9;7.389269e+007
407.306;0.1326428;-0.2423691;770.3005;79.59788;1;1;0;0.4177725;0.4169023;706939.1;7.993041e+007
409.306;0.1392856;-0.249868;830.2424;85.79189;1;1;0;0.4386949;0.4377354;761950.4;8.616825e+007
411.306;0.145982;-0.2576005;891.4023;92.11176;1;1;0;0.459786;0.4587322;818079.6;9.253527e+007
413.306;0.1526249;-0.2655889;951.965;98.36992;1;1;0;0.4807083;0.4795566;873660.8;9.884279e+007
415.306;0.1592677;-0.2737178;1012.312;104.6058;1;1;0;0.5016307;0.5003767;929043.8;1.051305e+008
417.306;0.1659106;-0.2821909;1072.992;110.876;1;1;0;0.5225531;0.5211925;984732.4;1.114554e+008
419.306;0.1726606;-0.2909346;1134.288;117.21;1;1;0;0.5438129;0.5423396;1040987;1.178474e+008
421.306;0.1793035;-0.2996905;1194.829;123.4659;1;1;0;0.5647353;0.5631467;1096548;1.241632e+008
423.306;0.1858927;-0.3086254;1255.473;129.7324;1;1;0;0.5854889;0.5837816;1152203;1.30492e+008
425.306;0.1926963;-0.3179902;1318.245;136.2189;1;1;0;0.6069176;0.6050833;1209813;1.370457e+008
427.306;0.1993392;-0.3271876;1379.414;142.5398;1;1;0;0.6278399;0.6258772;1265950;1.434347e+008
429.306;0.2059284;-0.3365873;1440.047;148.8052;1;1;0;0.6485935;0.6464992;1321595;1.497703e+008
431.306;0.212732;-0.3461139;1502.379;155.2462;1;1;0;0.6700221;0.6677874;1378801;1.562864e+008
433.306;0.2193749;-0.3554743;1564.473;161.6625;1;1;0;0.6909444;0.6885683;1435787;1.627795e+008
435.306;0.2259641;-0.3646924;1625.55;167.9738;1;1;0;0.7116981;0.7091775;1491840;1.691693e+008
437.306;0.2327677;-0.3743205;1689.132;174.544;1;1;0;0.7331266;0.7304523;1550192;1.758236e+008
439.306;0.2394106;-0.3839521;1752.5;181.092;1;1;0;0.754049;0.7512203;1608348;1.824576e+008
441.306;0.2459998;-0.3934588;1814.777;187.5273;1;1;0;0.7748026;0.7718165;1665502;1.889803e+008
443.306;0.2527498;-0.4031812;1879.187;194.1831;1;1;0;0.7960625;0.7929106;1724614;1.957289e+008
445.306;0.2594462;-0.4128315;1942.839;200.7604;1;1;0;0.8171535;0.8138329;1783030;2.024009e+008
447.306;0.265982;-0.4223755;2004.583;207.1407;1;1;0;0.8377385;0.834249;1839696;2.08876e+008
449.306;0.272732;-0.4323296;2068.359;213.7308;1;1;0;0.8589984;0.85533;1898225;2.155668e+008
451.306;0.2794284;-0.4422379;2131.978;220.3049;1;1;0;0.8800894;0.8762392;1956612;2.222438e+008
453.306;0.2859641;-0.4518234;2193.194;226.6305;1;1;0;0.9006743;0.8966425;2012792;2.286717e+008
455.306;0.2926605;-0.4617616;2256.106;233.1314;1;1;0;0.9217654;0.9175431;2070529;2.352803e+008
457.306;0.2993569;-0.4716589;2318.057;239.533;1;1;0;0.9428565;0.9384394;2127384;2.417915e+008
459.306;0.3059462;-0.4814756;2379.63;245.8956;1;1;0;0.9636101;0.958997;2183893;2.482651e+008
461.306;0.3125891;-0.4911994;2441.004;252.2376;1;1;0;0.9845325;0.9797176;2240218;2.547209e+008
463.306;0.3192855;-0.5010396;2503.73;258.7192;1;1;0;1.005624;1.000601;2297785;2.61321e+008
465.306;0.3259819;-0.511045;2568.194;265.3806;1;1;0;1.026715;1.02148;2356946;2.681052e+008
467.306;0.3326248;-0.5210283;2633.086;272.0861;1;1;0;1.047637;1.042187;2416500;2.749366e+008
469.306;0.3392676;-0.5310261;2699.307;278.929;1;1;0;1.068559;1.062891;2477275;2.819095e+008
471.306;0.3460177;-0.540915;2767.605;285.9864;1;1;0;1.089819;1.083924;2539955;2.891032e+008
473.306;0.3526069;-0.550424;2834.152;292.863;1;1;0;1.110573;1.104451;2601028;2.961154e+008
475.306;0.3592498;-0.5597559;2900.74;299.7437;1;1;0;1.131495;1.125142;2662139;3.031353e+008
477.306;0.3660533;-0.5693092;2970.541;306.9565;1;1;0;1.152924;1.146328;2726198;3.104955e+008
479.306;0.3726962;-0.5786159;3039.036;314.0344;1;1;0;1.173846;1.16701;2789059;3.177207e+008
481.306;0.3792855;-0.5878934;3108.457;321.2079;1;1;0;1.1946;1.187521;2852770;3.25045e+008
483.306;0.3860891;-0.5973556;3181.036;328.7077;1;1;0;1.216028;1.208694;2919379;3.327049e+008
485.306;0.3927319;-0.6065792;3253.448;336.1903;1;1;0;1.236951;1.229363;2985835;3.403488e+008
487.306;0.3993211;-0.6155266;3324.784;343.5617;1;1;0;1.257704;1.249861;3051302;3.478827e+008
489.306;0.4060712;-0.6248585;3398.476;351.1765;1;1;0;1.278964;1.270855;3118933;3.55668e+008
491.306;0.4127676;-0.6339264;3470.629;358.6324;1;1;0;1.300055;1.291677;3185151;3.632948e+008
493.306;0.4193569;-0.643085;3542.05;366.0125;1;1;0;1.320809;1.312162;3250697;3.708469e+008
495.306;0.4261069;-0.6525531;3616.113;373.6657;1;1;0;1.342069;1.333143;3318668;3.786806e+008
497.306;0.4328033;-0.6621306;3688.226;381.1175;1;1;0;1.36316;1.353952;3384850;3.863127e+008
499.306;0.439339;-0.6714734;3758.299;388.3583;1;1;0;1.383745;1.374259;3449158;3.937322e+008
501.306;0.446089;-0.6812391;3831.505;395.923;1;1;0;1.405005;1.395226;3516343;4.014857e+008
503.306;0.4527319;-0.6910592;3902.888;403.2993;1;1;0;1.425927;1.415856;3581855;4.0905e+008
505.306;0.4592676;-0.7008502;3972.305;410.4723;1;1;0;1.446512;1.43615;3645561;4.164098e+008
507.306;0.465964;-0.7107913;4044.028;417.8838;1;1;0;1.467603;1.456938;3711385;4.240166e+008
509.306;0.4726604;-0.7208783;4116.197;425.3412;1;1;0;1.488694;1.477722;3777618;4.316732e+008
511.306;0.4793033;-0.7312467;4186.542;432.6102;1;1;0;1.509617;1.498335;3842176;4.39141e+008
513.306;0.4859461;-0.7416084;4257.012;439.8922;1;1;0;1.530539;1.518944;3906850;4.466249e+008
515.306;0.492589;-0.7519399;4327.318;447.1571;1;1;0;1.551461;1.539549;3971373;4.540946e+008
517.306;0.499339;-0.762528;4397.355;454.3942;1;1;0;1.572721;1.560482;4035649;4.615406e+008
519.306;0.5059283;-0.7729483;4466.749;461.565;1;1;0;1.593475;1.580912;4099335;4.689199e+008
521.306;0.5125711;-0.7835203;4537.027;468.8271;1;1;0;1.614397;1.601504;4163832;4.763958e+008
523.306;0.5193747;-0.7945698;4608.92;476.256;1;1;0;1.635826;1.62259;4229811;4.840467e+008
525.306;0.5260175;-0.8053883;4678.897;483.487;1;1;0;1.656748;1.643174;4294033;4.914972e+008
527.306;0.5325532;-0.8160238;4748.435;490.6726;1;1;0;1.677333;1.663421;4357851;4.989028e+008
529.306;0.5394104;-0.8268331;4821.597;498.2326;1;1;0;1.69893;1.68466;4424994;5.066973e+008
531.306;0.5460532;-0.8364603;4892.313;505.54;1;1;0;1.719853;1.705231;4489894;5.142346e+008
533.306;0.5526425;-0.8470678;4964.023;512.9501;1;1;0;1.740606;1.725631;4555706;5.218785e+008
535.306;0.5593925;-0.8580093;5038.555;520.6517;1;1;0;1.761866;1.746525;4624107;5.298249e+008
537.306;0.5660889;-0.8689878;5111.039;528.1418;1;1;0;1.782957;1.767249;4690629;5.375583e+008
539.306;0.5726782;-0.8797748;5181.347;535.4069;1;1;0;1.803711;1.787637;4755153;5.450641e+008
541.306;0.5794282;-0.8909421;5254.652;542.9818;1;1;0;1.824971;1.808518;4822428;5.52891e+008
543.306;0.5861246;-0.9019647;5325.608;550.3139;1;1;0;1.846062;1.829229;4887548;5.60473e+008
545.306;0.5926603;-0.9129345;5393.522;557.3317;1;1;0;1.866647;1.849439;4949876;5.677351e+008
547.306;0.5994639;-0.9245031;5464.973;564.715;1;1;0;1.888075;1.870472;5015449;5.753772e+008
549.306;0.6061068;-0.9361514;5535.358;571.9881;1;1;0;1.908998;1.891005;5080045;5.829074e+008
551.306;0.6126424;-0.9475816;5602.807;578.9579;1;1;0;1.929582;1.911202;5141946;5.901293e+008
553.306;0.6193924;-0.9594339;5672.498;586.1593;1;1;0;1.950842;1.932057;5205905;5.975943e+008
555.306;0.6260889;-0.9713095;5739.989;593.1334;1;1;0;1.971933;1.952743;5267844;6.048296e+008
557.306;0.6326246;-0.9833698;5804.959;599.8469;1;1;0;1.992518;1.972928;5327470;6.11799e+008
559.306;0.6392675;-0.9956954;5870.313;606.6002;1;1;0;2.013441;1.993439;5387448;6.188137e+008
560.8001;0.6443031;-1.005607;5919.297;611.6619;1;1;0;2.029301;2.008985;5432403;6.240744e+008
561.802;0.641196;-1.003151;5863.063;605.8511;1;1;0;2.019515;1.999393;5380795;6.180864e+008
563.802;0.6343389;-0.9945466;5745.526;593.7055;1;1;0;1.997918;1.978221;5272925;6.055672e+008
565.802;0.6276961;-0.9857545;5636.372;582.4263;1;1;0;1.976995;1.957707;5172750;5.939408e+008
567.802;0.6210531;-0.9767928;5531.546;571.5943;1;1;0;1.956073;1.937188;5076547;5.827751e+008
569.802;0.6143031;-0.9674892;5426.694;560.7595;1;1;0;1.934813;1.916333;4980319;5.716091e+008
571.802;0.6076067;-0.9581797;5324.861;550.2367;1;1;0;1.913722;1.895641;4886862;5.607667e+008
573.802;0.6010175;-0.9488205;5226.424;540.0649;1;1;0;1.892968;1.875275;4796522;5.502881e+008
575.802;0.5942674;-0.939122;5126.958;529.7867;1;1;0;1.871709;1.854408;4705239;5.397028e+008
577.802;0.5875711;-0.9295415;5030.911;519.8619;1;1;0;1.850618;1.833702;4617092;5.294825e+008
579.802;0.5809818;-0.9202679;4937.579;510.2175;1;1;0;1.829864;1.813323;4531437;5.195538e+008
581.802;0.5742318;-0.9103298;4842.206;500.3623;1;1;0;1.808604;1.792443;4443908;5.094118e+008
583.802;0.5675354;-0.9006163;4748.608;490.6905;1;1;0;1.787513;1.771725;4358010;4.994617e+008
585.802;0.5609996;-0.8910816;4657.848;481.3119;1;1;0;1.766928;1.751499;4274715;4.898163e+008
587.802;0.5542496;-0.8809862;4565.273;471.7458;1;1;0;1.745668;1.730606;4189754;4.799809e+008
589.802;0.5475532;-0.8711202;4475.459;462.465;1;1;0;1.724577;1.709875;4107328;4.704406e+008
591.802;0.5410175;-0.8614621;4389.063;453.5374;1;1;0;1.703992;1.689637;4028039;4.612657e+008
593.802;0.5343211;-0.8514992;4300.946;444.4319;1;1;0;1.682901;1.668897;3947170;4.519113e+008
595.802;0.5276246;-0.8417047;4214.738;435.5238;1;1;0;1.66181;1.648153;3868053;4.427614e+008
597.802;0.521089;-0.8319046;4131.122;426.8835;1;1;0;1.641225;1.627903;3791315;4.338896e+008
599.802;0.5143925;-0.821862;4047.153;418.2067;1;1;0;1.620134;1.60715;3714253;4.249822e+008
601.802;0.5076961;-0.8118219;3964.713;409.6878;1;1;0;1.599043;1.586393;3638594;4.162389e+008
603.802;0.5011068;-0.8017521;3884.917;401.4423;1;1;0;1.578289;1.565964;3565362;4.077782e+008
605.802;0.4944104;-0.7916395;3806.613;393.3508;1;1;0;1.557198;1.545198;3493499;3.994761e+008
607.802;0.487714;-0.7812303;3728.634;385.2929;1;1;0;1.536107;1.524428;3421934;3.912115e+008
609.802;0.4810176;-0.7708793;3651.732;377.3464;1;1;0;1.515016;1.503654;3351358;3.830633e+008
611.802;0.4743747;-0.7605334;3576.027;369.5235;1;1;0;1.494094;1.483042;3281879;3.750445e+008
613.802;0.4677318;-0.7502033;3500.508;361.7199;1;1;0;1.473171;1.462425;3212572;3.670486e+008
615.802;0.4609818;-0.7398919;3425.252;353.9434;1;1;0;1.451911;1.441472;3143507;3.590824e+008
617.802;0.454339;-0.7295443;3351.792;346.3525;1;1;0;1.430989;1.420847;3076089;3.513088e+008
619.802;0.4476961;-0.7195374;3278.629;338.7924;1;1;0;1.410067;1.400218;3008944;3.435696e+008
621.802;0.4409462;-0.7093357;3204.415;331.1235;1;1;0;1.388807;1.379251;2940835;3.357222e+008
623.802;0.4343033;-0.6992132;3131.727;323.6125;1;1;0;1.367884;1.358613;2874126;3.280391e+008
625.802;0.4276604;-0.689482;3059.854;316.1856;1;1;0;1.346962;1.337971;2808165;3.204445e+008
627.802;0.4209104;-0.6794238;2986.429;308.5982;1;1;0;1.325702;1.316992;2740779;3.126893e+008
629.802;0.414214;-0.6697084;2914.921;301.2092;1;1;0;1.304611;1.296174;2675154;3.051388e+008
631.802;0.4076783;-0.6602428;2845.936;294.0807;1;1;0;1.284026;1.275852;2611843;2.978568e+008
633.802;0.4008747;-0.6506134;2774.181;286.6659;1;1;0;1.262598;1.254693;2545989;2.902853e+008
635.802;0.3941783;-0.6410116;2703.051;279.3158;1;1;0;1.241506;1.233863;2480710;2.827835e+008
637.802;0.3876962;-0.6317925;2634.165;272.1975;1;1;0;1.22109;1.213695;2417490;2.755213e+008
639.802;0.3809462;-0.6223697;2563.238;264.8684;1;1;0;1.199831;1.19269;2352398;2.680464e+008
641.802;0.3742498;-0.6129116;2493.329;257.6445;1;1;0;1.178739;1.171846;2288239;2.606814e+008
643.802;0.3677141;-0.6038842;2426.74;250.7636;1;1;0;1.158154;1.151499;2227127;2.536678e+008
645.802;0.3610176;-0.5946567;2359.628;243.8288;1;1;0;1.137063;1.130647;2165536;2.466012e+008
647.802;0.3543212;-0.5853368;2293.571;237.0028;1;1;0;1.115972;1.109791;2104912;2.396477e+008
649.802;0.3477319;-0.5759322;2230.041;230.438;1;1;0;1.095219;1.089265;2046608;2.329618e+008
651.802;0.3410355;-0.5659488;2166.078;223.8285;1;1;0;1.074128;1.0684;1987906;2.262327e+008
653.802;0.3343926;-0.5560342;2103.336;217.3452;1;1;0;1.053205;1.047698;1930325;2.196342e+008
655.802;0.3277498;-0.5459866;2043.471;211.1591;1;1;0;1.032283;1.026991;1875384;2.133388e+008
657.802;0.3210534;-0.5357395;1984.553;205.0709;1;1;0;1.011192;1.006113;1821313;2.071446e+008
659.802;0.3144105;-0.5254759;1927.491;199.1744;1;1;0;0.9902693;0.9853983;1768944;2.011468e+008
661.802;0.3077141;-0.5151635;1872.144;193.4552;1;1;0;0.9691783;0.9645119;1718150;1.953302e+008
663.802;0.3010177;-0.5049887;1817.396;187.7979;1;1;0;0.9480871;0.9436209;1667905;1.895784e+008
665.802;0.2943748;-0.4947307;1763.24;182.2018;1;1;0;0.9271647;0.9228929;1618204;1.838911e+008
667.802;0.2876784;-0.4844749;1708.189;176.5132;1;1;0;0.9060737;0.9019935;1567681;1.781125e+008
669.802;0.280982;-0.4743358;1654.46;170.9612;1;1;0;0.8849826;0.8810896;1518372;1.724742e+008
671.802;0.2743927;-0.4642009;1601.303;165.4683;1;1;0;0.864229;0.8605159;1469587;1.668983e+008
673.802;0.2675891;-0.4538963;1547.011;159.8582;1;1;0;0.8428004;0.8392686;1419761;1.612054e+008
675.802;0.2609463;-0.4438058;1493.535;154.3322;1;1;0;0.821878;0.8185189;1370683;1.556006e+008
677.802;0.254357;-0.4341299;1440.982;148.9018;1;1;0;0.8011243;0.7979324;1322454;1.500947e+008
679.802;0.2475534;-0.4240618;1387.822;143.4086;1;1;0;0.7796957;0.7766718;1273666;1.445267e+008
681.802;0.2409106;-0.41423;1335.275;137.9787;1;1;0;0.7587734;0.7559092;1225442;1.390257e+008
683.8021;0.2343213;-0.4047983;1284.715;132.7542;1;1;0;0.7380198;0.7353097;1179040;1.337339e+008
685.8021;0.2275713;-0.3949006;1232.802;127.3898;1;1;0;0.71676;0.7142035;1131398;1.283029e+008
687.8021;0.2208749;-0.3851394;1181.806;122.1201;1;1;0;0.6956689;0.6932602;1084596;1.229697e+008
689.8021;0.2143392;-0.3756681;1133.054;117.0825;1;1;0;0.675084;0.6728155;1039854;1.178729e+008
691.8021;0.2076427;-0.3659923;1083.083;111.9188;1;1;0;0.6539929;0.6518637;993993.4;1.126507e+008
693.8021;0.2009463;-0.3562979;1033.7;106.8159;1;1;0;0.6329017;0.6309073;948672.4;1.074919e+008
695.8021;0.1944106;-0.3468199;985.9495;101.8817;1;1;0;0.6123168;0.6104498;904849.8;1.025055e+008
697.8021;0.1876606;-0.3371894;936.9305;96.81635;1;1;0;0.591057;0.5893171;859862.9;9.738859e+007
699.8021;0.1810177;-0.3276701;889.5252;91.91779;1;1;0;0.5701346;0.5685155;816356.9;9.244184e+007
701.8021;0.1744285;-0.3183307;843.6436;87.17668;1;1;0;0.549381;0.5478774;774249.3;8.765561e+007
703.8021;0.167732;-0.3089978;796.908;82.34733;1;1;0;0.5282899;0.5268993;731358.1;8.278236e+007
705.8021;0.1610356;-0.2994766;750.7422;77.57685;1;1;0;0.5071988;0.5059168;688989.6;7.797032e+007
707.8021;0.1543928;-0.2899617;706.2303;72.97728;1;1;0;0.4862764;0.4850979;648139.1;7.333215e+007
709.8021;0.1476963;-0.2805907;661.3351;68.3381;1;1;0;0.4651853;0.4641067;606936.7;6.865599e+007
711.8021;0.1410535;-0.2715397;616.9203;63.74856;1;1;0;0.4442629;0.443279;566175.3;6.403177e+007
713.8021;0.1343571;-0.2627205;572.5731;59.16601;1;1;0;0.4231718;0.422279;525475.9;5.941638e+007
715.8021;0.1276606;-0.2539764;528.6887;54.63127;1;1;0;0.4020807;0.4012745;485201.2;5.485093e+007
717.8021;0.1210714;-0.2459908;486.0207;50.22224;1;1;0;0.3813271;0.3806019;446042.8;5.041375e+007
719.8021;0.1143214;-0.2380985;442.9297;45.7695;1;1;0;0.3600672;0.3594206;406496.4;4.59343e+007
721.8021;0.1076249;-0.2307839;401.2361;41.46115;1;1;0;0.3389761;0.3384029;368232.3;4.160169e+007
723.8021;0.1010356;-0.2240018;361.148;37.3187;1;1;0;0.3182225;0.3177173;331441.6;3.743746e+007
725.8021;0.09428565;-0.2175964;320.6821;33.13721;1;1;0;0.2969627;0.2965226;294304.3;3.323562e+007
727.8021;0.08758922;-0.2115028;282.1635;29.15695;1;1;0;0.2758716;0.2754917;258954;2.923739e+007
729.8021;0.08099994;-0.2061252;244.9088;25.30729;1;1;0;0.2551179;0.2547931;224763.7;2.537185e+007
731.8021;0.07424996;-0.200546;208.1171;21.50547;1;1;0;0.2338581;0.2335851;190998.3;2.155576e+007
733.1281;0.06996424;-0.1970846;186.0521;19.22542;1;1;0;0.2203598;0.2201174;170748.3;1.926779e+007