File: Ensayos/Graficos/EspC/EspC50ext125.raw
"Test Type";"Manual"
"Method Name:";"C:\INSTRON\user\template\CYCLE.MTM"
"Name:";""
"Operator ID:";""
"Company:";""
"Lab name:";""
"Test date:";"04/04/2017"
"Temperature:";""
"Humidity:";""
"Note 1:";""
"Note 2:";""
"Note 3:";""
"Geometry:";"Rectangular"
"Specimen";1
"Specimen name:";""
"Width:";0.250000;"in"
"Thickness:";0.060000;"in"
"Length:";1.250000;"in"
"Diameter:";0.039370;"in"
"Inner diameter:";0.019685;"in"
"Outer diameter:";0.039370;"in"
"Wall thickness:";0.019685;"in"
"Area:";0.015000;"in*in"
"Linear density:";1.000000;"den"
"Sled weight:";2.204623;"lbf"
"Loading span:";0.000000;"mm"
"Support span:";1.000000;"mm"
"Span ratio:";"2"
"Fixture type:";"3-point"
"Comment:";""
"Included"
"Final Width:";0.250000;"in"
"Final Thickness:";0.060000;"in"
"Final Length:";1.250000;"in"
"Final Diameter:";0.039370;"in"
"Final Inner diameter:";0.019685;"in"
"Final Outer diameter:";0.039370;"in"
"Final Wall thickness:";0.019685;"in"
"Final Area:";0.015000;"in*in"
"Final Linear density:";1.000000;"den"
"Time sec";"Extension mm";"Strain 1 %";"Load N";"Stress MPa";"Cycle Count ";"Total Cycle Count ";"Repetitions Count ";"Strain [Exten.] %";"True strain %";"Tenacity gf/tex";"True stress Pa"
0;3.540266;-3.67139e-005;49.66997;5.132574;0;0;0;11.15044;10.57144;45584.34;5704878
4;3.553658;-0.000137038;49.57808;5.123079;0;0;0;11.19263;10.60939;45500.02;5696486
8;3.566891;-6.955437e-005;49.67763;5.133366;0;0;0;11.2343;10.64686;45591.38;5710063
12;3.58023;-3.373541e-005;49.77395;5.143318;0;0;0;11.27631;10.68462;45679.77;5723295
16;3.593515;-5.528942e-005;49.79765;5.145767;0;0;0;11.31816;10.72222;45701.52;5728173
20;3.606908;5.122653e-005;49.74441;5.140266;0;0;0;11.36034;10.76011;45652.66;5724218
24;3.620301;-0.0002514702;50.21023;5.1884;0;0;0;11.40252;10.79798;46080.16;5780009
28;3.633533;-0.003327346;88.58231;9.153523;0;0;0;11.4442;10.83538;81295.93;1.020107e+007
32;3.647034;-0.009353536;151.7632;15.68223;0;0;0;11.48672;10.87353;139279.8;1.74836e+007
36;3.660372;-0.01735125;223.2376;23.06793;0;0;0;11.52873;10.91121;204875.1;2.572737e+007
40;3.673605;-0.02660835;297.878;30.78079;0;0;0;11.57041;10.94857;273375.9;3.434225e+007
44;3.687051;-0.03733065;379.6701;39.23265;0;0;0;11.61276;10.98652;348440.2;4.378865e+007
48;3.700337;-0.04936156;466.1235;48.16619;0;0;0;11.6546;11.024;427782.3;5.377977e+007
52;3.713623;-0.06298158;558.7743;57.74012;0;0;0;11.69645;11.06147;512812.1;6.449367e+007
56;3.726962;-0.07810717;658.1779;68.01185;0;0;0;11.73846;11.09908;604039.2;7.59954e+007
60;3.740194;-0.09380508;760.361;78.5708;0;0;0;11.78014;11.13637;697817.3;8.782655e+007
64;3.753587;-0.1100502;867.1031;89.60084;0;0;0;11.82232;11.1741;795779.2;1.001937e+008
68;3.766873;-0.1265024;976.9411;100.9508;0;0;0;11.86417;11.21151;896582.4;1.129278e+008
72;3.780265;-0.143505;1090.98;112.7349;0;0;0;11.90635;11.24922;1001241;1.261575e+008
76;3.793658;-0.1609422;1207.608;124.7864;0;0;0;11.94853;11.2869;1108275;1.396965e+008
80;3.80689;-0.1785788;1324.627;136.8784;0;0;0;11.99021;11.32412;1215670;1.532904e+008
84.00001;3.820391;-0.1974533;1445.951;149.4153;0;0;0;12.03273;11.36208;1327014;1.67394e+008
88.00001;3.83373;-0.2171816;1569.043;162.1348;0;0;0;12.07474;11.39958;1439981;1.817121e+008
92.00001;3.846962;-0.2372197;1691.797;174.8194;0;0;0;12.11642;11.43676;1552638;1.960012e+008
96.00001;3.860408;-0.2584207;1816.389;187.6939;0;0;0;12.15877;11.47452;1666982;2.105152e+008
100;3.87364;-0.2799218;1940.38;200.5064;0;0;0;12.20044;11.51167;1780774;2.24969e+008
104;3.886926;-0.3018272;2066.329;213.5211;0;0;0;12.24229;11.54896;1896363;2.39661e+008
108;3.900265;-0.3247265;2195.231;226.841;0;0;0;12.2843;11.58639;2014662;2.547069e+008
112;3.913551;-0.3474558;2326.121;240.3663;0;0;0;12.32615;11.62365;2134785;2.699942e+008
116;3.926943;-0.370692;2460.62;254.2646;0;0;0;12.36833;11.66119;2258221;2.857129e+008
120;3.940176;-0.3936802;2595.415;268.1934;0;0;0;12.41;11.69827;2381928;3.014762e+008
124;3.953622;-0.4164372;2733.897;282.5032;0;0;0;12.45235;11.73594;2509019;3.176815e+008
128;3.967015;-0.4392802;2872.511;296.8268;0;0;0;12.49454;11.77345;2636232;3.339139e+008
132;3.980247;-0.4621447;3011.365;311.175;0;0;0;12.53621;11.81049;2763664;3.501846e+008
136;3.993694;-0.4857168;3153.408;325.8528;0;0;0;12.57856;11.84811;2894023;3.668404e+008
140;4.007033;-0.509818;3296.135;340.6013;0;0;0;12.62058;11.88543;3025010;3.835871e+008
144;4.020319;-0.534359;3438.431;355.3052;0;0;0;12.66242;11.92257;3155601;4.002955e+008
148;4.033712;-0.5596631;3584.526;370.4017;0;0;0;12.7046;11.96001;3289679;4.174598e+008
152;4.046997;-0.5848922;3729.379;385.3699;0;0;0;12.74645;11.99713;3422617;4.344909e+008
156;4.060229;-0.610551;3876.766;400.6;0;0;0;12.78812;12.03409;3557881;4.518292e+008
160;4.073569;-0.6368594;4024.236;415.8386;0;0;0;12.83014;12.07133;3693221;4.691912e+008
164;4.086854;-0.6630684;4169.979;430.8987;0;0;0;12.87198;12.10841;3826976;4.863639e+008
168;4.100301;-0.6898591;4317.494;446.1419;0;0;0;12.91433;12.14592;3962357;5.037582e+008
172;4.113533;-0.7169785;4461.464;461.0189;0;0;0;12.95601;12.18283;4094485;5.207486e+008
176;4.12698;-0.7454894;4606.82;476.0391;0;0;0;12.99836;12.22031;4227885;5.379163e+008
180;4.140372;-0.7746421;4750.586;490.8949;0;0;0;13.04054;12.25764;4359825;5.549103e+008
184;4.153604;-0.8034;4892.592;505.5688;0;0;0;13.08222;12.2945;4490150;5.717084e+008
188;4.167051;-0.8324488;5035.42;520.3278;0;0;0;13.12457;12.33194;4621230;5.886186e+008
192;4.18039;-0.8616342;5176.48;534.904;0;0;0;13.16658;12.36907;4750686;6.053325e+008
196;4.193622;-0.8909909;5313.417;549.0542;0;0;0;13.20826;12.40589;4876360;6.215747e+008
200;4.207015;-0.9210969;5452.005;563.375;0;0;0;13.25044;12.44315;5003548;6.380247e+008
204;4.220247;-0.9511515;5586.44;577.2666;0;0;0;13.29212;12.47994;5126925;6.539975e+008
208;4.233587;-0.9812962;5720.655;591.1356;0;0;0;13.33413;12.51702;5250101;6.699583e+008
212;4.246873;-1.009695;5853.732;604.8868;0;0;0;13.37598;12.55393;5372231;6.857963e+008
214.856;4.243175;-1.010354;5775.195;596.7714;0;0;0;13.36433;12.54366;5300154;6.765259e+008
218.856;4.22973;-0.9946384;5564.19;574.9675;0;0;0;13.32198;12.5063;5106506;6.515645e+008
222.856;4.21639;-0.977265;5362.667;554.1434;0;0;0;13.27997;12.46922;4921559;6.277334e+008
226.856;4.203158;-0.9586428;5171.436;534.3828;0;0;0;13.23829;12.43242;4746058;6.05126e+008
230.856;4.189765;-0.9382747;4982.254;514.834;0;0;0;13.19611;12.39516;4572437;5.82772e+008
234.856;4.176479;-0.9172808;4800.973;496.1015;0;0;0;13.15427;12.35819;4406067;5.613601e+008
238.856;4.163247;-0.8950152;4623.011;477.7121;0;0;0;13.11259;12.32135;4242743;5.403525e+008
242.856;4.149854;-0.8720373;4446.132;459.4346;0;0;0;13.07041;12.28405;4080414;5.194845e+008
246.856;4.136569;-0.8483142;4273.417;441.5873;0;0;0;13.02856;12.24704;3921905;4.991198e+008
250.856;4.123176;-0.8240821;4104.433;424.1256;0;0;0;12.98638;12.20971;3766822;4.792042e+008
254.856;4.10989;-0.799161;3937.618;406.888;0;0;0;12.94454;12.17267;3613728;4.595578e+008
258.856;4.096497;-0.7738352;3771.992;389.7733;0;0;0;12.90235;12.13531;3461726;4.400633e+008
262.856;4.083104;-0.7485627;3609.208;372.9522;0;0;0;12.86017;12.09794;3312331;4.209145e+008
266.856;4.069872;-0.7238922;3451.094;356.6137;0;0;0;12.8185;12.06101;3167223;4.023262e+008
270.856;4.056372;-0.6984923;3291.9;340.1636;0;0;0;12.77598;12.02331;3021123;3.836229e+008
274.856;4.043086;-0.6740233;3138.345;324.2963;0;0;0;12.73413;11.9862;2880199;3.655926e+008
278.856;4.029854;-0.6499671;2988.618;308.8245;0;0;0;12.69245;11.94923;2742788;3.480219e+008
282.856;4.016462;-0.6256776;2839.919;293.4589;0;0;0;12.65027;11.91179;2606320;3.305822e+008
286.856;4.003176;-0.6018384;2695.679;278.5541;0;0;0;12.60843;11.87464;2473945;3.136754e+008
290.856;3.989944;-0.5778913;2558.511;264.38;0;0;0;12.56675;11.83762;2348059;2.976039e+008
294.856;3.976551;-0.5531113;2421.804;250.2536;0;0;0;12.52457;11.80014;2222598;2.815968e+008
298.856;3.963211;-0.5286353;2288.019;236.4291;0;0;0;12.48256;11.7628;2099817;2.659415e+008
302.856;3.949819;-0.5039904;2156.045;222.7918;0;0;0;12.44037;11.72529;1978699;2.505079e+008
306.856;3.936533;-0.479633;2027.698;209.5293;0;0;0;12.39853;11.68807;1860909;2.355078e+008
310.856;3.92314;-0.4547467;1899.787;196.3117;0;0;0;12.35635;11.65053;1743519;2.205686e+008
314.856;3.909747;-0.4289148;1777.204;183.6448;0;0;0;12.31416;11.61298;1631020;2.062591e+008
318.856;3.896515;-0.4032438;1660.219;171.5563;0;0;0;12.27249;11.57587;1523657;1.926105e+008
322.856;3.883016;-0.3767751;1544.675;159.6167;0;0;0;12.22997;11.53799;1417617;1.791378e+008
326.856;3.86973;-0.3514915;1433.692;148.1485;0;0;0;12.18812;11.5007;1315763;1.66205e+008
330.856;3.856498;-0.3273762;1328.875;137.3174;0;0;0;12.14645;11.46354;1219568;1.539966e+008
334.856;3.843105;-0.3033137;1225.746;126.6607;0;0;0;12.10427;11.42592;1124922;1.419921e+008
338.856;3.829873;-0.2803708;1126.379;116.3927;0;0;0;12.06259;11.38874;1033728;1.304327e+008
342.856;3.816587;-0.258406;1029.919;106.4251;0;0;0;12.02075;11.35139;945202.3;1.192182e+008
346.856;3.803194;-0.2372696;935.4595;96.66434;0;0;0;11.97856;11.31373;858512.9;1.082433e+008
350.856;3.789855;-0.2167251;843.8447;87.19746;0;0;0;11.93655;11.2762;774433.9;9.760583e+007
354.856;3.776515;-0.1970557;754.8457;78.00088;0;0;0;11.89454;11.23866;692755.6;8.727872e+007
358.856;3.76323;-0.1776671;668.0782;69.03488;0;0;0;11.85269;11.20126;613125.1;7.721738e+007
362.856;3.749783;-0.1581866;582.2579;60.16677;0;0;0;11.81034;11.16339;534364.1;6.727267e+007
366.856;3.73639;-0.1392807;500.4868;51.71708;0;0;0;11.76816;11.12565;459319.1;5.780323e+007
370.856;3.723158;-0.1216373;422.442;43.65243;0;0;0;11.72648;11.08836;387693.9;4.877132e+007
374.856;3.709712;-0.1048363;348.1277;35.97327;0;0;0;11.68413;11.05045;319492.3;4.017643e+007
378.856;3.696426;-0.09034194;279.9476;28.92798;0;0;0;11.64229;11.01297;256920.4;3.229586e+007
382.856;3.683194;-0.07804627;216.9882;22.42216;0;0;0;11.60061;10.97563;199139.7;2.502326e+007
386.856;3.669801;-0.06734568;159.0864;16.43896;0;0;0;11.55843;10.93783;146000.6;1.833904e+007
390.856;3.656516;-0.05850226;107.4594;11.10416;0;0;0;11.51658;10.90031;98620.3;1.238298e+007
394.856;3.64323;-0.05166024;64.00115;6.613465;0;0;0;11.47474;10.86278;58736.71;7372343
397.822;3.633319;-0.04905306;48.2595;4.986825;1;1;0;11.44352;10.83478;44289.9;5557494
401.822;3.646658;-0.05276999;84.68221;8.750512;1;1;0;11.48554;10.87247;77716.64;9755556
405.822;3.660051;-0.05974519;146.1558;15.1028;1;1;0;11.52772;10.9103;134133.7;1.684381e+007
409.822;3.67323;-0.06867098;213.7019;22.08257;1;1;0;11.56923;10.94751;196123.7;2.463735e+007
413.822;3.686676;-0.07918809;289.0999;29.87371;1;1;0;11.61158;10.98546;265319.8;3.334252e+007
417.822;3.699908;-0.09083211;368.8863;38.11833;1;1;0;11.65325;11.02279;338543.4;4.256036e+007
421.822;3.713194;-0.1049721;456.0118;47.12131;1;1;0;11.6951;11.06026;418502.3;5.263219e+007
425.822;3.726533;-0.1208416;549.99;56.83241;1;1;0;11.73711;11.09787;504750.3;6.35029e+007
429.822;3.739872;-0.1377538;649.1597;67.07997;1;1;0;11.77913;11.13546;595762.8;7.498141e+007
433.822;3.753265;-0.1551342;752.4413;77.75242;1;1;0;11.82131;11.17319;690548.9;8.694377e+007
437.822;3.766498;-0.1728236;859.3541;88.80009;1;1;0;11.86299;11.21046;788667.6;9.933444e+007
441.822;3.779944;-0.1910703;971.6775;100.4069;1;1;0;11.90534;11.24831;891751.8;1.123607e+008
445.822;3.793337;-0.209697;1084.96;112.1127;1;1;0;11.94752;11.286;995716.1;1.255074e+008
449.822;3.806569;-0.2286799;1198.982;123.895;1;1;0;11.98919;11.32322;1100359;1.38749e+008
453.822;3.820015;-0.2487314;1317.533;136.1453;1;1;0;12.03154;11.36103;1209158;1.525257e+008
457.822;3.833355;-0.269696;1437.764;148.5693;1;1;0;12.07356;11.39852;1319501;1.665069e+008
461.822;3.846587;-0.290722;1559.448;161.1433;1;1;0;12.11523;11.4357;1431175;1.806662e+008
465.822;3.85998;-0.3127187;1683.124;173.9231;1;1;0;12.15742;11.47332;1544678;1.950677e+008
469.822;3.873212;-0.3346557;1807.178;186.7421;1;1;0;12.19909;11.51047;1658528;2.095229e+008
473.822;3.886551;-0.3569184;1935.076;199.9583;1;1;0;12.24111;11.54791;1775906;2.244354e+008
477.822;3.899837;-0.3795386;2063.665;213.2459;1;1;0;12.28295;11.58518;1893918;2.394387e+008
481.822;3.913176;-0.402976;2194.787;226.7951;1;1;0;12.32496;11.62259;2014254;2.547475e+008
485.822;3.926622;-0.4266034;2330.003;240.7675;1;1;0;12.36731;11.66029;2138348;2.705439e+008
489.822;3.939855;-0.4489502;2465.689;254.7883;1;1;0;12.40899;11.69737;2262872;2.86405e+008
493.822;3.953301;-0.4716063;2604.282;269.1097;1;1;0;12.45134;11.73504;2390066;3.026175e+008
497.822;3.966694;-0.4938877;2744.575;283.6066;1;1;0;12.49352;11.77255;2518819;3.190391e+008
501.822;3.979926;-0.5163035;2884.393;298.0545;1;1;0;12.5352;11.80959;2647136;3.354163e+008
505.822;3.993372;-0.5393925;3026.792;312.7691;1;1;0;12.57755;11.84721;2777822;3.521078e+008
509.822;4.006658;-0.5628643;3169.008;327.4648;1;1;0;12.6194;11.88438;2908340;3.687889e+008
513.822;4.01989;-0.5866911;3312.089;342.2498;1;1;0;12.66107;11.92138;3039652;3.855823e+008
517.822;4.033283;-0.6108172;3459.514;357.4839;1;1;0;12.70325;11.95881;3174951;4.028959e+008
521.822;4.046569;-0.6347167;3606.569;372.6795;1;1;0;12.7451;11.99593;3309909;4.201779e+008
525.822;4.059855;-0.6592103;3756.646;388.1875;1;1;0;12.78694;12.03304;3447641;4.378248e+008
529.822;4.073194;-0.6837058;3905.67;403.5867;1;1;0;12.82896;12.07028;3584408;4.553627e+008
533.822;4.086533;-0.7087447;4054.665;418.9829;1;1;0;12.87097;12.10751;3721147;4.7291e+008
537.822;4.09998;-0.7344534;4204.691;434.4856;1;1;0;12.91332;12.14503;3858833;4.905922e+008
541.822;4.113158;-0.7602181;4350.931;449.5971;1;1;0;12.95483;12.18178;3993044;5.078416e+008
545.822;4.126658;-0.7866748;4500.835;465.0872;1;1;0;12.99735;12.21942;4130617;5.255362e+008
549.822;4.139997;-0.8125613;4649.464;480.4456;1;1;0;13.03936;12.25659;4267021;5.430927e+008
553.822;4.153283;-0.8384606;4798.033;495.7978;1;1;0;13.08121;12.2936;4403369;5.606541e+008
557.822;4.166729;-0.8649924;4947.566;511.2495;1;1;0;13.12356;12.33105;4540602;5.783436e+008
561.822;4.180015;-0.8905993;5094.474;526.43;1;1;0;13.1654;12.36803;4675426;5.957366e+008
565.822;4.193194;-0.9165651;5239.968;541.4645;1;1;0;13.20691;12.4047;4808953;6.129752e+008
569.822;4.206587;-0.9421851;5388.376;556.8;1;1;0;13.24909;12.44196;4945154;6.30571e+008
573.822;4.219819;-0.9679126;5533.971;571.8448;1;1;0;13.29077;12.47875;5078772;6.478473e+008
577.822;4.233211;-0.9928028;5681.087;587.0469;1;1;0;13.33295;12.51597;5213787;6.653175e+008
581.822;4.246497;-1.017116;5824.323;601.8478;1;1;0;13.37479;12.55289;5345241;6.823438e+008
583.866;4.246818;-1.02149;5810.066;600.3746;1;1;0;13.37581;12.55378;5332157;6.806796e+008
587.866;4.233372;-1.006587;5595.799;578.2338;1;1;0;13.33346;12.51642;5135515;6.553323e+008
591.866;4.219979;-0.989707;5391.912;557.1654;1;1;0;13.29127;12.4792;4948399;6.312198e+008
595.866;4.206694;-0.9716308;5198.312;537.16;1;1;0;13.24943;12.44225;4770723;6.083307e+008
599.866;4.193462;-0.9517267;5010.17;517.7186;1;1;0;13.20775;12.40545;4598057;5.860976e+008
603.866;4.180122;-0.9309199;4826.382;498.7271;1;1;0;13.16574;12.36833;4429386;5.643882e+008
607.866;4.166783;-0.9092831;4647.942;480.2883;1;1;0;13.12373;12.3312;4265624;5.433201e+008
611.866;4.153497;-0.8861617;4471.49;462.0549;1;1;0;13.08188;12.2942;4103686;5.225004e+008
615.866;4.140158;-0.8628957;4297.858;444.1129;1;1;0;13.03987;12.25704;3944336;5.020246e+008
619.866;4.126765;-0.8386036;4127.448;426.5038;1;1;0;12.99769;12.21972;3787943;4.819394e+008
623.866;4.113372;-0.8138691;3960.187;409.2202;1;1;0;12.9555;12.18238;3634441;4.622367e+008
627.866;4.100087;-0.7889416;3795.417;392.1939;1;1;0;12.91366;12.14533;3483224;4.428405e+008
631.866;4.086694;-0.7633647;3631.392;375.2446;1;1;0;12.87148;12.10796;3332691;4.235442e+008
635.866;4.073301;-0.7384054;3471.32;358.7038;1;1;0;12.82929;12.07058;3185786;4.04723e+008
639.866;4.060069;-0.7136808;3315.308;342.5826;1;1;0;12.78762;12.03364;3042606;3.863907e+008
643.866;4.046622;-0.6890044;3159.143;326.4454;1;1;0;12.74527;11.99608;2899287;3.680518e+008
647.866;4.03339;-0.6650478;3008.376;310.8661;1;1;0;12.70359;11.95911;2760921;3.503573e+008
651.866;4.020158;-0.6412943;2860.225;295.5572;1;1;0;12.66192;11.92213;2624956;3.329804e+008
655.866;4.006765;-0.6171142;2713.915;280.4384;1;1;0;12.61973;11.88468;2490680;3.15829e+008
659.866;3.993479;-0.5935004;2573.694;265.9489;1;1;0;12.57789;11.84751;2361994;2.993996e+008
663.866;3.98014;-0.569494;2437.425;251.8678;1;1;0;12.53588;11.81019;2236934;2.834416e+008
667.866;3.966801;-0.5454049;2303.229;238.0008;1;1;0;12.49386;11.77285;2113776;2.677363e+008
671.866;3.953408;-0.5212596;2170.627;224.2986;1;1;0;12.45168;11.73534;1992081;2.522275e+008
675.866;3.940069;-0.4969921;2040.769;210.8799;1;1;0;12.40967;11.69797;1872905;2.370493e+008
679.866;3.926783;-0.4726114;1913.294;197.7074;1;1;0;12.36782;11.66074;1755915;2.221595e+008
683.866;3.913337;-0.4478244;1787.674;184.7267;1;1;0;12.32547;11.62304;1640628;2.074951e+008
687.866;3.899998;-0.4222408;1668.469;172.4088;1;1;0;12.28346;11.58563;1531229;1.935866e+008
691.866;3.886765;-0.3966187;1554.005;160.5808;1;1;0;12.24178;11.54851;1426180;1.802388e+008
695.866;3.873319;-0.3711899;1441.279;148.9325;1;1;0;12.19943;11.51077;1322726;1.671014e+008
699.866;3.860033;-0.3467761;1334.73;137.9224;1;1;0;12.15759;11.47347;1224942;1.546904e+008
703.866;3.846855;-0.3229718;1232.843;127.3941;1;1;0;12.11608;11.43646;1131435;1.428292e+008
707.866;3.833462;-0.2995874;1131.75;116.9477;1;1;0;12.0739;11.39883;1038658;1.310679e+008
711.866;3.820176;-0.2772789;1035.132;106.9638;1;1;0;12.03205;11.36148;949986.6;1.198338e+008
715.866;3.806783;-0.2558841;940.7792;97.21405;1;1;0;11.98987;11.32382;863395.1;1.088699e+008
719.866;3.793444;-0.2349924;848.8305;87.71266;1;1;0;11.94786;11.2863;779009.6;9.819245e+007
723.866;3.780051;-0.2147292;758.9329;78.42323;1;1;0;11.90567;11.24861;696506.6;8.776004e+007
727.866;3.766712;-0.1948242;671.8459;69.42421;1;1;0;11.86366;11.21106;616582.9;7.766046e+007
731.866;3.753426;-0.1753761;586.6169;60.6172;1;1;0;11.82181;11.17365;538364.5;6.778325e+007
735.866;3.73998;-0.1558657;503.9182;52.07166;1;1;0;11.77946;11.13577;462468.2;5.820542e+007
739.866;3.726641;-0.1372709;425.8284;44.00236;1;1;0;11.73745;11.09817;390801.7;4.916711e+007
743.866;3.713408;-0.1200069;352.2821;36.40256;1;1;0;11.69577;11.06087;323305;4.066012e+007
747.866;3.700015;-0.1045499;282.8048;29.22322;1;1;0;11.65359;11.0231;259542.6;3.262878e+007
751.866;3.68673;-0.09126594;219.4643;22.67802;1;1;0;11.61175;10.98561;201412.1;2.531133e+007
755.866;3.673498;-0.08035678;162.6669;16.80895;1;1;0;11.57007;10.94827;149286.7;1.875376e+007
759.866;3.660105;-0.07063435;110.7596;11.44519;1;1;0;11.52789;10.91045;101649.1;1.276457e+007
763.866;3.646819;-0.06343022;66.53439;6.875234;1;1;0;11.48604;10.87292;61061.57;7664926
767.866;3.633426;-0.06023826;47.88243;4.947861;1;1;0;11.44386;10.83508;43943.84;5514087
770.8341;3.636855;-0.06013316;48.53242;5.015027;2;2;0;11.45466;10.84477;44540.37;5589481
774.8341;3.650248;-0.06437507;88.89281;9.185609;2;2;0;11.49684;10.88261;81580.9;1.024166e+007
778.8341;3.663533;-0.07169419;149.9868;15.49866;2;2;0;11.53869;10.92013;137649.6;1.728701e+007
782.8341;3.676926;-0.08100568;219.2777;22.65874;2;2;0;11.58087;10.95794;201240.9;2.528282e+007
786.8341;3.690266;-0.09172116;293.8166;30.3611;2;2;0;11.62288;10.99559;269648.6;3.388994e+007
790.8341;3.703498;-0.1042946;374.0044;38.6472;2;2;0;11.66456;11.03292;343240.5;4.315523e+007
794.8341;3.716837;-0.1190927;461.8991;47.72967;2;2;0;11.70657;11.07054;423905.4;5.331718e+007
798.8341;3.730123;-0.1355921;556.1188;57.46572;2;2;0;11.74842;11.10799;510375;6.421703e+007
802.8341;3.743462;-0.1530521;655.3901;67.72378;2;2;0;11.79043;11.14558;601480.8;7.570871e+007
806.8341;3.756748;-0.1707652;758.2978;78.35759;2;2;0;11.83228;11.183;695923.7;8.762908e+007
810.8341;3.77014;-0.1890883;867.0282;89.59309;2;2;0;11.87446;11.22071;795710.4;1.002318e+008
814.8341;3.783533;-0.2075542;978.3278;101.0941;2;2;0;11.91664;11.25841;897855.1;1.131411e+008
818.8341;3.796766;-0.2262548;1089.994;112.6329;2;2;0;11.95832;11.29564;1000336;1.261019e+008
822.8341;3.810265;-0.2461641;1205.806;124.6002;2;2;0;12.00084;11.33361;1106622;1.395533e+008
826.8341;3.823605;-0.2668049;1323.824;136.7954;2;2;0;12.04285;11.37112;1214932;1.532694e+008
830.8341;3.836837;-0.2876181;1443.862;149.1993;2;2;0;12.08453;11.40831;1325096;1.672294e+008
834.8341;3.850283;-0.3097658;1566.694;161.892;2;2;0;12.12688;11.44609;1437825;1.815244e+008
838.8341;3.863569;-0.3314951;1690.129;174.647;2;2;0;12.16872;11.4834;1551107;1.958994e+008
842.8341;3.876801;-0.353563;1815.346;187.5862;2;2;0;12.2104;11.52055;1666024;2.104912e+008
846.8341;3.89014;-0.3758079;1943.198;200.7976;2;2;0;12.25241;11.55798;1783360;2.254001e+008
850.8341;3.90348;-0.3988919;2071.399;214.045;2;2;0;12.29442;11.5954;1901015;2.403606e+008
854.8341;3.916819;-0.4221434;2203.646;227.7105;2;2;0;12.33644;11.63281;2022384;2.558019e+008
858.8341;3.930104;-0.4447727;2338.533;241.6489;2;2;0;12.37828;11.67005;2146176;2.715609e+008
862.8341;3.943497;-0.4672923;2476.884;255.9452;2;2;0;12.42046;11.70758;2273147;2.877348e+008
866.8341;3.95689;-0.4896059;2615.559;270.275;2;2;0;12.46265;11.74509;2400415;3.039584e+008
870.8341;3.970122;-0.5115204;2754.34;284.6157;2;2;0;12.50432;11.78215;2527780;3.202049e+008
874.8341;3.983623;-0.5345351;2896.457;299.3011;2;2;0;12.54684;11.81993;2658208;3.36854e+008
878.8341;3.996962;-0.5573995;3037.356;313.8608;2;2;0;12.58886;11.85726;2787517;3.533723e+008
882.8341;4.010194;-0.5807288;3179.506;328.5497;2;2;0;12.63053;11.89426;2917975;3.700472e+008
886.8341;4.023587;-0.6046845;3325.776;343.6642;2;2;0;12.67271;11.93171;3052213;3.872158e+008
890.8341;4.036872;-0.6281857;3472.329;358.808;2;2;0;12.71456;11.96884;3186711;4.044289e+008
894.8341;4.050104;-0.6519505;3619.214;373.9862;2;2;0;12.75623;12.00581;3321514;4.216928e+008
898.8341;4.063497;-0.6765282;3770.014;389.5689;2;2;0;12.79842;12.04321;3459910;4.394276e+008
902.8341;4.076783;-0.7009923;3917.946;404.8552;2;2;0;12.84026;12.0803;3595674;4.568397e+008
906.8341;4.090176;-0.7261861;4068.24;420.3857;2;2;0;12.88244;12.11768;3733605;4.745416e+008
910.8341;4.103408;-0.751508;4215.828;435.6364;2;2;0;12.92412;12.15459;3869053;4.919386e+008
914.8341;4.116854;-0.7774111;4364.98;451.0488;2;2;0;12.96647;12.19209;4005937;5.095339e+008
918.8341;4.130247;-0.8032317;4514.223;466.4707;2;2;0;13.00865;12.22942;4142904;5.271522e+008
922.8341;4.143479;-0.8291624;4663.258;481.871;2;2;0;13.05033;12.26629;4279680;5.447567e+008
926.8341;4.156926;-0.8547602;4813.727;497.4195;2;2;0;13.09268;12.30375;4417772;5.62545e+008
930.8341;4.170265;-0.8802704;4963.053;512.8498;2;2;0;13.13469;12.34089;4554815;5.802111e+008
934.8341;4.183497;-0.9055861;5110.453;528.0812;2;2;0;13.17637;12.37772;4690091;5.976631e+008
938.8341;4.196944;-0.9308309;5260.617;543.5982;2;2;0;13.21872;12.41513;4827903;6.154549e+008
942.8341;4.210176;-0.9553361;5407.915;558.819;2;2;0;13.2604;12.45194;4963085;6.329206e+008
946.8341;4.223461;-0.9795909;5556.607;574.1838;2;2;0;13.30224;12.48888;5099546;6.505632e+008
950.8341;4.236801;-1.002819;5705.916;589.6125;2;2;0;13.34425;12.52595;5236574;6.682919e+008
954.8341;4.250086;-1.025657;5853.958;604.9102;2;2;0;13.3861;12.56286;5372438;6.858841e+008
958.8341;4.263479;-1.048911;5997.706;619.7642;2;2;0;13.42828;12.60006;5504362;7.029879e+008
962.8341;4.276765;-1.07268;6138.202;634.2822;2;2;0;13.47013;12.63694;5633302;7.197208e+008
966.8341;4.290158;-1.097496;6281.841;649.1249;2;2;0;13.51231;12.67411;5765126;7.368366e+008
970.8341;4.303551;-1.122268;6423.14;663.7258;2;2;0;13.55449;12.71126;5894802;7.536904e+008
974.8341;4.316837;-1.146504;6561.664;678.04;2;2;0;13.59634;12.74811;6021932;7.702286e+008
978.8341;4.330283;-1.170623;6701.466;692.4862;2;2;0;13.63869;12.78538;6150235;7.869322e+008
982.8341;4.343568;-1.19333;6838.949;706.6927;2;2;0;13.68053;12.8222;6276408;8.033721e+008
986.8341;4.356854;-1.215986;6976.012;720.856;2;2;0;13.72238;12.859;6402197;8.197746e+008
990.8341;4.370247;-1.239068;7113.103;735.0221;2;2;0;13.76456;12.89608;6528012;8.361946e+008
994.8341;4.383479;-1.262721;7243.086;748.4537;2;2;0;13.80623;12.93271;6647303;8.517869e+008
998.8341;4.396765;-1.286187;7372.847;761.8624;2;2;0;13.84808;12.96947;6766390;8.673657e+008
1002.834;4.410104;-1.310437;7501.554;775.1621;2;2;0;13.89009;13.00637;6884511;8.828329e+008
1006.834;4.423444;-1.334601;7626.983;788.1232;2;2;0;13.93211;13.04325;6999623;8.979253e+008
1010.834;4.436837;-1.358812;7751.947;801.0361;2;2;0;13.97429;13.08027;7114308;9.129752e+008
1014.834;4.450069;-1.38233;7871.92;813.4334;2;2;0;14.01596;13.11683;7224413;9.274439e+008
1018.834;4.463568;-1.406452;7992.442;825.8873;2;2;0;14.05848;13.15411;7335021;9.419945e+008
1022.834;4.476908;-1.430402;8109.532;837.9866;2;2;0;14.1005;13.19094;7442479;9.561469e+008
1026.834;4.490193;-1.45397;8224.955;849.9137;2;2;0;14.14234;13.22761;7548408;9.701114e+008
1030.834;4.503586;-1.477466;8339.697;861.7704;2;2;0;14.18452;13.26456;7653712;9.840084e+008
1034.834;4.516926;-1.501158;8450.516;873.2217;2;2;0;14.22654;13.30135;7755415;9.974509e+008
1038.834;4.530158;-1.525159;8558.589;884.3893;2;2;0;14.26821;13.33783;7854599;1.010576e+009
1042.834;4.543551;-1.54888;8668.029;895.6981;2;2;0;14.3104;13.37473;7955037;1.023876e+009
1046.834;4.556783;-1.572732;8767.814;906.0093;2;2;0;14.35207;13.41118;8046614;1.03604e+009
1050.834;4.570122;-1.59818;8870.662;916.6368;2;2;0;14.39408;13.44792;8141002;1.048578e+009
1054.834;4.583461;-1.622289;8973.311;927.244;2;2;0;14.4361;13.48464;8235208;1.061102e+009
1058.834;4.596801;-1.647091;9073.935;937.6418;2;2;0;14.47811;13.52135;8327555;1.073395e+009
1062.834;4.610193;-1.671758;9174.638;948.0479;2;2;0;14.52029;13.55819;8419974;1.085707e+009
1066.834;4.623426;-1.696756;9275.039;958.4225;2;2;0;14.56197;13.59457;8512116;1.097988e+009
1070.834;4.636926;-1.722769;9376.789;968.9368;2;2;0;14.60449;13.63168;8605497;1.110445e+009
1074.834;4.650265;-1.749449;9477.494;979.343;2;2;0;14.6465;13.66833;8697919;1.122783e+009
1078.834;4.66355;-1.776266;9575.302;989.4498;2;2;0;14.68835;13.70482;8787682;1.134784e+009
1082.834;4.676997;-1.802714;9675.471;999.8007;2;2;0;14.7307;13.74174;8879611;1.147078e+009
1086.834;4.690336;-1.830795;9769.844;1009.552;2;2;0;14.77271;13.77836;8966221;1.158691e+009
1090.834;4.703461;-1.857613;9861.29;1019.002;2;2;0;14.81405;13.81437;9050145;1.169957e+009
1094.834;4.716854;-1.885149;9954.435;1028.627;2;2;0;14.85623;13.8511;9135629;1.181442e+009
1098.834;4.73014;-1.913425;10041.61;1037.635;2;2;0;14.89808;13.88753;9215634;1.192223e+009
1102.834;4.743533;-1.940792;10131.17;1046.889;2;2;0;14.94026;13.92423;9297824;1.203297e+009
1106.834;4.756711;-1.969264;10218.6;1055.924;2;2;0;14.98177;13.96034;9378068;1.214121e+009
1110.834;4.770157;-1.998391;10306.17;1064.973;2;2;0;15.02412;13.99716;9458433;1.224976e+009
1113.75;4.766569;-2.000951;10198.18;1053.814;2;2;0;15.01281;13.98734;9359320;1.212021e+009
1117.75;4.753283;-1.986765;9972.903;1030.535;2;2;0;14.97097;13.95095;9152578;1.184816e+009
1121.75;4.739836;-1.971648;9757.491;1008.276;2;2;0;14.92862;13.9141;8954885;1.158798e+009
1125.75;4.726497;-1.956225;9550.584;986.8956;2;2;0;14.8866;13.87754;8764997;1.133811e+009
1129.75;4.713211;-1.941052;9351.249;966.2977;2;2;0;14.84476;13.84111;8582058;1.109742e+009
1133.75;4.699818;-1.924901;9153.797;945.8943;2;2;0;14.80258;13.80438;8400848;1.085911e+009
1137.75;4.686586;-1.90899;8960.846;925.956;2;2;0;14.7609;13.76807;8223769;1.062635e+009
1141.75;4.6733;-1.892745;8773.831;906.631;2;2;0;14.71906;13.7316;8052136;1.040079e+009
1145.75;4.659962;-1.876009;8588.789;887.51;2;2;0;14.67704;13.69497;7882315;1.01777e+009
1149.75;4.646676;-1.859112;8408.143;868.8432;2;2;0;14.6352;13.65847;7716528;9.960001e+008
1153.75;4.633283;-1.841924;8230.652;850.5024;2;2;0;14.59302;13.62167;7553636;9.746163e+008
1157.75;4.619997;-1.824779;8059.976;832.8659;2;2;0;14.55117;13.58515;7397000;9.540576e+008
1161.75;4.606551;-1.807602;7893.867;815.7012;2;2;0;14.50882;13.54817;7244554;9.340499e+008
1165.75;4.593211;-1.790544;7731.482;798.9214;2;2;0;14.46681;13.51147;7095526;9.144998e+008
1169.75;4.579925;-1.773294;7574.791;782.7299;2;2;0;14.42496;13.47491;6951723;8.956384e+008
1173.75;4.566479;-1.756098;7419.271;766.6595;2;2;0;14.38261;13.43789;6808996;8.769252e+008
1177.75;4.55314;-1.738945;7268.715;751.1021;2;2;0;14.3406;13.40115;6670824;8.588146e+008
1181.75;4.539908;-1.722047;7122.042;735.9459;2;2;0;14.29892;13.3647;6536216;8.411782e+008
1185.75;4.526515;-1.704914;6973.593;720.606;2;2;0;14.25674;13.32778;6399977;8.23341e+008
1189.75;4.513229;-1.688053;6829.816;705.7491;2;2;0;14.2149;13.29115;6268027;8.060706e+008
1193.75;4.499997;-1.671311;6687.869;691.0812;2;2;0;14.17322;13.25466;6137756;7.890296e+008
1197.75;4.486604;-1.654093;6546.03;676.4245;2;2;0;14.13104;13.21771;6007584;7.720103e+008
1201.75;4.473318;-1.637177;6407.24;662.0828;2;2;0;14.08919;13.18103;5880210;7.553649e+008
1205.75;4.459925;-1.620307;6269.145;647.8129;2;2;0;14.04701;13.14405;5753474;7.388112e+008
1209.75;4.44664;-1.603324;6133.202;633.7654;2;2;0;14.00517;13.10736;5628713;7.225253e+008
1213.75;4.433247;-1.586224;5996.817;619.6724;2;2;0;13.96298;13.07035;5503547;7.061971e+008
1217.75;4.419854;-1.568879;5861.166;605.655;2;2;0;13.9208;13.03333;5379054;6.899671e+008
1221.75;4.406569;-1.551734;5728.198;591.915;2;2;0;13.87896;12.99659;5257023;6.740667e+008
1225.75;4.393122;-1.534647;5594.279;578.0767;2;2;0;13.83661;12.95939;5134119;6.580628e+008
1229.75;4.379836;-1.517508;5462.729;564.4831;2;2;0;13.79476;12.92263;5013390;6.423522e+008
1233.75;4.366604;-1.499782;5332.206;550.9958;2;2;0;13.75308;12.886;4893604;6.267747e+008
1237.75;4.353211;-1.481891;5200.151;537.35;2;2;0;13.7109;12.84891;4772411;6.110255e+008
1241.75;4.339926;-1.464004;5071.226;524.0277;2;2;0;13.66906;12.8121;4654090;5.956574e+008
1245.75;4.326694;-1.445894;4944.092;510.8905;2;2;0;13.62738;12.77543;4537414;5.805116e+008
1249.75;4.313301;-1.427404;4815.873;497.6412;2;2;0;13.5852;12.7383;4419742;5.652468e+008
1253.75;4.299961;-1.408063;4688.685;484.4984;2;2;0;13.54319;12.70131;4303016;5.501149e+008
1257.75;4.286569;-1.387847;4559.92;471.1927;2;2;0;13.501;12.66415;4184842;5.348084e+008
1261.75;4.273336;-1.366425;4432.556;458.0316;2;2;0;13.45933;12.62742;4067954;5.196796e+008
1265.75;4.25989;-1.344491;4305.048;444.8558;2;2;0;13.41698;12.59009;3950934;5.04542e+008
1269.75;4.246497;-1.322796;4179.744;431.9077;2;2;0;13.37479;12.55289;3835938;4.896745e+008
1273.75;4.233211;-1.300462;4054.637;418.98;2;2;0;13.33295;12.51597;3721121;4.748424e+008
1277.75;4.219765;-1.277186;3928.112;405.9057;2;2;0;13.2906;12.4786;3605004;4.59853e+008
1281.75;4.20648;-1.253536;3802.909;392.9681;2;2;0;13.24875;12.44166;3490100;4.450315e+008
1285.75;4.193247;-1.22877;3678.942;380.1581;2;2;0;13.20708;12.40485;3376329;4.303659e+008
1289.75;4.179908;-1.203311;3555.47;367.3993;2;2;0;13.16506;12.36773;3263014;4.157677e+008
1293.75;4.166622;-1.177502;3433.727;354.8192;2;2;0;13.12322;12.33075;3151284;4.013829e+008
1297.75;4.153336;-1.150635;3313.604;342.4064;2;2;0;13.08137;12.29375;3041042;3.871979e+008
1301.75;4.139944;-1.123189;3193.495;329.9951;2;2;0;13.03919;12.25644;2930813;3.730238e+008
1305.75;4.126604;-1.095856;3074.939;317.7443;2;2;0;12.99718;12.21927;2822009;3.590421e+008
1309.75;4.113265;-1.067502;2956.616;305.5176;2;2;0;12.95517;12.18208;2713419;3.450979e+008
1313.75;4.09998;-1.039457;2838.885;293.3521;2;2;0;12.91332;12.14503;2605372;3.312336e+008
1317.75;4.086533;-1.010417;2719.926;281.0595;2;2;0;12.87097;12.10751;2496197;3.172346e+008
1321.75;4.07314;-0.9812106;2602.503;268.9259;2;2;0;12.82879;12.07013;2388434;3.034258e+008
1325.75;4.059908;-0.9516647;2485.516;256.8372;2;2;0;12.78711;12.03319;2281069;2.896793e+008
1329.75;4.046462;-0.921983;2367.675;244.6602;2;2;0;12.74476;11.99563;2172921;2.758416e+008
1333.75;4.033176;-0.8932141;2252.782;232.788;2;2;0;12.70292;11.95851;2067479;2.623588e+008
1337.75;4.019944;-0.8646394;2138.678;220.9971;2;2;0;12.66124;11.92153;1962760;2.489781e+008
1341.75;4.006604;-0.8360589;2024.252;209.1731;2;2;0;12.61923;11.88423;1857746;2.355691e+008
1345.75;3.993319;-0.8081191;1914.466;197.8285;2;2;0;12.57738;11.84706;1756990;2.227102e+008
1349.75;3.97998;-0.7802905;1805.147;186.5322;2;2;0;12.53537;11.80974;1656664;2.099147e+008
1353.75;3.96664;-0.7527567;1697.032;175.3603;2;2;0;12.49335;11.7724;1557442;1.972687e+008
1357.75;3.953248;-0.725216;1590.634;164.3658;2;2;0;12.45117;11.73489;1459795;1.848313e+008
1361.75;3.939908;-0.6976212;1484.757;153.4252;2;2;0;12.40916;11.69752;1362628;1.72464e+008
1365.75;3.926622;-0.6689458;1382.965;142.9067;2;2;0;12.36731;11.66029;1269209;1.605804e+008
1369.75;3.913176;-0.6414452;1279.597;132.2253;2;2;0;12.32496;11.62259;1174343;1.48522e+008
1373.75;3.899783;-0.6151632;1178.07;121.7341;2;2;0;12.28278;11.58503;1081167;1.366864e+008
1377.75;3.886551;-0.589026;1080.851;111.6881;2;2;0;12.24111;11.54791;991944.9;1.2536e+008
1381.75;3.873158;-0.5614106;989.2917;102.227;2;2;0;12.19892;11.51032;907917.1;1.146976e+008
1385.75;3.859873;-0.5339299;903.9839;93.41186;2;2;0;12.15708;11.47302;829626.3;1.04768e+008
1389.75;3.84664;-0.5064196;822.9776;85.04119;2;2;0;12.1154;11.43585;755283.3;9.534427e+007
1393.75;3.833248;-0.4792319;743.7058;76.84975;2;2;0;12.07322;11.39822;682531.9;8.612799e+007
1397.75;3.819962;-0.45271;667.9847;69.02522;2;2;0;12.03138;11.36088;613039.4;7.732991e+007
1401.75;3.806623;-0.426612;592.7592;61.25191;2;2;0;11.98936;11.32337;544001.6;6.859562e+007
1405.75;3.793283;-0.4006756;519.8582;53.71878;2;2;0;11.94735;11.28585;477097;6.013675e+007
1409.75;3.779891;-0.375713;450.1323;46.51376;2;2;0;11.90517;11.24816;413106.5;5.20513e+007
1413.75;3.766551;-0.3520838;384.2052;39.70128;2;2;0;11.86315;11.21061;352602.2;4.441111e+007
1417.75;3.753265;-0.32932;322.8173;33.35785;2;2;0;11.82131;11.17319;296263.8;3.730119e+007
1421.75;3.739819;-0.3078804;263.9576;27.27568;2;2;0;11.77896;11.13531;242245.7;3.048847e+007
1425.75;3.72648;-0.2892783;210.039;21.70407;2;2;0;11.73694;11.09772;192762.1;2.425147e+007
1429.75;3.713248;-0.2730869;161.4029;16.67833;2;2;0;11.69527;11.06042;148126.6;1.862891e+007
1433.75;3.699801;-0.2590352;115.962;11.98276;2;2;0;11.65292;11.02249;106423.5;1.33791e+007
1437.75;3.686569;-0.2475753;75.81144;7.833865;2;2;0;11.61124;10.98516;69575.54;8743474
1440.216;3.691712;-0.2495078;100.3714;10.37174;3;3;0;11.62744;10.99967;92115.34;1.15777e+007
1444.216;3.704944;-0.2578125;162.0164;16.74173;3;3;0;11.66912;11.037;148689.7;1.869534e+007
1448.216;3.71839;-0.2686765;233.7151;24.15061;3;3;0;11.71147;11.07492;214490.8;2.6979e+007
1452.216;3.731783;-0.2812507;308.6965;31.8987;3;3;0;11.75365;11.11267;283304.5;3.564796e+007
1456.216;3.745016;-0.2959211;387.1818;40.00887;3;3;0;11.79533;11.14996;355334;4.472804e+007
1460.216;3.758462;-0.3130645;472.1891;48.79297;3;3;0;11.83768;11.18783;433349;5.456892e+007
1464.216;3.771748;-0.3313885;561.079;57.97828;3;3;0;11.87952;11.22524;514927.2;6.486581e+007
1468.216;3.78498;-0.3503265;655.6347;67.74905;3;3;0;11.9212;11.26248;601705.2;7.582555e+007
1472.216;3.798319;-0.3703192;754.7313;77.98906;3;3;0;11.96321;11.30001;692650.6;8.731905e+007
1476.216;3.811605;-0.3910412;857.1256;88.56982;3;3;0;12.00505;11.33738;786622.4;9.920268e+007
1480.216;3.824998;-0.4126765;963.7502;99.58772;3;3;0;12.04724;11.37504;884476.6;1.115853e+008
1484.216;3.83823;-0.4349513;1071.818;110.7548;3;3;0;12.08891;11.41222;983655.4;1.241438e+008
1488.216;3.851676;-0.457996;1183.692;122.3151;3;3;0;12.13126;11.45;1086327;1.371535e+008
1492.216;3.865069;-0.481228;1300.085;134.3424;3;3;0;12.17345;11.48761;1193146;1.506965e+008
1496.216;3.878301;-0.5042307;1419.232;146.6542;3;3;0;12.21512;11.52476;1302492;1.645682e+008
1500.216;3.891748;-0.5279777;1542.311;159.3725;3;3;0;12.25747;11.56249;1415448;1.789075e+008
1504.216;3.905087;-0.550764;1668.149;172.3757;3;3;0;12.29949;11.59991;1530935;1.935771e+008
1508.216;3.918319;-0.5728342;1796.22;185.6097;3;3;0;12.34116;11.63701;1648471;2.085161e+008
1512.216;3.931765;-0.5948481;1927.335;199.1583;3;3;0;12.38351;11.67471;1768801;2.238211e+008
1516.216;3.945051;-0.6165454;2056.382;212.4933;3;3;0;12.42536;11.71193;1887234;2.388963e+008
1520.216;3.958283;-0.6379439;2186.019;225.8891;3;3;0;12.46703;11.749;2006207;2.540507e+008
1524.216;3.971676;-0.659744;2319.53;239.6853;3;3;0;12.50922;11.7865;2128737;2.69668e+008
1528.216;3.984908;-0.6816851;2451.444;253.3164;3;3;0;12.55089;11.82353;2249800;2.851099e+008
1532.216;3.998355;-0.7042181;2585.927;267.213;3;3;0;12.59324;11.86115;2373221;3.008638e+008
1536.216;4.011587;-0.7271605;2721.243;281.1957;3;3;0;12.63492;11.89816;2497407;3.167246e+008
1540.216;4.025033;-0.7504235;2860.832;295.6199;3;3;0;12.67727;11.93575;2625513;3.330965e+008
1544.216;4.038426;-0.7742514;3000.356;310.0374;3;3;0;12.71945;11.97318;2753561;3.494724e+008
1548.216;4.051658;-0.7984588;3139.968;324.464;3;3;0;12.76113;12.01015;2881688;3.658692e+008
1552.216;4.065104;-0.8237131;3282.748;339.218;3;3;0;12.80348;12.0477;3012725;3.826497e+008
1556.216;4.078444;-0.8490469;3423.737;353.7868;3;3;0;12.84549;12.08494;3142116;3.992325e+008
1560.216;4.091676;-0.8741703;3562.685;368.1448;3;3;0;12.88717;12.12186;3269635;4.155882e+008
1564.216;4.105122;-0.9008431;3704.792;382.8292;3;3;0;12.92952;12.15937;3400053;4.323272e+008
1568.216;4.118355;-0.9268703;3843.588;397.1716;3;3;0;12.9712;12.19627;3527432;4.486895e+008
1572.216;4.131586;-0.9529201;3983.054;411.583;3;3;0;13.01287;12.23315;3655426;4.651418e+008
1576.216;4.144926;-0.9796888;4123.502;426.0961;3;3;0;13.05488;12.27032;3784322;4.817224e+008
1580.216;4.158265;-1.005907;4263.316;440.5435;3;3;0;13.0969;12.30748;3912635;4.98241e+008
1584.216;4.171658;-1.031392;4403.942;455.0749;3;3;0;13.13908;12.34477;4041694;5.148675e+008
1588.216;4.18489;-1.056378;4542.409;469.3832;3;3;0;13.18076;12.3816;4168772;5.312515e+008
1592.216;4.19839;-1.081492;4683.699;483.9832;3;3;0;13.22328;12.41916;4298440;5.479817e+008
1596.216;4.211729;-1.106256;4824.806;498.5643;3;3;0;13.26529;12.45626;4427940;5.647003e+008
1600.216;4.225015;-1.130898;4963.617;512.9081;3;3;0;13.30713;12.4932;4555333;5.811615e+008
1604.216;4.238408;-1.155118;5102.858;527.2964;3;3;0;13.34932;12.53042;4683121;5.976869e+008
1608.216;4.251801;-1.178323;5241.358;541.6081;3;3;0;13.3915;12.56762;4810228;6.141376e+008
1612.216;4.264979;-1.200957;5378.636;555.7935;3;3;0;13.43301;12.60422;4936214;6.304532e+008
1616.216;4.278426;-1.224651;5520.098;570.4113;3;3;0;13.47536;12.64155;5066040;6.472762e+008
1620.216;4.291658;-1.248293;5658.296;584.6917;3;3;0;13.51703;12.67827;5192870;6.637247e+008
1624.216;4.304997;-1.271544;5796.674;598.9908;3;3;0;13.55905;12.71527;5319866;6.802083e+008
1628.216;4.318283;-1.294865;5933.094;613.0876;3;3;0;13.60089;12.75212;5445065;6.96473e+008
1632.216;4.331622;-1.318547;6068.994;627.1306;3;3;0;13.64291;12.78909;5569787;7.126895e+008
1636.216;4.345015;-1.341736;6205.507;641.2371;3;3;0;13.68509;12.82621;5695071;7.289909e+008
1640.216;4.358247;-1.365431;6340.187;655.1539;3;3;0;13.72676;12.86286;5818672;7.450854e+008
1644.216;4.371693;-1.388675;6477.118;669.3035;3;3;0;13.76911;12.90009;5944340;7.614607e+008
1648.216;4.385086;-1.411552;6611.144;683.1529;3;3;0;13.8113;12.93716;6067342;7.775052e+008
1652.216;4.398318;-1.433046;6742.603;696.7371;3;3;0;13.85297;12.97377;6187988;7.932558e+008
1656.216;4.411819;-1.454263;6877.162;710.6415;3;3;0;13.89549;13.01111;6311478;8.093886e+008
1660.216;4.425104;-1.474547;7006.868;724.0444;3;3;0;13.93734;13.04784;6430515;8.24957e+008
1664.216;4.438336;-1.49437;7135.995;737.3876;3;3;0;13.97901;13.08441;6549021;8.404671e+008
1668.216;4.451676;-1.515403;7264.99;750.7172;3;3;0;14.02103;13.12127;6667406;8.559754e+008
1672.216;4.464961;-1.534708;7391.362;763.7756;3;3;0;14.06287;13.15796;6783382;8.711843e+008
1676.216;4.4783;-1.553878;7518.509;776.9141;3;3;0;14.10488;13.19479;6900071;8.86497e+008
1680.216;4.491586;-1.573264;7644.759;789.96;3;3;0;14.14673;13.23145;7015936;9.017135e+008
1684.216;4.504979;-1.592527;7770.574;802.9609;3;3;0;14.18891;13.2684;7131403;9.168923e+008
1688.216;4.518372;-1.611902;7895.85;815.9061;3;3;0;14.23109;13.30533;7246374;9.320185e+008
1692.216;4.531604;-1.630991;8019.31;828.6636;3;3;0;14.27277;13.34181;7359678;9.469369e+008
1696.216;4.545051;-1.650581;8144.264;841.5756;3;3;0;14.31512;13.37887;7474354;9.620482e+008
1700.216;4.55839;-1.669985;8266.247;854.1806;3;3;0;14.35713;13.41561;7586304;9.768164e+008
1704.216;4.571676;-1.689096;8387.327;866.6921;3;3;0;14.39898;13.4522;7697424;9.91487e+008
1708.216;4.585122;-1.708822;8511.14;879.4862;3;3;0;14.44133;13.48921;7811053;1.006496e+009
1712.216;4.598408;-1.728017;8633.017;892.0802;3;3;0;14.48317;13.52577;7922905;1.021282e+009
1716.216;4.611586;-1.747972;8753.142;904.4932;3;3;0;14.52468;13.56202;8033149;1.035868e+009
1720.216;4.625033;-1.768707;8879.254;917.5247;3;3;0;14.56703;13.59899;8148887;1.051181e+009
1724.216;4.638265;-1.789633;9003.129;930.3251;3;3;0;14.60871;13.63536;8262573;1.066234e+009
1728.216;4.651658;-1.811108;9130.446;943.4813;3;3;0;14.65089;13.67216;8379418;1.08171e+009
1732.216;4.66489;-1.83257;9256.233;956.4793;3;3;0;14.69257;13.7085;8494857;1.097011e+009
1736.216;4.678283;-1.854783;9382.988;969.5773;3;3;0;14.73475;13.74528;8611186;1.112442e+009
1740.216;4.691729;-1.875976;9507.983;982.4935;3;3;0;14.7771;13.78218;8725900;1.127678e+009
1744.216;4.704961;-1.898157;9628.877;994.986;3;3;0;14.81878;13.81848;8836850;1.142431e+009
1748.216;4.718408;-1.92055;9750.785;1007.583;3;3;0;14.86113;13.85536;8948730;1.157321e+009
1752.216;4.731747;-1.943387;9869.414;1019.841;3;3;0;14.90314;13.89193;9057602;1.17183e+009
1756.216;4.745033;-1.966603;9982.474;1031.524;3;3;0;14.94498;13.92834;9161361;1.185686e+009
1760.216;4.758479;-1.991172;10097.07;1043.366;3;3;0;14.98734;13.96518;9266533;1.199739e+009
1763.85;4.770372;-2.014229;10191.35;1053.108;3;3;0;15.02479;13.99775;9353057;1.211336e+009
1766.852;4.760354;-2.005753;10010.29;1034.398;3;3;0;14.99324;13.97032;9186886;1.189488e+009
1770.852;4.747068;-1.991149;9790.661;1011.704;3;3;0;14.9514;13.93392;8985326;1.162967e+009
1774.852;4.733783;-1.976185;9581.712;990.1122;3;3;0;14.90955;13.89751;8793565;1.137734e+009
1778.852;4.720443;-1.960826;9377.547;969.0151;3;3;0;14.86754;13.86094;8606193;1.113084e+009
1782.852;4.707158;-1.945183;9179.336;948.5333;3;3;0;14.82569;13.82451;8424286;1.08916e+009
1786.852;4.693925;-1.929188;8985.814;928.536;3;3;0;14.78402;13.78821;8246683;1.065811e+009
1790.852;4.680532;-1.913209;8793.551;908.6687;3;3;0;14.74183;13.75145;8070234;1.042623e+009
1794.852;4.667193;-1.896925;8607.977;889.4927;3;3;0;14.69982;13.71483;7899924;1.020247e+009
1798.852;4.653801;-1.880258;8424.151;870.4973;3;3;0;14.65764;13.67805;7731219;9.980917e+008
1802.852;4.640515;-1.863094;8245.251;852.011;3;3;0;14.6158;13.64154;7567035;9.765391e+008
1806.852;4.627122;-1.845405;8070.092;833.9112;3;3;0;14.57361;13.60473;7406283;9.554422e+008
1810.852;4.613729;-1.828298;7900.922;816.4303;3;3;0;14.53143;13.56791;7251029;9.350693e+008
1814.852;4.600497;-1.81134;7739.138;799.7125;3;3;0;14.48975;13.53151;7102552;9.155889e+008
1818.852;4.586997;-1.794168;7578.071;783.0689;3;3;0;14.44724;13.49437;6954734;8.962007e+008
1822.852;4.573711;-1.777308;7422.313;766.9739;3;3;0;14.40539;13.4578;6811788;8.774595e+008
1826.852;4.560479;-1.760597;7271.88;751.4291;3;3;0;14.36371;13.42137;6673729;8.593623e+008
1830.852;4.547086;-1.743761;7122.108;735.9526;3;3;0;14.32153;13.38447;6536276;8.413523e+008
1834.852;4.533801;-1.72687;6975.088;720.7605;3;3;0;14.27969;13.34787;6401349;8.236828e+008
1838.852;4.520568;-1.709847;6828.984;705.6631;3;3;0;14.23801;13.31139;6267264;8.061355e+008
1842.852;4.507176;-1.693137;6684.209;690.7029;3;3;0;14.19583;13.27446;6134397;7.88754e+008
1846.852;4.49389;-1.676321;6542.047;676.0129;3;3;0;14.15398;13.23781;6003929;7.716957e+008
1850.852;4.480497;-1.659322;6401.028;661.4409;3;3;0;14.1118;13.20085;5874509;7.547822e+008
1854.852;4.467158;-1.642799;6261.617;647.035;3;3;0;14.06979;13.16403;5746565;7.380715e+008
1858.852;4.453765;-1.626282;6123.297;632.7419;3;3;0;14.02761;13.12704;5619623;7.215005e+008
1862.852;4.440372;-1.60938;5986.151;618.5701;3;3;0;13.98542;13.09004;5493757;7.050798e+008
1866.852;4.42714;-1.592982;5851.188;604.6239;3;3;0;13.94375;13.05347;5369896;6.889312e+008
1870.852;4.413694;-1.575936;5714.386;590.4877;3;3;0;13.9014;13.0163;5244347;6.725737e+008
1874.852;4.400408;-1.558626;5580.985;576.7029;3;3;0;13.85955;12.97955;5121919;6.566314e+008
1878.852;4.387176;-1.541532;5449.297;563.0952;3;3;0;13.81788;12.94294;5001063;6.40903e+008
1882.852;4.373783;-1.52431;5316.518;549.3746;3;3;0;13.77569;12.90587;4879206;6.250548e+008
1886.852;4.360497;-1.506492;5184.533;535.7361;3;3;0;13.73385;12.86909;4758077;6.093133e+008
1890.852;4.347211;-1.488621;5053.837;522.2308;3;3;0;13.692;12.83229;4638131;5.937347e+008
1894.852;4.333872;-1.47048;4923.635;508.7767;3;3;0;13.64999;12.79533;4518640;5.782246e+008
1898.852;4.320533;-1.452306;4795.804;495.5674;3;3;0;13.60798;12.75836;4401323;5.630041e+008
1902.852;4.30714;-1.433492;4667.235;482.2819;3;3;0;13.5658;12.72122;4283330;5.477073e+008
1906.852;4.293854;-1.413962;4539.966;469.1308;3;3;0;13.52395;12.68436;4166530;5.325758e+008
1910.852;4.280408;-1.393262;4410.566;455.7594;3;3;0;13.4816;12.64705;4047774;5.172031e+008
1914.852;4.267069;-1.371778;4282.54;442.53;3;3;0;13.43959;12.61002;3930278;5.020042e+008
1918.852;4.253837;-1.350644;4158.037;429.6647;3;3;0;13.39791;12.57328;3816016;4.872308e+008
1922.852;4.24039;-1.328428;4032.061;416.6471;3;3;0;13.35556;12.53592;3700402;4.722926e+008
1926.852;4.227104;-1.306366;3906.008;403.6217;3;3;0;13.31371;12.499;3584718;4.573587e+008
1930.852;4.213872;-1.283298;3781.528;390.7587;3;3;0;13.27204;12.46222;3470477;4.426203e+008
1934.852;4.20048;-1.25968;3654.425;377.6246;3;3;0;13.22986;12.42497;3353829;4.275838e+008
1938.852;4.187194;-1.235196;3530.429;364.8117;3;3;0;13.18801;12.38801;3240032;4.129231e+008
1942.852;4.173855;-1.210416;3408.226;352.1841;3;3;0;13.146;12.35088;3127881;3.984822e+008
1946.852;4.160569;-1.185236;3286.748;339.6313;3;3;0;13.10415;12.31389;3016395;3.841371e+008
1950.852;4.147176;-1.158931;3165.862;327.1397;3;3;0;13.06197;12.27659;2905453;3.698707e+008
1954.852;4.133783;-1.132096;3046.949;314.852;3;3;0;13.01979;12.23927;2796321;3.558451e+008
1958.852;4.120497;-1.105447;2929.436;302.709;3;3;0;12.97794;12.20224;2688474;3.419944e+008
1962.852;4.107051;-1.0775;2811.382;290.51;3;3;0;12.93559;12.16475;2580131;3.280892e+008
1966.852;4.093712;-1.049258;2692.622;278.2382;3;3;0;12.89358;12.12754;2471140;3.141131e+008
1970.852;4.08048;-1.020944;2577.061;266.2968;3;3;0;12.8519;12.09062;2365084;3.00521e+008
1974.852;4.067033;-0.9920643;2459.271;254.1252;3;3;0;12.80955;12.05308;2256983;2.866774e+008
1978.852;4.053801;-0.9635767;2343.629;242.1754;3;3;0;12.76788;12.01613;2150853;2.730961e+008
1982.852;4.040515;-0.9352057;2229.554;230.3877;3;3;0;12.72603;11.97902;2046161;2.597069e+008
1986.852;4.027176;-0.9069011;2114.946;218.5448;3;3;0;12.68402;11.94174;1940980;2.462651e+008
1990.852;4.01389;-0.8784858;2001.949;206.8685;3;3;0;12.64217;11.9046;1837278;2.330212e+008
1994.852;4.000551;-0.8508043;1890.497;195.3518;3;3;0;12.60016;11.8673;1734994;2.199664e+008
1998.852;3.987212;-0.8238444;1781.701;184.1095;3;3;0;12.55815;11.82998;1635147;2.072302e+008
2002.852;3.973819;-0.7967238;1673.307;172.9087;3;3;0;12.51597;11.79249;1535668;1.945499e+008
2006.852;3.960426;-0.7700548;1566.817;161.9047;3;3;0;12.47378;11.755;1437938;1.821004e+008
2010.852;3.94714;-0.7437739;1462.118;151.0858;3;3;0;12.43194;11.71779;1341851;1.698687e+008
2014.852;3.933694;-0.7168714;1357.324;140.2571;3;3;0;12.38959;11.68011;1245677;1.576343e+008
2018.852;3.920354;-0.6901579;1254.686;129.6511;3;3;0;12.34757;11.64272;1151481;1.456599e+008
2022.852;3.907122;-0.6637003;1155.443;119.396;3;3;0;12.3059;11.60562;1060401;1.340887e+008
2026.852;3.893676;-0.6371891;1056.984;109.2219;3;3;0;12.26355;11.5679;970040.9;1.226163e+008
2030.852;3.880444;-0.6110412;963.0306;99.51336;3;3;0;12.22187;11.53077;883816.1;1.116758e+008
2034.852;3.867212;-0.5843016;876.5548;90.57751;3;3;0;12.18019;11.49363;804453.5;1.0161e+008
2038.852;3.853819;-0.5570139;794.1159;82.05881;3;3;0;12.13801;11.45602;728795.6;9.201912e+007
2042.852;3.840533;-0.5299846;716.2182;74.00936;3;3;0;12.09617;11.4187;657305.4;8.296166e+007
2046.852;3.827194;-0.503487;640.0304;66.13661;3;3;0;12.05415;11.38121;587384.5;7.410882e+007
2050.852;3.813855;-0.477783;566.0103;58.48785;3;3;0;12.01214;11.34371;519452.9;6.551349e+007
2054.852;3.800462;-0.4522954;493.4101;50.98581;3;3;0;11.96996;11.30604;452824.4;5.708879e+007
2058.852;3.787069;-0.4280001;425.0885;43.9259;3;3;0;11.92778;11.26836;390122.7;4.916529e+007
2062.852;3.773837;-0.4046576;361.1819;37.3222;3;3;0;11.8861;11.23112;331472.8;4.175836e+007
2066.852;3.760391;-0.3820572;300.3497;31.03619;3;3;0;11.84375;11.19326;275644.3;3.471204e+007
2070.852;3.747051;-0.3610328;244.0665;25.22025;3;3;0;11.80174;11.15569;223990.7;2.819668e+007
2074.852;3.733819;-0.3425317;192.8783;19.9308;3;3;0;11.76006;11.11841;177013.1;2.227468e+007
2078.852;3.720426;-0.3266177;145.109;14.99463;3;3;0;11.71788;11.08066;133173;1.675168e+007
2082.852;3.707141;-0.313149;102.3963;10.58097;3;3;0;11.67603;11.04319;93973.63;1.181641e+007
2086.852;3.693908;-0.3015807;65.36627;6.754528;3;3;0;11.63436;11.00587;59989.54;7540374
2090.852;3.680516;-0.2959736;47.51148;4.90953;3;3;0;11.59217;10.96807;43603.41;5478651
2092.924;3.673658;-0.2953951;47.62689;4.921455;3;3;0;11.57058;10.94872;43709.32;5490896