File: Ensayos/Compresion/Clavo3/Clavo3.raw
"Test Type";"Manual"
"Method Name:";"C:\INSTRON\USER\TEMPLATE\CYCLE.MTM"
"Name:";""
"Operator ID:";""
"Company:";""
"Lab name:";""
"Test date:";"22/06/2017"
"Temperature:";""
"Humidity:";""
"Note 1:";""
"Note 2:";""
"Note 3:";""
"Geometry:";"Rectangular"
"Specimen";1
"Specimen name:";""
"Width:";0.250000;"in"
"Thickness:";0.060000;"in"
"Length:";1.250000;"in"
"Diameter:";0.039370;"in"
"Inner diameter:";0.019685;"in"
"Outer diameter:";0.039370;"in"
"Wall thickness:";0.019685;"in"
"Area:";0.015000;"in*in"
"Linear density:";1.000000;"den"
"Sled weight:";2.204623;"lbf"
"Loading span:";0.000000;"mm"
"Support span:";1.000000;"mm"
"Span ratio:";"2"
"Fixture type:";"3-point"
"Comment:";""
"Included"
"Final Width:";0.250000;"in"
"Final Thickness:";0.060000;"in"
"Final Length:";1.250000;"in"
"Final Diameter:";0.039370;"in"
"Final Inner diameter:";0.019685;"in"
"Final Outer diameter:";0.039370;"in"
"Final Wall thickness:";0.019685;"in"
"Final Area:";0.015000;"in*in"
"Final Linear density:";1.000000;"den"
"Time sec";"Extension mm";"Strain 1 %";"Load N";"Stress MPa";"Cycle Count ";"Total Cycle Count ";"Repetitions Count ";"Strain [Exten.] %";"True strain %";"Tenacity gf/tex";"True stress Pa"
0;0;-1.354347e-005;50.77509;5.246769;0;0;0;0;0;46598.56;5246769
7;0.01162499;-0.0002930536;52.00769;5.374139;0;0;0;0.03661415;0.03660745;47729.78;5376106
14;0.02324999;-0.0045377;80.78399;8.347696;0;0;0;0.0732283;0.0732015;74139.07;8353809
21;0.03503569;-0.01319226;143.8905;14.86871;0;0;0;0.1103486;0.1102878;132054.7;1.488512e+007
28;0.04655354;-0.02138051;209.282;21.62585;0;0;0;0.1466253;0.1465179;192067.5;2.165756e+007
36;0.05994639;-0.02964679;284.0531;29.35221;0;0;0;0.1888075;0.1886295;260688.2;2.940763e+007
44;0.07323209;-0.03822037;365.3552;37.75345;0;0;0;0.2306523;0.2303867;335302.8;3.784053e+007
51;0.09653565;-0.0552232;529.2175;54.68592;0;0;0;0.3040493;0.303588;485686.5;5.485219e+007
58;0.1198392;-0.0747895;712.9021;73.66669;0;0;0;0.3774463;0.3767358;654262.1;7.394475e+007
65;0.1430356;-0.09658303;910.8388;94.1202;0;0;0;0.4505059;0.4494941;835917.4;9.454422e+007
72;0.1663392;-0.1184173;1119.089;115.6394;0;0;0;0.5239029;0.5225353;1027038;1.162452e+008
79;0.1897499;-0.1407512;1331.596;137.5985;0;0;0;0.5976374;0.5958587;1222065;1.384209e+008
86.00001;0.2131606;-0.162912;1538.792;159.0088;0;0;0;0.6713719;0.6691283;1412218;1.600764e+008
93.00001;0.2364106;-0.1871405;1746.765;180.4994;0;0;0;0.7446002;0.7418417;1603084;1.818434e+008
100;0.2598748;-0.215006;1956.61;202.1835;0;0;0;0.8185034;0.8151718;1795669;2.038383e+008
107;0.2831784;-0.248501;2158.241;223.0187;0;0;0;0.8919004;0.8879465;1980715;2.250078e+008
114;0.3064284;-0.2910215;2350.544;242.89;0;0;0;0.9651287;0.9605011;2157199;2.452342e+008
121;0.3297319;-0.3451653;2530.903;261.5272;0;0;0;1.038526;1.03317;2322723;2.642432e+008
128;0.3530355;-0.411399;2695.914;278.5783;0;0;0;1.111923;1.105786;2474160;2.816759e+008
135;0.3764997;-0.4898909;2847.367;294.2285;0;0;0;1.185826;1.17885;2613156;2.977175e+008
142;0.3997497;-0.5762205;2980.664;308.0026;0;0;0;1.259054;1.251194;2735488;3.118805e+008
149;0.423214;-0.668482;3102.239;320.5654;0;0;0;1.332958;1.324152;2847064;3.248384e+008
156;0.4465176;-0.7625094;3214.792;332.1959;0;0;0;1.406355;1.396557;2950359;3.368677e+008
163;0.469714;-0.8571249;3320.117;343.0794;0;0;0;1.479414;1.468578;3047019;3.48155e+008
170;0.4930711;-0.9526391;3424.126;353.8271;0;0;0;1.55298;1.541044;3142473;3.593219e+008
175.016;0.5031961;-1.004475;3433.538;354.7996;0;0;0;1.58487;1.572442;3151111;3.604227e+008
182.016;0.479839;-0.9522431;3139.194;324.3841;0;0;0;1.511304;1.499997;2880979;3.292865e+008
189.016;0.4564819;-0.8949159;2883.99;298.0129;0;0;0;1.437738;1.427501;2646767;3.022976e+008
196.016;0.4332319;-0.8336978;2649.373;273.7691;0;0;0;1.36451;1.355284;2431448;2.775047e+008
203.016;0.4098747;-0.768563;2430.083;251.1091;0;0;0;1.290944;1.282682;2230196;2.543508e+008
210.016;0.3865712;-0.6982563;2235.006;230.9511;0;0;0;1.217547;1.210195;2051165;2.337631e+008
217.016;0.3631069;-0.6248326;2056.369;212.4919;0;0;0;1.143644;1.137154;1887221;2.14922e+008
224.016;0.3397498;-0.5527072;1887.651;195.0576;0;0;0;1.070078;1.064393;1732381;1.971449e+008
231.016;0.3164998;-0.4836152;1723.392;178.0842;0;0;0;0.9968497;0.991914;1581634;1.798595e+008
238.016;0.2931427;-0.4174338;1557.751;160.9679;0;0;0;0.9232839;0.9190477;1429618;1.624541e+008
245.016;0.2698927;-0.3567233;1394.687;144.118;0;0;0;0.8500557;0.8464631;1279967;1.45343e+008
252.016;0.2465355;-0.3015518;1235.12;127.6293;0;0;0;0.7764899;0.7734907;1133525;1.286203e+008
259.016;0.223232;-0.250318;1076.833;111.273;0;0;0;0.7030929;0.7006327;988258;1.120554e+008
266.016;0.1997677;-0.2059196;915.6441;94.61675;0;0;0;0.6291897;0.6272186;840327.4;9.521207e+007
273.016;0.1764106;-0.1676158;755.0167;78.01855;0;0;0;0.5556239;0.5540861;692912.6;7.845204e+007
280.016;0.1531606;-0.1358219;597.4797;61.73969;0;0;0;0.4823956;0.4812358;548333.8;6.203752e+007
287.016;0.1298035;-0.1077767;444.711;45.95356;0;0;0;0.4088299;0.4079965;408131.1;4.614143e+007
294.016;0.1065535;-0.08174644;307.1441;31.73829;0;0;0;0.3356016;0.3350397;281879.8;3.18448e+007
301.016;0.08319637;-0.05806857;187.7738;19.40333;0;0;0;0.2620358;0.2616931;172328.4;1.945417e+007
308.016;0.05989282;-0.03687881;92.19352;9.526683;0;0;0;0.1886388;0.1884611;84610.11;9544654
315.016;0.03648212;-0.02507639;49.77643;5.143575;0;0;0;0.1149043;0.1148384;45682.05;5149485
322.016;0.01307142;-0.02477323;49.55412;5.120602;0;0;0;0.04116983;0.04116136;45478.02;5122710
327.54;0.02142856;-0.02498967;50.35218;5.203069;1;1;0;0.06749152;0.06746875;46210.44;5206581
334.54;0.04483926;-0.02746799;61.46841;6.351749;1;1;0;0.141226;0.1411264;56412.3;6360719
341.54;0.06803567;-0.0479057;152.4425;15.75242;1;1;0;0.2142856;0.2140563;139903.3;1.578618e+007
348.54;0.0913928;-0.0710435;294.0703;30.38732;1;1;0;0.2878514;0.2874379;269881.4;3.047479e+007
355.54;0.1146428;-0.09623179;454.9837;47.01507;1;1;0;0.3610797;0.3604293;417558.8;4.718484e+007
362.54;0.1381071;-0.1225472;637.7378;65.8997;1;1;0;0.4349828;0.4340395;585280.4;6.618636e+007
369.54;0.1615178;-0.1488326;834.9718;86.28059;1;1;0;0.5087174;0.5074278;766290.8;8.671951e+007
376.54;0.1847142;-0.1762747;1039.177;107.3818;1;1;0;0.5817769;0.5800911;953698.9;1.080065e+008
383.54;0.2081249;-0.2063746;1248.781;129.041;1;1;0;0.6555114;0.6533722;1146062;1.298869e+008
390.54;0.2313749;-0.2401348;1455.593;150.4116;1;1;0;0.7287397;0.7260972;1335863;1.515077e+008
397.54;0.254732;-0.2776114;1657.761;171.3024;1;1;0;0.8023055;0.7991041;1521402;1.726767e+008
404.54;0.2779819;-0.3208022;1853.229;191.5007;1;1;0;0.8755337;0.8717231;1700791;1.931774e+008
411.54;0.3014463;-0.3706174;2045.263;211.3443;1;1;0;0.949437;0.9449582;1877029;2.133508e+008
418.54;0.3248569;-0.4270839;2230.275;230.4622;1;1;0;1.023171;1.017972;2046823;2.328203e+008
425.54;0.3480533;-0.4894731;2405.868;248.6069;1;1;0;1.096231;1.090266;2207973;2.513322e+008
432.54;0.3715176;-0.5600367;2577.326;266.3242;1;1;0;1.170134;1.163341;2365327;2.694406e+008
439.54;0.394714;-0.6350362;2736.065;282.7272;1;1;0;1.243194;1.23553;2511009;2.862421e+008
446.54;0.4180176;-0.7150495;2887.998;298.427;1;1;0;1.316591;1.307999;2650444;3.023561e+008
453.54;0.4413212;-0.797364;3031.786;313.2852;1;1;0;1.389988;1.380416;2782405;3.176398e+008
461.54;0.4681604;-0.8953275;3188.694;329.499;1;1;0;1.474521;1.463756;2926407;3.343576e+008
469.54;0.4948389;-0.9952623;3336.879;344.8115;1;1;0;1.558548;1.546527;3062403;3.501856e+008
475.538;0.4948389;-1.015765;3247.831;335.6099;1;1;0;1.558548;1.546527;2980680;3.408406e+008
482.538;0.4714283;-0.962102;2968.812;306.7779;1;1;0;1.484813;1.473898;2724612;3.11333e+008
489.538;0.4481247;-0.904533;2719.89;281.0559;1;1;0;1.411416;1.401549;2496165;2.850228e+008
496.538;0.4246604;-0.8420181;2487.033;256.9939;1;1;0;1.337513;1.328647;2282461;2.604312e+008
503.538;0.4013033;-0.7736829;2285.528;236.1717;1;1;0;1.263947;1.256026;2097531;2.391568e+008
510.538;0.3781069;-0.7025037;2103.328;217.3443;1;1;0;1.190888;1.183853;1930318;2.199326e+008
517.538;0.3547498;-0.6301732;1929.426;199.3745;1;1;0;1.117322;1.111126;1770721;2.016021e+008
524.538;0.3314998;-0.5594081;1763.179;182.1955;1;1;0;1.044094;1.038681;1618148;1.840978e+008
531.538;0.3080891;-0.4913212;1599.133;165.2441;1;1;0;0.9703593;0.9656815;1467596;1.668476e+008
538.538;0.2847855;-0.42647;1435.847;148.3712;1;1;0;0.8969623;0.8929635;1317741;1.49702e+008
545.538;0.2613213;-0.3667304;1275.298;131.781;1;1;0;0.8230591;0.8196904;1170398;1.328657e+008
552.538;0.2379641;-0.310979;1119.815;115.7145;1;1;0;0.7494933;0.7466986;1027705;1.165818e+008
561.538;0.2080713;-0.2479986;919.3868;95.00349;1;1;0;0.6553426;0.6532046;843762.3;9.562609e+007
569.538;0.1814463;-0.1979931;744.5979;76.94193;1;1;0;0.5714844;0.5698576;683350.7;7.738165e+007
578.538;0.1514999;-0.1509437;551.1094;56.94809;1;1;0;0.4771651;0.4760302;505777.7;5.721982e+007
586.538;0.1247142;-0.1158764;385.302;39.81462;1;1;0;0.3928007;0.3920312;353608.8;3.997102e+007
594.538;0.09798208;-0.08464909;237.9526;24.58849;1;1;0;0.308605;0.3081298;218379.8;2.466437e+007
601.538;0.07462495;-0.05995756;130.2603;13.46026;1;1;0;0.2350392;0.2347634;119545.7;1.349189e+007
608.538;0.05142854;-0.03983452;55.43399;5.728191;1;1;0;0.1619796;0.1618486;50874.25;5737469
615.5341;0.02812498;-0.03768536;49.53547;5.118675;1;1;0;0.08858262;0.08854341;45460.91;5123210
621.536;0.04810711;-0.03937792;56.50556;5.83892;2;2;0;0.1515185;0.1514038;51857.67;5847767
628.536;0.0713571;-0.06034432;147.5511;15.24698;2;2;0;0.2247468;0.2244946;135414.2;1.528124e+007
635.536;0.09466065;-0.08745626;284.9615;29.44608;2;2;0;0.2981438;0.2977002;261521.9;2.953388e+007
642.536;0.1180714;-0.1138848;446.548;46.14339;2;2;0;0.3718783;0.3711885;409817.1;4.631499e+007
649.536;0.141482;-0.1417194;626.6706;64.75609;2;2;0;0.4456127;0.4446228;575123.6;6.504465e+007
656.536;0.164732;-0.1698271;819.9474;84.72807;2;2;0;0.518841;0.5174997;752502.3;8.516767e+007
664.536;0.1915177;-0.2047605;1050.767;108.5794;2;2;0;0.6032055;0.6013935;964335.3;1.092344e+008
673.536;0.2214106;-0.248109;1313.615;135.7405;2;2;0;0.6973562;0.6949359;1205563;1.366871e+008
681.536;0.247982;-0.2920154;1541.635;159.3026;2;2;0;0.7810456;0.7780113;1414827;1.605468e+008
689.536;0.2747677;-0.3422691;1761.287;182;2;2;0;0.86541;0.8616868;1616411;1.83575e+008
698.536;0.3048212;-0.4075847;2002.005;206.8742;2;2;0;0.9600669;0.9554875;1837329;2.088604e+008
706.536;0.3314998;-0.4733901;2208.338;228.1954;2;2;0;1.044094;1.038681;2026690;2.30578e+008
713.536;0.3548569;-0.5375845;2383.692;246.3153;2;2;0;1.11766;1.11146;2187621;2.490683e+008
720.536;0.3780533;-0.6077122;2551.398;263.645;2;2;0;1.190719;1.183686;2341532;2.667843e+008
727.536;0.4013569;-0.6823842;2712.664;280.3091;2;2;0;1.264116;1.256193;2489533;2.838526e+008
734.536;0.4246604;-0.7606079;2867.438;296.3026;2;2;0;1.337513;1.328647;2631576;3.002656e+008
741.536;0.4481247;-0.8406605;3019.103;311.9746;2;2;0;1.411416;1.401549;2770766;3.163779e+008
748.536;0.4713747;-0.9218185;3164.663;327.0158;2;2;0;1.484645;1.473732;2904353;3.318709e+008
755.536;0.4948389;-1.005423;3307.208;341.7455;2;2;0;1.558548;1.546527;3035172;3.470718e+008
762.536;0.5181961;-1.092019;3437.382;355.1969;2;2;0;1.632114;1.618938;3154639;3.609941e+008
769.536;0.5413925;-1.18132;3554.582;367.3075;2;2;0;1.705173;1.690798;3262198;3.735708e+008
776.536;0.5647496;-1.272175;3669.268;379.1585;2;2;0;1.778739;1.763105;3367451;3.859027e+008
783.536;0.5879996;-1.362147;3781.81;390.7878;2;2;0;1.851967;1.835027;3470736;3.980251e+008
790.536;0.6114103;-1.451234;3897.239;402.7155;2;2;0;1.925702;1.907395;3576670;4.104706e+008
797.536;0.6347139;-1.53993;4013.886;414.769;2;2;0;1.999099;1.979379;3683722;4.230607e+008
804.536;0.6581246;-1.628436;4133.1;427.0879;2;2;0;2.072833;2.051642;3793131;4.359407e+008
811.536;0.6815352;-1.717448;4253.606;439.5401;2;2;0;2.146568;2.123853;3903724;4.489752e+008
818.536;0.7047316;-1.806067;4372.86;451.8631;2;2;0;2.219627;2.195352;4013169;4.618928e+008
825.536;0.7280889;-1.895115;4494.576;464.4404;2;2;0;2.293193;2.267295;4124873;4.75091e+008
832.536;0.7513388;-1.983622;4613.325;476.7112;2;2;0;2.366421;2.338856;4233855;4.879922e+008
837.83;0.7423924;-1.978991;4415.525;456.2718;2;2;0;2.338244;2.311326;4052324;4.669406e+008
844.83;0.7191423;-1.930091;4082.362;421.8449;2;2;0;2.265015;2.239745;3746566;4.313998e+008
851.83;0.6957317;-1.877672;3781.548;390.7607;2;2;0;2.191281;2.167618;3470495;3.993234e+008
858.83;0.6724281;-1.823323;3501.662;361.8391;2;2;0;2.117884;2.095768;3213632;3.695025e+008
865.83;0.6490175;-1.766916;3249.031;335.7339;2;2;0;2.044149;2.023537;2981781;3.425968e+008
872.83;0.6256067;-1.70717;3025.044;312.5885;2;2;0;1.970415;1.951253;2776218;3.187478e+008
879.83;0.6024104;-1.646772;2824.212;291.8358;2;2;0;1.897355;1.87958;2591906;2.97373e+008
886.83;0.5790532;-1.583814;2636.726;272.4622;2;2;0;1.82379;1.807358;2419841;2.774313e+008
895.83;0.5491068;-1.49964;2418.849;249.9482;2;2;0;1.72947;1.714685;2219886;2.54271e+008
903.83;0.5224282;-1.420029;2243.521;231.8309;2;2;0;1.645443;1.632052;2058979;2.356456e+008
912.83;0.4923211;-1.323562;2063.949;213.2752;2;2;0;1.550618;1.538718;1894178;2.165823e+008
920.83;0.4656426;-1.233413;1916.567;198.0456;2;2;0;1.466591;1.45594;1758919;2.009502e+008
927.83;0.442339;-1.152475;1793.244;185.3023;2;2;0;1.393194;1.383578;1645740;1.878839e+008
934.83;0.4191426;-1.070671;1671.561;172.7283;2;2;0;1.320134;1.311496;1534066;1.750085e+008
941.83;0.3957319;-0.9888966;1548.627;160.0251;2;2;0;1.2464;1.238696;1421244;1.620197e+008
948.83;0.3724819;-0.9078772;1426.684;147.4243;2;2;0;1.173171;1.166343;1309332;1.491539e+008
955.83;0.3490712;-0.8269024;1307.3;135.0879;2;2;0;1.099437;1.093437;1199767;1.365731e+008
962.83;0.3257677;-0.7490583;1190.704;123.0397;2;2;0;1.02604;1.020812;1092763;1.243021e+008
969.83;0.3023034;-0.6743987;1074.057;110.9861;2;2;0;0.9521366;0.9476324;985710.2;1.120429e+008
976.83;0.2789998;-0.6053537;958.2765;99.0221;2;2;0;0.8787397;0.8749012;879453.1;9.989225e+007
983.83;0.2558034;-0.5437496;842.7302;87.0823;2;2;0;0.80568;0.8024517;773411.1;8.77839e+007
990.83;0.2324463;-0.4879393;720.9863;74.50207;2;2;0;0.7321143;0.7294473;661681.3;7.50475e+007
997.83;0.2091427;-0.4371415;599.0531;61.90228;2;2;0;0.6587173;0.6565572;549777.8;6.231004e+007
1004.83;0.185732;-0.3873181;482.7256;49.88174;2;2;0;0.5849828;0.5832784;443018.8;5.017354e+007
1011.83;0.1624285;-0.3386058;372.1088;38.45131;2;2;0;0.5115857;0.5102815;341500.8;3.864803e+007
1018.83;0.1389642;-0.2904518;265.0805;27.39171;2;2;0;0.4376825;0.4367275;243276.2;2.75116e+007
1025.83;0.1156606;-0.2461066;167.5682;17.31542;2;2;0;0.3642855;0.3636236;153784.8;1.73785e+007
1032.83;0.09241066;-0.2066674;85.21876;8.805956;2;2;0;0.2910572;0.2906344;78209.05;8831587
1039.83;0.0691071;-0.1871689;49.15214;5.079065;2;2;0;0.2176601;0.2174236;45109.11;5090120
1046.83;0.04580354;-0.1859901;49.08455;5.07208;2;2;0;0.1442631;0.1441592;45047.08;5079397
1053.638;0.02298213;-0.1853435;49.10513;5.074207;2;2;0;0.07238466;0.07235847;45065.97;5077880
1059.64;0.04291069;-0.18533;49.66041;5.131586;3;3;0;0.1351518;0.1350605;45575.57;5138522
1066.64;0.06642852;-0.1854151;50.2236;5.189782;3;3;0;0.2092237;0.2090051;46092.43;5200640
1073.64;0.08978565;-0.200718;100.9411;10.4306;3;3;0;0.2827895;0.2823904;92638.17;1.04601e+007
1080.64;0.1130356;-0.2361362;216.8644;22.40937;3;3;0;0.3560178;0.3553855;199026.2;2.248915e+007
1087.64;0.1363928;-0.2743443;358.6862;37.06432;3;3;0;0.4295835;0.4286635;329182.3;3.722354e+007
1094.64;0.1595892;-0.3096205;517.7951;53.5056;3;3;0;0.5026431;0.5013841;475203.6;5.377454e+007
1101.64;0.1829999;-0.3440082;687.4496;71.0366;3;3;0;0.5763776;0.5747229;630903.2;7.144604e+007
1108.64;0.2063034;-0.3798436;863.5346;89.23209;3;3;0;0.6497746;0.6476727;792504.2;8.981189e+007
1115.64;0.2297677;-0.4186667;1044.66;107.9484;3;3;0;0.7236778;0.7210718;958730.8;1.087296e+008
1122.64;0.2531248;-0.4602605;1225.845;126.6709;3;3;0;0.7972436;0.7940824;1125013;1.276808e+008
1129.64;0.2763213;-0.5046518;1404.539;145.136;3;3;0;0.8703032;0.8665379;1289008;1.463991e+008
1136.64;0.2997319;-0.5530721;1581.038;163.3742;3;3;0;0.9440376;0.9396094;1450989;1.649165e+008
1143.64;0.3229284;-0.6055145;1752.73;181.1158;3;3;0;1.017097;1.01196;1608559;1.829579e+008
1150.64;0.3463391;-0.6622895;1923.378;198.7495;3;3;0;1.090832;1.084925;1765170;2.009175e+008
1157.64;0.369589;-0.723947;2093.764;216.356;3;3;0;1.16406;1.157337;1921541;2.188745e+008
1164.64;0.3930533;-0.7914448;2258.039;233.3312;3;3;0;1.237963;1.230363;2072303;2.362197e+008
1171.64;0.416464;-0.8640239;2414.042;249.4515;3;3;0;1.311698;1.303169;2215474;2.527235e+008
1178.64;0.439714;-0.9409054;2560.34;264.569;3;3;0;1.384926;1.375424;2349739;2.682331e+008
1185.64;0.4630712;-1.020434;2702.761;279.2859;3;3;0;1.458492;1.447958;2480445;2.833592e+008
1192.64;0.4862675;-1.100797;2838.795;293.3428;3;3;0;1.531551;1.519941;2605289;2.978355e+008
1199.64;0.5096782;-1.182952;2976.462;307.5684;3;3;0;1.605286;1.592537;2731632;3.125057e+008
1206.64;0.5329282;-1.265048;3111.877;321.5612;3;3;0;1.678514;1.664583;2855908;3.269587e+008
1213.64;0.5564461;-1.348616;3252.334;336.0751;3;3;0;1.752586;1.737405;2984812;3.419651e+008
1220.64;0.5798032;-1.431054;3394.263;350.7412;3;3;0;1.826152;1.809678;3115067;3.571463e+008
1227.64;0.6030532;-1.511991;3538.226;365.6174;3;3;0;1.89938;1.881567;3247188;3.725619e+008
1234.64;0.6264103;-1.59245;3687.814;381.0748;3;3;0;1.972946;1.953735;3384471;3.885932e+008
1241.64;0.6496067;-1.672305;3839.028;396.7004;3;3;0;2.046005;2.025356;3523248;4.048169e+008
1248.64;0.6730174;-1.751816;3993.924;412.7063;3;3;0;2.11974;2.097586;3665402;4.214546e+008
1255.64;0.6962674;-1.832032;4149.476;428.7801;3;3;0;2.192968;2.169268;3808159;4.381831e+008
1262.64;0.7197317;-1.913152;4304.427;444.7917;3;3;0;2.266871;2.24156;3950365;4.548746e+008
1270.606;0.7462495;-2.006627;4473.538;462.2665;3;3;0;2.350392;2.323196;4105565;4.731316e+008
1277.606;0.7229995;-1.964564;4103.852;424.0656;3;3;0;2.277164;2.251624;3766288;4.337222e+008
1284.606;0.6995889;-1.913038;3792.2;391.8615;3;3;0;2.203429;2.179505;3480271;4.004959e+008
1291.606;0.6761781;-1.85934;3504.65;362.1479;3;3;0;2.129695;2.107334;3216374;3.698605e+008
1298.606;0.6529281;-1.804606;3243.195;335.1309;3;3;0;2.056467;2.035607;2976425;3.420227e+008
1305.606;0.6295174;-1.745337;3011.831;311.2232;3;3;0;1.982732;1.963332;2764092;3.173939e+008
1312.606;0.6062675;-1.685031;2805.969;289.9508;3;3;0;1.909504;1.891502;2575163;2.954874e+008
1319.606;0.5830175;-1.622466;2615.112;270.2288;3;3;0;1.836276;1.81962;2400005;2.751909e+008
1326.606;0.5596604;-1.557417;2439.843;252.1176;3;3;0;1.76271;1.747354;2239153;2.565617e+008
1333.606;0.5362497;-1.489194;2278.723;235.4685;3;3;0;1.688975;1.674871;2091286;2.394455e+008
1341.606;0.5096247;-1.407693;2109.282;217.9596;3;3;0;1.605117;1.592371;1935783;2.214581e+008
1350.606;0.4795711;-1.311347;1934.123;199.8597;3;3;0;1.51046;1.499166;1775031;2.028785e+008
1358.606;0.4528926;-1.223421;1786.525;184.6079;3;3;0;1.426433;1.416355;1639573;1.872412e+008
1367.606;0.4229997;-1.122931;1623.153;167.7262;3;3;0;1.332283;1.323486;1489640;1.699608e+008
1375.606;0.3963212;-1.033932;1476.691;152.5917;3;3;0;1.248256;1.240529;1355225;1.544965e+008
1382.606;0.3729105;-0.9578771;1347.099;139.2005;3;3;0;1.174521;1.167677;1236293;1.408355e+008
1389.606;0.3495533;-0.8819279;1221.87;126.2602;3;3;0;1.100955;1.094939;1121365;1.276502e+008
1396.606;0.3262498;-0.8097547;1099.255;113.5899;3;3;0;1.027558;1.022315;1008836;1.147571e+008
1403.606;0.3028391;-0.7425152;978.3143;101.0927;3;3;0;0.9538239;0.9493037;897842.6;1.020569e+008
1410.606;0.2795891;-0.6795917;858.439;88.70554;3;3;0;0.8805956;0.8767409;787827.8;8.948668e+007
1417.606;0.2563391;-0.6228919;740.4311;76.51136;3;3;0;0.8073673;0.8041255;679526.6;7.712909e+007
1424.606;0.232982;-0.5703315;619.8854;64.05495;3;3;0;0.7338015;0.7311223;568896.5;6.452499e+007
1431.606;0.2096249;-0.5210308;501.2263;51.79349;3;3;0;0.6602358;0.6580658;459997.7;5.213545e+007
1438.606;0.1862142;-0.4729263;388.7518;40.1711;3;3;0;0.5865013;0.5847881;356774.9;4.040671e+007
1445.606;0.1629106;-0.4245316;284.5205;29.40051;3;3;0;0.5131043;0.5117924;261117.2;2.955137e+007
1452.606;0.1394463;-0.3738585;187.6076;19.38616;3;3;0;0.4392011;0.4382394;172175.9;1.94713e+007
1459.606;0.1162499;-0.3268238;103.3609;10.68065;3;3;0;0.3661415;0.3654728;94858.94;1.071976e+007
1466.606;0.09299994;-0.292908;49.74143;5.139958;3;3;0;0.2929132;0.2924851;45649.93;5155014
1473.606;0.06964281;-0.2904347;48.96885;5.060125;3;3;0;0.2193474;0.2191072;44940.9;5071224
1478.664;0.06616067;-0.2899028;49.52772;5.117874;4;4;0;0.2083801;0.2081633;45453.79;5128539
1487.664;0.09610708;-0.293;62.78706;6.488008;4;4;0;0.3026994;0.3022422;57622.48;6507648
1495.664;0.1226785;-0.3303462;171.8756;17.76052;4;4;0;0.3863889;0.3856444;157737.9;1.782914e+007
1502.664;0.145982;-0.3707184;305.3862;31.55664;4;4;0;0.459786;0.4587322;280266.5;3.170173e+007
1509.664;0.1693392;-0.4076112;456.6576;47.18805;4;4;0;0.5333518;0.5319345;419095.1;4.743973e+007
1516.664;0.1927499;-0.4428389;618.4494;63.90657;4;4;0;0.6070862;0.6052509;567578.6;6.429453e+007
1523.664;0.2160534;-0.4795862;787.6;81.3855;4;4;0;0.6804832;0.6781784;722815.6;8.193931e+007
1530.664;0.2394641;-0.5186391;963.1371;99.52437;4;4;0;0.7542177;0.7513877;883913.9;1.00275e+008
1537.664;0.2627677;-0.5598377;1139.475;117.746;4;4;0;0.8276148;0.8242088;1045747;1.187205e+008
1544.664;0.2859641;-0.6046558;1315.554;135.9408;4;4;0;0.9006743;0.8966425;1207342;1.371652e+008
1551.664;0.3093212;-0.653175;1490.825;154.0522;4;4;0;0.9742401;0.9695249;1368197;1.555531e+008
1558.664;0.3326784;-0.7044463;1664.411;171.9895;4;4;0;1.047806;1.042354;1527504;1.737916e+008
1565.664;0.356089;-0.7600217;1839.657;190.0983;4;4;0;1.12154;1.115298;1688335;1.922303e+008
1572.664;0.3793926;-0.8199272;2010.569;207.7592;4;4;0;1.194937;1.187854;1845189;2.102418e+008
1579.664;0.4028569;-0.8854743;2176.144;224.8686;4;4;0;1.268841;1.260858;1997144;2.277219e+008
1586.664;0.4261069;-0.9551856;2332.464;241.0218;4;4;0;1.342069;1.333143;2140606;2.442564e+008
1593.664;0.4493569;-1.028335;2482.348;256.5098;4;4;0;1.415297;1.405375;2278161;2.601402e+008
1600.664;0.4726604;-1.103952;2629.25;271.6897;4;4;0;1.488694;1.477722;2412980;2.757344e+008
1607.664;0.4960175;-1.181113;2772.26;286.4675;4;4;0;1.56226;1.550182;2544227;2.909428e+008
1614.664;0.5194282;-1.26035;2915.14;301.2317;4;4;0;1.635994;1.622756;2675354;3.061599e+008
1621.664;0.5426782;-1.340057;3056.417;315.8304;4;4;0;1.709223;1.69478;2805010;3.212286e+008
1628.664;0.5661961;-1.421174;3201.244;330.7959;4;4;0;1.783295;1.767581;2937925;3.36695e+008
1635.664;0.5894461;-1.501285;3347.754;345.9352;4;4;0;1.856523;1.8395;3072383;3.523576e+008
1642.664;0.612696;-1.580292;3496.604;361.3165;4;4;0;1.929751;1.911368;3208990;3.68289e+008
1649.664;0.6359996;-1.658949;3652.866;377.4636;4;4;0;2.003148;1.983349;3352398;3.850247e+008
1656.664;0.6593031;-1.736169;3812.147;393.9227;4;4;0;2.076545;2.055279;3498578;4.021027e+008
1663.664;0.6827674;-1.813066;3977.82;411.0422;4;4;0;2.150449;2.127653;3650623;4.198814e+008
1670.664;0.7060174;-1.889841;4143.662;428.1792;4;4;0;2.223677;2.199314;3802823;4.377005e+008
1677.664;0.7295352;-1.968364;4310.788;445.449;4;4;0;2.297749;2.271748;3956202;4.556843e+008
1684.664;0.7528388;-2.047605;4466.466;461.5358;4;4;0;2.371146;2.343471;4099075;4.724795e+008
1691.664;0.7759816;-2.128423;4609.825;476.3495;4;4;0;2.444036;2.414648;4230642;4.879917e+008
1698.664;0.7993387;-2.211388;4749.35;490.7672;4;4;0;2.517602;2.486433;4358690;5.031227e+008
1706.664;0.8260173;-2.307422;4902.536;506.5964;4;4;0;2.601629;2.568363;4499276;5.197761e+008
1713.664;0.8493209;-2.392112;5033.71;520.1511;4;4;0;2.675026;2.639873;4619661;5.340653e+008
1720.664;0.8727316;-2.478126;5164.281;533.6435;4;4;0;2.748761;2.711661;4739492;5.483121e+008
1725.928;0.8701601;-2.491733;5020.877;518.825;4;4;0;2.740662;2.703778;4607883;5.330442e+008
1732.928;0.8469101;-2.446948;4650.584;480.5613;4;4;0;2.667434;2.632478;4268048;4.933799e+008
1739.928;0.8235531;-2.398575;4316.979;446.0887;4;4;0;2.593868;2.560798;3961884;4.576596e+008
1746.928;0.800303;-2.348626;4009.484;414.3141;4;4;0;2.520639;2.489395;3679682;4.247575e+008
1753.928;0.7769995;-2.297742;3725.396;384.9583;4;4;0;2.447242;2.417777;3418962;3.943792e+008
1760.928;0.7536959;-2.243979;3468.813;358.4447;4;4;0;2.373845;2.346108;3183485;3.669537e+008
1767.928;0.7302317;-2.188053;3231.742;333.9474;4;4;0;2.299942;2.273892;2965914;3.41628e+008
1774.928;0.7068209;-2.130203;3008.111;310.8388;4;4;0;2.226208;2.201789;2760678;3.177587e+008
1781.928;0.683571;-2.07165;2802.997;289.6436;4;4;0;2.152979;2.13013;2572435;2.958796e+008
1788.928;0.6602138;-2.011699;2612.589;269.9681;4;4;0;2.079414;2.058089;2397690;2.755818e+008
1795.928;0.6369639;-1.950625;2437.041;251.828;4;4;0;2.006186;1.986327;2236581;2.568802e+008
1802.928;0.6137139;-1.887309;2272.174;234.7918;4;4;0;1.932957;1.914513;2085276;2.393302e+008
1809.928;0.5903032;-1.821191;2117.891;218.8492;4;4;0;1.859223;1.84215;1943683;2.22918e+008
1816.928;0.5669461;-1.752247;1975.117;204.0958;4;4;0;1.785657;1.769901;1812653;2.077402e+008
1823.928;0.5435354;-1.680457;1840.685;190.2045;4;4;0;1.711922;1.697434;1689279;1.934607e+008
1830.928;0.5202854;-1.607178;1714.898;177.2065;4;4;0;1.638694;1.625412;1573838;1.801104e+008
1837.928;0.4968747;-1.532108;1592.027;164.5098;4;4;0;1.56496;1.55284;1461074;1.670843e+008
1844.928;0.4736247;-1.45571;1476.945;152.618;4;4;0;1.491731;1.480714;1355459;1.548947e+008
1851.928;0.4503747;-1.378983;1362.624;140.8048;4;4;0;1.418503;1.408536;1250541;1.428021e+008
1858.928;0.4270176;-1.302216;1247.172;128.8747;4;4;0;1.344937;1.335973;1144586;1.30608e+008
1865.928;0.4036069;-1.225782;1130.921;116.8621;4;4;0;1.271203;1.263191;1037897;1.183477e+008
1872.928;0.3801962;-1.151356;1015.855;104.9719;4;4;0;1.197468;1.190355;932295.9;1.062289e+008
1879.928;0.3569462;-1.079613;902.4873;93.25721;4;4;0;1.12424;1.117967;828252.9;9.430565e+007
1886.928;0.3335355;-1.011323;790.827;81.71896;4;4;0;1.050506;1.045026;725777.3;8.257742e+007
1893.928;0.3102855;-0.9487939;683.8783;70.66756;4;4;0;0.9772772;0.9725327;627625.6;7.135818e+007
1900.928;0.2870355;-0.8898957;577.9587;59.72252;4;4;0;0.904049;0.8999869;530418.4;6.026243e+007
1907.928;0.2636784;-0.8354375;474.4409;49.02566;4;4;0;0.8304832;0.8270537;435415.6;4.943281e+007
1914.928;0.2402677;-0.7831925;375.2826;38.77928;4;4;0;0.7567487;0.7538997;344413.6;3.907274e+007
1922.928;0.2136427;-0.7259829;266.8068;27.57009;4;4;0;0.6728904;0.6706366;244860.5;2.775561e+007
1931.928;0.1835892;-0.6591878;156.0765;16.12794;4;4;0;0.5782336;0.5765682;143238.4;1.62212e+007
1939.928;0.1569106;-0.5964992;75.29117;7.780103;4;4;0;0.4942066;0.4929895;69098.06;7818553
1948.928;0.1270178;-0.5682147;48.8592;5.048794;4;4;0;0.400056;0.3992579;44840.27;5068992
1956.928;0.1003392;-0.5657102;48.88214;5.051164;4;4;0;0.316029;0.3155307;44861.32;5067128
1964.928;0.07360709;-0.5644143;48.83747;5.046549;4;4;0;0.2318334;0.231565;44820.33;5058249
1971.928;0.05030354;-0.5634773;48.78036;5.040648;4;4;0;0.1584363;0.158311;44767.91;5048634
1977.41;0.03208927;-0.5630901;48.87679;5.050612;5;5;0;0.1010685;0.1010175;44856.41;5055717
1984.41;0.05544639;-0.5628848;49.16568;5.080464;5;5;0;0.1746343;0.174482;45121.54;5089336
1991.41;0.07864281;-0.5625834;49.37044;5.101622;5;5;0;0.2476939;0.2473876;45309.45;5114259
1998.41;0.1019464;-0.5626022;49.59748;5.125083;5;5;0;0.3210909;0.3205765;45517.82;5141540
2005.41;0.1251963;-0.5624476;50.17808;5.185079;5;5;0;0.3943192;0.3935438;46050.66;5205524
2012.41;0.1486606;-0.5708983;77.32284;7.990043;5;5;0;0.4682224;0.4671297;70962.62;8027454
2019.41;0.1720713;-0.6067949;182.2411;18.83162;5;5;0;0.5419569;0.5404936;167250.8;1.893368e+007
2026.41;0.1953213;-0.643153;313.7309;32.41893;5;5;0;0.6151852;0.6133007;287924.9;3.261837e+007
2033.41;0.2187856;-0.6783881;461.1352;47.65074;5;5;0;0.6890884;0.6867251;423204.4;4.797909e+007
2040.41;0.241982;-0.714661;615.2288;63.57377;5;5;0;0.762148;0.7592583;564622.9;6.405829e+007
2047.41;0.265232;-0.7518081;777.5273;80.34465;5;5;0;0.8353763;0.8319063;713571.5;8.101583e+007
2054.41;0.2885891;-0.790864;946.4546;97.8005;5;5;0;0.908942;0.904836;868603.6;9.868945e+007
2061.41;0.3119998;-0.8334821;1122.133;115.954;5;5;0;0.9826765;0.9778796;1029832;1.170935e+008
2068.41;0.3354105;-0.8794118;1299.177;134.2486;5;5;0;1.056411;1.05087;1192313;1.356668e+008
2075.41;0.3586605;-0.9290496;1476.279;152.5492;5;5;0;1.129639;1.123307;1354848;1.542724e+008
2082.41;0.3821247;-0.9821697;1649.929;170.493;5;5;0;1.203542;1.196358;1514213;1.725449e+008
2089.41;0.4053747;-1.039059;1818.619;187.9243;5;5;0;1.276771;1.268689;1669028;1.903237e+008
2096.41;0.4286247;-1.099761;1982.519;204.8607;5;5;0;1.349999;1.340968;1819446;2.076263e+008
2103.41;0.4519283;-1.163723;2141.635;221.3027;5;5;0;1.423396;1.413361;1965474;2.244527e+008
2110.41;0.475339;-1.230695;2297.172;237.375;5;5;0;1.497131;1.486034;2108218;2.409288e+008
2117.41;0.4986961;-1.30019;2450.966;253.267;5;5;0;1.570696;1.558489;2249361;2.57245e+008
2124.41;0.5219997;-1.372569;2600.561;268.7252;5;5;0;1.644094;1.630725;2386651;2.731433e+008
2132.41;0.5487854;-1.458564;2771.523;286.3912;5;5;0;1.728458;1.71369;2543550;2.913414e+008
2141.41;0.5786782;-1.557326;2959.916;305.8586;5;5;0;1.822609;1.806198;2716447;3.114332e+008
2149.41;0.6052496;-1.647307;3128.994;323.33;5;5;0;1.906298;1.888356;2871618;3.294937e+008
2158.41;0.6352496;-1.749404;3324.351;343.5169;5;5;0;2.000786;1.981033;3050905;3.5039e+008
2166.41;0.6620353;-1.83959;3505.225;362.2072;5;5;0;2.08515;2.063709;3216901;3.697598e+008
2174.41;0.6887674;-1.928648;3692.06;381.5136;5;5;0;2.169346;2.146151;3388368;3.897899e+008
2181.41;0.712071;-2.004923;3859.08;398.7724;5;5;0;2.242743;2.217964;3541650;4.077158e+008
2188.41;0.7353209;-2.080204;4026.51;416.0735;5;5;0;2.315971;2.28956;3695308;4.257097e+008
2195.41;0.7586245;-2.153782;4195.387;433.5242;5;5;0;2.389369;2.36127;3850294;4.438827e+008
2202.41;0.781928;-2.22663;4366.364;451.1919;5;5;0;2.462765;2.432928;4007208;4.623037e+008
2209.41;0.8053388;-2.300353;4541.966;469.3374;5;5;0;2.5365;2.504865;4168364;4.812421e+008
2216.41;0.8285887;-2.375222;4718.268;487.5553;5;5;0;2.609728;2.576256;4330165;5.002792e+008
2223.41;0.8521066;-2.452676;4893.735;505.687;5;5;0;2.6838;2.648418;4491199;5.192586e+008
2229.066;0.8642673;-2.502154;4943.532;510.8326;5;5;0;2.722102;2.685712;4536900;5.24738e+008
2236.066;0.8408566;-2.458345;4559.434;471.1425;5;5;0;2.648367;2.613905;4184396;4.8362e+008
2243.066;0.8176066;-2.410844;4223.452;436.4243;5;5;0;2.575139;2.542541;3876051;4.476628e+008
2250.066;0.7942495;-2.361069;3913.921;404.4393;5;5;0;2.501573;2.470796;3591980;4.145566e+008
2257.066;0.7708388;-2.310139;3627.444;374.8366;5;5;0;2.427839;2.398835;3329067;3.83937e+008
2264.066;0.7474816;-2.256262;3372.338;348.4756;5;5;0;2.354273;2.326987;3094945;3.566797e+008
2271.066;0.7241781;-2.199922;3136.963;324.1534;5;5;0;2.280876;2.255253;2878931;3.31547e+008
2278.066;0.7007674;-2.141652;2916.229;301.3443;5;5;0;2.207141;2.183137;2676354;3.079954e+008
2285.066;0.6775175;-2.082611;2714.719;280.5215;5;5;0;2.133913;2.111464;2491419;2.865076e+008
2292.066;0.6542674;-2.0225;2528.057;261.233;5;5;0;2.060685;2.03974;2320110;2.666162e+008
2299.066;0.6309103;-1.96006;2352.048;243.0454;5;5;0;1.987119;1.967634;2158579;2.47875e+008
2306.066;0.6075532;-1.895961;2189.674;226.2667;5;5;0;1.913553;1.895475;2009561;2.305965e+008
2313.066;0.5841425;-1.829343;2037.277;210.5191;5;5;0;1.839819;1.823099;1869700;2.143923e+008
2320.066;0.5608925;-1.761341;1895.111;195.8285;5;5;0;1.766591;1.751168;1739228;1.99288e+008
2327.066;0.5373747;-1.691084;1758.798;181.7428;5;5;0;1.692519;1.678355;1614127;1.848189e+008
2334.066;0.5141782;-1.620581;1629.571;168.3893;5;5;0;1.619459;1.606486;1495530;1.711163e+008
2341.066;0.4909818;-1.549488;1503.269;155.3381;5;5;0;1.546399;1.534564;1379617;1.577403e+008
2348.066;0.4675711;-1.477416;1380.814;142.6844;5;5;0;1.472665;1.461927;1267235;1.447857e+008
2355.066;0.444214;-1.405183;1259.818;130.1814;5;5;0;1.399099;1.389402;1156191;1.320028e+008
2362.066;0.4208033;-1.333541;1137.697;117.5622;5;5;0;1.325365;1.316659;1044115;1.191203e+008
2369.066;0.3975533;-1.26353;1017.252;105.1163;5;5;0;1.252136;1.244362;933577.9;1.064325e+008
2377.066;0.3707676;-1.185966;880.2016;90.95435;5;5;0;1.167772;1.161006;807800.3;9.201649e+007
2386.066;0.3408212;-1.10431;732.022;75.64243;5;5;0;1.073453;1.067732;671809.3;7.645441e+007
2394.066;0.3142498;-1.037796;606.4043;62.6619;5;5;0;0.9897632;0.9848971;556524.3;6.328211e+007
2402.066;0.2875713;-0.9760441;483.6436;49.9766;5;5;0;0.9057363;0.901659;443861.3;5.042926e+007
2409.066;0.2642141;-0.9254297;381.3007;39.40115;5;5;0;0.8321705;0.828727;349936.6;3.972903e+007
2416.066;0.2407499;-0.8774922;284.8461;29.43415;5;5;0;0.7582672;0.7554069;261415.9;2.965734e+007
2423.066;0.2173927;-0.8298172;194.1325;20.0604;5;5;0;0.6847014;0.682368;178164;2.019775e+007
2430.066;0.1941963;-0.7794929;113.1653;11.69377;5;5;0;0.6116419;0.609779;103856.9;1.17653e+007
2437.066;0.1708392;-0.7288321;53.37008;5.514919;5;5;0;0.5380762;0.5366337;48980.11;5544594
2442.37;0.1663927;-0.7213033;51.20322;5.29101;6;6;0;0.5240716;0.5227032;46991.48;5318739
2449.37;0.1898034;-0.7509433;141.9171;14.6648;6;6;0;0.5978062;0.5960264;130243.7;1.475246e+007
2456.37;0.2132142;-0.7858976;271.2379;28.02797;6;6;0;0.6715406;0.6692958;248927.1;2.821619e+007
2463.37;0.2364641;-0.8195378;412.6848;42.64418;6;6;0;0.7447689;0.7420092;378739.3;4.296178e+007
2470.37;0.259982;-0.8541499;566.646;58.55354;6;6;0;0.8188408;0.8155065;520036.3;5.9033e+007
2477.37;0.283232;-0.8893237;728.9929;75.32941;6;6;0;0.8920692;0.8881138;669029.3;7.600141e+007
2484.37;0.3064819;-0.9278147;898.2114;92.81536;6;6;0;0.9652974;0.9606682;824328.6;9.371131e+007
2491.37;0.3297855;-0.969862;1071.086;110.6791;6;6;0;1.038695;1.033337;982983.4;1.118287e+008
2498.37;0.3530891;-1.016117;1247.6;128.919;6;6;0;1.112092;1.105953;1144979;1.303527e+008
2505.37;0.3765533;-1.066867;1424.043;147.1514;6;6;0;1.185995;1.179017;1306907;1.488966e+008
2512.37;0.3998033;-1.119631;1595.749;164.8944;6;6;0;1.259223;1.251361;1464490;1.669708e+008
2519.37;0.4232676;-1.1761;1766.334;182.5215;6;6;0;1.333126;1.324318;1621043;1.849548e+008
2526.37;0.4466247;-1.235206;1932.421;199.6839;6;6;0;1.406692;1.39689;1773469;2.024929e+008
2533.37;0.4697675;-1.296121;2092.627;216.2385;6;6;0;1.479583;1.468744;1920497;2.194379e+008
2540.37;0.4931246;-1.360318;2251.376;232.6426;6;6;0;1.553149;1.541211;2066188;2.362559e+008
2547.37;0.5164282;-1.427357;2407.311;248.7559;6;6;0;1.626546;1.613459;2209297;2.528021e+008
2554.37;0.5398389;-1.497189;2563.052;264.8492;6;6;0;1.70028;1.685987;2352227;2.693524e+008
2561.37;0.5631425;-1.569635;2716.427;280.6981;6;6;0;1.773677;1.758131;2492987;2.856767e+008
2568.37;0.5866067;-1.643989;2871.337;296.7054;6;6;0;1.84758;1.83072;2635154;3.021873e+008
2575.37;0.6099639;-1.719622;3025.679;312.6541;6;6;0;1.921146;1.902925;2776801;3.186607e+008
2582.37;0.6331068;-1.795515;3180.745;328.6777;6;6;0;1.994037;1.974417;2919112;3.352316e+008
2589.37;0.6564638;-1.872226;3341.391;345.2777;6;6;0;2.067603;2.046518;3066543;3.524167e+008
2596.37;0.6797674;-1.948637;3504.815;362.1649;6;6;0;2.141;2.118402;3216525;3.699189e+008
2603.37;0.7031781;-2.024897;3671.305;379.3689;6;6;0;2.214734;2.190565;3369320;3.877709e+008
2610.37;0.7264817;-2.098883;3842.528;397.062;6;6;0;2.288131;2.262346;3526459;4.061473e+008
2617.37;0.749946;-2.171342;4019.301;415.3286;6;6;0;2.362035;2.33457;3688692;4.251388e+008
2624.37;0.7732495;-2.241718;4197.308;433.7227;6;6;0;2.435431;2.406248;3852057;4.442857e+008
2631.37;0.7964459;-2.31108;4376.912;452.2818;6;6;0;2.508491;2.477545;4016888;4.636273e+008
2638.37;0.8198031;-2.381704;4565.418;471.7608;6;6;0;2.582057;2.549285;4189888;4.839419e+008
2645.37;0.8431066;-2.453488;4751.571;490.9967;6;6;0;2.655454;2.620809;4360729;5.040349e+008
2652.37;0.8665173;-2.528447;4935.88;510.042;6;6;0;2.729188;2.69261;4529878;5.23962e+008
2659.37;0.8897673;-2.606663;5104.951;527.5127;6;6;0;2.802417;2.763867;4685042;5.422958e+008
2666.37;0.9132852;-2.689505;5263.383;543.884;6;6;0;2.876489;2.835894;4830441;5.595287e+008
2673.37;0.9365887;-2.770654;5403.666;558.3799;6;6;0;2.949886;2.907214;4959186;5.748515e+008
2680.37;0.9597851;-2.85386;5537.363;572.1954;6;6;0;3.022945;2.978155;5081885;5.894925e+008
2687.37;0.9831422;-2.938555;5668.623;585.7589;6;6;0;3.096511;3.049536;5202348;6.038969e+008
2692.866;0.9950351;-2.992216;5685.424;587.495;6;6;0;3.133969;3.085862;5217768;6.059069e+008
2699.866;0.9715173;-2.95231;5287.915;546.4189;6;6;0;3.059897;3.014016;4852955;5.631388e+008
2706.866;0.9481601;-2.909479;4928.16;509.2442;6;6;0;2.986331;2.942608;4522792;5.244519e+008
2713.866;0.9246959;-2.863465;4591.194;474.4244;6;6;0;2.912428;2.870823;4213544;4.882416e+008
2720.866;0.9013923;-2.816459;4274.219;441.6702;6;6;0;2.839031;2.799477;3922642;4.542094e+008
2727.866;0.8781959;-2.768449;3979.443;411.21;6;6;0;2.765971;2.728409;3652113;4.225839e+008
2734.866;0.8548924;-2.717494;3704.954;382.846;6;6;0;2.692574;2.656962;3400201;3.931544e+008
2741.866;0.8315887;-2.665336;3448.953;356.3925;6;6;0;2.619177;2.585464;3165258;3.65727e+008
2748.866;0.8081781;-2.611541;3206.972;331.3878;6;6;0;2.545443;2.513586;2943182;3.398231e+008
2755.866;0.7848745;-2.558136;2987.198;308.6778;6;6;0;2.472046;2.441985;2741485;3.163084e+008
2762.866;0.7613566;-2.503218;2780.936;287.364;6;6;0;2.397974;2.369674;2552189;2.942549e+008
2769.866;0.7380531;-2.447896;2590.014;267.6353;6;6;0;2.324577;2.29797;2376971;2.738567e+008
2776.866;0.7149103;-2.390501;2407.787;248.8052;6;6;0;2.251686;2.22671;2209734;2.544075e+008
2783.866;0.6914995;-2.330689;2233.427;230.7879;6;6;0;2.177951;2.154573;2049716;2.358144e+008
2790.866;0.6682496;-2.269318;2070.139;213.9148;6;6;0;2.104723;2.08288;1899859;2.184171e+008
2797.866;0.6448388;-2.206264;1917.341;198.1256;6;6;0;2.030988;2.010639;1759629;2.021495e+008
2805.866;0.6181067;-2.131854;1751.785;181.0182;6;6;0;1.946793;1.928085;1607692;1.845422e+008
2813.866;0.5914818;-2.055034;1599.044;165.2348;6;6;0;1.862935;1.845795;1467514;1.683131e+008
2822.866;0.5615354;-1.965779;1436.765;148.466;6;6;0;1.768615;1.753157;1318583;1.510918e+008
2830.866;0.5348568;-1.885914;1299.441;134.2758;6;6;0;1.684588;1.670557;1192555;1.365378e+008
2838.866;0.5082318;-1.806141;1166.288;120.5167;6;6;0;1.60073;1.588054;1070355;1.224458e+008
2845.866;0.4848747;-1.737017;1052.72;108.7813;6;6;0;1.527164;1.515621;966128.5;1.104426e+008
2852.866;0.461464;-1.668915;940.4828;97.18342;6;6;0;1.45343;1.442969;863123.1;9.859591e+007
2859.866;0.4381604;-1.602234;830.4885;85.81732;6;6;0;1.380033;1.370597;762176.4;8.700163e+007
2866.866;0.4146962;-1.536222;720.6303;74.46528;6;6;0;1.30613;1.297673;661354.6;7.543789e+007
2873.866;0.3914462;-1.472699;615.1088;63.56137;6;6;0;1.232901;1.225363;564512.8;6.434501e+007
2880.866;0.3682497;-1.411546;513.4354;53.0551;6;6;0;1.159842;1.153167;471202.5;5.367045e+007
2887.866;0.3448927;-1.35391;414.9371;42.87692;6;6;0;1.086276;1.080418;380806.3;4.334269e+007
2894.866;0.3215355;-1.299655;320.0836;33.07537;6;6;0;1.01271;1.007617;293755;3.341033e+007
2901.866;0.2981248;-1.248046;231.9654;23.96981;6;6;0;0.9389758;0.9345948;212885;2.419488e+007
2908.866;0.2748213;-1.19827;150.4309;15.54456;6;6;0;0.8655787;0.861854;138057.2;1.567911e+007
2915.866;0.251357;-1.150099;80.16179;8.283401;6;6;0;0.7916755;0.7885582;73568.05;8348979
2922.866;0.228107;-1.117366;49.23172;5.087288;6;6;0;0.7184473;0.7158787;45182.15;5123838
2929.866;0.2049106;-1.112513;48.82403;5.045159;6;6;0;0.6453876;0.6433139;44807.99;5077720
2936.866;0.1814999;-1.110299;48.70484;5.032843;6;6;0;0.5716531;0.5700254;44698.6;5061614
2943.552;0.1925892;-1.109193;49.17114;5.081028;7;7;0;0.60658;0.6047477;45126.55;5111849
2952.552;0.2226427;-1.10864;50.22104;5.189518;7;7;0;0.7012368;0.6987896;46090.09;5225909
2959.552;0.2458927;-1.120632;100.2562;10.35983;7;7;0;0.7744651;0.7714815;92009.56;1.044006e+007
2966.552;0.2692498;-1.146064;218.3478;22.56265;7;7;0;0.8480309;0.8444553;200387.5;2.275399e+007
2973.552;0.2924462;-1.174518;355.9845;36.78513;7;7;0;0.9210905;0.9168743;326702.8;3.712396e+007
2980.552;0.3158569;-1.205731;508.6504;52.56065;7;7;0;0.9948249;0.9899091;466811.2;5.308354e+007
2987.552;0.3391069;-1.238743;669.6518;69.19749;7;7;0;1.068053;1.06239;614569.3;6.993656e+007
2994.552;0.3625712;-1.276556;841.5235;86.9576;7;7;0;1.141956;1.135485;772303.6;8.795062e+007
3001.552;0.3859819;-1.317811;1015.828;104.9691;7;7;0;1.215691;1.208361;932270.9;1.062452e+008
3008.552;0.4091783;-1.362142;1191.371;123.1085;7;7;0;1.288751;1.280517;1093374;1.246951e+008
3015.552;0.432589;-1.410161;1368.097;141.3703;7;7;0;1.362485;1.353287;1255563;1.432964e+008
3022.552;0.4557854;-1.460326;1539.684;159.101;7;7;0;1.435545;1.425338;1413036;1.613849e+008
3029.552;0.4791425;-1.512512;1706.941;176.3842;7;7;0;1.50911;1.497837;1566536;1.79046e+008
3036.552;0.5024461;-1.567345;1872.386;193.4803;7;7;0;1.582507;1.570116;1718373;1.965422e+008
3043.552;0.5259104;-1.625414;2038.058;210.5998;7;7;0;1.656411;1.642842;1870417;2.140882e+008
3050.552;0.5492675;-1.686248;2202.022;227.5427;7;7;0;1.729977;1.715183;2020894;2.314791e+008
3057.552;0.5725175;-1.749578;2364.893;244.3727;7;7;0;1.803205;1.78714;2170367;2.487793e+008
3064.552;0.5959282;-1.816567;2530.026;261.4366;7;7;0;1.876939;1.859542;2321918;2.663436e+008
3071.552;0.6191246;-1.885395;2691.762;278.1493;7;7;0;1.949999;1.93123;2470350;2.835732e+008
3079.552;0.6493924;-1.977934;2907.442;300.4363;7;7;0;2.04533;2.024694;2668289;3.065812e+008
3087.552;0.6895174;-2.104847;3191.162;329.7541;7;7;0;2.171708;2.148463;2928672;3.369154e+008
3094.552;0.7244459;-2.216335;3446.379;356.1266;7;7;0;2.281719;2.256078;3162896;3.642524e+008
3101.552;0.7595352;-2.32544;3707.762;383.1362;7;7;0;2.392237;2.364071;3402779;3.923017e+008
3108.552;0.794571;-2.431261;3974.007;410.6482;7;7;0;2.502586;2.471784;3647123;4.20925e+008
3115.552;0.8293388;-2.534839;4251.202;439.2917;7;7;0;2.612091;2.578558;3901517;4.507664e+008
3122.552;0.8644816;-2.637844;4540.957;469.2332;7;7;0;2.722777;2.686368;4167439;4.820093e+008
3129.552;0.8995173;-2.739208;4836.169;499.7385;7;7;0;2.833125;2.793735;4438368;5.138967e+008
3136.552;0.9344459;-2.840869;5132.437;530.3529;7;7;0;2.943136;2.900658;4710267;5.459619e+008
3143.552;0.9694279;-2.946582;5418.715;559.9351;7;7;0;3.053316;3.00763;4972997;5.770316e+008
3150.552;1.004624;-3.060597;5679.926;586.9269;7;7;0;3.164171;3.115143;5212722;6.054983e+008
3157.552;1.039553;-3.183449;5901.591;609.8323;7;7;0;3.274182;3.221723;5416153;6.297993e+008
3164.552;1.074374;-3.310422;6097.684;630.0953;7;7;0;3.383856;3.327863;5596117;6.514168e+008
3171.552;1.109517;-3.445389;6287.907;649.7516;7;7;0;3.494542;3.434869;5770693;6.724575e+008
3178.552;1.144499;-3.585552;6469.271;668.4927;7;7;0;3.604722;3.541272;5937139;6.9259e+008
3185.552;1.179481;-3.728471;6645.984;686.7531;7;7;0;3.714902;3.647562;6099316;7.122653e+008
3192.552;1.21441;-3.87219;6812.938;704.005;7;7;0;3.824913;3.753577;6252537;7.309326e+008
3199.232;1.247731;-4.00967;6967.819;720.0095;7;7;0;3.929863;3.854609;6394679;7.483048e+008
3204.182;1.223249;-3.980035;6517.392;673.4651;7;7;0;3.852754;3.780388;5981301;6.994121e+008
3210.646;1.190785;-3.928217;5991.903;619.1646;7;7;0;3.750504;3.681883;5499037;6.423864e+008
3218.498;1.151678;-3.860557;5400.663;558.0696;7;7;0;3.627332;3.563093;4956430;5.783127e+008
3227.498;1.106678;-3.780431;4768.047;492.6992;7;7;0;3.4856;3.426228;4375849;5.098727e+008
3234.498;1.071589;-3.715665;4323.581;446.7709;7;7;0;3.375082;3.319376;3967943;4.618498e+008
3241.498;1.036553;-3.649701;3912.598;404.3026;7;7;0;3.264733;3.212573;3590766;4.17502e+008
3248.498;1.001624;-3.583832;3535.194;365.3041;7;7;0;3.154722;3.105983;3244405;3.768284e+008
3255.498;0.9665351;-3.515984;3180.749;328.678;7;7;0;3.044205;2.998788;2919115;3.386836e+008
3262.498;0.9314458;-3.444752;2845.509;294.0365;7;7;0;2.933688;2.891479;2611451;3.026626e+008
3269.498;0.8966244;-3.371602;2538.536;262.3159;7;7;0;2.824014;2.784874;2329728;2.697237e+008
3276.498;0.8616423;-3.295619;2250.073;232.508;7;7;0;2.713834;2.677663;2064992;2.388178e+008
3283.498;0.8266066;-3.216633;1981.31;204.7357;7;7;0;2.603485;2.570172;1818336;2.10066e+008
3290.498;0.7915174;-3.135354;1732.792;179.0555;7;7;0;2.492968;2.462401;1590260;1.835193e+008
3297.498;0.7566423;-3.051783;1508.442;155.8727;7;7;0;2.383126;2.355172;1384365;1.595873e+008
3304.498;0.7215531;-2.964171;1294.786;133.7949;7;7;0;2.272608;2.247169;1188283;1.368355e+008
3311.498;0.6864638;-2.873294;1093.076;112.9515;7;7;0;2.162091;2.139049;1003165;1.153936e+008
3318.498;0.6516424;-2.782674;910.4276;94.07771;7;7;0;2.052417;2.031639;835540;9.600858e+007
3325.498;0.6166067;-2.692659;740.0376;76.4707;7;7;0;1.942068;1.923451;679165.5;7.795581e+007
3332.498;0.5815711;-2.605303;581.7173;60.1109;7;7;0;1.83172;1.815146;533867.9;6.121197e+007
3339.498;0.5465354;-2.520683;434.4167;44.88981;7;7;0;1.721371;1.706724;398683.5;4.566253e+007
3346.498;0.5116604;-2.441313;301.1927;31.12331;7;7;0;1.611529;1.598681;276418;3.162487e+007
3353.498;0.4765176;-2.367937;178.4974;18.44477;7;7;0;1.500843;1.489692;163815.1;1.87216e+007
3360.498;0.4414819;-2.308674;75.73061;7.825512;7;7;0;1.390494;1.380915;69501.35;7934325
3368.498;0.4015176;-2.285329;48.10906;4.97128;7;7;0;1.264622;1.256693;44151.83;5034148
3372.652;0.3807319;-2.281792;48.10918;4.971292;7;7;0;1.199156;1.192023;44151.94;5030905