File: Ensayos/Compresion/EspA/EspA40.raw
"Test Type";"Manual"
"Method Name:";"C:\INSTRON\user\template\CYCLE.MTM"
"Name:";""
"Operator ID:";""
"Company:";""
"Lab name:";""
"Test date:";"27/03/2017"
"Temperature:";""
"Humidity:";""
"Note 1:";""
"Note 2:";""
"Note 3:";""
"Geometry:";"Rectangular"
"Specimen";1
"Specimen name:";""
"Width:";0.250000;"in"
"Thickness:";0.060000;"in"
"Length:";1.250000;"in"
"Diameter:";0.039370;"in"
"Inner diameter:";0.019685;"in"
"Outer diameter:";0.039370;"in"
"Wall thickness:";0.019685;"in"
"Area:";0.015000;"in*in"
"Linear density:";1.000000;"den"
"Sled weight:";2.204623;"lbf"
"Loading span:";0.000000;"mm"
"Support span:";1.000000;"mm"
"Span ratio:";"2"
"Fixture type:";"3-point"
"Comment:";""
"Included"
"Final Width:";0.250000;"in"
"Final Thickness:";0.060000;"in"
"Final Length:";1.250000;"in"
"Final Diameter:";0.039370;"in"
"Final Inner diameter:";0.019685;"in"
"Final Outer diameter:";0.039370;"in"
"Final Wall thickness:";0.019685;"in"
"Final Area:";0.015000;"in*in"
"Final Linear density:";1.000000;"den"
"Time sec";"Extension mm";"Strain 1 %";"Load N";"Stress MPa";"Cycle Count ";"Total Cycle Count ";"Repetitions Count ";"Strain [Exten.] %";"True strain %";"Tenacity gf/tex";"True stress Pa"
0;0;0.0003773661;56.79864;5.869204;0;0;0;0;0;52126.64;5869204
3;0.01007142;0.0005198573;57.28284;5.919239;0;0;0;0.03172101;0.03171599;52571.02;5921116
6;0.02008927;0.0005502685;57.45422;5.936947;0;0;0;0.0632733;0.06325329;52728.3;5940704
9;0.02999998;0.0005256577;57.33405;5.924531;0;0;0;0.09448814;0.09444352;52618.02;5930129
12;0.04001783;0.0005682954;57.4763;5.939229;0;0;0;0.1260404;0.125961;52748.56;5946715
15;0.04998211;0.0005751924;57.89372;5.982364;0;0;0;0.157424;0.1573002;53131.65;5991781
18;0.05994639;0.0005190738;60.00831;6.200871;0;0;0;0.1888075;0.1886295;55072.3;6212579
21;0.06991067;-2.831977e-005;78.92401;8.155497;0;0;0;0.2201911;0.219949;72432.08;8173455
24;0.07987494;-0.001840582;134.8022;13.92958;0;0;0;0.2515746;0.2512587;123713.9;1.396463e+007
27;0.08983923;-0.003988302;197.4815;20.40646;0;0;0;0.2829582;0.2825586;181237.5;2.04642e+007
30;0.09985708;-0.006620401;265.5899;27.44435;0;0;0;0.3145105;0.3140169;243743.7;2.753066e+007
33;0.1098214;-0.009823564;338.1928;34.94666;0;0;0;0.345894;0.3452972;310374.7;3.506754e+007
36;0.1198392;-0.01372476;414.7817;42.86086;0;0;0;0.3774463;0.3767358;380663.7;4.302264e+007
39;0.1298571;-0.01883879;495.5744;51.20945;0;0;0;0.4089986;0.4081645;454810.7;5.14189e+007
42;0.1399285;-0.02484397;581.3141;60.06924;0;0;0;0.4407196;0.4397513;533497.9;6.033398e+007
45;0.1499463;-0.03147038;669.5965;69.19177;0;0;0;0.4722719;0.4711602;614518.6;6.951855e+007
48;0.1599642;-0.03862537;759.1504;78.44569;0;0;0;0.5038242;0.5025593;696706.1;7.884092e+007
51;0.1699285;-0.04624233;850.7292;87.90886;0;0;0;0.5352077;0.5337806;780752.1;8.837935e+007
54;0.1799463;-0.05460137;943.182;97.46234;0;0;0;0.56676;0.56516;865600.2;9.801472e+007
57;0.1899642;-0.06349354;1037.344;107.1924;0;0;0;0.5983123;0.5965295;952016.9;1.078338e+008
60;0.1999284;-0.07264718;1132.072;116.981;0;0;0;0.6296958;0.6277216;1038953;1.177176e+008
63;0.2099463;-0.08188124;1227.058;126.7962;0;0;0;0.6612482;0.6590715;1126126;1.276347e+008
66;0.2199106;-0.09111105;1321.707;136.5767;0;0;0;0.6926317;0.6902441;1212990;1.375227e+008
69;0.2298749;-0.100616;1416.336;146.3551;0;0;0;0.7240153;0.7214069;1299835;1.474147e+008
72;0.2398927;-0.1102147;1511.361;156.1742;0;0;0;0.7555676;0.7527275;1387043;1.573542e+008
75;0.2499106;-0.1200441;1606.368;165.9917;0;0;0;0.7871199;0.7840382;1474236;1.672983e+008
78;0.2599284;-0.1300571;1700.419;175.7103;0;0;0;0.8186721;0.8153392;1560551;1.771488e+008
81.00001;0.2699462;-0.1403034;1794.491;185.4311;0;0;0;0.8502244;0.8466303;1646885;1.870077e+008
84.00001;0.2799641;-0.150573;1887.735;195.0663;0;0;0;0.8817767;0.8779117;1732458;1.967864e+008
87.00001;0.289982;-0.1608161;1979.78;204.5776;0;0;0;0.913329;0.9091834;1816932;2.064461e+008
90.00001;0.2999998;-0.1712802;2071.31;214.0358;0;0;0;0.9448813;0.9404452;1900934;2.160582e+008
93.00001;0.3100177;-0.1815423;2161.262;223.3309;0;0;0;0.9764336;0.9716973;1983487;2.255115e+008
96.00001;0.3200355;-0.1918323;2251.24;232.6286;0;0;0;1.007986;1.00294;2066064;2.349735e+008
97.342;0.3243212;-0.1962047;2289.298;236.5612;0;0;0;1.021484;1.016302;2100991;2.389777e+008
100.342;0.3143569;-0.1894452;2134.635;220.5794;0;0;0;0.9901005;0.9852311;1959050;2.227633e+008
103.342;0.3043391;-0.1817173;1993.32;205.9768;0;0;0;0.9585483;0.9539834;1829358;2.079512e+008
106.342;0.2943213;-0.1735654;1863.734;192.5863;0;0;0;0.9269961;0.9227258;1710432;1.943715e+008
109.342;0.284357;-0.1651597;1740.315;179.8329;0;0;0;0.8956125;0.8916257;1597165;1.814435e+008
112.342;0.2743927;-0.1565713;1621.736;167.5797;0;0;0;0.864229;0.8605159;1488339;1.690279e+008
115.342;0.2644284;-0.1480333;1505.642;155.5833;0;0;0;0.8328453;0.8293963;1381795;1.568791e+008
118.342;0.2544641;-0.1393679;1394.787;144.1283;0;0;0;0.8014618;0.7982671;1280058;1.452834e+008
121.342;0.2444463;-0.1307325;1288.137;133.1077;0;0;0;0.7699095;0.7669608;1182181;1.341325e+008
124.342;0.234482;-0.1222341;1186.708;122.6267;0;0;0;0.738526;0.7358122;1089095;1.235323e+008
127.342;0.2245177;-0.1140207;1089.642;112.5966;0;0;0;0.7071424;0.7046539;1000013;1.133928e+008
130.342;0.2144999;-0.105915;995.8981;102.9097;0;0;0;0.6755902;0.6733183;913980.1;1.036049e+008
131.762;0.209732;-0.1020824;952.2112;98.39536;1;1;0;0.6605732;0.658401;873886.8;9.904533e+007
134.762;0.2195891;-0.1081665;1080.952;111.6986;1;1;0;0.6916193;0.6892386;992037.4;1.124711e+008
137.762;0.229607;-0.1154173;1206.622;124.6845;1;1;0;0.7231717;0.7205693;1107371;1.255862e+008
140.762;0.2396784;-0.1229993;1327.802;137.2064;1;1;0;0.7548926;0.7520576;1218583;1.382422e+008
143.762;0.2496427;-0.1310714;1445.837;149.4035;1;1;0;0.7862761;0.7832011;1326910;1.505782e+008
146.762;0.2596605;-0.1394353;1562.333;161.4414;1;1;0;0.8178285;0.8145024;1433822;1.627617e+008
149.762;0.2696784;-0.1480569;1676.462;173.2347;1;1;0;0.8493808;0.8457939;1538564;1.747061e+008
152.762;0.2796963;-0.1566364;1787.731;184.7326;1;1;0;0.880933;0.8770755;1640681;1.8636e+008
155.762;0.2897141;-0.1654373;1896.808;196.0039;1;1;0;0.9124854;0.9083474;1740785;1.977924e+008
158.762;0.2997319;-0.1743527;2004.125;207.0933;1;1;0;0.9440376;0.9396094;1839275;2.090484e+008
161.762;0.3098034;-0.1833091;2110.037;218.0376;1;1;0;0.9757586;0.9710288;1936475;2.201651e+008
164.762;0.3198212;-0.1923665;2215.682;228.9543;1;1;0;1.007311;1.002271;2033430;2.312606e+008
167.762;0.3297855;-0.2008372;2323.159;240.0603;1;1;0;1.038695;1.033337;2132067;2.425537e+008
170.762;0.3398033;-0.2108683;2415.856;249.639;1;1;0;1.070247;1.06456;2217139;2.523108e+008
173.762;0.3497676;-0.2216571;2504.398;258.7884;1;1;0;1.10163;1.095607;2298398;2.616392e+008
176.762;0.3597319;-0.2323808;2593.585;268.0043;1;1;0;1.133014;1.126643;2380249;2.710408e+008
179.762;0.3696962;-0.2430703;2683.312;277.2761;1;1;0;1.164397;1.157671;2462595;2.805047e+008
182.762;0.3796605;-0.2541215;2775.162;286.7673;1;1;0;1.195781;1.188688;2546890;2.901964e+008
185.762;0.3896248;-0.2651739;2868.022;296.3629;1;1;0;1.227165;1.219696;2632112;2.999997e+008
188.762;0.399589;-0.2763903;2960.56;305.9252;1;1;0;1.258548;1.250694;2717038;3.097754e+008
191.762;0.4096069;-0.2878423;3055.673;315.7535;1;1;0;1.2901;1.281849;2804328;3.198271e+008
194.762;0.4196247;-0.2996174;3151.696;325.6759;1;1;0;1.321653;1.312995;2892452;3.299803e+008
197.762;0.4296426;-0.311419;3248.87;335.7173;1;1;0;1.353205;1.344131;2981633;3.402602e+008
200.762;0.4396604;-0.3233298;3345.733;345.7265;1;1;0;1.384757;1.375257;3070529;3.50514e+008
203.762;0.4497319;-0.3355018;3443.891;355.8694;1;1;0;1.416478;1.40654;3160613;3.609103e+008
206.762;0.4597497;-0.3477746;3542.874;366.0977;1;1;0;1.448031;1.437647;3251453;3.713989e+008
209.762;0.4697675;-0.360235;3642.114;376.3525;1;1;0;1.479583;1.468744;3342531;3.81921e+008
212.762;0.4797318;-0.3728034;3741.564;386.6291;1;1;0;1.510966;1.499665;3433800;3.924709e+008
215.762;0.4898033;-0.385423;3842.266;397.0349;1;1;0;1.542688;1.530909;3526219;4.031599e+008
218.762;0.4997676;-0.3980255;3940.473;407.1831;1;1;0;1.574071;1.561811;3616348;4.135924e+008
221.762;0.5097854;-0.4108849;4041.349;417.6069;1;1;0;1.605623;1.592869;3708926;4.243121e+008
224.762;0.5198032;-0.4239354;4142.452;428.0542;1;1;0;1.637175;1.623918;3801713;4.350622e+008
227.762;0.5297139;-0.4370352;4243.163;438.4611;1;1;0;1.66839;1.654626;3894140;4.457763e+008
230.762;0.5397318;-0.45027;4345.097;448.9942;1;1;0;1.699943;1.685655;3987689;4.566269e+008
233.762;0.5496425;-0.4637244;4446.623;459.4853;1;1;0;1.731157;1.716344;4080864;4.674397e+008
236.762;0.5596604;-0.4772307;4548.386;470.0008;1;1;0;1.76271;1.747354;4174257;4.782856e+008
239.762;0.5696246;-0.4907556;4649.678;480.4677;1;1;0;1.794093;1.778189;4267217;4.890877e+008
242.762;0.5795889;-0.5043295;4749.066;490.7378;1;1;0;1.825477;1.809015;4358430;4.996961e+008
245.762;0.5895532;-0.5179007;4849.115;501.0762;1;1;0;1.856861;1.839831;4450249;5.103805e+008
248.762;0.599571;-0.5316782;4949.102;511.4082;1;1;0;1.888413;1.870804;4542012;5.210657e+008
251.762;0.6095889;-0.5454836;5049.489;521.7816;1;1;0;1.919965;1.901766;4634141;5.317996e+008
254.762;0.6196067;-0.5595993;5148.993;532.0637;1;1;0;1.951517;1.932719;4725461;5.42447e+008
257.762;0.6296782;-0.5740482;5249.514;542.4509;1;1;0;1.983238;1.963828;4817713;5.53209e+008
260.762;0.639696;-0.5887471;5349.459;552.7786;1;1;0;2.014791;1.994762;4909438;5.639159e+008
263.762;0.6496603;-0.6037145;5448.481;563.0108;1;1;0;2.046174;2.025521;5000314;5.74531e+008
266.762;0.6597317;-0.6188059;5546.778;573.1682;1;1;0;2.077895;2.056601;5090526;5.850781e+008
269.762;0.6697496;-0.6342645;5643.324;583.1447;1;1;0;2.109447;2.087507;5179130;5.954458e+008
272.762;0.6796603;-0.6498189;5735.825;592.7031;1;1;0;2.140662;2.118072;5264023;6.053909e+008
275.762;0.6896781;-0.6661064;5825.118;601.9301;1;1;0;2.172215;2.148958;5345971;6.150053e+008
278.762;0.6996424;-0.6829968;5907.83;610.4769;1;1;0;2.203598;2.17967;5421879;6.239294e+008
281.762;0.7096067;-0.7012237;5983.63;618.3096;1;1;0;2.234982;2.210372;5491444;6.321287e+008
284.762;0.7196246;-0.7213768;6050.335;625.2025;1;1;0;2.266534;2.24123;5552662;6.393729e+008
287.762;0.7296424;-0.7431648;6109.287;631.2943;1;1;0;2.298086;2.272078;5606765;6.458019e+008
290.762;0.7396602;-0.7659101;6161.631;636.7032;1;1;0;2.329638;2.302916;5654804;6.515361e+008
293.762;0.7496781;-0.7896763;6209.918;641.6928;1;1;0;2.361191;2.333746;5699119;6.568444e+008
296.762;0.7596959;-0.8140786;6254.166;646.2651;1;1;0;2.392743;2.364566;5739727;6.617286e+008
299.762;0.7696602;-0.8390408;6296.358;650.6249;1;1;0;2.424127;2.395211;5778449;6.663969e+008
302.762;0.7797316;-0.8642664;6337.498;654.876;1;1;0;2.455848;2.426177;5816204;6.709588e+008
305.762;0.7897495;-0.889702;6376.153;658.8704;1;1;0;2.4874;2.456968;5851680;6.752592e+008
308.762;0.7997674;-0.9150784;6413.855;662.7664;1;1;0;2.518952;2.48775;5886281;6.794611e+008
311.762;0.8097316;-0.9407893;6449.495;666.4492;1;1;0;2.550336;2.518357;5918989;6.834458e+008
314.762;0.8197495;-0.9665754;6487.058;670.3307;1;1;0;2.581888;2.54912;5953463;6.876379e+008
317.762;0.8298209;-0.9928149;6518.741;673.6046;1;1;0;2.613609;2.580038;5982540;6.9121e+008
320.762;0.8397852;-1.018406;6554.782;677.3288;1;1;0;2.644993;2.610618;6015616;6.952441e+008
323.602;0.8491066;-1.042821;6586.305;680.5862;1;1;0;2.674351;2.639216;6044547;6.987875e+008
325.588;0.8426244;-1.041117;6439.092;665.3742;1;1;0;2.653935;2.619329;5909443;6.830328e+008
328.588;0.8326066;-1.032844;6244.795;645.2968;1;1;0;2.622383;2.588588;5731128;6.62219e+008
331.588;0.8226423;-1.024112;6063.171;626.5289;1;1;0;2.590999;2.558002;5564443;6.427623e+008
334.588;0.8126245;-1.015056;5889.38;608.5706;1;1;0;2.559447;2.527242;5404947;6.241466e+008
337.588;0.8026602;-1.005761;5724.474;591.5302;1;1;0;2.528064;2.496637;5253605;6.064844e+008
340.588;0.7926423;-0.9963087;5563.34;574.8796;1;1;0;2.496511;2.465858;5105726;5.892316e+008
343.588;0.7825709;-0.98658;5405.602;558.58;1;1;0;2.46479;2.434904;4960962;5.723478e+008
346.588;0.772553;-0.9766994;5251.208;542.6259;1;1;0;2.433238;2.404106;4819268;5.558293e+008
349.588;0.7625352;-0.9667598;5100.148;527.0164;1;1;0;2.401686;2.373299;4680634;5.396737e+008
352.588;0.7525174;-0.9566928;4951.759;511.6828;1;1;0;2.370133;2.342482;4544450;5.238103e+008
355.588;0.7424995;-0.9463575;4806.433;496.6657;1;1;0;2.338581;2.311655;4411078;5.082807e+008
358.588;0.7324817;-0.9362105;4663.243;481.8694;1;1;0;2.307029;2.280819;4279666;4.929863e+008
361.588;0.7224638;-0.9257711;4522.865;467.3637;1;1;0;2.275476;2.249974;4150835;4.779984e+008
364.588;0.712446;-0.915275;4384.15;453.0298;1;1;0;2.243924;2.219119;4023530;4.631954e+008
367.588;0.7024281;-0.9047902;4248.194;438.9809;1;1;0;2.212372;2.188254;3898757;4.486928e+008
370.588;0.6924638;-0.8945063;4116.518;425.3744;1;1;0;2.180988;2.157545;3777913;4.346518e+008
373.588;0.6824995;-0.8841679;3987.789;412.0723;1;1;0;2.149605;2.126827;3659772;4.209302e+008
376.588;0.6725352;-0.8737797;3862.174;399.0921;1;1;0;2.118221;2.096099;3544489;4.075457e+008
379.588;0.662571;-0.8634456;3739.018;386.366;1;1;0;2.086838;2.065361;3431464;3.944288e+008
382.588;0.6526067;-0.8528689;3618.282;373.8899;1;1;0;2.055454;2.034615;3320659;3.81575e+008
385.588;0.6426424;-0.8425124;3500.164;361.6844;1;1;0;2.024071;2.003859;3212257;3.690051e+008
388.588;0.6326246;-0.8320969;3385.437;349.8292;1;1;0;1.992518;1.972928;3106967;3.567996e+008
391.588;0.6226067;-0.8217979;3273.537;338.2661;1;1;0;1.960966;1.941987;3004271;3.448994e+008
394.588;0.6125888;-0.8114852;3164.406;326.9893;1;1;0;1.929414;1.911037;2904116;3.332982e+008
397.588;0.6025711;-0.8013208;3057.749;315.968;1;1;0;1.897862;1.880077;2806233;3.219647e+008
400.588;0.5925532;-0.7909733;2952.872;305.1307;1;1;0;1.866309;1.849107;2709982;3.108254e+008
403.588;0.5825354;-0.7806945;2850.432;294.5453;1;1;0;1.834757;1.818128;2615969;2.999494e+008
406.588;0.5725175;-0.7702216;2748.955;284.0592;1;1;0;1.803205;1.78714;2522839;2.891814e+008
409.588;0.5624461;-0.7605607;2646.558;273.4782;1;1;0;1.771484;1.755976;2428864;2.783228e+008
412.588;0.5524282;-0.7488883;2548.601;263.3559;1;1;0;1.739931;1.724968;2338965;2.679381e+008
415.588;0.5424104;-0.7376979;2450.366;253.205;1;1;0;1.708379;1.69395;2248810;2.575307e+008
418.588;0.5324461;-0.7261064;2356.001;243.4539;1;1;0;1.676996;1.663089;2162207;2.475367e+008
421.588;0.5224282;-0.7167938;2261.636;233.7029;1;1;0;1.645443;1.632052;2075604;2.375483e+008
424.588;0.5124639;-0.7059853;2171.729;224.4124;1;1;0;1.61406;1.601172;1993092;2.280345e+008
427.588;0.5025533;-0.6936147;2083.614;215.3073;1;1;0;1.582845;1.570449;1912226;2.187152e+008
430.588;0.492589;-0.6832696;1996.855;206.3421;1;1;0;1.551461;1.539549;1832603;2.095435e+008
433.588;0.4825711;-0.6709673;1911.188;197.4898;1;1;0;1.519909;1.508474;1753982;2.004915e+008
436.588;0.4726068;-0.6591883;1827.218;188.8129;1;1;0;1.488526;1.477556;1676920;1.916234e+008
439.588;0.462589;-0.6472201;1745.433;180.3618;1;1;0;1.456973;1.446461;1601862;1.829896e+008
442.588;0.4526247;-0.6353282;1665.362;172.0878;1;1;0;1.42559;1.415524;1528377;1.74541e+008
445.588;0.4426068;-0.6231099;1586.744;163.9638;1;1;0;1.394037;1.38441;1456225;1.662496e+008
448.588;0.4326426;-0.610817;1508.945;155.9247;1;1;0;1.362654;1.353453;1384826;1.580494e+008
451.588;0.4226247;-0.5983842;1432.985;148.0754;1;1;0;1.331102;1.32232;1315114;1.500464e+008
454.588;0.4126069;-0.5857051;1358.98;140.4282;1;1;0;1.299549;1.291178;1247196;1.422531e+008
457.588;0.402589;-0.5730445;1286.632;132.9522;1;1;0;1.267997;1.260025;1180799;1.34638e+008
460.588;0.3925712;-0.5603825;1216.105;125.6645;1;1;0;1.236445;1.228863;1116074;1.272182e+008
463.588;0.3825533;-0.5475629;1147.879;118.6143;1;1;0;1.204892;1.197691;1053459;1.200435e+008
466.588;0.3725355;-0.5347382;1082.209;111.8285;1;1;0;1.17334;1.16651;993191.3;1.131406e+008
469.588;0.3625712;-0.5217633;1017.502;105.1421;1;1;0;1.141956;1.135485;933806.9;1.063428e+008
472.588;0.3525534;-0.5086939;954.7586;98.65858;1;1;0;1.110404;1.104285;876224.5;9.975409e+007
475.588;0.3425891;-0.4955464;893.4609;92.32448;1;1;0;1.079021;1.073241;819968.9;9.332068e+007
478.588;0.3326248;-0.482198;833.3669;86.11475;1;1;0;1.047637;1.042187;764817.9;8.701692e+007
481.588;0.3226069;-0.4688786;774.1924;80.00005;1;1;0;1.016085;1.010957;710510.9;8.081291e+007
484.588;0.3126427;-0.455477;716.8561;74.07528;1;1;0;0.9847013;0.9798847;657890.8;7.48047e+007
487.588;0.3026248;-0.4423146;660.6366;68.26592;1;1;0;0.953149;0.9486352;606295.7;6.89166e+007
490.588;0.2926069;-0.4287323;605.2872;62.54647;1;1;0;0.9215967;0.9173759;555499.1;6.312289e+007
493.588;0.2825891;-0.4151954;550.9422;56.93081;1;1;0;0.8900445;0.8861069;505624.3;5.743752e+007
496.588;0.2725713;-0.4013757;496.9448;51.35107;1;1;0;0.8584921;0.854828;456068.4;5.179191e+007
499.588;0.2625534;-0.3874598;444.2221;45.90304;1;1;0;0.8269399;0.8235394;407682.4;4.628263e+007
502.588;0.2525355;-0.3729839;392.8181;40.59129;1;1;0;0.7953875;0.792241;360506.7;4.091415e+007
505.588;0.2425177;-0.3586667;343.3761;35.48227;1;1;0;0.7638353;0.7609328;315131.6;3.575329e+007
508.588;0.2324999;-0.3441894;295.9802;30.58468;1;1;0;0.732283;0.7296148;271634.3;3.080865e+007
511.588;0.222482;-0.3300766;250.4558;25.88049;1;1;0;0.7007307;0.698287;229854.5;2.606184e+007
514.588;0.2124641;-0.3160113;207.4467;21.4362;1;1;0;0.6691784;0.6669494;190383.1;2.157965e+007
517.588;0.2024999;-0.3022235;167.1333;17.27048;1;1;0;0.6377949;0.6357696;153385.7;1.738062e+007
520.588;0.192482;-0.2891859;128.8756;13.31717;1;1;0;0.6062426;0.6044123;118274.9;1.339791e+007
523.588;0.1825177;-0.2777982;95.02297;9.819059;1;1;0;0.574859;0.573213;87206.81;9875505
526.588;0.1725535;-0.2698122;65.69785;6.788792;1;1;0;0.5434754;0.542004;60293.85;6825687
529.588;0.1625892;-0.2656042;56.42532;5.830628;1;1;0;0.5120919;0.5107851;51784.03;5860486
531.0241;0.1643035;-0.2650332;57.67046;5.959293;2;2;0;0.5174912;0.5161568;52926.75;5990132
534.0241;0.1743749;-0.2653689;87.23281;9.014075;2;2;0;0.5492123;0.5477096;80057.45;9063582
537.0241;0.1844463;-0.267717;145.4083;15.02555;2;2;0;0.5809333;0.5792523;133447.6;1.511284e+007
540.0241;0.1944642;-0.2707372;212.242;21.93172;2;2;0;0.6124855;0.6106175;194784;2.206605e+007
543.0241;0.204482;-0.2745688;283.1931;29.26335;2;2;0;0.6440378;0.6419727;259899;2.945182e+007
546.0241;0.2144999;-0.2793383;357.3804;36.92938;2;2;0;0.6755902;0.6733183;327983.9;3.717887e+007
549.0241;0.2245177;-0.2847892;435.6215;45.01431;2;2;0;0.7071424;0.7046539;399789.3;4.533262e+007
552.0241;0.2345891;-0.2910388;518.3915;53.56723;2;2;0;0.7388634;0.7361472;475751;5.396302e+007
555.0241;0.2444998;-0.2977506;603.666;62.37894;2;2;0;0.7700782;0.7671282;554011.2;6.285931e+007
558.0241;0.2545177;-0.3047557;690.6239;71.36461;2;2;0;0.8016305;0.7984345;633816.4;7.193669e+007
561.0241;0.264482;-0.3123119;779.7557;80.57492;2;2;0;0.8330141;0.8295637;715616.6;8.124612e+007
564.0241;0.2744462;-0.320591;870.3535;89.93671;2;2;0;0.8643976;0.8606831;798762.3;9.071412e+007
567.0241;0.2844105;-0.3290768;961.4501;99.35004;2;2;0;0.8957812;0.8917929;882365.6;1.0024e+008
570.0241;0.2943748;-0.3377519;1052.089;108.7161;2;2;0;0.9271647;0.9228929;965549.4;1.097241e+008
573.0241;0.3043927;-0.3468322;1142.565;118.0652;2;2;0;0.958717;0.9541505;1048583;1.191972e+008
576.0241;0.3143569;-0.3562051;1234.099;127.5238;2;2;0;0.9901005;0.9852311;1132588;1.287864e+008
579.0241;0.3243212;-0.3654191;1326.893;137.1126;2;2;0;1.021484;1.016302;1217749;1.385132e+008
582.0241;0.3342855;-0.374962;1419.537;146.6858;2;2;0;1.052868;1.047364;1302773;1.482302e+008
585.0241;0.3443569;-0.3844436;1512.761;156.3189;2;2;0;1.084589;1.078749;1388328;1.580143e+008
588.0241;0.3543748;-0.3942617;1606.423;165.9974;2;2;0;1.116141;1.109958;1474286;1.678502e+008
591.0241;0.3643926;-0.4040093;1699.495;175.6149;2;2;0;1.147693;1.141157;1559703;1.776304e+008
594.0241;0.3744104;-0.4140682;1793.056;185.2828;2;2;0;1.179245;1.172347;1645568;1.874678e+008
597.0241;0.3844283;-0.4242341;1886.367;194.925;2;2;0;1.210798;1.203526;1731204;1.972852e+008
600.0241;0.3944462;-0.434605;1980.34;204.6356;2;2;0;1.24235;1.234696;1817447;2.071779e+008
603.0241;0.404464;-0.4451528;2075.339;214.4521;2;2;0;1.273903;1.265857;1904631;2.17184e+008
606.0241;0.4144283;-0.4560148;2170.486;224.284;2;2;0;1.305286;1.296841;1991952;2.272116e+008
609.0241;0.4243926;-0.4667263;2265.312;234.0827;2;2;0;1.33667;1.327815;2078978;2.372116e+008
612.0241;0.4344104;-0.4776284;2360.872;243.9573;2;2;0;1.368222;1.358946;2166678;2.472951e+008
615.0241;0.4443747;-0.4886532;2455.705;253.7567;2;2;0;1.399606;1.389901;2253710;2.573083e+008
618.0241;0.4543926;-0.4999352;2551.472;263.6526;2;2;0;1.431158;1.421013;2341599;2.674259e+008
621.0241;0.4643569;-0.5112879;2648.189;273.6467;2;2;0;1.462541;1.451949;2430361;2.776489e+008
624.0241;0.4743747;-0.5229221;2746.586;283.8144;2;2;0;1.494094;1.483042;2520664;2.880549e+008
627.0241;0.4843925;-0.5345706;2845.302;294.0151;2;2;0;1.525646;1.514125;2611261;2.985007e+008
630.0241;0.4944104;-0.5462266;2943.556;304.1681;2;2;0;1.557198;1.545198;2701433;3.089045e+008
633.0241;0.5044282;-0.5580355;3043.522;314.4979;2;2;0;1.58875;1.576262;2793176;3.194945e+008
636.0241;0.5144461;-0.5700598;3144.065;324.8874;2;2;0;1.620303;1.607316;2885449;3.301515e+008
639.0241;0.5244639;-0.5821594;3245.308;335.3491;2;2;0;1.651855;1.63836;2978364;3.408886e+008
642.0241;0.5344818;-0.5944341;3346.626;345.8187;2;2;0;1.683407;1.669395;3071348;3.516402e+008
645.0241;0.5444997;-0.6068263;3448.395;356.3349;2;2;0;1.71496;1.70042;3164746;3.624459e+008
648.0241;0.5545175;-0.6194126;3551.381;366.9768;2;2;0;1.746512;1.731436;3259261;3.733861e+008
651.0241;0.5645353;-0.6318341;3653.247;377.5029;2;2;0;1.778064;1.762441;3352748;3.842152e+008
654.0241;0.5744996;-0.644348;3754.389;387.9543;2;2;0;1.809448;1.793272;3445570;3.949741e+008
657.0241;0.5845175;-0.6568407;3855.202;398.3716;2;2;0;1.841;1.824259;3538091;4.057057e+008
660.0241;0.5944818;-0.6695209;3955.433;408.7289;2;2;0;1.872384;1.85507;3630077;4.163818e+008
663.0241;0.6044461;-0.6821273;4056.015;419.1223;2;2;0;1.903767;1.885872;3722386;4.271015e+008
666.0241;0.6144103;-0.6950169;4157.23;429.5813;2;2;0;1.935151;1.916665;3815276;4.378944e+008
669.0241;0.6243746;-0.7078996;4257.884;439.9823;2;2;0;1.966534;1.947448;3907650;4.486347e+008
672.0241;0.6343389;-0.7210439;4359.857;450.5195;2;2;0;1.997918;1.978221;4001236;4.595205e+008
675.0241;0.6443567;-0.7345548;4463.208;461.1991;2;2;0;2.02947;2.009151;4096085;4.70559e+008
678.0241;0.6543746;-0.7481459;4567.323;471.9576;2;2;0;2.061022;2.040071;4191636;4.816848e+008
681.0241;0.6643924;-0.7618013;4671.705;482.7439;2;2;0;2.092575;2.070981;4287433;4.928456e+008
684.0241;0.6744639;-0.7756482;4776.915;493.6156;2;2;0;2.124296;2.102047;4383989;5.041014e+008
687.0241;0.6844282;-0.7894716;4880.604;504.3301;2;2;0;2.155679;2.132773;4479148;5.152018e+008
690.0241;0.694446;-0.8034236;4984.827;515.0998;2;2;0;2.187232;2.163655;4574798;5.263662e+008
693.0241;0.7045174;-0.8176216;5089.533;525.9195;2;2;0;2.218952;2.194692;4670892;5.375894e+008
696.0241;0.7145352;-0.8318824;5193.897;536.7037;2;2;0;2.250504;2.225554;4766671;5.487823e+008
699.0241;0.7244995;-0.8461422;5297.42;547.4011;2;2;0;2.281888;2.256242;4861678;5.598922e+008
702.0241;0.7345174;-0.8606061;5401.381;558.1439;2;2;0;2.313441;2.287086;4957089;5.710562e+008
705.0241;0.7445888;-0.8748218;5503.926;568.7401;2;2;0;2.345162;2.318085;5051198;5.82078e+008
708.0241;0.7545531;-0.8890753;5604.858;579.1697;2;2;0;2.376545;2.348745;5143828;5.92934e+008
711.0241;0.7645174;-0.9034242;5705.399;589.5591;2;2;0;2.407929;2.379395;5236100;6.037553e+008
714.0241;0.774428;-0.9179261;5805.013;599.8525;2;2;0;2.439143;2.409871;5327519;6.144838e+008
717.0241;0.7843923;-0.9325339;5903.612;610.0411;2;2;0;2.470527;2.440503;5418008;6.251124e+008
720.0241;0.7944102;-0.9472392;6001.523;620.1586;2;2;0;2.502079;2.47129;5507866;6.356755e+008
723.0241;0.8043745;-0.9620436;6098.717;630.2021;2;2;0;2.533463;2.501903;5597065;6.46168e+008
726.0241;0.8143388;-0.9771401;6192.804;639.9244;2;2;0;2.564847;2.532506;5683413;6.563374e+008
729.0241;0.8243566;-0.9926719;6287.158;649.6743;2;2;0;2.596399;2.563265;5770006;6.665425e+008
732.0241;0.8343209;-1.008457;6376.338;658.8896;2;2;0;2.627782;2.593849;5851850;6.762038e+008
735.0241;0.8443388;-1.025041;6462.349;667.7775;2;2;0;2.659335;2.624589;5930787;6.855359e+008
738.0241;0.8543566;-1.042826;6542.387;676.048;2;2;0;2.690887;2.655319;6004241;6.942397e+008
741.0241;0.8643745;-1.062219;6614.808;683.5316;2;2;0;2.722439;2.68604;6070705;7.021403e+008
744.0241;0.8744458;-1.083459;6677.179;689.9766;2;2;0;2.75416;2.716915;6127945;7.089796e+008
747.0241;0.8844637;-1.106351;6730.54;695.4905;2;2;0;2.785712;2.747617;6176916;7.148648e+008
750.0241;0.894428;-1.130869;6777.161;700.308;2;2;0;2.817096;2.778146;6219703;7.200364e+008
753.0241;0.9044458;-1.15663;6817.516;704.4781;2;2;0;2.848648;2.808829;6256739;7.245462e+008
756.0241;0.9144637;-1.18263;6854.888;708.3398;2;2;0;2.880201;2.839502;6291037;7.287415e+008
759.0241;0.9244279;-1.208643;6889.974;711.9653;2;2;0;2.911584;2.870003;6323236;7.326948e+008
762.0241;0.9343922;-1.234507;6923.288;715.4078;2;2;0;2.942968;2.900494;6353810;7.364621e+008
765.0241;0.9443565;-1.261757;6956.096;718.798;2;2;0;2.974351;2.930975;6383920;7.401776e+008
768.0241;0.9543744;-1.289526;6989.519;722.2517;2;2;0;3.005904;2.961612;6414593;7.439619e+008
771.0241;0.9643922;-1.316842;7022.257;725.6347;2;2;0;3.037456;2.992239;6444639;7.476756e+008
774.0241;0.9744101;-1.343851;7053.648;728.8784;2;2;0;3.069008;3.022856;6473447;7.512477e+008
777.0241;0.9843743;-1.370864;7086.239;732.2462;2;2;0;3.100392;3.0533;6503358;7.549487e+008
780.0241;0.9943922;-1.398188;7118.687;735.5991;2;2;0;3.131944;3.083899;6533137;7.586377e+008
783.0241;1.004464;-1.425907;7150.82;738.9195;2;2;0;3.163665;3.114652;6562626;7.622965e+008
786.0241;1.014481;-1.453326;7182.488;742.192;2;2;0;3.195217;3.145232;6591690;7.659066e+008
789.0241;1.024446;-1.480721;7213.895;745.4373;2;2;0;3.226601;3.175639;6620513;7.694895e+008
792.0241;1.034517;-1.508447;7246.07;748.7621;2;2;0;3.258322;3.206364;6650042;7.731592e+008
795.0241;1.044535;-1.535712;7277.648;752.0251;2;2;0;3.289874;3.236916;6679022;7.767658e+008
798.0241;1.054499;-1.562494;7308.479;755.211;2;2;0;3.321258;3.267295;6707317;7.802935e+008
801.0241;1.064517;-1.589137;7339.31;758.3969;2;2;0;3.35281;3.297829;6735612;7.838245e+008
804.0241;1.074535;-1.615604;7370.072;761.5756;2;2;0;3.384362;3.328353;6763844;7.873501e+008
807.0241;1.084499;-1.642126;7401.334;764.806;2;2;0;3.415746;3.358704;6792534;7.909298e+008
810.0241;1.094464;-1.669259;7432.474;768.0239;2;2;0;3.447129;3.389047;6821113;7.944986e+008
813.0241;1.104481;-1.69631;7463.066;771.185;2;2;0;3.478682;3.419543;6849188;7.980121e+008
816.0241;1.114392;-1.722889;7492.941;774.2722;2;2;0;3.509896;3.449704;6876607;8.014483e+008
819.0241;1.124356;-1.74956;7523.43;777.4227;2;2;0;3.54128;3.480019;6904587;8.049534e+008
822.0241;1.134321;-1.775858;7552.886;780.4664;2;2;0;3.572663;3.510324;6931621;8.083499e+008
825.0241;1.144339;-1.802224;7584.315;783.7142;2;2;0;3.604216;3.540784;6960465;8.119609e+008
828.0241;1.154356;-1.828183;7615.44;786.9304;2;2;0;3.635768;3.571234;6989030;8.155414e+008
831.0241;1.164374;-1.854689;7646.856;790.1768;2;2;0;3.667321;3.601675;7017861;8.19155e+008
834.0241;1.174392;-1.880993;7678.28;793.4239;2;2;0;3.698873;3.632106;7046700;8.227716e+008
837.0241;1.184464;-1.907306;7710.288;796.7313;2;2;0;3.730594;3.662691;7076075;8.264542e+008
840.0241;1.194481;-1.933751;7742.403;800.0499;2;2;0;3.762146;3.693104;7105549;8.301489e+008
843.0241;1.204499;-1.960749;7772.445;803.1543;2;2;0;3.793698;3.723507;7133120;8.336235e+008
846.0241;1.214517;-1.987907;7804.627;806.4798;2;2;0;3.82525;3.753902;7162655;8.373297e+008
847.6441;1.219767;-2.002457;7820.547;808.1248;2;2;0;3.841786;3.769827;7177265;8.391713e+008
850.5701;1.210178;-1.999003;7602.332;785.5759;2;2;0;3.811584;3.740737;6976999;8.155187e+008
853.5701;1.20016;-1.990931;7405.833;765.2709;2;2;0;3.780031;3.710339;6796663;7.941984e+008
856.5701;1.190196;-1.982305;7220.682;746.1386;2;2;0;3.748648;3.680094;6626742;7.741087e+008
859.5701;1.180178;-1.973533;7043.614;727.8416;2;2;0;3.717095;3.649677;6464239;7.548961e+008
862.5701;1.17016;-1.964772;6874.727;710.39;2;2;0;3.685543;3.619251;6309244;7.365717e+008
865.5701;1.160142;-1.955843;6712.847;693.6622;2;2;0;3.653991;3.588816;6160679;7.190086e+008
868.5701;1.150071;-1.946758;6553.88;677.2357;2;2;0;3.62227;3.558208;6014788;7.01767e+008
871.5701;1.140053;-1.93764;6399.555;661.2886;2;2;0;3.590718;3.527754;5873157;6.850337e+008
874.5701;1.130035;-1.928339;6248.926;645.7236;2;2;0;3.559165;3.497291;5734918;6.68706e+008
877.5701;1.120017;-1.919023;6100.582;630.3947;2;2;0;3.527613;3.466819;5598776;6.526326e+008
880.5701;1.109999;-1.909542;5954.227;615.2714;2;2;0;3.496061;3.436337;5464460;6.367816e+008
883.5701;1.099981;-1.900046;5810.506;600.4201;2;2;0;3.464508;3.405845;5332560;6.212217e+008
886.5701;1.089964;-1.890424;5669.194;585.8179;2;2;0;3.432956;3.375345;5202872;6.059287e+008
889.5701;1.079946;-1.880849;5530.294;571.4649;2;2;0;3.401404;3.344835;5075398;5.909027e+008
892.5701;1.070035;-1.871176;5395.171;557.5021;2;2;0;3.370189;3.314643;4951389;5.76291e+008
895.5701;1.060017;-1.861549;5260.675;543.6041;2;2;0;3.338637;3.284114;4827956;5.617531e+008
898.5701;1.050053;-1.851726;5128.437;529.9395;2;2;0;3.307253;3.25374;4706595;5.47466e+008
901.5701;1.040089;-1.842057;4998.51;516.5137;2;2;0;3.27587;3.223357;4587356;5.334341e+008
904.5701;1.030124;-1.83218;4870.218;503.2569;2;2;0;3.244486;3.192964;4469617;5.19585e+008
907.5701;1.02016;-1.822196;4743.752;490.1887;2;2;0;3.213103;3.162562;4353553;5.05939e+008
910.5701;1.010142;-1.812255;4619.056;477.3034;2;2;0;3.18155;3.131987;4239114;4.92489e+008
913.5701;1.000124;-1.802042;4495.844;464.5714;2;2;0;3.149998;3.101403;4126036;4.792054e+008
916.5701;0.99016;-1.7919;4373.894;451.9699;2;2;0;3.118614;3.070973;4014118;4.660651e+008
919.5701;0.9800886;-1.781783;4254.861;439.6698;2;2;0;3.086893;3.040207;3904875;4.532419e+008
922.5701;0.9701244;-1.771594;4138.268;427.6219;2;2;0;3.05551;3.009759;3797873;4.406879e+008
925.5701;0.960053;-1.761431;4022.753;415.6853;2;2;0;3.023789;2.978974;3691860;4.282548e+008
928.5701;0.9500352;-1.75133;3909.774;404.0108;2;2;0;2.992237;2.948343;3588174;4.160998e+008
931.5701;0.9400173;-1.741054;3798.59;392.5218;2;2;0;2.960684;2.917702;3486136;4.041431e+008
934.5701;0.9299994;-1.730871;3688.141;381.1086;2;2;0;2.929132;2.887053;3384771;3.922718e+008
937.5701;0.9199815;-1.720684;3580.352;369.9705;2;2;0;2.89758;2.856394;3285849;3.806907e+008
940.5701;0.9099637;-1.710405;3474.03;358.9838;2;2;0;2.866027;2.825725;3188272;3.692724e+008
943.5701;0.8999459;-1.700137;3369.754;348.2086;2;2;0;2.834475;2.795047;3092574;3.580785e+008
946.5701;0.8900352;-1.689914;3266.663;337.5559;2;2;0;2.80326;2.764688;2997963;3.470184e+008
949.5701;0.8800709;-1.679393;3164.757;327.0255;2;2;0;2.771877;2.734156;2904439;3.360903e+008
952.5701;0.8701066;-1.668951;3064.903;316.7073;2;2;0;2.740493;2.703614;2812799;3.253866e+008
955.5701;0.8600887;-1.658342;2964.883;306.3719;2;2;0;2.708941;2.672898;2721005;3.146713e+008
958.5701;0.8501244;-1.647666;2867.873;296.3475;2;2;0;2.677557;2.642338;2631975;3.042824e+008
961.5701;0.8401066;-1.637043;2772.289;286.4704;2;2;0;2.646005;2.611604;2544253;2.940505e+008
964.5701;0.8301423;-1.626426;2677.842;276.7109;2;2;0;2.614621;2.581025;2457575;2.839458e+008
967.5701;0.8201245;-1.615603;2585.565;267.1756;2;2;0;2.583069;2.550272;2372888;2.740769e+008
970.5701;0.8101602;-1.604888;2495.374;257.8558;2;2;0;2.551686;2.519674;2290116;2.644355e+008
973.5701;0.8001423;-1.593931;2405.92;248.6123;2;2;0;2.520133;2.488901;2208021;2.548776e+008
976.5701;0.7901245;-1.582549;2317.491;239.4746;2;2;0;2.488581;2.45812;2126865;2.454341e+008
979.5701;0.7801066;-1.570895;2229.677;230.4004;2;2;0;2.457029;2.427329;2046274;2.360614e+008
982.5701;0.7700888;-1.559098;2143.587;221.5044;2;2;0;2.425477;2.396529;1967265;2.26877e+008
985.5701;0.7601245;-1.547007;2059.072;212.7712;2;2;0;2.394093;2.365884;1889703;2.178652e+008
988.5701;0.7501067;-1.534609;1974.44;204.0259;2;2;0;2.362541;2.335065;1812032;2.088461e+008
991.5701;0.7400888;-1.521888;1891.366;195.4415;2;2;0;2.330988;2.304236;1735791;1.999973e+008
994.5701;0.730071;-1.508936;1809.692;187.0019;2;2;0;2.299436;2.273397;1660835;1.913019e+008
997.5701;0.7201067;-1.495937;1729.501;178.7155;2;2;0;2.268053;2.242715;1587241;1.827689e+008
1000.57;0.7101424;-1.482667;1650.09;170.5096;2;2;0;2.236669;2.212022;1514361;1.743233e+008
1003.57;0.7001781;-1.469053;1571.146;162.3521;2;2;0;2.205286;2.181321;1441911;1.659324e+008
1006.57;0.6901602;-1.455194;1493.486;154.3272;2;2;0;2.173733;2.150444;1370639;1.576819e+008
1009.57;0.680196;-1.441566;1417.707;146.4967;2;2;0;2.142349;2.119724;1301093;1.496352e+008
1012.57;0.6701246;-1.427571;1342.825;138.7589;2;2;0;2.110629;2.088663;1232370;1.416875e+008
1015.57;0.6601067;-1.413267;1268.579;131.0868;2;2;0;2.079076;2.057758;1164232;1.338122e+008
1018.57;0.6500888;-1.398688;1196.121;123.5994;2;2;0;2.047524;2.026844;1097734;1.261301e+008
1021.57;0.640071;-1.383953;1125.623;116.3146;2;2;0;2.015972;1.99592;1033034;1.186594e+008
1024.57;0.6300532;-1.369268;1057.17;109.2411;2;2;0;1.984419;1.964987;970212.4;1.11409e+008
1027.57;0.6200354;-1.354351;990.1746;102.3182;2;2;0;1.952867;1.934043;908727.4;1.043164e+008
1030.57;0.6100175;-1.3394;925.0523;95.58893;2;2;0;1.921315;1.903091;848961.7;9.742549e+007
1033.57;0.5999996;-1.324767;862.0192;89.0755;2;2;0;1.889763;1.872128;791113.5;9.075881e+007
1036.57;0.5899818;-1.309907;800.5381;82.72243;2;2;0;1.85821;1.841156;734689.5;8.425959e+007
1039.57;0.5799639;-1.295026;740.3722;76.50528;2;2;0;1.826658;1.810175;679472.6;7.790277e+007
1042.57;0.5699996;-1.280335;681.6983;70.4423;2;2;0;1.795274;1.77935;625624.9;7.170693e+007
1045.57;0.5600354;-1.265467;624.0018;64.48032;2;2;0;1.763891;1.748515;572674.3;6.561768e+007
1048.57;0.5500175;-1.250222;567.4209;58.63361;2;2;0;1.732339;1.717505;520747.5;5.964935e+007
1051.57;0.5400533;-1.234942;512.3291;52.94078;2;2;0;1.700955;1.686651;470187.3;5.384128e+007
1054.57;0.5300889;-1.219643;458.6621;47.39518;2;2;0;1.669571;1.655787;420934.7;4.818647e+007
1057.57;0.5201246;-1.203786;407.0559;42.06253;2;2;0;1.638188;1.624914;373573.3;4.275159e+007
1060.57;0.5101604;-1.187883;357.4144;36.93289;2;2;0;1.606804;1.594032;328015.1;3.752633e+007
1063.57;0.5001425;-1.171428;309.8633;32.01928;2;2;0;1.575252;1.562974;284375.4;3.252366e+007
1066.57;0.4901247;-1.155538;264.4555;27.32712;2;2;0;1.5437;1.531906;242702.6;2.774897e+007
1069.57;0.4801068;-1.139615;221.3832;22.87631;2;2;0;1.512148;1.500829;203173.2;2.322223e+007
1072.57;0.470089;-1.123748;180.2192;18.62269;2;2;0;1.480595;1.469741;165395.2;1.889841e+007
1075.57;0.4600711;-1.10881;142.3611;14.71067;2;2;0;1.449043;1.438645;130651.1;1.492384e+007
1078.57;0.4500533;-1.09552;108.0492;11.16511;2;2;0;1.417491;1.407538;99161.6;1.132337e+007
1081.57;0.4400354;-1.083683;77.90739;8.050447;2;2;0;1.385938;1.376422;71499.09;8162020
1084.57;0.4300176;-1.074056;59.45452;6.143646;2;2;0;1.354386;1.345296;54564.06;6226854
1085.702;0.4329105;-1.073133;64.75038;6.690886;3;3;0;1.363497;1.354286;59424.31;6782116
1088.702;0.4429818;-1.075278;115.408;11.92552;3;3;0;1.395218;1.385575;105915;1.20919e+007
1091.702;0.4529997;-1.078567;179.8779;18.58742;3;3;0;1.426771;1.416688;165081.9;1.885262e+007
1094.702;0.4630176;-1.082474;250.6902;25.9047;3;3;0;1.458323;1.447792;230069.6;2.628248e+007
1097.702;0.4730354;-1.087498;325.3815;33.62282;3;3;0;1.489875;1.478886;298617.1;3.412376e+007
1100.702;0.4830533;-1.093419;404.3441;41.78231;3;3;0;1.521428;1.50997;371084.6;4.2418e+007
1103.702;0.4930711;-1.099893;487.0903;50.33277;3;3;0;1.55298;1.541044;447024.5;5.111443e+007
1106.702;0.5030889;-1.106918;574.2794;59.34232;3;3;0;1.584532;1.572109;527041.8;6.028262e+007
1109.702;0.5130532;-1.114343;664.6224;68.67779;3;3;0;1.615916;1.602999;609953.7;6.978757e+007
1112.702;0.5230175;-1.122245;757.2872;78.25317;3;3;0;1.647299;1.633878;694996.2;7.954223e+007
1115.702;0.5329818;-1.130901;853.4779;88.19289;3;3;0;1.678683;1.664749;783274.8;8.967337e+007
1118.702;0.542946;-1.140209;951.4974;98.3216;3;3;0;1.710066;1.695609;873231.6;1.00003e+008
1121.702;0.5529103;-1.149472;1051.458;108.6509;3;3;0;1.74145;1.72646;964970;1.10543e+008
1124.702;0.5628746;-1.158865;1151.397;118.9779;3;3;0;1.772833;1.757302;1056688;1.210872e+008
1127.702;0.5728925;-1.168381;1252.023;129.376;3;3;0;1.804386;1.7883;1149038;1.317104e+008
1130.702;0.5829103;-1.178095;1352.49;139.7576;3;3;0;1.835938;1.819288;1241240;1.423234e+008
1133.702;0.5929282;-1.188044;1452.764;150.1192;3;3;0;1.867491;1.850267;1333266;1.529227e+008
1136.702;0.6029461;-1.198067;1553.451;160.5236;3;3;0;1.899043;1.881236;1425672;1.63572e+008
1139.702;0.6129638;-1.208384;1654.526;170.968;3;3;0;1.930595;1.912195;1518432;1.742687e+008
1142.702;0.6230353;-1.218739;1756.241;181.4785;3;3;0;1.962316;1.943311;1611780;1.850397e+008
1145.702;0.6330532;-1.229336;1858.744;192.0706;3;3;0;1.993868;1.974251;1705852;1.959002e+008
1148.702;0.643071;-1.239978;1961.507;202.6894;3;3;0;2.025421;2.005182;1800162;2.067947e+008
1151.702;0.6530889;-1.250977;2065.277;213.4124;3;3;0;2.056973;2.036103;1895397;2.178022e+008
1154.702;0.6631067;-1.261862;2167.993;224.0264;3;3;0;2.088525;2.067014;1989664;2.287052e+008
1157.702;0.673071;-1.272811;2269.293;234.494;3;3;0;2.119909;2.097751;2082631;2.394651e+008
1160.702;0.6830353;-1.28373;2371.702;245.0763;3;3;0;2.151292;2.128478;2176617;2.503486e+008
1163.702;0.6930531;-1.294828;2472.407;255.4826;3;3;0;2.182844;2.159361;2269038;2.610593e+008
1166.702;0.7029638;-1.305969;2573.381;265.9165;3;3;0;2.214059;2.189905;2361706;2.718041e+008
1169.702;0.7129281;-1.317451;2675.334;276.4518;3;3;0;2.245443;2.220604;2455273;2.826593e+008
1172.702;0.7229459;-1.32892;2777.809;287.0408;3;3;0;2.276995;2.251458;2549319;2.935767e+008
1175.702;0.7329102;-1.340508;2879.891;297.5893;3;3;0;2.308378;2.282139;2643004;3.044588e+008
1178.702;0.7428745;-1.352097;2981.969;308.1374;3;3;0;2.339762;2.312809;2736686;3.153471e+008
1181.702;0.7528388;-1.363657;3083.888;318.6691;3;3;0;2.371146;2.343471;2830222;3.262252e+008
1184.702;0.7628567;-1.375417;3186.406;329.2626;3;3;0;2.402698;2.374288;2924307;3.371738e+008
1187.702;0.7728745;-1.387336;3289.619;339.928;3;3;0;2.43425;2.405095;3019031;3.482027e+008
1190.702;0.7828924;-1.399289;3393.113;350.6223;3;3;0;2.465803;2.435892;3114011;3.59268e+008
1193.702;0.7929638;-1.411321;3495.906;361.2444;3;3;0;2.497524;2.466846;3208349;3.702665e+008
1196.702;0.802928;-1.423481;3598.854;371.8823;3;3;0;2.528907;2.497459;3302829;3.812869e+008
1199.702;0.8129459;-1.435551;3700.837;382.4206;3;3;0;2.56046;2.528229;3396423;3.922123e+008
1202.702;0.8229638;-1.447704;3804.315;393.1133;3;3;0;2.592012;2.558989;3491389;4.033029e+008
1205.702;0.8329816;-1.459983;3907.245;403.7495;3;3;0;2.623564;2.589739;3585853;4.143421e+008
1208.702;0.8429459;-1.472263;4009.226;414.2875;3;3;0;2.654948;2.620316;3679446;4.252866e+008
1211.702;0.8529637;-1.484688;4112.001;424.9076;3;3;0;2.6865;2.651047;3773767;4.363227e+008
1214.702;0.862928;-1.497299;4214.807;435.5309;3;3;0;2.717883;2.681605;3868117;4.473682e+008
1217.702;0.8728923;-1.509916;4318.005;446.1947;3;3;0;2.749267;2.712153;3962826;4.584618e+008
1220.702;0.8829101;-1.522631;4421.133;456.8513;3;3;0;2.780819;2.742857;4057471;4.695555e+008
1223.702;0.892928;-1.535386;4523.996;467.4805;3;3;0;2.812372;2.773551;4151873;4.806278e+008
1226.702;0.9029458;-1.548181;4627.759;478.2027;3;3;0;2.843924;2.804235;4247101;4.918025e+008
1229.702;0.9129101;-1.561122;4730.97;488.8679;3;3;0;2.875307;2.834746;4341822;5.029243e+008
1232.702;0.9229816;-1.574121;4835.097;499.6277;3;3;0;2.907028;2.865576;4437384;5.14152e+008
1235.702;0.9329458;-1.587231;4938.418;510.3042;3;3;0;2.938412;2.896068;4532206;5.25299e+008
1238.702;0.9430173;-1.600343;5042.888;521.0994;3;3;0;2.970133;2.926879;4628083;5.365768e+008
1241.702;0.9530351;-1.613598;5146.872;531.8445;3;3;0;3.001685;2.957517;4723514;5.478088e+008
1244.702;0.963053;-1.626921;5250.975;542.6018;3;3;0;3.033238;2.988145;4819054;5.590602e+008
1247.702;0.9730709;-1.640179;5354.09;553.2571;3;3;0;3.06479;3.018763;4913688;5.702133e+008
1250.702;0.9830886;-1.653373;5457.293;563.9214;3;3;0;3.096342;3.049373;5008401;5.813824e+008
1253.702;0.9930529;-1.666957;5561.45;574.6843;3;3;0;3.127726;3.079809;5103990;5.926588e+008
1256.702;1.003071;-1.680515;5665.501;585.4363;3;3;0;3.159278;3.110399;5199483;6.039319e+008
1259.702;1.013035;-1.694159;5768.998;596.1309;3;3;0;3.190662;3.140817;5294467;6.151515e+008
1262.702;1.022999;-1.707651;5870.55;606.6248;3;3;0;3.222045;3.171226;5387666;6.261705e+008
1265.702;1.032964;-1.721217;5972.301;617.139;3;3;0;3.253429;3.201625;5481047;6.372172e+008
1268.702;1.042981;-1.734949;6073.415;627.5875;3;3;0;3.284981;3.232178;5573844;6.482036e+008
1271.702;1.052892;-1.748691;6173.486;637.9282;3;3;0;3.316196;3.262396;5665684;6.590831e+008
1274.702;1.062856;-1.762327;6272.915;648.2025;3;3;0;3.347579;3.292768;5756934;6.699016e+008
1277.702;1.072874;-1.77612;6372.864;658.5306;3;3;0;3.379132;3.323293;5848662;6.807832e+008
1280.702;1.082892;-1.790109;6472.116;668.7866;3;3;0;3.410684;3.35381;5939750;6.915968e+008
1283.702;1.09291;-1.804091;6572.414;679.1508;3;3;0;3.442236;3.384317;6031798;7.025288e+008
1286.702;1.102981;-1.818245;6672.644;689.5079;3;3;0;3.473957;3.414978;6123783;7.134611e+008
1289.702;1.112999;-1.832407;6770.881;699.6591;3;3;0;3.50551;3.445466;6213940;7.241857e+008
1292.702;1.123017;-1.846559;6868.57;709.7537;3;3;0;3.537062;3.475945;6303594;7.348581e+008
1295.702;1.133035;-1.860947;6966.797;719.9038;3;3;0;3.568614;3.506414;6393740;7.455944e+008
1298.702;1.143106;-1.875535;7063.781;729.9255;3;3;0;3.600335;3.537038;6482747;7.562052e+008
1301.702;1.153071;-1.890033;7159.192;739.7846;3;3;0;3.631719;3.567326;6570310;7.666515e+008
1304.702;1.163089;-1.904853;7254.126;749.5945;3;3;0;3.663271;3.597768;6657435;7.770542e+008
1307.702;1.173106;-1.920038;7348.778;759.3753;3;3;0;3.694823;3.628201;6744302;7.874329e+008
1310.702;1.183071;-1.935711;7440.543;768.8576;3;3;0;3.726207;3.658462;6828518;7.975068e+008
1313.702;1.193035;-1.951839;7530.054;778.1072;3;3;0;3.75759;3.688713;6910667;8.073452e+008
1316.702;1.202999;-1.9685;7615.857;786.9734;3;3;0;3.788974;3.718956;6989412;8.167917e+008
1319.702;1.212963;-1.986337;7698.368;795.4996;3;3;0;3.820357;3.749189;7065136;8.258906e+008
1322.702;1.222928;-2.005903;7775.073;803.4258;3;3;0;3.851741;3.779413;7135531;8.343717e+008
1324.158;1.221374;-2.009002;7713.988;797.1136;3;3;0;3.846848;3.774701;7079471;8.277774e+008
1327.158;1.211249;-2.001074;7502.501;775.2599;3;3;0;3.814958;3.743988;6885380;8.048358e+008
1329.75;1.200535;-1.992138;7297.906;754.1185;3;3;0;3.781213;3.711477;6697614;7.826333e+008
1331.238;1.188053;-1.981373;7072.24;730.7996;3;3;0;3.741899;3.673589;6490511;7.581454e+008
1332.804;1.174821;-1.969864;6846.904;707.5148;3;3;0;3.700223;3.633408;6283709;7.336945e+008
1334.466;1.160999;-1.957644;6621.29;684.2013;3;3;0;3.656691;3.59142;6076653;7.092204e+008
1336.22;1.146588;-1.94476;6395.792;660.8998;3;3;0;3.611302;3.547623;5869704;6.847669e+008
1337.994;1.131696;-1.931589;6170.388;637.608;3;3;0;3.564396;3.502342;5662840;6.603349e+008
1339.83;1.116481;-1.917577;5945.064;614.3245;3;3;0;3.516477;3.456061;5456050;6.35927e+008
1341.7;1.100785;-1.903102;5719.597;591.0262;3;3;0;3.467039;3.408292;5249130;6.115174e+008
1343.636;1.084767;-1.888085;5494.167;567.7318;3;3;0;3.41659;3.35952;5042242;5.871288e+008
1345.592;1.068374;-1.872671;5268.756;544.4391;3;3;0;3.364958;3.309582;4835372;5.627593e+008
1347.622;1.051499;-1.856424;5043.54;521.1668;3;3;0;3.311809;3.25815;4628681;5.384268e+008
1349.718;1.034089;-1.83988;4818.015;497.8625;3;3;0;3.256972;3.205057;4421707;5.140777e+008
1351.854;1.016303;-1.822648;4592.682;474.5781;3;3;0;3.200954;3.150791;4214909;4.897691e+008
1354.006;0.9981422;-1.80498;4367.623;451.3219;3;3;0;3.143755;3.095351;4008362;4.655104e+008
1356.28;0.9793387;-1.786525;4142.18;428.0261;3;3;0;3.084531;3.037916;3801463;4.412287e+008
1358.6;0.9599458;-1.767506;3916.993;404.7567;3;3;0;3.023451;2.978646;3594799;4.169944e+008
1360.994;0.9399101;-1.747901;3691.618;381.4679;3;3;0;2.960347;2.917375;3387962;3.927607e+008
1363.476;0.9192852;-1.727404;3466.428;358.1983;3;3;0;2.895386;2.854262;3181296;3.685695e+008
1366.058;0.8978566;-1.706126;3241.182;334.9229;3;3;0;2.827895;2.788648;2974578;3.443941e+008
1368.666;0.8759994;-1.683974;3015.988;311.6527;3;3;0;2.759053;2.721677;2767906;3.202513e+008
1371.4;0.8533923;-1.660638;2790.786;288.3818;3;3;0;2.68785;2.652362;2561229;2.96133e+008
1374.212;0.829928;-1.636381;2565.437;265.0957;3;3;0;2.613946;2.580367;2354416;2.720252e+008
1377.138;0.805553;-1.610662;2341.916;241.9985;3;3;0;2.537175;2.505523;2149281;2.481384e+008
1380.114;0.7807495;-1.583277;2121.93;219.2665;3;3;0;2.459054;2.429306;1947390;2.246584e+008
1383.114;0.755678;-1.553993;1906.488;197.0042;3;3;0;2.380088;2.352206;1749669;2.016931e+008
1386.114;0.730821;-1.523597;1699.642;175.63;3;3;0;2.301798;2.275707;1559837;1.796726e+008
1389.114;0.7055888;-1.491438;1494.15;154.3958;3;3;0;2.222327;2.197993;1371248;1.578269e+008
1392.114;0.6807317;-1.458387;1301.063;134.4435;3;3;0;2.144037;2.121376;1194044;1.37326e+008
1395.114;0.6557138;-1.424614;1115.227;115.2403;3;3;0;2.06524;2.044203;1023493;1.176203e+008
1398.114;0.6305888;-1.389811;938.819;97.01149;3;3;0;1.986107;1.966641;861596.1;9.893824e+007
1401.114;0.6057854;-1.355197;775.927;80.17928;3;3;0;1.907985;1.890012;712102.8;8.170909e+007
1404.114;0.5806604;-1.320922;622.7062;64.34644;3;3;0;1.828852;1.812329;571485.3;6.552324e+007
1407.114;0.5557496;-1.285747;477.471;49.33877;3;3;0;1.750393;1.73525;438196.5;5.020239e+007
1410.114;0.5307318;-1.248815;342.0177;35.3419;3;3;0;1.671596;1.657779;313884.9;3.593267e+007
1413.114;0.5057675;-1.212442;221.6184;22.90062;3;3;0;1.592969;1.580414;203389.1;2.326542e+007
1416.114;0.480589;-1.178079;117.4759;12.1392;3;3;0;1.513666;1.502324;107812.9;1.232295e+007
1419.114;0.4557319;-1.155264;58.09091;6.002739;3;3;0;1.435376;1.425172;53312.62;6088902
1421.932;0.4323211;-1.151772;57.9914;5.992456;3;3;0;1.361641;1.352454;53221.29;6074052