File: Ensayos/Resistencia/comp/Extensometro/Extensometro.raw
"Test Type";"Manual"
"Method Name:";"C:\INSTRON\user\template\CYCLE.MTM"
"Name:";""
"Operator ID:";""
"Company:";""
"Lab name:";""
"Test date:";"12/05/2017"
"Temperature:";""
"Humidity:";""
"Note 1:";""
"Note 2:";""
"Note 3:";""
"Geometry:";"Rectangular"
"Specimen";1
"Specimen name:";""
"Width:";0.250000;"in"
"Thickness:";0.060000;"in"
"Length:";1.250000;"in"
"Diameter:";0.039370;"in"
"Inner diameter:";0.019685;"in"
"Outer diameter:";0.039370;"in"
"Wall thickness:";0.019685;"in"
"Area:";0.015000;"in*in"
"Linear density:";1.000000;"den"
"Sled weight:";2.204623;"lbf"
"Loading span:";0.000000;"mm"
"Support span:";1.000000;"mm"
"Span ratio:";"2"
"Fixture type:";"3-point"
"Comment:";""
"Included"
"Final Width:";0.250000;"in"
"Final Thickness:";0.060000;"in"
"Final Length:";1.250000;"in"
"Final Diameter:";0.039370;"in"
"Final Inner diameter:";0.019685;"in"
"Final Outer diameter:";0.039370;"in"
"Final Wall thickness:";0.019685;"in"
"Final Area:";0.015000;"in*in"
"Final Linear density:";1.000000;"den"
"Time sec";"Extension mm";"Strain 1 %";"Load N";"Stress MPa";"Cycle Count ";"Total Cycle Count ";"Repetitions Count ";"Strain [Exten.] %";"True strain %";"Tenacity gf/tex";"True stress Pa"
0;2.401981;-5.703921e-005;70.58063;7.293346;0;0;0;7.565293;7.292786;64774.99;7845109
2;2.402302;0.0001261541;70.87039;7.323288;0;0;0;7.566306;7.293727;65040.91;7877391
4;2.402677;5.520516e-005;70.94709;7.331214;0;0;0;7.567487;7.294825;65111.31;7886003
6;2.403052;0.0001103964;70.78986;7.314967;0;0;0;7.568668;7.295923;64967.01;7868612
8;2.403373;5.095215e-005;70.85579;7.32178;0;0;0;7.56968;7.296864;65027.52;7876015
10;2.403695;0.0001027331;70.73659;7.309463;0;0;0;7.570693;7.297805;64918.13;7862839
12;2.404016;0.0001308383;70.62277;7.2977;0;0;0;7.571705;7.298746;64813.66;7850261
14;2.404338;-2.963956e-005;70.84452;7.320615;0;0;0;7.572717;7.299687;65017.17;7874984
16;2.404659;0.0001688019;70.90366;7.326726;0;0;0;7.573729;7.300628;65071.45;7881632
18;2.404981;0.0001358164;70.94568;7.331068;0;0;0;7.574742;7.30157;65110.01;7886378
20;2.405302;0.0001370904;70.87913;7.324192;0;0;0;7.575754;7.30251;65048.94;7879055
22;2.405677;0.0001949863;70.73501;7.309299;0;0;0;7.576936;7.303609;64916.67;7863119
24;2.405999;0.0001233318;70.68505;7.304136;0;0;0;7.577948;7.30455;64870.82;7857640
26;2.406373;8.568182e-005;70.89385;7.325713;0;0;0;7.579129;7.305647;65062.45;7880938
28;2.406695;0.0001415198;70.87376;7.323637;0;0;0;7.580142;7.306589;65044.01;7878779
30;2.407016;-2.246627e-005;70.85652;7.321856;0;0;0;7.581154;7.307529;65028.19;7876936
32;2.407338;6.59455e-005;70.72291;7.308049;0;0;0;7.582166;7.308471;64905.57;7862157
34;2.407766;0.0001095928;70.78205;7.31416;0;0;0;7.583516;7.309725;64959.84;7868830
36;2.407981;0.0001896358;70.62573;7.298007;0;0;0;7.584191;7.310353;64816.39;7851502
38;2.408302;4.583679e-005;70.66529;7.302094;0;0;0;7.585203;7.311293;64852.69;7855973
40;2.408624;0.0001655484;70.60903;7.296281;0;0;0;7.586216;7.312235;64801.05;7849792
42;2.408998;0.0001647056;70.79163;7.315149;0;0;0;7.587397;7.313332;64968.63;7870179
44;2.40932;0.0001404027;70.77242;7.313164;0;0;0;7.588409;7.314273;64951;7868117
46;2.409695;0.0001168249;70.91858;7.328268;0;0;0;7.589591;7.315372;65085.14;7884453
48;2.410016;0.000113689;70.64896;7.300407;0;0;0;7.590602;7.316312;64837.7;7854552
50;2.410338;0.0001231946;70.77873;7.313817;0;0;0;7.591615;7.317253;64956.8;7869054
52;2.410713;0.0001800909;70.76111;7.311996;0;0;0;7.592796;7.31835;64940.63;7867181
54;2.410981;0.0001118075;70.66996;7.302577;0;0;0;7.59364;7.319135;64856.97;7857108
56;2.411302;5.94974e-005;70.70661;7.306364;0;0;0;7.594652;7.320076;64890.61;7861257
58;2.411731;0.0001995529;70.70631;7.306334;0;0;0;7.596002;7.321331;64890.34;7861323
60;2.412052;0.0001100044;70.75066;7.310916;0;0;0;7.597014;7.322271;64931.04;7866327
62;2.412373;6.294686e-005;70.78378;7.314339;0;0;0;7.598027;7.323212;64961.43;7870084
64;2.412695;0.0001997685;70.75412;7.311274;0;0;0;7.59904;7.324153;64934.21;7866861
66;2.413016;9.510906e-005;70.94351;7.330843;0;0;0;7.600051;7.325094;65108.02;7887992
68;2.413338;0.0001825605;70.75248;7.311104;0;0;0;7.601064;7.326035;64932.7;7866825
70;2.413659;0.000132073;70.73462;7.309259;0;0;0;7.602076;7.326975;64916.32;7864914
72;2.413981;0.000271717;70.8764;7.32391;0;0;0;7.603089;7.327917;65046.43;7880753
74;2.414302;0.0001016943;70.75125;7.310977;0;0;0;7.604101;7.328857;64931.57;7866911
76;2.414677;0.0002035511;70.78863;7.31484;0;0;0;7.605282;7.329955;64965.88;7871154
78;2.414998;8.993484e-005;70.70247;7.305937;0;0;0;7.606294;7.330896;64886.81;7861648
80;2.41532;0.0002441998;70.61334;7.296727;0;0;0;7.607307;7.331837;64805.02;7851811
82.00001;2.415641;0.0001519466;70.85972;7.322186;0;0;0;7.608319;7.332777;65031.13;7879281
84.00001;2.416016;0.0001379332;70.72452;7.308215;0;0;0;7.6095;7.333875;64907.05;7864334
86.00001;2.416338;0.0001429505;70.84167;7.32032;0;0;0;7.610512;7.334816;65014.55;7877434
88.00001;2.416659;0.0002227191;70.63193;7.298647;0;0;0;7.611525;7.335756;64822.07;7854186
90.00001;2.417034;0.000229716;70.7104;7.306756;0;0;0;7.612706;7.336854;64894.09;7862998
92.00001;2.417409;0.000188107;70.74249;7.310072;0;0;0;7.613887;7.337951;64923.54;7866653
94.00001;2.417731;-7.629715e-006;70.81597;7.317665;0;0;0;7.6149;7.338893;64990.97;7874898
96.00001;2.418052;0.0001926344;70.60938;7.296317;0;0;0;7.615912;7.339833;64801.37;7851998
98.00001;2.418373;0.0001272908;70.8226;7.31835;0;0;0;7.616924;7.340774;64997.06;7875784
100;2.418641;9.077761e-005;70.95599;7.332133;0;0;0;7.617768;7.341558;65119.48;7890678
102;2.418963;0.0001061238;70.88471;7.324769;0;0;0;7.618781;7.342499;65054.06;7882827
104;2.419338;-6.19897e-006;71.06705;7.34361;0;0;0;7.619961;7.343596;65221.4;7903190
106;2.419659;0.0003535434;70.92865;7.329309;0;0;0;7.620974;7.344537;65094.38;7887873
108;2.41998;0.000100048;70.75442;7.311305;0;0;0;7.621985;7.345477;64934.48;7868571
110;2.420356;1.890752e-005;70.96221;7.332777;0;0;0;7.623167;7.346575;65125.19;7891766
112;2.420731;0.0001277808;70.85133;7.321318;0;0;0;7.624349;7.347673;65023.42;7879521
114;2.421052;0.0001405986;70.76619;7.312521;0;0;0;7.625361;7.348613;64945.29;7870128
116;2.421374;0.0001388347;70.70526;7.306225;0;0;0;7.626373;7.349554;64889.37;7863425
118;2.421695;0.000101126;70.69792;7.305466;0;0;0;7.627385;7.350494;64882.63;7862682
120;2.422016;0.0001464;70.97886;7.334497;0;0;0;7.628398;7.351435;65140.47;7894002
122;2.422338;9.352152e-005;70.71974;7.307721;0;0;0;7.62941;7.352375;64902.66;7865257
124;2.422659;7.413793e-005;70.75653;7.311523;0;0;0;7.630423;7.353316;64936.43;7869423
126;2.42298;7.074726e-005;70.73022;7.308804;0;0;0;7.631434;7.354256;64912.28;7866571
128;2.423302;6.035974e-005;70.71377;7.307105;0;0;0;7.632447;7.355197;64897.18;7864815
130;2.423731;0.0002540777;70.65402;7.30093;0;0;0;7.633798;7.356452;64842.34;7858268
132;2.424052;0.0001090636;70.83611;7.319746;0;0;0;7.634809;7.357392;65009.46;7878595
134;2.424374;1.247899e-005;70.95528;7.33206;0;0;0;7.635822;7.358333;65118.83;7891924
136;2.424695;7.282477e-005;70.6008;7.29543;0;0;0;7.636834;7.359273;64793.5;7852570
138;2.425016;0.000113591;70.8523;7.321419;0;0;0;7.637847;7.360214;65024.31;7880617
140;2.425338;-0.0003976136;70.92298;7.328722;0;0;0;7.638859;7.361154;65089.18;7888553
142;2.425659;-0.0001781815;70.62749;7.298189;0;0;0;7.639872;7.362095;64818;7855761
144;2.42598;-5.323694e-005;70.66476;7.30204;0;0;0;7.640883;7.363035;64852.2;7859980
146;2.426302;-0.0007350718;67.65079;6.990596;0;0;0;7.641896;7.363976;62086.15;7524810
148;2.426677;-0.001934951;71.13447;7.350577;0;0;0;7.643077;7.365073;65283.28;7912387
150;2.427052;0.0005175687;66.09291;6.829614;0;0;0;7.644258;7.36617;60656.41;7351687
152;2.427373;-0.0006784107;71.60128;7.398814;0;0;0;7.64527;7.36711;65711.69;7964473
154;2.427695;-5.999864e-005;76.01838;7.855248;0;0;0;7.646283;7.368051;69765.45;8455883
156;2.428016;0.001166928;70.32314;7.266739;0;0;0;7.647296;7.368992;64538.68;7822448
158;2.428391;4.44844e-005;70.82736;7.318842;0;0;0;7.648477;7.370089;65001.43;7878622
160;2.428659;9.581461e-005;70.68109;7.303727;0;0;0;7.64932;7.370872;64867.19;7862413
162;2.428981;-0.0003311725;70.89722;7.326061;0;0;0;7.650332;7.371812;65065.54;7886529
164;2.429302;5.8929e-005;70.74117;7.309936;0;0;0;7.651345;7.372753;64922.33;7869244
166;2.429623;0.0001256445;70.85682;7.321886;0;0;0;7.652357;7.373693;65028.46;7882183
168;2.429999;7.946888e-005;70.70285;7.305975;0;0;0;7.653539;7.374791;64887.16;7865141
170;2.430373;-0.0004845751;70.87799;7.324073;0;0;0;7.654719;7.375888;65047.89;7884711
172;2.430695;-0.0002121468;70.90753;7.327127;0;0;0;7.655732;7.376828;65075.01;7888072
174;2.431016;-5.01403e-005;70.78461;7.314424;0;0;0;7.656744;7.377768;64962.19;7874471
176;2.431338;-7.591319e-005;70.60947;7.296326;0;0;0;7.657757;7.378709;64801.46;7855061
178;2.431659;0.0001393051;70.82892;7.319003;0;0;0;7.658769;7.379649;65002.86;7879548
180;2.432034;-0.000273845;70.85168;7.321354;0;0;0;7.65995;7.380746;65023.74;7882167
182;2.432302;-0.0003408937;70.83474;7.319604;0;0;0;7.660794;7.38153;65008.2;7880344
184;2.432731;8.354553e-005;70.88915;7.325227;0;0;0;7.662143;7.382784;65058.13;7886496
186;2.432999;-0.0001415899;70.79312;7.315304;0;0;0;7.662988;7.383568;64970;7875875
188;2.43332;0.0003622651;70.89315;7.32564;0;0;0;7.664;7.384508;65061.8;7887077
190;2.433695;0.0004465806;70.85235;7.321424;0;0;0;7.665181;7.385605;65024.36;7882625
192;2.434016;0.0009002617;70.59076;7.294393;0;0;0;7.666193;7.386545;64784.29;7853596
194;2.434338;0.001054977;70.91461;7.327857;0;0;0;7.667206;7.387485;65081.5;7889700
196;2.434659;0.001125084;70.68958;7.304604;0;0;0;7.668218;7.388425;64874.98;7864737
198;2.434981;0.001492019;70.82428;7.318524;0;0;0;7.66923;7.389366;64998.6;7879798
200;2.435302;0.001823205;70.72989;7.30877;0;0;0;7.670242;7.390306;64911.98;7869371
202;2.435677;0.001846587;70.91282;7.327673;0;0;0;7.671423;7.391403;65079.86;7889810
204;2.435999;0.001651674;72.78314;7.520939;0;0;0;7.672437;7.392344;66796.33;8097979
206;2.43632;0.00150468;72.02117;7.442202;0;0;0;7.673449;7.393284;66097.04;8013276
208;2.436641;0.001908364;68.76654;7.10589;0;0;0;7.674461;7.394224;63110.13;7651229
210;2.437016;0.001747984;71.15744;7.35295;0;0;0;7.675642;7.39532;65304.36;7917336
212;2.437391;0.001125554;72.63281;7.505405;0;0;0;7.676823;7.396418;66658.37;8081582
214;2.437713;0.001815189;70.6975;7.305423;0;0;0;7.677835;7.397357;64882.25;7866322
216;2.438034;0.001777931;70.73506;7.309304;0;0;0;7.678848;7.398298;64916.72;7870575
218;2.438355;0.001900857;70.68887;7.304531;0;0;0;7.67986;7.399238;64874.33;7865509
220;2.438677;0.001840923;70.9929;7.335948;0;0;0;7.680872;7.400178;65153.35;7899413
222;2.438945;0.002894573;78.60227;8.122252;0;0;0;7.681716;7.400961;72136.81;8746180
224;2.43932;0.003638753;74.77891;7.72717;0;0;0;7.682898;7.402059;68627.95;8320840
226;2.439641;0.002254759;76.99029;7.955679;0;0;0;7.683909;7.402999;70657.42;8566986
228;2.440016;0.002996352;75.16634;7.767204;0;0;0;7.685091;7.404095;68983.51;8364121
230;2.440338;0.003036491;66.52389;6.874149;0;0;0;7.686103;7.405036;61051.94;7402503
232;2.440659;0.001935097;70.76352;7.312245;0;0;0;7.687116;7.405976;64942.84;7874346
234;2.440981;0.001737008;70.86252;7.322474;0;0;0;7.688128;7.406916;65033.69;7885436
236;2.441355;0.001956832;70.90765;7.327139;0;0;0;7.689309;7.408012;65075.11;7890545
238;2.44173;0.00182787;70.75956;7.311836;0;0;0;7.69049;7.409109;64939.2;7874152
240;2.442052;0.001829771;70.85494;7.321692;0;0;0;7.691502;7.410049;65026.73;7884840
242;2.44232;0.002025586;70.81001;7.317049;0;0;0;7.692346;7.410833;64985.5;7879902
244;2.442695;0.001987505;70.74096;7.309914;0;0;0;7.693527;7.411929;64922.14;7872305
246;2.443016;0.002040207;70.62993;7.298441;0;0;0;7.69454;7.41287;64820.24;7860022
248;2.443338;0.00196234;70.70814;7.306522;0;0;0;7.695552;7.41381;64892.01;7868799
250;2.443659;0.001944661;70.85274;7.321464;0;0;0;7.696564;7.41475;65024.71;7884965
252;2.44398;0.001948679;70.86598;7.322833;0;0;0;7.697577;7.415689;65036.87;7886513
254;2.444302;0.002039894;70.7335;7.309144;0;0;0;7.698588;7.416629;64915.29;7871844
256;2.44473;0.001860483;70.60961;7.296341;0;0;0;7.699939;7.417883;64801.59;7858155
258;2.445052;0.001993385;70.94824;7.331332;0;0;0;7.700951;7.418822;65112.36;7895915
260;2.445373;0.002141888;70.85353;7.321546;0;0;0;7.701963;7.419763;65025.44;7885449
262;2.445641;0.002186319;70.81389;7.31745;0;0;0;7.702807;7.420546;64989.06;7881099
264;2.445963;0.002350148;70.6847;7.304101;0;0;0;7.70382;7.421486;64870.5;7866795
266;2.446338;0.002417491;70.72631;7.3084;0;0;0;7.705;7.422583;64908.69;7871512
268;2.446659;0.002443283;70.90354;7.326714;0;0;0;7.706013;7.423523;65071.34;7891311
270;2.446981;0.002748324;70.778;7.313741;0;0;0;7.707025;7.424463;64956.13;7877413
272;2.447355;0.002713399;71.02629;7.339398;0;0;0;7.708206;7.425559;65184;7905134
274;2.447731;0.002785543;70.72969;7.308749;0;0;0;7.709387;7.426656;64911.79;7872209
276;2.448052;0.002703971;70.7306;7.308843;0;0;0;7.7104;7.427595;64912.63;7872384
278;2.448373;0.002486225;70.79095;7.315079;0;0;0;7.711412;7.428536;64968.01;7879175
280;2.448695;0.002619362;70.96926;7.333505;0;0;0;7.712424;7.429475;65131.66;7899096
282;2.449016;0.002582241;70.82084;7.318169;0;0;0;7.713437;7.430416;64995.45;7882651
284;2.449338;0.002601723;70.69343;7.305002;0;0;0;7.714449;7.431355;64878.51;7868543
286;2.449659;0.002734762;70.74329;7.310154;0;0;0;7.715462;7.432295;64924.27;7874167
288;2.449981;0.002347522;70.68641;7.304276;0;0;0;7.716474;7.433235;64872.07;7867909
290;2.450355;0.002422959;70.65789;7.30133;0;0;0;7.717655;7.434331;64845.9;7864822
292;2.450731;0.002769825;70.81758;7.317832;0;0;0;7.718836;7.435428;64992.45;7882683
294;2.451052;0.002730881;70.78898;7.314876;0;0;0;7.719848;7.436367;64966.2;7879573
296;2.451373;0.002771824;70.68309;7.303934;0;0;0;7.720861;7.437308;64869.02;7867860
298;2.451695;0.002637825;70.9226;7.328683;0;0;0;7.721873;7.438247;65088.83;7894595
300;2.452016;0.002601115;70.8989;7.326234;0;0;0;7.722886;7.439187;65067.08;7892031
302;2.452338;0.002523326;70.91629;7.328031;0;0;0;7.723898;7.440127;65083.04;7894041
304;2.452659;0.002588572;70.60574;7.295941;0;0;0;7.724911;7.441067;64798.03;7859546
306;2.452981;0.002637589;70.8219;7.318277;0;0;0;7.725923;7.442007;64996.41;7883682
308;2.453302;0.002450417;70.8192;7.317999;0;0;0;7.726935;7.442946;64993.94;7883456
310;2.453677;0.002704285;70.91253;7.327642;0;0;0;7.728116;7.444042;65079.59;7893931
312;2.454052;0.002549432;70.71701;7.307439;0;0;0;7.729297;7.445139;64900.15;7872252
314;2.454373;0.002399793;70.85993;7.322207;0;0;0;7.73031;7.446079;65031.32;7888237
316;2.454695;0.00267273;70.70719;7.306425;0;0;0;7.731322;7.447018;64891.14;7871308
318;2.455016;0.002604623;70.68576;7.304209;0;0;0;7.732335;7.447959;64871.47;7868995
320;2.455338;0.002618696;70.93056;7.329505;0;0;0;7.733347;7.448898;65096.13;7896322
322;2.455659;0.002545826;70.7133;7.307056;0;0;0;7.73436;7.449838;64896.75;7872210
324;2.455981;0.002677513;70.96427;7.33299;0;0;0;7.735372;7.450777;65127.08;7900224
326;2.456302;0.002548354;70.80972;7.317019;0;0;0;7.736384;7.451717;64985.23;7883091
328;2.456677;0.002409573;70.72743;7.308516;0;0;0;7.737565;7.452813;64909.71;7874017
330;2.456998;0.002430015;70.64159;7.299645;0;0;0;7.738577;7.453753;64830.94;7864534
332;2.457373;0.002361751;70.87382;7.323643;0;0;0;7.739758;7.454849;65044.06;7890475
334;2.457748;0.002583848;70.74734;7.310573;0;0;0;7.74094;7.455945;64927.99;7876480
336;2.458016;0.002480463;70.87949;7.324229;0;0;0;7.741783;7.456728;65049.27;7891254
338;2.458391;0.002398205;70.70529;7.306228;0;0;0;7.742965;7.457825;64889.39;7871946
340;2.458713;0.002358831;70.9149;7.327888;0;0;0;7.743978;7.458765;65081.77;7895358
342;2.459034;0.002732645;70.68784;7.304425;0;0;0;7.744989;7.459704;64873.39;7870152
344;2.459302;0.002177048;70.80592;7.316627;0;0;0;7.745833;7.460487;64981.75;7883361
346;2.459623;0.002245391;70.80763;7.316803;0;0;0;7.746845;7.461426;64983.32;7883624
348;2.459998;0.002388327;70.85582;7.321783;0;0;0;7.748026;7.462523;65027.54;7889076
350;2.46032;0.00242;70.77321;7.313247;0;0;0;7.749038;7.463462;64951.73;7879953
352;2.460695;0.002451593;70.95596;7.33213;0;0;0;7.75022;7.464558;65119.45;7900387
354;2.461016;0.002260835;70.65205;7.300726;0;0;0;7.751232;7.465498;64840.54;7866622
356;2.461338;0.002038737;70.8108;7.317131;0;0;0;7.752245;7.466438;64986.23;7884373
358;2.461659;0.002035229;70.90824;7.327199;0;0;0;7.753257;7.467377;65075.65;7895296
360;2.462034;0.000506848;60.75618;6.278151;0;0;0;7.754438;7.468473;55758.65;6764986
362;2.462355;-0.001192751;47.81551;4.940946;0;0;0;7.75545;7.469412;43882.43;5324138
364;2.46273;0.002250545;72.64782;7.506957;0;0;0;7.756631;7.470508;66672.14;8089243
366;2.463052;0.002113704;77.52479;8.010911;0;0;0;7.757644;7.471448;71147.95;8632369
368;2.463373;0.001861051;77.44274;8.002432;0;0;0;7.758656;7.472387;71072.66;8623313
370;2.463695;0.003189756;70.95975;7.332522;0;0;0;7.759669;7.473327;65122.92;7901501
372;2.464016;0.002208995;74.72144;7.721231;0;0;0;7.760681;7.474266;68575.2;8320451
374;2.464338;0.002040795;82.42931;8.517712;0;0;0;7.761693;7.475206;75649.05;9178831
376;2.464659;0.003384434;70.6005;7.2954;0;0;0;7.762706;7.476145;64793.23;7861721
378;2.464981;0.001337323;70.94803;7.331311;0;0;0;7.763719;7.477085;65112.17;7900494
380;2.465409;0.001283562;70.78302;7.31426;0;0;0;7.765068;7.478337;64960.73;7882217
382;2.465677;0.001346084;70.7691;7.312821;0;0;0;7.765911;7.47912;64947.96;7880729
384;2.465998;0.001179942;70.77219;7.313141;0;0;0;7.766924;7.48006;64950.79;7881147
386;2.46632;0.001119713;70.97478;7.334076;0;0;0;7.767936;7.480999;65136.73;7903782
388;2.466641;0.00125338;70.72091;7.307842;0;0;0;7.768949;7.481939;64903.73;7875585
390;2.467016;0.001265747;70.77192;7.313113;0;0;0;7.77013;7.483034;64950.55;7881352
392;2.467338;0.001118185;70.93358;7.329818;0;0;0;7.771142;7.483974;65098.91;7899429
394;2.467713;0.001120948;70.79712;7.315717;0;0;0;7.772323;7.48507;64973.67;7884318
396;2.468034;0.001284033;70.68743;7.304383;0;0;0;7.773336;7.48601;64873.01;7872177
398;2.468409;0.001072107;70.74276;7.3101;0;0;0;7.774517;7.487105;64923.79;7878425
400;2.468677;0.001282034;70.8594;7.322153;0;0;0;7.77536;7.487888;65030.83;7891476
402;2.469052;0.001468794;70.6953;7.305196;0;0;0;7.776541;7.488983;64880.23;7873288
404;2.469373;0.001259906;71.04873;7.341716;0;0;0;7.777554;7.489923;65204.59;7912722
406;2.469695;0.0009136676;70.96262;7.332819;0;0;0;7.778566;7.490863;65125.57;7903207
408;2.469963;0.0009804419;70.75315;7.311174;0;0;0;7.77941;7.491645;64933.32;7879940
410;2.470338;0.001012271;70.82161;7.318247;0;0;0;7.780591;7.492741;64996.14;7887650
412;2.470659;0.00089497;70.89159;7.325479;0;0;0;7.781603;7.49368;65060.37;7895518
414;2.471034;0.0007283968;70.86381;7.322608;0;0;0;7.782785;7.494777;65034.88;7892511
416;2.471409;0.0006624652;70.7042;7.306116;0;0;0;7.783966;7.495872;64888.4;7874821
418;2.471677;0.0009790307;70.94859;7.331369;0;0;0;7.784809;7.496654;65112.69;7902102
420;2.472052;0.0005622352;70.76334;7.312227;0;0;0;7.78599;7.49775;64942.68;7881556
422;2.472373;0.0007131878;70.90334;7.326693;0;0;0;7.787003;7.49869;65071.15;7897222
424;2.472695;0.0007185384;70.84058;7.320208;0;0;0;7.788014;7.499628;65013.55;7890306
426;2.473016;0.0004531659;70.88968;7.325282;0;0;0;7.789027;7.500568;65058.62;7895850
428;2.473338;0.0006518033;70.75022;7.310871;0;0;0;7.79004;7.501507;64930.63;7880390
430;2.473659;0.0005088079;70.8424;7.320396;0;0;0;7.791052;7.502447;65015.23;7890732
432;2.473981;0.0002463361;70.7812;7.314072;0;0;0;7.792065;7.503386;64959.06;7883989
434;2.474302;0.0003772192;70.94316;7.330808;0;0;0;7.793077;7.504325;65107.7;7902103
436;2.47473;0.000334885;70.88219;7.324508;0;0;0;7.794426;7.505577;65051.75;7895411
438;2.475052;0.0003922517;70.92116;7.328535;0;0;0;7.795439;7.506516;65087.51;7899826
440;2.475373;0.0002359093;70.8207;7.318153;0;0;0;7.796452;7.507455;64995.31;7888710
442;2.475695;0.0003703007;70.69421;7.305083;0;0;0;7.797463;7.508394;64879.23;7874695
444;2.475963;0.0005404605;70.87511;7.323776;0;0;0;7.798308;7.509177;65045.25;7894907
446;2.476338;0.0004727651;74.43564;7.691699;0;0;0;7.799489;7.510273;68312.91;8291612
448;2.476659;-0.000735699;64.13678;6.627481;0;0;0;7.800501;7.511212;58861.18;7144457
450;2.47698;-0.0005607374;66.1939;6.84005;0;0;0;7.801513;7.512151;60749.09;7373678
452;2.477302;-0.0006086965;66.66781;6.889021;0;0;0;7.802526;7.513091;61184.03;7426539
454;2.477677;-0.0006206716;68.34026;7.061841;0;0;0;7.803707;7.514186;62718.91;7612927
456;2.478052;0.0001266441;69.50282;7.181972;0;0;0;7.804887;7.515281;63785.84;7742517
458;2.478373;-0.000282841;68.07382;7.034309;0;0;0;7.8059;7.51622;62474.38;7583400
460;2.478748;8.956245e-005;72.39207;7.480528;0;0;0;7.807081;7.517316;66437.43;8064539
462;2.479016;-3.924317e-005;70.93637;7.330107;0;0;0;7.807925;7.518099;65101.47;7902436
464;2.479391;0.000127428;70.68561;7.304194;0;0;0;7.809106;7.519194;64871.34;7874586
466;2.479659;0.000424708;70.69002;7.30465;0;0;0;7.80995;7.519977;64875.38;7875139
468;2.47998;0.000196613;71.05516;7.342381;0;0;0;7.810962;7.520916;65210.49;7915892
470;2.480302;0.0001470272;70.90885;7.327263;0;0;0;7.811975;7.521855;65076.22;7899667
472;2.480677;0.0001175304;70.99795;7.33647;0;0;0;7.813156;7.52295;65157.99;7909680
474;2.480998;-0.0002649666;70.69812;7.305487;0;0;0;7.814167;7.523889;64882.82;7876350
476;2.481373;9.813521e-006;70.75662;7.311532;0;0;0;7.815349;7.524985;64936.5;7882954
478;2.481748;-0.0001891179;70.87564;7.323831;0;0;0;7.81653;7.52608;65045.73;7896300
480;2.482016;-0.0002713951;70.76834;7.312743;0;0;0;7.817374;7.526863;64947.26;7884407
482;2.482338;-0.000347773;70.84167;7.32032;0;0;0;7.818386;7.527802;65014.55;7892651
484;2.482659;-0.0001189921;70.80724;7.316763;0;0;0;7.819399;7.528741;64982.96;7888890
486;2.48298;-0.0002229656;70.967;7.333272;0;0;0;7.820411;7.52968;65129.58;7906764
488;2.483302;-0.0004973929;70.70904;7.306616;0;0;0;7.821424;7.530619;64892.84;7878097
490;2.483677;-0.00115955;67.85143;7.011328;0;0;0;7.822605;7.531714;62270.28;7559797
492;2.484052;-0.0004745795;66.57508;6.879438;0;0;0;7.823785;7.532809;61098.91;7417671
494;2.48432;-0.001554336;67.65717;6.991255;0;0;0;7.824628;7.533591;62092;7538295
496;2.484695;-0.001214545;66.50336;6.872028;0;0;0;7.82581;7.534687;61033.1;7409820
498;2.485016;-0.0007503592;60.80207;6.282894;0;0;0;7.826823;7.535626;55800.77;6774645
500;2.485338;-0.0004751087;70.82666;7.318769;0;0;0;7.827835;7.536565;65000.78;7891670
502;2.485659;-0.000746165;70.8991;7.326255;0;0;0;7.828848;7.537504;65067.27;7899817
504;2.485981;-0.0006860151;70.775;7.313432;0;0;0;7.82986;7.538443;64953.38;7886063
506;2.486302;-0.0006473265;70.94307;7.330798;0;0;0;7.830873;7.539382;65107.62;7904864
508;2.486677;-0.0006681799;70.75122;7.310974;0;0;0;7.832054;7.540477;64931.55;7883573
510;2.486998;-0.0007363065;70.75515;7.31138;0;0;0;7.833066;7.541415;64935.16;7884085
512;2.48732;-0.0008608004;70.74006;7.309821;0;0;0;7.834077;7.542354;64921.3;7882477
514;2.487641;-0.0004926304;70.80895;7.316939;0;0;0;7.83509;7.543293;64984.53;7890228
516;2.488016;-0.0007511823;70.66926;7.302505;0;0;0;7.836271;7.544388;64856.33;7874749
518;2.488391;-0.0004758339;70.66018;7.301566;0;0;0;7.837452;7.545484;64848;7873823
520;2.488766;-0.0006391536;71.02156;7.33891;0;0;0;7.838634;7.54658;65179.66;7914180
522;2.489034;-0.0006351357;70.98104;7.334722;0;0;0;7.839478;7.547362;65142.46;7909726
524;2.489356;-0.0007931833;70.62779;7.298219;0;0;0;7.84049;7.548301;64818.27;7870436
526;2.489677;-0.0005785922;70.83406;7.319534;0;0;0;7.841502;7.549239;65007.57;7893496
528;2.489998;-0.0007379137;70.83955;7.320101;0;0;0;7.842515;7.550178;65012.61;7894181
530;2.490373;-0.0006378404;70.75421;7.311283;0;0;0;7.843695;7.551272;64934.29;7884758
532;2.490695;-0.001176817;71.09486;7.346484;0;0;0;7.844708;7.552212;65246.93;7922794
534;2.491016;-0.0007733882;70.85614;7.321815;0;0;0;7.84572;7.55315;65027.84;7896265
536;2.491338;-0.0008602712;70.64508;7.300006;0;0;0;7.846733;7.554089;64834.14;7872818
538;2.491659;-0.001000131;70.78502;7.314466;0;0;0;7.847745;7.555028;64962.57;7888487
540;2.492034;-0.0009482714;70.74611;7.310445;0;0;0;7.848927;7.556123;64926.86;7884237
542;2.492302;-0.001268424;70.81429;7.317492;0;0;0;7.84977;7.556905;64989.43;7891898
544;2.492731;-0.0008936878;70.7876;7.314734;0;0;0;7.85112;7.558157;64964.94;7889022
546;2.493052;-0.0010603;70.82651;7.318754;0;0;0;7.852132;7.559095;65000.64;7893432
548;2.493373;-0.001291747;70.66999;7.30258;0;0;0;7.853144;7.560034;64857;7876062
550;2.493695;-0.001129779;70.68599;7.304234;0;0;0;7.854157;7.560973;64871.69;7877920
552;2.494016;-0.0013488;70.50093;7.28511;0;0;0;7.855169;7.561911;64701.84;7857368
554;2.494338;-0.001398856;70.94577;7.331078;0;0;0;7.856182;7.56285;65110.1;7907020
556;2.494659;-0.001389566;70.84164;7.320317;0;0;0;7.857193;7.563789;65014.53;7895489
558;2.495034;-0.001186675;70.66582;7.302149;0;0;0;7.858375;7.564884;64853.18;7875980
560;2.495355;-0.001297861;70.78134;7.314087;0;0;0;7.859387;7.565822;64959.2;7888929
562;2.495731;-0.0012559;70.79271;7.315261;0;0;0;7.860569;7.566918;64969.63;7890282
564;2.496052;-0.001243435;70.79706;7.315711;0;0;0;7.861581;7.567856;64973.62;7890841
566;2.49632;-0.001510395;71.09457;7.346454;0;0;0;7.862424;7.568638;65246.66;7924063
568;2.496641;-0.000578063;73.82993;7.629108;0;0;0;7.863437;7.569577;67757.02;8229019
570;2.496963;-0.0002641434;78.15167;8.075688;0;0;0;7.864449;7.570515;71723.27;8710797
572;2.497338;-0.001173289;73.41031;7.585748;0;0;0;7.865631;7.57161;67371.92;8182415
574;2.497659;0.0007590303;76.79371;7.935366;0;0;0;7.866642;7.572549;70477.02;8559613
576;2.497981;-0.0007654113;75.79992;7.832674;0;0;0;7.867655;7.573488;69564.97;8448922
578;2.498355;-0.0006419759;76.16727;7.870634;0;0;0;7.868836;7.574582;69902.1;8489961
580;2.498731;0.0003542294;74.2455;7.67205;0;0;0;7.870018;7.575678;68138.41;8275842
582;2.498998;-0.001292707;73.44074;7.588892;0;0;0;7.870861;7.576459;67399.84;8186203
584;2.499373;-0.0003164732;73.35488;7.580019;0;0;0;7.872042;7.577554;67321.04;8176721
586;2.499695;-0.0006618298;69.19597;7.150265;0;0;0;7.873054;7.578492;63504.23;7713209
588;2.500016;-0.001443777;71.96079;7.435963;0;0;0;7.874066;7.579431;66041.63;8021476
590;2.500338;-0.001189635;70.73096;7.30888;0;0;0;7.87508;7.58037;64912.95;7884460
592;2.500659;-0.001048384;70.81312;7.31737;0;0;0;7.876091;7.581308;64988.36;7893693
594;2.500981;-0.001558707;70.85676;7.32188;0;0;0;7.877104;7.582247;65028.41;7898632
596;2.501302;-0.001297234;70.78543;7.314509;0;0;0;7.878116;7.583185;64962.95;7890755
598;2.501731;-0.001326966;70.70887;7.306598;0;0;0;7.879467;7.584437;64892.68;7882319
600;2.502052;-0.001047463;70.87315;7.323573;0;0;0;7.880478;7.585375;65043.45;7900706
602;2.502373;-0.001212821;70.80543;7.316576;0;0;0;7.881491;7.586313;64981.3;7893231
604;2.502695;-0.001178699;70.94777;7.331284;0;0;0;7.882503;7.587251;65111.93;7909173
606;2.503016;-0.001134326;70.78595;7.314563;0;0;0;7.883515;7.58819;64963.43;7891208
608;2.503337;-0.001244238;70.80152;7.316172;0;0;0;7.884527;7.589128;64977.71;7893018
610;2.503659;-0.001307504;70.87946;7.324226;0;0;0;7.88554;7.590067;65049.24;7901780
612;2.50398;-0.001238417;70.68597;7.304231;0;0;0;7.886552;7.591005;64871.66;7880283
614;2.504302;-0.0006864071;70.2442;7.258582;0;0;0;7.887565;7.591944;64466.24;7831108
616;2.504677;-0.001986634;73.10024;7.553707;0;0;0;7.888747;7.593039;67087.35;8149599
618;2.504998;-0.0008867496;77.31109;7.988829;0;0;0;7.889759;7.593977;70951.84;8619128
620;2.505373;-0.0002464062;77.57747;8.016355;0;0;0;7.890939;7.595071;71196.3;8648920
622;2.505695;-0.000376427;76.27157;7.881412;0;0;0;7.891952;7.596009;69997.83;8503409
624;2.506016;-0.001306975;70.59379;7.294706;0;0;0;7.892964;7.596948;64787.07;7870474
626;2.506337;-0.001276342;70.83876;7.32002;0;0;0;7.893976;7.597886;65011.89;7897861
628;2.506659;-0.001129818;70.84921;7.3211;0;0;0;7.894989;7.598825;65021.48;7899100
630;2.50698;-0.0009622848;70.79016;7.314998;0;0;0;7.896001;7.599763;64967.29;7892590
632;2.507302;-0.0008273446;70.61037;7.29642;0;0;0;7.897014;7.600701;64802.29;7872619
634;2.507677;-0.001151279;70.88152;7.324438;0;0;0;7.898196;7.601796;65051.13;7902936
636;2.507998;-0.0009808844;70.61663;7.297067;0;0;0;7.899208;7.602734;64808.03;7873477
638;2.50832;-0.0008797136;70.95725;7.332264;0;0;0;7.900219;7.603672;65120.64;7911529
640;2.508695;-0.0008673857;70.91003;7.327384;0;0;0;7.9014;7.604766;65077.29;7906350
642;2.509016;-0.0009695756;70.89737;7.326077;0;0;0;7.902413;7.605705;65065.68;7905013
644.0001;2.509391;-0.0006209459;71.01302;7.338027;0;0;0;7.903594;7.606799;65171.82;7917995
646.0001;2.509713;-0.0009212638;70.81509;7.317574;0;0;0;7.904607;7.607738;64990.16;7895999
648.0001;2.510034;-0.0006638093;70.8604;7.322256;0;0;0;7.905619;7.608676;65031.75;7901126
650.0001;2.510302;-0.0002428392;70.74279;7.310102;0;0;0;7.906463;7.609458;64923.81;7888073
652.0001;2.510623;-0.0003224509;70.80616;7.316651;0;0;0;7.907475;7.610396;64981.97;7895214
654.0001;2.510998;4.811023e-005;70.92697;7.329135;0;0;0;7.908657;7.611491;65092.85;7908771
656.0001;2.51132;3.980022e-005;70.69848;7.305524;0;0;0;7.909668;7.612429;64883.14;7883366
658.0001;2.511695;2.196502e-005;70.66602;7.30217;0;0;0;7.910849;7.613523;64853.36;7879834
660.0001;2.512016;0.0002606434;70.73184;7.308971;0;0;0;7.911862;7.614462;64913.76;7887247
662.0001;2.512338;0.0005847742;70.85018;7.3212;0;0;0;7.912874;7.615399;65022.37;7900517
664.0001;2.512659;0.0004173779;70.58894;7.294205;0;0;0;7.913887;7.616338;64782.62;7871460
666.0001;2.513088;6.743503e-005;70.92771;7.329211;0;0;0;7.915236;7.617588;65093.52;7909335
668.0001;2.513302;0.0001402067;70.77897;7.313841;0;0;0;7.915912;7.618214;64957.02;7892799
670.0001;2.51373;0.0004773317;70.9248;7.328911;0;0;0;7.917261;7.619465;65090.85;7909160
672.0001;2.514052;0.0005560615;71.00397;7.337092;0;0;0;7.918274;7.620403;65163.52;7918063
674.0001;2.514373;0.0003899194;70.88345;7.324638;0;0;0;7.919286;7.621341;65052.9;7904697
676.0001;2.514641;0.0005862638;70.82023;7.318105;0;0;0;7.920129;7.622123;64994.88;7897708
678.0001;2.515016;0.0008357609;70.61781;7.297188;0;0;0;7.92131;7.623217;64809.11;7875221
680.0001;2.515338;0.0007520138;70.73574;7.309374;0;0;0;7.922323;7.624155;64917.34;7888447
682.0001;2.515659;0.0009198217;70.86918;7.323163;0;0;0;7.923336;7.625094;65039.8;7903402
684.0001;2.51598;0.0009746797;70.80261;7.316284;0;0;0;7.924348;7.626031;64978.71;7896052
686.0001;2.516302;0.0007600298;70.84845;7.321021;0;0;0;7.925361;7.62697;65020.78;7901238
688.0001;2.516677;0.001081965;70.69595;7.305263;0;0;0;7.926541;7.628064;64880.82;7884317
690.0001;2.516999;0.0008623374;70.74781;7.310622;0;0;0;7.927554;7.629002;64928.42;7890175
692.0001;2.51732;0.001748121;70.97722;7.334328;0;0;0;7.928566;7.62994;65138.96;7915835
694.0001;2.517641;0.001168751;70.87003;7.323251;0;0;0;7.929578;7.630878;65040.59;7903954
696.0001;2.517962;0.001692695;67.10434;6.934129;0;0;0;7.93059;7.631815;61584.65;7484047
698.0001;2.518338;0.006457542;92.06725;9.513635;0;0;0;7.931772;7.63291;84494.22;1.026823e+007
700.0001;2.518659;0.006173276;87.39605;9.030943;0;0;0;7.932784;7.633848;80207.25;9747349
702.0001;2.519034;0.004238428;96.73284;9.995747;0;0;0;7.933965;7.634942;88776.04;1.078881e+007
704.0001;2.519409;0.005934245;85.3305;8.817502;0;0;0;7.935147;7.636037;78311.6;9517184
706.0001;2.51973;0.007388149;63.86227;6.599114;0;0;0;7.936159;7.636975;58609.25;7122830
708.0001;2.520052;0.002575695;78.82968;8.14575;0;0;0;7.937172;7.637913;72345.52;8792292
710.0001;2.52032;0.001474282;75.0465;7.75482;0;0;0;7.938015;7.638694;68873.52;8370399
712.0001;2.520641;0.004127713;45.33478;4.684603;0;0;0;7.939027;7.639632;41605.75;5056515
714.0001;2.520962;0.001575805;71.02823;7.339598;0;0;0;7.940039;7.640569;65185.77;7922365
716.0001;2.521338;0.001379481;72.06739;7.446978;0;0;0;7.941221;7.641664;66139.45;8038359
718.0001;2.521659;0.002869957;73.19471;7.563468;0;0;0;7.942233;7.642602;67174.05;8164177
720.0001;2.522034;0.002253132;74.89144;7.738798;0;0;0;7.943414;7.643696;68731.21;8353522
722.0001;2.522409;0.002791109;78.84052;8.146871;0;0;0;7.944596;7.644791;72355.46;8794106
724.0001;2.522731;0.002016394;70.63428;7.29889;0;0;0;7.945608;7.645728;64824.23;7878831
726.0001;2.523052;0.002204272;70.88903;7.325214;0;0;0;7.946621;7.646667;65058.02;7907322
728.0001;2.523373;0.002627437;70.80824;7.316866;0;0;0;7.947633;7.647604;64983.88;7898384
730.0001;2.523695;0.001950639;70.93012;7.32946;0;0;0;7.948645;7.648542;65095.73;7912053
732.0001;2.524016;0.00217844;70.90178;7.326532;0;0;0;7.949657;7.649479;65069.72;7908966
734.0001;2.524338;0.002338271;70.72449;7.308212;0;0;0;7.95067;7.650417;64907.02;7889264
736.0001;2.524659;0.002160526;70.70687;7.306391;0;0;0;7.951682;7.651355;64890.85;7887372
738.0001;2.524981;0.002227183;70.7585;7.311726;0;0;0;7.952694;7.652293;64938.23;7893205
740.0001;2.525302;0.002481207;71.07201;7.344123;0;0;0;7.953707;7.653231;65225.96;7928253
742.0001;2.525677;0.002525286;70.84267;7.320424;0;0;0;7.954888;7.654325;65015.47;7902755
744.0001;2.526052;0.002088166;70.9105;7.327433;0;0;0;7.956069;7.65542;65077.73;7910409
746.0001;2.526373;0.002673456;70.97291;7.333882;0;0;0;7.957082;7.656357;65135;7917445
748.0001;2.526695;0.002834776;70.89106;7.325424;0;0;0;7.958094;7.657294;65059.88;7908388
750.0001;2.526962;0.002856727;70.82599;7.3187;0;0;0;7.958937;7.658076;65000.16;7901190
752.0001;2.527338;0.002970716;70.84281;7.320438;0;0;0;7.960119;7.65917;65015.61;7903154
754.0001;2.527659;0.003081804;70.87473;7.323737;0;0;0;7.961131;7.660107;65044.9;7906789
756.0001;2.527981;0.003004035;70.97384;7.333978;0;0;0;7.962143;7.661046;65135.86;7917920
758.0001;2.528302;0.003215941;70.73694;7.309499;0;0;0;7.963155;7.661983;64918.45;7891565
760.0001;2.528677;0.003084136;70.84898;7.321076;0;0;0;7.964337;7.663077;65021.27;7904151
762.0001;2.529105;0.003335084;70.7551;7.311375;0;0;0;7.965686;7.664327;64935.11;7893776
764.0001;2.529373;0.003585482;70.90348;7.326708;0;0;0;7.96653;7.665109;65071.29;7910392
766.0001;2.529695;0.003276071;70.65081;7.300598;0;0;0;7.967543;7.666046;64839.4;7882277
768.0001;2.530016;0.00372642;70.74232;7.310054;0;0;0;7.968554;7.666984;64923.38;7892560
770.0001;2.530391;0.00381248;70.84968;7.321149;0;0;0;7.969736;7.668078;65021.91;7904625
772.0001;2.530659;0.003966216;70.84707;7.320878;0;0;0;7.97058;7.668859;65019.51;7904394
774.0001;2.530981;0.004125341;70.89185;7.325506;0;0;0;7.971592;7.669797;65060.61;7909466
776.0001;2.531302;0.00462706;70.93593;7.33006;0;0;0;7.972604;7.670735;65101.06;7914457
778.0001;2.531623;0.004620553;70.81444;7.317507;0;0;0;7.973617;7.671673;64989.57;7900977
780.0001;2.531998;0.004558306;70.7234;7.3081;0;0;0;7.974798;7.672766;64906.02;7890906
782.0001;2.532373;0.004956757;71.02465;7.339229;0;0;0;7.975979;7.67386;65182.49;7924604
784.0001;2.532695;0.004796592;70.95417;7.331945;0;0;0;7.976992;7.674798;65117.8;7916814
786.0001;2.533016;0.005338117;70.91461;7.327857;0;0;0;7.978004;7.675735;65081.5;7912474
788.0001;2.533337;0.005158765;70.78434;7.314396;0;0;0;7.979015;7.676672;64961.95;7898013
790.0001;2.533659;0.005629243;70.68332;7.303957;0;0;0;7.980028;7.67761;64869.23;7886815
792.0001;2.53398;0.005470039;70.79119;7.315104;0;0;0;7.98104;7.678547;64968.23;7898925
794.0001;2.534302;0.005773336;70.70567;7.306267;0;0;0;7.982053;7.679485;64889.75;7889457
796.0001;2.534677;0.005806948;70.94263;7.330753;0;0;0;7.983235;7.68058;65107.21;7915984
798.0001;2.534998;0.005943064;70.8784;7.324116;0;0;0;7.984247;7.681517;65048.27;7908891
800.0001;2.535373;0.005799462;70.57569;7.292836;0;0;0;7.985428;7.682611;64770.46;7875201
802.0001;2.535695;0.005915802;70.78528;7.314494;0;0;0;7.98644;7.683548;64962.81;7898662
804.0001;2.536016;0.006118633;70.82889;7.319;0;0;0;7.987453;7.684485;65002.83;7903602
806.0001;2.536337;0.006551206;70.86199;7.32242;0;0;0;7.988464;7.685422;65033.2;7907369
808.0001;2.536659;0.0060489;70.88663;7.324966;0;0;0;7.989477;7.68636;65055.82;7910193
810.0001;2.537034;0.006635836;70.86034;7.32225;0;0;0;7.990658;7.687454;65031.7;7907346
812.0001;2.537302;0.008823493;74.74564;7.723731;0;0;0;7.991502;7.688235;68597.41;8340973
814.0001;2.537623;0.006014817;69.74415;7.20691;0;0;0;7.992514;7.689172;64007.32;7782924
816.0001;2.537998;0.00631486;71.42532;7.380631;0;0;0;7.993696;7.690267;65550.2;7970616
818.0001;2.53832;0.006806936;71.11779;7.348854;0;0;0;7.994709;7.691205;65267.97;7936373
820.0001;2.538641;0.007000674;72.54166;7.495986;0;0;0;7.99572;7.692142;66574.71;8095344
822.0001;2.539016;0.007327313;75.37144;7.788397;0;0;0;7.996901;7.693235;69171.73;8411228
824.0001;2.539391;0.007344188;75.34407;7.785569;0;0;0;7.998082;7.694328;69146.61;8408266
826.0001;2.539713;0.007968362;74.92089;7.741841;0;0;0;7.999095;7.695266;68758.24;8361118
828.0001;2.540034;0.005468412;51.48176;5.319793;0;0;0;8.000107;7.696203;47247.11;5745382
830.0001;2.540409;0.00494584;59.38627;6.136593;0;0;0;8.001288;7.697297;54501.43;6627600
832.0001;2.540677;0.00556043;58.9006;6.086407;0;0;0;8.002131;7.698078;54055.7;6573450
834.0001;2.540998;0.005612054;71.32309;7.370068;0;0;0;8.003144;7.699016;65456.38;7959905
836.0001;2.54132;0.006896328;71.08494;7.345458;0;0;0;8.004156;7.699953;65237.82;7933400
838.0001;2.541641;0.007578241;70.83873;7.320016;0;0;0;8.00517;7.700891;65011.86;7905996
840.0001;2.541963;0.007633138;70.96189;7.332743;0;0;0;8.006182;7.701827;65124.89;7919816
842.0001;2.542337;0.007827464;70.88668;7.324972;0;0;0;8.007362;7.702921;65055.87;7911509
844.0001;2.542713;0.007718786;70.91279;7.32767;0;0;0;8.008544;7.704015;65079.83;7914510
846.0001;2.543034;0.007968264;70.81426;7.317489;0;0;0;8.009556;7.704952;64989.41;7903587
848.0001;2.543409;0.008022142;70.81568;7.317635;0;0;0;8.010737;7.706045;64990.7;7903831
850.0001;2.54373;0.008007208;70.90351;7.326711;0;0;0;8.011749;7.706982;65071.31;7913708
852.0001;2.544052;0.008409676;70.94292;7.330783;0;0;0;8.012762;7.70792;65107.48;7918181
854.0001;2.544373;0.008149125;70.77585;7.313519;0;0;0;8.013774;7.708857;64954.16;7899609
856.0001;2.544695;0.008222543;70.88275;7.324565;0;0;0;8.014787;7.709795;65052.26;7911614
858.0001;2.545016;0.008561981;70.79964;7.315977;0;0;0;8.015799;7.710732;64975.98;7902411
860.0001;2.545337;0.008660252;70.76742;7.312648;0;0;0;8.016811;7.711669;64946.42;7898890
862.0001;2.545659;0.006364681;70.66479;7.302043;0;0;0;8.017823;7.712605;64852.23;7887508
864.0001;2.54598;0.006743356;70.92398;7.328825;0;0;0;8.018836;7.713543;65090.1;7916512
866.0001;2.546356;0.006946208;70.72576;7.308343;0;0;0;8.020018;7.714637;64908.18;7894473
868.0001;2.546677;0.007208405;70.80064;7.316081;0;0;0;8.021029;7.715574;64976.9;7902905
870.0001;2.546998;0.007695562;70.88437;7.324732;0;0;0;8.022042;7.716512;65053.74;7912326
872.0001;2.54732;0.007452022;70.78405;7.314366;0;0;0;8.023054;7.717448;64961.68;7901202
874.0001;2.547641;0.008167627;70.9683;7.333405;0;0;0;8.024067;7.718386;65130.77;7921843
876.0001;2.547963;0.008349056;70.83297;7.319422;0;0;0;8.025079;7.719323;65006.57;7906811
878.0001;2.548338;0.008514904;70.84296;7.320454;0;0;0;8.026259;7.720416;65015.74;7908012
880.0001;2.548659;0.008667856;70.72964;7.308743;0;0;0;8.027272;7.721353;64911.74;7895436
882.0001;2.549034;0.008690924;70.85503;7.321701;0;0;0;8.028454;7.722446;65026.82;7909520
884.0001;2.549356;0.008831137;70.70823;7.306531;0;0;0;8.029467;7.723384;64892.09;7893207
886.0001;2.54973;0.008763245;70.78716;7.314688;0;0;0;8.030647;7.724477;64964.54;7902105
888.0001;2.550052;0.008538482;70.94451;7.330947;0;0;0;8.03166;7.725415;65108.94;7919744
890.0001;2.550373;0.008466984;70.74808;7.310649;0;0;0;8.032672;7.726351;64928.66;7897890
892.0001;2.550695;0.008847815;70.83006;7.319121;0;0;0;8.033685;7.727289;65003.91;7907116
894.0001;2.551016;0.008850912;70.83676;7.319813;0;0;0;8.034697;7.728226;65010.05;7907938
896.0001;2.551338;0.008098755;70.96589;7.333156;0;0;0;8.035708;7.729162;65128.56;7922427
898.0001;2.551659;0.008823826;70.82719;7.318824;0;0;0;8.03672;7.730098;65001.27;7907017
900.0001;2.55198;0.008236204;70.99936;7.336616;0;0;0;8.037734;7.731037;65159.28;7926313
902.0001;2.552302;0.008272443;70.88754;7.32506;0;0;0;8.038746;7.731973;65056.65;7913903
904.0001;2.552677;0.007412668;70.76496;7.312394;0;0;0;8.039927;7.733067;64944.16;7900305
906.0001;2.553052;0.007125756;70.81068;7.317118;0;0;0;8.041109;7.734161;64986.12;7905496
908.0001;2.553373;0.00685123;71.01593;7.338327;0;0;0;8.042121;7.735097;65174.48;7928484
910.0001;2.553695;0.006782496;70.99008;7.335657;0;0;0;8.043134;7.736035;65150.77;7925673
912.0001;2.554016;0.00710404;70.94601;7.331102;0;0;0;8.044146;7.736971;65110.31;7920827
914.0001;2.554338;0.007485478;70.78634;7.314603;0;0;0;8.045157;7.737908;64963.78;7903074
916.0001;2.554659;0.008037371;70.85435;7.321631;0;0;0;8.046169;7.738845;65026.2;7910742
918.0001;2.55498;0.00781492;70.87808;7.324083;0;0;0;8.047182;7.739782;65047.97;7913465
920.0001;2.555302;0.008122294;70.87071;7.323321;0;0;0;8.048195;7.740719;65041.21;7912716
922.0001;2.555677;-0.03411356;70.91358;7.327752;0;0;0;8.049376;7.741812;65080.56;7917590
924.0001;2.556052;-0.03241787;70.87567;7.323834;0;0;0;8.050557;7.742905;65045.76;7913443
926.0001;2.556373;-0.03215296;70.87467;7.32373;0;0;0;8.05157;7.743842;65044.84;7913406
928.0001;2.556641;-0.03181296;70.85491;7.321689;0;0;0;8.052413;7.744623;65026.71;7911261
930.0001;2.557016;-0.0312713;70.87976;7.324256;0;0;0;8.053595;7.745716;65049.51;7914122
932.0001;2.557338;-0.0310708;70.95414;7.331942;0;0;0;8.054606;7.746653;65117.78;7922501
934.0001;2.557659;-0.03142868;70.84625;7.320794;0;0;0;8.055618;7.747589;65018.76;7910529
936.0001;2.55798;-0.03084803;70.84257;7.320414;0;0;0;8.056631;7.748527;65015.39;7910193
938.0001;2.558302;-0.03069392;70.81673;7.317743;0;0;0;8.057644;7.749464;64991.67;7907381
940.0001;2.558677;-0.03047669;70.78053;7.314003;0;0;0;8.058825;7.750557;64958.45;7903425
942.0001;2.558998;-0.03035354;70.81653;7.317722;0;0;0;8.059837;7.751493;64991.48;7907519
944.0001;2.55932;-0.02968149;70.82446;7.318542;0;0;0;8.06085;7.752431;64998.76;7908478
946.0001;2.559695;-0.02983783;70.69921;7.3056;0;0;0;8.062031;7.753523;64883.82;7894579
948.0001;2.560016;-0.02954406;74.83151;7.732605;0;0;0;8.063044;7.754461;68676.21;8356088
950.0001;2.560391;-0.02964572;66.40158;6.86151;0;0;0;8.064224;7.755553;60939.69;7414838
952.0001;2.560659;-0.0294591;65.99021;6.819003;0;0;0;8.065067;7.756334;60562.16;7368960
954.0001;2.561034;-0.03622432;82.64905;8.540419;0;0;0;8.066249;7.757427;75850.72;9229310
956.0001;2.561302;-0.03558279;83.03548;8.580351;0;0;0;8.067092;7.758207;76205.37;9272535
958.0001;2.561677;-0.03968529;80.17061;8.284313;0;0;0;8.068274;7.759301;73576.15;8952714
960.0001;2.561998;-0.04312341;78.41544;8.102945;0;0;0;8.069285;7.760236;71965.35;8756795
962.0001;2.56232;-0.04281208;69.69502;7.201833;0;0;0;8.070299;7.761174;63962.23;7783043
964.0001;2.562695;-0.0446339;68.47705;7.075976;0;0;0;8.07148;7.762267;62844.44;7647112
966.0001;2.563016;-0.04442095;70.84633;7.320802;0;0;0;8.072493;7.763204;65018.84;7911774
968.0001;2.563391;-0.04438395;71.0144;7.338169;0;0;0;8.073673;7.764297;65173.08;7930629
970.0001;2.563712;-0.04419649;71.05736;7.342608;0;0;0;8.074685;7.765233;65212.51;7935501
972.0001;2.564034;-0.04349868;70.85153;7.321339;0;0;0;8.075697;7.766169;65023.61;7912588
974.0001;2.564409;-0.0429579;70.78863;7.31484;0;0;0;8.076879;7.767263;64965.88;7905650
976.0001;2.564677;-0.04264751;70.95229;7.331751;0;0;0;8.077723;7.768044;65116.08;7923989
978.0001;2.565052;-0.04221607;70.81799;7.317874;0;0;0;8.078903;7.769136;64992.83;7909078
980.0001;2.56532;-0.04246198;70.76619;7.312521;0;0;0;8.079747;7.769916;64945.29;7903355
982.0001;2.565641;-0.04198466;70.88657;7.32496;0;0;0;8.08076;7.770854;65055.76;7916872
984.0001;2.566016;-0.0417247;70.82907;7.319018;0;0;0;8.081942;7.771947;65002.99;7910537
986.0001;2.566338;-0.04115867;70.82084;7.318169;0;0;0;8.082953;7.772883;64995.45;7909693
988.0001;2.566659;-0.04096321;70.82152;7.318239;0;0;0;8.083965;7.773819;64996.07;7909842
990.0001;2.56698;-0.04016474;70.78481;7.314445;0;0;0;8.084977;7.774756;64962.38;7905816
992.0001;2.567355;-0.03985353;70.96089;7.33264;0;0;0;8.086159;7.775849;65123.98;7925569
994.0001;2.567677;-0.03981131;70.74496;7.310327;0;0;0;8.087171;7.776785;64925.8;7901526
996.0001;2.567998;-0.0386533;70.68646;7.304282;0;0;0;8.088183;7.777722;64872.12;7895066
998.0001;2.56832;-0.0381817;70.76837;7.312746;0;0;0;8.089195;7.778659;64947.29;7904288
1000;2.568641;-0.03799425;70.79794;7.315802;0;0;0;8.090209;7.779597;64974.43;7907666
1002;2.568963;-0.03770695;70.98433;7.335062;0;0;0;8.091222;7.780533;65145.48;7928558
1004;2.569338;-0.03741639;70.93308;7.329767;0;0;0;8.092402;7.781625;65098.45;7922921
1006;2.569713;-0.03720176;70.91837;7.328246;0;0;0;8.093583;7.782717;65084.95;7921364
1008;2.570034;-0.03694703;71.08582;7.345549;0;0;0;8.094595;7.783654;65238.63;7940142
1010;2.570409;-0.03675204;70.76558;7.312458;0;0;0;8.095777;7.784747;64944.73;7904458
1012;2.57073;-0.03634334;70.92612;7.329047;0;0;0;8.096788;7.785683;65092.06;7922465
1014;2.571052;-0.03591347;70.84827;7.321003;0;0;0;8.097801;7.78662;65020.62;7913843
1016;2.571373;-0.03589593;70.86028;7.322244;0;0;0;8.098813;7.787556;65031.64;7915259
1018;2.571695;-0.0354545;70.93875;7.330352;0;0;0;8.099826;7.788493;65103.65;7924098
1020;2.571963;-0.03540783;70.98527;7.335159;0;0;0;8.10067;7.789273;65146.35;7929356
1022;2.572338;-0.03529855;71.05484;7.342348;0;0;0;8.101851;7.790367;65210.2;7937214
1024;2.572659;-0.03506812;70.98394;7.335022;0;0;0;8.102863;7.791302;65145.13;7929369
1026;2.57298;-0.03472813;70.98359;7.334986;0;0;0;8.103875;7.792238;65144.81;7929404
1028;2.573355;-0.03465011;70.80229;7.316251;0;0;0;8.105057;7.793331;64978.41;7909237
1030;2.57373;-0.03470289;70.82939;7.319051;0;0;0;8.106237;7.794424;65003.29;7912351
1032;2.574052;-0.03442496;70.83062;7.319179;0;0;0;8.10725;7.79536;65004.42;7912563
1034;2.574373;-0.034409;70.7762;7.313556;0;0;0;8.108262;7.796297;64954.48;7906558
1036;2.574695;-0.03264984;74.35979;7.68386;0;0;0;8.109275;7.797234;68243.3;8306966
1038;2.575016;-0.0357486;54.32076;5.613156;0;0;0;8.110287;7.79817;49852.59;6068400
1040;2.575338;-0.03328572;71.72133;7.411219;0;0;0;8.1113;7.799106;65821.87;8012365
1042;2.575659;-0.0330908;70.94794;7.331302;0;0;0;8.112312;7.800043;65112.09;7926040
1044;2.57598;-0.03248701;70.76605;7.312506;0;0;0;8.113324;7.800979;64945.16;7905794
1046;2.576302;-0.03207666;70.82375;7.318469;0;0;0;8.114336;7.801915;64998.11;7912314
1048;2.576677;-0.03179447;70.78105;7.314056;0;0;0;8.115518;7.803008;64958.93;7907630
1050;2.576998;-0.03145343;70.98491;7.335123;0;0;0;8.11653;7.803944;65146.02;7930480
1052;2.577373;-0.03122977;70.96577;7.333144;0;0;0;8.117711;7.805036;65128.45;7928427
1054;2.577695;-0.03059928;70.78919;7.314898;0;0;0;8.118724;7.805973;64966.39;7908774
1056;2.577963;-0.03040399;70.65152;7.300671;0;0;0;8.119567;7.806753;64840.05;7893454
1058;2.578338;-0.03024608;70.86128;7.322347;0;0;0;8.120749;7.807846;65032.55;7916976
1060;2.578659;-0.029865;70.76573;7.312473;0;0;0;8.12176;7.808782;64944.86;7906375
1062;2.57898;-0.0296176;70.82237;7.318326;0;0;0;8.122773;7.809718;64996.85;7912778
1063.94;2.579302;-0.02911557;71.01601;7.338336;0;0;0;8.123785;7.810654;65174.56;7934486