File: Ensayos/Resistencia/comp/Extensometro/extensometro2.raw
"Test Type";"Manual"
"Method Name:";"C:\INSTRON\user\template\CYCLE.MTM"
"Name:";""
"Operator ID:";""
"Company:";""
"Lab name:";""
"Test date:";"12/05/2017"
"Temperature:";""
"Humidity:";""
"Note 1:";""
"Note 2:";""
"Note 3:";""
"Geometry:";"Rectangular"
"Specimen";1
"Specimen name:";""
"Width:";0.250000;"in"
"Thickness:";0.060000;"in"
"Length:";1.250000;"in"
"Diameter:";0.039370;"in"
"Inner diameter:";0.019685;"in"
"Outer diameter:";0.039370;"in"
"Wall thickness:";0.019685;"in"
"Area:";0.015000;"in*in"
"Linear density:";1.000000;"den"
"Sled weight:";2.204623;"lbf"
"Loading span:";0.000000;"mm"
"Support span:";1.000000;"mm"
"Span ratio:";"2"
"Fixture type:";"3-point"
"Comment:";""
"Included"
"Final Width:";0.250000;"in"
"Final Thickness:";0.060000;"in"
"Final Length:";1.250000;"in"
"Final Diameter:";0.039370;"in"
"Final Inner diameter:";0.019685;"in"
"Final Outer diameter:";0.039370;"in"
"Final Wall thickness:";0.019685;"in"
"Final Area:";0.015000;"in*in"
"Final Linear density:";1.000000;"den"
"Time sec";"Extension mm";"Strain 1 %";"Load N";"Stress MPa";"Cycle Count ";"Total Cycle Count ";"Repetitions Count ";"Strain [Exten.] %";"True strain %";"Tenacity gf/tex";"True stress Pa"
0;2.579302;-0.0002792395;71.24237;7.361726;0;0;0;8.123785;7.810654;65382.3;7959777
6;2.580373;0.000160448;71.28058;7.365674;0;0;0;8.12716;7.813775;65417.36;7964295
12;2.581338;-0.0005758922;71.09713;7.346718;0;0;0;8.130198;7.816585;65249;7944020
18;2.582302;-0.0002088;71.34327;7.372153;0;0;0;8.133234;7.819393;65474.9;7971748
24;2.58332;-0.0003224752;71.24745;7.362251;0;0;0;8.13644;7.822358;65386.96;7961276
30;2.584391;0.0004086907;71.32926;7.370705;0;0;0;8.139815;7.825479;65462.05;7970667
36;2.585302;0.0004549055;71.21553;7.358953;0;0;0;8.142682;7.82813;65357.66;7958169
42;2.586373;2.995672e-005;71.4909;7.387408;0;0;0;8.146058;7.831251;65610.39;7989190
48;2.587391;0.0003722364;72.60215;7.502237;0;0;0;8.149264;7.834216;66630.23;8113615
54;2.588302;4.269619e-005;71.25191;7.362712;0;0;0;8.152131;7.836867;65391.05;7962930
60;2.58932;0.0009522145;71.16792;7.354033;0;0;0;8.155338;7.839832;65313.98;7953780
66;2.590391;0.001111242;71.38159;7.376113;0;0;0;8.158712;7.842952;65510.07;7977909
72;2.591355;0.003675791;77.26842;7.984419;0;0;0;8.161749;7.84576;70912.67;8636088
78;2.592373;6.868941e-006;63.1331;6.523766;0;0;0;8.164955;7.848724;57940.06;7056429
84.00001;2.593338;0.0008162747;63.51222;6.562942;0;0;0;8.167993;7.851532;58287.99;7099003
90.00001;2.594302;-0.0006050165;43.8084;4.526877;0;0;0;8.171029;7.854339;40204.93;4896770
96.00001;2.595373;0.0004430677;71.42897;7.381008;0;0;0;8.174404;7.857459;65553.55;7984361
102;2.596338;0.000813178;71.41539;7.379605;0;0;0;8.177442;7.860267;65541.09;7983068
108;2.597302;-0.001602966;71.39528;7.377527;0;0;0;8.180478;7.863074;65522.64;7981044
114;2.59832;-0.001494269;71.1689;7.354134;0;0;0;8.183683;7.866037;65314.87;7955973
120;2.599338;-0.001208788;71.27787;7.365395;0;0;0;8.18689;7.869001;65414.88;7968392
126;2.600355;-0.0003370961;95.96282;9.916179;0;0;0;8.190096;7.871964;88069.36;1.072832e+007
132;2.60132;-0.001246497;72.015;7.441565;0;0;0;8.193132;7.874771;66091.38;8051262
138;2.602338;-0.00155977;71.42617;7.380719;0;0;0;8.196339;7.877734;65550.98;7985668
144;2.603302;-0.001642086;71.16739;7.353979;0;0;0;8.199376;7.880541;65313.49;7956959
150;2.604373;-0.00209122;71.39434;7.37743;0;0;0;8.20275;7.88366;65521.77;7982582
156;2.605338;-0.002343892;71.43733;7.381873;0;0;0;8.205788;7.886467;65561.23;7987613
162;2.606302;-0.001679599;83.26199;8.603756;0;0;0;8.208825;7.889274;76413.24;9310024
168;2.607373;0.001449641;105.8109;10.93381;0;0;0;8.212199;7.892392;97107.34;1.183172e+007
174;2.608338;-0.002492336;103.8745;10.73372;0;0;0;8.215237;7.895199;95330.23;1.161552e+007
180;2.609302;-0.003341764;66.11531;6.831929;0;0;0;8.218274;7.898006;60676.97;7393396
186;2.610373;-0.001892877;66.95925;6.919136;0;0;0;8.221648;7.901123;61451.48;7488003
192;2.611391;-0.002037283;71.47762;7.386036;0;0;0;8.224854;7.904086;65598.2;7993526
198;2.612302;-0.002629374;71.51286;7.389677;0;0;0;8.227722;7.906736;65630.54;7997679
204;2.61332;-0.002919402;71.35793;7.373667;0;0;0;8.230928;7.909698;65488.35;7980589
210;2.614391;-0.001942972;72.46868;7.488446;0;0;0;8.234303;7.912817;66507.74;8105067
216;2.615302;-0.002943862;103.1091;10.65462;0;0;0;8.237171;7.915467;94627.77;1.153226e+007
222;2.616373;-0.002994153;71.27946;7.365559;0;0;0;8.240545;7.918584;65416.34;7972521
228;2.617337;-0.002856567;71.47689;7.38596;0;0;0;8.243583;7.92139;65597.53;7994828
234;2.618302;-0.002561953;71.28372;7.365999;0;0;0;8.24662;7.924196;65420.25;7973445
240;2.619373;-0.002548782;71.4497;7.38315;0;0;0;8.249994;7.927313;65572.57;7992260
246;2.620337;-0.002905879;71.29346;7.367006;0;0;0;8.253032;7.930118;65429.19;7975007
252;2.621356;-0.002426052;71.19882;7.357226;0;0;0;8.256238;7.93308;65342.33;7964656
258;2.622373;-0.002840731;71.21353;7.358746;0;0;0;8.259443;7.936041;65355.83;7966538
264;2.623337;-0.002477402;71.24108;7.361593;0;0;0;8.262481;7.938847;65381.11;7969843
270;2.624409;-0.002221437;71.29567;7.367234;0;0;0;8.265856;7.941964;65431.22;7976199
276;2.625373;-0.003555277;71.33778;7.371586;0;0;0;8.268892;7.944769;65469.87;7981134
282;2.626338;-0.002853823;71.36776;7.374684;0;0;0;8.271929;7.947574;65497.38;7984712
288;2.627302;-0.002362982;71.43798;7.38194;0;0;0;8.274967;7.95038;65561.82;7992793
294;2.628373;-0.002778758;71.46203;7.384425;0;0;0;8.27834;7.953495;65583.89;7995733
300;2.629284;-0.003021945;71.40823;7.378866;0;0;0;8.281209;7.956145;65534.52;7989925
306;2.630302;-0.001999457;71.31643;7.36938;0;0;0;8.284416;7.959106;65450.27;7979889
312;2.631373;-0.004313333;71.51242;7.389632;0;0;0;8.287789;7.962221;65630.14;8002069
318;2.632338;-0.003570094;71.27958;7.365571;0;0;0;8.290827;7.965026;65416.45;7976238
324;2.633302;-0.003233616;71.38418;7.37638;0;0;0;8.293865;7.967832;65512.44;7988167
330;2.634373;-0.003779609;71.39126;7.377112;0;0;0;8.297238;7.970947;65518.95;7989208
336;2.635338;-0.00441274;71.47474;7.385738;0;0;0;8.300276;7.973752;65595.56;7998775
342;2.636302;-0.003924956;71.49169;7.387489;0;0;0;8.303312;7.976556;65611.11;8000896
348;2.637373;-0.004069127;71.29509;7.367174;0;0;0;8.306687;7.979671;65430.68;7979142
354;2.638338;-0.00390571;71.42309;7.380401;0;0;0;8.309725;7.982476;65548.16;7993692
360;2.639302;-0.00385534;71.32941;7.37072;0;0;0;8.312761;7.98528;65462.18;7983431
366;2.64032;-0.003834525;71.33628;7.37143;0;0;0;8.315968;7.988239;65468.49;7984436
372;2.641391;-0.004806448;71.23406;7.360868;0;0;0;8.319343;7.991355;65374.67;7973243
378;2.642302;-0.004320153;71.37875;7.375819;0;0;0;8.32221;7.994003;65507.46;7989650
384;2.643373;-0.004914399;71.36342;7.374235;0;0;0;8.325584;7.997118;65493.39;7988183
390;2.644338;-0.004636523;71.26108;7.363659;0;0;0;8.328623;7.999922;65399.47;7976951
396;2.645302;-0.004187193;71.21526;7.358925;0;0;0;8.331659;8.002726;65357.42;7972046
402;2.646373;-0.004650399;71.35352;7.373212;0;0;0;8.335033;8.00584;65484.31;7987772
408;2.647337;-0.00440733;71.27051;7.364634;0;0;0;8.338071;8.008643;65408.12;7978702
414;2.648302;-0.004731853;71.33232;7.371021;0;0;0;8.341108;8.011447;65464.85;7985846
420;2.64932;-0.004561732;71.40195;7.378216;0;0;0;8.344314;8.014406;65528.75;7993878
426;2.650337;-0.004294988;71.20936;7.358315;0;0;0;8.34752;8.017366;65352;7972552
432;2.651355;-0.006216214;71.47078;7.385329;0;0;0;8.350726;8.020324;65591.92;8002058
438;2.652373;-0.005344562;71.37225;7.375148;0;0;0;8.353931;8.023283;65501.5;7991263
444;2.653337;-0.005750303;71.2582;7.363362;0;0;0;8.356968;8.026085;65396.82;7978716
450;2.654302;-0.005060845;71.43851;7.381994;0;0;0;8.360006;8.028889;65562.3;7999129
456;2.655373;-0.005671907;71.46887;7.385131;0;0;0;8.36338;8.032003;65590.17;8002778
462;2.656337;-0.005523933;71.42001;7.380083;0;0;0;8.366417;8.034805;65545.33;7997531
468;2.657302;-0.005656031;71.61444;7.400174;0;0;0;8.369455;8.037608;65723.77;8019528
474;2.658373;-0.00643161;71.32011;7.369759;0;0;0;8.372829;8.040722;65453.64;7986816
480;2.659337;-0.005969304;71.27963;7.365577;0;0;0;8.375866;8.043524;65416.5;7982508
486;2.660302;-0.005743757;71.4181;7.379885;0;0;0;8.378904;8.046328;65543.57;7998238
492;2.661373;-0.006271132;71.32694;7.370466;0;0;0;8.382278;8.04944;65459.92;7988278
498;2.662391;-0.006891366;71.26319;7.363878;0;0;0;8.385484;8.052398;65401.41;7981375
504;2.663302;-0.005756105;71.34386;7.372214;0;0;0;8.388351;8.055044;65475.44;7990621
510;2.66432;-0.006672993;71.26615;7.364184;0;0;0;8.391559;8.058002;65404.13;7982154
516;2.665338;-0.005834619;71.23852;7.361329;0;0;0;8.394764;8.06096;65378.77;7979295
522;2.666302;-0.006141385;71.39816;7.377825;0;0;0;8.3978;8.063761;65525.28;7997400
528;2.667373;-0.006241341;71.05111;7.341963;0;0;0;8.401175;8.066875;65206.77;7958774
534;2.668338;-0.006478608;71.30956;7.368669;0;0;0;8.404213;8.069677;65443.96;7987948
540;2.669302;-0.006261528;71.27702;7.365307;0;0;0;8.407249;8.072478;65414.1;7984527
546;2.67032;-0.006107557;71.39631;7.377634;0;0;0;8.410456;8.075436;65523.58;7998126
552;2.671338;-0.00586194;71.44262;7.382419;0;0;0;8.413662;8.078392;65566.08;8003551
558;2.672409;-0.00708234;71.28258;7.365881;0;0;0;8.417036;8.081505;65419.2;7985870
564;2.673373;-0.006485389;71.25047;7.362564;0;0;0;8.420074;8.084307;65389.73;7982497
570;2.674337;-0.006467045;71.33723;7.371528;0;0;0;8.42311;8.087107;65469.35;7992440
576;2.675302;-0.006228131;71.19714;7.357053;0;0;0;8.426147;8.089909;65340.79;7976969
582;2.676373;-0.006810853;71.21353;7.358746;0;0;0;8.429523;8.093021;65355.83;7979053
588;2.677337;-0.006525685;71.28313;7.365938;0;0;0;8.432558;8.095821;65419.7;7987075
594;2.678302;-0.006399858;71.36533;7.374432;0;0;0;8.435596;8.098623;65495.14;7996509
600;2.679373;-0.007536256;71.28175;7.365796;0;0;0;8.438972;8.101735;65418.44;7987393
606;2.680337;-0.007566714;71.33311;7.371103;0;0;0;8.442007;8.104535;65465.58;7993372
612;2.681302;-0.007020289;71.22489;7.359921;0;0;0;8.445045;8.107336;65366.26;7981469
618;2.682373;-0.007029109;71.00539;7.337238;0;0;0;8.448421;8.110449;65164.81;7957119
624;2.683337;-0.006914023;71.37461;7.375391;0;0;0;8.451456;8.113248;65503.66;7998719
630;2.684302;-0.006384924;71.13104;7.350223;0;0;0;8.454494;8.116049;65280.13;7971647
636;2.685373;-0.007963479;71.1092;7.347965;0;0;0;8.457869;8.11916;65260.08;7969446
642;2.686337;-0.008381215;71.33211;7.371;0;0;0;8.460905;8.12196;65464.66;7994653
648.0001;2.687248;-0.007297108;71.2342;7.360883;0;0;0;8.463775;8.124605;65374.8;7983891
654.0001;2.688373;-0.007183472;71.24069;7.361553;0;0;0;8.467318;8.127872;65380.76;7984879
660.0001;2.689337;-0.007528495;71.4953;7.387863;0;0;0;8.470354;8.130672;65614.43;8013641
666.0001;2.690302;-0.007010333;71.21048;7.358431;0;0;0;8.473392;8.133472;65353.03;7981939
672.0001;2.691373;-0.00705251;71.19265;7.356589;0;0;0;8.476766;8.136583;65336.67;7980190
678.0001;2.692337;-0.006978191;71.16969;7.354216;0;0;0;8.479803;8.139382;65315.59;7977838
684.0001;2.693409;-0.006624386;71.41675;7.379745;0;0;0;8.483178;8.142493;65542.34;8005782
690.0001;2.694373;-0.00680709;71.45654;7.383857;0;0;0;8.486215;8.145293;65578.85;8010467
696.0001;2.695337;-0.006794664;71.37863;7.375807;0;0;0;8.489252;8.148092;65507.35;8001958
702.0001;2.696409;-0.007443592;71.1382;7.350963;0;0;0;8.492626;8.151202;65286.7;7975252
708.0001;2.697373;-0.007289308;71.08943;7.345922;0;0;0;8.495664;8.154002;65241.94;7970007
714.0001;2.698337;-0.007449667;71.38415;7.376377;0;0;0;8.498701;8.156801;65512.42;8003273
720.0001;2.699302;-0.007519323;71.27546;7.365146;0;0;0;8.501738;8.1596;65412.67;7991311
726.0001;2.700373;-0.006825239;71.32072;7.369823;0;0;0;8.505113;8.162711;65454.2;7996634
732.0001;2.701338;-0.007112366;71.27364;7.364958;0;0;0;8.50815;8.16551;65411;7991579
738.0001;2.702302;-0.006381984;71.27479;7.365076;0;0;0;8.511187;8.168308;65412.05;7991931
744.0001;2.703373;-0.007074461;71.19747;7.357087;0;0;0;8.514562;8.171419;65341.09;7983510
750.0001;2.704338;-0.00661882;71.1373;7.350869;0;0;0;8.517598;8.174217;65285.87;7976986
756.0001;2.705302;-0.007551309;71.05774;7.342649;0;0;0;8.520636;8.177016;65212.86;7968289
762.0001;2.706373;-0.006289594;71.27247;7.364836;0;0;0;8.524011;8.180126;65409.92;7992616
768.0001;2.707338;-0.006507262;71.20023;7.357372;0;0;0;8.527047;8.182924;65343.63;7984738
774.0001;2.708302;-0.006742569;71.08021;7.34497;0;0;0;8.530085;8.185722;65233.48;7971502
780.0001;2.709373;-0.00652447;71.0349;7.340287;0;0;0;8.53346;8.188832;65191.89;7966668
786.0001;2.710338;-0.006462145;71.13315;7.350441;0;0;0;8.536496;8.19163;65282.07;7977911
792.0001;2.711302;-0.006276266;71.28134;7.365753;0;0;0;8.539534;8.194428;65418.06;7994754
798.0001;2.71232;-0.007572828;71.28551;7.366184;0;0;0;8.542739;8.197381;65421.89;7995458
804.0001;2.713338;-0.0053642;71.1523;7.352419;0;0;0;8.545945;8.200336;65299.64;7980753
810.0001;2.714302;-0.006275835;71.23485;7.36095;0;0;0;8.548982;8.203133;65375.4;7990236
816.0001;2.715373;-0.006639948;71.16887;7.354131;0;0;0;8.552357;8.206242;65314.84;7983083
822.0001;2.716338;-0.006546617;70.98368;7.334995;0;0;0;8.555394;8.20904;65144.89;7962533
828.0001;2.717302;-0.006410168;71.0679;7.343698;0;0;0;8.558431;8.211838;65222.18;7972203
834.0001;2.718373;-0.006495581;71.15095;7.35228;0;0;0;8.561805;8.214946;65298.4;7981768
840.0001;2.719338;-0.005575126;71.17753;7.355026;0;0;0;8.564843;8.217744;65322.79;7984972
846.0001;2.720302;-0.005736702;71.13562;7.350696;0;0;0;8.567879;8.22054;65284.33;7980494
852.0001;2.72132;-0.005622791;71.2019;7.357544;0;0;0;8.571085;8.223494;65345.16;7988166
858.0001;2.722338;-0.005201253;71.06952;7.343865;0;0;0;8.574292;8.226447;65223.67;7973550
864.0001;2.723302;-0.006399741;71.02987;7.339768;0;0;0;8.577328;8.229243;65187.29;7969324
870.0001;2.724373;-0.005759554;71.03458;7.340254;0;0;0;8.580703;8.232352;65191.6;7970100
876.0001;2.725338;-0.00570989;70.92283;7.328707;0;0;0;8.583741;8.235149;65089.04;7957784
882.0001;2.726302;-0.004625234;71.20492;7.357857;0;0;0;8.586777;8.237945;65347.93;7989660
888.0001;2.727373;-0.005182242;71.10426;7.347455;0;0;0;8.590152;8.241053;65255.55;7978612
894.0001;2.728338;-0.00549477;71.13621;7.350757;0;0;0;8.593189;8.243851;65284.88;7982421
900.0001;2.729302;-0.005993607;71.13809;7.350951;0;0;0;8.596226;8.246647;65286.6;7982855
906.0001;2.730373;-0.005618754;71.08964;7.345944;0;0;0;8.599601;8.249755;65242.13;7977666
912.0001;2.731337;-0.004861756;71.14297;7.351455;0;0;0;8.602637;8.252551;65291.07;7983874
918.0001;2.732302;-0.004671723;70.81982;7.318062;0;0;0;8.605675;8.255347;64994.5;7947831
924.0001;2.733373;-0.00504936;71.05833;7.342709;0;0;0;8.60905;8.258455;65213.4;7974846
930.0001;2.734337;-0.005347698;71.01181;7.337902;0;0;0;8.612086;8.261251;65170.71;7969848
936.0001;2.735302;-0.00440541;71.19709;7.357047;0;0;0;8.615124;8.264047;65340.74;7990866
942.0001;2.73632;-0.004491646;70.8823;7.32452;0;0;0;8.61833;8.266999;65051.85;7955771
948.0001;2.737337;-0.00594214;71.05906;7.342785;0;0;0;8.621535;8.26995;65214.07;7975846
954.0001;2.738302;-0.005371138;70.9677;7.333344;0;0;0;8.624573;8.272747;65130.23;7965814
960.0001;2.739373;-0.005586258;70.98759;7.335399;0;0;0;8.627948;8.275853;65148.48;7968293
966.0001;2.740338;-0.005047948;71.05122;7.341974;0;0;0;8.630984;8.278649;65206.88;7975659
972.0001;2.741302;-0.005247272;71.01954;7.3387;0;0;0;8.634021;8.281444;65177.8;7972325
978.0001;2.742319;-0.004807427;70.92166;7.328586;0;0;0;8.637227;8.284395;65087.97;7961573
984.0001;2.743338;-0.004681483;71.00154;7.33684;0;0;0;8.640433;8.287347;65161.28;7970775
990.0001;2.744355;-0.004475967;70.79004;7.314985;0;0;0;8.643639;8.290297;64967.18;7947266
996.0001;2.745373;-0.005000871;70.98033;7.334649;0;0;0;8.646844;8.293248;65141.82;7968865
1002;2.746338;-0.004375227;71.06873;7.343783;0;0;0;8.649882;8.296044;65222.94;7979012
1008;2.747302;-0.00513587;71.19406;7.356734;0;0;0;8.652919;8.298839;65337.96;7993307
1014;2.748373;-0.00444645;70.95957;7.332504;0;0;0;8.656293;8.301944;65122.76;7967227
1020;2.749338;-0.004960457;70.93431;7.329894;0;0;0;8.659331;8.30474;65099.58;7964614
1026;2.750302;-0.003212096;70.81174;7.317228;0;0;0;8.662368;8.307535;64987.09;7951073
1032;2.751373;-0.004621275;70.91346;7.327739;0;0;0;8.665742;8.31064;65080.45;7962742
1038;2.752338;-0.004023853;70.9181;7.328218;0;0;0;8.66878;8.313436;65084.7;7963486
1044;2.753302;-0.004361233;70.76886;7.312797;0;0;0;8.671817;8.31623;64947.74;7946949
1050;2.754373;-0.003922055;70.93452;7.329916;0;0;0;8.675191;8.319335;65099.78;7965800
1056;2.755338;-0.003644414;70.93913;7.330392;0;0;0;8.678228;8.32213;65104.01;7966540
1062;2.756302;-0.004165516;70.91587;7.327988;0;0;0;8.681266;8.324924;65082.66;7964150
1068;2.757373;-0.002611303;70.73174;7.308961;0;0;0;8.68464;8.328029;64913.68;7943719
1074;2.758338;-0.003417573;70.91179;7.327567;0;0;0;8.687677;8.330824;65078.92;7964162
1080;2.759302;-0.003421258;70.95211;7.331733;0;0;0;8.690715;8.333618;65115.92;7968913
1086;2.76032;-0.002685623;70.87799;7.324073;0;0;0;8.69392;8.336567;65047.89;7960822
1092;2.761337;-0.002951074;70.85013;7.321194;0;0;0;8.697125;8.339516;65022.32;7957928
1098;2.762302;-0.001456325;70.88971;7.325284;0;0;0;8.700164;8.342311;65058.65;7962596
1104;2.76332;-0.002107605;70.92183;7.328604;0;0;0;8.703369;8.34526;65088.13;7966439
1110;2.764391;-0.001080178;70.97534;7.334134;0;0;0;8.706743;8.348364;65137.24;7972698
1116;2.765302;-0.002320569;70.88149;7.324435;0;0;0;8.709612;8.351003;65051.1;7962365
1122;2.766373;-0.00206041;70.81327;7.317385;0;0;0;8.712987;8.354107;64988.49;7954948
1128;2.767337;-0.001324031;70.84272;7.320429;0;0;0;8.716023;8.356901;65015.52;7958479
1134;2.768302;-0.0006551119;70.7131;7.307035;0;0;0;8.719061;8.359695;64896.57;7944140
1140;2.769373;-0.001945834;70.86777;7.323018;0;0;0;8.722435;8.362798;65038.51;7961763
1146;2.770337;-0.001596969;70.74223;7.310045;0;0;0;8.725472;8.365592;64923.3;7947881
1152;2.771302;-0.001572666;70.72055;7.307805;0;0;0;8.72851;8.368386;64903.41;7945668
1158;2.772319;-0.001009151;70.64861;7.300371;0;0;0;8.731714;8.371332;64837.38;7937818
1164;2.773337;-0.001540837;70.75025;7.310874;0;0;0;8.734921;8.374282;64930.66;7949473
1170;2.774409;-0.001354998;70.69014;7.304662;0;0;0;8.738297;8.377386;64875.49;7942965
1176;2.775373;-0.002035519;70.56506;7.291738;0;0;0;8.741332;8.380178;64760.71;7929133
1182;2.776337;-0.001455777;70.70573;7.306273;0;0;0;8.74437;8.382971;64889.8;7945160
1188;2.777356;-0.0009173878;70.74414;7.310242;0;0;0;8.747577;8.38592;64925.05;7949711
1194;2.778373;-0.0008551801;70.66068;7.301618;0;0;0;8.750781;8.388867;64848.46;7940567
1200;2.779338;-0.0004048701;70.68714;7.304352;0;0;0;8.753819;8.39166;64872.74;7943762
1206;2.780302;-0.0004561414;70.56471;7.291701;0;0;0;8.756856;8.394452;64760.38;7930225
1212;2.781373;-0.0006395894;70.66873;7.30245;0;0;0;8.76023;8.397555;64855.84;7942161
1218;2.782338;-0.0009816731;70.73404;7.309198;0;0;0;8.763268;8.400348;64915.78;7949723
1224;2.783302;-0.0001448285;70.31818;7.266227;0;0;0;8.766305;8.40314;64534.13;7903206
1230;2.784373;-0.001107696;70.64018;7.2995;0;0;0;8.769679;8.406242;64829.64;7939642
1236;2.785338;-0.0005375563;70.67519;7.303117;0;0;0;8.772717;8.409035;64861.77;7943799
1242;2.786302;-0.001135252;70.68916;7.304562;0;0;0;8.775754;8.411827;64874.6;7945592
1248;2.78732;-0.0002040571;70.69058;7.304708;0;0;0;8.778959;8.414774;64875.89;7945985
1254;2.788391;-0.0003494436;70.54404;7.289565;0;0;0;8.782334;8.417877;64741.41;7929759
1260;2.789302;-0.001341435;70.70661;7.306364;0;0;0;8.785203;8.420514;64890.61;7948243
1266;2.790373;-0.0002045667;70.51252;7.286309;0;0;0;8.788577;8.423615;64712.49;7926671
1272;2.791391;-0.0003579496;70.61213;7.296602;0;0;0;8.791782;8.426561;64803.91;7938103
1278;2.792302;-0.0002533686;70.69066;7.304716;0;0;0;8.794651;8.429199;64875.97;7947140
1284;2.79332;-0.0003549705;70.84537;7.320703;0;0;0;8.797857;8.432145;65017.95;7964768
1290;2.794391;-0.0005862013;70.84072;7.320223;0;0;0;8.801231;8.435246;65013.69;7964492
1296;2.795302;-0.0005975689;70.81118;7.31717;0;0;0;8.8041;8.437883;64986.58;7961381
1302;2.796373;-0.0001744232;70.66494;7.302059;0;0;0;8.807474;8.440985;64852.37;7945185
1308;2.797337;-0.0001681515;70.59792;7.295133;0;0;0;8.810512;8.443776;64790.86;7937872
1314;2.798302;-0.0006697721;70.67214;7.302802;0;0;0;8.813549;8.446567;64858.97;7946438
1320;2.799373;-0.0007934036;70.7165;7.307387;0;0;0;8.816923;8.449668;64899.69;7951673
1326;2.800337;-0.0005915716;70.94612;7.331114;0;0;0;8.819961;8.452459;65110.42;7977715
1332;2.801302;-0.0003215736;70.82625;7.318727;0;0;0;8.822998;8.455251;65000.41;7964458
1338;2.802373;-0.0004034197;70.53337;7.288463;0;0;0;8.826372;8.458351;64731.62;7931770
1344;2.803337;-0.0003745698;70.57792;7.293067;0;0;0;8.82941;8.461142;64772.51;7937001
1350;2.804355;0.0001237975;70.81218;7.317274;0;0;0;8.832616;8.464088;64987.5;7963580
1356;2.805373;-0.0004363463;70.94853;7.331363;0;0;0;8.835821;8.467033;65112.63;7979149
1362;2.806337;-0.0005630744;71.01169;7.33789;0;0;0;8.838858;8.469824;65170.6;7986475
1368;2.807302;-0.0003860549;71.021;7.338852;0;0;0;8.841895;8.472614;65179.14;7987745
1374;2.808373;-0.0006919976;70.89338;7.325664;0;0;0;8.84527;8.475715;65062.01;7973638
1380;2.809337;-0.004002373;71.07442;7.344372;0;0;0;8.848307;8.478505;65228.17;7994224
1386;2.810302;-0.002770605;71.01922;7.338667;0;0;0;8.851344;8.481295;65177.5;7988238
1392;2.811373;-0.003852831;70.91217;7.327606;0;0;0;8.854719;8.484395;65079.26;7976445
1398;2.812337;-0.003915392;70.98656;7.335293;0;0;0;8.857756;8.487185;65147.53;7985035
1404;2.813302;-0.00195187;71.11457;7.34852;0;0;0;8.860793;8.489975;65265.01;7999657
1410;2.81432;-0.003311699;71.15321;7.352514;0;0;0;8.863999;8.49292;65300.48;8004240
1416;2.815338;-0.003721046;71.24113;7.361598;0;0;0;8.867205;8.495865;65381.16;8014367
1422;2.816302;-0.002336602;71.28254;7.365877;0;0;0;8.870241;8.498654;65419.16;8019248
1428;2.81732;-0.001920943;71.40524;7.378556;0;0;0;8.873448;8.501599;65531.77;8033288
1434;2.818337;-0.003184383;71.22619;7.360054;0;0;0;8.876653;8.504543;65367.45;8013380
1440;2.819302;-0.002902194;71.24331;7.361823;0;0;0;8.87969;8.507333;65383.16;8015530
1446;2.820373;-0.002529105;71.22798;7.36024;0;0;0;8.883065;8.510433;65369.09;8014054
1452;2.821337;-0.002703654;71.2715;7.364737;0;0;0;8.886102;8.513221;65409.04;8019175
1458;2.822302;-0.003235105;71.24454;7.361951;0;0;0;8.889139;8.516011;65384.29;8016365
1464;2.82332;-0.003278262;71.14346;7.351506;0;0;0;8.892345;8.518956;65291.53;8005227
1470;2.824337;-0.002278078;71.31716;7.369455;0;0;0;8.895551;8.521898;65450.94;8025009
1476;2.825355;-0.003412399;71.13536;7.350669;0;0;0;8.898757;8.524843;65284.09;8004787
1482;2.82632;-0.002578377;71.38779;7.376753;0;0;0;8.901793;8.527632;65515.76;8033416
1488;2.827284;-0.003663503;71.28994;7.366642;0;0;0;8.904831;8.53042;65425.96;8022629
1494;2.828355;-0.002074914;71.24052;7.361535;0;0;0;8.908206;8.533519;65380.6;8017316
1500;2.829373;-0.002487907;71.23418;7.36088;0;0;0;8.911411;8.536463;65374.78;8016838
1506;2.830337;-0.002813723;71.37769;7.375709;0;0;0;8.914449;8.539252;65506.49;8033213
1512;2.831302;-0.003178542;71.46206;7.384428;0;0;0;8.917486;8.54204;65583.92;8042933
1518;2.832373;-0.002750967;71.43419;7.381548;0;0;0;8.92086;8.545138;65558.34;8040045
1524;2.833337;-0.00324075;71.26842;7.364418;0;0;0;8.923897;8.547926;65406.2;8021611
1530;2.834302;-0.00266281;71.41393;7.379454;0;0;0;8.926935;8.550715;65539.74;8038213
1536;2.835373;-0.003286572;71.28939;7.366585;0;0;0;8.930309;8.553813;65425.45;8024443
1542;2.836337;-0.002407982;71.40571;7.378604;0;0;0;8.933346;8.556601;65532.2;8037761
1548;2.837302;-0.003393741;71.557;7.394238;0;0;0;8.936383;8.559388;65671.05;8055015
1554;2.838373;-0.002707653;71.52998;7.391446;0;0;0;8.939758;8.562487;65646.25;8052224
1560;2.839337;-0.002231824;71.58731;7.39737;0;0;0;8.942795;8.565274;65698.87;8058901
1566;2.840302;-0.002796319;71.48867;7.387177;0;0;0;8.945832;8.568062;65608.34;8048021
1572;2.841373;-0.002411313;71.47945;7.386224;0;0;0;8.949207;8.57116;65599.88;8047233
1578;2.842337;-0.003118764;71.54179;7.392667;0;0;0;8.952244;8.573947;65657.09;8054476
1584;2.843302;-0.002659008;71.70486;7.409517;0;0;0;8.95528;8.576734;65806.75;8073060
1590;2.84432;-0.004640011;71.64187;7.403008;0;0;0;8.958488;8.579677;65748.94;8066206
1596;2.845391;-0.002792282;71.54957;7.393471;0;0;0;8.961862;8.582774;65664.23;8056063
1602;2.846302;-0.003126448;71.81457;7.420854;0;0;0;8.964729;8.585406;65907.44;8086114
1608;2.847373;-0.002859938;71.63697;7.402502;0;0;0;8.968104;8.588504;65744.44;8066366
1614;2.848337;-0.003009362;71.60569;7.39927;0;0;0;8.971142;8.591291;65715.73;8063068
1620;2.849409;-0.002904232;71.66948;7.405861;0;0;0;8.974516;8.594387;65774.27;8070501
1626;2.850373;-0.002249856;71.90949;7.430662;0;0;0;8.977553;8.597174;65994.54;8097753
1632;2.851337;-0.00274395;71.68466;7.407429;0;0;0;8.980591;8.599961;65788.2;8072660
1638;2.852302;-0.002524009;71.77334;7.416594;0;0;0;8.983627;8.602748;65869.59;8082873
1644;2.853373;-0.002960325;71.70924;7.409969;0;0;0;8.987002;8.605845;65810.77;8075903
1650;2.854284;-0.003000307;71.70562;7.409596;0;0;0;8.989871;8.608476;65807.45;8075709
1656;2.855302;-0.002638468;71.70956;7.410003;0;0;0;8.993076;8.611417;65811.06;8076390
1662;2.856373;-0.002953975;72.05197;7.445385;0;0;0;8.996451;8.614514;66125.3;8115206
1668;2.857338;-0.003136365;71.79085;7.418402;0;0;0;8.999488;8.6173;65885.66;8086021
1674;2.858302;-0.003110454;71.67482;7.406413;0;0;0;9.002525;8.620086;65779.18;8073177
1680;2.859373;-0.003048835;71.74468;7.413632;0;0;0;9.005899;8.623182;65843.3;8081296
1686;2.860338;-0.003199983;72.02587;7.442688;0;0;0;9.008937;8.625969;66101.35;8113195
1692;2.861302;-0.003087876;71.91034;7.43075;0;0;0;9.011974;8.628754;65995.32;8100407
1698;2.862373;-0.002506448;71.93597;7.433399;0;0;0;9.015348;8.63185;66018.85;8103545
1704;2.863338;-0.002671982;71.93328;7.43312;0;0;0;9.018386;8.634636;66016.38;8103468
1710;2.864301;-0.003257095;71.99295;7.439286;0;0;0;9.021422;8.637421;66071.14;8110416
1716;2.86532;-0.002638625;72.04648;7.444818;0;0;0;9.024629;8.640362;66120.27;8116685
1722;2.866338;-0.002731211;71.86913;7.426492;0;0;0;9.027835;8.643303;65957.51;8096943
1728;2.867302;-0.00308133;71.84699;7.424204;0;0;0;9.030871;8.646088;65937.19;8094674
1734;2.868373;-0.003366576;71.89181;7.428835;0;0;0;9.034246;8.649183;65978.32;8099974
1740;2.869338;-0.003195084;71.94922;7.434768;0;0;0;9.037284;8.651969;66031.01;8106669
1746;2.870302;-0.002812782;72.00505;7.440536;0;0;0;9.040319;8.654753;66082.24;8113185
1752;2.871373;-0.003218759;71.93682;7.433487;0;0;0;9.043694;8.657849;66019.63;8105749
1758;2.872338;-0.002993565;72.04836;7.445012;0;0;0;9.046733;8.660635;66121.99;8118542
1764;2.873302;-0.002989449;72.07891;7.448168;0;0;0;9.049768;8.663419;66150.02;8122210
1770;2.874373;-0.002797142;72.03206;7.443328;0;0;0;9.053144;8.666514;66107.04;8117183
1776;2.875337;-0.003487738;71.80285;7.419643;0;0;0;9.056181;8.669298;65896.68;8091579
1782;2.876355;-0.003059379;72.06369;7.446597;0;0;0;9.059386;8.672238;66136.06;8121212
1788;2.87732;-0.002983687;71.96745;7.436652;0;0;0;9.062424;8.675023;66047.74;8110593
1794;2.878337;-0.003305701;71.92667;7.432437;0;0;0;9.06563;8.677962;66010.31;8106235
1800;2.879409;-0.003120215;71.88688;7.428325;0;0;0;9.069004;8.681056;65973.79;8102000
1806;2.880373;-0.003148908;72.00334;7.44036;0;0;0;9.072042;8.683841;66080.68;8115353
1812;2.881337;-0.003566683;72.08398;7.448693;0;0;0;9.075079;8.686626;66154.69;8124668
1818;2.882302;-0.003262544;72.08304;7.448596;0;0;0;9.078115;8.689409;66153.82;8124788
1824;2.883373;-0.003395191;72.01151;7.441204;0;0;0;9.081491;8.692504;66088.17;8116976
1830;2.884337;-0.003478566;72.06311;7.446536;0;0;0;9.084527;8.695288;66135.52;8123018
1836;2.885302;-0.003160903;72.07256;7.447512;0;0;0;9.087564;8.698072;66144.2;8124310
1842;2.886319;-0.002835518;71.86776;7.42635;0;0;0;9.09077;8.70101;65956.25;8101462
1848;2.887391;-0.003568957;71.72735;7.411841;0;0;0;9.094145;8.704104;65827.39;8085885
1854;2.888302;-0.003054832;71.94646;7.434482;0;0;0;9.097013;8.706733;66028.47;8110798
1860;2.889319;-0.003278106;72.27675;7.468612;0;0;0;9.100219;8.709671;66331.59;8148272
1866;2.890337;-0.003076979;71.90297;7.429988;0;0;0;9.103425;8.71261;65988.56;8106372
1872;2.891302;-0.002981375;72.00354;7.440381;0;0;0;9.106462;8.715394;66080.87;8117937
1878;2.892373;-0.0037194;72.10448;7.450811;0;0;0;9.109837;8.718486;66173.49;8129568
1884;2.893338;-0.003463592;72.12492;7.452923;0;0;0;9.112874;8.72127;66192.26;8132099
1890;2.894302;-0.003452773;72.09432;7.449761;0;0;0;9.115911;8.724053;66164.17;8128875
1896;2.895319;-0.003242866;72.02792;7.4429;0;0;0;9.119117;8.726991;66103.23;8121627
1902;2.896391;-0.002952015;72.14451;7.454947;0;0;0;9.122492;8.730084;66210.23;8135024
1908;2.897355;-0.002925987;72.33037;7.474153;0;0;0;9.125528;8.732867;66380.8;8156209
1914;2.898373;-0.003756482;72.20644;7.461347;0;0;0;9.128734;8.735805;66267.07;8142474
1920;2.899338;-0.003046836;72.319;7.472979;0;0;0;9.131772;8.738588;66370.38;8155394
1926;2.900409;-0.003242788;72.07676;7.447947;0;0;0;9.135146;8.74168;66148.05;8128328
1932;2.901373;-0.003566605;72.19404;7.460066;0;0;0;9.138183;8.744463;66255.7;8141781
1938;2.902338;-0.003161687;72.0572;7.445926;0;0;0;9.141221;8.747246;66130.11;8126574
1944;2.903302;-0.003693216;72.29909;7.470921;0;0;0;9.144258;8.750029;66352.1;8154081
1950;2.904373;-0.003249491;72.35674;7.476878;0;0;0;9.147632;8.75312;66405.01;8160835
1956;2.905337;-0.003300527;72.62095;7.504179;0;0;0;9.150669;8.755902;66647.48;8190862
1962;2.906355;-0.003503966;72.35565;7.476765;0;0;0;9.153875;8.75884;66404.01;8161179
1968;2.907373;-0.003572328;72.34669;7.47584;0;0;0;9.157081;8.761777;66395.79;8160409
1974;2.908337;-0.003595181;72.43597;7.485065;0;0;0;9.160117;8.764559;66477.72;8170706
1980;2.909302;-0.003467002;72.55343;7.497203;0;0;0;9.163156;8.767342;66585.52;8184183
1986;2.910373;-0.003485073;72.33213;7.474335;0;0;0;9.16653;8.770432;66382.42;8159472
1992;2.911337;-0.003103281;72.64749;7.506922;0;0;0;9.169566;8.773214;66671.84;8195275
1998;2.912302;-0.00342557;72.38425;7.479721;0;0;0;9.172605;8.775997;66430.26;8165806
2004;2.913373;-0.004056074;72.58106;7.500058;0;0;0;9.175979;8.779088;66610.88;8188262
2010;2.914337;-0.00318842;72.45271;7.486795;0;0;0;9.179015;8.781869;66493.09;8174009
2016;2.915302;-0.003767575;72.51969;7.493716;0;0;0;9.182054;8.784652;66554.55;8181793
2022;2.916319;-0.003059928;72.48659;7.490296;0;0;0;9.185258;8.787587;66524.18;8178299
2028;2.917391;-0.003177836;72.41767;7.483175;0;0;0;9.188633;8.790678;66460.93;8170776
2034;2.918302;-0.003727553;72.52633;7.494402;0;0;0;9.191502;8.793305;66560.65;8183251
2040;2.919266;-0.004120281;72.36156;7.477376;0;0;0;9.194538;8.796086;66409.43;8164886
2046;2.920337;-0.003311738;72.6627;7.508494;0;0;0;9.197913;8.799177;66685.8;8199119
2052;2.921302;-0.003254469;72.40678;7.482049;0;0;0;9.20095;8.801958;66450.93;8170468
2058;2.922373;-0.003514746;72.30931;7.471977;0;0;0;9.204325;8.805048;66361.48;8159722
2064;2.923337;-0.002538238;72.53925;7.495738;0;0;0;9.207362;8.807829;66572.51;8185898
2070;2.924355;-0.003487816;72.36828;7.47807;0;0;0;9.210567;8.810765;66415.59;8166843
2076;2.925319;-0.003748564;72.30916;7.471962;0;0;0;9.213605;8.813545;66361.34;8160399
2082;2.926337;-0.003431606;72.48251;7.489875;0;0;0;9.216811;8.816481;66520.44;8180202
2088;2.927355;-0.00372379;72.45145;7.486664;0;0;0;9.220016;8.819416;66491.92;8176936
2094;2.928373;-0.003575778;72.57396;7.499324;0;0;0;9.223222;8.822351;66604.36;8191004
2100;2.929337;-0.003519763;72.57184;7.499105;0;0;0;9.22626;8.825132;66602.42;8190993
2106;2.930302;-0.002979297;72.62964;7.505078;0;0;0;9.229297;8.827913;66655.46;8197743
2112;2.931319;-0.003756011;72.39448;7.480778;0;0;0;9.232502;8.830847;66439.64;8171441
2118;2.932337;-0.003422826;72.29269;7.47026;0;0;0;9.235708;8.833782;66346.23;8160191
2124;2.933302;-0.003743115;72.47094;7.488679;0;0;0;9.238746;8.836563;66509.81;8180539
2130;2.934373;-0.003274264;72.38775;7.480083;0;0;0;9.24212;8.839652;66433.47;8171401
2136;2.935284;-0.003339843;72.41809;7.483217;0;0;0;9.244988;8.842277;66461.3;8175040
2142;2.936302;-0.003520273;72.61971;7.504052;0;0;0;9.248195;8.845212;66646.35;8198041
2148;2.937373;-0.00312386;72.54107;7.495925;0;0;0;9.251569;8.848301;66574.17;8189416
2154;2.938391;-0.00256356;72.36096;7.477314;0;0;0;9.254774;8.851235;66408.88;8169323
2160;2.939302;-0.003858123;72.3415;7.475303;0;0;0;9.257644;8.853861;66391.02;8167340
2166;2.94032;-0.002728349;72.34026;7.475175;0;0;0;9.260849;8.856795;66389.88;8167440
2172;2.941337;-0.002850883;72.45353;7.486879;0;0;0;9.264054;8.859728;66493.84;8180468
2178;2.942302;-0.003630538;72.43588;7.485056;0;0;0;9.267093;8.862509;66477.64;8178703
2184;2.943373;-0.003335139;72.43808;7.485283;0;0;0;9.270466;8.865596;66479.66;8179204
2190;2.944337;-0.003418514;72.52609;7.494378;0;0;0;9.273503;8.868376;66560.43;8189369
2196;2.945302;-0.002695736;72.31886;7.472964;0;0;0;9.276541;8.871156;66370.24;8166196
2202;2.946319;-0.00357323;72.38875;7.480186;0;0;0;9.279746;8.874088;66434.38;8174328
2208;2.947391;-0.003229813;72.32987;7.474101;0;0;0;9.283121;8.877177;66380.34;8167931
2214;2.948355;-0.002992664;72.52336;7.494096;0;0;0;9.286159;8.879957;66557.92;8190009
2220;2.949319;-0.003132602;72.48971;7.490618;0;0;0;9.289195;8.882735;66527.04;8186436
2226;2.950337;-0.003721713;72.49969;7.49165;0;0;0;9.292401;8.885668;66536.2;8187804
2232;2.951355;-0.003441798;72.53614;7.495416;0;0;0;9.295608;8.888602;66569.65;8192160
2238;2.952373;-0.003608077;72.51085;7.492803;0;0;0;9.298812;8.891534;66546.45;8189545
2244;2.953337;-0.003378414;72.63041;7.505157;0;0;0;9.30185;8.894314;66656.16;8203275
2250;2.954302;-0.003207784;72.53126;7.494912;0;0;0;9.304887;8.897092;66565.17;8192305
2256;2.955319;-0.004411603;72.54401;7.496229;0;0;0;9.308092;8.900025;66576.88;8193985
2262;2.956337;-0.0031718;72.589;7.500878;0;0;0;9.311299;8.902958;66618.16;8199308
2268;2.957302;-0.003394917;72.84149;7.526969;0;0;0;9.314336;8.905736;66849.88;8228056
2274;2.958373;-0.003324634;72.69072;7.51139;0;0;0;9.31771;8.908823;66711.52;8211279
2280;2.959337;-0.003418671;72.82625;7.525394;0;0;0;9.320747;8.911602;66835.9;8226817
2286;2.960302;-0.002776485;72.92662;7.535766;0;0;0;9.323785;8.914379;66928.02;8238385
2292;2.961373;-0.003573151;72.71096;7.513481;0;0;0;9.327159;8.917466;66730.09;8214275
2298;2.962337;-0.002943901;72.52941;7.494721;0;0;0;9.330195;8.920244;66563.48;8193993
2304;2.963302;-0.002841201;72.87837;7.53078;0;0;0;9.333234;8.923022;66883.73;8233645
2310;2.964319;-0.003650881;72.80443;7.523139;0;0;0;9.336439;8.925954;66815.87;8225533
2316;2.965337;-0.003291668;72.76987;7.519568;0;0;0;9.339644;8.928886;66784.15;8221869
2322;2.966302;-0.003583343;72.93992;7.53714;0;0;0;9.342683;8.931664;66940.22;8241311
2328;2.967319;-0.003587028;72.81791;7.524532;0;0;0;9.345888;8.934596;66828.24;8227767
2334;2.968391;-0.003689609;72.79597;7.522265;0;0;0;9.349262;8.937681;66808.11;8225542
2340;2.969302;-0.003339765;72.83268;7.526058;0;0;0;9.352132;8.940306;66841.8;8229905
2346;2.970319;-0.003643316;72.80261;7.522951;0;0;0;9.355337;8.943237;66814.2;8226748
2352;2.971391;-0.003563783;72.98897;7.542209;0;0;0;9.358711;8.946322;66985.23;8248062
2358;2.972409;-0.003277086;72.75935;7.518481;0;0;0;9.361917;8.949254;66774.5;8222355
2364;2.973373;-0.002945116;72.98788;7.542096;0;0;0;9.364955;8.952032;66984.23;8248410
2370;2.974337;-0.002956954;72.73968;7.516448;0;0;0;9.367991;8.954808;66756.45;8220589
2376;2.975302;-0.003185598;72.91402;7.534464;0;0;0;9.371029;8.957585;66916.45;8240521
2382;2.97632;-0.003402208;72.6924;7.511563;0;0;0;9.374235;8.960516;66713.05;8215714
2388;2.977337;-0.003235654;72.95637;7.53884;0;0;0;9.37744;8.963447;66955.31;8245790
2394;2.978409;-0.003952748;73.10288;7.553979;0;0;0;9.380816;8.966533;67089.77;8262604
2400;2.979373;-0.002976357;72.81013;7.523728;0;0;0;9.383852;8.969309;66821.1;8229744
2406;2.980337;-0.003388527;72.86398;7.529293;0;0;0;9.386889;8.972085;66870.52;8236060
2412;2.981302;-0.002995016;73.01352;7.544745;0;0;0;9.389926;8.974862;67007.76;8253191
2418;2.982373;-0.003151534;72.99558;7.542892;0;0;0;9.393301;8.977947;66991.3;8251418
2424;2.983337;-0.003643238;72.54275;7.496099;0;0;0;9.396338;8.980723;66575.71;8200457
2430;2.984302;-0.003188146;72.91379;7.53444;0;0;0;9.399375;8.983499;66916.23;8242630
2436;2.985373;-0.003250824;72.7452;7.517019;0;0;0;9.40275;8.986584;66761.51;8223825
2442;2.986337;-0.002923243;72.78499;7.521131;0;0;0;9.405787;8.98936;66798.03;8228552
2448;2.987302;-0.003231852;72.86801;7.529709;0;0;0;9.408824;8.992136;66874.22;8238166
2454;2.988373;-0.002956366;72.76314;7.518873;0;0;0;9.412199;8.995221;66777.98;8226564
2460;2.989391;-0.003371358;72.85538;7.528404;0;0;0;9.415404;8.99815;66862.63;8237234
2466;2.990302;-0.002551996;72.83374;7.526168;0;0;0;9.418273;9.000772;66842.77;8235003
2472;2.99132;-0.00307447;72.78308;7.520934;0;0;0;9.421479;9.003702;66796.28;8229517
2478;2.992337;-0.002948722;72.82308;7.525066;0;0;0;9.424684;9.006631;66832.98;8234280
2484;2.993302;-0.003359403;72.66546;7.50878;0;0;0;9.427722;9.009407;66688.34;8216686
2490;2.994373;-0.003028138;72.89614;7.532616;0;0;0;9.431097;9.012491;66900.04;8243025
2496;2.995337;-0.003653782;72.75553;7.518087;0;0;0;9.434133;9.015265;66771;8227353
2502;2.996302;-0.003137815;72.8683;7.529739;0;0;0;9.43717;9.018041;66874.48;8240334
2508;2.99732;-0.003495225;72.75771;7.518312;0;0;0;9.440377;9.020971;66772.99;8228068
2514;2.998391;-0.003054127;72.80073;7.522757;0;0;0;9.44375;9.024053;66812.48;8233187
2520;2.999355;-0.003043661;72.98383;7.541677;0;0;0;9.446788;9.026829;66980.52;8254124
2526;3.000319;-0.003146125;72.94826;7.538002;0;0;0;9.449825;9.029604;66947.88;8250330
2532;3.001337;-0.003139892;72.95405;7.5386;0;0;0;9.453031;9.032533;66953.19;8251227
2538;3.002409;-0.003282888;72.95305;7.538497;0;0;0;9.456406;9.035616;66952.27;8251368
2544;3.003373;-0.002565324;72.89726;7.532732;0;0;0;9.459442;9.038391;66901.06;8245286
2550;3.004337;-0.003199043;72.82669;7.52544;0;0;0;9.46248;9.041165;66836.3;8237533
2556;3.005302;-0.00246525;73.0677;7.550344;0;0;0;9.465517;9.04394;67057.48;8265023
2562;3.006373;-0.003465434;72.85964;7.528844;0;0;0;9.468891;9.047023;66866.54;8241742
2568;3.007337;-0.002705575;73.16948;7.560862;0;0;0;9.471929;9.049797;67150.9;8277021
2574;3.008301;-0.00244036;72.82881;7.525658;0;0;0;9.474965;9.052571;66838.24;8238712
2580;3.009373;-0.00363187;72.84913;7.527758;0;0;0;9.47834;9.055654;66856.89;8241265
2586;3.010337;-0.003357796;73.05375;7.548903;0;0;0;9.481378;9.058429;67044.68;8264642
2592;3.011301;-0.003589889;73.05489;7.549021;0;0;0;9.484414;9.061202;67045.73;8265001
2598;3.012373;-0.003106025;72.89423;7.532419;0;0;0;9.487789;9.064284;66898.29;8247079
2604;3.013337;-0.003007677;73.08732;7.552372;0;0;0;9.490826;9.067058;67075.49;8269154
2610;3.014301;-0.003207;72.99484;7.542815;0;0;0;9.493863;9.069832;66990.62;8258919
2616;3.015373;-0.003488483;73.43204;7.587993;0;0;0;9.497238;9.072914;67391.86;8308643
2622;3.016337;-0.00317815;73.18898;7.562877;0;0;0;9.500275;9.075687;67168.8;8281371
2628;3.017301;-0.002703811;73.05586;7.549121;0;0;0;9.503312;9.078461;67046.63;8266538
2634;3.01832;-0.0028051;73.18713;7.562685;0;0;0;9.506518;9.081389;67167.09;8281634
2640;3.019391;-0.002741991;73.11868;7.555612;0;0;0;9.509892;9.08447;67104.27;8274143
2646;3.020302;-0.003330161;73.10667;7.55437;0;0;0;9.512761;9.087089;67093.25;8273000
2652;3.02132;-0.003058438;73.16285;7.560176;0;0;0;9.515967;9.090017;67144.8;8279600
2658;3.022337;-0.002942647;73.22719;7.566825;0;0;0;9.519173;9.092944;67203.86;8287124
2664;3.023302;-0.002918344;73.13227;7.557017;0;0;0;9.522209;9.095717;67116.75;8276612
2670;3.024373;-0.002876127;73.29135;7.573455;0;0;0;9.525585;9.098799;67262.74;8294871
2676;3.025337;-0.002472032;73.40902;7.585614;0;0;0;9.528622;9.101571;67370.73;8308419
2682;3.026302;-0.003080115;73.14663;7.558501;0;0;0;9.531658;9.104344;67129.93;8278951
2688;3.027319;-0.003038094;73.28116;7.572402;0;0;0;9.534864;9.107271;67253.39;8294420
2694;3.028337;-0.003094266;73.27253;7.57151;0;0;0;9.538071;9.110198;67245.47;8293686
2700;3.029409;-0.003028334;73.25095;7.56928;0;0;0;9.541445;9.113278;67225.66;8291498
2706;3.030373;-0.00283246;73.17973;7.56192;0;0;0;9.544481;9.116051;67160.3;8283666
2712;3.031337;-0.002934023;73.19867;7.563878;0;0;0;9.54752;9.118824;67177.69;8286041
2718;3.032355;-0.00281827;73.29761;7.574101;0;0;0;9.550725;9.12175;67268.48;8297483
2724;3.033373;-0.003350819;73.31291;7.575683;0;0;0;9.55393;9.124676;67282.52;8299458
2730;3.034337;-0.002396575;73.12534;7.556301;0;0;0;9.556969;9.127449;67110.39;8278454
2736;3.035301;-0.003170271;73.26683;7.570921;0;0;0;9.560004;9.13022;67240.23;8294701
2742;3.036373;-0.002983452;73.05997;7.549546;0;0;0;9.563379;9.1333;67050.39;8271537
2748;3.037337;-0.002270396;73.26645;7.570882;0;0;0;9.566417;9.136073;67239.89;8295144
2754;3.038301;-0.003064475;73.13785;7.557593;0;0;0;9.569453;9.138844;67121.87;8280814
2760;3.039373;-0.002635567;73.27553;7.57182;0;0;0;9.572828;9.141924;67248.22;8296657
2766;3.040337;-0.002610872;73.1341;7.557205;0;0;0;9.575866;9.144696;67118.42;8280873
2772;3.041301;-0.003074627;72.98192;7.541481;0;0;0;9.578902;9.147467;66978.77;8263871
2778;3.042319;-0.002960874;73.26181;7.570402;0;0;0;9.582108;9.150393;67235.63;8295806
2784;3.043391;-0.002905134;73.37775;7.582383;0;0;0;9.585484;9.153473;67342.03;8309191
2790;3.044301;-0.003031117;73.24866;7.569043;0;0;0;9.588351;9.15609;67223.55;8294789
2796;3.045373;-0.003005717;73.32683;7.577121;0;0;0;9.591726;9.159169;67295.3;8303898
2802;3.046338;-0.002520167;73.54276;7.599434;0;0;0;9.594764;9.161941;67493.47;8328582
2808;3.047301;-0.002976083;73.15066;7.558917;0;0;0;9.5978;9.164712;67133.62;8284406
2814;3.048319;-0.002295326;73.27244;7.5715;0;0;0;9.601007;9.167637;67245.38;8298441
2820;3.049337;-0.002973731;73.19859;7.563869;0;0;0;9.604212;9.170562;67177.61;8290319
2826;3.050409;-0.002856763;72.94974;7.538155;0;0;0;9.607586;9.17364;66949.23;8262389
2832;3.051373;-0.002264398;73.26381;7.570609;0;0;0;9.610623;9.176412;67237.46;8298191
2838;3.052337;-0.003029432;73.16484;7.560382;0;0;0;9.613661;9.179182;67146.64;8287212
2844;3.053301;-0.003292766;72.97884;7.541162;0;0;0;9.616697;9.181953;66975.93;8266372
2850;3.054373;-0.002012079;73.20642;7.564679;0;0;0;9.620072;9.185032;67184.8;8292407
2856;3.055337;-0.00252005;73.28357;7.572651;0;0;0;9.62311;9.187802;67255.6;8301376
2862;3.056302;-0.00296397;73.07686;7.551291;0;0;0;9.626146;9.190572;67065.89;8278189
2868;3.057373;-0.002468465;73.22959;7.567073;0;0;0;9.629521;9.193651;67206.06;8295746
2874;3.058337;-0.003410282;73.06156;7.54971;0;0;0;9.632559;9.196421;67051.86;8276940
2880;3.059355;-0.002660301;73.35728;7.580267;0;0;0;9.635764;9.199345;67323.24;8310684
2886;3.060319;-0.003186185;73.5008;7.595098;0;0;0;9.638801;9.202115;67454.96;8327174
2892;3.061337;-0.003174152;73.28419;7.572714;0;0;0;9.642008;9.20504;67256.16;8302876
2898;3.062302;-0.002661712;73.31901;7.576313;0;0;0;9.645044;9.207809;67288.13;8307052
2904;3.063373;-0.00239289;73.22581;7.566682;0;0;0;9.648418;9.210887;67202.59;8296747
2910;3.064284;-0.003086191;73.55474;7.600672;0;0;0;9.651288;9.213503;67504.47;8334235
2916;3.065302;-0.002476383;73.19116;7.563101;0;0;0;9.654493;9.216427;67170.79;8293280
2922;3.066373;-0.002506134;73.35079;7.579597;0;0;0;9.657867;9.219504;67317.29;8311624
2928;3.067337;-0.00279432;73.18599;7.562567;0;0;0;9.660905;9.222274;67166.05;8293180
2934;3.068302;-0.002330839;73.50247;7.59527;0;0;0;9.663942;9.225043;67456.49;8329273
2940;3.069319;-0.00243056;73.55686;7.600891;0;0;0;9.667148;9.227966;67506.41;8335680
2946;3.070391;-0.002138376;73.21359;7.56542;0;0;0;9.670523;9.231044;67191.38;8297035
2952;3.071302;-0.001859401;73.52364;7.597458;0;0;0;9.673391;9.233659;67475.93;8332390
2958;3.072319;-0.00263055;73.73649;7.619452;0;0;0;9.676597;9.236582;67671.27;8356756
2964;3.073337;-0.002686094;73.61506;7.606905;0;0;0;9.679803;9.239505;67559.82;8343238
2970;3.074302;-0.002327155;73.37261;7.581851;0;0;0;9.682839;9.242274;67337.31;8315990
2976;3.075373;-0.002825953;73.56731;7.60197;0;0;0;9.686214;9.24535;67516;8338313
2982;3.076337;-0.002328566;73.43772;7.588579;0;0;0;9.689251;9.248119;67397.07;8323856
2988;3.077302;-0.002671982;73.36444;7.581008;0;0;0;9.692288;9.250888;67329.82;8315781
2994;3.078319;-0.003099008;73.57183;7.602438;0;0;0;9.695495;9.253811;67520.16;8339532
3000;3.079337;-0.002264398;73.48676;7.593647;0;0;0;9.6987;9.256733;67442.08;8330132
3006;3.080355;-0.002004082;73.43223;7.588012;0;0;0;9.701906;9.259656;67392.03;8324194
3012;3.081319;-0.002614361;73.54473;7.599637;0;0;0;9.704943;9.262424;67495.27;8337177
3018;3.082337;-0.002167696;73.34049;7.578532;0;0;0;9.708149;9.265346;67307.84;8314267
3024;3.083355;-0.002331937;73.60317;7.605676;0;0;0;9.711355;9.268269;67548.91;8344290
3030;3.084373;-0.002745675;73.50029;7.595046;0;0;0;9.714561;9.27119;67454.5;8332871
3036;3.085337;-0.002525263;73.44937;7.589784;0;0;0;9.717598;9.273958;67407.77;8327328
3042;3.086302;-0.002084243;73.62566;7.608;0;0;0;9.720635;9.276727;67569.55;8347546
3048;3.087373;-0.002823719;73.48532;7.593498;0;0;0;9.724009;9.279801;67440.75;8331891
3054;3.088337;-0.002475991;73.53087;7.598205;0;0;0;9.727046;9.28257;67482.55;8337286
3060;3.089302;-0.002146059;73.3196;7.576374;0;0;0;9.730084;9.285338;67288.66;8313562
3066;3.090373;-0.002504684;73.43839;7.588649;0;0;0;9.733458;9.288413;67397.69;8327287
3072;3.091391;-0.002204974;73.39916;7.584595;0;0;0;9.736664;9.291335;67361.68;8323082
3078;3.092302;-0.002287525;73.51765;7.596839;0;0;0;9.739533;9.293949;67470.43;8336736
3084;3.093319;-0.0019416;73.43243;7.588033;0;0;0;9.742738;9.296869;67392.21;8327315
3090;3.094337;-0.002539923;73.5861;7.603913;0;0;0;9.745944;9.299791;67533.25;8344986
3096;3.095302;-0.002218144;73.53706;7.598845;0;0;0;9.748981;9.302558;67488.24;8339655
3102;3.096373;-0.002571517;73.503;7.595325;0;0;0;9.752356;9.305633;67456.98;8336048
3108;3.097337;-0.001734241;73.42127;7.58688;0;0;0;9.755393;9.3084;67381.98;8327010
3114;3.098302;-0.002119561;73.39352;7.584012;0;0;0;9.75843;9.311168;67356.5;8324092
3120;3.099319;-0.002128576;73.3833;7.582956;0;0;0;9.761636;9.314088;67347.13;8323176
3126;3.100391;-0.002660536;73.59759;7.605099;0;0;0;9.765011;9.317163;67543.79;8347738
3132;3.101355;-0.002159112;73.62407;7.607836;0;0;0;9.768047;9.31993;67568.09;8350973
3138;3.102319;-0.001946814;73.64469;7.609967;0;0;0;9.771085;9.322696;67587.02;8353543
3144;3.103284;-0.002448748;73.2473;7.568903;0;0;0;9.774121;9.325463;67222.31;8308697
3150;3.104302;-0.002827756;73.4812;7.593073;0;0;0;9.777328;9.328384;67436.98;8335473
3153.792;3.104944;-0.002485908;73.54579;7.599747;0;0;0;9.779353;9.330228;67496.25;8342953