File: Ensayos/Resistencia/comp/Clavo5/Clavo5b.raw
"Test Type";"Manual"
"Method Name:";"C:\INSTRON\user\template\CYCLE.MTM"
"Name:";""
"Operator ID:";""
"Company:";""
"Lab name:";""
"Test date:";"23/05/2017"
"Temperature:";""
"Humidity:";""
"Note 1:";""
"Note 2:";""
"Note 3:";""
"Geometry:";"Rectangular"
"Specimen";1
"Specimen name:";""
"Width:";0.250000;"in"
"Thickness:";0.060000;"in"
"Length:";1.250000;"in"
"Diameter:";0.039370;"in"
"Inner diameter:";0.019685;"in"
"Outer diameter:";0.039370;"in"
"Wall thickness:";0.019685;"in"
"Area:";0.015000;"in*in"
"Linear density:";1.000000;"den"
"Sled weight:";2.204623;"lbf"
"Loading span:";0.000000;"mm"
"Support span:";1.000000;"mm"
"Span ratio:";"2"
"Fixture type:";"3-point"
"Comment:";""
"Included"
"Final Width:";0.250000;"in"
"Final Thickness:";0.060000;"in"
"Final Length:";1.250000;"in"
"Final Diameter:";0.039370;"in"
"Final Inner diameter:";0.019685;"in"
"Final Outer diameter:";0.039370;"in"
"Final Wall thickness:";0.019685;"in"
"Final Area:";0.015000;"in*in"
"Final Linear density:";1.000000;"den"
"Time sec";"Extension mm";"Strain 1 %";"Load N";"Stress MPa";"Cycle Count ";"Total Cycle Count ";"Repetitions Count ";"Strain [Exten.] %";"True strain %";"Tenacity gf/tex";"True stress Pa"
0;0;-0.0001273633;58.96158;6.092709;0;0;0;0;0;54111.67;6092709
4;0.0006964281;-4.242058e-005;59.12089;6.10917;0;0;0;0.002193474;0.00219345;54257.88;6109305
8;0.001339285;2.690162e-005;59.06166;6.103051;0;0;0;0.00421822;0.004218131;54203.52;6103308
12;0.001982142;7.603667e-005;59.31616;6.129349;0;0;0;0.006242966;0.006242771;54437.08;6129731
16;0.002732141;0.0002021768;59.61289;6.160011;0;0;0;0.008605169;0.008604799;54709.41;6160541
20;0.003321426;0.0001970418;59.39862;6.137869;0;0;0;0.01046119;0.01046064;54512.76;6138511
24;0.004017854;0.0001180964;59.583;6.156922;0;0;0;0.01265466;0.01265386;54681.97;6157701
28;0.004767854;0.0001577455;59.72033;6.171113;0;0;0;0.01501686;0.01501574;54808.01;6172040
32;0.005357139;0.0001792458;59.56018;6.154564;0;0;0;0.01687288;0.01687146;54661.03;6155602
36;0.006053567;3.297733e-005;59.51478;6.149873;0;0;0;0.01906635;0.01906453;54619.37;6151046
40;0.006696424;5.996539e-005;59.94198;6.194017;0;0;0;0.0210911;0.02108888;55011.43;6195323
44;0.007339281;0.0002256958;60.5838;6.260338;0;0;0;0.02311585;0.02311317;55600.45;6261785
48;0.008089281;0.0001206248;60.94562;6.297727;0;0;0;0.02547805;0.0254748;55932.52;6299331
52;0.008732137;0.0002460789;61.62835;6.368275;0;0;0;0.02750279;0.02749901;56559.08;6370027
56;0.009374994;0.0001237214;61.73244;6.379032;0;0;0;0.02952754;0.02952318;56654.62;6380916
60;0.01001785;0.0001288564;61.94483;6.400979;0;0;0;0.03155228;0.03154731;56849.54;6402999
64;0.01066071;0.0002264405;62.08737;6.415708;0;0;0;0.03357703;0.03357139;56980.35;6417862
68;0.01141071;0.0002475292;62.40815;6.448855;0;0;0;0.03593924;0.03593278;57274.74;6451173
72;0.01205356;0.000345035;62.92114;6.501864;0;0;0;0.03796398;0.03795678;57745.54;6504333
76;0.01269642;0.0001370292;62.83417;6.492877;0;0;0;0.03998872;0.03998073;57665.72;6495474
80;0.01333928;0.0002255194;63.36071;6.547286;0;0;0;0.04201347;0.04200465;58148.95;6550037
84.00001;0.01403571;0.0003895055;63.60014;6.572028;0;0;0;0.04420695;0.04419718;58368.69;6574933
88.00001;0.01473213;0.0004849533;63.90227;6.603248;0;0;0;0.04640042;0.04638966;58645.96;6606311
92.00001;0.01537499;0.0003581273;64.12976;6.626755;0;0;0;0.04842516;0.04841344;58854.74;6629964
96.00001;0.01601785;0.0004056356;64.41095;6.655812;0;0;0;0.05044991;0.05043719;59112.8;6659169
100;0.0166607;0.0003210457;64.78875;6.694851;0;0;0;0.05247466;0.05246089;59459.53;6698364
104;0.0174107;0.0003319036;65.15193;6.73238;0;0;0;0.05483686;0.05482183;59792.83;6736072
108;0.01805356;0.0002668344;65.3576;6.753633;0;0;0;0.05686161;0.05684545;59981.59;6757473
112;0.01869642;0.0002092325;65.57869;6.776478;0;0;0;0.05888636;0.05886902;60184.49;6780469
116;0.01933927;0.0002193261;66.00103;6.82012;0;0;0;0.06091109;0.06089255;60572.09;6824275
120;0.0200357;0.0002841993;66.13415;6.833875;0;0;0;0.06310457;0.06308466;60694.25;6838188
124;0.02073213;0.0001140199;66.72549;6.894981;0;0;0;0.06529804;0.06527674;61236.96;6899483
128;0.02137499;0.0001418506;66.76161;6.898713;0;0;0;0.06732279;0.06730014;61270.11;6903358
132;0.02201784;0.0001528458;66.96295;6.919519;0;0;0;0.06934753;0.0693235;61454.89;6924318
136;0.0226607;2.419692e-005;67.06397;6.929957;0;0;0;0.07137228;0.07134682;61547.6;6934904
140;0.0234107;1.320179e-005;67.6374;6.989212;0;0;0;0.07373448;0.07370731;62073.86;6994365
144;0.02405356;9.992807e-005;67.70861;6.99657;0;0;0;0.07575923;0.07573055;62139.21;7001871
148;0.02469641;6.510032e-005;68.12297;7.039387;0;0;0;0.07778398;0.07775375;62519.48;7044863
152;0.02533927;-8.242248e-005;68.18684;7.045988;0;0;0;0.07980872;0.07977689;62578.1;7051611
156;0.0260357;8.989329e-005;68.43279;7.071403;0;0;0;0.0820022;0.08196859;62803.82;7077201
160;0.03096426;1.823879e-005;71.22665;7.360102;0;0;0;0.09752524;0.09747771;65367.87;7367280
164;0.03766069;4.72847e-005;74.5924;7.707897;0;0;0;0.1186163;0.1185461;68456.77;7717040
168;0.04430354;0.0001824013;78.55619;8.117489;0;0;0;0.1395387;0.1394415;72094.52;8128816
172;0.05105354;0.0001262693;82.24791;8.498968;0;0;0;0.1607985;0.1606694;75482.58;8512634
176;0.05764282;0.0001958463;86.08676;8.895649;0;0;0;0.1815522;0.1813876;79005.66;8911799
180;0.0642321;0.0001177633;90.22594;9.323366;0;0;0;0.2023058;0.2021015;82804.37;9342228
184;0.0709821;-1.282591e-005;94.16407;9.730307;0;0;0;0.2235657;0.2233161;86418.56;9752060
188;0.07767852;5.590831e-005;98.4265;10.17076;0;0;0;0.2446568;0.244358;90330.38;1.019564e+007
192;0.0842678;0.0001479263;102.7687;10.61946;0;0;0;0.2654104;0.2650588;94315.45;1.064764e+007
196;0.09107137;0.0002115256;107.3435;11.09218;0;0;0;0.2868389;0.2864284;98513.9;1.1124e+007
200;0.0977678;3.044908e-005;112.0047;11.57384;0;0;0;0.3079301;0.3074569;102791.7;1.160948e+007
204;0.1043571;0.000137774;116.6075;12.04947;0;0;0;0.3286837;0.3281447;107015.9;1.208907e+007
208;0.1110535;0.0001320903;121.3154;12.53595;0;0;0;0.3497748;0.3491645;111336.5;1.25798e+007
212;0.1176964;0.0001453784;126.5492;13.07678;0;0;0;0.3706972;0.3700118;116139.9;1.312526e+007
216;0.1243392;0.0001102764;131.2316;13.56062;0;0;0;0.3916195;0.3908547;120437.1;1.361373e+007
220;0.1310892;7.478811e-006;136.0062;14.054;0;0;0;0.4128794;0.4120294;124819;1.411203e+007
224;0.1377321;-1.52758e-005;140.9845;14.56843;0;0;0;0.4338018;0.4328636;129387.8;1.463163e+007
228;0.1443749;-0.0001523327;146.1244;15.09955;0;0;0;0.4547241;0.4536934;134104.9;1.516821e+007
232;0.1510713;-6.396003e-005;151.6045;15.66583;0;0;0;0.4758152;0.4746868;139134.2;1.574037e+007
236;0.1577678;-0.0001917857;156.9906;16.22239;0;0;0;0.4969063;0.4956758;144077.3;1.6303e+007
240;0.164357;-7.954142e-005;162.5463;16.79648;0;0;0;0.51766;0.5163247;149176;1.688343e+007
244;0.1709999;-0.0002406464;168.0281;17.36294;0;0;0;0.5385823;0.5371371;154206.9;1.745645e+007
248;0.1776963;-0.0001243255;173.9803;17.978;0;0;0;0.5596734;0.5581131;159669.5;1.807862e+007
252;0.1843392;-0.0001570561;179.7887;18.57821;0;0;0;0.5805957;0.5789168;165000.1;1.868607e+007
256;0.190982;-0.0003674921;185.5885;19.17751;0;0;0;0.6015182;0.5997163;170322.8;1.929287e+007
260;0.1976249;-0.0001376725;191.5053;19.78892;0;0;0;0.6224405;0.6205114;175753;1.99121e+007
264;0.2043213;-0.0001197001;197.8057;20.43996;0;0;0;0.6435316;0.6414698;181535.1;2.05715e+007
268;0.2109642;-0.0001531754;204.1266;21.09312;0;0;0;0.664454;0.6622563;187336.1;2.123328e+007
272;0.2176606;-0.0001347326;210.4595;21.74753;0;0;0;0.6855451;0.6832059;193148.1;2.189662e+007
276;0.224357;-8.608753e-005;216.6061;22.38267;0;0;0;0.7066362;0.7041512;198789;2.254084e+007
280;0.2309999;-9.780779e-005;223.4266;23.08746;0;0;0;0.7275586;0.7249247;205048.5;2.325544e+007
284;0.2376427;-0.0003071071;230.4746;23.81576;0;0;0;0.748481;0.7456937;211516.9;2.399402e+007
288;0.2443391;-0.0001967247;237.5653;24.54846;0;0;0;0.769572;0.7666259;218024.2;2.473738e+007
292;0.250982;-0.0004897124;244.6289;25.27838;0;0;0;0.7904944;0.7873864;224506.9;2.54782e+007
296;0.2576248;-0.000240078;251.9023;26.02996;0;0;0;0.8114168;0.8081425;231182;2.624117e+007
300;0.2643748;-0.0002676345;259.4133;26.80609;0;0;0;0.8326766;0.829229;238075.1;2.70293e+007
304;0.2710712;-0.0003849941;266.9449;27.58436;0;0;0;0.8537677;0.8501437;244987.2;2.781986e+007
308;0.2776605;-0.0004115314;274.1261;28.32642;0;0;0;0.8745214;0.8707196;251577.8;2.857414e+007
312;0.2844105;-0.0004126682;282.246;29.16548;0;0;0;0.8957812;0.8917929;259029.7;2.942673e+007
316;0.2910534;-0.0004560411;290.0317;29.97001;0;0;0;0.9167036;0.9125273;266175.1;3.024474e+007
320;0.2976962;-0.0003970281;298.2919;30.82356;0;0;0;0.9376259;0.9332575;273755.8;3.111257e+007
324;0.3044462;-0.0003741559;306.5223;31.67403;0;0;0;0.9588858;0.9543177;281309.2;3.197775e+007
328;0.3110891;-0.0003752141;314.724;32.52155;0;0;0;0.9798082;0.9750392;288836.3;3.284019e+007
332;0.3176248;-0.0003396809;323.4405;33.42226;0;0;0;1.000393;0.9954223;296835.8;3.375661e+007
336;0.3244284;-0.0001630926;331.9944;34.30615;0;0;0;1.021822;1.016636;304686;3.46567e+007
340;0.3310712;-0.0003279607;340.8142;35.21754;0;0;0;1.042744;1.037345;312780.4;3.558477e+007
344;0.3376605;-0.0001424742;349.1185;36.07565;0;0;0;1.063498;1.057882;320401.7;3.645932e+007
348;0.3443569;-0.0002148735;358.1935;37.0134;0;0;0;1.084589;1.078749;328730.2;3.741485e+007
352;0.3509998;-6.190217e-005;367.3538;37.95997;0;0;0;1.105511;1.099445;337137;3.837962e+007
356;0.3576426;-0.0001257562;376.6591;38.92152;0;0;0;1.126433;1.120136;345676.8;3.935994e+007
360;0.3643391;-0.0001015316;385.7374;39.85961;0;0;0;1.147525;1.14099;354008.4;4.031701e+007
364;0.3709819;-4.929992e-005;395.2159;40.83906;0;0;0;1.168447;1.161673;362707.3;4.131624e+007
368;0.3776247;-1.558932e-005;404.7083;41.81995;0;0;0;1.189369;1.182352;371418.9;4.231734e+007
372;0.3842676;-6.029499e-005;414.7177;42.85424;0;0;0;1.210292;1.203026;380604.9;4.33729e+007
376;0.3909105;-0.0001548413;424.2123;43.83536;0;0;0;1.231214;1.223696;389318.6;4.437507e+007
380;0.397714;-0.0002446643;434.6721;44.91621;0;0;0;1.252643;1.244862;398918;4.547885e+007
384;0.4043033;-7.085895e-005;444.7706;45.95972;0;0;0;1.273396;1.265357;408185.8;4.654497e+007
388;0.4109997;-9.553427e-005;454.8534;47.00161;0;0;0;1.294487;1.286181;417439.3;4.761004e+007
392;0.4176961;-0.0002169707;465.4918;48.10091;0;0;0;1.315578;1.307;427202.5;4.873372e+007
396;0.424339;-0.0003446983;475.4894;49.13401;0;0;0;1.336501;1.327648;436377.9;4.979068e+007
400;0.4309819;-0.0003593389;485.3971;50.1578;0;0;0;1.357423;1.348293;445470.5;5.083865e+007
404;0.4377319;-0.0003743518;495.9891;51.2523;0;0;0;1.378683;1.369266;455191.3;5.195891e+007
408;0.4443747;-0.0004471431;507.5332;52.4452;0;0;0;1.399606;1.389901;465785.8;5.317923e+007
412;0.4510175;-0.0005478435;518.3461;53.56253;0;0;0;1.420528;1.410533;475709.3;5.43234e+007
416;0.457714;-0.0004543948;529.6827;54.73399;0;0;0;1.441619;1.431326;486113.5;5.552305e+007
420;0.464464;-0.0005721465;540.5547;55.85744;0;0;0;1.462879;1.452282;496091.2;5.667456e+007
424;0.4710533;-0.0004447324;552.5042;57.09222;0;0;0;1.483632;1.472734;507057.8;5.793925e+007
428;0.4777497;-0.0003577121;563.9025;58.27005;0;0;0;1.504724;1.493515;517518.5;5.914685e+007
432;0.4844461;-0.0003828383;576.4564;59.56729;0;0;0;1.525815;1.514291;529039.8;6.047617e+007
436;0.4909818;-0.0004564527;587.6409;60.72301;0;0;0;1.546399;1.534564;539304.3;6.166203e+007
440;0.4977318;-0.0004263483;600.7231;62.07484;0;0;0;1.567659;1.555498;551310.4;6.304796e+007
444;0.5043747;-0.0004797168;611.7186;63.21104;0;0;0;1.588582;1.576096;561401.4;6.42152e+007
448;0.510964;-0.0005884333;624.3354;64.51479;0;0;0;1.609335;1.596523;572980.4;6.555305e+007
452;0.5176603;-0.0004782469;637.6098;65.88647;0;0;0;1.630426;1.617278;585162.9;6.69607e+007
456;0.5243568;-0.0003446983;649.8431;67.15059;0;0;0;1.651518;1.638028;596390;6.825959e+007
460;0.5309996;-0.0003584373;662.7017;68.47931;0;0;0;1.67244;1.658609;608190.9;6.962458e+007
464;0.5376425;-0.0003064604;676.4849;69.90357;0;0;0;1.693362;1.679185;620840.3;7.10873e+007
468;0.5443389;-0.0003873852;688.7907;71.17519;0;0;0;1.714453;1.699922;632133.9;7.239545e+007
472;0.5509818;-0.0002020361;702.6156;72.60376;0;0;0;1.735376;1.72049;644821.7;7.386371e+007
476;0.5576246;-0.0002479373;716.6866;74.05776;0;0;0;1.756298;1.741053;657735.3;7.535844e+007
480;0.5643211;-0.0004577266;730.2869;75.46313;0;0;0;1.777389;1.761778;670216.9;7.68044e+007
484;0.5710175;-0.0002160887;743.2178;76.79933;0;0;0;1.79848;1.782499;682084.1;7.818055e+007
488;0.5776604;-0.0004382255;757.6576;78.29144;0;0;0;1.819403;1.80305;695336.2;7.971588e+007
492;0.5843032;-0.0003824463;772.0991;79.78373;0;0;0;1.840325;1.823596;708589.8;8.125201e+007
496;0.5910532;-0.0005094684;786.9712;81.32052;0;0;0;1.861585;1.844469;722238.6;8.283437e+007
500;0.5976961;-0.0004517293;801.5331;82.82526;0;0;0;1.882507;1.865007;735602.7;8.438445e+007
504;0.6043389;-0.0005623273;816.0154;84.32176;0;0;0;1.90343;1.885541;748893.8;8.592677e+007
508;0.6110353;-0.0005579959;830.7576;85.84512;0;0;0;1.924521;1.906236;762423.3;8.749723e+007
512;0.6177318;-0.0006430758;845.6921;87.38836;0;0;0;1.945612;1.926927;776129.4;8.90886e+007
516;0.6243746;-0.0006918189;860.4461;88.91294;0;0;0;1.966534;1.947448;789669.8;9.066145e+007
520;0.6311246;-0.0006784326;875.388;90.45695;0;0;0;1.987794;1.968295;803382.6;9.225504e+007
524;0.6377674;-0.0008937489;889.6495;91.93063;0;0;0;2.008716;1.988808;816471;9.377726e+007
528;0.6443567;-0.0008539823;903.8037;93.39324;0;0;0;2.02947;2.009151;829461;9.528863e+007
532;0.6511067;-0.0007933621;919.3566;95.00037;0;0;0;2.05073;2.029985;843734.6;9.694857e+007
536;0.6577496;-0.0008467305;934.0136;96.51493;0;0;0;2.071652;2.050485;857185.9;9.851438e+007
540;0.6643389;-0.0007486564;948.287;97.98985;0;0;0;2.092406;2.070816;870285.3;1.000402e+008
544;0.6710352;-0.0007826805;963.5708;99.56918;0;0;0;2.113497;2.091472;884311.9;1.016736e+008
548;0.6777317;-0.0006896238;978.2648;101.0876;0;0;0;2.134588;2.112125;897797.2;1.032454e+008
552;0.6842674;-0.0009467254;992.7455;102.5839;0;0;0;2.155173;2.132278;911086.8;1.047948e+008
556;0.6909639;-0.0009139949;1007.311;104.089;0;0;0;2.176264;2.152922;924453.8;1.063542e+008
560;0.6976602;-0.0008754629;1022.477;105.6561;0;0;0;2.197355;2.173561;938372.4;1.079778e+008
564;0.7043032;-0.0006846652;1036.444;107.0994;0;0;0;2.218278;2.194032;951190.5;1.094751e+008
568;0.7109995;-0.001025083;1052.575;108.7663;0;0;0;2.239369;2.214663;965995.4;1.11202e+008
572;0.7176424;-0.0007839741;1067.239;110.2816;0;0;0;2.260291;2.235125;979452.8;1.127743e+008
576;0.7243388;-0.0008071011;1084.441;112.0592;0;0;0;2.281382;2.255748;995240.1;1.146157e+008
580;0.7309817;-0.0008823618;1101.26;113.7971;0;0;0;2.302305;2.276201;1010675;1.16417e+008
584;0.7376245;-0.0009096634;1116.01;115.3212;0;0;0;2.323227;2.296651;1024212;1.180004e+008
588;0.7443745;-0.0007220408;1133.666;117.1457;0;0;0;2.344486;2.317426;1040415;1.198921e+008
592;0.7510174;-0.0008662709;1148.611;118.69;0;0;0;2.365409;2.337867;1054132;1.214976e+008
596;0.7576602;-0.0008077086;1165.251;120.4095;0;0;0;2.386332;2.358304;1069403;1.232829e+008
600;0.7644102;-0.000887928;1182.801;122.223;0;0;0;2.407591;2.379066;1085509;1.251656e+008
604;0.771053;-0.0009106826;1197.497;123.7416;0;0;0;2.428514;2.399494;1098996;1.267467e+008
608;0.777696;-0.0009784369;1213.291;125.3736;0;0;0;2.449436;2.419918;1113491;1.284446e+008
612;0.7843923;-0.001107282;1227.865;126.8796;0;0;0;2.470527;2.440503;1126866;1.300142e+008
616;0.7910888;-0.001215998;1245.009;128.6512;0;0;0;2.491618;2.461083;1142600;1.318566e+008
620;0.7976781;-0.001071533;1260.001;130.2003;0;0;0;2.512372;2.48133;1156359;1.334714e+008
624;0.8044281;-0.001044408;1274.754;131.7249;0;0;0;2.533632;2.502067;1169899;1.350623e+008
628;0.8111245;-0.001078236;1290.832;133.3863;0;0;0;2.554723;2.522635;1184654;1.367939e+008
632;0.8177137;-0.0009441187;1307.981;135.1583;0;0;0;2.575476;2.54287;1200392;1.386392e+008
636;0.8244102;-0.001041879;1321.795;136.5858;0;0;0;2.596568;2.563429;1213071;1.401323e+008
640;0.831053;-0.001200554;1337.49;138.2075;0;0;0;2.61749;2.58382;1227474;1.418251e+008
644.0001;0.8376423;-0.001267034;1353.635;139.8759;0;0;0;2.638243;2.604042;1242291;1.435661e+008
648.0001;0.8443388;-0.001170313;1367.34;141.2921;0;0;0;2.659335;2.624589;1254869;1.450496e+008
652.0001;0.8510351;-0.001201436;1383.654;142.9779;0;0;0;2.680426;2.645132;1269841;1.468103e+008
656.0001;0.857678;-0.001187952;1396.45;144.3001;0;0;0;2.701348;2.665506;1281585;1.481982e+008
660.0001;0.8642673;-0.001067848;1413.15;146.0258;0;0;0;2.722102;2.685712;1296911;1.500007e+008
664.0001;0.8709637;-0.001145872;1427.13;147.4704;0;0;0;2.743193;2.706241;1309740;1.515157e+008
668.0001;0.8776601;-0.001152066;1439.114;148.7088;0;0;0;2.764284;2.726767;1320739;1.528195e+008
672.0001;0.884303;-0.001170705;1450.09;149.8429;0;0;0;2.785206;2.747125;1330812;1.540164e+008
676.0001;0.8909459;-0.001323147;1452.316;150.0729;0;0;0;2.806129;2.767478;1332855;1.542842e+008
680.0001;0.8976959;-0.001010658;1461.677;151.0402;0;0;0;2.827389;2.788156;1341446;1.553107e+008
684.0001;0.9043387;-0.001187168;1476.46;152.5678;0;0;0;2.848311;2.808501;1355013;1.569134e+008
688.0001;0.9109816;-0.001318031;1491.574;154.1297;0;0;0;2.869233;2.828842;1368884;1.58552e+008
692.0001;0.9177316;-0.00124379;1504.083;155.4223;0;0;0;2.890493;2.849506;1380364;1.599147e+008
696.0001;0.9243744;-0.001136857;1514.599;156.5089;0;0;0;2.911415;2.869839;1390015;1.610655e+008
700.0001;0.9309637;-0.001441251;1522.916;157.3683;0;0;0;2.932169;2.890003;1397648;1.619826e+008
704.0001;0.9377673;-0.001332946;1536.04;158.7244;0;0;0;2.953598;2.910819;1409692;1.634125e+008
708.0001;0.9444101;-0.001363168;1543.212;159.4656;0;0;0;2.97452;2.931139;1416275;1.642089e+008
712.0001;0.9510529;-0.001101343;1551.271;160.2984;0;0;0;2.995442;2.951455;1423671;1.651e+008
716.0001;0.9577494;-0.001407325;1565.692;161.7885;0;0;0;3.016534;2.971931;1436905;1.666689e+008
720.0001;0.9644459;-0.001316993;1579.063;163.1702;0;0;0;3.037625;2.992402;1449177;1.681267e+008
724.0001;0.9710351;-0.001384512;1596.178;164.9387;0;0;0;3.058378;3.012542;1464884;1.699832e+008
728.0001;0.9777315;-0.001348587;1613.223;166.7001;0;0;0;3.079469;3.033005;1480527;1.718335e+008
732.0001;0.9844279;-0.00146036;1627.657;168.1916;0;0;0;3.10056;3.053464;1493774;1.734065e+008
736.0001;0.9910172;-0.001572213;1645.217;170.0061;0;0;0;3.121314;3.073592;1509889;1.753125e+008
740.0001;0.9977137;-0.001448699;1663.046;171.8484;0;0;0;3.142405;3.094042;1526251;1.772486e+008
744.0001;1.00441;-0.001346333;1676.814;173.2711;0;0;0;3.163496;3.114488;1538887;1.787525e+008
748.0001;1.010999;-0.001549164;1682.898;173.8998;0;0;0;3.18425;3.134604;1544471;1.794372e+008
752.0001;1.017696;-0.001494698;1696.19;175.2733;0;0;0;3.205341;3.155042;1556669;1.808914e+008
756.0001;1.024339;-0.001327008;1713.679;177.0805;0;0;0;3.226264;3.175313;1572720;1.827936e+008
760.0001;1.030981;-0.00130541;1728.864;178.6497;0;0;0;3.247186;3.195579;1586656;1.844507e+008
764.0001;1.037624;-0.001477921;1744.99;180.316;0;0;0;3.268108;3.215841;1601455;1.862089e+008
768.0001;1.044267;-0.00127117;1761.442;182.016;0;0;0;3.289031;3.236099;1616554;1.880026e+008
772.0001;1.051017;-0.001182386;1781.187;184.0563;0;0;0;3.310291;3.25668;1634675;1.901491e+008
776.0001;1.05766;-0.001228444;1798.882;185.8848;0;0;0;3.331213;3.27693;1650914;1.92077e+008
780.0001;1.064303;-0.001245162;1814.746;187.5241;0;0;0;3.352135;3.297176;1665473;1.938102e+008
784.0001;1.071053;-0.001281185;1829.259;189.0238;0;0;0;3.373395;3.317744;1678792;1.954003e+008
788.0001;1.077696;-0.001131585;1845.215;190.6726;0;0;0;3.394317;3.337982;1693436;1.971446e+008
792.0001;1.084285;-0.001300529;1862.013;192.4084;0;0;0;3.415071;3.358052;1708853;1.989793e+008
796.0001;1.091035;-0.00139243;1880.494;194.3181;0;0;0;3.436331;3.378608;1725814;2.009955e+008
800.0001;1.097731;-0.001488054;1900.6;196.3958;0;0;0;3.457422;3.398996;1744266;2.03186e+008
804.0001;1.104374;-0.001293121;1916.196;198.0073;0;0;0;3.478344;3.419217;1758578;2.048947e+008
808.0001;1.111071;-0.001494326;1935.086;199.9593;0;0;0;3.499435;3.439597;1775915;2.069568e+008
812.0001;1.117767;-0.001632656;1950.26;201.5272;0;0;0;3.520526;3.459973;1789840;2.086221e+008
816.0001;1.12441;-0.001524998;1969.8;203.5464;0;0;0;3.541449;3.480182;1807773;2.107549e+008
820.0001;1.131053;-0.001491935;1989.037;205.5342;0;0;0;3.562371;3.500387;1825428;2.128561e+008
824.0001;1.137749;-0.00153423;2002.864;206.963;0;0;0;3.583462;3.52075;1838118;2.143795e+008
828.0001;1.144339;-0.001530153;2019.887;208.7221;0;0;0;3.604216;3.540784;1853741;2.162449e+008
832.0001;1.151142;-0.001501911;2039.307;210.7288;0;0;0;3.625644;3.561464;1871563;2.183691e+008
836.0001;1.157785;-0.001603219;2054.056;212.2529;0;0;0;3.646567;3.581653;1885099;2.199928e+008
840.0001;1.164321;-0.001578191;2073.416;214.2535;0;0;0;3.667152;3.601512;1902867;2.221105e+008
844.0001;1.171071;-0.001602337;2093.643;216.3436;0;0;0;3.688411;3.622017;1921430;2.243232e+008
848.0001;1.177713;-0.001558415;2108.598;217.8889;0;0;0;3.709334;3.642193;1935154;2.259711e+008
852.0001;1.184303;-0.001520059;2129.227;220.0206;0;0;0;3.730088;3.662203;1954087;2.282275e+008
856.0001;1.190999;-0.001717932;2148.764;222.0394;0;0;0;3.751179;3.682533;1972017;2.303685e+008
860.0001;1.197642;-0.001586265;2156.284;222.8165;0;0;0;3.772101;3.702697;1978918;2.312213e+008
864.0001;1.204339;-0.001694296;2174.279;224.6759;0;0;0;3.793192;3.72302;1995433;2.331983e+008
868.0001;1.210981;-0.00155181;2187.777;226.0708;0;0;0;3.814115;3.743176;2007821;2.346933e+008
872.0001;1.217624;-0.00162368;2203.766;227.723;0;0;0;3.835037;3.763327;2022495;2.364562e+008
876.0001;1.224374;-0.001714326;2225.529;229.9718;0;0;0;3.856297;3.783799;2042468;2.388402e+008
880.0001;1.230964;-0.00174543;2246.355;232.1238;0;0;0;3.87705;3.803781;2061580;2.411234e+008
884.0001;1.23766;-0.00169216;2263.819;233.9284;0;0;0;3.898141;3.824082;2077608;2.430473e+008
888.0001;1.24441;-0.001744901;2288.853;236.5153;0;0;0;3.919401;3.844543;2100583;2.457853e+008
892.0001;1.251053;-0.001731417;2310.486;238.7507;0;0;0;3.940324;3.864674;2120436;2.481583e+008
896.0001;1.257642;-0.001715718;2327.361;240.4944;0;0;0;3.961077;3.884639;2135923;2.500206e+008
900.0001;1.264392;-0.001770811;2352.293;243.0707;0;0;0;3.982337;3.905086;2158804;2.527506e+008
904.0001;1.271035;-0.001692865;2373.628;245.2754;0;0;0;4.003259;3.925205;2178384;2.550944e+008
908.0001;1.277678;-0.001595791;2396.278;247.6159;0;0;0;4.024181;3.94532;2199171;2.575804e+008
912.0001;1.284374;-0.001731142;2414.518;249.5007;0;0;0;4.045273;3.965594;2215911;2.595936e+008
916.0001;1.291071;-0.001899813;2437.811;251.9076;0;0;0;4.066364;3.985862;2237288;2.621511e+008
920.0001;1.297713;-0.001665701;2458.264;254.0211;0;0;0;4.087286;4.005965;2256059;2.644037e+008
924.0001;1.30441;-0.00188429;2475.34;255.7856;0;0;0;4.108378;4.026227;2271730;2.662943e+008
928.0001;1.311106;-0.002013723;2499.586;258.2911;0;0;0;4.129468;4.046483;2293982;2.689572e+008
932.0001;1.317696;-0.001761697;2521.895;260.5963;0;0;0;4.150222;4.066412;2314456;2.714117e+008
936.0001;1.324446;-0.001868297;2545.753;263.0617;0;0;0;4.171482;4.086822;2336351;2.740352e+008
940.0001;1.331088;-0.00186965;2561.889;264.7291;0;0;0;4.192404;4.106905;2351160;2.758276e+008
944.0001;1.337678;-0.00187747;2585.3;267.1482;0;0;0;4.213158;4.126821;2372645;2.784035e+008
948.0001;1.344374;-0.001957748;2608.599;269.5558;0;0;0;4.23425;4.147058;2394028;2.809694e+008
952.0001;1.351017;-0.001895873;2630.949;271.8653;0;0;0;4.255172;4.167128;2414539;2.834336e+008
956.0001;1.35766;-0.001936973;2648.988;273.7293;0;0;0;4.276094;4.187194;2431095;2.854342e+008
960.0001;1.364303;-0.001866278;2673.093;276.2201;0;0;0;4.297017;4.207257;2453216;2.880893e+008
964.0001;1.370999;-0.001816085;2696.988;278.6893;0;0;0;4.318108;4.227477;2475146;2.907234e+008
968.0001;1.377642;-0.002041652;2713.35;280.38;0;0;0;4.33903;4.247532;2490162;2.925458e+008
972.0001;1.384285;-0.002061564;2736.893;282.8128;0;0;0;4.359952;4.267582;2511768;2.951433e+008
976.0001;1.390928;-0.002140686;2758.121;285.0064;0;0;0;4.380875;4.287628;2531251;2.974922e+008
980.0001;1.397678;-0.00204567;2781.228;287.3941;0;0;0;4.402134;4.307993;2552457;3.000456e+008
984.0001;1.404267;-0.002249677;2800.722;289.4085;0;0;0;4.422888;4.32787;2570347;3.022087e+008
988.0001;1.41091;-0.001990537;2825.234;291.9415;0;0;0;4.44381;4.347904;2592844;3.049148e+008
992.0001;1.417767;-0.002143783;2845.434;294.0287;0;0;0;4.465408;4.368581;2611382;3.071583e+008
996.0001;1.42441;-0.002227746;2870.47;296.6159;0;0;0;4.48633;4.388607;2634359;3.09923e+008
1000;1.430999;-0.002113894;2894.592;299.1085;0;0;0;4.507084;4.408467;2656496;3.125895e+008
1004;1.437749;-0.002210675;2920.301;301.765;0;0;0;4.528344;4.428808;2680091;3.1543e+008
1008;1.444392;-0.002239819;2939.108;303.7084;0;0;0;4.549265;4.448822;2697351;3.175249e+008
1012;1.451035;-0.002132709;2964.964;306.3802;0;0;0;4.570188;4.468832;2721080;3.203823e+008
1016;1.457785;-0.002258849;2991.515;309.1239;0;0;0;4.591448;4.489161;2745447;3.233171e+008
1020;1.464428;-0.002178238;3017.711;311.8308;0;0;0;4.61237;4.509162;2769488;3.262136e+008
1024;1.47107;-0.002445767;3038.62;313.9913;0;0;0;4.633293;4.52916;2788677;3.285395e+008
1028;1.477767;-0.002334777;3065.337;316.7521;0;0;0;4.654384;4.549315;2813196;3.314949e+008
1032;1.48441;-0.002447629;3087.346;319.0264;0;0;0;4.675306;4.569305;2833395;3.339418e+008
1036;1.490999;-0.002362686;3112.209;321.5956;0;0;0;4.69606;4.58913;2856213;3.366979e+008
1040;1.497749;-0.002374367;3137.456;324.2044;0;0;0;4.71732;4.609434;2879383;3.394982e+008
1044;1.504392;-0.002266454;3159.61;326.4937;0;0;0;4.738242;4.629412;2899716;3.419638e+008
1048;1.510981;-0.002167949;3184.437;329.0591;0;0;0;4.758996;4.649225;2922500;3.44719e+008
1052;1.517678;-0.002209283;3205.578;331.2437;0;0;0;4.780087;4.669356;2941902;3.470774e+008
1056;1.524374;-0.002274666;3229.957;333.7629;0;0;0;4.801178;4.689482;2964275;3.497874e+008
1060;1.530963;-0.00242946;3249.139;335.7451;0;0;0;4.821932;4.709284;2981880;3.519345e+008
1064;1.537606;-0.002623707;3271.01;338.0051;0;0;0;4.842854;4.729241;3001952;3.543742e+008
1068;1.544303;-0.002450176;3288.04;339.7648;0;0;0;4.863945;4.749356;3017581;3.562908e+008
1072;1.550999;-0.002398729;3310.369;342.0721;0;0;0;4.885036;4.769468;3038073;3.587825e+008
1076;1.557695;-0.00231943;3329.733;344.0731;0;0;0;4.906127;4.789574;3055845;3.609538e+008
1080;1.564285;-0.002540685;3348.922;346.0559;0;0;0;4.926881;4.809355;3073455;3.631057e+008
1084;1.571035;-0.002662827;3365.678;347.7874;0;0;0;4.948141;4.829614;3088833;3.649964e+008
1088;1.577677;-0.002660279;3386.161;349.904;0;0;0;4.969063;4.849548;3107631;3.67291e+008
1092;1.584267;-0.002945506;3402.587;351.6014;0;0;0;4.989817;4.869317;3122706;3.691456e+008
1096;1.59107;-0.002836339;3423.594;353.7721;0;0;0;5.011245;4.889725;3141985;3.715005e+008
1100;1.597767;-0.002869206;3439.318;355.3969;0;0;0;5.032336;4.909808;3156416;3.732817e+008
1104;1.604356;-0.002555032;3455.272;357.0455;0;0;0;5.05309;4.929566;3171058;3.750874e+008
1108;1.611052;-0.002802667;3471.015;358.6723;0;0;0;5.074181;4.94964;3185506;3.76872e+008
1112;1.617695;-0.002766507;3485.317;360.1501;0;0;0;5.095104;4.96955;3198631;3.785002e+008
1116;1.624338;-0.00275606;3503.072;361.9848;0;0;0;5.116026;4.989457;3214925;3.80504e+008
1120;1.631088;-0.00271306;3516.884;363.4121;0;0;0;5.137286;5.009679;3227601;3.820816e+008
1124;1.637731;-0.002883788;3534.061;365.187;0;0;0;5.158208;5.029577;3243365;3.840241e+008
1128;1.64432;-0.002864561;3547.393;366.5647;0;0;0;5.178962;5.049311;3255601;3.85549e+008
1132;1.65107;-0.002907601;3565.187;368.4034;0;0;0;5.200222;5.069522;3271931;3.875612e+008
1136;1.657767;-0.002846824;3575.282;369.4465;0;0;0;5.221313;5.089569;3281196;3.887365e+008
1140;1.664303;-0.002852253;3587.03;370.6606;0;0;0;5.241898;5.10913;3291978;3.900902e+008
1144;1.671052;-0.003016513;3601.661;372.1724;0;0;0;5.263157;5.129329;3305405;3.917604e+008
1148;1.677695;-0.003130992;3613.235;373.3683;0;0;0;5.28408;5.149203;3316027;3.930974e+008
1152;1.684338;-0.002885983;3625.926;374.6798;0;0;0;5.305002;5.169074;3327674;3.945566e+008
1156;1.690981;-0.003113529;3636.813;375.8048;0;0;0;5.325924;5.18894;3337666;3.958199e+008
1160;1.697624;-0.0029497;3648.162;376.9775;0;0;0;5.346847;5.208803;3348081;3.971339e+008
1164;1.704267;-0.002964458;3659.866;378.187;0;0;0;5.367769;5.228661;3358823;3.984872e+008
1168;1.710963;-0.003123133;3667.082;378.9326;0;0;0;5.38886;5.248675;3365445;3.993528e+008
1172;1.71766;-0.002955521;3678.28;380.0896;0;0;0;5.409952;5.268686;3375721;4.006523e+008
1176;1.724356;-0.002956403;3690.651;381.3681;0;0;0;5.431042;5.288692;3387076;4.020803e+008
1180;1.730945;-0.00302888;3701.151;382.4531;0;0;0;5.451797;5.308376;3396712;4.033036e+008
1184;1.737588;-0.003093773;3712.836;383.6604;0;0;0;5.472719;5.328214;3407435;4.046571e+008
1188;1.744338;-0.003053732;3724.278;384.8428;0;0;0;5.493978;5.348369;3417936;4.05986e+008
1192;1.750981;-0.003157882;3728.997;385.3304;0;0;0;5.514901;5.3682;3422267;4.06581e+008
1196;1.757624;-0.003102456;3736.329;386.0881;0;0;0;5.535823;5.388027;3428996;4.074613e+008
1200;1.764427;-0.003095812;3745.246;387.0096;0;0;0;5.557252;5.408329;3437180;4.085166e+008
1204;1.77107;-0.0030426;3753.144;387.8256;0;0;0;5.578175;5.428148;3444427;4.094592e+008
1208;1.77766;-0.003228282;3755.042;388.0218;0;0;0;5.598928;5.447803;3446170;4.097469e+008
1212;1.78441;-0.003248175;3752.767;387.7867;0;0;0;5.620188;5.467934;3444081;4.09581e+008
1216;1.791052;-0.003268088;3744.14;386.8953;0;0;0;5.64111;5.487741;3436165;4.087205e+008
1220;1.797695;-0.003145456;3738.806;386.344;0;0;0;5.662033;5.507544;3431269;4.08219e+008
1224;1.804392;-0.003282258;3733.211;385.7659;0;0;0;5.683123;5.527503;3426134;4.076895e+008
1228;1.811088;-0.00338292;3724.293;384.8444;0;0;0;5.704215;5.547458;3417950;4.067968e+008
1232;1.817731;-0.003230791;3713.996;383.7804;0;0;0;5.725137;5.567249;3408500;4.057524e+008
1236;1.824427;-0.003110903;3703.253;382.6702;0;0;0;5.746228;5.587196;3398640;4.046593e+008
1240;1.83107;-0.003030037;3695.859;381.9062;0;0;0;5.76715;5.60698;3391855;4.039313e+008
1244;1.83766;-0.003088697;3688.943;381.1916;0;0;0;5.787904;5.6266;3385508;4.032545e+008
1248;1.844356;-0.002835104;3687.729;381.0661;0;0;0;5.808995;5.646535;3384394;4.032022e+008
1252;1.850999;-0.002902074;3687.401;381.0322;0;0;0;5.829917;5.666307;3384093;4.032461e+008
1256;1.857642;-0.002830772;3688.739;381.1705;0;0;0;5.85084;5.686074;3385321;4.034722e+008
1260;1.864285;-0.00291207;3692.794;381.5895;0;0;0;5.871762;5.705839;3389042;4.039955e+008
1264;1.870981;-0.002898683;3696.815;382.0049;0;0;0;5.892854;5.725758;3392732;4.045159e+008
1268;1.877624;-0.003073312;3698.953;382.226;0;0;0;5.913775;5.745514;3394695;4.048299e+008
1272;1.884267;-0.003008733;3699.66;382.299;0;0;0;5.934698;5.765266;3395343;4.049873e+008
1276;1.890963;-0.002893137;3697.818;382.1086;0;0;0;5.95579;5.785174;3393653;4.048662e+008
1280;1.897713;-0.00298882;3699.919;382.3258;0;0;0;5.977049;5.805237;3395581;4.051776e+008
1284;1.904302;-0.003072234;3702.856;382.6293;0;0;0;5.997803;5.824818;3398277;4.055786e+008
1288;1.910945;-0.00291938;3707.023;383.0598;0;0;0;6.018725;5.844555;3402101;4.061151e+008
1292;1.917695;-0.002798591;3712.184;383.5931;0;0;0;6.039985;5.864605;3406837;4.067621e+008
1296;1.924338;-0.003040601;3718.014;384.1956;0;0;0;6.060907;5.884334;3412188;4.074813e+008
1300;1.930981;-0.003149925;3722.803;384.6904;0;0;0;6.08183;5.904059;3416583;4.080866e+008
1304;1.937731;-0.002911893;3729.319;385.3637;0;0;0;6.103089;5.924098;3422562;4.088828e+008
1308;1.944374;-0.002854135;3735.163;385.9676;0;0;0;6.124012;5.943815;3427926;4.096043e+008
1312;1.951017;-0.002741988;3740.774;386.5474;0;0;0;6.144934;5.963528;3433075;4.103005e+008
1316;1.957713;-0.002716529;3747.705;387.2637;0;0;0;6.166025;5.983396;3439436;4.111424e+008
1320;1.964409;-0.002853292;3753.48;387.8604;0;0;0;6.187117;6.00326;3444736;4.118578e+008
1324;1.971052;-0.002664807;3755.993;388.1201;0;0;0;6.208039;6.022961;3447043;4.122147e+008
1328;1.977749;-0.00280447;3760.24;388.5589;0;0;0;6.22913;6.042818;3450940;4.127628e+008
1332;1.984445;-0.00284947;3764.419;388.9908;0;0;0;6.250221;6.06267;3454775;4.133035e+008
1336;1.990981;-0.002907954;3768.868;389.4505;0;0;0;6.270805;6.082042;3458858;4.138722e+008
1340;1.997731;-0.002996424;3774.174;389.9987;0;0;0;6.292065;6.102045;3463728;4.145377e+008
1344;2.004374;-0.00289541;3779.519;390.5511;0;0;0;6.312988;6.121727;3468634;4.152066e+008
1348;2.010963;-0.002975355;3784.44;391.0595;0;0;0;6.333742;6.141247;3473149;4.158282e+008
1352;2.017659;-0.002825422;3789.866;391.6202;0;0;0;6.354833;6.16108;3478129;4.16507e+008
1356;2.024356;-0.002954286;3795.356;392.1875;0;0;0;6.375924;6.180908;3483167;4.171931e+008
1360;2.030999;-0.002780363;3799.489;392.6147;0;0;0;6.396846;6.200575;3486961;4.177296e+008
1364;2.037588;-0.002970965;3802.962;392.9735;0;0;0;6.4176;6.220079;3490148;4.18193e+008
1368;2.044338;-0.002809507;3808.693;393.5657;0;0;0;6.438859;6.240055;3495408;4.189069e+008
1372;2.050981;-0.002796415;3813.449;394.0571;0;0;0;6.459782;6.259709;3499772;4.195124e+008
1376;2.057624;-0.00264605;3813.566;394.0692;0;0;0;6.480704;6.27936;3499879;4.196077e+008
1380;2.064266;-0.00279469;3812.458;393.9548;0;0;0;6.501626;6.299007;3498863;4.195683e+008
1384;2.07107;-0.002539215;3813.213;394.0328;0;0;0;6.523055;6.319126;3499556;4.197358e+008
1388;2.077713;-0.002637877;3814.444;394.16;0;0;0;6.543978;6.338765;3500685;4.199537e+008
1392;2.084302;-0.00259768;3815.813;394.3015;0;0;0;6.564732;6.358242;3501942;4.201863e+008
1396;2.091052;-0.002236938;3820.015;394.7357;0;0;0;6.585991;6.378191;3505799;4.20733e+008
1400;2.097695;-0.002626961;3822.472;394.9896;0;0;0;6.606914;6.397818;3508053;4.210862e+008
1404;2.104338;-0.002479712;3825.844;395.338;0;0;0;6.627835;6.417441;3511148;4.215404e+008
1408;2.111088;-0.002585391;3829.222;395.6871;0;0;0;6.649096;6.437378;3514248;4.219967e+008
1412;2.117731;-0.002492648;3831.476;395.92;0;0;0;6.670018;6.456994;3516316;4.223279e+008
1416;2.124374;-0.002415995;3831.724;395.9456;0;0;0;6.69094;6.476606;3516544;4.224381e+008
1420;2.13107;-0.00238642;3834.203;396.2018;0;0;0;6.712032;6.496373;3518820;4.22795e+008
1424;2.137766;-0.00224368;3834.568;396.2395;0;0;0;6.733123;6.516136;3519154;4.229188e+008
1428;2.144409;-0.002096902;3832.273;396.0023;0;0;0;6.754045;6.535736;3517048;4.227485e+008
1432;2.151106;-0.002107818;3828.898;395.6535;0;0;0;6.775136;6.555491;3513950;4.224596e+008
1436;2.157802;-0.001942225;3825.486;395.3011;0;0;0;6.796227;6.575242;3510819;4.221666e+008
1440;2.164338;-0.001910651;3820.333;394.7685;0;0;0;6.816812;6.594514;3506090;4.216791e+008
1444;2.171034;-0.002030931;3815.542;394.2734;0;0;0;6.837903;6.614257;3501693;4.212334e+008
1448;2.177731;-0.002046316;3811.171;393.8218;0;0;0;6.858994;6.633997;3497682;4.20834e+008
1452;2.184266;-0.001912885;3806.004;393.2878;0;0;0;6.87958;6.653259;3492939;4.203444e+008
1454.886;2.189195;-0.0016667;3804.024;393.0833;0;0;0;6.895103;6.667782;3491123;4.201868e+008
1458.886;2.182552;-0.001801758;3680.668;380.3364;0;0;0;6.87418;6.648207;3377913;4.064814e+008
1462.886;2.175909;-0.001758797;3568.212;368.7159;0;0;0;6.853258;6.628628;3274707;3.93985e+008
1466.886;2.169213;-0.001587324;3461.562;357.6954;0;0;0;6.832166;6.608888;3176830;3.821338e+008
1470.886;2.162516;-0.001343471;3360.862;347.2898;0;0;0;6.811075;6.589143;3084413;3.70944e+008
1474.886;2.155874;-0.001244809;3264.38;337.32;0;0;0;6.790153;6.569553;2995867;3.602245e+008
1478.886;2.149177;-0.001226209;3174.645;328.0473;0;0;0;6.769063;6.549802;2913514;3.502531e+008
1482.886;2.142534;-0.00119099;3090.156;319.3168;0;0;0;6.74814;6.530204;2835974;3.408647e+008
1486.886;2.135838;-0.001238772;3008.901;310.9203;0;0;0;6.727049;6.510444;2761402;3.318361e+008
1490.886;2.129195;-0.001140012;2931.099;302.8808;0;0;0;6.706126;6.490839;2690000;3.231924e+008
1494.886;2.122552;-0.001213803;2855.918;295.1122;0;0;0;6.685204;6.471229;2621004;3.14841e+008
1498.886;2.115802;-0.001091602;2784.304;287.712;0;0;0;6.663944;6.4513;2555280;3.06885e+008
1502.886;2.109106;-0.001034334;2715.975;280.6513;0;0;0;6.642853;6.431524;2492571;2.992945e+008
1506.886;2.102463;-0.0008888687;2651.479;273.9867;0;0;0;6.621931;6.411903;2433380;2.921299e+008
1510.886;2.095766;-0.001090426;2587.42;267.3673;0;0;0;6.600839;6.39212;2374591;2.850157e+008
1514.886;2.08907;-0.0009017649;2526.801;261.1033;0;0;0;6.579748;6.372332;2318958;2.782833e+008
1518.886;2.082481;-0.001006522;2467.892;255.0161;0;0;0;6.558995;6.352859;2264895;2.717426e+008
1522.886;2.075784;-0.0008473577;2410.124;249.0467;0;0;0;6.537904;6.333064;2211879;2.653291e+008
1526.886;2.069088;-0.0008171162;2353.456;243.1909;0;0;0;6.516812;6.313265;2159871;2.590392e+008
1530.886;2.062552;-0.0006985022;2300.313;237.6994;0;0;0;6.496227;6.293937;2111099;2.531409e+008
1534.886;2.055802;-0.0006360005;2246.783;232.168;0;0;0;6.474967;6.273972;2061973;2.472008e+008
1538.886;2.049106;-0.0007207276;2195.18;226.8357;0;0;0;6.453876;6.254162;2014614;2.414754e+008
1542.886;2.04257;-0.0009151512;2145.302;221.6816;0;0;0;6.433292;6.234823;1968839;2.35943e+008
1546.886;2.03582;-0.0007675108;2095.393;216.5244;0;0;0;6.412032;6.214847;1923036;2.30408e+008
1550.886;2.029177;-0.0007039116;2047.505;211.576;0;0;0;6.391109;6.195183;1879087;2.25098e+008
1554.886;2.022534;-0.0005701473;2001.311;206.8026;0;0;0;6.370187;6.175516;1836693;2.199763e+008
1558.886;2.015892;-0.0007876587;1955.657;202.0849;0;0;0;6.349265;6.155844;1794793;2.149158e+008
1562.886;2.009195;-0.000559897;1911.312;197.5026;0;0;0;6.328173;6.13601;1754096;2.100009e+008
1566.886;2.002552;-0.0006299051;1868.977;193.128;0;0;0;6.307251;6.116331;1715243;2.053091e+008
1570.886;1.995909;-0.0005593286;1827.668;188.8594;0;0;0;6.286328;6.096648;1677332;2.007317e+008
1574.886;1.989213;-0.000494867;1787.118;184.6692;0;0;0;6.265237;6.076802;1640118;1.962392e+008
1578.886;1.982517;-0.0005529197;1747.251;180.5496;0;0;0;6.244147;6.056953;1603530;1.918234e+008
1582.886;1.975874;-0.0005347905;1708.758;176.572;0;0;0;6.223224;6.037258;1568203;1.875605e+008
1586.886;1.969231;-0.0006015844;1670.563;172.6252;0;0;0;6.202302;6.01756;1533150;1.833319e+008
1590.886;1.962481;-0.0005017659;1633.605;168.8062;0;0;0;6.181042;5.99754;1499232;1.792401e+008
1594.886;1.955784;-0.00055535;1597.556;165.0811;0;0;0;6.159951;5.977674;1466148;1.7525e+008
1598.886;1.949195;-0.0007378377;1563.245;161.5357;0;0;0;6.139198;5.958123;1434660;1.714527e+008
1602.886;1.942445;-0.00077782;1528.324;157.9271;0;0;0;6.117938;5.938091;1402611;1.67589e+008
1606.886;1.935802;-0.0005617589;1495.387;154.5237;0;0;0;6.097015;5.918373;1372384;1.63945e+008
1610.886;1.929159;-0.0005043138;1462.419;151.117;0;0;0;6.076093;5.898651;1342128;1.60299e+008
1614.886;1.922409;-0.0005858854;1430.037;147.7708;0;0;0;6.054833;5.878607;1312409;1.56718e+008
1618.886;1.915767;-0.0007210608;1398.249;144.486;0;0;0;6.033911;5.858877;1283235;1.532041e+008
1622.886;1.909124;-0.0007155926;1367.462;141.3047;0;0;0;6.012989;5.839143;1254981;1.498013e+008
1626.886;1.902427;-0.000706479;1336.721;138.1281;0;0;0;5.991897;5.819246;1226768;1.464046e+008
1630.886;1.895731;-0.0007169254;1306.331;134.9879;0;0;0;5.970806;5.799346;1198879;1.430477e+008
1634.886;1.889195;-0.0006943863;1277.207;131.9783;0;0;0;5.950222;5.779919;1172150;1.398313e+008
1638.886;1.882499;-0.0006106;1247.465;128.9049;0;0;0;5.92913;5.76001;1144854;1.365479e+008
1642.886;1.875802;-0.0006298268;1218.68;125.9305;0;0;0;5.908039;5.740098;1118437;1.333705e+008
1646.886;1.869213;-0.000776644;1192.672;123.2431;0;0;0;5.887286;5.7205;1094569;1.304987e+008
1650.886;1.862517;-0.0008430067;1166.217;120.5093;0;0;0;5.866194;5.700579;1070289;1.275786e+008
1654.886;1.85582;-0.000675532;1139.849;117.7847;0;0;0;5.845103;5.680655;1046091;1.246693e+008
1658.886;1.849231;-0.0006741993;1115.214;115.239;0;0;0;5.82435;5.661046;1023481;1.219509e+008
1662.886;1.842588;-0.0007260782;1090.247;112.6591;0;0;0;5.803427;5.641273;1000568;1.191972e+008
1666.886;1.835838;-0.0007265878;1065.861;110.1392;0;0;0;5.782167;5.621177;978187.9;1.165076e+008
1670.886;1.829195;-0.0004659582;1042.221;107.6964;0;0;0;5.761245;5.601396;956492.6;1.13901e+008
1674.886;1.822606;-0.0005499406;1019.277;105.3255;0;0;0;5.740491;5.581771;935436.1;1.113717e+008
1678.886;1.81591;-0.0006021332;996.3926;102.9608;0;0;0;5.7194;5.561823;914433.9;1.088495e+008
1682.886;1.80916;-0.0007694707;973.9124;100.6378;0;0;0;5.698141;5.541711;893802.9;1.063723e+008
1686.886;1.802463;-0.0005928431;952.3416;98.40882;0;0;0;5.677049;5.521755;874006.3;1.039955e+008
1690.886;1.795874;-0.0006771587;931.0738;96.21115;0;0;0;5.656296;5.502115;854487.9;1.016531e+008
1694.886;1.789177;-0.0005789278;910.6755;94.10332;0;0;0;5.635205;5.482151;835767.5;9.940624e+007
1698.886;1.782481;-0.0004253684;890.0992;91.9771;0;0;0;5.614113;5.462183;816883.7;9.71408e+007
1702.886;1.775838;-0.0006031719;870.054;89.90576;0;0;0;5.593191;5.44237;798487.4;9.493436e+007
1706.886;1.769142;-0.0005459424;851.1821;87.95566;0;0;0;5.5721;5.422394;781167.8;9.285664e+007
1710.886;1.762445;-0.0005205223;831.9257;85.96583;0;0;0;5.551009;5.402415;763495.3;9.07378e+007
1714.886;1.755803;-0.0005659531;814.1378;84.12774;0;0;0;5.530087;5.382591;747170.6;8.878008e+007
1718.886;1.749106;-0.0008077674;795.4403;82.19566;0;0;0;5.508996;5.362603;730011;8.672381e+007
1722.886;1.74241;-0.0005450604;778.3362;80.42823;0;0;0;5.487905;5.342611;714313.8;8.484205e+007
1726.886;1.73582;-0.0006365884;761.5447;78.69312;0;0;0;5.467151;5.322935;698903.6;8.299539e+007
1730.886;1.729124;-0.0006454669;745.0491;76.98856;0;0;0;5.44606;5.302935;683764.8;8.11814e+007
1734.886;1.722481;-0.00061158;728.2485;75.25249;0;0;0;5.425138;5.283092;668346.1;7.933505e+007
1738.886;1.715838;-0.0007370733;713.1118;73.68836;0;0;0;5.404215;5.263244;654454.4;7.767064e+007
1742.886;1.709195;-0.0005253241;697.8122;72.1074;0;0;0;5.383293;5.243393;640413.3;7.598915e+007
1746.886;1.702499;-0.0005352413;682.4884;70.52394;0;0;0;5.362202;5.223377;626350;7.430557e+007
1750.886;1.69591;-0.0005807505;668.1095;69.03812;0;0;0;5.341447;5.203677;613153.9;7.272576e+007
1754.886;1.689213;-0.0005201107;654.1713;67.59784;0;0;0;5.320356;5.183653;600362.2;7.119429e+007
1758.886;1.682463;-0.0004739743;640.0635;66.14002;0;0;0;5.299097;5.163465;587414.8;6.964485e+007
1762.886;1.675927;-0.0003788008;627.1723;64.80794;0;0;0;5.278512;5.143915;575584;6.822883e+007
1766.886;1.669231;-0.0002899579;613.6801;63.41373;0;0;0;5.257421;5.123879;563201.6;6.674766e+007
1770.886;1.662535;-0.0002866652;600.436;62.04518;0;0;0;5.23633;5.103839;551046.9;6.529407e+007
1774.886;1.655892;-0.0003626119;587.8899;60.74874;0;0;0;5.215407;5.083956;539532.8;6.391704e+007
1778.886;1.649195;-0.0005731068;575.3927;59.45736;0;0;0;5.194316;5.063908;528063.5;6.254577e+007
1782.886;1.642553;-0.0005161321;563.168;58.19415;0;0;0;5.173394;5.044017;516844.4;6.120476e+007
1786.886;1.635856;-0.0005077633;551.1846;56.95586;0;0;0;5.152302;5.023961;505846.7;5.98904e+007
1790.886;1.62916;-0.0005675798;539.7168;55.77085;0;0;0;5.131212;5.003902;495322.2;5.863257e+007
1794.886;1.622517;-0.0004494558;528.1751;54.5782;0;0;0;5.11029;4.983999;484729.8;5.73673e+007
1798.886;1.61582;-0.0003379954;517.084;53.43212;0;0;0;5.089198;4.963931;474551.1;5.615139e+007
1802.886;1.609124;-0.0003823679;505.9453;52.28111;0;0;0;5.068107;4.943859;464328.5;5.493078e+007
1806.886;1.602535;-0.0004450264;495.5758;51.2096;0;0;0;5.047354;4.924105;454812;5.379433e+007
1810.886;1.588981;-0.0003129281;470.3348;48.60136;0;0;0;5.004665;4.883459;431647.2;5.103369e+007
1814.886;1.575695;-0.0002616567;450.2206;46.52289;0;0;0;4.96282;4.843601;413187.5;4.883174e+007
1818.886;1.562463;-0.0001372413;431.461;44.58439;0;0;0;4.921144;4.803887;395971;4.677846e+007
1822.886;1.544035;-0.0002944461;403.963;41.74292;0;0;0;4.863101;4.748552;370734.8;4.377292e+007
1826.886;1.523999;-0.0002474277;378.1051;39.07093;0;0;0;4.799997;4.688355;347003.9;4.094634e+007
1830.886;1.503963;-0.0002720443;355.0184;36.6853;0;0;0;4.736892;4.628123;325816.2;3.842305e+007
1834.886;1.484035;-0.0003282938;334.0706;34.52069;0;0;0;4.674125;4.568177;306591.5;3.613424e+007
1838.886;1.464106;-0.0002357858;314.4995;32.49835;0;0;0;4.611358;4.508195;288630.3;3.399697e+007
1842.886;1.444178;-0.0002005073;296.3907;30.6271;0;0;0;4.548591;4.448176;272010.9;3.20202e+007
1846.886;1.424196;-0.0001705599;279.5769;28.88967;0;0;0;4.485655;4.38796;256580.2;3.018556e+007
1850.886;1.40416;-0.0001792618;263.734;27.25257;0;0;0;4.422551;4.327547;242040.4;2.845782e+007
1854.886;1.384071;-2.427179e-005;248.5503;25.68358;0;0;0;4.359278;4.266935;228105.7;2.68032e+007
1858.886;1.364035;-0.0001177206;235.0432;24.28785;0;0;0;4.296173;4.206448;215709.7;2.53313e+007
1862.886;1.343999;-3.622728e-005;221.9604;22.93596;0;0;0;4.233068;4.145925;203703;2.390685e+007
1866.886;1.324071;-9.292758e-005;210.0282;21.70296;0;0;0;4.170301;4.085689;192752.2;2.260803e+007
1870.886;1.304089;-1.75101e-005;198.5954;20.52157;0;0;0;4.107366;4.025254;182259.9;2.136447e+007
1874.886;1.284106;0.0001103156;188.1366;19.44082;0;0;0;4.044429;3.964783;172661.3;2.022709e+007
1878.886;1.264178;1.345659e-005;177.9829;18.39161;0;0;0;3.981662;3.904437;163342.9;1.91239e+007
1882.886;1.244196;-2.597691e-005;168.6611;17.42835;0;0;0;3.918726;3.843893;154787.8;1.811132e+007
1886.886;1.22416;-4.849637e-005;159.3489;16.46609;0;0;0;3.855622;3.78315;146241.6;1.710096e+007
1890.886;1.204124;9.271556e-005;151.033;15.60678;0;0;0;3.792517;3.722369;138609.7;1.619867e+007
1894.886;1.184142;0.0001397731;143.4571;14.82393;0;0;0;3.729581;3.661715;131657;1.53768e+007
1898.886;1.16416;0.0002074882;136.1903;14.07303;0;0;0;3.666646;3.601023;124987.9;1.458904e+007
1902.886;1.144178;0.0001034363;129.1971;13.3504;0;0;0;3.60371;3.540295;118570;1.383151e+007
1906.886;1.124196;0.0001275237;122.7798;12.68727;0;0;0;3.540774;3.47953;112680.5;1.31365e+007
1910.886;1.104214;4.616755e-005;116.9289;12.08268;0;0;0;3.477838;3.418728;107310.9;1.250289e+007
1914.886;1.084178;-2.17239e-005;111.3303;11.50416;0;0;0;3.414733;3.357726;102172.8;1.189699e+007
1918.772;1.064624;0.000124133;105.7668;10.92926;0;0;0;3.353148;3.298155;97066.95;1.129574e+007