File: Ensayos/Resistencia/comp/Clavo5/Clavo5a.raw
"Test Type";"Manual"
"Method Name:";"C:\INSTRON\user\template\CYCLE.MTM"
"Name:";""
"Operator ID:";""
"Company:";""
"Lab name:";""
"Test date:";"23/05/2017"
"Temperature:";""
"Humidity:";""
"Note 1:";""
"Note 2:";""
"Note 3:";""
"Geometry:";"Rectangular"
"Specimen";1
"Specimen name:";""
"Width:";0.250000;"in"
"Thickness:";0.060000;"in"
"Length:";1.250000;"in"
"Diameter:";0.039370;"in"
"Inner diameter:";0.019685;"in"
"Outer diameter:";0.039370;"in"
"Wall thickness:";0.019685;"in"
"Area:";0.015000;"in*in"
"Linear density:";1.000000;"den"
"Sled weight:";2.204623;"lbf"
"Loading span:";0.000000;"mm"
"Support span:";1.000000;"mm"
"Span ratio:";"2"
"Fixture type:";"3-point"
"Comment:";""
"Included"
"Final Width:";0.250000;"in"
"Final Thickness:";0.060000;"in"
"Final Length:";1.250000;"in"
"Final Diameter:";0.039370;"in"
"Final Inner diameter:";0.019685;"in"
"Final Outer diameter:";0.039370;"in"
"Final Wall thickness:";0.019685;"in"
"Final Area:";0.015000;"in*in"
"Final Linear density:";1.000000;"den"
"Time sec";"Extension mm";"Strain 1 %";"Load N";"Stress MPa";"Cycle Count ";"Total Cycle Count ";"Repetitions Count ";"Strain [Exten.] %";"True strain %";"Tenacity gf/tex";"True stress Pa"
0;52.81432;0.001207554;9.358312;0.9670275;0;0;0;166.3443;97.96197;8588.54;2575623
7;52.8155;0.001172923;9.888311;1.021794;0;0;0;166.348;97.96337;9074.944;2721529
14;52.81668;0.001060326;10.07431;1.041014;0;0;0;166.3517;97.96476;9245.64;2772758
21;52.81786;0.001210671;10.03226;1.036668;0;0;0;166.3555;97.96615;9207.048;2761223
28;52.81898;0.001214061;10.13574;1.047361;0;0;0;166.359;97.96748;9302.017;2789742
35;52.82022;0.001206222;10.20712;1.054738;0;0;0;166.3629;97.96894;9367.53;2809430
42;52.82139;0.001215453;10.33289;1.067734;0;0;0;166.3666;97.97034;9482.953;2844087
49;52.82252;0.00127331;10.01881;1.035279;0;0;0;166.3701;97.97167;9194.706;2757674
56;52.8237;0.00134126;10.35312;1.069825;0;0;0;166.3739;97.97306;9501.521;2849733
63;52.82482;0.001294183;10.50223;1.085233;0;0;0;166.3774;97.97439;9638.367;2890815
70;52.826;0.001518515;10.43484;1.078269;0;0;0;166.3811;97.97578;9576.52;2872305
77;52.82723;0.001175412;10.3994;1.074607;0;0;0;166.385;97.97724;9543.992;2862591
84.00001;52.82836;0.001302512;10.42624;1.07738;0;0;0;166.3885;97.97857;9568.624;2870017
91.00001;52.82953;0.001239834;10.48391;1.08334;0;0;0;166.3922;97.97996;9621.552;2885932
98.00001;52.83072;0.001258159;10.33856;1.06832;0;0;0;166.396;97.98135;9488.154;2845960
105;52.83184;0.001230231;10.82912;1.119011;0;0;0;166.3995;97.98269;9938.365;2981040
112;52.83302;0.001285187;10.71192;1.106901;0;0;0;166.4032;97.98408;9830.811;2948820
119;52.83425;0.001194501;10.40789;1.075484;0;0;0;166.4071;97.98554;9551.78;2865165
126;52.83538;0.001298044;10.66638;1.102195;0;0;0;166.4106;97.98687;9789.013;2936364
133;52.83656;0.001358409;10.36757;1.071318;0;0;0;166.4144;97.98826;9514.779;2854144
140;52.83768;0.001286676;10.67851;1.103448;0;0;0;166.4179;97.98959;9800.143;2939783
147;52.83886;0.001310724;10.50417;1.085433;0;0;0;166.4216;97.99099;9640.146;2891829
154;52.83998;0.001406094;10.58202;1.093477;0;0;0;166.4251;97.99231;9711.589;2913298
161;52.84116;0.00127182;10.73515;1.109301;0;0;0;166.4288;97.99371;9852.128;2955499
168;52.8424;0.001192032;10.72476;1.108227;0;0;0;166.4327;97.99516;9842.588;2952680
175;52.84352;0.001307882;10.67584;1.103172;0;0;0;166.4363;97.9965;9797.691;2939250
182;52.8447;0.001271448;10.60985;1.096354;0;0;0;166.44;97.99788;9737.136;2921125
189;52.84582;0.00145566;10.63534;1.098988;0;0;0;166.4435;97.99922;9760.527;2928181
196;52.847;0.001423988;10.66159;1.1017;0;0;0;166.4473;98.00061;9784.62;2935450
203;52.84823;0.001195207;10.56945;1.092179;0;0;0;166.4511;98.00207;9700.055;2910122
210;52.84936;0.001326972;10.73462;1.109247;0;0;0;166.4547;98.00339;9851.643;2955640
217;52.85054;0.001248438;10.60495;1.095847;0;0;0;166.4584;98.00479;9732.636;2919977
224;52.85172;0.001129805;10.51468;1.086519;0;0;0;166.4621;98.00618;9649.794;2895163
231;52.85284;0.001310705;10.66861;1.102425;0;0;0;166.4656;98.00751;9791.062;2937585
238;52.85402;0.00115448;10.63502;1.098954;0;0;0;166.4693;98.0089;9760.232;2928376
245;52.85515;0.001334439;10.70082;1.105754;0;0;0;166.4729;98.01024;9820.624;2946535
252;52.85632;0.001281345;10.7506;1.110897;0;0;0;166.4766;98.01163;9866.303;2960281
259;52.85755;0.001165769;10.66518;1.10207;0;0;0;166.4805;98.01308;9787.908;2936803
266;52.85874;0.001140016;10.50446;1.085464;0;0;0;166.4842;98.01448;9640.416;2892589
273;52.85986;0.001266822;10.66412;1.101961;0;0;0;166.4877;98.01581;9786.938;2936592
280;52.86109;0.001345101;10.55236;1.090413;0;0;0;166.4916;98.01726;9684.37;2905858
287;52.86216;0.001206182;10.86218;1.122428;0;0;0;166.495;98.01853;9968.709;2991214
294;52.8634;0.001339378;10.91287;1.127665;0;0;0;166.4989;98.01999;10015.22;3005215
301;52.86457;0.00131729;10.93369;1.129816;0;0;0;166.5026;98.02138;10034.33;3010990
308;52.8657;0.001296868;11.12746;1.14984;0;0;0;166.5061;98.02271;10212.17;3064394
315;52.86688;0.001399371;11.14896;1.152061;0;0;0;166.5099;98.0241;10231.89;3070356
322;52.868;0.001356038;10.72667;1.108424;0;0;0;166.5134;98.02543;9844.339;2954099
329;52.86918;0.001314644;11.12112;1.149185;0;0;0;166.5171;98.02682;10206.35;3062773
336;52.87031;0.001370717;11.07842;1.144773;0;0;0;166.5206;98.02815;10167.16;3051055
343;52.87154;0.001294967;11.04057;1.140861;0;0;0;166.5245;98.02961;10132.43;3040675
350;52.87271;0.001206947;11.29951;1.167618;0;0;0;166.5282;98.031;10370.06;3112032
357;52.87384;0.001365073;11.45388;1.18357;0;0;0;166.5318;98.03233;10511.73;3154589
364;52.87502;0.001514536;11.68201;1.207143;0;0;0;166.5355;98.03372;10721.1;3217465
371;52.87614;0.001573471;11.67622;1.206546;0;0;0;166.539;98.03505;10715.79;3215915
378;52.87732;0.001702002;11.14352;1.1515;0;0;0;166.5428;98.03645;10226.91;3069239
385;52.87856;0.001436786;10.65023;1.100526;0;0;0;166.5466;98.03791;9774.191;2933415
392;52.87973;0.001526295;10.82606;1.118696;0;0;0;166.5503;98.03929;9935.563;2981887
399;52.88086;0.001545855;10.68776;1.104404;0;0;0;166.5539;98.04063;9808.632;2943832
406;52.88199;0.001388239;11.11014;1.14805;0;0;0;166.5574;98.04196;10196.27;3060212
413;52.88316;0.001296103;11.45746;1.18394;0;0;0;166.5611;98.04334;10515.02;3155923
420;52.88434;0.001256494;11.61421;1.200137;0;0;0;166.5648;98.04474;10658.88;3199144
427;52.88557;0.001320308;11.54699;1.193191;0;0;0;166.5687;98.04619;10597.19;3180675
434;52.8867;0.001096584;11.45156;1.18333;0;0;0;166.5723;98.04752;10509.6;3154430
441;52.88788;0.001352;10.95418;1.131934;0;0;0;166.576;98.04892;10053.14;3017465
448;52.889;0.001340378;11.4949;1.187809;0;0;0;166.5795;98.05025;10549.38;3166455
455;52.89018;0.00131388;11.41491;1.179543;0;0;0;166.5833;98.05164;10475.97;3144464
462;52.89141;0.001329755;11.50811;1.189174;0;0;0;166.5871;98.05309;10561.51;3170185
469;52.89259;0.001364759;11.68307;1.207253;0;0;0;166.5908;98.05448;10722.07;3218425
476;52.89372;0.001512125;11.6022;1.198896;0;0;0;166.5944;98.05581;10647.85;3196189
483;52.89489;0.001612473;11.72168;1.211243;0;0;0;166.5981;98.05721;10757.51;3229150
490;52.89602;0.001535331;11.55841;1.194372;0;0;0;166.6016;98.05854;10607.67;3184215
497;52.89715;0.001448291;11.41561;1.179616;0;0;0;166.6052;98.05987;10476.62;3144917
504;52.89843;0.001697376;11.48547;1.186834;0;0;0;166.6092;98.06139;10540.73;3164210
511;52.89956;0.001655434;11.59471;1.198122;0;0;0;166.6128;98.06271;10640.98;3194347
518;52.90068;0.0015388;11.61156;1.199864;0;0;0;166.6163;98.06404;10656.45;3199033
525;52.90186;0.00139994;11.87766;1.227361;0;0;0;166.62;98.06544;10900.66;3272390
532;52.90303;0.001618274;11.79853;1.219184;0;0;0;166.6237;98.06682;10828.03;3250633
539;52.90416;0.0017011;11.84102;1.223574;0;0;0;166.6273;98.06815;10867.03;3262383
546;52.90534;0.001592051;11.82202;1.221611;0;0;0;166.631;98.06955;10849.59;3257194
553;52.90657;0.001436159;11.91111;1.230817;0;0;0;166.6349;98.071;10931.36;3281788
560;52.9077;0.001527785;11.58672;1.197297;0;0;0;166.6384;98.07233;10633.65;3192454
567;52.90888;0.001549168;11.73865;1.212997;0;0;0;166.6421;98.07373;10773.08;3234360
574;52.91;0.001615334;12.03544;1.243665;0;0;0;166.6457;98.07505;11045.46;3316178
581;52.91118;0.001502208;12.07006;1.247242;0;0;0;166.6494;98.07644;11077.23;3325763
588;52.91241;0.00136129;12.14051;1.254521;0;0;0;166.6533;98.07789;11141.88;3345222
595;52.91354;0.001448879;11.9901;1.238979;0;0;0;166.6568;98.07923;11003.85;3303823
602;52.91471;0.001385613;12.232;1.263976;0;0;0;166.6605;98.08062;11225.86;3370526
609;52.9159;0.001477513;12.30225;1.271235;0;0;0;166.6642;98.08201;11290.32;3389928
616;52.91702;0.0014752;12.10609;1.250965;0;0;0;166.6678;98.08335;11110.3;3335921
623;52.9182;0.001674367;12.04369;1.244517;0;0;0;166.6715;98.08473;11053.03;3318772
630;52.91943;0.001716838;12.54133;1.29594;0;0;0;166.6754;98.08619;11509.74;3455953
637;52.92056;0.001569982;12.13325;1.253772;0;0;0;166.6789;98.08752;11135.23;3343545
644.0001;52.92173;0.001634404;12.30791;1.27182;0;0;0;166.6826;98.08891;11295.52;3391723
651.0001;52.92291;0.001574666;12.40555;1.281909;0;0;0;166.6863;98.0903;11385.13;3418677
658.0001;52.92404;0.001559242;12.36009;1.277212;0;0;0;166.6899;98.09163;11343.41;3406196
665.0001;52.92516;0.001468694;12.5909;1.301062;0;0;0;166.6934;98.09296;11555.23;3469847
672.0001;52.92634;0.001468968;12.52867;1.294632;0;0;0;166.6971;98.09435;11498.12;3452747
679.0001;52.92747;0.001554479;12.34779;1.275941;0;0;0;166.7007;98.09568;11332.12;3402943
686.0001;52.9287;0.001656826;12.37522;1.278775;0;0;0;166.7046;98.09714;11357.29;3410551
693.0001;52.92987;0.001554891;12.66214;1.308423;0;0;0;166.7083;98.09852;11620.61;3489673
700.0001;52.93105;0.00155981;12.61818;1.303881;0;0;0;166.712;98.09992;11580.26;3477606
707.0001;52.93218;0.001522709;12.76333;1.31888;0;0;0;166.7155;98.10125;11713.47;3517657
714.0001;52.93336;0.001670526;12.76794;1.319356;0;0;0;166.7192;98.10264;11717.7;3518976
721.0001;52.93448;0.001455582;12.81985;1.324721;0;0;0;166.7228;98.10397;11765.35;3533332
728.0001;52.93566;0.001443332;13.05594;1.349117;0;0;0;166.7265;98.10536;11982.02;3598452
735.0001;52.9369;0.001509499;12.92439;1.335523;0;0;0;166.7304;98.10682;11861.29;3562245
742.0001;52.93802;0.001651338;12.63113;1.305219;0;0;0;166.7339;98.10814;11592.15;3481462
749.0001;52.9392;0.001501581;13.07685;1.351277;0;0;0;166.7376;98.10953;12001.21;3604365
756.0001;52.94038;0.0013471;13.25324;1.369504;0;0;0;166.7413;98.11093;12163.09;3653035
763.0001;52.9415;0.001400822;13.30774;1.375136;0;0;0;166.7449;98.11225;12213.11;3668105
770.0001;52.94273;0.001483236;13.50213;1.395223;0;0;0;166.7488;98.11371;12391.51;3721741
777.0001;52.94391;0.00150309;13.58435;1.403719;0;0;0;166.7525;98.1151;12466.97;3744457
784.0001;52.94504;0.001304982;13.38644;1.383268;0;0;0;166.756;98.11643;12285.33;3689951
791.0001;52.94621;0.00145811;13.53678;1.398804;0;0;0;166.7597;98.11782;12423.31;3731446
798.0001;52.94734;0.001442979;13.73676;1.419468;0;0;0;166.7633;98.11915;12606.83;3786619
805.0001;52.94852;0.00137791;13.91823;1.43822;0;0;0;166.767;98.12055;12773.38;3836696
812.0001;52.94975;0.001464558;13.95408;1.441925;0;0;0;166.7709;98.12199;12806.28;3846635
819.0001;52.95088;0.001420538;14.09627;1.456617;0;0;0;166.7744;98.12332;12936.77;3885882
826.0001;52.95206;0.001202263;14.31806;1.479535;0;0;0;166.7781;98.12472;13140.32;3947077
833.0001;52.95318;0.001303688;14.04773;1.451601;0;0;0;166.7817;98.12604;12892.22;3872606
840.0001;52.95436;0.001478924;14.36968;1.48487;0;0;0;166.7854;98.12743;13187.69;3961415
847.0001;52.95549;0.001584701;14.88925;1.538559;0;0;0;166.7889;98.12876;13664.53;4104705
854.0001;52.95666;0.00167958;14.9814;1.548081;0;0;0;166.7926;98.13015;13749.1;4130166
861.0001;52.95789;0.001525982;14.96011;1.545881;0;0;0;166.7965;98.13161;13729.56;4124356
868.0001;52.95907;0.001682364;15.20891;1.571591;0;0;0;166.8002;98.133;13957.9;4193008
875.0001;52.9602;0.001499778;15.64459;1.616611;0;0;0;166.8038;98.13433;14357.74;4313180
882.0001;52.96138;0.001701375;16.39571;1.694226;0;0;0;166.8075;98.13572;15047.07;4520323
889.0001;52.9625;0.001610768;16.13057;1.666829;0;0;0;166.811;98.13705;14803.75;4447285
896.0001;52.96374;0.001660667;16.43764;1.698559;0;0;0;166.8149;98.13851;15085.55;4532010
903.0001;52.96491;0.001503913;16.68134;1.723741;0;0;0;166.8186;98.13989;15309.21;4599263
910.0001;52.96604;0.001523179;17.1122;1.768264;0;0;0;166.8222;98.14122;15704.63;4718121
917.0001;52.96722;0.00150407;17.39084;1.797057;0;0;0;166.8259;98.14261;15960.35;4795013
924.0001;52.96834;0.001518907;17.7564;1.834831;0;0;0;166.8294;98.14394;16295.84;4895870
931.0001;52.96952;0.001645811;18.02758;1.862853;0;0;0;166.8331;98.14533;16544.71;4970710
938.0001;52.97065;0.001461167;18.43143;1.904585;0;0;0;166.8367;98.14666;16915.34;5082130
945.0001;52.97182;0.001616354;18.98847;1.962146;0;0;0;166.8404;98.14805;17426.57;5235797
952.0001;52.97306;0.001807798;19.57503;2.022757;0;0;0;166.8443;98.1495;17964.87;5397610
959.0001;52.97423;0.001630602;19.93856;2.060322;0;0;0;166.848;98.15089;18298.5;5497927
966.0001;52.97536;0.001714937;20.469;2.115134;0;0;0;166.8515;98.15222;18785.31;5644267
973.0001;52.97653;0.00182285;20.64119;2.132927;0;0;0;166.8552;98.15361;18943.34;5691828
980.0001;52.97766;0.001628446;21.69578;2.241902;0;0;0;166.8588;98.15494;19911.19;5982713
987.0001;52.97889;0.001626173;22.37492;2.31208;0;0;0;166.8627;98.1564;20534.47;6170079
994.0001;52.98007;0.001576704;22.98192;2.374803;0;0;0;166.8664;98.15778;21091.53;6337550
1001;52.9812;0.001420068;23.77091;2.456332;0;0;0;166.8699;98.15912;21815.63;6555212
1008;52.98233;0.001526393;24.27263;2.508177;0;0;0;166.8735;98.16045;22276.08;6693659
1015;52.9835;0.001595931;25.16235;2.600114;0;0;0;166.8772;98.16183;23092.61;6939111
1022;52.98468;0.001671721;25.64231;2.64971;0;0;0;166.8809;98.16322;23533.09;7071570
1029;52.98581;0.001618;26.22531;2.709954;0;0;0;166.8844;98.16455;24068.13;7232445
1036;52.98704;0.001545052;27.21985;2.812724;0;0;0;166.8883;98.16601;24980.87;7506831
1043;52.98821;0.001504482;28.07116;2.900692;0;0;0;166.892;98.16739;25762.15;7741715
1050;52.9894;0.001637383;29.13627;3.010753;0;0;0;166.8957;98.16879;26739.65;8035573
1057;52.99052;0.001675994;29.74173;3.073318;0;0;0;166.8993;98.17012;27295.31;8202665
1064;52.99164;0.00151336;30.45399;3.146919;0;0;0;166.9028;98.17144;27948.99;8399215
1071;52.99282;0.001478748;31.25978;3.230184;0;0;0;166.9065;98.17283;28688.5;8621572
1078;52.99406;0.00164048;31.89006;3.295313;0;0;0;166.9104;98.17429;29266.93;8795533
1085;52.99523;0.00177152;32.69902;3.378906;0;0;0;166.9141;98.17568;30009.35;9018777
1092;52.99636;0.001686166;33.2509;3.435933;0;0;0;166.9177;98.177;30515.83;9171112
1099;52.99754;0.001554753;33.91263;3.504312;0;0;0;166.9214;98.1784;31123.13;9353758
1106;52.99866;0.001739671;34.76722;3.59262;0;0;0;166.9249;98.17972;31907.43;9589598
1113;52.99984;0.001687028;35.04962;3.621801;0;0;0;166.9286;98.18111;32166.6;9667625
1120;53.00107;0.001545561;35.68509;3.687467;0;0;0;166.9325;98.18257;32749.8;9843049
1127;53.00215;0.001626898;36.28695;3.749659;0;0;0;166.9359;98.18384;33302.15;1.000919e+007
1134;53.00337;0.001505305;36.87403;3.810324;0;0;0;166.9398;98.18528;33840.94;1.017127e+007
1141;53.0045;0.001598793;37.53391;3.878511;0;0;0;166.9433;98.18661;34446.54;1.035343e+007
1148;53.00568;0.001546698;37.91227;3.917609;0;0;0;166.947;98.188;34793.78;1.045794e+007
1155;53.00686;0.001543621;38.72849;4.001952;0;0;0;166.9507;98.18939;35542.86;1.068324e+007
1162;53.00804;0.001533684;38.35327;3.963179;0;0;0;166.9544;98.19078;35198.5;1.057988e+007
1169;53.00922;0.001452759;39.30097;4.061109;0;0;0;166.9582;98.19218;36068.25;1.084146e+007
1176;53.0104;0.001576018;39.37292;4.068543;0;0;0;166.9619;98.19357;36134.28;1.086146e+007
1183;53.01152;0.001566964;39.75395;4.107916;0;0;0;166.9654;98.19489;36483.97;1.096672e+007
1190;53.0127;0.001474906;39.84263;4.11708;0;0;0;166.9691;98.19628;36565.36;1.099133e+007
1197;53.01393;0.001661392;40.14162;4.147975;0;0;0;166.973;98.19774;36839.75;1.107398e+007
1204;53.015;0.00154121;40.10976;4.144683;0;0;0;166.9764;98.199;36810.51;1.106533e+007
1211;53.01623;0.001441745;40.32391;4.166813;0;0;0;166.9803;98.20045;37007.05;1.112457e+007
1218;53.01736;0.001376205;41.02792;4.239561;0;0;0;166.9838;98.20178;37653.16;1.131894e+007
1225;53.01854;0.001512478;41.53596;4.292058;0;0;0;166.9875;98.20317;38119.4;1.145926e+007
1232;53.01966;0.001485176;41.82147;4.321561;0;0;0;166.9911;98.2045;38381.43;1.153818e+007
1239;53.02084;0.001440216;42.30739;4.371773;0;0;0;166.9948;98.20589;38827.38;1.167241e+007
1246;53.02208;0.001656708;42.68664;4.410961;0;0;0;166.9987;98.20735;39175.43;1.177721e+007
1253;53.02314;0.001556772;42.55291;4.397143;0;0;0;167.002;98.2086;39052.7;1.174046e+007
1260;53.02438;0.001561339;42.8282;4.42559;0;0;0;167.0059;98.21006;39305.35;1.181659e+007
1267;53.0255;0.001476749;43.06761;4.450328;0;0;0;167.0095;98.21139;39525.07;1.18828e+007
1274;53.02668;0.001498621;43.14322;4.458142;0;0;0;167.0132;98.21278;39594.46;1.190383e+007
1281;53.02781;0.001628093;43.79426;4.525416;0;0;0;167.0167;98.21411;40191.95;1.208362e+007
1288;53.02899;0.001482452;43.96384;4.54294;0;0;0;167.0204;98.2155;40347.58;1.213058e+007
1295;53.03022;0.001486548;44.26653;4.574217;0;0;0;167.0243;98.21695;40625.37;1.221427e+007
1302;53.03139;0.001356782;44.25713;4.573246;0;0;0;167.028;98.21834;40616.75;1.221185e+007
1309;53.03252;0.001532469;44.16534;4.563761;0;0;0;167.0316;98.21967;40532.5;1.218668e+007
1316;53.0337;0.001574176;44.44369;4.592524;0;0;0;167.0353;98.22106;40787.95;1.226366e+007
1323;53.03493;0.001514712;44.12053;4.559131;0;0;0;167.0391;98.22251;40491.38;1.217466e+007
1330;53.036;0.001587033;44.21602;4.568998;0;0;0;167.0425;98.22377;40579.02;1.220117e+007
1337;53.03723;0.001584505;44.33198;4.580981;0;0;0;167.0464;98.22522;40685.44;1.223334e+007
1342.638;53.03718;0.001581075;44.03508;4.550301;0;0;0;167.0462;98.22516;40412.96;1.215141e+007
1349.638;53.03595;0.001625036;44.34405;4.582228;0;0;0;167.0424;98.22371;40696.52;1.223649e+007
1356.638;53.03477;0.00167715;44.21077;4.568455;0;0;0;167.0387;98.22232;40574.19;1.219954e+007
1363.638;53.03364;0.001551696;44.10884;4.557923;0;0;0;167.0351;98.22099;40480.65;1.217125e+007
1370.638;53.03187;0.001523512;44.12018;4.559094;0;0;0;167.0295;98.2189;40491.05;1.217413e+007
1377.638;53.02014;0.001800625;42.81807;4.424543;0;0;0;166.9926;98.20507;39296.05;1.18132e+007
1384.638;53.00857;0.001810326;38.34272;3.962089;0;0;0;166.9561;98.19142;35188.83;1.057704e+007
1391.638;52.99684;0.001896445;28.36386;2.930938;0;0;0;166.9192;98.17757;26030.78;7823237
1398.638;52.98521;0.001860206;18.66484;1.928705;0;0;0;166.8826;98.16385;17129.56;5147376
1405.638;52.97348;0.002076248;14.03252;1.450029;0;0;0;166.8456;98.15001;12878.26;3869340
1412.638;52.97048;0.001886645;14.21408;1.468791;0;0;0;166.8362;98.14646;13044.89;3919265
1419.638;52.96936;0.001961671;14.35362;1.48321;0;0;0;166.8326;98.14514;13172.95;3957688
1426.638;52.96818;0.001985915;14.29119;1.476759;0;0;0;166.8289;98.14375;13115.66;3940420
1433.638;52.96695;0.002016;14.73638;1.522762;0;0;0;166.825;98.14229;13524.23;4063111
1440.638;52.96588;0.001857423;14.87551;1.537139;0;0;0;166.8217;98.14103;13651.92;4101420
1447.638;52.96465;0.002104078;14.85719;1.535246;0;0;0;166.8178;98.13958;13635.1;4096308
1454.638;52.96352;0.001895426;14.8805;1.537655;0;0;0;166.8142;98.13824;13656.5;4102682
1461.638;52.96234;0.001842998;14.99391;1.549373;0;0;0;166.8105;98.13686;13760.58;4133891
1468.638;52.96122;0.001998106;14.97318;1.547231;0;0;0;166.807;98.13553;13741.55;4128121
1475.638;52.96004;0.001955752;14.6827;1.517216;0;0;0;166.8033;98.13414;13474.97;4047981
1482.638;52.9588;0.001908009;14.8369;1.533149;0;0;0;166.7994;98.13268;13616.48;4090432
1489.638;52.95774;0.001951225;14.4524;1.493417;0;0;0;166.796;98.13142;13263.61;3984378
1496.638;52.9565;0.00202868;14.43181;1.49129;0;0;0;166.7921;98.12996;13244.72;3978645
1503.638;52.95532;0.002074719;14.1897;1.466272;0;0;0;166.7884;98.12857;13022.52;3911845
1510.638;52.9542;0.001883274;14.03266;1.450045;0;0;0;166.7849;98.12725;12878.4;3868500
1517.638;52.95302;0.001821125;14.05099;1.451938;0;0;0;166.7812;98.12585;12895.22;3873497
1524.638;52.95189;0.002086655;13.95764;1.442292;0;0;0;166.7776;98.12452;12809.54;3847712
1531.638;52.95072;0.001954968;13.43369;1.38815;0;0;0;166.7739;98.12313;12328.69;3703223
1538.638;52.94948;0.00198225;13.34527;1.379014;0;0;0;166.77;98.12168;12247.55;3678796
1545.638;52.94836;0.002045418;13.13358;1.357139;0;0;0;166.7665;98.12035;12053.27;3620393
1552.638;52.94718;0.002138357;13.29074;1.373379;0;0;0;166.7628;98.11896;12197.5;3663664
1559.638;52.94606;0.001870809;12.57445;1.299363;0;0;0;166.7592;98.11763;11540.14;3466170
1566.638;52.94488;0.00192163;12.7667;1.319229;0;0;0;166.7555;98.11624;11716.57;3519115
1573.638;52.94364;0.00187271;12.52403;1.294153;0;0;0;166.7516;98.11478;11493.87;3452174
1580.638;52.94247;0.001726187;12.48936;1.290569;0;0;0;166.7479;98.11339;11462.04;3442567
1587.638;52.94134;0.001762112;12.42663;1.284088;0;0;0;166.7444;98.11206;11404.47;3425232
1594.638;52.94021;0.001570923;12.40235;1.281579;0;0;0;166.7408;98.11073;11382.19;3418493
1601.638;52.93904;0.001580154;12.27919;1.268853;0;0;0;166.7371;98.10935;11269.16;3384501
1608.638;52.93791;0.001453563;11.94688;1.234513;0;0;0;166.7336;98.10801;10964.18;3292861
1615.638;52.93663;0.001523199;11.6419;1.202998;0;0;0;166.7295;98.1065;10684.29;3208752
1622.638;52.93556;0.001611552;11.82217;1.221626;0;0;0;166.7262;98.10523;10849.73;3258397
1629.638;52.93433;0.001571824;11.57865;1.196463;0;0;0;166.7223;98.10378;10626.24;3191232
1636.638;52.9332;0.001701531;11.38384;1.176333;0;0;0;166.7187;98.10245;10447.46;3137500
1643.638;52.93202;0.001747335;11.20075;1.157414;0;0;0;166.715;98.10105;10279.43;3086996
1650.638;52.93089;0.001714428;11.34934;1.172767;0;0;0;166.7115;98.09973;10415.79;3127905
1657.638;52.92972;0.001748648;11.00357;1.137038;0;0;0;166.7078;98.09834;10098.47;3032569
1664.638;52.92848;0.001702159;10.86083;1.122288;0;0;0;166.7039;98.09688;9967.47;2993186
1671.638;52.9273;0.001428555;10.70038;1.105709;0;0;0;166.7002;98.09549;9820.221;2948927
1678.638;52.92618;0.001354529;10.44054;1.078858;0;0;0;166.6966;98.09416;9581.748;2877278
1685.638;52.925;0.00150701;10.37347;1.071927;0;0;0;166.6929;98.09277;9520.196;2858754
1692.638;52.92388;0.001546071;10.26978;1.061213;0;0;0;166.6894;98.09144;9425.039;2830143
1699.638;52.92265;0.001637462;10.31633;1.066023;0;0;0;166.6855;98.08999;9467.753;2842928
1706.638;52.92152;0.001805642;10.26788;1.061016;0;0;0;166.682;98.08866;9423.287;2829538
1713.638;52.92034;0.001832277;10.0899;1.042625;0;0;0;166.6782;98.08726;9259.949;2780453
1720.638;52.91916;0.001779987;10.12766;1.046527;0;0;0;166.6745;98.08588;9294.605;2790821
1727.638;52.91804;0.001750823;10.13838;1.047634;0;0;0;166.671;98.08454;9304.441;2793737
1734.638;52.91686;0.00162974;10.27454;1.061705;0;0;0;166.6673;98.08315;9429.404;2831219
1741.638;52.91563;0.00163948;10.42694;1.077453;0;0;0;166.6634;98.0817;9569.271;2873172
1748.638;52.91455;0.001532156;10.5284;1.087937;0;0;0;166.66;98.08043;9662.379;2901092
1755.638;52.91332;0.001523767;10.58161;1.093435;0;0;0;166.6561;98.07897;9711.211;2915711
1761.554;52.9137;0.001384986;11.27055;1.164626;1;1;0;166.6573;98.07942;10343.49;3105561
1768.554;52.91482;0.001359213;12.08783;1.249078;1;1;0;166.6609;98.08075;11093.54;3330802
1775.554;52.916;0.001364171;12.65709;1.307901;1;1;0;166.6646;98.08214;11615.97;3487710
1782.554;52.91712;0.001682481;13.59296;1.404608;1;1;0;166.6681;98.08347;12474.86;3745643
1789.554;52.91836;0.001719249;13.86082;1.432288;1;1;0;166.672;98.08492;12720.69;3819510
1796.554;52.91954;0.001560261;14.53937;1.502405;1;1;0;166.6757;98.08632;13343.43;4006549
1803.554;52.92066;0.001553499;15.06036;1.55624;1;1;0;166.6793;98.08765;13821.56;4150170
1810.554;52.92184;0.001591286;15.31956;1.583024;1;1;0;166.683;98.08904;14059.44;4221656
1817.554;52.92296;0.001457267;15.87502;1.640422;1;1;0;166.6865;98.09036;14569.21;4374783
1824.554;52.92414;0.001345983;16.4984;1.704838;1;1;0;166.6902;98.09175;15141.31;4546635
1831.554;52.92538;0.00142536;16.95774;1.752304;1;1;0;166.6941;98.09321;15562.88;4673290
1838.554;52.92655;0.00161018;17.16453;1.773671;1;1;0;166.6978;98.0946;15752.65;4730343
1845.554;52.92768;0.001834884;17.21724;1.779118;1;1;0;166.7013;98.09593;15801.03;4744931
1852.554;52.92886;0.00143757;17.45435;1.80362;1;1;0;166.7051;98.09733;16018.64;4810347
1859.554;52.92999;0.001574078;17.40781;1.798811;1;1;0;166.7086;98.09866;15975.92;4797583
1866.554;52.93116;0.00161947;17.2049;1.777843;1;1;0;166.7123;98.10004;15789.71;4741727
1873.554;52.93239;0.001470555;16.91596;1.747986;1;1;0;166.7162;98.1015;15524.53;4662161
1880.554;52.93352;0.001466792;16.65764;1.721293;1;1;0;166.7198;98.10283;15287.46;4591027
1887.554;52.9347;0.001414835;16.30967;1.685336;1;1;0;166.7235;98.10422;14968.11;4495186
1894.554;52.93588;0.001435669;16.18851;1.672816;1;1;0;166.7272;98.10561;14856.92;4461855
1901.554;52.937;0.001251515;15.99482;1.652802;1;1;0;166.7307;98.10695;14679.16;4408530
1908.554;52.93813;0.001411954;15.82328;1.635075;1;1;0;166.7343;98.10827;14521.73;4361306
1915.554;52.93941;0.001332832;15.63981;1.616117;1;1;0;166.7383;98.10979;14353.35;4310802
1922.554;52.94054;0.001406407;15.61905;1.613971;1;1;0;166.7419;98.11112;14334.29;4305137
1929.554;52.94167;0.001422577;15.56575;1.608464;1;1;0;166.7454;98.11245;14285.38;4290504
1936.554;52.94284;0.001351393;15.338;1.58493;1;1;0;166.7491;98.11383;14076.37;4227786
1943.554;52.94402;0.001336458;15.41411;1.592795;1;1;0;166.7528;98.11522;14146.22;4248825
1950.554;52.94514;0.001361604;15.39553;1.590874;1;1;0;166.7564;98.11655;14129.16;4243758
1957.554;52.94632;0.001317172;15.09654;1.559978;1;1;0;166.7601;98.11794;13854.76;4161400
1964.554;52.94756;0.001223528;15.39376;1.590692;1;1;0;166.764;98.1194;14127.54;4243393
1971.554;52.94868;0.001636011;15.43578;1.595034;1;1;0;166.7675;98.12073;14166.11;4255033
1978.554;52.94986;0.001342495;15.1819;1.568799;1;1;0;166.7712;98.12212;13933.11;4185105
1985.554;52.95098;0.001394746;15.33847;1.584978;1;1;0;166.7747;98.12345;14076.8;4228322
1992.554;52.95216;0.00141021;15.28749;1.579711;1;1;0;166.7785;98.12484;14030.01;4214328
1999.554;52.9534;0.001316428;15.31697;1.582757;1;1;0;166.7823;98.1263;14057.07;4222517
2006.554;52.95457;0.001356782;15.5434;1.606155;1;1;0;166.7861;98.12769;14264.88;4284998
2013.554;52.9557;0.00154956;15.62151;1.614226;1;1;0;166.7896;98.12901;14336.56;4306588
2020.554;52.95688;0.001352118;15.63393;1.61551;1;1;0;166.7933;98.13041;14347.96;4310072
2027.554;52.958;0.001272486;15.73741;1.626203;1;1;0;166.7968;98.13173;14442.93;4338658
2034.554;52.95918;0.001233504;15.79018;1.631655;1;1;0;166.8006;98.13312;14491.35;4353266
2041.554;52.96041;0.00120044;15.84448;1.637266;1;1;0;166.8044;98.13458;14541.18;4368298
2048.554;52.96148;0.001310391;15.82157;1.634899;1;1;0;166.8078;98.13584;14520.16;4362039
2055.554;52.96271;0.001225135;16.06113;1.659653;1;1;0;166.8117;98.1373;14740.01;4428149
2062.554;52.96384;0.001250555;16.03526;1.65698;1;1;0;166.8152;98.13863;14716.27;4421075
2069.554;52.96502;0.001191503;16.08233;1.661844;1;1;0;166.819;98.14002;14759.47;4434115
2076.554;52.96614;0.001155401;16.03596;1.657053;1;1;0;166.8225;98.14135;14716.92;4421390
2083.554;52.96732;0.001150227;16.176;1.671524;1;1;0;166.8262;98.14274;14845.44;4460063
2090.554;52.96856;0.001349178;16.08841;1.662472;1;1;0;166.8301;98.14419;14765.05;4435976
2097.554;52.96974;0.001362819;16.3334;1.687788;1;1;0;166.8338;98.14558;14989.89;4503588
2104.554;52.97086;0.001237522;16.31754;1.686149;1;1;0;166.8373;98.14691;14975.33;4499275
2111.554;52.97204;0.001287989;16.62463;1.717882;1;1;0;166.841;98.14829;15257.17;4584014
2118.554;52.97316;0.001364191;16.67487;1.723074;1;1;0;166.8446;98.14963;15303.28;4597929
2125.554;52.97434;0.001312469;16.65969;1.721505;1;1;0;166.8483;98.15102;15289.34;4593807
2132.554;52.97547;0.001249771;16.75648;1.731506;1;1;0;166.8519;98.15235;15378.17;4620557
2139.554;52.9767;0.001233778;16.8986;1.746192;1;1;0;166.8558;98.15381;15508.6;4659815
2146.554;52.97787;0.001362309;16.74256;1.730068;1;1;0;166.8595;98.15519;15365.39;4616850
2153.554;52.979;0.00132021;17.06842;1.76374;1;1;0;166.863;98.15652;15664.45;4706769
2160.554;52.98018;0.00137744;17.11193;1.768237;1;1;0;166.8667;98.15791;15704.39;4718835
2167.554;52.98136;0.001198127;17.27229;1.784807;1;1;0;166.8704;98.1593;15851.55;4763123
2174.554;52.98248;0.001082002;17.39366;1.797348;1;1;0;166.874;98.16063;15962.94;4796654
2181.554;52.98371;0.001279013;17.4281;1.800907;1;1;0;166.8778;98.16208;15994.55;4806223
2188.554;52.98484;0.001274819;17.42534;1.800622;1;1;0;166.8814;98.16341;15992.01;4805526
2195.554;52.98602;0.001244244;17.77334;1.836582;1;1;0;166.8851;98.1648;16311.39;4901564
2202.554;52.98715;0.001117496;17.65148;1.82399;1;1;0;166.8887;98.16613;16199.55;4868021
2209.554;52.98832;0.001182605;17.89649;1.849308;1;1;0;166.8924;98.16752;16424.41;4935662
2216.554;52.9895;0.001393158;18.02047;1.862119;1;1;0;166.8961;98.16891;16538.19;4969923
2223.554;52.99073;0.001352392;18.15478;1.875998;1;1;0;166.8999;98.17037;16661.46;5007038
2230.554;52.99186;0.001432357;18.27568;1.888491;1;1;0;166.9035;98.1717;16772.4;5040447
2237.554;52.99304;0.001296123;18.14935;1.875437;1;1;0;166.9072;98.17309;16656.47;5005676
2244.554;52.99416;0.00127376;18.38344;1.899626;1;1;0;166.9108;98.17442;16871.31;5070307
2251.554;52.99534;0.001409759;18.717;1.934093;1;1;0;166.9145;98.17581;17177.42;5162375
2258.554;52.99658;0.001378635;18.60747;1.922775;1;1;0;166.9184;98.17726;17076.9;5132240
2265.554;52.99764;0.00126692;18.58715;1.920676;1;1;0;166.9217;98.17852;17058.25;5126700
2272.554;52.99888;0.001291419;18.91838;1.954903;1;1;0;166.9256;98.17998;17362.24;5218136
2278.204;52.9985;0.001248615;18.22191;1.882935;1;1;0;166.9244;98.17953;16723.06;5026012
2285.204;52.99727;0.001272604;17.50498;1.808851;1;1;0;166.9205;98.17808;16065.1;4828196
2292.204;52.99609;0.001220274;16.7849;1.734443;1;1;0;166.9168;98.17669;15404.25;4629521
2299.204;52.99496;0.001247772;16.35322;1.689836;1;1;0;166.9133;98.17536;15008.08;4510396
2306.204;52.99379;0.001120064;15.69472;1.621791;1;1;0;166.9096;98.17397;14403.74;4328715
2313.204;52.99266;0.0011897;15.64418;1.616569;1;1;0;166.906;98.17265;14357.36;4314720
2320.204;52.99149;0.001309;15.24424;1.575241;1;1;0;166.9023;98.17126;13990.32;4204355
2327.204;52.99025;0.001271546;14.899;1.539567;1;1;0;166.8984;98.1698;13673.48;4109079
2334.204;52.98918;0.001233739;14.97156;1.547064;1;1;0;166.8951;98.16854;13740.07;4129038
2341.204;52.98795;0.001131784;14.47695;1.495954;1;1;0;166.8912;98.16708;13286.14;3992569
2348.204;52.98682;0.001277504;14.25683;1.473209;1;1;0;166.8876;98.16575;13084.13;3931812
2355.204;52.98564;0.001156499;14.20224;1.467568;1;1;0;166.8839;98.16436;13034.03;3916703
2360.296;52.985;0.001149149;14.20309;1.467656;2;2;0;166.8819;98.16361;13034.81;3916908
2367.296;52.98623;0.001187171;14.59875;1.508541;2;2;0;166.8858;98.16506;13397.92;4026080
2374.296;52.98747;0.001085707;14.74977;1.524146;2;2;0;166.8897;98.16651;13536.52;4067788
2381.296;52.98859;0.001206908;14.90728;1.540422;2;2;0;166.8932;98.16783;13681.08;4111282
2388.296;52.98977;0.0009243271;15.14187;1.564664;2;2;0;166.8969;98.16923;13896.37;4176039
2395.296;52.99095;0.000982419;15.34041;1.585179;2;2;0;166.9006;98.17062;14078.58;4230852
2402.296;52.99207;0.0008412855;15.47795;1.599391;2;2;0;166.9042;98.17195;14204.81;4268842
2409.296;52.99325;0.001127864;15.83197;1.635973;2;2;0;166.9079;98.17334;14529.7;4366541
2416.296;52.99449;0.001147091;15.9484;1.648005;2;2;0;166.9118;98.17479;14636.56;4398718
2423.296;52.99555;0.001307334;15.93237;1.646348;2;2;0;166.9151;98.17605;14621.84;4394351
2430.296;52.99679;0.001163829;15.97776;1.651039;2;2;0;166.919;98.17751;14663.5;4406936
2437.296;52.99797;0.001049781;16.21136;1.675177;2;2;0;166.9227;98.1789;14877.88;4471428
2444.296;52.99909;0.001220549;16.35877;1.690409;2;2;0;166.9263;98.18023;15013.17;4512146
2451.296;53.00032;0.001186917;16.72198;1.727941;2;2;0;166.9301;98.18168;15346.5;4612395
2458.296;53.0015;0.00115789;16.76391;1.732274;2;2;0;166.9339;98.18307;15384.99;4624026
2465.296;53.00263;0.001183702;16.82604;1.738695;2;2;0;166.9374;98.1844;15442.01;4641227
2472.296;53.0038;0.001141937;16.98643;1.755268;2;2;0;166.9411;98.18579;15589.21;4685532
2479.296;53.00493;0.001297907;16.89508;1.745828;2;2;0;166.9447;98.18712;15505.37;4660396
2486.296;53.00611;0.00130216;17.20984;1.778353;2;2;0;166.9484;98.18851;15794.24;4747285
2493.296;53.00723;0.001420244;17.17803;1.775067;2;2;0;166.9519;98.18983;15765.05;4738576
2500.296;53.00841;0.001244264;17.31308;1.789022;2;2;0;166.9556;98.19123;15888.99;4775895
2507.296;53.00965;0.00131876;17.46595;1.804819;2;2;0;166.9595;98.19268;16029.28;4818135
2514.296;53.01077;0.001259316;17.59345;1.817994;2;2;0;166.9631;98.19401;16146.3;4853372
2521.296;53.01195;0.001243833;17.64995;1.823832;2;2;0;166.9668;98.1954;16198.15;4869025
2528.296;53.01307;0.001219726;17.84381;1.843865;2;2;0;166.9703;98.19673;16376.06;4922571
2535.296;53.01425;0.001215884;17.8528;1.844793;2;2;0;166.974;98.19812;16384.31;4925118
2542.296;53.01548;0.001088235;17.9349;1.853277;2;2;0;166.9779;98.19957;16459.66;4947840
2549.296;53.01656;0.001207888;18.02256;1.862335;2;2;0;166.9813;98.20084;16540.1;4972085
2556.296;53.01779;0.001300474;18.02819;1.862917;2;2;0;166.9852;98.20229;16545.28;4973712
2563.296;53.01896;0.00128505;18.34483;1.895636;2;2;0;166.9889;98.20368;16835.87;5061138
2570.296;53.02009;0.001293281;18.32245;1.893324;2;2;0;166.9924;98.20501;16815.33;5055032
2575.434;53.02036;0.001342338;18.14521;1.875009;2;2;0;166.9933;98.20532;16652.67;5006148
2582.434;53.01918;0.001491664;17.47517;1.805771;2;2;0;166.9895;98.20394;16037.75;4821221
2589.434;53.01795;0.001150521;17.06436;1.763321;2;2;0;166.9857;98.20248;15660.73;4707815
2596.434;53.01682;0.001196951;16.73551;1.72934;2;2;0;166.9821;98.20115;15358.93;4617028
2603.434;53.01564;0.001207006;16.48101;1.703041;2;2;0;166.9784;98.19976;15125.36;4546752
2610.434;53.01441;0.001335792;16.35102;1.689608;2;2;0;166.9745;98.1983;15006.06;4510824
2617.434;53.01334;0.00134224;16.03291;1.656737;2;2;0;166.9711;98.19704;14714.12;4423011
2624.434;53.01211;0.001380752;15.77926;1.630527;2;2;0;166.9673;98.19559;14481.33;4352973
2631.434;53.01093;0.001260374;15.62574;1.614663;2;2;0;166.9636;98.1942;14340.44;4310562
2638.434;53.00981;0.001249947;15.42095;1.593502;2;2;0;166.96;98.19287;14152.5;4254013
2645.434;53.00863;0.001389062;15.43581;1.595037;2;2;0;166.9563;98.19148;14166.13;4258052
2652.434;53.0075;0.001199715;15.24116;1.574923;2;2;0;166.9528;98.19015;13987.49;4204299
2659.434;53.00627;0.001476141;15.14904;1.565404;2;2;0;166.9489;98.1887;13902.95;4178828
2666.434;53.00509;0.001505834;14.89979;1.539648;2;2;0;166.9452;98.18731;13674.21;4110017
2673.434;53.00397;0.001338202;15.03657;1.553782;2;2;0;166.9416;98.18598;13799.73;4147692
2680.434;53.00279;0.001159223;14.99649;1.549641;2;2;0;166.9379;98.18459;13762.95;4136578
2687.434;53.00166;0.001033161;14.78727;1.528021;2;2;0;166.9344;98.18326;13570.94;4078813
2694.434;53.00048;0.001123749;14.60997;1.5097;2;2;0;166.9306;98.18187;13408.22;4029851
2701.434;52.9993;0.001191836;14.39872;1.487871;2;2;0;166.9269;98.18048;13214.35;3971528
2708.434;52.99807;0.001184408;14.18354;1.465635;2;2;0;166.923;98.17903;13016.86;3912118
2715.434;52.99695;0.001115595;14.40947;1.488981;2;2;0;166.9195;98.1777;13224.21;3974382
2722.434;52.99577;0.001258277;14.40072;1.488077;2;2;0;166.9158;98.17631;13216.18;3971913
2729.434;52.99464;0.001222469;14.20497;1.46785;2;2;0;166.9123;98.17498;13036.54;3917872
2736.434;52.99347;0.001246302;14.23689;1.471148;2;2;0;166.9086;98.17359;13065.83;3926621
2743.434;52.99234;0.001148816;13.95074;1.441579;2;2;0;166.905;98.17227;12803.21;3847646
2750.434;52.99111;0.001107501;13.95749;1.442277;2;2;0;166.9011;98.17081;12809.41;3849453
2757.434;52.98993;0.001210318;13.94201;1.440678;2;2;0;166.8974;98.16942;12795.21;3845132
2764.434;52.98881;0.001075711;13.81211;1.427254;2;2;0;166.8939;98.1681;12675.99;3809253
2770.416;52.98945;0.001142485;13.84218;1.430361;3;3;0;166.8959;98.16885;12703.58;3817575
2777.416;52.99062;0.001047782;14.06899;1.453798;3;3;0;166.8996;98.17024;12911.74;3880181
2784.416;52.99175;0.001145425;14.24262;1.47174;3;3;0;166.9032;98.17157;13071.09;3928121
2791.416;52.99293;0.001087862;14.23078;1.470517;3;3;0;166.9069;98.17296;13060.22;3924912
2798.416;52.99416;0.001106109;14.63578;1.512367;3;3;0;166.9108;98.17442;13431.91;4036670
2805.416;52.99529;0.001080728;14.31218;1.478928;3;3;0;166.9143;98.17575;13134.93;3947472
2812.416;52.99646;0.001096898;14.3468;1.482506;3;3;0;166.918;98.17713;13166.7;3957075
2819.416;52.99764;0.0009514327;14.57893;1.506492;3;3;0;166.9217;98.17852;13379.73;4021155
2826.416;52.99877;0.001049919;14.48625;1.496916;3;3;0;166.9253;98.17985;13294.68;3995647
2833.416;52.99995;0.001271232;14.66823;1.51572;3;3;0;166.929;98.18124;13461.68;4045895
2840.416;53.00118;0.001088627;14.82083;1.531489;3;3;0;166.9328;98.18269;13601.74;4088047
2847.416;53.0023;0.001099093;14.85851;1.535382;3;3;0;166.9364;98.18402;13636.31;4098494
2854.416;53.00349;0.00120728;14.9291;1.542677;3;3;0;166.9401;98.18542;13701.1;4118023
2861.416;53.00461;0.00127721;15.05296;1.555475;3;3;0;166.9436;98.18674;13814.77;4152243
2868.416;53.00579;0.001218785;14.97796;1.547726;3;3;0;166.9474;98.18813;13745.94;4131613
2875.416;53.00691;0.001071438;15.1049;1.560843;3;3;0;166.9509;98.18946;13862.44;4166685
2882.416;53.00809;0.001159733;15.13019;1.563456;3;3;0;166.9546;98.19085;13885.65;4173718
2889.416;53.00932;0.001153128;15.02204;1.55228;3;3;0;166.9585;98.1923;13786.39;4143944
2896.416;53.0105;0.001158596;15.18862;1.569494;3;3;0;166.9622;98.1937;13939.28;4189957
2903.416;53.01163;0.001279464;15.33157;1.584265;3;3;0;166.9657;98.19502;14070.46;4229446
2910.416;53.0128;0.001384809;15.20286;1.570966;3;3;0;166.9695;98.19641;13952.35;4193999
2917.416;53.01393;0.001276779;15.37723;1.588984;3;3;0;166.973;98.19774;14112.37;4242157
2924.416;53.01511;0.001233308;15.47313;1.598894;3;3;0;166.9767;98.19913;14200.39;4268674
2931.416;53.01629;0.001265078;15.31548;1.582602;3;3;0;166.9804;98.20052;14055.7;4225239
2938.416;53.01747;0.001164574;15.37538;1.588793;3;3;0;166.9841;98.20191;14110.67;4241824
2945.416;53.01864;0.001149031;15.68846;1.621145;3;3;0;166.9879;98.2033;14398;4328259
2952.416;53.01977;0.001144602;15.74998;1.627501;3;3;0;166.9914;98.20462;14454.46;4345289
2959.416;53.02095;0.001136762;15.68764;1.62106;3;3;0;166.9951;98.20602;14397.25;4328150
2966.416;53.02213;0.001264764;15.78722;1.631349;3;3;0;166.9988;98.20741;14488.63;4355683
2973.416;53.02325;0.001129295;15.88204;1.641147;3;3;0;167.0024;98.20873;14575.65;4381901
2980.416;53.02448;0.0009879656;16.04592;1.658081;3;3;0;167.0062;98.21019;14726.05;4427181
2987.416;53.02566;0.0009674061;15.88761;1.641724;3;3;0;167.0099;98.21158;14580.77;4383565
2994.416;53.02679;0.001121632;15.80768;1.633464;3;3;0;167.0135;98.21291;14507.42;4361569
3001.416;53.02797;0.001034082;16.14946;1.668781;3;3;0;167.0172;98.21429;14821.08;4455931
3008.416;53.02909;0.001125179;16.0414;1.657614;3;3;0;167.0208;98.21562;14721.9;4426174
3015.416;53.03032;0.001138036;16.33757;1.688218;3;3;0;167.0246;98.21707;14993.71;4507959
3022.416;53.0315;0.001127747;16.35985;1.690521;3;3;0;167.0284;98.21846;15014.17;4514172
3029.416;53.03263;0.001039021;16.59444;1.714763;3;3;0;167.0319;98.21979;15229.46;4578963
3036.416;53.03381;0.001118849;16.43958;1.69876;3;3;0;167.0356;98.22118;15087.33;4536293
3043.416;53.03493;0.001049233;16.61039;1.71641;3;3;0;167.0391;98.22251;15244.09;4583487
3050.416;53.03611;0.001215982;16.44962;1.699797;3;3;0;167.0429;98.2239;15096.55;4539188
3057.416;53.03729;0.001300827;16.86941;1.743176;3;3;0;167.0466;98.22529;15481.81;4655093
3064.416;53.03847;0.001203791;16.75031;1.730869;3;3;0;167.0503;98.22668;15372.51;4622291
3071.416;53.03964;0.001259257;16.61265;1.716644;3;3;0;167.054;98.22807;15246.17;4584367
3078.416;53.04077;0.001269762;16.73874;1.729674;3;3;0;167.0576;98.2294;15361.89;4619224
3085.416;53.04195;0.001206731;16.92864;1.749296;3;3;0;167.0613;98.23079;15536.17;4671693
3092.416;53.04307;0.001394864;16.77172;1.733081;3;3;0;167.0648;98.23211;15392.15;4628449
3099.416;53.05197;0.001325385;18.75884;1.938417;3;3;0;167.0928;98.2426;17215.82;5177374
3106.416;53.06359;0.001384143;20.20254;2.0876;3;3;0;167.1294;98.25631;18540.78;5576595
3113.416;53.07527;0.001207554;22.00696;2.274057;3;3;0;167.1662;98.27008;20196.77;6075512
3120.416;53.087;0.001325816;24.23883;2.504684;3;3;0;167.2032;98.28391;22245.06;6692596
3127.416;53.09852;0.001338281;26.36435;2.724322;3;3;0;167.2394;98.29748;24195.74;7280461
3134.416;53.1103;0.001204223;28.96131;2.992675;3;3;0;167.2766;98.31137;26579.09;7998718
3141.416;53.13221;0.001222038;35.3627;3.654153;3;3;0;167.3456;98.33718;32453.93;9769216
3148.416;53.15563;0.001048155;41.88651;4.328282;3;3;0;167.4193;98.36476;38441.12;1.157466e+007
3155.416;53.17904;0.001049605;44.02439;4.549196;3;3;0;167.493;98.39234;40403.15;1.216878e+007
3162.416;53.20229;0.00124344;45.32711;4.683811;3;3;0;167.5663;98.4197;41598.71;1.25323e+007
3169.416;53.2257;0.001382222;45.47925;4.699532;3;3;0;167.64;98.44726;41738.34;1.257783e+007
3176.416;53.24889;0.001190464;45.53889;4.705695;3;3;0;167.7131;98.47455;41793.07;1.259776e+007
3183.416;53.27225;0.0009644466;45.56247;4.708131;3;3;0;167.7866;98.50203;41814.71;1.260775e+007
3190.416;53.2955;0.0009880635;45.85459;4.738317;3;3;0;167.8598;98.52937;42082.8;1.269205e+007
3197.416;53.31896;0.001003194;45.67808;4.720078;3;3;0;167.9337;98.55695;41920.81;1.264668e+007
3204.416;53.34232;0.001094193;45.81254;4.733972;3;3;0;168.0073;98.58441;42044.21;1.268739e+007
3211.416;53.36563;0.001256788;45.7211;4.724523;3;3;0;168.0807;98.61179;41960.29;1.266553e+007
3218.416;53.38904;0.001178587;45.62505;4.714598;3;3;0;168.1544;98.63929;41872.14;1.26424e+007
3225.416;53.41229;0.001110872;45.63879;4.716018;3;3;0;168.2277;98.6666;41884.75;1.264966e+007
3232.416;53.43559;0.001150403;45.65659;4.717857;3;3;0;168.3011;98.69396;41901.09;1.265806e+007
3239.416;53.4867;0.0009793224;45.66014;4.718224;3;3;0;168.462;98.75393;41904.34;1.266664e+007
3246.416;53.54504;0.00118235;45.83914;4.736721;3;3;0;168.6458;98.82235;42068.63;1.2725e+007
3253.416;53.60343;0.00128844;49.32811;5.097249;3;3;0;168.8297;98.89079;45270.61;1.370292e+007
3260.416;53.66172;0.001233053;57.67986;5.960264;3;3;0;169.0133;98.95906;52935.38;1.60339e+007
3267.416;53.72016;0.001161967;57.76211;5.968763;3;3;0;169.1974;99.02746;53010.86;1.606775e+007
3274.416;53.77839;0.001149521;57.79435;5.972095;3;3;0;169.3808;99.09557;53040.45;1.608767e+007
3281.416;53.83657;0.001242166;58.34264;6.028752;3;3;0;169.564;99.16357;53543.64;1.625134e+007
3288.416;53.89502;0.00122196;58.58954;6.054265;3;3;0;169.7481;99.23183;53770.23;1.633126e+007
3295.416;53.95341;0.001234699;64.34259;6.648747;3;3;0;169.932;99.29999;59050.06;1.79471e+007
3302.416;54.01186;0.001175392;96.91052;10.01411;3;3;0;170.1161;99.36816;88939.11;2.704972e+007
3309.416;54.03613;0.00108947;106.9257;11.04901;3;3;0;170.1925;99.39646;98130.47;2.98536e+007
3316.416;54.04775;0.001189131;112.8855;11.66486;3;3;0;170.2291;99.41001;103600;3.152184e+007
3323.416;54.05943;0.001209181;120.2931;12.43031;3;3;0;170.2659;99.42362;110398.3;3.359489e+007
3330.416;54.07106;0.001203909;127.9779;13.22441;3;3;0;170.3025;99.43717;117451.1;3.574592e+007
3337.416;54.08284;0.001149012;136.2838;14.08269;3;3;0;170.3396;99.45089;125073.8;3.80711e+007
3344.416;54.09441;0.001113145;145.1992;15.00395;3;3;0;170.3761;99.46438;133255.8;4.056708e+007
3351.416;54.10614;0.001041452;154.5015;15.96519;3;3;0;170.4131;99.47804;141793;4.317196e+007
3358.416;54.11782;0.001082355;163.844;16.93058;3;3;0;170.4498;99.49164;150367;4.578873e+007
3365.416;54.12945;0.001020677;174.0949;17.98984;3;3;0;170.4865;99.50518;159774.7;4.866009e+007
3372.416;54.15104;0.001144563;197.2351;20.381;3;3;0;170.5545;99.53032;181011.4;5.51417e+007
3379.416;54.17445;0.0009703852;222.1205;22.95249;3;3;0;170.6282;99.55757;203849.9;6.211592e+007
3386.416;54.19765;0.0008242539;248.3628;25.66421;3;3;0;170.7012;99.58456;227933.6;6.947334e+007
3393.416;54.221;0.0007417218;277.2197;28.6461;3;3;0;170.7748;99.61174;254416.9;7.756642e+007
3400.416;54.24431;0.0006717725;307.6986;31.79559;3;3;0;170.8482;99.63884;282388.8;8.611778e+007
3407.416;54.26771;0.0006886081;341.105;35.24758;3;3;0;170.9219;99.66605;313047.2;9.549343e+007
3414.416;54.29113;0.0008483217;376.3143;38.88589;3;3;0;170.9957;99.69327;345360.4;1.053791e+008
3421.416;54.31438;0.0008433827;412.4953;42.6246;3;3;0;171.0689;99.72029;378565.3;1.15542e+008
3428.416;54.33779;0.0007859375;452.4482;46.75307;3;3;0;171.1426;99.74748;415231.9;1.267675e+008
3435.416;54.36104;0.0008458325;494.6443;51.11335;3;3;0;171.2159;99.77449;453957.2;1.386275e+008
3442.416;54.38434;0.0005568039;538.7042;55.66622;3;3;0;171.2893;99.80154;494392.9;1.510165e+008
3449.416;54.40764;0.0007299035;584.5581;60.40446;3;3;0;171.3627;99.82859;536475.1;1.639151e+008
3456.416;54.43111;0.0006012547;633.8718;65.50021;3;3;0;171.4366;99.85583;581732.4;1.777915e+008
3463.416;54.45447;0.0005699157;684.9161;70.7748;3;3;0;171.5101;99.88293;628578.1;1.921608e+008
3470.416;54.47771;0.0003480729;737.5134;76.20987;3;3;0;171.5834;99.9099;676848.9;2.069733e+008
3477.416;54.50107;0.0003489549;793.1055;81.95439;3;3;0;171.6569;99.93698;727868.3;2.226348e+008
3484.416;54.52437;0.0003191053;849.6509;87.79743;3;3;0;171.7303;99.96399;779762.5;2.385722e+008
3491.416;54.54768;0.0001648992;907.1967;93.74385;3;3;0;171.8037;99.991;832574.9;2.547993e+008
3498.416;54.57093;0.0001958463;967.6595;99.99168;3;3;0;171.8769;100.0179;888064.3;2.718543e+008
3505.416;54.59439;0.0003938761;1025.607;105.9796;3;3;0;171.9508;100.0451;941245.5;2.882125e+008
3512.416;54.6178;-0.0001241099;1087.669;112.3927;3;3;0;172.0246;100.0722;998202.1;3.057357e+008
3519.416;54.64105;0.0001803041;1150.941;118.9308;3;3;0;172.0978;100.0991;1056270;3.236082e+008
3526.416;54.66446;6.259164e-005;1217.802;125.8398;3;3;0;172.1715;100.1262;1117632;3.425002e+008
3533.416;54.68771;7.591909e-005;1283.035;132.5805;3;3;0;172.2448;100.1531;1177498;3.609436e+008
3540.416;54.71102;3.944508e-005;1349.203;139.4179;3;3;0;172.3182;100.1801;1238224;3.796603e+008
3547.416;54.73427;-0.0001092733;1412.712;145.9805;3;3;0;172.3914;100.207;1296509;3.976384e+008
3554.416;54.75773;-0.0001140359;1469.963;151.8964;3;3;0;172.4653;100.2341;1349050;4.138651e+008
3561.416;54.78114;-0.0002440174;1523.168;157.3944;3;3;0;172.539;100.2612;1397880;4.289611e+008
3568.416;54.80439;0.0001497882;1554.815;160.6646;3;3;0;172.6123;100.288;1426923;4.379913e+008
3575.416;54.82785;-0.0002275345;1616.717;167.0611;3;3;0;172.6862;100.3151;1483734;4.555526e+008
3582.416;54.85105;-0.0001379273;1683.063;173.9169;3;3;0;172.7592;100.3419;1544622;4.743744e+008
3589.416;54.8743;-0.0002449582;1747.88;180.6146;3;3;0;172.8325;100.3688;1604107;4.927753e+008
3596.416;54.89761;-0.0005171708;1810.773;187.1136;3;3;0;172.9059;100.3957;1661828;5.10644e+008
3603.416;54.92102;-0.0003296854;1865.546;192.7735;3;3;0;172.9796;100.4227;1712095;5.262322e+008
3610.416;54.94443;-0.0005852387;1934.419;199.8903;3;3;0;173.0533;100.4497;1775302;5.458071e+008
3617.416;54.96773;-0.0005688538;2004.154;207.0963;3;3;0;173.1267;100.4766;1839302;5.656355e+008
3624.416;54.99114;-0.000696993;2067.159;213.6068;3;3;0;173.2005;100.5036;1897124;5.835748e+008
3631.416;55.01439;-0.0006531889;2114.612;218.5103;3;3;0;173.2737;100.5304;1940674;5.971312e+008
3638.416;55.03764;-0.0003564774;2183.127;225.5902;3;3;0;173.3469;100.5572;2003553;6.166439e+008
3645.416;55.06095;-0.0004362655;2256.56;233.1783;3;3;0;173.4203;100.584;2070945;6.375568e+008
3652.416;55.08436;-0.0001179753;2327.037;240.4609;3;3;0;173.494;100.611;2135625;6.576464e+008
3657.56;55.10139;0.0001738952;2384.054;246.3527;3;3;0;173.5477;100.6306;2187953;6.738922e+008
3664.56;55.07819;-8.926254e-005;2094.594;216.4418;3;3;0;173.4746;100.6039;1922303;5.919135e+008
3671.56;55.05478;-6.16278e-005;1873.578;193.6034;3;3;0;173.4009;100.5769;1719466;5.293135e+008
3678.56;55.03153;-8.167772e-005;1698.69;175.5317;3;3;0;173.3277;100.5501;1558964;4.797767e+008
3685.56;55.00829;-0.0001850632;1554.86;160.6692;3;3;0;173.2545;100.5233;1426964;4.390356e+008
3692.56;54.98493;-0.0001066666;1424.981;147.2483;3;3;0;173.1809;100.4964;1307769;4.022543e+008
3699.56;54.96157;3.530964e-005;1308.644;135.2268;3;3;0;173.1073;100.4695;1201001;3.693144e+008
3706.56;54.93816;-1.117958e-005;1202.769;124.2864;3;3;0;173.0336;100.4425;1103835;3.393436e+008
3713.56;54.91486;0.000118998;1107.596;114.4519;3;3;0;172.9602;100.4156;1016491;3.12408e+008
3720.56;54.89139;0.0001113347;1018.71;105.267;3;3;0;172.8863;100.3885;934916;2.872591e+008
3727.56;54.8682;0.0004159252;939.2543;97.05647;3;3;0;172.8132;100.3617;861995.6;2.647829e+008
3734.56;54.84495;0.0003615571;865.126;89.39653;3;3;0;172.74;100.3349;793964.7;2.438201e+008
3741.56;54.82159;0.0003365094;796.1909;82.27323;3;3;0;172.6664;100.3079;730699.9;2.243315e+008
3748.56;54.79823;0.0003349219;733.3392;75.77854;3;3;0;172.5929;100.2809;673018.1;2.065669e+008
3755.56;54.77482;0.000470058;675.2779;69.77885;3;3;0;172.5191;100.2539;619732.6;1.901607e+008
3762.56;54.75157;0.0006152485;622.0721;64.28091;3;3;0;172.4459;100.227;570903.3;1.751307e+008
3769.56;54.72805;0.0005377535;572.4403;59.15228;3;3;0;172.3718;100.1998;525354;1.611141e+008
3776.56;54.70481;0.0005567843;525.2597;54.27695;3;3;0;172.2986;100.1729;482054.3;1.477954e+008
3783.56;54.68161;0.0005411441;480.8305;49.68592;3;3;0;172.2255;100.1461;441279.6;1.352578e+008
3790.56;54.65825;0.0007210644;439.3303;45.39755;3;3;0;172.152;100.119;403193;1.235503e+008
3797.56;54.63494;0.000741859;400.6898;41.4047;3;3;0;172.0786;100.0921;367730.9;1.126533e+008
3804.56;54.61154;0.0008478513;366.219;37.84271;3;3;0;172.0048;100.065;336095.5;1.02934e+008
3811.56;54.58818;0.0008936937;334.2442;34.53864;3;3;0;171.9313;100.0379;306750.8;9.392135e+007
3818.56;54.56477;0.0007584204;304.2149;31.4356;3;3;0;171.8575;100.0108;279191.6;8.546005e+007
3825.56;54.54147;0.0009908075;277.301;28.6545;3;3;0;171.7841;99.9838;254491.5;7.787838e+007
3832.56;54.51827;0.0009571753;252.3462;26.07583;3;3;0;171.7111;99.95691;231589.4;7.085091e+007
3839.56;54.49491;0.001045136;229.2923;23.69358;3;3;0;171.6375;99.92983;210431.7;6.436065e+007
3846.56;54.4716;0.0008984563;208.3586;21.53043;3;3;0;171.5641;99.90281;191220;5.846892e+007
3853.56;54.4482;0.00105329;188.9176;19.52152;3;3;0;171.4904;99.87565;173378.1;5.299905e+007
3860.56;54.42489;0.001036865;171.1325;17.68373;3;3;0;171.417;99.84862;157055.9;4.799664e+007
3867.56;54.40143;0.001185976;154.646;15.98011;3;3;0;171.3431;99.82138;141925.5;4.336094e+007
3874.56;54.37813;0.001092547;140.2951;14.49719;3;3;0;171.2697;99.79433;128755.1;3.932648e+007
3881.56;54.35493;0.001128825;127.2502;13.14922;3;3;0;171.1966;99.76739;116783.2;3.566023e+007
3888.56;54.33157;0.0009982943;114.9546;11.87867;3;3;0;171.1231;99.74026;105499;3.220581e+007
3890.258;54.32584;0.001066852;111.963;11.56953;3;3;0;171.105;99.73361;102753.4;3.136558e+007