File: Ensayos/Resistencia/comp/Clavo5/Clavo5d.raw
"Test Type";"Manual"
"Method Name:";"C:\INSTRON\user\template\CYCLE.MTM"
"Name:";""
"Operator ID:";""
"Company:";""
"Lab name:";""
"Test date:";"24/05/2017"
"Temperature:";""
"Humidity:";""
"Note 1:";""
"Note 2:";""
"Note 3:";""
"Geometry:";"Rectangular"
"Specimen";1
"Specimen name:";""
"Width:";0.250000;"in"
"Thickness:";0.060000;"in"
"Length:";1.250000;"in"
"Diameter:";0.039370;"in"
"Inner diameter:";0.019685;"in"
"Outer diameter:";0.039370;"in"
"Wall thickness:";0.019685;"in"
"Area:";0.015000;"in*in"
"Linear density:";1.000000;"den"
"Sled weight:";2.204623;"lbf"
"Loading span:";0.000000;"mm"
"Support span:";1.000000;"mm"
"Span ratio:";"2"
"Fixture type:";"3-point"
"Comment:";""
"Included"
"Final Width:";0.250000;"in"
"Final Thickness:";0.060000;"in"
"Final Length:";1.250000;"in"
"Final Diameter:";0.039370;"in"
"Final Inner diameter:";0.019685;"in"
"Final Outer diameter:";0.039370;"in"
"Final Wall thickness:";0.019685;"in"
"Final Area:";0.015000;"in*in"
"Final Linear density:";1.000000;"den"
"Time sec";"Extension mm";"Strain 1 %";"Load N";"Stress MPa";"Cycle Count ";"Total Cycle Count ";"Repetitions Count ";"Strain [Exten.] %";"True strain %";"Tenacity gf/tex";"True stress Pa"
0;0;0.0002806332;60.70311;6.272667;0;0;0;0;0;55709.95;6272667
28;0.04671425;-0.001843428;192.0553;19.84575;0;0;0;0.1471315;0.1470234;176257.7;1.987495e+007
56;0.09342851;-0.005890398;324.314;33.51251;0;0;0;0.294263;0.2938309;297637.4;3.361113e+007
84.00001;0.1399285;-0.01236842;499.6451;51.6301;0;0;0;0.4407196;0.4397513;458546.6;5.185764e+007
112;0.1866427;-0.0213383;720.1207;74.41262;0;0;0;0.5878512;0.58613;660886.9;7.485006e+007
140;0.233357;-0.03905225;968.758;100.1052;0;0;0;0.7349826;0.7322948;889072.4;1.00841e+008
168;0.2800177;-0.09996035;1189.49;122.9142;0;0;0;0.8819455;0.878079;1091648;1.239983e+008
196;0.3266248;-0.2066648;1362.612;140.8036;0;0;0;1.028739;1.023484;1250530;1.422521e+008
224;0.3733926;-0.3373263;1508.707;155.9001;0;0;0;1.17604;1.169178;1384608;1.577335e+008
252;0.4200533;-0.4775592;1636.854;169.1419;0;0;0;1.323002;1.314327;1502214;1.713796e+008
280;0.4666069;-0.6278661;1750.974;180.9344;0;0;0;1.469628;1.458934;1606947;1.835934e+008
308;0.5133211;-0.7870074;1855.213;191.7057;0;0;0;1.616759;1.603829;1702612;1.948052e+008
336;0.5600354;-0.9531786;1955.673;202.0866;0;0;0;1.763891;1.748515;1794808;2.056512e+008
364;0.6066961;-1.121873;2052.52;212.0942;0;0;0;1.910854;1.892826;1883689;2.16147e+008
392;0.6532495;-1.290485;2152.352;222.4101;0;0;0;2.057479;2.036599;1975309;2.269861e+008
420;0.700071;-1.453968;2257.072;233.2312;0;0;0;2.204948;2.18099;2071416;2.383739e+008
448;0.7467852;-1.613773;2366.829;244.5728;0;0;0;2.352079;2.324844;2172145;2.503254e+008
476;0.7932851;-1.76994;2481.72;256.4449;0;0;0;2.498536;2.467833;2277585;2.628522e+008
504;0.8399994;-1.927059;2605.928;269.2798;0;0;0;2.645668;2.611275;2391577;2.76404e+008
532;0.8867137;-2.081734;2736.617;282.7843;0;0;0;2.792799;2.754512;2511515;2.906819e+008
560;0.9333744;-2.231321;2870.252;296.5933;0;0;0;2.939762;2.897379;2634158;3.053124e+008
588;0.9799815;-2.377736;3008.311;310.8594;0;0;0;3.086556;3.03988;2760861;3.204543e+008
616;1.026696;-2.521651;3154.219;325.9366;0;0;0;3.233687;3.182504;2894768;3.364764e+008
644.0001;1.07341;-2.659953;3306.715;341.6946;0;0;0;3.380819;3.324926;3034720;3.532467e+008
672.0001;1.119964;-2.793651;3460.339;357.5691;0;0;0;3.527445;3.466656;3175708;3.701822e+008
700.0001;1.166624;-2.922048;3614.547;373.5039;0;0;0;3.674407;3.60851;3317231;3.87228e+008
728.0001;1.213338;-3.049092;3773.488;389.9278;0;0;0;3.821538;3.750326;3463098;4.048291e+008
756.0001;1.260053;-3.175788;3934.955;406.6129;0;0;0;3.96867;3.891942;3611284;4.2275e+008
784.0001;1.306606;-3.300873;4099.41;423.6066;0;0;0;4.115295;4.032871;3762212;4.410393e+008
812.0001;1.353428;-3.423056;4269.142;441.1455;0;0;0;4.262765;4.174411;3917982;4.599505e+008
840.0001;1.400088;-3.542574;4441.055;458.9099;0;0;0;4.409727;4.315266;4075754;4.791466e+008
868.0001;1.446642;-3.6618;4614.995;476.8838;0;0;0;4.556353;4.4556;4235387;4.986123e+008
896.0001;1.493303;-3.778175;4794.85;495.4688;0;0;0;4.703315;4.596059;4400448;5.187723e+008
924.0001;1.540017;-3.891989;4978.668;514.4634;0;0;0;4.850447;4.736483;4569146;5.394171e+008
952.0001;1.586785;-4.003999;5165.301;533.7488;0;0;0;4.997747;4.876871;4740427;5.604242e+008
980.0001;1.633285;-4.113597;5350.804;552.9175;0;0;0;5.144204;5.016259;4910672;5.813608e+008
1008;1.679999;-4.22206;5538.766;572.3403;0;0;0;5.291335;5.156094;5083173;6.026248e+008
1036;1.726713;-4.329335;5731.151;592.2202;0;0;0;5.438467;5.295734;5259733;6.244278e+008
1064;1.773267;-4.439708;5919.65;611.6984;0;0;0;5.585092;5.4347;5432727;6.458623e+008
1092;1.819927;-4.551911;6114.432;631.8259;0;0;0;5.732055;5.573792;5611487;6.680425e+008
1120;1.866642;-4.666433;6308.211;651.8498;0;0;0;5.879187;5.712851;5789327;6.901733e+008
1148;1.913356;-4.778814;6498.919;671.5563;0;0;0;6.026318;5.851716;5964348;7.120264e+008
1176;1.959963;-4.8916;6683.173;690.5959;0;0;0;6.173112;5.990071;6133446;7.332272e+008
1204;2.006677;-5.002846;6872.44;710.1536;0;0;0;6.320243;6.128552;6307145;7.55037e+008
1232;2.053392;-5.111121;7061.045;729.6428;0;0;0;6.467375;6.266841;6480236;7.768315e+008
1260;2.099999;-5.214585;7245.987;748.7535;0;0;0;6.614169;6.404623;6649966;7.982773e+008
1288;2.146606;-5.31557;7426.551;767.4118;0;0;0;6.760963;6.542216;6815677;8.192962e+008
1316;2.19332;-5.415722;7604.97;785.8484;0;0;0;6.908095;6.679935;6979420;8.401356e+008
1344;2.240088;-5.515671;7789.384;804.9046;0;0;0;7.055395;6.817623;7148665;8.616938e+008
1372;2.286641;-5.618333;7973.561;823.9363;0;0;0;7.20202;6.954491;7317693;8.832763e+008
1400;2.333356;-5.724815;8158.547;843.0515;0;0;0;7.349152;7.091644;7487462;9.050086e+008
1428;2.38007;-5.832332;8337.791;861.5734;0;0;0;7.496283;7.228608;7651963;9.261594e+008
1456;2.426677;-5.946826;8518.867;880.2847;0;0;0;7.643077;7.365073;7818145;9.475656e+008
1484;2.473284;-6.065099;8699.737;898.9746;0;0;0;7.789871;7.50135;7984137;9.690036e+008
1512;2.519945;-6.193104;8885.82;918.2032;0;0;0;7.936834;7.6376;8154913;9.910795e+008
1540;2.566713;-6.325076;9074.028;937.6515;0;0;0;8.084134;7.773976;8327641;1.013452e+009
1568;2.61332;-6.463487;9248.146;955.6436;0;0;0;8.230928;7.909698;8487436;1.034302e+009
1596;2.65998;-6.606526;9424.162;973.832;0;0;0;8.377891;8.045392;8648974;1.055419e+009
1624;2.706695;-6.749501;9594.563;991.4401;0;0;0;8.525023;8.181058;8805358;1.075961e+009
1652;2.753355;-6.894971;9759.365;1008.47;0;0;0;8.671986;8.316385;8956604;1.095924e+009
1678.786;2.778052;-7.00077;9669.083;999.1406;0;0;0;8.749769;8.387936;8873748;1.086563e+009
1706.786;2.731391;-6.956531;8863.403;915.8868;0;0;0;8.602807;8.252707;8134341;9.946788e+008
1734.786;2.68457;-6.911233;8118.952;838.96;0;0;0;8.455338;8.116827;7451124;9.098969e+008
1762.786;2.638016;-6.866592;7415.325;766.2518;0;0;0;8.308712;7.981541;6805375;8.299175e+008
1790.786;2.591355;-6.821818;6739.296;696.3953;0;0;0;8.161749;7.84576;6184953;7.532334e+008
1818.786;2.544641;-6.777098;6086.151;628.9036;0;0;0;8.014618;7.709639;5585533;6.793078e+008
1846.786;2.497927;-6.733084;5479.313;566.1968;0;0;0;7.867487;7.573331;5028610;6.107422e+008
1874.786;2.451373;-6.689907;4932.549;509.6977;0;0;0;7.720861;7.437308;4526820;5.490508e+008
1902.786;2.404713;-6.646656;4427.221;457.4804;0;0;0;7.573899;7.300786;4063058;4.921295e+008
1930.786;2.357945;-6.603658;3948.898;408.0536;0;0;0;7.426598;7.163762;3624080;4.383581e+008
1958.786;2.311284;-6.56058;3502.479;361.9236;0;0;0;7.279635;7.026865;3214381;3.882703e+008
1986.786;2.264731;-6.518096;3090.137;319.3148;0;0;0;7.13301;6.890096;2835957;3.420916e+008
2014.786;2.217963;-6.475373;2699.708;278.9704;0;0;0;6.98571;6.752509;2477643;2.984585e+008
2042.786;2.171249;-6.433602;2338.578;241.6536;0;0;0;6.838578;6.61489;2146218;2.581792e+008
2070.786;2.124695;-6.392124;2002.077;206.8817;0;0;0;6.691953;6.477556;1837395;2.207261e+008
2098.786;2.078034;-6.35071;1682.325;173.8406;0;0;0;6.54499;6.339715;1543945;1.852184e+008
2126.786;2.031266;-6.309617;1382.975;142.9077;0;0;0;6.39769;6.201368;1269218;1.520505e+008
2154.786;1.984606;-6.269884;1108.207;114.5149;0;0;0;6.250727;6.063146;1017051;1.21673e+008
2182.786;1.938052;-6.232865;865.2456;89.4089;0;0;0;6.104102;5.925052;794074.5;9.486651e+007
2210.786;1.891284;-6.197422;652.0849;67.38224;0;0;0;5.956801;5.786129;598447.4;7.139607e+007
2238.786;1.844624;-6.163182;466.9058;48.24703;0;0;0;5.809839;5.647333;428500.3;5.105011e+007
2266.786;1.797963;-6.134618;313.8627;32.43254;0;0;0;5.662876;5.508342;288045.8;3.426916e+007
2294.786;1.751356;-6.117244;200.9491;20.76478;0;0;0;5.516082;5.369319;184419.9;2.191018e+007
2322.786;1.704642;-6.11016;129.2342;13.35423;0;0;0;5.36895;5.229782;118604;1.407121e+007
2350.786;1.676892;-6.107774;106.056;10.95914;0;0;0;5.281549;5.146799;97332.34;1.153796e+007
2376.2;1.675927;-6.106552;115.064;11.88997;1;1;0;5.278512;5.143915;105599.4;1.251759e+007
2404.2;1.67132;-6.105366;113.875;11.7671;1;1;0;5.264001;5.13013;104508.1;1.238652e+007
2432.2;1.66666;-6.104611;111.0466;11.47484;1;1;0;5.249322;5.116184;101912.4;1.207719e+007
2460.2;1.661999;-6.10325;108.4567;11.20721;1;1;0;5.234643;5.102236;99535.55;1.179387e+007
2488.2;1.657285;-6.098967;109.9629;11.36286;1;1;0;5.219794;5.088125;100917.9;1.195597e+007
2516.2;1.652677;-6.092366;114.1409;11.79458;1;1;0;5.205283;5.074333;104752.2;1.240852e+007
2544.2;1.647963;-6.085347;116.6323;12.05203;1;1;0;5.190435;5.060219;107038.7;1.267759e+007
2572.2;1.63532;-6.064633;117.1999;12.11069;1;1;0;5.150615;5.022357;107559.6;1.273446e+007
2600.2;1.619356;-6.015466;135.7264;14.02509;1;1;0;5.100334;4.974527;124562.2;1.474042e+007
2628.2;1.585499;-5.931698;127.5814;13.18344;1;1;0;4.993698;4.873014;117087.1;1.384178e+007
2656.2;1.548213;-5.811166;128.804;13.30977;1;1;0;4.876262;4.761101;118209.1;1.395879e+007
2684.2;1.51082;-5.688914;125.2112;12.93851;1;1;0;4.75849;4.648742;114911.9;1.355419e+007
2712.2;1.473481;-5.535331;133.875;13.83378;1;1;0;4.640885;4.536416;122863.1;1.447579e+007
2740.2;1.431321;-5.36647;133.3744;13.78205;1;1;0;4.508096;4.409436;122403.7;1.440336e+007
2768.2;1.384499;-5.160112;143.2072;14.79811;1;1;0;4.360627;4.268228;131427.7;1.54434e+007
2796.2;1.324874;-4.899431;139.3638;14.40095;1;1;0;4.172832;4.088118;127900.3;1.500188e+007
2824.2;1.259356;-4.624396;131.4765;13.58594;1;1;0;3.966477;3.889832;120661.9;1.412482e+007
2852.2;1.194106;-4.32322;125.0113;12.91786;1;1;0;3.760965;3.691966;114728.4;1.340369e+007
2880.2;1.128856;-4.042297;107.1997;11.07733;1;1;0;3.555453;3.493706;98381.96;1.147118e+007
2908.2;1.075124;-3.79626;97.62326;10.08776;1;1;0;3.386218;3.330148;89593.23;1.042935e+007
2936.2;1.042714;-3.623089;99.16637;10.24721;1;1;0;3.284137;3.231362;91009.4;1.058374e+007
2964.2;1.033071;-3.507524;110.5251;11.42095;1;1;0;3.253766;3.201952;101433.8;1.179256e+007
2992.2;1.019035;-3.397915;106.564;11.01164;1;1;0;3.209559;3.159129;97798.56;1.136506e+007
3020.2;1.004999;-3.281581;105.6567;10.91788;1;1;0;3.165352;3.116288;96965.84;1.126347e+007
3048.2;0.9909637;-3.181691;98.93227;10.22302;1;1;0;3.121145;3.073428;90794.56;1.05421e+007
3076.2;0.977035;-3.087451;93.0013;9.610154;1;1;0;3.077276;3.030877;85351.45;9905885
3104.2;0.9639637;-3.001603;87.29126;9.020115;1;1;0;3.036106;2.990929;80111.09;9293975
3132.2;0.9593565;-2.937456;88.10126;9.103814;1;1;0;3.021595;2.976844;80854.45;9378895
3160.2;0.9546423;-2.877517;87.55232;9.047091;1;1;0;3.006747;2.962431;80350.66;9319114
3188.2;0.9500352;-2.822401;86.9043;8.980129;1;1;0;2.992237;2.948343;79755.95;9248836
3216.2;0.9453209;-2.769819;86.36623;8.924528;1;1;0;2.977389;2.933925;79262.14;9190246
3242.358;0.9462851;-2.733272;89.7557;9.274775;2;2;0;2.980426;2.936874;82372.81;9551202
3270.358;0.9509994;-2.69321;97.25022;10.04921;2;2;0;2.995274;2.951291;89250.87;1.035021e+007
3298.358;0.9556065;-2.659802;103.1579;10.65967;2;2;0;3.009784;2.965379;94672.63;1.098051e+007
3326.358;0.9584458;-2.62586;107.6181;11.12056;2;2;0;3.018727;2.97406;98765.93;1.145626e+007
3354.358;0.9588208;-2.589236;109.1811;11.28207;2;2;0;3.019908;2.975207;100200.4;1.162278e+007
3382.358;0.959303;-2.548533;112.16;11.58989;2;2;0;3.021427;2.976681;102934.2;1.194007e+007
3408.45;0.9592494;-2.516717;113.8155;11.76096;2;2;0;3.021258;2.976517;104453.6;1.211629e+007
3436.45;0.955178;-2.449461;113.8861;11.76826;2;2;0;3.008435;2.964069;104518.4;1.21223e+007
3464.45;0.9504637;-2.375777;113.1744;11.69471;2;2;0;2.993586;2.949653;103865.2;1.20448e+007
3492.45;0.9458565;-2.322261;111.9007;11.5631;2;2;0;2.979076;2.935563;102696.3;1.190757e+007
3520.45;0.9411423;-2.267203;110.6399;11.43282;2;2;0;2.964228;2.921144;101539.2;1.177171e+007
3548.45;0.9365351;-2.205306;108.0997;11.17032;2;2;0;2.949717;2.90705;99207.9;1.149982e+007
3576.45;0.9318744;-2.146503;106.1793;10.97188;2;2;0;2.935037;2.89279;97445.48;1.129391e+007
3604.45;0.9272137;-2.106532;103.2357;10.66771;2;2;0;2.920358;2.878528;94743.99;1.097924e+007
3632.45;0.9241066;-2.071457;102.1843;10.55907;2;2;0;2.910572;2.869019;93779.11;1.08664e+007
3660.45;0.9236244;-2.038171;102.5624;10.59813;2;2;0;2.909053;2.867544;94126.05;1.090644e+007
3688.45;0.9231958;-2.007599;103.3193;10.67635;2;2;0;2.907703;2.866232;94820.75;1.098679e+007
3716.45;0.9227673;-1.975539;103.9048;10.73685;2;2;0;2.906354;2.86492;95358.05;1.10489e+007
3744.45;0.9222851;-1.950681;101.9226;10.53203;2;2;0;2.904835;2.863444;93538.95;1.083796e+007
3772.45;0.921803;-1.927832;99.19837;10.25052;2;2;0;2.903316;2.861969;91038.77;1.054812e+007
3800.45;0.9212673;-1.911783;95.65913;9.884797;2;2;0;2.901629;2.860329;87790.66;1.017162e+007
3826.678;0.9209459;-1.898676;92.11567;9.518639;3;3;0;2.900617;2.859345;84538.66;9794738
3854.678;0.921428;-1.887939;89.14598;9.21177;3;3;0;2.902135;2.860821;81813.24;9479108
3882.678;0.9242137;-1.879175;88.26898;9.121146;3;3;0;2.910909;2.869347;81008.38;9386655
3910.678;0.9288744;-1.871555;89.55832;9.254378;3;3;0;2.925589;2.88361;82191.66;9525123
3938.678;0.9335887;-1.865022;90.99676;9.403018;3;3;0;2.940437;2.898035;83511.79;9679507
3966.678;0.9382494;-1.858724;93.02567;9.612672;3;3;0;2.955116;2.912294;85373.8;9896738
3994.678;0.9428566;-1.85152;94.80933;9.796984;3;3;0;2.969627;2.926388;87010.75;1.008792e+007
4022.678;0.9475708;-1.846404;96.25653;9.946527;3;3;0;2.984475;2.940806;88338.91;1.024338e+007
4050.678;0.952178;-1.8415;97.99038;10.12569;3;3;0;2.998986;2.954896;89930.14;1.042936e+007
4078.678;0.9568923;-1.837533;100.3657;10.37114;3;3;0;3.013834;2.96931;92110.05;1.068371e+007
4106.678;0.9616066;-1.833809;103.0917;10.65283;3;3;0;3.028682;2.983723;94611.89;1.097548e+007
4134.392;0.9658922;-1.830649;105.0992;10.86027;3;3;0;3.04218;2.996824;96454.19;1.119066e+007
4161.394;0.9654637;-1.82662;100.8341;10.41954;3;3;0;3.040831;2.995514;92539.95;1.073638e+007
4186.596;0.9654101;-1.823668;97.95649;10.12219;4;4;0;3.040662;2.99535;89899.05;1.042997e+007
4213.222;0.9661602;-1.820695;97.21275;10.04534;5;5;0;3.043024;2.997642;89216.48;1.035102e+007
4241.222;0.9684637;-1.818208;98.90784;10.2205;5;5;0;3.050279;3.004683;90772.13;1.053225e+007
4269.222;0.9696423;-1.815668;98.88253;10.21788;5;5;0;3.053991;3.008285;90748.91;1.052993e+007
4297.222;0.9710887;-1.81353;98.80571;10.20994;5;5;0;3.058547;3.012706;90678.41;1.052222e+007
4325.222;0.9719994;-1.811341;98.77717;10.20699;5;5;0;3.061415;3.015489;90652.21;1.051947e+007
4353.222;0.9727494;-1.809319;98.68855;10.19784;5;5;0;3.063778;3.017781;90570.88;1.051028e+007
4381.222;0.9734458;-1.807583;98.61426;10.19016;5;5;0;3.065971;3.019909;90502.7;1.050259e+007
4409.222;0.9741422;-1.805832;98.71633;10.20071;5;5;0;3.068165;3.022037;90596.38;1.051368e+007
4437.222;0.9748386;-1.804141;98.48987;10.17731;5;5;0;3.070358;3.024166;90388.55;1.048979e+007
4465.222;0.9755351;-1.802375;98.78821;10.20814;5;5;0;3.072551;3.026294;90662.34;1.052179e+007
4493.222;0.9762315;-1.800811;98.29917;10.1576;5;5;0;3.074745;3.028422;90213.54;1.046992e+007
4521.222;0.9769279;-1.799516;99.24124;10.25495;5;5;0;3.076938;3.03055;91078.12;1.057049e+007
4549.222;0.9776244;-1.798303;99.90782;10.32383;5;5;0;3.079132;3.032678;91689.86;1.064171e+007
4576.122;0.9794993;-1.797536;101.7613;10.51536;5;5;0;3.085037;3.038407;93390.88;1.083976e+007
4604.122;0.9466065;-1.79147;67.16153;6.940039;5;5;0;2.981438;2.937857;61637.13;7146951
4632.122;0.8999459;-1.787491;50.27183;5.194766;5;5;0;2.834475;2.795047;46136.7;5342010
4658.37;0.8871959;-1.786216;50.30123;5.197803;6;6;0;2.794318;2.755989;46163.68;5343047
4686.37;0.8876244;-1.785245;50.41707;5.209774;6;6;0;2.795667;2.757302;46269.99;5355422
4714.37;0.8881066;-1.78454;50.57755;5.226357;6;6;0;2.797186;2.758779;46417.27;5372548
4742.37;0.8885887;-1.78367;50.64582;5.233411;6;6;0;2.798705;2.760257;46479.93;5379879
4770.37;0.8890172;-1.783042;51.02988;5.273098;6;6;0;2.800054;2.76157;46832.39;5420747
4798.37;0.8894994;-1.782351;50.78251;5.247536;6;6;0;2.801573;2.763047;46605.37;5394550
4826.37;0.8899816;-1.781565;51.08549;5.278845;6;6;0;2.803092;2.764524;46883.43;5426816
4854.37;0.8904637;-1.781183;51.26553;5.297448;6;6;0;2.80461;2.766001;47048.66;5446021
4882.37;0.8908923;-1.780736;51.35227;5.306412;6;6;0;2.80596;2.767314;47128.27;5455307
4910.37;0.8913744;-1.780273;52.07184;5.380768;6;6;0;2.807478;2.768791;47788.65;5531832
4938.37;0.891803;-1.780042;51.88397;5.361354;6;6;0;2.808828;2.770104;47616.23;5511946
4966.37;0.8922852;-1.779736;52.17415;5.391339;6;6;0;2.810347;2.771581;47882.54;5542855
4994.37;0.8927673;-1.779451;52.12032;5.385777;6;6;0;2.811865;2.773058;47833.14;5537218
5022.37;0.8932495;-1.779431;51.95142;5.368324;6;6;0;2.813384;2.774535;47678.13;5519356
5050.37;0.8937316;-1.779274;51.77726;5.350327;6;6;0;2.814903;2.776012;47518.3;5500934
5078.37;0.8941602;-1.779097;52.20187;5.394204;6;6;0;2.816252;2.777325;47907.98;5546118
5106.37;0.8946423;-1.779124;52.51525;5.426586;6;6;0;2.817771;2.778802;48195.58;5579495
5134.37;0.8950708;-1.779001;52.84818;5.460989;6;6;0;2.819121;2.780115;48501.13;5614941
5162.37;0.895553;-1.779008;53.0993;5.486939;6;6;0;2.820639;2.781592;48731.6;5641706
5190.37;0.8960887;-1.779018;53.19315;5.496637;6;6;0;2.822327;2.783233;48817.73;5651770
5218.37;0.8964638;-1.779219;53.59782;5.538453;6;6;0;2.823508;2.784382;49189.11;5694832
5246.37;0.8969459;-1.779261;54.20385;5.601075;6;6;0;2.825026;2.785858;49745.29;5759307
5274.37;0.897428;-1.77958;54.96718;5.679953;6;6;0;2.826545;2.787335;50445.83;5840499
5302.37;0.8979101;-1.779768;55.26074;5.710288;6;6;0;2.828063;2.788812;50715.24;5871778
5330.37;0.8983922;-1.780116;56.28778;5.816416;6;6;0;2.829582;2.790289;51657.81;5980996
5358.37;0.8988744;-1.780546;56.956;5.885466;6;6;0;2.8311;2.791766;52271.06;6052089
5386.37;0.8993566;-1.780948;58.16203;6.010088;6;6;0;2.832619;2.793242;53377.89;6180331
5414.37;0.8997852;-1.78123;59.19228;6.116548;6;6;0;2.833969;2.794555;54323.39;6289889
5442.37;0.9002137;-1.781576;60.37761;6.239032;6;6;0;2.835319;2.795868;55411.22;6415928
5470.37;0.9006959;-1.782134;61.48626;6.353593;6;6;0;2.836838;2.797344;56428.68;6533834
5498.37;0.901178;-1.783059;62.74506;6.483669;6;6;0;2.838356;2.798821;57583.93;6667698
5526.37;0.9016065;-1.7832;63.57254;6.569176;6;6;0;2.839706;2.800133;58343.36;6755721
5554.37;0.9020887;-1.783682;64.19163;6.633149;6;6;0;2.841224;2.80161;58911.52;6821611
5582.37;0.9026245;-1.784224;65.24376;6.741869;6;6;0;2.842912;2.803251;59877.11;6933534
5610.37;0.903053;-1.784958;67.09915;6.933593;6;6;0;2.844261;2.804563;61579.89;7130803
5638.37;0.9035351;-1.785548;67.91886;7.018296;6;6;0;2.84578;2.80604;62332.17;7218022
5666.37;0.9039637;-1.786114;69.62476;7.194573;6;6;0;2.84713;2.807352;63897.75;7399412
5694.37;0.9044458;-1.786618;70.69166;7.304819;6;6;0;2.848648;2.808829;64876.89;7512908
5722.37;0.904928;-1.787281;71.85614;7.425149;6;6;0;2.850167;2.810305;65945.58;7636778
5750.37;0.9053566;-1.788025;73.18731;7.562704;6;6;0;2.851517;2.811618;67167.26;7778356
5778.37;0.9058387;-1.788673;74.21028;7.668411;6;6;0;2.853035;2.813094;68106.09;7887194
5806.37;0.9063209;-1.789507;75.67572;7.81984;6;6;0;2.854554;2.814571;69450.98;8043062
5834.37;0.9067494;-1.790265;76.68891;7.924537;6;6;0;2.855904;2.815883;70380.84;8150854
5862.37;0.9072316;-1.791003;78.18321;8.078948;6;6;0;2.857422;2.817359;71752.22;8309797
5890.37;0.9077137;-1.791839;79.28564;8.192865;6;6;0;2.858941;2.818836;72763.97;8427095
5918.37;0.9081422;-1.792634;80.42721;8.310828;6;6;0;2.860291;2.820148;73811.64;8548542
5946.37;0.9086244;-1.793529;81.838;8.45661;6;6;0;2.861809;2.821624;75106.38;8698622
5974.37;0.9091065;-1.794392;82.93599;8.570069;6;6;0;2.863328;2.823101;76114.05;8815459
6002.37;0.9095887;-1.795164;84.04467;8.684633;6;6;0;2.864846;2.824577;77131.55;8933435
6030.37;0.9100709;-1.796331;85.52858;8.837971;6;6;0;2.866365;2.826053;78493.39;9091299
6058.37;0.9104994;-1.797022;86.64789;8.953633;6;6;0;2.867715;2.827365;79520.63;9210398
6086.37;0.9109816;-1.798072;88.03636;9.097109;6;6;0;2.869233;2.828842;80794.89;9358126
6114.37;0.9114637;-1.799067;89.60636;9.259342;6;6;0;2.870752;2.830318;82235.75;9525155
6142.37;0.9118923;-1.7999;90.7373;9.376206;6;6;0;2.872102;2.83163;83273.66;9645501
6170.37;0.9123745;-1.800967;92.42382;9.55048;6;6;0;2.87362;2.833106;84821.46;9824925
6198.37;0.9128566;-1.801921;93.43607;9.65508;6;6;0;2.875139;2.834582;85750.45;9932677
6226.37;0.9133387;-1.803086;95.2411;9.8416;6;6;0;2.876657;2.836058;87407.01;1.012471e+007
6254.37;0.9137673;-1.804087;96.41386;9.962786;6;6;0;2.878007;2.83737;88483.3;1.024952e+007
6282.37;0.9141958;-1.805364;97.89911;10.11626;6;6;0;2.879357;2.838682;89846.38;1.040755e+007
6310.37;0.9147316;-1.806221;99.29011;10.26;6;6;0;2.881044;2.840323;91122.96;1.055559e+007
6338.37;0.9151601;-1.807521;100.7839;10.41436;6;6;0;2.882394;2.841635;92493.91;1.071454e+007
6366.37;0.9156423;-1.808481;102.1367;10.55415;6;6;0;2.883913;2.843111;93735.4;1.085852e+007
6394.37;0.9160709;-1.80978;103.6226;10.70769;6;6;0;2.885262;2.844423;95099.08;1.101663e+007
6422.37;0.9166065;-1.810863;104.8792;10.83754;6;6;0;2.88695;2.846062;96252.34;1.115042e+007
6450.37;0.9170351;-1.812145;106.4795;11.00291;6;6;0;2.8883;2.847374;97721.01;1.13207e+007
6478.37;0.9175172;-1.813336;107.8783;11.14744;6;6;0;2.889818;2.84885;99004.7;1.146958e+007
6506.37;0.9179459;-1.8145;109.025;11.26594;6;6;0;2.891168;2.850162;100057.1;1.159166e+007
6534.37;0.918428;-1.815612;111.054;11.4756;6;6;0;2.892687;2.851638;101919.2;1.180755e+007
6562.37;0.9189101;-1.817116;112.7097;11.64669;6;6;0;2.894205;2.853114;103438.7;1.198377e+007
6590.37;0.9193923;-1.81833;114.2127;11.802;6;6;0;2.895724;2.85459;104818.1;1.214376e+007
6618.37;0.9198744;-1.819648;115.5262;11.93774;6;6;0;2.897242;2.856066;106023.6;1.22836e+007
6646.37;0.920303;-1.821;117.1268;12.10313;6;6;0;2.898592;2.857377;107492.5;1.245395e+007
6674.37;0.9207852;-1.822379;118.8553;12.28174;6;6;0;2.900111;2.858853;109078.8;1.263792e+007
6702.37;0.9212137;-1.823695;120.2019;12.42089;6;6;0;2.90146;2.860165;110314.7;1.278128e+007
6730.37;0.9216959;-1.825049;121.7246;12.57823;6;6;0;2.902979;2.861641;111712.1;1.294338e+007
6758.37;0.922178;-1.826303;123.2679;12.73771;6;6;0;2.904498;2.863116;113128.5;1.310768e+007
6786.37;0.9226601;-1.827607;124.7821;12.89418;6;6;0;2.906016;2.864592;114518.1;1.326888e+007
6814.37;0.9230887;-1.829104;126.3312;13.05425;6;6;0;2.907366;2.865904;115939.8;1.343378e+007
6842.37;0.9235708;-1.830448;127.8316;13.20929;6;6;0;2.908885;2.867379;117316.7;1.359353e+007
6870.37;0.924053;-1.831909;129.6137;13.39344;6;6;0;2.910403;2.868855;118952.2;1.378324e+007
6898.37;0.9244816;-1.833481;131.0723;13.54417;6;6;0;2.911753;2.870167;120290.9;1.393854e+007
6926.37;0.9250172;-1.834831;132.8947;13.73248;6;6;0;2.91344;2.871806;121963.4;1.413257e+007
6954.37;0.9254459;-1.836178;134.6974;13.91876;6;6;0;2.91479;2.873118;123617.8;1.432446e+007
6982.37;0.925928;-1.837644;136.1908;14.07308;6;6;0;2.916309;2.874593;124988.4;1.448349e+007
7010.37;0.9264101;-1.839375;137.8538;14.24492;6;6;0;2.917827;2.876069;126514.6;1.466056e+007
7038.37;0.9268922;-1.840852;139.1741;14.38135;6;6;0;2.919346;2.877544;127726.3;1.480119e+007
7066.37;0.9273208;-1.842335;140.7691;14.54617;6;6;0;2.920696;2.878856;129190.1;1.497102e+007
7094.37;0.9277494;-1.843834;142.0187;14.6753;6;6;0;2.922045;2.880168;130336.9;1.510412e+007
7122.37;0.9282315;-1.845275;144.1875;14.8994;6;6;0;2.923564;2.881643;132327.3;1.5335e+007
7150.37;0.9287137;-1.846947;145.4381;15.02863;6;6;0;2.925082;2.883118;133475;1.546823e+007
7178.37;0.9291423;-1.848458;147.0388;15.19404;6;6;0;2.926432;2.88443;134944.1;1.563868e+007
7206.37;0.9296244;-1.849823;148.4321;15.33802;6;6;0;2.927951;2.885905;136222.8;1.578711e+007
7234.37;0.9301602;-1.851233;150.7483;15.57736;6;6;0;2.929638;2.887545;138348.4;1.603372e+007
7262.37;0.9305887;-1.852994;151.9745;15.70406;6;6;0;2.930988;2.888856;139473.8;1.616435e+007
7290.37;0.9310708;-1.854625;153.4714;15.85875;6;6;0;2.932507;2.890331;140847.6;1.632381e+007
7317.302;0.9308565;-1.855785;153.8842;15.9014;6;6;0;2.931832;2.889675;141226.4;1.63676e+007
7345.302;0.9143566;-1.850514;125.6053;12.97925;6;6;0;2.879863;2.839174;115273.6;1.335303e+007
7371.505;0.8937851;-1.843627;100.4218;10.37694;7;7;0;2.815071;2.776176;92161.58;1.066906e+007
7398.348;0.8938923;-1.844766;103.5293;10.69805;7;7;0;2.815409;2.776505;95013.44;1.099924e+007
7426.348;0.889928;-1.844352;98.84077;10.21357;7;7;0;2.802923;2.76436;90710.59;1.049985e+007
7454.348;0.887678;-1.844497;97.53065;10.07819;7;7;0;2.795836;2.757466;89508.23;1.035996e+007
7479.505;0.888428;-1.845334;100.5944;10.39477;8;8;0;2.798198;2.759764;92319.93;1.068564e+007
7507.505;0.886553;-1.845807;99.47129;10.27872;8;8;0;2.792293;2.754019;91289.23;1.056573e+007
7535.505;0.8852137;-1.846181;99.40545;10.27192;8;8;0;2.788074;2.749915;91228.82;1.055831e+007
7563.505;0.8838208;-1.84683;98.81276;10.21067;8;8;0;2.783688;2.745647;90684.88;1.049491e+007
7591.505;0.8824816;-1.847338;98.46144;10.17437;8;8;0;2.77947;2.741544;90362.45;1.045716e+007
7619.505;0.8810352;-1.84779;98.09063;10.13605;8;8;0;2.774914;2.737111;90022.14;1.041732e+007
7647.505;0.8796423;-1.84835;97.36333;10.0609;8;8;0;2.770527;2.732842;89354.66;1.033964e+007
7675.505;0.8782494;-1.849018;97.01553;10.02496;8;8;0;2.76614;2.728573;89035.48;1.030226e+007
7703.505;0.8768566;-1.849475;96.46225;9.967786;8;8;0;2.761753;2.724305;88527.71;1.024307e+007
7731.505;0.8754101;-1.850147;96.03817;9.923965;8;8;0;2.757197;2.719871;88138.51;1.019759e+007
7759.505;0.8739637;-1.850698;95.3205;9.849805;8;8;0;2.752642;2.715438;87479.88;1.012094e+007
7787.505;0.8726244;-1.851477;95.02398;9.819164;8;8;0;2.748423;2.711332;87207.74;1.008904e+007
7815.505;0.8711781;-1.852045;94.27102;9.741358;8;8;0;2.743868;2.706899;86516.72;1.000865e+007
7843.505;0.8697851;-1.85266;93.81687;9.694429;8;8;0;2.739481;2.702629;86099.92;9960006
7871.505;0.8683923;-1.853119;93.25401;9.636267;8;8;0;2.735094;2.698359;85583.36;9899828
7898.029;0.8688745;-1.854478;95.15201;9.832395;9;9;0;2.736613;2.699837;87325.25;1.010147e+007
7926.029;0.8702673;-1.856;98.30505;10.15821;9;9;0;2.740999;2.704107;90218.93;1.043665e+007
7952.607;0.8710709;-1.857468;99.94898;10.32808;9;9;0;2.74353;2.70657;91727.64;1.061144e+007
7980.607;0.8705887;-1.858511;100.6096;10.39635;9;9;0;2.742012;2.705092;92333.94;1.068142e+007
8008.607;0.870053;-1.859448;100.9513;10.43166;9;9;0;2.740324;2.70345;92647.52;1.071752e+007
8036.607;0.8674816;-1.859483;97.30167;10.05453;9;9;0;2.732225;2.695566;89298.08;1.032924e+007
8064.607;0.8628209;-1.858955;91.52421;9.45752;9;9;0;2.717546;2.681277;83995.84;9714533
8092.607;0.8605709;-1.859461;90.58648;9.360621;9;9;0;2.710459;2.674377;83135.26;9614338
8120.607;0.8600351;-1.860177;91.83471;9.489606;9;9;0;2.708772;2.672734;84280.8;9746657
8148.607;0.8596066;-1.861244;92.821;9.591522;9;9;0;2.707422;2.67142;85185.97;9851206
8176.607;0.8591244;-1.86208;93.50883;9.662599;9;9;0;2.705904;2.669941;85817.23;9924059
8204.607;0.8586423;-1.863086;94.21975;9.73606;9;9;0;2.704385;2.668463;86469.66;9999361
8232.607;0.8582138;-1.864208;94.73433;9.789234;9;9;0;2.703035;2.667149;86941.92;1.005384e+007
8260.607;0.8577851;-1.865114;95.12805;9.829918;9;9;0;2.701685;2.665834;87303.25;1.009549e+007
8288.607;0.857303;-1.865983;95.70166;9.889191;9;9;0;2.700167;2.664356;87829.68;1.015622e+007
8316.607;0.8567673;-1.867002;95.91901;9.911651;9;9;0;2.69848;2.662713;88029.15;1.017911e+007
8344.607;0.8563923;-1.868164;95.79374;9.898706;9;9;0;2.697299;2.661563;87914.19;1.01657e+007
8372.607;0.8559102;-1.869028;96.4114;9.962531;9;9;0;2.69578;2.660084;88481.04;1.02311e+007
8400.606;0.855428;-1.869905;96.93478;10.01661;9;9;0;2.694262;2.658605;88961.38;1.028649e+007
8428.606;0.8549995;-1.870978;97.41854;10.0666;9;9;0;2.692912;2.657291;89405.34;1.033769e+007
8456.606;0.8544637;-1.871781;97.64082;10.08957;9;9;0;2.691224;2.655648;89609.34;1.036111e+007
8484.606;0.8539816;-1.872781;97.74977;10.10083;9;9;0;2.689706;2.654169;89709.32;1.037251e+007
8512.606;0.8536066;-1.873962;98.47254;10.17552;9;9;0;2.688525;2.653019;90372.64;1.044909e+007
8540.606;0.8530709;-1.874843;98.45029;10.17322;9;9;0;2.686837;2.651376;90352.22;1.044655e+007
8568.606;0.8526423;-1.875897;99.19044;10.2497;9;9;0;2.685488;2.650061;91031.49;1.052495e+007
8596.606;0.8521066;-1.876538;98.96375;10.22627;9;9;0;2.6838;2.648418;90823.45;1.050073e+007
8624.606;0.8516244;-1.877663;99.20184;10.25088;9;9;0;2.682282;2.646939;91041.95;1.052583e+007
8652.606;0.8512495;-1.878541;99.47863;10.27948;9;9;0;2.681101;2.645789;91295.97;1.055508e+007
8680.606;0.8507673;-1.879607;100.1325;10.34704;9;9;0;2.679582;2.64431;91896.02;1.06243e+007
8708.606;0.8503388;-1.880386;100.3468;10.36919;9;9;0;2.678232;2.642995;92092.7;1.06469e+007
8736.606;0.8498566;-1.88136;100.4286;10.37765;9;9;0;2.676714;2.641516;92167.83;1.065543e+007
8764.606;0.8493745;-1.88229;100.802;10.41622;9;9;0;2.675195;2.640038;92510.46;1.069488e+007
8792.606;0.8488388;-1.883112;100.8305;10.41917;9;9;0;2.673508;2.638394;92536.66;1.069773e+007
8820.606;0.8484101;-1.884148;100.9638;10.43294;9;9;0;2.672158;2.637079;92658.95;1.071173e+007
8848.606;0.847928;-1.885117;101.2521;10.46274;9;9;0;2.67064;2.6356;92923.59;1.074216e+007
8876.606;0.8474995;-1.886151;101.6129;10.50002;9;9;0;2.66929;2.634286;93254.69;1.07803e+007
8904.606;0.8470173;-1.886849;101.6741;10.50635;9;9;0;2.667771;2.632806;93310.9;1.078663e+007
8932.606;0.8465887;-1.887789;101.8863;10.52827;9;9;0;2.666421;2.631492;93505.59;1.0809e+007
8960.606;0.8461066;-1.888794;101.9918;10.53918;9;9;0;2.664902;2.630013;93602.44;1.082003e+007
8988.606;0.8456245;-1.889732;102.1881;10.55946;9;9;0;2.663384;2.628533;93782.62;1.08407e+007
9016.606;0.8451959;-1.890559;102.4614;10.5877;9;9;0;2.662034;2.627219;94033.41;1.086955e+007
9044.606;0.8447137;-1.891531;102.8204;10.62479;9;9;0;2.660516;2.625739;94362.83;1.090747e+007
9072.606;0.8441781;-1.892364;102.649;10.60709;9;9;0;2.658828;2.624096;94205.61;1.088911e+007
9100.606;0.8437494;-1.893307;102.8992;10.63294;9;9;0;2.657479;2.622781;94435.16;1.09155e+007
9128.606;0.8432673;-1.894149;103.0792;10.65154;9;9;0;2.65596;2.621302;94600.41;1.093444e+007
9156.606;0.8427852;-1.895006;103.174;10.66133;9;9;0;2.654442;2.619823;94687.34;1.094433e+007
9184.606;0.8423566;-1.895858;103.4745;10.69239;9;9;0;2.653092;2.618508;94963.2;1.097607e+007
9212.606;0.841928;-1.896822;103.563;10.70153;9;9;0;2.651742;2.617193;95044.38;1.098531e+007
9240.606;0.8413923;-1.897592;103.416;10.68634;9;9;0;2.650054;2.615549;94909.47;1.096953e+007
9268.606;0.8410173;-1.898655;103.6672;10.7123;9;9;0;2.648873;2.614398;95140.04;1.099606e+007
9296.606;0.8404816;-1.899458;103.6963;10.71531;9;9;0;2.647186;2.612754;95166.72;1.099896e+007
9324.606;0.840053;-1.900392;104.1116;10.75822;9;9;0;2.645836;2.611439;95547.89;1.104287e+007
9352.606;0.8395709;-1.901317;103.9336;10.73983;9;9;0;2.644318;2.60996;95384.52;1.102382e+007
9380.606;0.8390352;-1.902272;103.691;10.71476;9;9;0;2.642631;2.608316;95161.87;1.099791e+007
9408.606;0.838553;-1.903014;103.9512;10.74165;9;9;0;2.641112;2.606837;95400.7;1.102535e+007
9436.606;0.8381245;-1.903988;104.0589;10.75277;9;9;0;2.639762;2.605522;95499.49;1.103662e+007
9464.606;0.8376958;-1.904704;104.205;10.76787;9;9;0;2.638412;2.604206;95633.53;1.105197e+007
9492.606;0.8372137;-1.905545;104.2018;10.76755;9;9;0;2.636894;2.602727;95630.68;1.105147e+007
9520.606;0.8367852;-1.906614;104.5625;10.80481;9;9;0;2.635544;2.601412;95961.66;1.108958e+007
9548.606;0.8362495;-1.907236;104.2781;10.77542;9;9;0;2.633857;2.599768;95700.63;1.105923e+007
9576.606;0.8358209;-1.908127;104.4551;10.79371;9;9;0;2.632507;2.598453;95863.09;1.107786e+007
9604.606;0.8353387;-1.908953;104.5538;10.80391;9;9;0;2.630988;2.596973;95953.69;1.108816e+007
9632.606;0.8348566;-1.909781;104.3119;10.77892;9;9;0;2.62947;2.595493;95731.68;1.106235e+007
9660.606;0.8344281;-1.910729;104.4857;10.79688;9;9;0;2.62812;2.594178;95891.22;1.108064e+007
9688.606;0.8339994;-1.911434;104.5122;10.79962;9;9;0;2.62677;2.592863;95915.53;1.10833e+007
9716.606;0.8334638;-1.912415;104.3669;10.7846;9;9;0;2.625083;2.591219;95782.18;1.106771e+007
9744.606;0.8330352;-1.913109;104.4895;10.79727;9;9;0;2.623733;2.589903;95894.67;1.108056e+007
9772.606;0.8326066;-1.913885;105.0933;10.85967;9;9;0;2.622383;2.588588;96448.84;1.114445e+007
9800.606;0.8320709;-1.914662;104.3702;10.78494;9;9;0;2.620696;2.586944;95785.2;1.106758e+007
9828.606;0.8315887;-1.915485;104.1143;10.7585;9;9;0;2.619177;2.585464;95550.31;1.104028e+007
9856.606;0.8311066;-1.916352;104.2079;10.76818;9;9;0;2.617659;2.583984;95636.28;1.105005e+007
9884.606;0.830678;-1.917221;104.2649;10.77406;9;9;0;2.616309;2.582669;95688.56;1.105595e+007
9912.606;0.8302495;-1.917873;104.428;10.79092;9;9;0;2.614959;2.581354;95838.24;1.107309e+007
9940.606;0.8297674;-1.918682;104.3551;10.78338;9;9;0;2.613441;2.579874;95771.3;1.10652e+007
9968.606;0.8292851;-1.919466;104.1261;10.75972;9;9;0;2.611922;2.578394;95561.2;1.104076e+007
9996.606;0.8288566;-1.920296;104.4905;10.79737;9;9;0;2.610572;2.577078;95895.59;1.107925e+007
10024.61;0.8283209;-1.921015;103.8495;10.73113;9;9;0;2.608885;2.575434;95307.29;1.10111e+007
10052.61;0.8278387;-1.921699;103.9392;10.74041;9;9;0;2.607366;2.573954;95389.64;1.102045e+007
10080.61;0.8274638;-1.92265;104.261;10.77366;9;9;0;2.606185;2.572803;95684.95;1.105444e+007
10108.61;0.826928;-1.923207;104.0645;10.75336;9;9;0;2.604498;2.571158;95504.66;1.103343e+007
10136.61;0.8265531;-1.924063;104.5049;10.79886;9;9;0;2.603317;2.570007;95908.79;1.107999e+007
10164.61;0.8260709;-1.924777;104.1308;10.76021;9;9;0;2.601798;2.568527;95565.51;1.104017e+007
10192.61;0.8255352;-1.925368;103.9497;10.74149;9;9;0;2.600111;2.566883;95399.29;1.102078e+007
10220.61;0.8251066;-1.92632;104.0054;10.74725;9;9;0;2.598761;2.565567;95450.38;1.102654e+007
10248.61;0.824678;-1.927167;104.2257;10.77002;9;9;0;2.597411;2.564251;95652.62;1.104976e+007
10276.61;0.8241959;-1.927845;103.9835;10.74498;9;9;0;2.595893;2.562771;95430.28;1.102391e+007
10304.61;0.8237138;-1.928583;103.7714;10.72306;9;9;0;2.594374;2.561291;95235.6;1.100126e+007
10332.61;0.8232316;-1.929135;103.531;10.69823;9;9;0;2.592855;2.559811;95015.05;1.097562e+007
10360.61;0.8226959;-1.929671;103.3239;10.67682;9;9;0;2.591168;2.558166;94824.95;1.095348e+007
10388.61;0.8222673;-1.930577;103.4551;10.69038;9;9;0;2.589818;2.556851;94945.36;1.096724e+007
10416.61;0.8218388;-1.931339;103.5159;10.69666;9;9;0;2.588469;2.555535;95001.15;1.097354e+007
10444.61;0.8213567;-1.931978;103.3754;10.68215;9;9;0;2.58695;2.554055;94872.22;1.095849e+007
10472.61;0.8208744;-1.932723;102.4454;10.58604;9;9;0;2.585431;2.552574;94018.69;1.085974e+007
10500.61;0.8204459;-1.933315;102.9572;10.63893;9;9;0;2.584082;2.551259;94488.41;1.091385e+007
10528.61;0.8199102;-1.933967;102.3983;10.58118;9;9;0;2.582394;2.549614;93975.46;1.085442e+007
10556.61;0.8194816;-1.934641;102.4703;10.58862;9;9;0;2.581044;2.548298;94041.6;1.086192e+007
10584.61;0.8190531;-1.935458;102.6221;10.60431;9;9;0;2.579695;2.546982;94180.92;1.087787e+007
10612.61;0.8185708;-1.935989;102.4385;10.58533;9;9;0;2.578176;2.545501;94012.38;1.085824e+007
10640.61;0.8180887;-1.936693;102.1834;10.55897;9;9;0;2.576658;2.544021;93778.25;1.083104e+007
10668.61;0.8175531;-1.937234;101.8752;10.52712;9;9;0;2.57497;2.542376;93495.4;1.079819e+007
10696.61;0.8171245;-1.937944;101.6058;10.49929;9;9;0;2.57362;2.54106;93248.16;1.07695e+007
10724.61;0.8166424;-1.938521;101.6677;10.50568;9;9;0;2.572102;2.53958;93304.97;1.07759e+007
10752.61;0.8162137;-1.939222;101.4389;10.48204;9;9;0;2.570752;2.538264;93095.04;1.075151e+007
10780.61;0.8157852;-1.939742;101.6107;10.49979;9;9;0;2.569402;2.536948;93252.69;1.076958e+007
10808.61;0.8153031;-1.940426;100.9892;10.43557;9;9;0;2.567884;2.535467;92682.29;1.070354e+007
10836.61;0.8147673;-1.941179;100.8425;10.42041;9;9;0;2.566196;2.533822;92547.65;1.068782e+007
10864.61;0.8143388;-1.94163;100.6766;10.40327;9;9;0;2.564847;2.532506;92395.44;1.06701e+007
10892.61;0.8138566;-1.942288;100.411;10.37582;9;9;0;2.563328;2.531025;92151.66;1.064179e+007
10920.61;0.8134281;-1.942817;100.2684;10.36109;9;9;0;2.561978;2.529709;92020.79;1.062654e+007
10948.61;0.8129459;-1.943433;99.8152;10.31426;9;9;0;2.56046;2.528229;91604.86;1.057835e+007
10976.61;0.8125173;-1.943988;100.0876;10.34241;9;9;0;2.55911;2.526913;91854.9;1.060708e+007
11004.61;0.8119816;-1.944591;99.42806;10.27425;9;9;0;2.557422;2.525267;91249.57;1.053701e+007
11032.61;0.8116066;-1.945387;99.94611;10.32779;9;9;0;2.556241;2.524116;91725;1.059179e+007
11060.61;0.8111245;-1.945941;99.52397;10.28416;9;9;0;2.554723;2.522635;91337.58;1.05469e+007
11088.61;0.8106424;-1.946446;99.34725;10.2659;9;9;0;2.553204;2.521154;91175.4;1.052801e+007
11116.61;0.8101602;-1.94701;98.66646;10.19555;9;9;0;2.551686;2.519674;90550.61;1.045571e+007
11144.61;0.809678;-1.947545;98.51876;10.18029;9;9;0;2.550167;2.518193;90415.06;1.043991e+007
11172.61;0.8092495;-1.948149;98.63146;10.19194;9;9;0;2.548817;2.516876;90518.49;1.045171e+007
11200.61;0.8087673;-1.948645;97.97611;10.12422;9;9;0;2.547299;2.515396;89917.05;1.038211e+007
11228.61;0.8082852;-1.949236;97.94216;10.12071;9;9;0;2.54578;2.513915;89885.89;1.037836e+007
11256.61;0.807803;-1.94951;97.60917;10.0863;9;9;0;2.544261;2.512434;89580.29;1.034292e+007
11284.61;0.8073209;-1.950234;97.25562;10.04977;9;9;0;2.542743;2.510953;89255.82;1.030531e+007
11312.61;0.8068388;-1.950716;96.95992;10.01921;9;9;0;2.541224;2.509472;88984.45;1.027382e+007
11340.61;0.8064102;-1.951274;96.76347;9.998912;9;9;0;2.539875;2.508156;88804.15;1.025287e+007
11368.61;0.8059816;-1.951708;96.52897;9.97468;9;9;0;2.538525;2.506839;88588.94;1.022789e+007
11396.61;0.8054994;-1.952275;96.11605;9.932012;9;9;0;2.537006;2.505358;88209.98;1.018399e+007
11424.61;0.8050173;-1.952777;95.81835;9.901249;9;9;0;2.535488;2.503877;87936.77;1.015229e+007
11452.61;0.8045352;-1.953208;95.59911;9.878594;9;9;0;2.533969;2.502396;87735.57;1.012892e+007
11480.61;0.8041066;-1.953906;95.59195;9.877855;9;9;0;2.532619;2.50108;87729;1.012802e+007
11508.61;0.8036245;-1.954401;95.23435;9.840902;9;9;0;2.531101;2.499599;87400.8;1.008999e+007
11536.61;0.8031959;-1.95473;95.20275;9.837638;9;9;0;2.529751;2.498282;87371.81;1.008651e+007
11564.61;0.8027138;-1.955199;94.59708;9.775051;9;9;0;2.528232;2.496801;86815.96;1.002219e+007
11592.61;0.8022852;-1.95581;94.60442;9.77581;9;9;0;2.526883;2.495485;86822.7;1.002283e+007
11620.61;0.8017495;-1.956094;93.80518;9.693221;9;9;0;2.525195;2.493839;86089.2;9937994
11648.61;0.8013209;-1.956738;93.77799;9.690412;9;9;0;2.523845;2.492522;86064.24;9934983
11676.61;0.8008388;-1.957151;93.00841;9.610888;9;9;0;2.522327;2.491041;85357.96;9853306
11704.61;0.8003566;-1.95751;92.67583;9.576521;9;9;0;2.520808;2.48956;85052.73;9817927
11732.61;0.7998745;-1.95787;92.1344;9.520574;9;9;0;2.51929;2.488079;84555.85;9760425
11760.61;0.7994459;-1.958368;91.64707;9.470217;9;9;0;2.51794;2.486762;84108.6;9708671
11788.61;0.7989637;-1.958849;91.42261;9.447021;9;9;0;2.516421;2.485281;83902.6;9684748
11816.61;0.7985352;-1.959225;91.3324;9.4377;9;9;0;2.515071;2.483964;83819.82;9675065
11844.61;0.7979995;-1.959642;90.31234;9.332294;9;9;0;2.513384;2.482318;82883.66;9566850
11872.61;0.7975709;-1.959916;90.36355;9.337585;9;9;0;2.512034;2.481001;82930.66;9572149
11900.61;0.7970887;-1.960225;89.87352;9.286949;9;9;0;2.510516;2.47952;82480.94;9520099
11928.61;0.7966066;-1.960673;89.36698;9.234606;9;9;0;2.508997;2.478039;82016.06;9466302
11956.61;0.7961781;-1.961234;89.12918;9.210034;9;9;0;2.507648;2.476722;81797.83;9440989
11984.61;0.7956959;-1.96143;88.87313;9.183576;9;9;0;2.506129;2.47524;81562.84;9413727
12012.61;0.7952138;-1.96184;88.38262;9.132889;9;9;0;2.50461;2.473759;81112.67;9361632
12040.61;0.7947852;-1.96227;88.08041;9.10166;9;9;0;2.50326;2.472442;80835.31;9329498
12068.61;0.7942495;-1.96255;87.1559;9.006127;9;9;0;2.501573;2.470796;79986.85;9231422
12096.61;0.7938209;-1.962971;87.06299;8.996527;9;9;0;2.500223;2.469479;79901.59;9221460
12124.61;0.7933923;-1.963667;86.34297;8.922125;9;9;0;2.498873;2.468162;79240.8;9145077
12152.61;0.7929102;-1.964068;86.12056;8.899142;9;9;0;2.497355;2.466681;79036.68;9121386
12180.61;0.792428;-1.964321;85.39139;8.823794;9;9;0;2.495836;2.465199;78367.48;9044022
12208.61;0.7919459;-1.964587;84.97342;8.780603;9;9;0;2.494318;2.463718;77983.89;8999620
12236.61;0.7915174;-1.965096;84.65704;8.747911;9;9;0;2.492968;2.462401;77693.54;8965994
12264.61;0.790928;-1.965206;83.84458;8.663958;9;9;0;2.491112;2.46059;76947.91;8879786
12292.61;0.7905531;-1.965547;83.78433;8.657731;9;9;0;2.489931;2.459437;76892.62;8873303
12320.61;0.7901245;-1.965902;83.61848;8.640594;9;9;0;2.488581;2.45812;76740.41;8855622
12348.61;0.7896424;-1.966091;83.0804;8.584992;9;9;0;2.487062;2.456639;76246.59;8798506
12376.61;0.7891602;-1.966552;82.68263;8.543889;9;9;0;2.485544;2.455157;75881.54;8756251
12404.61;0.7886245;-1.966748;81.88292;8.461252;9;9;0;2.483856;2.45351;75147.61;8671418
12432.61;0.7882495;-1.967275;81.86935;8.45985;9;9;0;2.482676;2.452358;75135.16;8669881
12460.61;0.7877673;-1.967473;81.30667;8.401707;9;9;0;2.481157;2.450876;74618.76;8610166
12488.61;0.7872852;-1.967703;80.81864;8.351276;9;9;0;2.479638;2.449394;74170.87;8558357
12516.61;0.7868566;-1.967973;80.55066;8.323585;9;9;0;2.478289;2.448077;73924.93;8529867
12544.61;0.7863209;-1.968372;79.63557;8.229026;9;9;0;2.476601;2.446431;73085.12;8432826
12572.61;0.7858923;-1.968639;79.42568;8.207336;9;9;0;2.475251;2.445113;72892.48;8410489
12600.61;0.7854638;-1.969029;79.07219;8.170809;9;9;0;2.473902;2.443796;72568.07;8372947
12628.61;0.7849816;-1.969349;78.76824;8.1394;9;9;0;2.472383;2.442314;72289.13;8340638
12656.61;0.784553;-1.969715;78.98257;8.161549;9;9;0;2.471033;2.440997;72485.83;8363223
12684.61;0.7840709;-1.970216;78.3268;8.093785;9;9;0;2.469515;2.439515;71883.99;8293662
12712.61;0.7835888;-1.970195;77.83204;8.042661;9;9;0;2.467996;2.438033;71429.94;8241153
12740.61;0.7831067;-1.970842;77.62901;8.021681;9;9;0;2.466478;2.436551;71243.6;8219533
12768.61;0.7826245;-1.971109;77.11002;7.968052;9;9;0;2.464959;2.435069;70767.3;8164461
12796.61;0.7821424;-1.971499;77.01805;7.958548;9;9;0;2.463441;2.433587;70682.9;8154602
12824.61;0.7817138;-1.971759;76.79741;7.935749;9;9;0;2.46209;2.43227;70480.41;8131134
12852.61;0.7812316;-1.972281;76.76555;7.932456;9;9;0;2.460572;2.430788;70451.16;8127640
12880.61;0.7807495;-1.972954;76.83796;7.939939;9;9;0;2.459054;2.429306;70517.63;8135186
12908.61;0.7802673;-1.973446;76.44709;7.899549;9;9;0;2.457535;2.427823;70158.91;8093683
12936.61;0.7797852;-1.97396;76.16185;7.870073;9;9;0;2.456016;2.426341;69897.13;8063364
12964.61;0.7793566;-1.974646;76.25661;7.879865;9;9;0;2.454667;2.425024;69984.09;8073289
12992.61;0.7789281;-1.975332;76.07737;7.861343;9;9;0;2.453317;2.423706;69819.59;8054207
13020.61;0.7783924;-1.975807;75.7131;7.823702;9;9;0;2.451629;2.422059;69485.28;8015510
13048.61;0.7779637;-1.976492;75.38213;7.789502;9;9;0;2.450279;2.420742;69181.54;7980367
13076.61;0.7775352;-1.977098;75.54519;7.806352;9;9;0;2.44893;2.419424;69331.2;7997524
13104.61;0.7770531;-1.977651;75.35609;7.786811;9;9;0;2.447411;2.417942;69157.64;7977387
13132.61;0.7765709;-1.978146;74.82368;7.731795;9;9;0;2.445893;2.41646;68669.02;7920907
13160.61;0.7760888;-1.978721;74.55773;7.704314;9;9;0;2.444374;2.414977;68424.95;7892636
13188.61;0.7755531;-1.979349;74.36351;7.684245;9;9;0;2.442687;2.41333;68246.71;7871947
13216.61;0.7751781;-1.97989;74.43217;7.691339;9;9;0;2.441506;2.412177;68309.72;7879124
13244.61;0.7746959;-1.980608;74.14043;7.661193;9;9;0;2.439987;2.410695;68041.98;7848125
13272.61;0.7742673;-1.981225;73.83046;7.629162;9;9;0;2.438637;2.409377;67757.5;7815210
13300.61;0.7737852;-1.98171;73.71276;7.617001;9;9;0;2.437119;2.407895;67649.48;7802636
13328.61;0.7732495;-1.98223;73.13114;7.5569;9;9;0;2.435431;2.406248;67115.71;7740943
13356.61;0.7728209;-1.982724;73.36189;7.580744;9;9;0;2.434082;2.40493;67327.48;7765265
13384.61;0.7723388;-1.983162;72.86525;7.529424;9;9;0;2.432563;2.403448;66871.69;7712582
13412.61;0.7719102;-1.983809;72.8769;7.530629;9;9;0;2.431213;2.40213;66882.38;7713714
13440.61;0.7714281;-1.984342;72.58311;7.50027;9;9;0;2.429695;2.400647;66612.76;7682504
13468.61;0.7709459;-1.985053;71.87928;7.42754;9;9;0;2.428176;2.399165;65966.82;7607894
13496.61;0.7704637;-1.984296;72.0907;7.449388;9;9;0;2.426657;2.397682;66160.85;7630159
13524.61;0.7700353;-1.985315;71.79908;7.419253;9;9;0;2.425308;2.396364;65893.22;7599193
13552.61;0.7696066;-1.98503;71.65299;7.404157;9;9;0;2.423958;2.395046;65759.15;7583631
13580.61;0.7691245;-1.984617;71.17506;7.354771;9;9;0;2.422439;2.393564;65320.52;7532935
13608.61;0.7686423;-1.98455;70.4988;7.28489;9;9;0;2.420921;2.392081;64699.89;7461252
13636.61;0.7681602;-1.984563;69.93905;7.227049;9;9;0;2.419402;2.390598;64186.18;7401901
13664.61;0.7676781;-1.984798;69.27063;7.157979;9;9;0;2.417884;2.389116;63572.74;7331051
13692.61;0.7671959;-1.985041;68.8639;7.115951;9;9;0;2.416365;2.387633;63199.47;7287898
13720.61;0.7667673;-1.985319;68.64349;7.093175;9;9;0;2.415015;2.386315;62997.19;7264476
13748.61;0.7662852;-1.985646;68.04064;7.03088;9;9;0;2.413497;2.384832;62443.93;7200570
13776.61;0.7658566;-1.98692;67.27511;6.951776;9;9;0;2.412147;2.383514;61741.37;7119462
13804.61;0.7653209;-1.989132;66.28744;6.849715;9;9;0;2.41046;2.381867;60834.94;7014825
13832.61;0.7648923;-1.991081;66.25146;6.845998;9;9;0;2.40911;2.380548;60801.92;7010926
13860.61;0.7644102;-1.992502;65.72085;6.791168;9;9;0;2.407591;2.379066;60314.95;6954671
13888.61;0.7639817;-1.993948;66.06564;6.826797;9;9;0;2.406241;2.377748;60631.39;6991066
13916.61;0.763553;-1.994675;65.74939;6.794117;9;9;0;2.404891;2.376429;60341.14;6957508
13944.61;0.7630174;-1.995405;65.19898;6.737242;9;9;0;2.403204;2.374782;59836.02;6899151
13972.61;0.7625352;-1.996126;65.29771;6.747443;9;9;0;2.401686;2.373299;59926.62;6909496
14000.61;0.7621066;-1.996838;65.30793;6.748499;9;9;0;2.400336;2.371981;59936;6910486
14028.61;0.7616245;-1.997492;65.07172;6.724091;9;9;0;2.398818;2.370498;59719.22;6885390
14056.61;0.7611959;-1.997973;65.46785;6.765024;9;9;0;2.397467;2.369179;60082.76;6927214
14084.61;0.7607138;-1.998619;65.00917;6.717628;9;9;0;2.395949;2.367697;59661.81;6878578
14112.61;0.7601781;-1.998916;64.41924;6.656668;9;9;0;2.394262;2.366049;59120.41;6816046
14140.61;0.7596959;-1.999429;64.34821;6.649328;9;9;0;2.392743;2.364566;59055.22;6808429
14168.61;0.7592674;-2.001766;64.46893;6.661802;9;9;0;2.391393;2.363247;59166.01;6821112
14196.61;0.7588388;-2.000922;64.60656;6.676024;9;9;0;2.390043;2.361929;59292.32;6835584
14224.61;0.7583566;-2.000277;64.47591;6.662524;9;9;0;2.388525;2.360446;59172.42;6821660
14252.61;0.7579281;-1.999775;64.35282;6.649804;9;9;0;2.387175;2.359127;59059.45;6808547
14280.61;0.7574459;-1.999319;64.06666;6.620234;9;9;0;2.385656;2.357644;58796.83;6778171
14308.61;0.7569638;-1.999108;63.3807;6.549353;9;9;0;2.384138;2.356161;58167.3;6705498
14336.61;0.7564816;-1.998933;63.02049;6.51213;9;9;0;2.382619;2.354678;57836.71;6667290
14364.61;0.7559995;-1.998631;62.8377;6.493242;9;9;0;2.381101;2.353195;57668.96;6647852
14392.61;0.7555709;-1.998753;62.4357;6.451702;9;9;0;2.379751;2.351876;57300.03;6605236
14420.61;0.7550888;-1.998742;62.12831;6.419939;9;9;0;2.378232;2.350393;57017.93;6572620
14448.61;0.7546602;-1.99896;61.85731;6.391934;9;9;0;2.376883;2.349074;56769.21;6543863
14476.61;0.754178;-2.001884;62.5356;6.462025;9;9;0;2.375364;2.347591;57391.71;6615521
14504.61;0.7536424;-2.004121;61.48778;6.35375;9;9;0;2.373677;2.345943;56430.08;6504568
14532.61;0.7532138;-2.006237;61.02051;6.305465;9;9;0;2.372327;2.344625;56001.24;6455051
14560.61;0.7527852;-2.007892;60.88379;6.291337;9;9;0;2.370977;2.343306;55875.77;6440504
14588.61;0.7523031;-2.008858;60.5848;6.260442;9;9;0;2.369459;2.341823;55601.38;6408781
14616.61;0.7518209;-2.010084;60.24664;6.225499;9;9;0;2.36794;2.340339;55291.03;6372915
14644.61;0.7513388;-2.011117;60.42003;6.243416;9;9;0;2.366421;2.338856;55450.16;6391162
14672.61;0.7508566;-2.012033;60.18776;6.219415;9;9;0;2.364903;2.337372;55237;6366498
14700.61;0.7504281;-2.013333;61.01634;6.305034;9;9;0;2.363553;2.336054;55997.41;6454057
14728.61;0.749946;-2.013908;60.51893;6.253635;9;9;0;2.362035;2.33457;55540.93;6401349
14756.61;0.7494638;-2.014459;60.16609;6.217175;9;9;0;2.360516;2.333087;55217.11;6363933
14784.61;0.7490352;-2.015155;60.25527;6.226391;9;9;0;2.359166;2.331768;55298.95;6373282
14812.61;0.7485531;-2.015652;60.1535;6.215874;9;9;0;2.357647;2.330284;55205.55;6362422
14840.61;0.7481245;-2.016116;59.98139;6.198089;9;9;0;2.356298;2.328966;55047.59;6344135
14868.61;0.7476424;-2.016545;59.94295;6.194117;9;9;0;2.354779;2.327482;55012.32;6339975
14896.61;0.7471602;-2.016302;59.68129;6.167079;9;9;0;2.353261;2.325998;54772.18;6312206
14924.61;0.7466781;-2.016009;59.77446;6.176706;9;9;0;2.351742;2.324514;54857.69;6321967
14952.61;0.7462495;-2.016218;59.82843;6.182284;9;9;0;2.350392;2.323196;54907.22;6327592
14980.61;0.7457138;-2.020365;59.85307;6.184829;9;9;0;2.348705;2.321547;54929.83;6330093
15008.61;0.7452852;-2.020272;59.81909;6.181319;9;9;0;2.347355;2.320229;54898.65;6326416
15017.59;0.745178;-2.020178;59.88346;6.18797;9;9;0;2.347018;2.319898;54957.72;6333203