File: Ensayos/Resistencia/comp/Clavo5/Clavo5c.raw
"Test Type";"Manual"
"Method Name:";"C:\INSTRON\user\template\CYCLE.MTM"
"Name:";""
"Operator ID:";""
"Company:";""
"Lab name:";""
"Test date:";"24/05/2017"
"Temperature:";""
"Humidity:";""
"Note 1:";""
"Note 2:";""
"Note 3:";""
"Geometry:";"Rectangular"
"Specimen";1
"Specimen name:";""
"Width:";0.250000;"in"
"Thickness:";0.060000;"in"
"Length:";1.250000;"in"
"Diameter:";0.039370;"in"
"Inner diameter:";0.019685;"in"
"Outer diameter:";0.039370;"in"
"Wall thickness:";0.019685;"in"
"Area:";0.015000;"in*in"
"Linear density:";1.000000;"den"
"Sled weight:";2.204623;"lbf"
"Loading span:";0.000000;"mm"
"Support span:";1.000000;"mm"
"Span ratio:";"2"
"Fixture type:";"3-point"
"Comment:";""
"Included"
"Final Width:";0.250000;"in"
"Final Thickness:";0.060000;"in"
"Final Length:";1.250000;"in"
"Final Diameter:";0.039370;"in"
"Final Inner diameter:";0.019685;"in"
"Final Outer diameter:";0.039370;"in"
"Final Wall thickness:";0.019685;"in"
"Final Area:";0.015000;"in*in"
"Final Linear density:";1.000000;"den"
"Time sec";"Extension mm";"Strain 1 %";"Load N";"Stress MPa";"Cycle Count ";"Total Cycle Count ";"Repetitions Count ";"Strain [Exten.] %";"True strain %";"Tenacity gf/tex";"True stress Pa"
0;0;-4.728932e-005;58.60711;6.05608;0;0;0;0;0;53786.36;6056080
1;0.001607142;9.015574e-005;62.11618;6.418685;0;0;0;0.005061864;0.005061736;57006.79;6419010
2;0.003374998;0.0001038493;66.26365;6.847258;0;0;0;0.01062991;0.01062935;60813.11;6847986
3;0.004928568;0.0002710112;69.63146;7.195265;0;0;0;0.01552305;0.01552184;63903.89;7196382
4;0.006803567;0.0002577972;73.54809;7.599984;0;0;0;0.02142856;0.02142626;67498.36;7601613
5;0.008357138;0.0002485377;76.75671;7.931543;0;0;0;0.02632169;0.02631823;70443.05;7933631
6;0.01012499;0.0003854248;80.34998;8.302848;0;0;0;0.03188974;0.03188466;73740.76;8305495
7;0.01167856;0.0003098114;83.3461;8.612447;0;0;0;0.03678288;0.03677611;76490.43;8615615
8;0.01333928;0.0003734147;86.22246;8.909672;0;0;0;0.04201347;0.04200465;79130.2;8913415
9;0.01499999;0.0003033512;88.89392;9.185723;0;0;0;0.04724407;0.04723291;81581.91;9190063
10;0.01676785;0.0004313899;91.40317;9.445013;0;0;0;0.05281211;0.05279818;83884.76;9450001
11;0.01837499;0.0004231091;93.26147;9.637037;0;0;0;0.05787398;0.05785724;85590.21;9642615
12;0.02008927;0.0003660247;95.27234;9.844829;0;0;0;0.0632733;0.06325329;87435.68;9851058
13;0.02174999;0.0005728187;96.73939;9.996424;0;0;0;0.06850389;0.06848044;88782.05;1.000327e+007
14;0.02335713;0.0007341175;97.83105;10.10923;0;0;0;0.07356575;0.07353871;89783.91;1.011667e+007
15;0.02496427;0.0007462156;98.94789;10.22464;0;0;0;0.07862762;0.07859673;90808.89;1.023268e+007
16;0.0267857;0.0006200269;100.2713;10.36139;0;0;0;0.0843644;0.08432883;92023.44;1.037013e+007
17;0.02839284;0.0006460829;101.1999;10.45735;0;0;0;0.08942626;0.08938631;92875.67;1.04667e+007
18;0.03005355;0.0006920187;102.8519;10.62805;0;0;0;0.09465685;0.09461209;94391.77;1.063811e+007
19;0.03171427;0.0008101224;103.9455;10.74106;0;0;0;0.09988745;0.0998376;95395.46;1.075179e+007
20;0.03332141;0.0007300456;105.1749;10.8681;0;0;0;0.1049493;0.1048943;96523.71;1.08795e+007
21;0.03498212;0.0008443417;107.0993;11.06695;0;0;0;0.1101799;0.1101193;98289.79;1.107914e+007
22;0.03669641;0.000826772;108.554;11.21727;0;0;0;0.1155792;0.1155125;99624.85;1.123023e+007
23;0.03835712;0.0007334519;110.1923;11.38656;0;0;0;0.1208098;0.1207369;101128.4;1.140032e+007
24;0.04001783;0.0008373334;111.7828;11.55091;0;0;0;0.1260404;0.125961;102588.1;1.156547e+007
25;0.04173211;0.0008236789;114.0022;11.78025;0;0;0;0.1314397;0.1313534;104624.9;1.179574e+007
26;0.04333926;0.0007076406;115.9055;11.97693;0;0;0;0.1365016;0.1364085;106371.7;1.199328e+007
27;0.04499997;0.0008838467;117.9021;12.18324;0;0;0;0.1417322;0.1416318;108204;1.220051e+007
28;0.04671425;0.0007552795;119.7411;12.37327;0;0;0;0.1471315;0.1470234;109891.7;1.239148e+007
29;0.04842854;0.0009926223;122.1328;12.62042;0;0;0;0.1525308;0.1524146;112086.7;1.263967e+007
30;0.04998211;0.000908963;123.934;12.80654;0;0;0;0.157424;0.1573002;113739.7;1.28267e+007
31;0.05174997;0.0008051207;126.2959;13.0506;0;0;0;0.162992;0.1628593;115907.4;1.307187e+007
32;0.05335711;0.0009616624;128.1181;13.23889;0;0;0;0.1680539;0.1679128;117579.7;1.326114e+007
33;0.05501782;0.0009440437;130.4592;13.48081;0;0;0;0.1732845;0.1731345;119728.2;1.350417e+007
34;0.05667854;0.00086244;132.9449;13.73767;0;0;0;0.1785151;0.1783559;122009.5;1.376219e+007
35;0.05844639;0.0009439263;135.5757;14.00952;0;0;0;0.1840831;0.1839139;124423.9;1.403531e+007
36;0.05999997;0.0008189806;137.5998;14.21867;0;0;0;0.1889763;0.1887979;126281.5;1.424554e+007
37;0.06176782;0.0007384047;140.2256;14.49001;0;0;0;0.1945443;0.1943553;128691.3;1.45182e+007
38;0.06337496;0.0007686207;142.4733;14.72227;0;0;0;0.1996062;0.1994072;130754.1;1.475166e+007
39;0.06503567;0.0005660356;145.4664;15.03156;0;0;0;0.2048368;0.2046273;133501;1.506235e+007
40;0.06664281;0.0007380621;148.0545;15.299;0;0;0;0.2098986;0.2096786;135876.3;1.533111e+007
41;0.06846425;0.000754144;151.0369;15.60718;0;0;0;0.2156354;0.2154033;138613.3;1.564084e+007
42;0.06996424;0.0006804198;153.3087;15.84193;0;0;0;0.2203598;0.2201174;140698.2;1.587684e+007
43;0.07178567;0.0007090207;156.422;16.16364;0;0;0;0.2260966;0.2258414;143555.4;1.620018e+007
44;0.07333924;0.0006346993;158.9702;16.42696;0;0;0;0.2309897;0.2307234;145894.1;1.64649e+007
45;0.07505353;0.0004739781;162.1388;16.75438;0;0;0;0.2363891;0.2361101;148802;1.679399e+007
46;0.07666066;0.0004359609;164.7959;17.02894;0;0;0;0.2414509;0.2411599;151240.5;1.707006e+007
47;0.07848209;0.0007077972;168.4982;17.41151;0;0;0;0.2471877;0.2468827;154638.3;1.745455e+007
48;0.07998209;0.0004957959;171.0799;17.67829;0;0;0;0.2519121;0.2515953;157007.7;1.772283e+007
49;0.08174994;0.0004394064;174.7837;18.06102;0;0;0;0.2574801;0.2571492;160406.8;1.810752e+007
50;0.08335709;0.0003693722;178.0159;18.39502;0;0;0;0.262542;0.262198;163373.2;1.844331e+007
51;0.08507138;0.0003171232;181.0667;18.71027;0;0;0;0.2679414;0.267583;166173;1.87604e+007
52;0.08662494;0.0003585955;184.5072;19.06578;0;0;0;0.2728345;0.2724629;169330.5;1.91178e+007
53;0.08844637;0.0003862959;188.4206;19.47017;0;0;0;0.2785712;0.2781839;172922;1.952441e+007
54;0.08999994;0.0002985844;191.5562;19.79418;0;0;0;0.2834644;0.2830634;175799.7;1.985029e+007
55;0.0917678;0.000233689;195.6418;20.21636;0;0;0;0.2890324;0.2886155;179549.2;2.027479e+007
56;0.09342851;0.0001799913;198.9503;20.55824;0;0;0;0.294263;0.2938309;182585.6;2.061874e+007
57;0.09503565;4.19296e-005;202.1097;20.88471;0;0;0;0.2993249;0.2988778;185485;2.094722e+007
58;0.0966428;-4.207224e-005;205.2463;21.20883;0;0;0;0.3043868;0.3039244;188363.7;2.127338e+007
59;0.09846422;-1.342236e-005;209.9082;21.69055;0;0;0;0.3101235;0.3096437;192642.1;2.175782e+007
60;0.1000714;-2.734108e-005;213.4397;22.05548;0;0;0;0.3151854;0.3146897;195883.1;2.2125e+007
61;0.1017856;-9.350893e-005;217.7464;22.50051;0;0;0;0.3205847;0.3200719;199835.6;2.257264e+007
62;0.1033928;-0.0002993046;221.6738;22.90634;0;0;0;0.3256466;0.3251175;203439.9;2.298093e+007
63;0.1049999;-0.0002430619;226.0933;23.36302;0;0;0;0.3307084;0.3301628;207495.9;2.344028e+007
64;0.1066606;-3.644407e-005;229.9283;23.75931;0;0;0;0.335939;0.335376;211015.5;2.383912e+007
65;0.1084285;-0.0002316587;234.8326;24.26609;0;0;0;0.3415071;0.3409253;215516.4;2.434896e+007
66;0.1100356;-0.0003925562;239.2297;24.72045;0;0;0;0.346569;0.3459698;219551.8;2.480613e+007
67;0.1116964;-0.000418994;243.7628;25.18887;0;0;0;0.3517995;0.3511822;223712;2.527748e+007
68;0.1134106;-0.0005229636;248.5601;25.6846;0;0;0;0.3571989;0.3565624;228114.7;2.577634e+007
69;0.1150178;-0.000584991;252.8054;26.12328;0;0;0;0.3622607;0.3616062;232010.8;2.621791e+007
70;0.1166785;-0.0006668101;257.6454;26.62341;0;0;0;0.3674913;0.3668177;236452.7;2.672125e+007
71;0.1183928;-0.0008587947;262.9951;27.17621;0;0;0;0.3728907;0.3721971;241362.3;2.727755e+007
72;0.1201071;-0.001097939;268.1517;27.70906;0;0;0;0.37829;0.3775763;246094.8;2.781388e+007
73;0.1217142;-0.001040883;273.3465;28.24586;0;0;0;0.3833518;0.3826189;250862.3;2.835414e+007
74;0.1234285;-0.001249528;278.8817;28.81783;0;0;0;0.3887511;0.3879975;255942.2;2.892986e+007
75;0.1249821;-0.001376793;283.2595;29.27021;0;0;0;0.3936443;0.3928716;259959.9;2.938543e+007
76;0.1266428;-0.00155665;289.0441;29.86795;0;0;0;0.3988749;0.3980815;265268.7;2.998708e+007
77;0.1283571;-0.001650939;294.7165;30.4541;0;0;0;0.4042742;0.4034592;270474.5;3.057722e+007
78;0.1300713;-0.001881841;300.6907;31.07144;0;0;0;0.4096735;0.4088366;275957.3;3.119873e+007
79;0.1316785;-0.002226403;305.9301;31.61284;0;0;0;0.4147354;0.4138777;280765.7;3.174395e+007
80;0.1334463;-0.002461906;312.4621;32.28781;0;0;0;0.4203035;0.4194226;286760.4;3.242352e+007
81.00001;0.1349999;-0.002550665;317.6181;32.8206;0;0;0;0.4251966;0.4242952;291492.3;3.296016e+007
82.00001;0.1367142;-0.002875944;324.1231;33.49278;0;0;0;0.4305959;0.4296715;297462.2;3.3637e+007
83.00001;0.1383213;-0.003069681;329.9305;34.09288;0;0;0;0.4356578;0.4347115;302791.9;3.424141e+007
84.00001;0.1400892;-0.003378223;336.9621;34.81949;0;0;0;0.4412258;0.4402553;309245.2;3.497312e+007
85.00001;0.1416428;-0.003544122;342.7594;35.41854;0;0;0;0.446119;0.4451268;314565.6;3.557655e+007
86.00001;0.1434106;-0.003755546;349.7213;36.13794;0;0;0;0.451687;0.45067;320954.9;3.630117e+007
87.00001;0.1450178;-0.003941403;355.7264;36.75846;0;0;0;0.4567489;0.4557089;326465.9;3.692636e+007
88.00001;0.146732;-0.004313979;362.9363;37.50349;0;0;0;0.4621482;0.4610835;333082.8;3.767682e+007
89.00001;0.1482856;-0.004692623;369.5599;38.18793;0;0;0;0.4670413;0.4659541;339161.6;3.836629e+007
90.00001;0.1501606;-0.00490992;377.2735;38.985;0;0;0;0.4729469;0.471832;346240.7;3.916938e+007
91.00001;0.151607;-0.005371813;383.1199;39.58914;0;0;0;0.4775025;0.4763661;351606.2;3.977818e+007
92.00001;0.1534285;-0.005734532;391.7269;40.47853;0;0;0;0.4832393;0.4820754;359505.3;4.067414e+007
93.00001;0.1550356;-0.005848554;398.4739;41.17572;0;0;0;0.4883012;0.4871128;365697.3;4.137678e+007
94.00001;0.1566963;-0.006302381;406.3488;41.98946;0;0;0;0.4935318;0.4923179;372924.4;4.219669e+007
95.00001;0.158357;-0.006660745;413.7156;42.75069;0;0;0;0.4987623;0.4975226;379685.2;4.296392e+007
96.00001;0.1601249;-0.007046338;422.1309;43.62028;0;0;0;0.5043303;0.5030628;387408.3;4.384027e+007
97.00001;0.1616249;-0.007246594;429.5529;44.38723;0;0;0;0.5090548;0.5077635;394219.9;4.461318e+007
98.00001;0.1634999;-0.007798068;438.4116;45.30263;0;0;0;0.5149602;0.5136389;402349.9;4.553592e+007
99.00001;0.1649999;-0.007996062;445.6932;46.05506;0;0;0;0.5196847;0.518339;409032.5;4.62944e+007
100;0.1667142;-0.008470758;454.0491;46.91851;0;0;0;0.525084;0.5237103;416701.2;4.716487e+007
101;0.1683749;-0.008876447;462.5541;47.79735;0;0;0;0.5303146;0.5289134;424506.5;4.805083e+007
102;0.1701428;-0.009416693;471.6964;48.74206;0;0;0;0.5358827;0.534452;432896.8;4.900326e+007
103;0.1716428;-0.009791354;479.2736;49.52504;0;0;0;0.5406071;0.5391511;439850.8;4.979277e+007
104;0.1734642;-0.01031522;489.0951;50.53992;0;0;0;0.5463438;0.5448568;448864.3;5.081605e+007
105;0.1750713;-0.0106998;497.2402;51.38159;0;0;0;0.5514057;0.549891;456339.5;5.166491e+007
106;0.1766785;-0.0110727;505.6078;52.24624;0;0;0;0.5564676;0.554925;464018.8;5.253698e+007
107;0.1782856;-0.01170309;514.7782;53.19386;0;0;0;0.5615294;0.5599587;472434.9;5.349255e+007
108;0.180107;-0.0121834;524.634;54.21229;0;0;0;0.5672662;0.5656634;481480;5.451982e+007
109;0.1817142;-0.0126305;533.0225;55.0791;0;0;0;0.5723281;0.5706965;489178.5;5.539433e+007
110;0.1834285;-0.0130239;542.8895;56.09869;0;0;0;0.5777274;0.576065;498233.9;5.642279e+007
111;0.1850892;-0.0135472;552.2589;57.06687;0;0;0;0.582958;0.5812653;506832.6;5.739954e+007
112;0.1866963;-0.01414664;561.5434;58.02627;0;0;0;0.5880198;0.5862978;515353.4;5.836748e+007
113;0.188357;-0.01462833;570.5188;58.95373;0;0;0;0.5932504;0.5914976;523590.6;5.930347e+007
114;0.1900713;-0.01512325;581.3073;60.06855;0;0;0;0.5986497;0.596865;533491.7;6.042815e+007
115;0.191732;-0.01563905;590.7691;61.04626;0;0;0;0.6038803;0.6020643;542175.1;6.141491e+007
116;0.1933391;-0.01614701;600.4447;62.04608;0;0;0;0.6089422;0.6070956;551054.9;6.24239e+007
117;0.195107;-0.01687081;611.2426;63.16187;0;0;0;0.6145102;0.6126298;560964.6;6.355e+007
118;0.1966606;-0.01740379;620.1965;64.0871;0;0;0;0.6194034;0.617493;569182;6.448406e+007
119;0.1983213;-0.01810369;630.4182;65.14334;0;0;0;0.624634;0.6226912;578562.9;6.555025e+007
120;0.2000892;-0.01866452;641.196;66.25705;0;0;0;0.6302021;0.6282246;588454.1;6.66746e+007
121;0.2017499;-0.01927361;651.2074;67.29156;0;0;0;0.6354327;0.6334223;597642.1;6.771916e+007
122;0.203357;-0.02000345;661.3646;68.34114;0;0;0;0.6404945;0.6384521;606963.8;6.877886e+007
123;0.2050713;-0.02076136;672.1565;69.45631;0;0;0;0.6458939;0.6438169;616868.1;6.990493e+007
124;0.2066785;-0.02139567;681.7123;70.44374;0;0;0;0.6509557;0.6488462;625637.8;7.09023e+007
125;0.2083392;-0.02218707;692.763;71.58566;0;0;0;0.6561863;0.6540428;635779.5;7.205539e+007
126;0.2099999;-0.02285741;703.3825;72.68301;0;0;0;0.6614169;0.6592392;645525.5;7.316374e+007
127;0.2117677;-0.02365276;714.56;73.83801;0;0;0;0.6669849;0.6647704;655783.6;7.43305e+007
128;0.2133213;-0.02426064;724.1637;74.8304;0;0;0;0.6718781;0.669631;664597.3;7.533317e+007
129;0.2150891;-0.02508272;735.9845;76.05189;0;0;0;0.6774461;0.6751618;675445.8;7.65671e+007
130;0.2166427;-0.02580401;745.9445;77.08109;0;0;0;0.6823393;0.6800219;684586.6;7.760704e+007
131;0.218357;-0.02630248;757.2156;78.24577;0;0;0;0.6877387;0.6853845;694930.5;7.878389e+007
132;0.2200177;-0.02746081;767.6238;79.32128;0;0;0;0.6929692;0.6905792;704482.6;7.987096e+007
133;0.2217856;-0.02842322;779.6692;80.56598;0;0;0;0.6985372;0.6961088;715537.2;8.112876e+007
134;0.2232856;-0.02919814;789.5162;81.5835;0;0;0;0.7032616;0.7008003;724574.2;8.215724e+007
135;0.225107;-0.02996983;801.2171;82.79259;0;0;0;0.7089984;0.7064968;735312.6;8.337959e+007
136;0.2267141;-0.03087395;811.3205;83.83662;0;0;0;0.7140603;0.711523;744584.9;8.443526e+007
137;0.2284284;-0.03193761;822.8144;85.02432;0;0;0;0.7194596;0.7168838;755133.4;8.563604e+007
138;0.229982;-0.03286536;833.369;86.11497;0;0;0;0.7243527;0.7217419;764819.9;8.673875e+007
139;0.2317499;-0.03419355;846.0649;87.42689;0;0;0;0.7299208;0.7272698;776471.5;8.806503e+007
140;0.233357;-0.0349845;855.6793;88.42037;0;0;0;0.7349826;0.7322948;785295.1;8.907025e+007
141;0.2350713;-0.03607155;868.0103;89.69457;0;0;0;0.740382;0.7376546;796611.8;9.035866e+007
142;0.2366784;-0.03695274;878.1133;90.73856;0;0;0;0.7454439;0.7426792;805883.7;9.141496e+007
143;0.2384463;-0.03831344;890.4575;92.01413;0;0;0;0.7510119;0.7482059;817212.6;9.270516e+007
144;0.2399999;-0.03948792;900.5651;93.05858;0;0;0;0.7559051;0.7530624;826488.8;9.376201e+007
145;0.2417677;-0.04089279;912.8631;94.32938;0;0;0;0.7614731;0.7585885;837775.1;9.504767e+007
146;0.2433213;-0.04223638;922.8604;95.36243;0;0;0;0.7663662;0.7634445;846950.2;9.609326e+007
147;0.2451427;-0.04369391;935.5351;96.67216;0;0;0;0.772103;0.7691376;858582.3;9.741856e+007
148;0.2466963;-0.04508668;945.6747;97.71992;0;0;0;0.7769961;0.7739931;867887.8;9.847919e+007
149;0.248357;-0.04631092;956.7612;98.86552;0;0;0;0.7822267;0.7791832;878062.4;9.963887e+007
150;0.2500177;-0.04824782;966.6271;99.885;0;0;0;0.7874572;0.784373;887116.8;1.006716e+008
151;0.2517855;-0.05010344;978.7988;101.1427;0;0;0;0.7930253;0.7898974;898287.3;1.019448e+008
152;0.2532855;-0.05179186;988.3613;102.1309;0;0;0;0.7977498;0.7945845;907063.2;1.029456e+008
153;0.255107;-0.05370045;1000.358;103.3705;0;0;0;0.8034866;0.8002758;918073.2;1.042011e+008
154;0.2567141;-0.05569428;1010.193;104.3868;0;0;0;0.8085484;0.8052972;927098.8;1.052308e+008
155;0.2583748;-0.05802001;1020.245;105.4256;0;0;0;0.8137789;0.8104856;936324.8;1.062835e+008
156;0.259982;-0.0604198;1030.548;106.4901;0;0;0;0.8188408;0.8155065;945779.6;1.073621e+008
157;0.2618034;-0.06292027;1042.319;107.7066;0;0;0;0.8245776;0.8211966;956583.1;1.085947e+008
158;0.263357;-0.06541032;1051.207;108.6249;0;0;0;0.8294708;0.8260495;964739.4;1.095259e+008
159;0.2651248;-0.06814676;1062.274;109.7686;0;0;0;0.8350388;0.8315717;974896.4;1.106852e+008
160;0.266732;-0.07078058;1071.649;110.7373;0;0;0;0.8401008;0.8365915;983500.4;1.116676e+008
161;0.2683391;-0.07356012;1081.364;111.7411;0;0;0;0.8451625;0.841611;992415.6;1.126855e+008
162;0.2699998;-0.07604294;1090.902;112.7268;0;0;0;0.8503931;0.8467977;1001170;1.136854e+008
163;0.2717141;-0.07906008;1101.451;113.8169;0;0;0;0.8557925;0.8521514;1010851;1.147909e+008
164;0.2733748;-0.08224436;1110.328;114.7341;0;0;0;0.861023;0.8573374;1018998;1.15722e+008
165;0.2750891;-0.08573496;1120.256;115.7601;0;0;0;0.8664224;0.8626905;1028109;1.16763e+008
166;0.2767498;-0.08866999;1129.533;116.7186;0;0;0;0.871653;0.867876;1036622;1.17736e+008
167;0.2783569;-0.09164591;1138.411;117.636;0;0;0;0.8767148;0.872894;1044770;1.186673e+008
168;0.2800177;-0.09486991;1147.793;118.6056;0;0;0;0.8819455;0.878079;1053381;1.196516e+008
169;0.281732;-0.09823566;1157.39;119.5972;0;0;0;0.8873447;0.883431;1062188;1.206584e+008
170;0.2834463;-0.1019393;1166.029;120.4899;0;0;0;0.8927441;0.8887827;1070117;1.215655e+008
171;0.2849998;-0.1052597;1174.678;121.3836;0;0;0;0.8976372;0.8936324;1078054;1.224732e+008
172;0.2867141;-0.109376;1183.524;122.2977;0;0;0;0.9030365;0.8989835;1086173;1.234021e+008
173;0.2883212;-0.1127534;1191.501;123.122;0;0;0;0.9080983;0.9039999;1093494;1.242401e+008
174;0.2900355;-0.1166483;1200.141;124.0148;0;0;0;0.9134977;0.9093506;1101423;1.251477e+008
175;0.2916427;-0.1212364;1208.604;124.8893;0;0;0;0.9185596;0.9143665;1109190;1.260365e+008
176;0.2934105;-0.1253647;1217.284;125.7863;0;0;0;0.9241277;0.9198838;1117156;1.269487e+008
177;0.2950177;-0.1292781;1224.541;126.5362;0;0;0;0.9291895;0.9248991;1123816;1.27712e+008
178;0.2967855;-0.1339275;1232.672;127.3764;0;0;0;0.9347576;0.9304157;1131278;1.28567e+008
179;0.2983391;-0.1379254;1240.247;128.1591;0;0;0;0.9396507;0.9352634;1138230;1.293634e+008
180;0.2999998;-0.1425347;1248.038;128.9642;0;0;0;0.9448813;0.9404452;1145380;1.301827e+008
181;0.3017141;-0.1468478;1255.315;129.7162;0;0;0;0.9502805;0.9457938;1152059;1.309489e+008
182;0.3034284;-0.1518266;1263.467;130.5585;0;0;0;0.95568;0.9511422;1159540;1.318062e+008
183;0.3049819;-0.1559283;1270.182;131.2524;0;0;0;0.9605731;0.9559889;1165703;1.325132e+008
184;0.3067498;-0.1607626;1277.895;132.0495;0;0;0;0.966141;0.9615038;1172782;1.333252e+008
185;0.3083569;-0.1652733;1284.305;132.7117;0;0;0;0.971203;0.9665171;1178664;1.340007e+008
186;0.3100712;-0.1702107;1291.857;133.4922;0;0;0;0.9766023;0.9718644;1185595;1.347959e+008
187;0.3116783;-0.1749394;1297.786;134.1048;0;0;0;0.9816641;0.976877;1191036;1.354213e+008
188;0.3134462;-0.1802357;1305.491;134.901;0;0;0;0.9872322;0.9823909;1198107;1.362328e+008
189;0.3149998;-0.1845553;1311.58;135.5302;0;0;0;0.9921254;0.9872362;1203695;1.368748e+008
190;0.3167677;-0.1898309;1318.946;136.2913;0;0;0;0.9976934;0.9927493;1210455;1.376511e+008
191;0.3183212;-0.1946267;1325.013;136.9182;0;0;0;1.002586;0.997594;1216023;1.38291e+008
192;0.3200891;-0.1995363;1331.916;137.6316;0;0;0;1.008155;1.003107;1222359;1.390192e+008
193;0.3216426;-0.2047149;1337.992;138.2594;0;0;0;1.013048;1.007951;1227935;1.396601e+008
194;0.3235176;-0.2102952;1345.279;139.0125;0;0;0;1.018953;1.013797;1234623;1.404289e+008
195;0.3249641;-0.2150871;1349.906;139.4906;0;0;0;1.023509;1.018307;1238869;1.409182e+008
196;0.3267855;-0.2207625;1357.039;140.2277;0;0;0;1.029246;1.023985;1245416;1.41671e+008
197;0.3283391;-0.2255634;1362.531;140.7951;0;0;0;1.034139;1.028828;1250455;1.422511e+008
198;0.3300533;-0.2309497;1368.865;141.4497;0;0;0;1.039538;1.034172;1256268;1.429201e+008
199;0.3316605;-0.2360052;1374.49;142.0309;0;0;0;1.0446;1.039182;1261431;1.435146e+008
200;0.3334284;-0.2418629;1381.014;142.7051;0;0;0;1.050168;1.044692;1267418;1.442037e+008
201;0.3349819;-0.2470574;1385.942;143.2143;0;0;0;1.055061;1.049534;1271941;1.447253e+008
202;0.3368034;-0.2529907;1392.728;143.9155;0;0;0;1.060798;1.055211;1278169;1.454422e+008
203;0.3383569;-0.2583665;1397.781;144.4376;0;0;0;1.065691;1.060053;1282806;1.459769e+008
204;0.3400712;-0.2638647;1403.242;145.002;0;0;0;1.07109;1.065395;1287818;1.465551e+008
205;0.3416248;-0.2693518;1408.392;145.5341;0;0;0;1.075984;1.070236;1292544;1.471001e+008
206;0.3434462;-0.2752828;1414.471;146.1623;0;0;0;1.08172;1.075912;1298123;1.477433e+008
207;0.3449998;-0.2806978;1419.208;146.6518;0;0;0;1.086613;1.080752;1302471;1.482453e+008
208;0.3467676;-0.2865067;1425.356;147.2871;0;0;0;1.092182;1.08626;1308113;1.488957e+008
209;0.3484283;-0.2920688;1430.31;147.799;0;0;0;1.097412;1.091434;1312659;1.49421e+008
210;0.3500355;-0.297578;1435.266;148.3112;0;0;0;1.102474;1.096441;1317208;1.499462e+008
211;0.3516426;-0.3031562;1440.193;148.8202;0;0;0;1.107536;1.101448;1321729;1.504685e+008
212;0.3534641;-0.309284;1446.04;149.4244;0;0;0;1.113273;1.107121;1327095;1.510879e+008
213;0.3550712;-0.3150307;1450.845;149.921;0;0;0;1.118335;1.112127;1331505;1.515976e+008
214;0.3567319;-0.3207238;1456.38;150.493;0;0;0;1.123565;1.1173;1336585;1.521838e+008
215;0.3583926;-0.3265856;1460.946;150.9647;0;0;0;1.128796;1.122472;1340775;1.526688e+008
216;0.3599998;-0.3321861;1465.853;151.4718;0;0;0;1.133857;1.127478;1345278;1.531892e+008
217;0.3616605;-0.3380098;1470.735;151.9763;0;0;0;1.139088;1.132649;1349759;1.537074e+008
218;0.3634283;-0.3439258;1475.936;152.5137;0;0;0;1.144656;1.138155;1354532;1.542594e+008
219;0.3650891;-0.3499781;1480.208;152.9551;0;0;0;1.149887;1.143326;1358453;1.547139e+008
220;0.3666962;-0.3558262;1485.067;153.4572;0;0;0;1.154949;1.14833;1362912;1.552296e+008
221;0.3683569;-0.3619634;1489.423;153.9073;0;0;0;1.160179;1.153501;1366910;1.556929e+008
222;0.369964;-0.3677398;1494.064;154.3869;0;0;0;1.165241;1.158504;1371169;1.561859e+008
223;0.3716783;-0.3738657;1497.967;154.7903;0;0;0;1.17064;1.163841;1374752;1.566023e+008
224;0.3733926;-0.3796493;1503.072;155.3177;0;0;0;1.17604;1.169178;1379436;1.571444e+008
225;0.3750534;-0.3856483;1507.281;155.7527;0;0;0;1.18127;1.174348;1383299;1.575926e+008
226;0.3766605;-0.3912622;1511.042;156.1413;0;0;0;1.186332;1.17935;1386751;1.579937e+008
227;0.3784283;-0.3973231;1515.891;156.6424;0;0;0;1.1919;1.184853;1391201;1.585094e+008
228;0.3799819;-0.4028527;1519.757;157.0419;0;0;0;1.196793;1.189688;1394749;1.589214e+008
229;0.3816962;-0.4085178;1523.787;157.4583;0;0;0;1.202193;1.195024;1398447;1.593512e+008
230;0.3833569;-0.4138004;1527.065;157.7971;0;0;0;1.207423;1.200192;1401456;1.597024e+008
231;0.3850712;-0.4192563;1530.597;158.162;0;0;0;1.212823;1.205527;1404697;1.600803e+008
232;0.3866247;-0.4237748;1532.819;158.3916;0;0;0;1.217716;1.210361;1406737;1.603204e+008
233;0.3884462;-0.4289234;1536.85;158.8081;0;0;0;1.223452;1.216029;1410435;1.60751e+008
234;0.3899998;-0.433333;1539.727;159.1054;0;0;0;1.228346;1.220863;1413076;1.610598e+008
235;0.391714;-0.4385543;1543.824;159.5288;0;0;0;1.233745;1.226196;1416836;1.61497e+008
236;0.3933212;-0.4437923;1547.289;159.8869;0;0;0;1.238807;1.231196;1420016;1.618675e+008
237;0.3951426;-0.4496482;1552.086;160.3826;0;0;0;1.244544;1.236863;1424419;1.623786e+008
238;0.3966426;-0.4549641;1555.654;160.7513;0;0;0;1.249268;1.241529;1427693;1.627595e+008
239;0.398464;-0.4610854;1560.597;161.262;0;0;0;1.255005;1.247195;1432230;1.632859e+008
240;0.4000176;-0.4668101;1564.026;161.6164;0;0;0;1.259898;1.252027;1435377;1.636526e+008
241;0.4017319;-0.4729437;1568.544;162.0832;0;0;0;1.265297;1.257359;1439523;1.64134e+008
242;0.4032854;-0.4789719;1572.376;162.4792;0;0;0;1.27019;1.262191;1443039;1.645429e+008
243;0.4051069;-0.4855258;1577.12;162.9694;0;0;0;1.275927;1.267856;1447394;1.650488e+008
244;0.4066604;-0.4911762;1580.709;163.3402;0;0;0;1.28082;1.272687;1450687;1.654323e+008
245;0.4084283;-0.4975;1585.709;163.8569;0;0;0;1.286388;1.278185;1455276;1.659647e+008
246;0.4100354;-0.5034056;1589.258;164.2236;0;0;0;1.29145;1.283182;1458533;1.663445e+008
247;0.4117498;-0.5093855;1594.337;164.7484;0;0;0;1.29685;1.288513;1463194;1.66885e+008
248;0.4133033;-0.5154226;1597.4;165.065;0;0;0;1.301743;1.293343;1466005;1.672137e+008
249;0.4150712;-0.5221299;1602.779;165.6209;0;0;0;1.307311;1.298839;1470942;1.677861e+008
250;0.4166783;-0.5279019;1606.004;165.9541;0;0;0;1.312373;1.303836;1473902;1.681321e+008
251;0.4184997;-0.5346736;1611.022;166.4726;0;0;0;1.318109;1.309498;1478507;1.686669e+008
252;0.4199997;-0.5409234;1614.72;166.8548;0;0;0;1.322834;1.314161;1481901;1.69062e+008
253;0.421714;-0.5471294;1619.039;167.3011;0;0;0;1.328233;1.319489;1485865;1.695232e+008
254;0.4233212;-0.5532989;1622.681;167.6774;0;0;0;1.333295;1.324485;1489207;1.699131e+008
255;0.4251426;-0.5605484;1627.835;168.2099;0;0;0;1.339032;1.330146;1493936;1.704623e+008
256;0.4266962;-0.5668273;1630.897;168.5263;0;0;0;1.343925;1.334974;1496747;1.707912e+008
257;0.428464;-0.5735346;1635.461;168.998;0;0;0;1.349493;1.340468;1500936;1.712786e+008
258;0.4300712;-0.5798692;1638.845;169.3477;0;0;0;1.354555;1.345463;1504042;1.716416e+008
259;0.4316783;-0.5863841;1642.913;169.768;0;0;0;1.359617;1.350457;1507775;1.720762e+008
260;0.4332855;-0.5925976;1647.029;170.1933;0;0;0;1.364679;1.355451;1511552;1.725159e+008
261;0.4351069;-0.5993912;1651.873;170.6939;0;0;0;1.370415;1.36111;1515998;1.730331e+008
262;0.436714;-0.6057373;1655.215;171.0392;0;0;0;1.375477;1.366103;1519065;1.733919e+008
263;0.4384283;-0.6122046;1659.487;171.4806;0;0;0;1.380877;1.371429;1522985;1.738486e+008
264;0.4400354;-0.618647;1662.902;171.8335;0;0;0;1.385938;1.376422;1526119;1.74215e+008
265;0.4416962;-0.6248432;1667.082;172.2655;0;0;0;1.391169;1.381581;1529956;1.74662e+008
266;0.4433568;-0.6314971;1670.833;172.6531;0;0;0;1.396399;1.38674;1533398;1.75064e+008
267;0.4450712;-0.6382084;1675.592;173.1448;0;0;0;1.401799;1.392065;1537765;1.75572e+008
268;0.4467319;-0.6446985;1678.971;173.494;0;0;0;1.40703;1.397223;1540867;1.759352e+008
269;0.448339;-0.6510849;1683.017;173.9121;0;0;0;1.412091;1.402214;1544579;1.763679e+008
270;0.4501069;-0.6579594;1687.107;174.3347;0;0;0;1.417659;1.407705;1548334;1.768062e+008
271;0.451714;-0.6645695;1690.451;174.6803;0;0;0;1.422721;1.412696;1551402;1.771655e+008
272;0.4533747;-0.6712493;1694.568;175.1057;0;0;0;1.427952;1.417853;1555180;1.776061e+008
272.84;0.454714;-0.6766254;1697.913;175.4513;0;0;0;1.43217;1.422011;1558250;1.779641e+008
272.842;0.454714;-0.676659;1697.904;175.4505;0;0;0;1.43217;1.422011;1558243;1.779632e+008
273.842;0.4533747;-0.6761857;1679.91;173.591;0;0;0;1.427952;1.417853;1541728;1.760698e+008
274.842;0.4515533;-0.6732599;1658.911;171.4211;0;0;0;1.422215;1.412196;1522456;1.738591e+008
275.842;0.449839;-0.6700341;1640.059;169.4731;0;0;0;1.416816;1.406873;1505156;1.718743e+008
276.842;0.4480712;-0.6664756;1620.107;167.4113;0;0;0;1.411248;1.401382;1486844;1.697739e+008
277.842;0.446464;-0.6633182;1603.835;165.7299;0;0;0;1.406186;1.396391;1471911;1.680604e+008
278.842;0.4446962;-0.6595027;1585.377;163.8226;0;0;0;1.400618;1.3909;1454971;1.661171e+008
279.842;0.4431426;-0.6561115;1569.82;162.215;0;0;0;1.395725;1.386074;1440694;1.644791e+008
280.842;0.4414283;-0.6523469;1552.485;160.4237;0;0;0;1.390325;1.380749;1424784;1.626541e+008
281.842;0.4398212;-0.6486256;1536.415;158.7632;0;0;0;1.385263;1.375756;1410037;1.609625e+008
282.842;0.4380533;-0.6447569;1519.386;157.0036;0;0;0;1.379695;1.370264;1394408;1.591697e+008
283.842;0.4364997;-0.6410917;1504.745;155.4906;0;0;0;1.374802;1.365438;1380971;1.576283e+008
284.842;0.4346783;-0.6369479;1488.305;153.7919;0;0;0;1.369066;1.359778;1365884;1.558974e+008
285.842;0.4331783;-0.6333785;1474.88;152.4045;0;0;0;1.364341;1.355118;1353563;1.544839e+008
286.842;0.431464;-0.6291609;1460.181;150.8857;0;0;0;1.358942;1.349791;1340073;1.529361e+008
287.842;0.4298569;-0.6251752;1446.251;149.4463;0;0;0;1.35388;1.344797;1327289;1.514696e+008
288.842;0.428089;-0.6207198;1431.921;147.9655;0;0;0;1.348312;1.339303;1314138;1.499605e+008
289.842;0.4264819;-0.6166685;1420.002;146.7338;0;0;0;1.34325;1.334308;1303199;1.487048e+008
290.842;0.424714;-0.6120855;1405.644;145.2502;0;0;0;1.337682;1.328814;1290022;1.471931e+008
291.842;0.4231605;-0.6080942;1393.154;143.9595;0;0;0;1.332789;1.323985;1278559;1.458782e+008
292.842;0.4214462;-0.603663;1380.033;142.6037;0;0;0;1.327389;1.318657;1266518;1.444966e+008
293.842;0.4197855;-0.599261;1368.007;141.361;0;0;0;1.322159;1.313495;1255481;1.4323e+008
294.842;0.4180711;-0.5945007;1354.809;139.9972;0;0;0;1.316759;1.308166;1243368;1.418406e+008
295.842;0.4165176;-0.5902811;1343.808;138.8605;0;0;0;1.311866;1.303336;1233273;1.406821e+008
296.842;0.4147497;-0.585616;1331.328;137.5708;0;0;0;1.306298;1.29784;1221819;1.393679e+008
297.842;0.4131426;-0.5810277;1319.486;136.3471;0;0;0;1.301237;1.292843;1210951;1.381213e+008
298.842;0.4114283;-0.5762203;1308.916;135.2549;0;0;0;1.295837;1.287513;1201251;1.370076e+008
299.842;0.4098212;-0.5713544;1299.328;134.2642;0;0;0;1.290775;1.282516;1192451;1.359972e+008
300.842;0.4080533;-0.5661916;1289.435;133.2419;0;0;0;1.285207;1.277019;1183372;1.349543e+008
301.842;0.4064997;-0.5612492;1280.089;132.2761;0;0;0;1.280314;1.272187;1174795;1.339697e+008
302.842;0.4047319;-0.5559213;1270.37;131.2718;0;0;0;1.274746;1.26669;1165875;1.329452e+008
303.842;0.4031247;-0.5507039;1261.416;130.3465;0;0;0;1.269684;1.261691;1157657;1.320015e+008
304.842;0.401464;-0.545647;1252.603;129.4359;0;0;0;1.264454;1.256526;1149570;1.310726e+008
305.842;0.3998569;-0.540439;1243.719;128.5179;0;0;0;1.259392;1.251527;1141416;1.301364e+008
306.842;0.398089;-0.5350161;1234.386;127.5535;0;0;0;1.253824;1.246028;1132852;1.291528e+008
307.842;0.3964283;-0.5296468;1226.565;126.7453;0;0;0;1.248593;1.240863;1125673;1.283278e+008
308.842;0.3947676;-0.5244005;1217.49;125.8076;0;0;0;1.243363;1.235696;1117345;1.273718e+008
309.842;0.3931069;-0.5188658;1209.596;124.9918;0;0;0;1.238132;1.23053;1110100;1.265394e+008
310.842;0.3914997;-0.5136591;1201.407;124.1456;0;0;0;1.23307;1.22553;1102584;1.256764e+008
311.842;0.3897855;-0.5080075;1193.403;123.3186;0;0;0;1.227671;1.220196;1095239;1.248325e+008
312.842;0.3881248;-0.5024555;1185.215;122.4725;0;0;0;1.22244;1.215029;1087725;1.239696e+008
313.842;0.3864105;-0.4967914;1177.04;121.6277;0;0;0;1.217041;1.209694;1080222;1.231079e+008
314.842;0.3848569;-0.4911783;1169.358;120.8339;0;0;0;1.212148;1.20486;1073172;1.222986e+008
315.842;0.383089;-0.4854589;1161.311;120.0024;0;0;0;1.20658;1.199358;1065787;1.214503e+008
316.842;0.3815355;-0.4800732;1153.749;119.221;0;0;0;1.201687;1.194524;1058847;1.206536e+008
317.842;0.3798212;-0.4741717;1146.427;118.4643;0;0;0;1.196287;1.189188;1052127;1.198815e+008
318.842;0.3781605;-0.4683635;1138.93;117.6896;0;0;0;1.191057;1.184019;1045246;1.190914e+008
319.842;0.3763926;-0.4622535;1131.603;116.9325;0;0;0;1.185488;1.178517;1038522;1.183187e+008
320.842;0.3747854;-0.4567585;1124.693;116.2185;0;0;0;1.180427;1.173514;1032181;1.175904e+008
321.842;0.3730712;-0.4505848;1116.963;115.4198;0;0;0;1.175027;1.168178;1025087;1.16776e+008
322.842;0.3715176;-0.4451102;1110.814;114.7843;0;0;0;1.170134;1.163341;1019443;1.161274e+008
323.842;0.3698033;-0.4388437;1103.706;114.0498;0;0;0;1.164735;1.158004;1012920;1.153782e+008
324.842;0.3681426;-0.433046;1097.137;113.3711;0;0;0;1.159504;1.152834;1006892;1.146856e+008
325.842;0.3664283;-0.4265311;1090.086;112.6424;0;0;0;1.154105;1.147496;1000420;1.139424e+008
326.842;0.3648212;-0.421097;1084.648;112.0805;0;0;0;1.149043;1.142492;995430.1;1.133684e+008
327.842;0.3630533;-0.414559;1077.881;111.3812;0;0;0;1.143475;1.136987;989219.1;1.126548e+008
328.842;0.3614998;-0.409047;1072.005;110.7741;0;0;0;1.138582;1.132149;983827.2;1.120354e+008
329.842;0.3597855;-0.4026004;1065.497;110.1016;0;0;0;1.133183;1.12681;977854;1.113492e+008
330.842;0.3581248;-0.3967193;1059.479;109.4797;0;0;0;1.127952;1.121638;972330.9;1.107146e+008
331.842;0.3563569;-0.3899949;1052.98;108.8081;0;0;0;1.122384;1.116132;966366.3;1.100294e+008
332.842;0.3548569;-0.3842908;1047.424;108.234;0;0;0;1.11766;1.11146;961267.5;1.094437e+008
333.842;0.3530355;-0.3777166;1041.134;107.5841;0;0;0;1.111923;1.105786;955495.4;1.087803e+008
334.842;0.3515355;-0.3719;1035.622;107.0145;0;0;0;1.107198;1.101114;950436.7;1.081994e+008
335.842;0.3497676;-0.3652602;1029.114;106.342;0;0;0;1.10163;1.095607;944464;1.075135e+008
336.842;0.3481605;-0.3591662;1023.599;105.7721;0;0;0;1.096568;1.0906;939402.4;1.06932e+008
337.842;0.3463391;-0.3525806;1017.621;105.1544;0;0;0;1.090832;1.084925;933916.3;1.063015e+008
338.842;0.3448391;-0.3467749;1012.191;104.5933;0;0;0;1.086107;1.080252;928932.8;1.057293e+008
339.842;0.3430712;-0.3398035;1006.029;103.9565;0;0;0;1.080539;1.074743;923277.3;1.050798e+008
340.842;0.3415176;-0.3337834;1000.775;103.4137;0;0;0;1.075646;1.069902;918456.1;1.04526e+008
341.842;0.3397498;-0.3272741;995.2421;102.8419;0;0;0;1.070078;1.064393;913378.1;1.039424e+008
342.842;0.3381426;-0.32117;989.5669;102.2555;0;0;0;1.065016;1.059385;908169.7;1.033445e+008
343.842;0.3363748;-0.3142513;983.5662;101.6354;0;0;0;1.059448;1.053875;902662.5;1.027121e+008
344.842;0.3348212;-0.3080303;978.5048;101.1124;0;0;0;1.054555;1.049033;898017.5;1.021787e+008
345.842;0.3329998;-0.3012699;972.2624;100.4673;0;0;0;1.048818;1.043356;892288.6;1.01521e+008
346.842;0.3314998;-0.2950345;966.9547;99.91885;0;0;0;1.044094;1.038681;887417.4;1.009621e+008
347.842;0.3297855;-0.288884;961.8447;99.39082;0;0;0;1.038695;1.033337;882727.8;1.004232e+008
348.842;0.3281784;-0.282452;956.3061;98.8185;0;0;0;1.033633;1.028327;877644.8;9.983991e+007
349.842;0.3264105;-0.2757186;950.7934;98.24884;0;0;0;1.028065;1.022816;872585.4;9.925891e+007
350.842;0.3248569;-0.2694213;945.0197;97.65223;0;0;0;1.023171;1.017972;867286.7;9.865138e+007
351.842;0.3230355;-0.2629458;938.9856;97.02871;0;0;0;1.017435;1.012294;861748.9;9.801591e+007
352.842;0.3214284;-0.2564904;933.7984;96.49269;0;0;0;1.012373;1.007283;856988.4;9.746956e+007
353.842;0.3198212;-0.2500101;928.1825;95.91238;0;0;0;1.007311;1.002271;851834.5;9.687852e+007
354.842;0.3181605;-0.243481;922.6707;95.34283;0;0;0;1.00208;0.9970928;846776;9.629824e+007
355.842;0.3164462;-0.2373075;917.047;94.76172;0;0;0;0.9966811;0.991747;841614.9;9.570619e+007
356.842;0.3147855;-0.2306913;910.9194;94.12852;0;0;0;0.9914504;0.9865678;835991.3;9.506176e+007
357.842;0.3130712;-0.2243213;905.3421;93.55221;0;0;0;0.9860511;0.9812213;830872.8;9.447468e+007
358.842;0.3114105;-0.2180463;899.3032;92.92818;0;0;0;0.9808205;0.9760417;825330.6;9.383964e+007
359.842;0.3098569;-0.2121119;893.8687;92.36662;0;0;0;0.9759273;0.9711959;820343.2;9.326805e+007
360.842;0.3081427;-0.2057075;887.6622;91.72527;0;0;0;0.9705281;0.9658487;814647.1;9.261549e+007
361.842;0.3064284;-0.199521;881.514;91.08997;0;0;0;0.9651287;0.9605011;809004.8;9.19691e+007
362.842;0.3047141;-0.1932051;875.3975;90.45792;0;0;0;0.9597294;0.9551532;803391.4;9.132608e+007
363.842;0.3031605;-0.1874357;869.4005;89.83823;0;0;0;0.9548363;0.9503065;797887.6;9.069604e+007
364.842;0.3013927;-0.1811299;863.2694;89.20468;0;0;0;0.9492682;0.944791;792260.8;9.005148e+007
365.842;0.2998391;-0.1753923;856.9806;88.55484;0;0;0;0.9443751;0.9399437;786489.4;8.939113e+007
366.842;0.2981248;-0.1692503;850.458;87.88083;0;0;0;0.9389758;0.9345948;780503.2;8.870601e+007
367.842;0.2964641;-0.1635017;843.8693;87.2;0;0;0;0.9337453;0.9294128;774456.4;8.801423e+007
368.842;0.2947498;-0.1576856;837.5616;86.5482;0;0;0;0.9283459;0.9240632;768667.6;8.735167e+007
369.842;0.2931427;-0.1520359;830.5367;85.8223;0;0;0;0.9232839;0.9190477;762220.6;8.661469e+007
370.842;0.2914284;-0.146039;823.6969;85.11552;0;0;0;0.9178847;0.9136977;755943.4;8.589678e+007
371.842;0.2898748;-0.1409767;817.0817;84.43195;0;0;0;0.9129916;0.908849;749872.3;8.52028e+007
372.842;0.288107;-0.1350889;809.851;83.68478;0;0;0;0.9074235;0.9033312;743236.4;8.444415e+007
373.842;0.2864998;-0.1294935;802.7332;82.94926;0;0;0;0.9023617;0.8983147;736704.1;8.369777e+007
374.842;0.2847855;-0.124049;795.1607;82.16677;0;0;0;0.8969623;0.8929635;729754.4;8.290377e+007
375.842;0.2831784;-0.1190797;788.0589;81.43291;0;0;0;0.8919004;0.8879465;723236.8;8.215921e+007
376.842;0.281357;-0.1137066;780.1184;80.6124;0;0;0;0.8861637;0.8822602;715949.4;8.132675e+007
377.842;0.279857;-0.1089837;772.9781;79.87457;0;0;0;0.8814393;0.8775773;709396.5;8.057861e+007
378.842;0.2781427;-0.1039578;765.0536;79.05569;0;0;0;0.8760399;0.8722249;702123.8;7.974825e+007
379.842;0.276482;-0.09905824;757.0665;78.23035;0;0;0;0.8708094;0.8670397;694793.6;7.891159e+007
380.842;0.2747141;-0.09421297;748.6229;77.35785;0;0;0;0.8652413;0.8615195;687044.6;7.802718e+007
381.842;0.2732141;-0.08984261;740.6099;76.52985;0;0;0;0.8605168;0.8568355;679690.8;7.71884e+007
382.842;0.2713927;-0.08496757;731.9515;75.63514;0;0;0;0.8547801;0.8511475;671744.5;7.628165e+007
383.842;0.2698391;-0.08100422;723.6549;74.77782;0;0;0;0.849887;0.8462958;664130.3;7.541334e+007
384.842;0.2680713;-0.07655364;714.5196;73.83384;0;0;0;0.8443189;0.8407745;655746.5;7.445723e+007
385.842;0.2665177;-0.07264425;706.1257;72.96647;0;0;0;0.8394258;0.8359222;648043.1;7.357897e+007
386.842;0.2646963;-0.06868659;696.4285;71.96442;0;0;0;0.833689;0.830233;639143.5;7.256438e+007
387.842;0.2631427;-0.06518831;687.3384;71.02511;0;0;0;0.8287959;0.8253803;630801.1;7.161376e+007
388.842;0.2613748;-0.06114375;677.328;69.9907;0;0;0;0.8232279;0.8198578;621614.1;7.056688e+007
389.842;0.2598212;-0.05793355;668.0042;69.02724;0;0;0;0.8183346;0.8150044;613057.3;6.959211e+007
390.842;0.258107;-0.05470961;657.6419;67.95647;0;0;0;0.8129354;0.8096488;603547.3;6.850891e+007
391.842;0.2564998;-0.05147211;647.908;66.95062;0;0;0;0.8078735;0.8046276;594614.1;6.74915e+007
392.842;0.254732;-0.04862244;637.2508;65.84939;0;0;0;0.8023055;0.7991041;584833.5;6.63777e+007
393.842;0.2531784;-0.0460445;627.5281;64.8447;0;0;0;0.7974123;0.7942498;575910.6;6.536178e+007
394.842;0.251357;-0.04335024;616.1844;63.67251;0;0;0;0.7916755;0.7885582;565499.9;6.417659e+007
395.842;0.249857;-0.04107939;606.8388;62.7068;0;0;0;0.7869511;0.7838708;556923;6.320027e+007
396.842;0.2481427;-0.03881036;595.8855;61.57495;0;0;0;0.7815518;0.7785135;546870.7;6.20562e+007
397.842;0.2465355;-0.03693083;585.4277;60.49432;0;0;0;0.7764899;0.7734907;537273.1;6.096405e+007
398.842;0.2447141;-0.03486119;573.9247;59.30567;0;0;0;0.7707531;0.767798;526716.3;5.976277e+007
399.842;0.2431606;-0.0332106;563.7268;58.25188;0;0;0;0.76586;0.7629422;517357.2;5.869801e+007
400.842;0.2413927;-0.03145525;552.1083;57.0513;0;0;0;0.760292;0.7574163;506694.4;5.748506e+007
401.842;0.2397856;-0.0300089;541.6034;55.9658;0;0;0;0.7552301;0.7523926;497053.6;5.638847e+007
402.842;0.2381784;-0.02858838;530.6928;54.83837;0;0;0;0.7501683;0.7473685;487040.5;5.524975e+007
403.842;0.2365177;-0.02752156;519.7729;53.70997;0;0;0;0.7449377;0.7421767;477018.8;5.411008e+007
404.842;0.2347499;-0.02611667;508.2998;52.52442;0;0;0;0.7393696;0.7366497;466489.4;5.291277e+007
405.842;0.2331427;-0.02483791;497.1284;51.37004;0;0;0;0.7343078;0.7316248;456236.9;5.174726e+007
406.842;0.2314284;-0.02368279;486.0049;50.2206;0;0;0;0.7289084;0.7262647;446028.3;5.058667e+007
407.842;0.2297141;-0.02249415;475.1868;49.10273;0;0;0;0.7235091;0.7209043;436100.1;4.9458e+007
408.842;0.2281606;-0.0214514;464.6393;48.01283;0;0;0;0.7186159;0.7160462;426420.2;4.835785e+007
409.842;0.2264999;-0.0204255;453.6552;46.8778;0;0;0;0.7133853;0.7108528;416339.6;4.721222e+007
410.842;0.2247856;-0.01941055;442.5977;45.73519;0;0;0;0.707986;0.7054916;406191.7;4.605899e+007
411.842;0.2230713;-0.01837254;431.6205;44.60088;0;0;0;0.7025868;0.7001301;396117.4;4.491424e+007
412.842;0.2214641;-0.01762715;421.2064;43.52475;0;0;0;0.6975248;0.6951034;386559.9;4.382834e+007
413.842;0.2197499;-0.01652127;410.1851;42.38588;0;0;0;0.6921255;0.6897413;376445.1;4.267924e+007
414.842;0.2181427;-0.01564494;399.714;41.30387;0;0;0;0.6870637;0.6847142;366835.4;4.158765e+007
415.842;0.2164284;-0.01480656;389.3329;40.23115;0;0;0;0.6816643;0.6793515;357308.2;4.050539e+007
416.842;0.2147677;-0.01403846;378.602;39.12228;0;0;0;0.6764337;0.6741562;347459.9;3.938692e+007
417.842;0.2130534;-0.01308586;368.1827;38.04562;0;0;0;0.6710344;0.668793;337897.7;3.830092e+007
418.842;0.2114999;-0.01245586;358.4297;37.0378;0;0;0;0.6661413;0.6639324;328946.9;3.728453e+007
419.842;0.2097856;-0.01179279;347.6406;35.92294;0;0;0;0.660742;0.6585686;319045.3;3.616029e+007
420.842;0.2081784;-0.01112879;338.4283;34.97099;0;0;0;0.6556801;0.6535399;310590.7;3.520029e+007
421.842;0.2064642;-0.01031712;328.0533;33.89891;0;0;0;0.6502808;0.6481756;301069.2;3.411935e+007
422.842;0.2048034;-0.009672819;318.1375;32.87428;0;0;0;0.6450502;0.6429786;291969;3.308633e+007
423.842;0.2030891;-0.008836971;308.3556;31.86348;0;0;0;0.6396509;0.6376138;282991.7;3.206729e+007
424.842;0.201482;-0.008353633;299.1618;30.91345;0;0;0;0.634589;0.632584;274554.1;3.110962e+007
425.842;0.1997142;-0.00764876;288.7906;29.84175;0;0;0;0.629021;0.6270509;265036;3.002946e+007
426.842;0.1982142;-0.007322893;280.1909;28.95312;0;0;0;0.6242966;0.6223559;257143.7;2.913387e+007
427.842;0.1964463;-0.006588078;270.688;27.97115;0;0;0;0.6187285;0.6168222;248422.5;2.814422e+007
428.842;0.1947856;-0.006138459;261.9742;27.07072;0;0;0;0.6134979;0.6116237;240425.4;2.72368e+007
429.842;0.1930713;-0.005471045;252.5475;26.09663;0;0;0;0.6080986;0.6062571;231774.1;2.625532e+007
430.842;0.1915177;-0.005172213;244.6171;25.27715;0;0;0;0.6032055;0.6013935;224496;2.542962e+007
431.842;0.1896963;-0.004771075;235.4422;24.32907;0;0;0;0.5974686;0.5956909;216075.8;2.447443e+007
432.842;0.1881427;-0.004218505;227.532;23.51169;0;0;0;0.5925756;0.5908267;208816.3;2.365101e+007
433.842;0.1864284;-0.003832021;218.8594;22.61552;0;0;0;0.5871762;0.585459;200857.1;2.274831e+007
434.842;0.1848213;-0.003531867;211.3426;21.83878;0;0;0;0.5821143;0.5804266;193958.5;2.196591e+007
435.842;0.1830535;-0.003135262;202.5667;20.93193;0;0;0;0.5765463;0.5748906;185904.5;2.105261e+007
436.842;0.1814999;-0.002895971;195.5918;20.21119;0;0;0;0.5716531;0.5700254;179503.3;2.032673e+007
437.842;0.1796785;-0.002693552;187.2614;19.35038;0;0;0;0.5659164;0.5643211;171858.1;1.945989e+007
438.842;0.1781785;-0.002559944;180.9489;18.69809;0;0;0;0.561192;0.5596232;166064.9;1.880303e+007
439.842;0.1764106;-0.002282088;172.9269;17.86915;0;0;0;0.5556239;0.5540861;158702.8;1.796844e+007
440.842;0.174857;-0.002165374;166.2237;17.17648;0;0;0;0.5507308;0.5492198;152550.9;1.727108e+007
441.842;0.1730356;-0.001967057;159.2122;16.45196;0;0;0;0.5449941;0.5435143;146116.1;1.654162e+007
442.842;0.171482;-0.001906194;152.9482;15.80468;0;0;0;0.5401009;0.5386476;140367.3;1.589004e+007
443.842;0.1697142;-0.001813804;145.6852;15.05417;0;0;0;0.5345328;0.5331093;133701.8;1.513464e+007
444.842;0.1681606;-0.001579809;140.1094;14.478;0;0;0;0.5296397;0.528242;128584.6;1.455468e+007
445.842;0.1664999;-0.001473441;133.5671;13.80196;0;0;0;0.5244091;0.5230389;122580.5;1.387434e+007
446.842;0.1647856;-0.001552529;127.9531;13.22185;0;0;0;0.5190098;0.5176676;117428.3;1.329047e+007
447.842;0.1630713;-0.001424628;121.331;12.53756;0;0;0;0.5136105;0.512296;111350.9;1.260196e+007
448.842;0.1614642;-0.001464397;116.6293;12.05172;0;0;0;0.5085486;0.5072598;107035.9;1.211301e+007
449.842;0.1596963;-0.001242774;110.6517;11.43404;0;0;0;0.5029805;0.5017198;101550;1.149155e+007
450.842;0.1581427;-0.001248284;105.9247;10.94557;0;0;0;0.4980874;0.496851;97211.83;1.100009e+007
451.842;0.156482;-0.001295072;101.0378;10.4406;0;0;0;0.4928568;0.4916462;92726.91;1.049205e+007
452.842;0.1548213;-0.001357285;96.93426;10.01656;0;0;0;0.4876263;0.4864412;88960.89;1.00654e+007
453.842;0.1530535;-0.00117458;92.23618;9.531091;0;0;0;0.4820582;0.4809;84649.26;9577036
454.842;0.1514463;-0.001392405;88.77341;9.17327;0;0;0;0.4769963;0.4758623;81471.31;9217027
455.842;0.1497856;-0.001365732;85.16398;8.800296;0;0;0;0.4717657;0.4706564;78158.79;8841813
456.842;0.1481249;-0.001311252;81.78613;8.451251;0;0;0;0.4665352;0.4654502;75058.78;8490679
457.842;0.1465178;-0.001530281;78.31735;8.092809;0;0;0;0.4614733;0.4604118;71875.32;8130155
458.842;0.1448035;-0.001410758;75.29042;7.780026;0;0;0;0.4560739;0.4550371;69097.38;7815509
459.842;0.1430892;-0.00155665;72.00378;7.440406;0;0;0;0.4506746;0.4496621;66081.08;7473938
460.842;0.1414285;-0.001551952;69.09949;7.140296;0;0;0;0.445444;0.4444549;63415.69;7172101
461.842;0.1397678;-0.001499331;66.18437;6.839065;0;0;0;0.4402134;0.4392473;60740.34;6869171
462.842;0.1380535;-0.001711352;63.58176;6.570129;0;0;0;0.4348141;0.4338715;58351.82;6598697
463.304;0.1373571;-0.001743848;62.63115;6.471899;0;0;0;0.4326206;0.4316875;57479.4;6499897