File: Ensayos/Resistencia/comp/Clavo5/clavo5nada.raw
"Test Type";"Manual"
"Method Name:";"C:\INSTRON\user\template\CYCLE.MTM"
"Name:";""
"Operator ID:";""
"Company:";""
"Lab name:";""
"Test date:";"23/05/2017"
"Temperature:";""
"Humidity:";""
"Note 1:";""
"Note 2:";""
"Note 3:";""
"Geometry:";"Rectangular"
"Specimen";1
"Specimen name:";""
"Width:";0.250000;"in"
"Thickness:";0.060000;"in"
"Length:";1.250000;"in"
"Diameter:";0.039370;"in"
"Inner diameter:";0.019685;"in"
"Outer diameter:";0.039370;"in"
"Wall thickness:";0.019685;"in"
"Area:";0.015000;"in*in"
"Linear density:";1.000000;"den"
"Sled weight:";2.204623;"lbf"
"Loading span:";0.000000;"mm"
"Support span:";1.000000;"mm"
"Span ratio:";"2"
"Fixture type:";"3-point"
"Comment:";""
"Included"
"Final Width:";0.250000;"in"
"Final Thickness:";0.060000;"in"
"Final Length:";1.250000;"in"
"Final Diameter:";0.039370;"in"
"Final Inner diameter:";0.019685;"in"
"Final Outer diameter:";0.039370;"in"
"Final Wall thickness:";0.019685;"in"
"Final Area:";0.015000;"in*in"
"Final Linear density:";1.000000;"den"
"Time sec";"Extension mm";"Strain 1 %";"Load N";"Stress MPa";"Cycle Count ";"Total Cycle Count ";"Repetitions Count ";"Strain [Exten.] %";"True strain %";"Tenacity gf/tex";"True stress Pa"
0;6.156478;0.007427561;95.96611;9.916517;0;0;0;19.39048;17.72293;88072.38;1.183938e+007
1;6.161407;0.007560149;118.4695;12.24187;0;0;0;19.40601;17.73593;108724.7;1.461753e+007
2;6.166336;0.007503448;139.9427;14.46078;0;0;0;19.42153;17.74893;128431.7;1.726928e+007
3;6.171478;0.007466465;160.4469;16.57955;0;0;0;19.43773;17.76249;147249.3;1.980223e+007
4;6.176407;0.007482909;180.4765;18.64928;0;0;0;19.45325;17.77549;165631.3;2.227717e+007
5;6.181442;0.007364843;201.6012;20.83217;0;0;0;19.46911;17.78877;185018.5;2.488801e+007
6;6.186424;0.007317433;221.9863;22.93863;0;0;0;19.4848;17.8019;203726.7;2.740817e+007
7;6.191407;0.007354377;243.5664;25.16858;0;0;0;19.50049;17.81503;223531.7;3.007657e+007
8;6.196442;0.007106095;266.7169;27.5608;0;0;0;19.51635;17.8283;244778;3.293967e+007
9;6.201371;0.007260301;291.3384;30.10503;0;0;0;19.53188;17.84129;267374.2;3.59851e+007
10;6.206406;0.007190097;317.8003;32.83943;0;0;0;19.54774;17.85456;291659.5;3.92588e+007
11;6.211388;0.007143059;344.9626;35.64621;0;0;0;19.56343;17.86768;316587.6;4.261983e+007
12;6.216425;0.00715672;373.9409;38.64064;0;0;0;19.57929;17.88095;343182.3;4.62062e+007
13;6.221407;0.007006512;402.8752;41.63052;0;0;0;19.59498;17.89407;369736.5;4.978801e+007
14;6.226443;0.006903224;433.9611;44.84273;0;0;0;19.61084;17.90733;398265.4;5.363677e+007
15;6.231425;0.006964824;464.8385;48.03341;0;0;0;19.62653;17.92045;426603;5.74607e+007
16;6.23646;0.006899207;497.2061;51.37806;0;0;0;19.6424;17.93371;456308.2;6.146994e+007
17;6.241442;0.006782886;529.3832;54.70304;0;0;0;19.65808;17.94682;485838.6;6.545661e+007
18;6.246425;0.006850914;562.5309;58.12831;0;0;0;19.67378;17.95993;516259.7;6.956434e+007
19;6.25146;0.006775301;596.2609;61.61375;0;0;0;19.68964;17.97319;547215.2;7.374527e+007
20;6.256442;0.006561552;630.2823;65.1293;0;0;0;19.70533;17.9863;578438.2;7.796324e+007
21;6.261478;0.006444526;665.4868;68.76711;0;0;0;19.72119;17.99954;610746.9;8.23288e+007
22;6.266406;0.006474297;699.5812;72.2902;0;0;0;19.73671;18.01251;642036.9;8.655791e+007
23;6.27155;0.006397311;735.5062;76.00246;0;0;0;19.75291;18.02604;675006.9;9.101516e+007
24;6.276424;0.006195068;769.3628;79.50098;0;0;0;19.76827;18.03886;706078.5;9.521694e+007
25;6.281568;0.006326833;806.7733;83.36674;0;0;0;19.78447;18.05238;740411.8;9.98604e+007
26;6.286443;0.006076219;841.8182;86.98806;0;0;0;19.79982;18.0652;772574.1;1.042115e+008
27;6.291532;0.006040725;877.965;90.72324;0;0;0;19.81585;18.07858;805747.6;1.087008e+008
28;6.296407;0.005994862;913.3104;94.3756;0;0;0;19.8312;18.09139;838185.8;1.130914e+008
29;6.301603;0.005959662;951.3543;98.30681;0;0;0;19.84757;18.10505;873100.3;1.178183e+008
30;6.306425;0.005753636;985.49;101.8342;0;0;0;19.86275;18.11772;904428.1;1.220612e+008
31;6.311567;0.005632396;1020.282;105.4294;0;0;0;19.87895;18.13123;936358.4;1.263876e+008
32;6.316442;0.005763926;1050.571;108.5592;0;0;0;19.89431;18.14404;964156.1;1.301563e+008
33;6.321585;0.005591355;1087.253;112.3497;0;0;0;19.9105;18.15755;997820.3;1.34719e+008
34;6.326514;0.005611856;1122.124;115.9531;0;0;0;19.92603;18.17049;1029823;1.390579e+008
35;6.331549;0.005486186;1158.96;119.7595;0;0;0;19.94189;18.18372;1063630;1.436418e+008
36;6.336531;0.005492203;1195.033;123.487;0;0;0;19.95758;18.1968;1096735;1.48132e+008
37;6.341514;0.00524984;1230.485;127.1504;0;0;0;19.97327;18.20988;1129271;1.525465e+008
37.434;6.343603;0.005333567;1245.703;128.7229;0;0;0;19.97985;18.21536;1143237;1.544415e+008
37.436;6.343603;0.00533196;1245.752;128.728;0;0;0;19.97985;18.21536;1143282;1.544476e+008
38.436;6.338835;0.005320671;1199.247;123.9225;0;0;0;19.96484;18.20285;1100603;1.486634e+008
39.436;6.333531;0.00536081;1147.001;118.5237;0;0;0;19.94813;18.18892;1052654;1.42167e+008
40.436;6.328764;0.005352088;1100.961;113.7662;0;0;0;19.93311;18.1764;1010401;1.364434e+008
41.436;6.323514;0.005539868;1052.416;108.7498;0;0;0;19.91658;18.16261;965848.9;1.304091e+008
42.436;6.318692;0.005702091;1008.295;104.1907;0;0;0;19.90139;18.14995;925357.1;1.249261e+008
43.436;6.31355;0.00575785;961.7263;99.37858;0;0;0;19.8852;18.13644;882619.1;1.191402e+008
44.436;6.308674;0.005855826;919.2979;94.9943;0;0;0;19.86984;18.12363;843680.6;1.138695e+008
45.436;6.303532;0.005965307;876.1214;90.53273;0;0;0;19.85364;18.11012;804055.8;1.085068e+008
46.436;6.298657;0.006150852;835.436;86.32856;0;0;0;19.83829;18.09731;766716.9;1.034547e+008
47.436;6.293567;0.006074553;794.3109;82.07896;0;0;0;19.82226;18.08393;728974.5;9.834886e+007
48.436;6.288639;0.006204318;754.8452;78.00082;0;0;0;19.80674;18.07097;692755.1;9.345024e+007
49.436;6.283603;0.006422144;716.5488;74.04353;0;0;0;19.79088;18.05773;657608.8;8.869738e+007
50.436;6.278621;0.00631962;678.2972;70.09086;0;0;0;19.77518;18.04463;622503.6;8.395145e+007
51.436;6.273639;0.006370264;642.0451;66.34479;0;0;0;19.75949;18.03153;589233.4;7.945418e+007
52.436;6.268603;0.006393333;605.7803;62.59742;0;0;0;19.74363;18.01829;555951.6;7.495643e+007
53.436;6.263675;0.006354154;572.1669;59.12403;0;0;0;19.72811;18.00532;525103.1;7.078809e+007
54.436;6.258532;0.006535466;536.7799;55.46737;0;0;0;19.71191;17.99179;492626.9;6.640105e+007
55.436;6.25371;0.006608688;504.6881;52.15121;0;0;0;19.69672;17.97911;463174.8;6.242329e+007
56.436;6.248514;0.006703587;470.749;48.64416;0;0;0;19.68036;17.96543;432027.3;5.82175e+007
57.436;6.243692;0.006849562;440.2714;45.4948;0;0;0;19.66517;17.95274;404056.7;5.444143e+007
58.436;6.23855;0.006797506;408.3776;42.1991;0;0;0;19.64898;17.93921;374786.3;5.049079e+007
59.436;6.233728;0.006921412;379.3388;39.19842;0;0;0;19.63379;17.92651;348136.1;4.689455e+007
60.436;6.228585;0.006790411;349.4108;36.10585;0;0;0;19.61759;17.91297;320669.9;4.318896e+007
61.436;6.22371;0.00692394;321.9282;33.26598;0;0;0;19.60224;17.90013;295447.8;3.978685e+007
62.436;6.218567;0.006909261;294.0114;30.38124;0;0;0;19.58604;17.88659;269827.4;3.633172e+007
63.436;6.213692;0.006987912;268.4706;27.74202;0;0;0;19.57068;17.87375;246387.4;3.317132e+007
64.436;6.208603;0.00699685;242.7283;25.08197;0;0;0;19.55466;17.86034;222762.5;2.998666e+007
65.436;6.203675;0.006974349;219.3846;22.66978;0;0;0;19.53913;17.84736;201339;2.709926e+007
66.43601;6.198639;0.006928801;196.2672;20.28098;0;0;0;19.52327;17.83409;180123.1;2.424049e+007
67.43601;6.19371;0.007107683;175.2044;18.10449;0;0;0;19.50775;17.8211;160792.9;2.163627e+007
68.43601;6.188675;0.007152859;155.1925;16.03659;0;0;0;19.49189;17.80783;142427.1;1.916243e+007
69.43601;6.183693;0.007116051;136.9123;14.14763;0;0;0;19.4762;17.7947;125650.5;1.690305e+007
70.43601;6.178657;0.007246445;120.1666;12.41724;0;0;0;19.46034;17.78142;110282.3;1.483368e+007
71.43601;6.173674;0.007323097;104.0472;10.75156;0;0;0;19.44464;17.76828;95488.75;1.284217e+007
72.43601;6.168692;0.007326409;91.11048;9.414769;0;0;0;19.42895;17.75515;83616.16;1.124396e+007
73.43601;6.163656;0.007298108;80.71037;8.340088;0;0;0;19.41309;17.74186;74071.5;9959157
74.43601;6.158674;0.0072887;71.50634;7.389004;0;0;0;19.3974;17.72872;65624.56;8822278
75.43601;6.153692;0.007418368;63.40651;6.55202;0;0;0;19.38171;17.71558;58190.98;7821913
76.43601;6.14871;0.007301871;60.2811;6.22906;0;0;0;19.36602;17.70244;55322.66;7435381
77.42001;6.143781;0.00742952;59.88818;6.188458;0;0;0;19.35049;17.68943;54962.05;7385955