File: Ensayos/Compresion/Clavo1/clavo1.raw
"Test Type";"Manual"
"Method Name:";"C:\INSTRON\user\template\CYCLE.MTM"
"Name:";""
"Operator ID:";""
"Company:";""
"Lab name:";""
"Test date:";"07/04/2017"
"Temperature:";""
"Humidity:";""
"Note 1:";""
"Note 2:";""
"Note 3:";""
"Geometry:";"Rectangular"
"Specimen";1
"Specimen name:";""
"Width:";0.250000;"in"
"Thickness:";0.060000;"in"
"Length:";1.250000;"in"
"Diameter:";0.039370;"in"
"Inner diameter:";0.019685;"in"
"Outer diameter:";0.039370;"in"
"Wall thickness:";0.019685;"in"
"Area:";0.015000;"in*in"
"Linear density:";1.000000;"den"
"Sled weight:";2.204623;"lbf"
"Loading span:";0.000000;"mm"
"Support span:";1.000000;"mm"
"Span ratio:";"2"
"Fixture type:";"3-point"
"Comment:";""
"Included"
"Final Width:";0.250000;"in"
"Final Thickness:";0.060000;"in"
"Final Length:";1.250000;"in"
"Final Diameter:";0.039370;"in"
"Final Inner diameter:";0.019685;"in"
"Final Outer diameter:";0.039370;"in"
"Final Wall thickness:";0.019685;"in"
"Final Area:";0.015000;"in*in"
"Final Linear density:";1.000000;"den"
"Time sec";"Extension mm";"Strain 1 %";"Load N";"Stress MPa";"Cycle Count ";"Total Cycle Count ";"Repetitions Count ";"Strain [Exten.] %";"True strain %";"Tenacity gf/tex";"True stress Pa"
0;5.35714e-005;-0.0004475069;123.0053;12.71058;0;0;0;0.0001687288;0.0001687287;112887.5;1.27106e+007
4;0.006696424;-0.001545743;148.5123;15.3463;0;0;0;0.0210911;0.02108888;136296.4;1.534954e+007
8;0.01344642;-0.003305648;182.9752;18.90748;0;0;0;0.04235093;0.04234196;167924.5;1.891549e+007
12;0.02014285;-0.004806043;218.8812;22.61777;0;0;0;0.06344203;0.06342192;200877;2.263212e+007
16;0.02673213;-0.006305811;255.6238;26.41451;0;0;0;0.08419567;0.08416025;234597.4;2.643675e+007
20;0.03348212;-0.009221873;297.4893;30.74063;0;0;0;0.1054555;0.1053999;273019.2;3.077304e+007
24;0.04012497;-0.01125383;338.556;34.98419;0;0;0;0.1263779;0.1262981;310707.9;3.50284e+007
28;0.04666068;-0.01454219;382.7837;39.5544;0;0;0;0.1469628;0.1468549;351297.7;3.961253e+007
32;0.05341068;-0.01761187;427.3407;44.15863;0;0;0;0.1682226;0.1680813;392189.7;4.423292e+007
36;0.0601071;-0.0201848;471.3822;48.70959;0;0;0;0.1893137;0.1891347;432608.5;4.880181e+007
40;0.06669638;-0.02397368;518.2575;53.55339;0;0;0;0.2100673;0.209847;475628.1;5.366588e+007
44;0.07333924;-0.0266354;564.4883;58.33057;0;0;0;0.2309897;0.2307234;518056.1;5.846531e+007
48;0.07998209;-0.03033;612.5846;63.30054;0;0;0;0.2519121;0.2515953;562196.3;6.346e+007
52;0.08667852;-0.03403682;661.2589;68.33022;0;0;0;0.2730032;0.2726312;606866.8;6.851677e+007
56;0.09332137;-0.03714585;708.4162;73.20315;0;0;0;0.2939256;0.2934945;650145.1;7.341831e+007
60;0.1000178;-0.0414101;760.5168;78.5869;0;0;0;0.3150167;0.3145215;697960.2;7.883446e+007
64;0.1066606;-0.04495758;810.1556;83.71625;0;0;0;0.335939;0.335376;743515.9;8.399748e+007
68;0.1133035;-0.048697;860.6291;88.93185;0;0;0;0.3568614;0.3562262;789837.7;8.924921e+007
72;0.1199464;-0.05315422;913.5457;94.39991;0;0;0;0.3777838;0.377072;838401.6;9.475654e+007
76;0.1267499;-0.05702038;964.7119;99.6871;0;0;0;0.3992123;0.3984176;885359.1;1.000851e+008
80;0.1333392;-0.06193979;1017.916;105.1848;0;0;0;0.419966;0.4190866;934186.6;1.056266e+008
84.00001;0.139982;-0.06620028;1068.962;110.4596;0;0;0;0.4408883;0.4399193;981034.2;1.109466e+008
88.00001;0.146732;-0.07094051;1123.293;116.0738;0;0;0;0.4621482;0.4610835;1030896;1.166102e+008
92.00001;0.1533749;-0.07581627;1176.473;121.5691;0;0;0;0.4830705;0.4819075;1079702;1.221564e+008
96.00001;0.1600178;-0.0800737;1226.612;126.7501;0;0;0;0.5039929;0.5027271;1125716;1.273889e+008
100;0.1667677;-0.08516193;1280.08;132.2752;0;0;0;0.5252528;0.5238781;1174787;1.3297e+008
104;0.1734106;-0.08996354;1332.732;137.7159;0;0;0;0.5461751;0.544689;1223108;1.384681e+008
108;0.1800534;-0.0942593;1385.214;143.1391;0;0;0;0.5670975;0.5654955;1271273;1.439508e+008
112;0.1868034;-0.1002603;1440.154;148.8162;0;0;0;0.5883573;0.5866332;1321694;1.496918e+008
116;0.1934463;-0.104649;1490.455;154.014;0;0;0;0.6092797;0.6074311;1367858;1.549524e+008
120;0.2000356;-0.1097515;1540.3;159.1647;0;0;0;0.6300333;0.6280569;1413602;1.601675e+008
124;0.206732;-0.1151681;1587.926;164.086;0;0;0;0.6511244;0.6490138;1457310;1.651544e+008
128;0.2134284;-0.1196496;1631.273;168.5652;0;0;0;0.6722155;0.6699662;1497092;1.696984e+008
132;0.2200177;-0.1201904;1626.539;168.076;0;0;0;0.6929692;0.6905792;1492747;1.692407e+008
136;0.2267141;-0.1235979;1654.737;170.9898;0;0;0;0.7140603;0.711523;1518626;1.722108e+008
140;0.2334106;-0.1273673;1688.512;174.4799;0;0;0;0.7351514;0.7324623;1549623;1.757626e+008
144;0.2399999;-0.1325297;1722.805;178.0236;0;0;0;0.7559051;0.7530624;1581095;1.793693e+008
148;0.2466963;-0.1363464;1757.92;181.6521;0;0;0;0.7769961;0.7739931;1613321;1.830635e+008
152;0.2533391;-0.1418709;1794.641;185.4467;0;0;0;0.7979185;0.794752;1647023;1.869264e+008
156;0.259982;-0.1471297;1828.858;188.9824;0;0;0;0.8188408;0.8155065;1678425;1.905299e+008
160;0.2666248;-0.1515138;1864.141;192.6283;0;0;0;0.8397632;0.8362568;1710805;1.942459e+008
164;0.2733213;-0.1581134;1899.393;196.271;0;0;0;0.8608543;0.8571701;1743158;1.979606e+008
168;0.2800713;-0.163195;1933.61;199.8068;0;0;0;0.8821142;0.8782463;1774560;2.015693e+008
172;0.2866605;-0.169123;1968.264;203.3877;0;0;0;0.9028679;0.8988164;1806363;2.05224e+008
176;0.2933034;-0.1755948;2000.352;206.7035;0;0;0;0.9237901;0.9195493;1835813;2.08613e+008
180;0.3000534;-0.1808727;2034.169;210.1979;0;0;0;0.9450501;0.9406124;1866847;2.121843e+008
184;0.3066962;-0.1887907;2067.676;213.6603;0;0;0;0.9659723;0.9613366;1897598;2.157242e+008
188;0.3133391;-0.1946159;2100.171;217.0181;0;0;0;0.9868947;0.9820567;1927421;2.191599e+008
192;0.3200891;-0.2013772;2134.586;220.5743;0;0;0;1.008155;1.003107;1959005;2.227981e+008
196;0.3267319;-0.2093862;2165.437;223.7623;0;0;0;1.029077;1.023818;1987318;2.26065e+008
200;0.3333748;-0.215411;2196.651;226.9877;0;0;0;1.049999;1.044525;2015964;2.293711e+008
204;0.3401248;-0.2242633;2228.663;230.2956;0;0;0;1.071259;1.065562;2045343;2.327627e+008
208;0.3467676;-0.2315379;2257.872;233.3139;0;0;0;1.092182;1.08626;2072150;2.358621e+008
212;0.3534105;-0.2381554;2289.009;236.5314;0;0;0;1.113104;1.106954;2100726;2.391643e+008
216;0.3601069;-0.2480418;2317.894;239.5162;0;0;0;1.134195;1.127811;2127235;2.422327e+008
220;0.3668033;-0.2547762;2348.238;242.6517;0;0;0;1.155286;1.148664;2155082;2.45455e+008
224;0.3733926;-0.263533;2377.124;245.6366;0;0;0;1.17604;1.169178;2181593;2.485254e+008
228;0.380089;-0.2728424;2404.888;248.5056;0;0;0;1.197131;1.190022;2207073;2.514806e+008
232;0.3867319;-0.2797823;2434.055;251.5195;0;0;0;1.218053;1.210695;2233841;2.545832e+008
236;0.3933212;-0.2903884;2459.733;254.1729;0;0;0;1.238807;1.231196;2257406;2.573216e+008
240;0.4000176;-0.2981739;2487.266;257.018;0;0;0;1.259898;1.252027;2282675;2.602561e+008
244;0.4066604;-0.3068761;2516.054;259.9927;0;0;0;1.28082;1.272687;2309095;2.633228e+008
248;0.4133569;-0.3175065;2540.411;262.5097;0;0;0;1.301911;1.293509;2331449;2.659273e+008
252;0.4199997;-0.3246903;2566.923;265.2492;0;0;0;1.322834;1.314161;2355780;2.68758e+008
256;0.4266426;-0.3355775;2591.521;267.7911;0;0;0;1.343756;1.334808;2378355;2.713895e+008
260;0.433339;-0.3442607;2616.399;270.3618;0;0;0;1.364847;1.355617;2401186;2.740518e+008
264;0.4399818;-0.3522755;2641.529;272.9585;0;0;0;1.38577;1.376256;2424249;2.767411e+008
268;0.4466783;-0.3632954;2664.228;275.3041;0;0;0;1.406861;1.397056;2445081;2.791773e+008
272;0.4533747;-0.3706094;2687.808;277.7407;0;0;0;1.427952;1.417853;2466721;2.817067e+008
276;0.4600176;-0.3801504;2706.917;279.7153;0;0;0;1.448874;1.438478;2484259;2.83768e+008
280;0.4666604;-0.3868687;2720.642;281.1336;0;0;0;1.469797;1.4591;2496855;2.852657e+008
284;0.4734104;-0.3850095;2708.943;279.9247;0;0;0;1.491056;1.48005;2486118;2.840985e+008
288;0.4801068;-0.3686344;2615.953;270.3156;0;0;0;1.512148;1.500829;2400777;2.744032e+008
292;0.4866961;-0.3567971;2565.22;265.0733;0;0;0;1.532901;1.521271;2354217;2.691366e+008
296;0.4934461;-0.3505772;2536.547;262.1104;0;0;0;1.554161;1.542208;2327902;2.66184e+008
300;0.500089;-0.346601;2515.229;259.9075;0;0;0;1.575083;1.562808;2308338;2.640013e+008
304;0.5067318;-0.3418382;2498.614;258.1906;0;0;0;1.596006;1.583403;2293089;2.623113e+008
308;0.5134282;-0.3402736;2483.553;256.6343;0;0;0;1.617097;1.604161;2279267;2.607843e+008
312;0.5200711;-0.3366441;2472.111;255.452;0;0;0;1.638019;1.624748;2268766;2.596363e+008
316;0.5267139;-0.3335681;2460.289;254.2304;0;0;0;1.658942;1.645331;2257917;2.584479e+008
320;0.533464;-0.3320654;2448.313;252.9928;0;0;0;1.680202;1.666242;2246926;2.572436e+008
324;0.5401604;-0.3285138;2437.786;251.9051;0;0;0;1.701293;1.686983;2237265;2.561907e+008
328;0.5466961;-0.3284135;2431.568;251.2626;0;0;0;1.721877;1.707221;2231559;2.55589e+008
332;0.5533925;-0.3273392;2428.635;250.9594;0;0;0;1.742969;1.727953;2228866;2.553335e+008
336;0.5600889;-0.3265097;2426.946;250.7849;0;0;0;1.76406;1.748681;2227317;2.552089e+008
340;0.5666782;-0.3263852;2421.667;250.2394;0;0;0;1.784813;1.769072;2222472;2.547057e+008
344;0.5733211;-0.322967;2410.466;249.082;0;0;0;1.805736;1.789626;2212192;2.535798e+008
348;0.5800175;-0.3203786;2396.636;247.6529;0;0;0;1.826827;1.810341;2199500;2.521771e+008
352;0.5866604;-0.31911;2389.817;246.9482;0;0;0;1.847749;1.830886;2193242;2.515112e+008
356;0.5933032;-0.318736;2393.3;247.3081;0;0;0;1.868671;1.851426;2196438;2.519295e+008
360;0.599946;-0.3203977;2393.871;247.3672;0;0;0;1.889594;1.871963;2196962;2.520414e+008
364;0.6066961;-0.3199842;2396.387;247.6271;0;0;0;1.910854;1.892826;2199271;2.523589e+008
368;0.6132853;-0.3216083;2406.568;248.6792;0;0;0;1.931607;1.913189;2208615;2.534827e+008
372;0.6199817;-0.3256425;2423.906;250.4707;0;0;0;1.952698;1.933878;2224526;2.553617e+008
376;0.6267317;-0.3292834;2448.419;253.0038;0;0;0;1.973958;1.954728;2247023;2.57998e+008
380;0.6333746;-0.3365897;2475.982;255.852;0;0;0;1.994881;1.975244;2272319;2.609559e+008
384;0.6400175;-0.3415692;2505.933;258.9469;0;0;0;2.015803;1.995755;2299806;2.641668e+008
388;0.6467139;-0.3481886;2539.57;262.4227;0;0;0;2.036894;2.016427;2330676;2.67768e+008
392;0.6534102;-0.3573443;2576.942;266.2846;0;0;0;2.057985;2.037095;2364975;2.717647e+008
396;0.6599996;-0.3655211;2618.544;270.5834;0;0;0;2.078739;2.057428;2403155;2.762081e+008
400;0.6668032;-0.3768478;2662.398;275.115;0;0;0;2.100168;2.078418;2443401;2.808929e+008
404;0.673446;-0.3872979;2702.612;279.2704;0;0;0;2.12109;2.098908;2480307;2.85194e+008
408;0.6800352;-0.3963268;2738.444;282.9731;0;0;0;2.141843;2.119228;2513192;2.890339e+008
412;0.6867317;-0.4100556;2766.967;285.9205;0;0;0;2.162935;2.139875;2539369;2.921048e+008
416;0.6934817;-0.418458;2794.973;288.8145;0;0;0;2.184194;2.160683;2565072;2.951228e+008
420;0.700071;-0.4283144;2820.515;291.4538;0;0;0;2.204948;2.18099;2588512;2.978802e+008
424;0.7067674;-0.4398302;2843.749;293.8546;0;0;0;2.226039;2.201624;2609835;3.00396e+008
428;0.7134103;-0.4477968;2869.142;296.4785;0;0;0;2.246961;2.222089;2633139;3.031403e+008
432;0.7200531;-0.4604897;2891.333;298.7717;0;0;0;2.267884;2.24255;2653506;3.055475e+008
436;0.7267495;-0.470021;2915.862;301.3063;0;0;0;2.288975;2.263171;2676016;3.082031e+008
440;0.7333924;-0.4790713;2940.767;303.8799;0;0;0;2.309897;2.283623;2698874;3.108992e+008
444;0.7399816;-0.4920962;2960.489;305.9178;0;0;0;2.330651;2.303906;2716973;3.130477e+008
448;0.7466781;-0.5002644;2985.187;308.4699;0;0;0;2.351742;2.324514;2739639;3.157243e+008
452;0.7533745;-0.5118755;3007.907;310.8177;0;0;0;2.372833;2.345119;2760491;3.181929e+008
456;0.7600174;-0.5224923;3029.641;313.0636;0;0;0;2.393755;2.365554;2780437;3.205575e+008
460;0.7666602;-0.5311525;3053.753;315.5551;0;0;0;2.414678;2.385986;2802566;3.231748e+008
464;0.773303;-0.5450327;3073.053;317.5495;0;0;0;2.4356;2.406412;2820278;3.252837e+008
468;0.7800531;-0.5542514;3097.011;320.0251;0;0;0;2.45686;2.427165;2842265;3.278877e+008
472;0.7866423;-0.564625;3119.149;322.3127;0;0;0;2.477614;2.447419;2862582;3.302983e+008
476;0.7932851;-0.5767689;3138.83;324.3464;0;0;0;2.498536;2.467833;2880645;3.324504e+008
480;0.8000887;-0.5851567;3163.069;326.8511;0;0;0;2.519964;2.488737;2902890;3.350876e+008
484;0.8067316;-0.5981245;3182.941;328.9045;0;0;0;2.540887;2.509143;2921127;3.372616e+008
488;0.8133745;-0.6083334;3204.277;331.1093;0;0;0;2.56181;2.529545;2940708;3.395917e+008
492;0.8200709;-0.6177112;3228.151;333.5762;0;0;0;2.5829;2.550107;2962618;3.421922e+008
496;0.8267138;-0.6310764;3246.473;335.4695;0;0;0;2.603823;2.570501;2979433;3.442046e+008
500;0.8334102;-0.6398025;3269.424;337.8411;0;0;0;2.624914;2.591054;3000496;3.467092e+008
504;0.8401601;-0.651645;3290.345;340.003;0;0;0;2.646174;2.611768;3019697;3.490001e+008
508;0.846803;-0.6624124;3310.34;342.0692;0;0;0;2.667096;2.632149;3038047;3.511925e+008
512;0.8533923;-0.6710705;3332.726;344.3824;0;0;0;2.68785;2.652362;3058591;3.536389e+008
516;0.8600887;-0.6845967;3350.632;346.2327;0;0;0;2.708941;2.672898;3075025;3.55612e+008
520;0.8667851;-0.6938437;3372.597;348.5023;0;0;0;2.730032;2.693431;3095182;3.580166e+008
524;0.8733744;-0.7047468;3392.192;350.5272;0;0;0;2.750786;2.713631;3113166;3.601695e+008
528;0.8800709;-0.7172791;3411.233;352.4948;0;0;0;2.771877;2.734156;3130641;3.622655e+008
532;0.8867673;-0.7255007;3433.644;354.8106;0;0;0;2.792968;2.754676;3151208;3.647203e+008
536;0.8933566;-0.7390705;3450.195;356.5208;0;0;0;2.813722;2.774864;3166397;3.665523e+008
540;0.8999994;-0.7486743;3471.294;358.7011;0;0;0;2.834644;2.795211;3185762;3.68869e+008
544;0.9066959;-0.7581331;3492.794;360.9227;0;0;0;2.855735;2.815719;3205493;3.712297e+008
548;0.9133387;-0.7711223;3509.339;362.6324;0;0;0;2.876657;2.836058;3220677;3.730641e+008
552;0.9199815;-0.7794553;3530.81;364.8511;0;0;0;2.89758;2.856394;3240382;3.754229e+008
556;0.926678;-0.79157;3549.665;366.7994;0;0;0;2.918671;2.876889;3257686;3.775051e+008
560;0.9333744;-0.8019412;3569.18;368.816;0;0;0;2.939762;2.897379;3275596;3.796583e+008
564;0.9400173;-0.810364;3590.683;371.0379;0;0;0;2.960684;2.917702;3295330;3.820232e+008
568;0.9466601;-0.8241647;3606.366;372.6585;0;0;0;2.981607;2.938021;3309723;3.837697e+008
572;0.9533565;-0.8327727;3627.464;374.8387;0;0;0;3.002698;2.958499;3329086;3.86094e+008
576;0.9599995;-0.8433594;3646.798;376.8366;0;0;0;3.02362;2.97881;3346829;3.882307e+008
580;0.9665887;-0.8544669;3664.587;378.6747;0;0;0;3.044374;2.998953;3363155;3.90203e+008
584;0.9734458;-0.8616957;3686.1;380.8978;0;0;0;3.065971;3.019909;3382899;3.92576e+008
588;0.9800886;-0.873517;3702.547;382.5973;0;0;0;3.086893;3.040207;3397992;3.944076e+008
592;0.9867315;-0.8813329;3721.346;384.5398;0;0;0;3.107816;3.060501;3415245;3.964906e+008
596;0.993428;-0.8890859;3741.865;386.6601;0;0;0;3.128907;3.080954;3434076;3.987584e+008
600;1.000071;-0.89993;3757.158;388.2405;0;0;0;3.149829;3.10124;3448112;4.004694e+008
604;1.006714;-0.9055717;3776.474;390.2364;0;0;0;3.170752;3.121521;3465839;4.026098e+008
608;1.013464;-0.9149374;3794.326;392.0811;0;0;0;3.192011;3.142126;3482222;4.045964e+008
612;1.020107;-0.9230608;3811.806;393.8874;0;0;0;3.212934;3.162399;3498265;4.065428e+008
616;1.026749;-0.9287854;3831.232;395.8948;0;0;0;3.233856;3.182667;3516093;4.086975e+008
620;1.033446;-0.9386492;3846.687;397.4918;0;0;0;3.254947;3.203096;3530277;4.1043e+008
624;1.040089;-0.9444382;3865.71;399.4575;0;0;0;3.27587;3.223357;3547734;4.125432e+008
628;1.046678;-0.9524456;3881.526;401.0918;0;0;0;3.296623;3.24345;3562249;4.143143e+008
632;1.053374;-0.9609428;3898.951;402.8924;0;0;0;3.317714;3.263866;3578241;4.162592e+008
636;1.060071;-0.9661312;3918.537;404.9163;0;0;0;3.338805;3.284278;3596216;4.184357e+008
640;1.06666;-0.975543;3932.742;406.3842;0;0;0;3.359559;3.304359;3609253;4.200369e+008
644.0001;1.073356;-0.9814732;3950.972;408.2679;0;0;0;3.38065;3.324762;3625983;4.2207e+008
648.0001;1.079999;-0.9879997;3968.817;410.1119;0;0;0;3.401572;3.344998;3642361;4.240622e+008
652.0001;1.086696;-0.9959531;3983.753;411.6553;0;0;0;3.422664;3.365394;3656068;4.257448e+008
654.7561;1.091356;-0.9994201;3997.391;413.0645;0;0;0;3.437343;3.379586;3668584;4.27263e+008
658.7561;1.084606;-0.9850805;3906.926;403.7165;0;0;0;3.416083;3.359031;3585560;4.175078e+008
662.7561;1.078017;-0.9703488;3831.159;395.8872;0;0;0;3.39533;3.338961;3516026;4.093289e+008
666.7561;1.071374;-0.9536771;3757.873;388.3143;0;0;0;3.374407;3.318723;3448768;4.014176e+008
670.7561;1.064678;-0.9402081;3688.948;381.1921;0;0;0;3.353316;3.298319;3385512;3.939747e+008
674.7561;1.058089;-0.9236316;3621.03;374.1739;0;0;0;3.332562;3.278236;3323181;3.866434e+008
678.7561;1.051339;-0.9084474;3555.764;367.4296;0;0;0;3.311303;3.25766;3263283;3.795963e+008
682.7561;1.044696;-0.8932103;3492.79;360.9223;0;0;0;3.29038;3.237406;3205489;3.72798e+008
686.7561;1.038053;-0.8752791;3431.54;354.5931;0;0;0;3.269458;3.217148;3149277;3.661864e+008
690.7561;1.031356;-0.8611198;3372.073;348.4482;0;0;0;3.248367;3.196723;3094702;3.597671e+008
694.7561;1.02466;-0.8436844;3312.435;342.2856;0;0;0;3.227276;3.176293;3039970;3.533322e+008
698.7561;1.018017;-0.8262065;3254.992;336.3498;0;0;0;3.206353;3.156023;2987251;3.471344e+008
702.7561;1.011374;-0.8117634;3196.935;330.3506;0;0;0;3.185431;3.135748;2933970;3.408737e+008
706.7561;1.004678;-0.7931399;3140.737;324.5435;0;0;0;3.16434;3.115306;2882395;3.348132e+008
710.7561;0.9979279;-0.7775152;3085.528;318.8385;0;0;0;3.14308;3.094696;2831726;3.288598e+008
714.7561;0.9912314;-0.7612307;3030.495;313.1518;0;0;0;3.121989;3.074246;2781221;3.229284e+008
718.7561;0.9846422;-0.7425646;2979.386;307.8705;0;0;0;3.101235;3.054119;2734315;3.174183e+008
722.7561;0.9779457;-0.7281824;2926.05;302.3591;0;0;0;3.080144;3.03366;2685367;3.116722e+008
726.7561;0.9711958;-0.7103774;2874.765;297.0597;0;0;0;3.058885;3.013033;2638300;3.061464e+008
730.7561;0.9646601;-0.6929865;2826.46;292.0682;0;0;0;3.0383;2.993057;2593969;3.009421e+008
734.7561;0.9579101;-0.6784522;2775.049;286.7556;0;0;0;3.01704;2.972422;2546786;2.954072e+008
738.7561;0.9512137;-0.6595468;2727.088;281.7997;0;0;0;2.995949;2.951947;2502771;2.902422e+008
742.7561;0.944678;-0.6453791;2679.057;276.8365;0;0;0;2.975364;2.931959;2458690;2.850734e+008
746.7561;0.937928;-0.6282644;2632.385;272.0137;0;0;0;2.954104;2.911311;2415857;2.800492e+008
750.7561;0.9312316;-0.6104624;2587.451;267.3705;0;0;0;2.933013;2.890823;2374620;2.752125e+008
754.7561;0.9246423;-0.5971754;2541.152;262.5862;0;0;0;2.912259;2.870659;2332129;2.702334e+008
758.7561;0.9179459;-0.5792387;2496.959;258.0196;0;0;0;2.891168;2.850162;2291571;2.654794e+008
762.7561;0.911303;-0.5646965;2452.955;253.4725;0;0;0;2.870246;2.829826;2251186;2.607478e+008
766.7561;0.9046601;-0.5494514;2408.899;248.92;0;0;0;2.849323;2.809485;2210754;2.560126e+008
770.7561;0.8980173;-0.5316461;2366.282;244.5163;0;0;0;2.828401;2.78914;2171643;2.514322e+008
774.7561;0.8913744;-0.5192905;2321.627;239.9019;0;0;0;2.807478;2.768791;2130660;2.466371e+008
778.7561;0.8847316;-0.5022682;2280.173;235.6184;0;0;0;2.786556;2.748438;2092617;2.42184e+008
782.7561;0.8780352;-0.486597;2239.315;231.3963;0;0;0;2.765465;2.727917;2055119;2.377955e+008
786.7561;0.8713387;-0.4733371;2196.191;226.9402;0;0;0;2.744374;2.707391;2015542;2.331683e+008
790.7561;0.8646423;-0.4563972;2156.741;222.8637;0;0;0;2.723283;2.686861;1979338;2.289329e+008
794.7561;0.8579995;-0.4436391;2116.619;218.7177;0;0;0;2.702361;2.666492;1942515;2.246282e+008
798.7561;0.851303;-0.4289459;2076.312;214.5527;0;0;0;2.681269;2.645953;1905524;2.203054e+008
802.7561;0.8446602;-0.4127916;2037.453;210.5372;0;0;0;2.660347;2.625575;1869861;2.161382e+008
806.7561;0.8379637;-0.4012033;1996.37;206.2919;0;0;0;2.639256;2.605028;1832158;2.117365e+008
810.7561;0.8313745;-0.3852063;1957.946;202.3215;0;0;0;2.618502;2.584807;1796895;2.076193e+008
814.7561;0.8246244;-0.3715311;1919.095;198.3068;0;0;0;2.597242;2.564087;1761239;2.034574e+008
818.7561;0.817928;-0.3577798;1879.009;194.1646;0;0;0;2.576151;2.543528;1724450;1.991666e+008
822.7561;0.8112852;-0.3422849;1841.956;190.3358;0;0;0;2.555229;2.523129;1690445;1.951993e+008
826.7561;0.8045888;-0.3305478;1802.628;186.2719;0;0;0;2.534138;2.502561;1654352;1.909923e+008
830.7561;0.7979459;-0.3160905;1764.748;182.3577;0;0;0;2.513216;2.482154;1619588;1.869407e+008
834.7561;0.791303;-0.3020541;1728.299;178.5913;0;0;0;2.492293;2.461742;1586138;1.830423e+008
838.7561;0.7846067;-0.2912793;1689.079;174.5385;0;0;0;2.471202;2.441162;1550143;1.788517e+008
842.7561;0.7779102;-0.2762852;1652.998;170.8102;0;0;0;2.450111;2.420577;1517030;1.749952e+008
846.7561;0.7713209;-0.2646689;1616.737;167.0631;0;0;0;2.429357;2.400318;1483751;1.711217e+008
850.7561;0.7646245;-0.2522148;1578.27;163.0883;0;0;0;2.408266;2.379725;1448449;1.670159e+008
854.7561;0.7579281;-0.2379047;1543.31;159.4757;0;0;0;2.387175;2.359127;1416365;1.632827e+008
858.7561;0.7513388;-0.2277682;1506.545;155.6766;0;0;0;2.366421;2.338856;1382624;1.593606e+008
862.7561;0.7446424;-0.2145321;1470.094;151.91;0;0;0;2.34533;2.31825;1349170;1.554728e+008
866.7561;0.7379995;-0.2025537;1434.585;148.2408;0;0;0;2.324408;2.297805;1316583;1.516865e+008
870.7561;0.7313566;-0.1916751;1398.481;144.51;0;0;0;2.303485;2.277356;1283449;1.478388e+008
874.7561;0.7246602;-0.1784827;1364.019;140.9489;0;0;0;2.282394;2.256737;1251821;1.441659e+008
878.7561;0.7180174;-0.1680575;1327.832;137.2095;0;0;0;2.261472;2.23628;1218610;1.403125e+008
882.7561;0.7113745;-0.1562036;1292.067;133.5139;0;0;0;2.24055;2.215818;1185788;1.365054e+008
886.7561;0.7047316;-0.1437238;1257.423;129.9339;0;0;0;2.219627;2.195352;1153993;1.32818e+008
890.7561;0.6980353;-0.1345662;1220.044;126.0715;0;0;0;2.198536;2.174717;1119689;1.288432e+008
894.7561;0.6912853;-0.12234;1185.371;122.4886;0;0;0;2.177277;2.153912;1087868;1.251555e+008
898.7561;0.6846424;-0.1118794;1150.023;118.836;0;0;0;2.156354;2.133434;1055428;1.213985e+008
902.7561;0.6779996;-0.1014874;1114.526;115.1679;0;0;0;2.135432;2.112951;1022850;1.176273e+008
906.7561;0.6713031;-0.08955449;1079.99;111.5992;0;0;0;2.114341;2.092299;991155.1;1.139588e+008
910.7561;0.6646603;-0.08107114;1044.534;107.9354;0;0;0;2.093418;2.071807;958615.1;1.101949e+008
914.7561;0.6579638;-0.069964;1011.207;104.4916;0;0;0;2.072327;2.051147;928029.9;1.06657e+008
918.7561;0.6512674;-0.05991928;976.9324;100.9499;0;0;0;2.051236;2.030481;896574.4;1.030206e+008
922.7561;0.644571;-0.05079095;941.5962;97.29847;0;0;0;2.030145;2.009812;864144.8;9.927377e+007
926.7561;0.6379817;-0.0399503;908.7697;93.90639;0;0;0;2.009391;1.989469;834018.4;9.579334e+007
930.7561;0.6312317;-0.03178783;875.0959;90.42677;0;0;0;1.988132;1.968626;803114.6;9.222457e+007
934.7561;0.6245889;-0.02192879;841.2671;86.93111;0;0;0;1.967209;1.94811;772068.4;8.864123e+007
938.7561;0.617946;-0.01195312;810.0243;83.70267;0;0;0;1.946287;1.927589;743395.4;8.533177e+007
942.7561;0.6112496;-0.004295722;775.8623;80.17259;0;0;0;1.925195;1.906898;712043.4;8.171607e+007
946.7561;0.6045532;0.005088662;743.9244;76.87234;0;0;0;1.904105;1.886203;682732.6;7.833607e+007
950.7561;0.5980175;0.01318753;713.4695;73.72533;0;0;0;1.88352;1.866001;654782.8;7.511396e+007
954.7561;0.5912675;0.0207678;680.3354;70.30146;0;0;0;1.86226;1.845132;624374.1;7.161066e+007
958.7561;0.5846246;0.02955761;649.7887;67.14497;0;0;0;1.841337;1.82459;596340.1;6.838133e+007
962.7561;0.5780353;0.03594586;618.8669;63.9497;0;0;0;1.820584;1.80421;567961.8;6.511396e+007
966.7561;0.5713389;0.04426199;587.8112;60.74062;0;0;0;1.799493;1.783493;539460.6;6.183364e+007
970.7561;0.5646425;0.05174217;558.8827;57.75132;0;0;0;1.778402;1.762773;512911.6;5.877838e+007
974.7561;0.5580532;0.05755541;529.6251;54.72803;0;0;0;1.757648;1.74238;486060.6;5.568996e+007
978.7561;0.5513568;0.06468568;502.0832;51.88203;0;0;0;1.736557;1.721651;460784.1;5.278299e+007
982.7561;0.5446604;0.06937943;475.1885;49.10291;0;0;0;1.715466;1.700918;436101.7;4.994526e+007
986.7561;0.5380175;0.07468936;447.7404;46.2666;0;0;0;1.694543;1.680346;410911.3;4.705061e+007
990.7561;0.5313746;0.08056561;421.5938;43.56478;0;0;0;1.673621;1.65977;386915.4;4.429389e+007
994.7561;0.5247318;0.08409984;395.4621;40.8645;0;0;0;1.652699;1.63919;362933.2;4.153987e+007
998.7561;0.5179818;0.0892308;369.7083;38.20327;0;0;0;1.631439;1.618274;339297.8;3.882653e+007
1002.756;0.5112854;0.09317205;344.6561;35.61453;0;0;0;1.610348;1.597519;316306.3;3.618805e+007
1006.756;0.5046425;0.09618095;318.9245;32.9556;0;0;0;1.589425;1.576926;292691.3;3.347941e+007
1010.756;0.4979461;0.1000241;294.0585;30.38611;0;0;0;1.568334;1.556163;269870.6;3.086267e+007
1014.756;0.4913032;0.1018183;270.3749;27.93879;0;0;0;1.547412;1.535561;248135.1;2.837112e+007
1018.756;0.4846604;0.1043887;246.5197;25.47375;0;0;0;1.526489;1.514956;226242.1;2.586261e+007
1022.756;0.4779104;0.1063976;223.935;23.14;0;0;0;1.50523;1.494013;205515.1;2.348831e+007
1026.756;0.4712676;0.1065979;201.2641;20.79733;0;0;0;1.484307;1.473399;184709;2.110603e+007
1030.756;0.4646247;0.1079549;180.6682;18.66909;0;0;0;1.463385;1.452781;165807.3;1.894229e+007
1034.756;0.4578747;0.1075078;160.6792;16.60355;0;0;0;1.442125;1.431825;147462.5;1.684299e+007
1038.756;0.4512319;0.1065745;142.0064;14.67402;0;0;0;1.421203;1.411198;130325.6;1.488257e+007
1042.756;0.4446426;0.1053723;125.3703;12.95496;0;0;0;1.400449;1.390733;115057.9;1.313639e+007
1046.756;0.4379461;0.1030796;111.2457;11.49541;0;0;0;1.379358;1.369931;102095.1;1.165397e+007
1050.756;0.4312497;0.102637;107.5958;11.11826;0;0;0;1.358267;1.349125;98745.5;1.126928e+007
1053.608;0.4297497;0.1024898;109.4998;11.315;1;1;0;1.353542;1.344464;100492.8;1.146815e+007
1057.608;0.4364461;0.1015575;126.0327;13.02341;1;1;0;1.374634;1.365271;115665.8;1.320243e+007
1061.608;0.4431961;0.1017825;150.3681;15.53807;1;1;0;1.395893;1.386241;137999.5;1.575497e+007
1065.608;0.449839;0.101192;179.5275;18.55121;1;1;0;1.416816;1.406873;164760.4;1.881405e+007
1069.608;0.4621604;0.09912888;237.8845;24.58145;1;1;0;1.455623;1.445131;218317.2;2.493926e+007
1073.608;0.4753926;0.09615023;303.7428;31.38682;1;1;0;1.497299;1.486201;278758.3;3.185677e+007
1077.608;0.4887854;0.09079115;375.0794;38.75828;1;1;0;1.539482;1.527752;344227.1;3.935495e+007
1081.608;0.5020175;0.0849046;447.1243;46.20293;1;1;0;1.581157;1.568787;410345.9;4.693347e+007
1085.608;0.5154104;0.0777828;521.699;53.909;1;1;0;1.62334;1.610305;478786.4;5.478413e+007
1089.608;0.5286425;0.06799163;598.2979;61.82424;1;1;0;1.665016;1.651306;549084.7;6.285362e+007
1093.608;0.5420353;0.05811421;675.7338;69.82597;1;1;0;1.707198;1.692789;620151.1;7.101804e+007
1097.608;0.5554818;0.04603048;756.5746;78.17953;1;1;0;1.749549;1.734421;694342.3;7.954732e+007
1101.608;0.5687139;0.03305551;837.8275;86.57568;1;1;0;1.791225;1.775372;768911.6;8.812645e+007
1105.608;0.5821603;0.01922265;923.1478;95.39213;1;1;0;1.833576;1.816969;847213.9;9.714121e+007
1109.608;0.5954996;0.00280088;1010.602;104.4291;1;1;0;1.875589;1.858217;927474.7;1.063878e+008
1113.608;0.6087853;-0.01265147;1097.604;113.4193;1;1;0;1.917434;1.899283;1007320;1.155941e+008
1117.608;0.6222317;-0.02968659;1188.111;122.7717;1;1;0;1.959785;1.940829;1090383;1.251778e+008
1121.608;0.6354639;-0.04832431;1278.085;132.069;1;1;0;2.001461;1.981695;1172956;1.347123e+008
1125.608;0.648696;-0.06610026;1368.263;141.3874;1;1;0;2.043137;2.022545;1255716;1.442762e+008
1129.608;0.6620889;-0.08583544;1459.427;150.8078;1;1;0;2.085319;2.063874;1339382;1.539526e+008
1133.608;0.675321;-0.1056992;1549.166;160.0808;1;1;0;2.126995;2.10469;1421739;1.634857e+008
1137.608;0.6887138;-0.1251207;1641.072;169.5778;1;1;0;2.169178;2.145986;1506085;1.732562e+008
1141.608;0.7019996;-0.1474766;1730.709;178.8403;1;1;0;2.211022;2.186934;1588349;1.827945e+008
1145.608;0.7153924;-0.1685182;1819.864;188.053;1;1;0;2.253204;2.228195;1670171;1.922902e+008
1149.608;0.7287852;-0.1896879;1908.835;197.2466;1;1;0;2.295387;2.269439;1751823;2.017742e+008
1153.608;0.7420174;-0.2130152;1992.844;205.9276;1;1;0;2.337063;2.310171;1828921;2.107402e+008
1157.608;0.7555174;-0.2343001;2078.634;214.7926;1;1;0;2.379582;2.351712;1907655;2.199038e+008
1161.608;0.7688566;-0.2583482;2162.174;223.4251;1;1;0;2.421596;2.39274;1984324;2.288356e+008
1165.608;0.7820888;-0.2812176;2243.118;231.7894;1;1;0;2.463272;2.433422;2058610;2.374989e+008
1169.608;0.7955352;-0.3035907;2327.194;240.4772;1;1;0;2.505623;2.474747;2135769;2.465026e+008
1173.608;0.8088209;-0.3300495;2407.259;248.7506;1;1;0;2.547467;2.51556;2209249;2.550875e+008
1177.608;0.8219995;-0.3541584;2487.537;257.046;1;1;0;2.588975;2.556028;2282923;2.637008e+008
1181.608;0.8353923;-0.3792635;2567.536;265.3126;1;1;0;2.631157;2.597137;2356342;2.722934e+008
1185.608;0.848678;-0.4072385;2642.986;273.1091;1;1;0;2.673002;2.637901;2425586;2.804093e+008
1189.608;0.8620709;-0.4321136;2721.234;281.1947;1;1;0;2.715184;2.678977;2497398;2.888297e+008
1193.608;0.8753566;-0.4607682;2798.039;289.1313;1;1;0;2.757029;2.719707;2567886;2.971027e+008
1197.608;0.8887495;-0.4891065;2874.991;297.083;1;1;0;2.799211;2.760749;2638508;3.05399e+008
1201.608;0.9021423;-0.5161135;2953.325;305.1775;1;1;0;2.841393;2.801774;2710398;3.138488e+008
1205.608;0.9153744;-0.5482983;3026.319;312.7202;1;1;0;2.883069;2.84229;2777388;3.217362e+008
1209.608;0.9288208;-0.5771169;3101.947;320.5352;1;1;0;2.92542;2.883446;2846795;3.299122e+008
1213.608;0.9422137;-0.6082482;3176.32;328.2204;1;1;0;2.967602;2.924421;2915051;3.379607e+008
1217.608;0.9554459;-0.6413683;3247.761;335.6026;1;1;0;3.009278;2.964888;2980615;3.457018e+008
1221.608;0.9688386;-0.6711162;3323.562;343.4354;1;1;0;3.05146;3.005829;3050181;3.539152e+008
1225.608;0.9821244;-0.7057212;3393.385;350.6505;1;1;0;3.093305;3.046427;3114261;3.614971e+008
1229.608;0.99541;-0.737608;3463.451;357.8907;1;1;0;3.13515;3.087007;3178563;3.69111e+008
1233.608;1.008696;-0.7691488;3534.02;365.1829;1;1;0;3.176994;3.127572;3243328;3.767847e+008
1237.608;1.022035;-0.8052219;3600.126;372.0137;1;1;0;3.219008;3.168283;3303996;3.839889e+008
1241.608;1.035428;-0.8362847;3668.234;379.0516;1;1;0;3.26119;3.209142;3366502;3.914132e+008
1245.608;1.04866;-0.8701756;3731.329;385.5714;1;1;0;3.302866;3.249494;3424407;3.983063e+008
1249.608;1.062106;-0.9039643;3792.535;391.8961;1;1;0;3.345217;3.290482;3480579;4.050059e+008
1253.608;1.075499;-0.9320094;3853.702;398.2166;1;1;0;3.387399;3.33129;3536714;4.117058e+008
1257.608;1.088731;-0.9648746;3905.6;403.5795;1;1;0;3.429075;3.371593;3584344;4.174186e+008
1261.608;1.102231;-0.9911688;3957.25;408.9166;1;1;0;3.471595;3.412695;3631745;4.231126e+008
1264.512;1.105285;-0.993751;3931.645;406.2708;1;1;0;3.481213;3.421989;3608246;4.204139e+008
1268.512;1.091839;-0.9673521;3777.308;390.3226;1;1;0;3.438862;3.381054;3466604;4.037453e+008
1272.512;1.078499;-0.9361334;3636.309;375.7527;1;1;0;3.396848;3.340429;3337203;3.885164e+008
1276.512;1.06516;-0.9050214;3504.433;362.1255;1;1;0;3.354835;3.299788;3216174;3.742742e+008
1280.512;1.051767;-0.8745759;3378.921;349.1558;1;1;0;3.312653;3.258967;3100986;3.607221e+008
1284.512;1.038428;-0.8406049;3258.967;336.7606;1;1;0;3.270639;3.218292;2990899;3.477748e+008
1288.512;1.025142;-0.8096325;3145.118;324.9961;1;1;0;3.228794;3.177764;2886415;3.354896e+008
1292.512;1.011696;-0.7760981;3032.623;313.3716;1;1;0;3.186443;3.136729;2783173;3.23357e+008
1296.512;0.9983565;-0.741552;2926.801;302.4367;1;1;0;3.14443;3.096005;2686055;3.119466e+008
1300.512;0.9851244;-0.7112154;2824.329;291.8479;1;1;0;3.102754;3.055592;2592013;3.009032e+008
1304.512;0.9716779;-0.6767843;2724.898;281.5734;1;1;0;3.060403;3.014507;2500760;2.901906e+008
1308.512;0.9584458;-0.6443495;2628.698;271.6327;1;1;0;3.018727;2.97406;2412474;2.798325e+008
1312.512;0.9452137;-0.6133208;2533.767;261.8231;1;1;0;2.977051;2.933597;2325351;2.696177e+008
1316.512;0.9318208;-0.5795214;2442.96;252.4397;1;1;0;2.934869;2.892626;2242013;2.598484e+008
1320.512;0.9185352;-0.5505956;2353.785;243.225;1;1;0;2.893024;2.851966;2160174;2.502615e+008
1324.512;0.9051423;-0.5191691;2265.908;234.1443;1;1;0;2.850842;2.810961;2079525;2.408193e+008
1328.512;0.8918566;-0.4876571;2181.557;225.428;1;1;0;2.808997;2.770268;2002112;2.317603e+008
1332.512;0.8784637;-0.4606054;2095.223;216.5069;1;1;0;2.766815;2.72923;1922880;2.224972e+008
1336.512;0.8650709;-0.4301697;2012.82;207.9918;1;1;0;2.724633;2.688175;1847255;2.136588e+008
1340.512;0.8517852;-0.4023108;1933.654;199.8113;1;1;0;2.682788;2.647432;1774600;2.051718e+008
1344.512;0.8383387;-0.3754326;1851.677;191.3404;1;1;0;2.640437;2.606179;1699367;1.963926e+008
1348.512;0.8249994;-0.3462956;1773.052;183.2158;1;1;0;2.598423;2.565238;1627209;1.879765e+008
1352.512;0.8117673;-0.3218585;1695.121;175.1629;1;1;0;2.556747;2.524609;1555688;1.796413e+008
1356.512;0.7983745;-0.2948877;1617.172;167.1081;1;1;0;2.514565;2.48347;1484151;1.713102e+008
1360.512;0.7851423;-0.2687702;1542.058;159.3464;1;1;0;2.472889;2.442808;1415216;1.632868e+008
1364.512;0.7718566;-0.246171;1465.99;151.4859;1;1;0;2.431045;2.401965;1345404;1.551686e+008
1368.512;0.7585173;-0.2205906;1390.796;143.7159;1;1;0;2.389031;2.36094;1276395;1.471493e+008
1372.512;0.745178;-0.1977452;1316.123;135.9996;1;1;0;2.347018;2.319898;1207865;1.391916e+008
1376.512;0.7317853;-0.1750961;1240.633;128.199;1;1;0;2.304836;2.278675;1138584;1.311538e+008
1380.512;0.7184995;-0.150674;1168.49;120.7442;1;1;0;2.26299;2.237765;1072376;1.234767e+008
1384.512;0.7051067;-0.1298389;1094.398;113.088;1;1;0;2.220809;2.196508;1004378;1.155995e+008
1388.512;0.6917138;-0.1073257;1020.907;105.494;1;1;0;2.178626;2.155233;936932.1;1.077923e+008
1392.512;0.6784817;-0.08609448;949.4111;98.10601;1;1;0;2.13695;2.114438;871316.9;1.002025e+008
1396.512;0.6649817;-0.06696031;876.2351;90.54447;1;1;0;2.094431;2.072799;804160;9.244087e+007
1400.512;0.651696;-0.04629823;807.0513;83.39547;1;1;0;2.052586;2.031804;740667;8.510723e+007
1404.512;0.6384639;-0.02870631;740.009;76.46775;1;1;0;2.01091;1.990958;679139.3;7.800545e+007
1408.512;0.625071;-0.01126081;674.0463;69.65159;1;1;0;1.968727;1.949599;618602.3;7.102284e+007
1412.512;0.6117853;0.005406094;612.8736;63.3304;1;1;0;1.926883;1.908553;562461.4;6.455071e+007
1416.512;0.5985532;0.01807688;551.0247;56.93933;1;1;0;1.885207;1.867657;505699.9;5.801276e+007
1420.512;0.5851603;0.03225021;492.5531;50.89725;1;1;0;1.843025;1.826247;452037.9;5.18353e+007
1424.512;0.5718211;0.04339579;437.401;45.1982;1;1;0;1.801011;1.784985;401422.4;4.601222e+007
1428.512;0.5584818;0.05362933;382.2525;39.4995;1;1;0;1.758998;1.743707;350810.2;4.01943e+007
1432.512;0.5451961;0.06340991;331.2511;34.22935;1;1;0;1.717153;1.702576;304003.9;3.481712e+007
1436.512;0.5317496;0.07045843;281.0243;29.03923;1;1;0;1.674802;1.660932;257908.5;2.952558e+007
1440.512;0.5183568;0.07702022;233.3212;24.10991;1;1;0;1.63262;1.619436;214129.3;2.450353e+007
1444.512;0.5051247;0.0814054;190.119;19.64567;1;1;0;1.590944;1.578421;174480.7;1.995822e+007
1446.774;0.5109104;0.07795249;225.3883;23.29017;2;2;0;1.609167;1.596357;206848.9;2.366495e+007
1450.774;0.5243033;0.07135582;300.852;31.08811;2;2;0;1.651349;1.637862;276105.3;3.160148e+007
1454.774;0.5375353;0.06416489;375.0232;38.75248;2;2;0;1.693025;1.678853;344175.5;3.940856e+007
1458.774;0.5509818;0.05410724;452.463;46.7546;2;2;0;1.735376;1.72049;415245.5;4.756597e+007
1462.774;0.5643211;0.04423115;531.8651;54.9595;2;2;0;1.777389;1.761778;488116.3;5.593634e+007
1466.774;0.5775532;0.0328625;612.3648;63.27782;2;2;0;1.819065;1.802718;561994.5;6.442889e+007
1470.774;0.5909461;0.01951943;695.5451;71.87314;2;2;0;1.861247;1.844138;638332.8;7.321088e+007
1474.774;0.6041782;0.006393346;777.9986;80.39336;2;2;0;1.902923;1.885044;714004.1;8.192318e+007
1478.774;0.6175174;-0.009469862;865.4696;89.43203;2;2;0;1.944937;1.926265;794280;9.117143e+007
1482.774;0.6308032;-0.0257676;953.7223;98.55151;2;2;0;1.986782;1.967303;875273.5;1.005095e+008
1486.774;0.6441424;-0.04205915;1044.691;107.9516;2;2;0;2.028795;2.008489;958759.3;1.101417e+008
1490.774;0.6575889;-0.06138471;1137.495;117.5414;2;2;0;2.071146;2.04999;1043930;1.199758e+008
1494.774;0.670821;-0.07954864;1230.154;127.1161;2;2;0;2.112822;2.090811;1128967;1.298019e+008
1498.774;0.6842674;-0.09931313;1325.948;137.0149;2;2;0;2.155173;2.132278;1216881;1.399678e+008
1502.774;0.6976602;-0.1207029;1420.318;146.7665;2;2;0;2.197355;2.173561;1303489;1.499915e+008
1506.774;0.7108924;-0.1401168;1512.995;156.3432;2;2;0;2.239031;2.214333;1388543;1.598437e+008
1510.774;0.7243388;-0.1620121;1607.626;166.1217;2;2;0;2.281382;2.255748;1475390;1.699115e+008
1514.774;0.7376781;-0.1831928;1698.084;175.469;2;2;0;2.323395;2.296816;1558407;1.795459e+008
1518.774;0.7508566;-0.2033493;1786.819;184.6383;2;2;0;2.364903;2.337372;1639843;1.890048e+008
1522.774;0.7642495;-0.2267766;1875.413;193.7931;2;2;0;2.407085;2.378571;1721150;1.984579e+008
1526.774;0.7774816;-0.2483585;1962.825;202.8257;2;2;0;2.448761;2.419259;1801372;2.077924e+008
1530.774;0.7908745;-0.2710429;2051.741;212.0137;2;2;0;2.490943;2.460425;1882974;2.172948e+008
1534.774;0.8041066;-0.295382;2137.914;220.9182;2;2;0;2.532619;2.50108;1962059;2.265133e+008
1538.774;0.8175531;-0.3182019;2225.118;229.9293;2;2;0;2.57497;2.542376;2042090;2.358499e+008
1542.774;0.8309459;-0.3448988;2311.024;238.8063;2;2;0;2.617152;2.583491;2120930;2.450562e+008
1546.774;0.8441781;-0.3695784;2393.787;247.3585;2;2;0;2.658828;2.624096;2196885;2.539353e+008
1550.774;0.8576244;-0.3941296;2478.029;256.0636;2;2;0;2.701179;2.665341;2274198;2.629803e+008
1554.774;0.8709637;-0.4221465;2559.717;264.5046;2;2;0;2.743193;2.706241;2349167;2.717605e+008
1558.774;0.8842495;-0.4475787;2642.135;273.0211;2;2;0;2.785038;2.746961;2424805;2.806249e+008
1562.774;0.8976959;-0.4758222;2725.633;281.6493;2;2;0;2.827389;2.788156;2501435;2.896126e+008
1566.774;0.910928;-0.5047314;2805.17;289.8681;2;2;0;2.869065;2.828678;2574429;2.981846e+008
1570.774;0.9242137;-0.5315983;2885.535;298.1725;2;2;0;2.910909;2.869347;2648184;3.068521e+008
1574.774;0.937553;-0.563485;2964.252;306.3066;2;2;0;2.952923;2.910164;2720426;3.153517e+008
1578.774;0.9508387;-0.5928627;3043.976;314.5448;2;2;0;2.994768;2.9508;2793593;3.239647e+008
1582.774;0.964178;-0.6228653;3126.218;323.0431;2;2;0;3.036781;2.991584;2869069;3.328532e+008
1586.774;0.9774637;-0.6567648;3202.657;330.9419;2;2;0;3.078626;3.032187;2939221;3.411304e+008
1590.774;0.9908564;-0.6868646;3282.069;339.1478;2;2;0;3.120808;3.0731;3012101;3.49732e+008
1594.774;1.004303;-0.720572;3360.885;347.2922;2;2;0;3.163159;3.114161;3084435;3.582776e+008
1598.774;1.017535;-0.7540349;3436.226;355.0774;2;2;0;3.204835;3.154551;3153578;3.664571e+008
1602.774;1.030981;-0.7851259;3515.134;363.2313;2;2;0;3.247186;3.195579;3225996;3.750261e+008
1606.774;1.044321;-0.8217209;3590.071;370.9748;2;2;0;3.289199;3.236263;3294768;3.831768e+008
1610.774;1.057606;-0.8542496;3663.663;378.5793;2;2;0;3.331044;3.276767;3362307;3.911899e+008
1614.774;1.070999;-0.8872216;3738.329;386.2948;2;2;0;3.373226;3.317581;3430832;3.993254e+008
1618.774;1.084285;-0.9236798;3805.725;393.259;2;2;0;3.415071;3.358052;3492683;4.066891e+008
1622.774;1.097517;-0.9539057;3872.712;400.181;2;2;0;3.456747;3.398343;3554161;4.140143e+008
1626.774;1.110856;-0.9859296;3935.672;406.6869;2;2;0;3.49876;3.438945;3611942;4.209159e+008
1630.774;1.124142;-1.01572;3988.887;412.1859;2;2;0;3.540605;3.479367;3660780;4.267797e+008
1634.774;1.137535;-1.03669;4038.104;417.2716;2;2;0;3.582788;3.520099;3705948;4.322215e+008
1638.774;1.150767;-1.060014;4079.561;421.5555;2;2;0;3.624463;3.560325;3743995;4.368346e+008
1642.774;1.164214;-1.077185;4120.735;425.8102;2;2;0;3.666814;3.601186;3781783;4.414238e+008
1646.774;1.177606;-1.090123;4160.122;429.8801;2;2;0;3.708997;3.641868;3817929;4.458244e+008
1650.774;1.190892;-1.105315;4193.469;433.326;2;2;0;3.750841;3.682208;3848533;4.495793e+008
1654.774;1.204339;-1.113864;4230.117;437.1129;2;2;0;3.793192;3.72302;3882167;4.536935e+008
1658.774;1.217678;-1.122649;4263.816;440.5952;2;2;0;3.835206;3.76349;3913094;4.574929e+008
1662.774;1.23091;-1.131286;4293.703;443.6835;2;2;0;3.876882;3.803618;3940523;4.608846e+008
1666.774;1.244303;-1.135511;4327.602;447.1864;2;2;0;3.919064;3.844218;3971633;4.647119e+008
1670.774;1.257588;-1.142564;4355.467;450.0658;2;2;0;3.960908;3.884476;3997207;4.678925e+008
1674.774;1.270821;-1.146498;4384.058;453.0202;2;2;0;4.002585;3.924557;4023445;4.711527e+008
1678.774;1.28416;-1.148573;4413.723;456.0857;2;2;0;4.044598;3.964945;4050671;4.745325e+008
1682.774;1.297499;-1.153575;4439.857;458.7862;2;2;0;4.086611;4.005317;4074655;4.77535e+008
1686.774;1.310892;-1.154264;4468.494;461.7453;2;2;0;4.128794;4.045835;4100936;4.808098e+008
1690.774;1.324124;-1.156403;4495.223;464.5073;2;2;0;4.17047;4.08585;4125466;4.838794e+008
1694.774;1.337571;-1.157563;4521.46;467.2184;2;2;0;4.212821;4.126498;4149545;4.869015e+008
1698.774;1.350963;-1.155442;4549.898;470.1571;2;2;0;4.255002;4.166966;4175645;4.901623e+008
1702.774;1.364196;-1.15631;4573.03;472.5473;2;2;0;4.296679;4.206934;4196873;4.928512e+008
1706.774;1.377642;-1.153929;4599.652;475.2983;2;2;0;4.33903;4.247532;4221306;4.959217e+008
1708.958;1.371588;-1.136387;4502.182;465.2264;2;2;0;4.319963;4.229256;4131853;4.85324e+008
1712.958;1.358142;-1.109858;4341.811;448.6547;2;2;0;4.277613;4.188651;3984673;4.678464e+008
1716.958;1.344803;-1.080144;4191.872;433.161;2;2;0;4.235599;4.148352;3847068;4.515079e+008
1720.958;1.331517;-1.051863;4051.339;418.6392;2;2;0;4.193754;4.1082;3718095;4.361959e+008
1724.958;1.318071;-1.023326;3914.411;404.4899;2;2;0;4.151403;4.067546;3592430;4.212819e+008
1728.958;1.304731;-0.9922941;3786.884;391.3122;2;2;0;4.10939;4.027199;3475393;4.073927e+008
1732.958;1.291553;-0.9645192;3665.622;378.7817;2;2;0;4.067883;3.987322;3364105;3.941901e+008
1736.958;1.27816;-0.9342307;3544.758;366.2924;2;2;0;4.025701;3.94678;3253182;3.810382e+008
1740.958;1.264874;-0.902193;3429.187;354.3501;2;2;0;3.983855;3.906547;3147118;3.684669e+008
1744.958;1.251588;-0.8741077;3315.775;342.6308;2;2;0;3.942011;3.866297;3043035;3.561373e+008
1748.958;1.238249;-0.8416371;3205.67;331.2532;2;2;0;3.899998;3.825869;2941986;3.441721e+008
1752.958;1.22491;-0.8106632;3100.382;320.3734;2;2;0;3.857984;3.785424;2845359;3.327334e+008
1756.958;1.211517;-0.7804875;2995.89;309.5759;2;2;0;3.815802;3.7448;2749462;3.213887e+008
1760.958;1.198231;-0.7470811;2896.161;299.2706;2;2;0;3.773957;3.704486;2657936;3.105649e+008
1764.958;1.184785;-0.716996;2797.563;289.0821;2;2;0;3.731606;3.663667;2567448;2.998695e+008
1768.958;1.171446;-0.6852611;2700.748;279.0778;2;2;0;3.689593;3.623156;2478597;2.893746e+008
1772.958;1.15816;-0.6528876;2608.756;269.572;2;2;0;3.647748;3.582792;2394171;2.794053e+008
1776.958;1.144714;-0.6239436;2515.044;259.8884;2;2;0;3.605397;3.541924;2308168;2.692584e+008
1780.958;1.131428;-0.5917128;2426.54;250.743;2;2;0;3.563552;3.501527;2226944;2.596783e+008
1784.958;1.118249;-0.5628651;2340.96;241.8996;2;2;0;3.522045;3.46144;2148403;2.504195e+008
1788.958;1.104803;-0.5332233;2253.47;232.859;2;2;0;3.479694;3.420521;2068110;2.409618e+008
1792.958;1.091571;-0.5017598;2171.416;224.3801;2;2;0;3.438018;3.380239;1992806;2.320944e+008
1796.958;1.078285;-0.4750989;2088.415;215.8033;2;2;0;3.396173;3.339777;1916632;2.231324e+008
1800.958;1.064892;-0.4450684;2007.252;207.4165;2;2;0;3.353991;3.298972;1842145;2.143732e+008
1804.958;1.051553;-0.4160942;1928.096;199.237;2;2;0;3.311977;3.258313;1769500;2.058357e+008
1808.958;1.03816;-0.3901412;1848.599;191.0223;2;2;0;3.269795;3.217475;1696542;1.972683e+008
1812.958;1.024928;-0.3614181;1772.78;183.1876;2;2;0;3.228119;3.17711;1626959;1.891011e+008
1816.958;1.011482;-0.3355502;1696.161;175.2703;2;2;0;3.185769;3.136076;1556643;1.80854e+008
1820.958;0.9980887;-0.3094603;1619.215;167.3192;2;2;0;3.143586;3.095187;1486026;1.72579e+008
1824.958;0.9848565;-0.2822204;1547.134;159.8708;2;2;0;3.10191;3.054773;1419874;1.648299e+008
1828.958;0.9714101;-0.2588467;1471.235;152.0279;2;2;0;3.059559;3.013688;1350218;1.566793e+008
1832.958;0.9581244;-0.2327274;1398.937;144.5571;2;2;0;3.017715;2.973077;1283867;1.489194e+008
1836.958;0.9448922;-0.208695;1328.209;137.2485;2;2;0;2.976038;2.932614;1218957;1.413331e+008
1840.958;0.931553;-0.1855008;1255.583;129.7439;2;2;0;2.934025;2.891807;1152305;1.335506e+008
1844.958;0.9182673;-0.160844;1187.58;122.7169;2;2;0;2.89218;2.851146;1089895;1.262661e+008
1848.958;0.904928;-0.1397387;1118.72;115.6013;2;2;0;2.850167;2.810305;1026699;1.188961e+008
1852.958;0.8915887;-0.116532;1051.236;108.6279;2;2;0;2.808153;2.769448;964766.2;1.116784e+008
1856.958;0.8781959;-0.09389249;985.3049;101.815;2;2;0;2.765971;2.728409;904258.3;1.046312e+008
1860.958;0.8648566;-0.07390203;918.2833;94.88947;2;2;0;2.723958;2.687518;842749.6;9.747421e+007
1864.958;0.8515173;-0.05238674;855.028;88.35307;2;2;0;2.681944;2.646611;784697.3;9.072265e+007
1868.958;0.8381245;-0.03285378;791.4495;81.78328;2;2;0;2.639762;2.605522;726348.5;8.394216e+007
1872.958;0.8247316;-0.01370323;727.7425;75.20021;2;2;0;2.59758;2.564416;667881.8;7.71536e+007
1876.958;0.8114995;0.006208766;667.8067;69.00683;2;2;0;2.555904;2.523787;612875.9;7.077058e+007
1880.958;0.7980531;0.02274845;606.8578;62.70876;2;2;0;2.513553;2.482483;556940.4;6.428498e+007
1884.958;0.7848209;0.03981277;550.6587;56.90152;2;2;0;2.471877;2.44182;505364.1;5.830805e+007
1888.958;0.7715888;0.05453605;497.879;51.4476;2;2;0;2.430201;2.401141;456925.8;5.269788e+007
1892.958;0.7581959;0.06771833;444.9288;45.97607;2;2;0;2.388019;2.359951;408331;4.707398e+007
1896.958;0.7449102;0.08059829;397.9751;41.12417;2;2;0;2.346174;2.319074;365239.4;4.208902e+007
1900.958;0.731571;0.08857497;351.6761;36.33994;2;2;0;2.304161;2.278016;322748.8;3.717727e+007
1904.958;0.7182317;0.09686249;307.0035;31.72376;2;2;0;2.262147;2.23694;281750.8;3.24414e+007
1908.958;0.7048388;0.1039271;266.1179;27.49891;2;2;0;2.219965;2.195682;244228.3;2.810937e+007
1912.958;0.6914995;0.1083009;224.2504;23.17259;2;2;0;2.177951;2.154573;205804.6;2.367728e+007
1916.958;0.6782138;0.1124732;187.0914;19.33282;2;2;0;2.136106;2.113612;171702.1;1.974579e+007
1920.958;0.6647674;0.1140827;152.3761;15.74556;2;2;0;2.093756;2.072138;139842.4;1.607524e+007
1924.958;0.6514281;0.1129082;121.6446;12.56997;2;2;0;2.051742;2.030977;111638.7;1.282787e+007
1928.958;0.638196;0.112321;107.1231;11.06941;2;2;0;2.010066;1.990131;98311.66;1.129191e+007
1932.346;0.6269461;0.1115435;106.4517;11.00003;2;2;0;1.974633;1.95539;97695.48;1.121724e+007