File: Ensayos/Graficos/EspCAmb2.raw
"Test Type";"Manual"
"Method Name:";"C:\INSTRON\user\template\Pablor.mtM"
"Name:";""
"Operator ID:";""
"Company:";""
"Lab name:";""
"Test date:";"31/03/2017"
"Temperature:";""
"Humidity:";""
"Note 1:";""
"Note 2:";""
"Note 3:";""
"Geometry:";"Rectangular"
"Specimen";1
"Specimen name:";""
"User Input 1:";"No definido"
"User Input 2:";"No definido"
"User Input 3:";"No definido"
"User Input 4:";"No definido"
"User Input 5:";"No definido"
"User Input 6:";"No definido"
"User Input 7:";"No definido"
"User Input 8:";"No definido"
"User Input 9:";"No definido"
"User Input 10:";"No definido"
"Width:";0.250000;"in"
"Thickness:";0.060000;"in"
"Length:";1.250000;"in"
"Diameter:";0.039370;"in"
"Inner diameter:";0.019685;"in"
"Outer diameter:";0.039370;"in"
"Wall thickness:";0.019685;"in"
"Area:";0.015000;"in*in"
"Linear density:";1.000000;"den"
"Sled weight:";2.204623;"lbf"
"Loading span:";0.000000;"mm"
"Support span:";1.000000;"mm"
"Span ratio:";"2"
"Fixture type:";"3-point"
"Comment:";""
"Included"
"Final Width:";0.250000;"in"
"Final Thickness:";0.060000;"in"
"Final Length:";1.250000;"in"
"Final Diameter:";0.039370;"in"
"Final Inner diameter:";0.019685;"in"
"Final Outer diameter:";0.039370;"in"
"Final Wall thickness:";0.019685;"in"
"Final Area:";0.015000;"in*in"
"Final Linear density:";1.000000;"den"
"Time sec";"Extension mm";"Strain 1 %";"Load N";"Stress MPa";"Cycle Count ";"Total Cycle Count ";"Repetitions Count ";"Strain [Exten.] %";"True strain %";"Tenacity gf/tex";"True stress Pa"
0;0.02298213;0.1323384;47.52087;4.9105;0;0;0;0.07238466;0.07235847;43612.02;4914054
4;0.03632141;0.1304195;81.99222;8.472547;0;0;0;0.1143981;0.1143327;75247.92;8482239
8;0.04971425;0.1256979;151.8128;15.68735;0;0;0;0.1565803;0.1564579;139325.4;1.571192e+007
12;0.06299996;0.1173411;234.9482;24.27803;0;0;0;0.1984251;0.1982285;215622.5;2.43262e+007
16;0.07639281;0.1062028;331.692;34.27491;0;0;0;0.2406073;0.2403183;304408.5;3.435738e+007
20;0.08978565;0.09447259;433.2734;44.77168;0;0;0;0.2827895;0.2823904;397634.3;4.489829e+007
24;0.1030178;0.08189688;540.0592;55.80623;0;0;0;0.3244655;0.3239402;495636.4;5.59873e+007
28;0.1164642;0.06816909;652.9352;67.4701;0;0;0;0.3668164;0.3661453;599227.8;6.771759e+007
32;0.1297499;0.05358454;767.5822;79.31699;0;0;0;0.4086612;0.4078284;704444.4;7.964113e+007
36;0.1429821;0.03770299;885.1329;91.46391;0;0;0;0.4503372;0.4493262;812325.9;9.187581e+007
40;0.1563213;0.02043776;1004.121;103.7594;0;0;0;0.4923506;0.4911426;921526.8;1.042703e+008
44;0.169607;0.002348685;1122.359;115.9774;0;0;0;0.5341954;0.5327736;1030039;1.165969e+008
48;0.1829999;-0.01619459;1241.381;128.2763;0;0;0;0.5763776;0.5747229;1139271;1.290157e+008
52;0.1962856;-0.03527664;1360.441;140.5792;0;0;0;0.6182223;0.6163192;1248537;1.414483e+008
56;0.2096784;-0.05488985;1480.679;153.0038;0;0;0;0.6604045;0.6582334;1358885;1.540143e+008
60;0.2230713;-0.07425547;1603.249;165.6693;0;0;0;0.7025868;0.7001301;1471373;1.668333e+008
64;0.2363034;-0.09357234;1725.013;178.2517;0;0;0;0.7442628;0.7415068;1583121;1.795783e+008
68;0.2498034;-0.1135356;1850.62;191.2311;0;0;0;0.7867824;0.7837034;1698396;1.927357e+008
72;0.2630891;-0.1335771;1974.608;204.0432;0;0;0;0.8286271;0.8252129;1812186;2.05734e+008
76;0.2763748;-0.1534153;2098.086;216.8027;0;0;0;0.8704718;0.8667051;1925507;2.186899e+008
80;0.2897677;-0.1736127;2222.802;229.69;0;0;0;0.912654;0.9085145;2039964;2.317862e+008
84.00001;0.3030534;-0.1934335;2345.197;242.3375;0;0;0;0.9544988;0.9499723;2152292;2.446506e+008
88.00001;0.3162855;-0.2131825;2466.631;254.8857;0;0;0;0.9961748;0.9912456;2263738;2.574248e+008
92.00001;0.3296248;-0.2328307;2595.463;268.1984;0;0;0;1.038188;1.032836;2381972;2.709828e+008
96.00001;0.3429105;-0.2523966;2727.724;281.8653;0;0;0;1.080033;1.074242;2503354;2.849096e+008
100;0.3563569;-0.2715304;2862.29;295.7706;0;0;0;1.122384;1.116132;2626851;2.990902e+008
104;0.369589;-0.2900479;2995.821;309.5688;0;0;0;1.16406;1.157337;2749399;3.131724e+008
108;0.3830355;-0.3086684;3138.063;324.2672;0;0;0;1.206411;1.199192;2879941;3.281792e+008
112;0.3963747;-0.3269009;3282.068;339.1477;0;0;0;1.248424;1.240696;3012101;3.433817e+008
116;0.4096604;-0.3452815;3423.852;353.7987;0;0;0;1.290269;1.282016;3142221;3.583637e+008
120;0.4231069;-0.3641393;3568.882;368.7852;0;0;0;1.33262;1.323819;3275322;3.736997e+008
124;0.4364461;-0.3834856;3712.234;383.5983;0;0;0;1.374634;1.365271;3406883;3.888713e+008
128;0.4496783;-0.4029631;3853.034;398.1477;0;0;0;1.41631;1.406374;3536102;4.037867e+008
132;0.4631247;-0.4232582;3996.136;412.9349;0;0;0;1.45866;1.448124;3667433;4.189582e+008
136;0.4763568;-0.4435965;4135.652;427.3516;0;0;0;1.500337;1.489193;3795473;4.337633e+008
140;0.4896425;-0.4645156;4274.135;441.6615;0;0;0;1.542181;1.53041;3922564;4.484727e+008
144;0.5029818;-0.4853086;4411.559;455.862;0;0;0;1.584195;1.571777;4048684;4.630837e+008
148;0.5162675;-0.5066098;4550.507;470.22;0;0;0;1.626039;1.612961;4176203;4.77866e+008
152;0.5296604;-0.5279873;4691.327;484.7714;0;0;0;1.668222;1.65446;4305440;4.928584e+008
156;0.542946;-0.5489862;4832.613;499.371;0;0;0;1.710066;1.695609;4435105;5.079106e+008
160;0.5563389;-0.5703396;4977.93;514.3872;0;0;0;1.752249;1.737074;4568469;5.234005e+008
164;0.5697854;-0.5918741;5123.475;529.4268;0;0;0;1.7946;1.778687;4702041;5.389279e+008
168;0.5830175;-0.6131729;5264.624;544.0122;0;0;0;1.836276;1.81962;4831580;5.540018e+008
172;0.5964639;-0.6349604;5407.545;558.7808;0;0;0;1.878626;1.861198;4962746;5.692782e+008
176;0.6098032;-0.6569984;5548.79;573.3762;0;0;0;1.92064;1.902429;5092373;5.843886e+008
180;0.6229818;-0.6791709;5686.238;587.5792;0;0;0;1.962147;1.943145;5218515;5.991083e+008
184;0.6364282;-0.7021595;5822.278;601.6366;0;0;0;2.004498;1.984673;5343365;6.136964e+008
188;0.6496603;-0.7269059;5948.005;614.6284;0;0;0;2.046174;2.025521;5458750;6.272048e+008
192;0.6629996;-0.7538006;6065.445;626.7639;0;0;0;2.088188;2.066684;5566529;6.398519e+008
196;0.6762853;-0.7810683;6174.802;638.0641;0;0;0;2.130032;2.107664;5666891;6.516551e+008
200;0.6896246;-0.8092777;6279.578;648.891;0;0;0;2.172046;2.148793;5763049;6.629852e+008
204;0.7030174;-0.8382822;6381.694;659.443;0;0;0;2.214228;2.19007;5856765;6.740446e+008
208;0.7163031;-0.8674373;6476.719;669.2623;0;0;0;2.256073;2.231;5943974;6.843614e+008
212;0.729696;-0.8975969;6572.018;679.1099;0;0;0;2.298255;2.272243;6031434;6.947176e+008
216;0.7430888;-0.9280609;6662.558;688.4658;0;0;0;2.340437;2.313469;6114527;7.045789e+008
220;0.7563745;-0.9584442;6750.328;697.5353;0;0;0;2.382282;2.354348;6195078;7.141526e+008
224;0.7698745;-0.9897172;6838.762;706.6735;0;0;0;2.424802;2.39587;6276237;7.238089e+008
228;0.7831067;-1.020959;6921.462;715.2192;0;0;0;2.466478;2.436551;6352134;7.328599e+008
232;0.7963387;-1.052679;7001.676;723.5079;0;0;0;2.508153;2.477216;6425750;7.416547e+008
236;0.8097316;-1.084697;7083.399;731.9527;0;0;0;2.550336;2.518357;6500751;7.506199e+008
240;0.8229638;-1.116645;7160.803;739.9512;0;0;0;2.592012;2.558989;6571789;7.591308e+008
244;0.836303;-1.149111;7238.472;747.9769;0;0;0;2.634025;2.599932;6643068;7.676788e+008
248;0.8496423;-1.181194;7314.336;755.8162;0;0;0;2.676039;2.640859;6712692;7.760421e+008
252;0.8629815;-1.213637;7389.169;763.549;0;0;0;2.718052;2.681769;6781370;7.843026e+008
256;0.8763745;-1.2462;7463.476;771.2274;0;0;0;2.760235;2.722827;6849565;7.925151e+008
260;0.8896066;-1.278388;7535.367;778.6561;0;0;0;2.801911;2.763375;6915542;8.004734e+008
264;0.903053;-1.310924;7609.129;786.2783;0;0;0;2.844261;2.804563;6983237;8.086421e+008
268;0.9164459;-1.343282;7681.139;793.7193;0;0;0;2.886444;2.845571;7049324;8.166296e+008
272;0.929678;-1.375311;7749.386;800.7714;0;0;0;2.92812;2.886069;7111957;8.24219e+008
276;0.9431244;-1.407466;7819.217;807.9874;0;0;0;2.97047;2.927207;7176044;8.319884e+008
280;0.9564101;-1.439523;7885.303;814.8163;0;0;0;3.012315;2.967836;7236694;8.393611e+008
284;0.9696423;-1.471878;7950.99;821.6039;0;0;0;3.053991;3.008285;7296979;8.466957e+008
288;0.9830351;-1.504273;8018.562;828.5864;0;0;0;3.096174;3.049209;7358992;8.542409e+008
292;0.9962672;-1.536591;8083.383;835.2846;0;0;0;3.137849;3.089625;7418481;8.614946e+008
296;1.00966;-1.56924;8149.005;842.0656;0;0;0;3.180032;3.130516;7478706;8.688435e+008
300;1.022892;-1.601853;8214.171;848.7994;0;0;0;3.221708;3.170899;7538511;8.761452e+008
304;1.036339;-1.63516;8280.413;855.6443;0;0;0;3.264059;3.21192;7599304;8.835731e+008
307.588;1.048392;-1.66519;8340.576;861.8612;0;0;0;3.302022;3.248677;7654518;8.903201e+008
310.59;1.038374;-1.656691;8166.206;843.843;0;0;0;3.27047;3.218128;7494492;8.714406e+008
314.59;1.025089;-1.640284;7960.032;822.5383;0;0;0;3.228626;3.177601;7305277;8.49095e+008
318.59;1.011696;-1.623331;7764.468;802.33;0;0;0;3.186443;3.136729;7125799;8.278958e+008
322.59;0.99841;-1.60592;7578.574;783.1209;0;0;0;3.144598;3.096169;6955196;8.077469e+008
326.59;0.9850172;-1.587792;7396.745;764.3318;0;0;0;3.102416;3.055264;6788323;7.880446e+008
330.59;0.9716244;-1.569354;7220.002;746.0684;0;0;0;3.060234;3.014343;6626118;7.688998e+008
334.59;0.9583387;-1.550421;7049.934;728.4947;0;0;0;3.01839;2.973733;6470039;7.504835e+008
338.59;0.9448922;-1.531145;6883.384;711.2844;0;0;0;2.976038;2.932614;6317189;7.324525e+008
342.59;0.931553;-1.511548;6721.644;694.5712;0;0;0;2.934025;2.891807;6168752;7.149501e+008
346.59;0.9183209;-1.491693;6563.487;678.2284;0;0;0;2.892349;2.85131;6023605;6.978451e+008
350.59;0.904928;-1.471205;6405.922;661.9465;0;0;0;2.850167;2.810305;5879000;6.808131e+008
354.59;0.8916423;-1.450524;6251.854;646.0262;0;0;0;2.808322;2.769612;5737606;6.641687e+008
358.59;0.8784101;-1.429418;6101.277;630.4666;0;0;0;2.766646;2.729066;5599414;6.479093e+008
362.59;0.8650174;-1.40762;5953.931;615.2408;0;0;0;2.724464;2.688011;5464189;6.320028e+008
366.59;0.8517316;-1.384944;5815.038;600.8884;0;0;0;2.682619;2.647268;5336720;6.17008e+008
370.59;0.8383387;-1.361543;5677.375;586.6632;0;0;0;2.640437;2.606179;5210380;6.021537e+008
374.59;0.8250531;-1.338235;5544.604;572.9435;0;0;0;2.598592;2.565403;5088531;5.87832e+008
378.59;0.8116601;-1.314223;5414.754;559.5257;0;0;0;2.55641;2.52428;4969361;5.738294e+008
382.59;0.7982674;-1.289795;5288.045;546.4324;0;0;0;2.514228;2.483141;4853075;5.601709e+008
386.59;0.7849816;-1.265247;5164.053;533.6199;0;0;0;2.472383;2.442314;4739282;5.468131e+008
390.59;0.7715888;-1.240018;5041.181;520.9231;0;0;0;2.430201;2.401141;4626517;5.335826e+008
394.59;0.7582495;-1.214806;4921.327;508.5382;0;0;0;2.388187;2.360116;4516522;5.20683e+008
398.59;0.7450173;-1.189559;4805.508;496.5701;0;0;0;2.346511;2.319404;4410229;5.082222e+008
402.59;0.7316245;-1.163873;4690.116;484.6463;0;0;0;2.304329;2.278181;4304329;4.958141e+008
406.59;0.7183388;-1.138106;4577.609;473.0206;0;0;0;2.262484;2.23727;4201077;4.837226e+008
410.59;0.7051067;-1.111978;4466.223;461.5106;0;0;0;2.220809;2.196508;4098852;4.717599e+008
414.59;0.6917138;-1.085215;4354.375;449.9529;0;0;0;2.178626;2.155233;3996204;4.597557e+008
418.59;0.6783746;-1.058204;4244.718;438.6218;0;0;0;2.136613;2.114107;3895567;4.479934e+008
422.59;0.6650353;-1.031345;4135.69;427.3555;0;0;0;2.094599;2.072964;3795508;4.363069e+008
426.59;0.651696;-1.004031;4026.83;416.1066;0;0;0;2.052586;2.031804;3695602;4.246476e+008
430.59;0.6383032;-0.9763668;3918.218;404.8834;0;0;0;2.010404;1.990462;3595924;4.130232e+008
434.59;0.6249102;-0.9489816;3811.364;393.8417;0;0;0;1.968221;1.949102;3497859;4.015934e+008
438.59;0.6116782;-0.9218831;3705.115;382.8626;0;0;0;1.926546;1.908223;3400349;3.902387e+008
442.59;0.5982317;-0.8938539;3597.962;371.7901;0;0;0;1.884194;1.866663;3302010;3.787954e+008
446.59;0.5848925;-0.8666044;3492.793;360.9227;0;0;0;1.842181;1.825418;3205492;3.675716e+008
450.59;0.5717139;-0.8398864;3387.949;350.0887;0;0;0;1.800674;1.784654;3109272;3.563927e+008
454.59;0.5583211;-0.8127394;3280.361;338.9713;0;0;0;1.758492;1.743209;3010533;3.449321e+008
458.59;0.5450354;-0.7859353;3174.884;328.072;0;0;0;1.716647;1.702079;2913733;3.337038e+008
462.59;0.5317496;-0.7594951;3069.192;317.1505;0;0;0;1.674802;1.660932;2816735;3.224621e+008
466.59;0.5183568;-0.7333729;2962.638;306.1399;0;0;0;1.63262;1.619436;2718945;3.11138e+008
470.59;0.5050711;-0.7074381;2858.153;295.3431;0;0;0;1.590775;1.578255;2623055;3.000413e+008
474.59;0.4916783;-0.6819149;2753.22;284.5;0;0;0;1.548593;1.536725;2526753;2.889058e+008
478.59;0.4783926;-0.6566625;2648.615;273.6908;0;0;0;1.506748;1.49551;2430752;2.778146e+008
482.59;0.4649461;-0.6308273;2542.85;262.7617;0;0;0;1.464397;1.453779;2333687;2.666095e+008
486.59;0.4515533;-0.6055281;2438.663;251.9957;0;0;0;1.422215;1.412196;2238070;2.555796e+008
490.59;0.4383211;-0.5807817;2335.303;241.3152;0;0;0;1.380539;1.371096;2143212;2.446466e+008
494.59;0.4248747;-0.5559817;2230.133;230.4476;0;0;0;1.338188;1.329314;2046693;2.335314e+008
498.59;0.411589;-0.5320276;2126.411;219.7296;0;0;0;1.296343;1.288013;1951503;2.225781e+008
502.59;0.3984104;-0.5085244;2022.423;208.9841;0;0;0;1.254836;1.247028;1856068;2.116065e+008
506.59;0.3850176;-0.4848587;1915.553;197.9409;0;0;0;1.212654;1.20536;1757989;2.003413e+008
510.59;0.3717319;-0.4618727;1810.36;187.0709;0;0;0;1.170809;1.164008;1661448;1.892612e+008
514.59;0.3583926;-0.4395453;1705.389;176.2238;0;0;0;1.128796;1.122472;1565111;1.78213e+008
518.59;0.3450533;-0.4176937;1599.887;165.322;0;0;0;1.086782;1.080919;1468288;1.671187e+008
522.59;0.3316605;-0.3955906;1495.384;154.5233;0;0;0;1.0446;1.039182;1372381;1.561375e+008
526.59;0.3183212;-0.3735997;1395.627;144.2151;0;0;0;1.002586;0.997594;1280829;1.45661e+008
530.59;0.3050355;-0.3516029;1301.778;134.5173;0;0;0;0.9607419;0.9561561;1194699;1.358097e+008
534.59;0.2915891;-0.3279581;1212.2;125.2609;0;0;0;0.9183909;0.9141993;1112490;1.264113e+008
538.59;0.2782498;-0.3042082;1125.812;116.3342;0;0;0;0.8763774;0.8725595;1033208;1.173537e+008
542.59;0.2650177;-0.2805986;1042.415;107.7165;0;0;0;0.8347014;0.831237;956671.2;1.086156e+008
546.59;0.2515713;-0.2564351;957.8523;98.97826;0;0;0;0.7923505;0.7892279;879063.8;9.976252e+007
550.59;0.2382856;-0.2329313;875.3498;90.453;0;0;0;0.7505057;0.7477035;803347.6;9.113185e+007
554.59;0.2250534;-0.2095576;796.0647;82.26018;0;0;0;0.7088297;0.7063293;730584.1;8.284326e+007
558.59;0.2116606;-0.1859635;718.2377;74.21804;0;0;0;0.6666476;0.6644353;659158.8;7.471282e+007
562.59;0.1983749;-0.1619922;643.966;66.54328;0;0;0;0.6248028;0.622859;590996.3;6.695905e+007
566.59;0.1850356;-0.1379022;572.2149;59.12899;0;0;0;0.5827893;0.5810977;525147.1;5.947359e+007
570.59;0.1717499;-0.1142742;502.1194;51.88578;0;0;0;0.5409445;0.5394867;460817.4;5.216645e+007
574.59;0.158357;-0.09141953;434.0405;44.85094;0;0;0;0.4987623;0.4975226;398338.3;4.507464e+007
578.59;0.1449642;-0.06950904;366.8456;37.90746;0;0;0;0.4565801;0.455541;336670.6;3.808053e+007
582.59;0.1316785;-0.04977426;301.5456;31.15977;0;0;0;0.4147354;0.4138777;276741.8;3.1289e+007
586.59;0.1182321;-0.03078815;237.9381;24.58698;0;0;0;0.3723845;0.3716928;218366.4;2.467854e+007
590.59;0.1048928;-0.01295044;177.8476;18.37762;0;0;0;0.330371;0.3298265;163218.6;1.843833e+007
594.59;0.09166066;0.003089516;123.0629;12.71653;0;0;0;0.288695;0.2882791;112940.3;1.275324e+007
598.59;0.0782678;0.01527749;76.89996;7.946345;0;0;0;0.2465128;0.2462094;70574.52;7965934
601.164;0.08303566;0.01415503;107.5894;11.11759;1;1;0;0.2615296;0.2611882;98739.55;1.114667e+007
605.164;0.09653565;0.004260487;190.5579;19.69102;1;1;0;0.3040493;0.303588;174883.5;1.975089e+007
609.164;0.1098749;-0.008945151;282.0465;29.14487;1;1;0;0.3460627;0.3454653;258846.7;2.924573e+007
613.164;0.1230535;-0.02321368;375.7147;38.82393;1;1;0;0.38757;0.3868209;344810.1;3.89744e+007
617.164;0.1364999;-0.03852886;473.9923;48.97931;1;1;0;0.4299209;0.4289994;435003.9;4.918988e+007
621.164;0.149732;-0.05497811;575.9046;59.51026;1;1;0;0.471597;0.4704885;528533.3;5.979091e+007
625.164;0.1630178;-0.07286159;679.4299;70.20789;1;1;0;0.5134417;0.5121281;623543.1;7.056837e+007
629.164;0.176357;-0.09171689;784.4464;81.05963;1;1;0;0.5554552;0.5539182;719921.5;8.150988e+007
633.164;0.1896427;-0.111832;891.6446;92.13679;1;1;0;0.5973;0.5955232;818302;9.268712e+007
637.164;0.2030891;-0.1327271;1001.481;103.4865;1;1;0;0.6396509;0.6376138;919103.4;1.041485e+008
641.164;0.2163213;-0.1533527;1111.172;114.8214;1;1;0;0.6813269;0.6790163;1019772;1.156037e+008
645.164;0.2297677;-0.1739948;1225.207;126.605;1;1;0;0.7236778;0.7210718;1124427;1.275212e+008
649.164;0.243107;-0.1949365;1341.384;138.61;1;1;0;0.7656913;0.7627748;1231048;1.396713e+008
653.164;0.2563927;-0.2156864;1457.744;150.6338;1;1;0;0.8075361;0.804293;1337836;1.518502e+008
657.164;0.2698391;-0.2366821;1577.095;162.9668;1;1;0;0.849887;0.8462958;1447370;1.643518e+008
661.164;0.2831784;-0.2577621;1696.873;175.3439;1;1;0;0.8919004;0.8879465;1557296;1.769078e+008
665.164;0.2964105;-0.2786454;1815.444;187.5963;1;1;0;0.9335765;0.9292456;1666114;1.893477e+008
669.164;0.3098034;-0.2994829;1938.209;200.282;1;1;0;0.9757586;0.9710288;1778781;2.022363e+008
673.164;0.3230355;-0.3199201;2061.657;213.0383;1;1;0;1.017435;1.012294;1892074;2.152058e+008
677.1641;0.3363748;-0.3405649;2192.181;226.5258;1;1;0;1.059448;1.053875;2011863;2.289258e+008
681.1641;0.3496605;-0.3604307;2324.435;240.1921;1;1;0;1.101293;1.095273;2133238;2.428373e+008
685.1641;0.3630533;-0.3800986;2458.36;254.031;1;1;0;1.143475;1.136987;2256147;2.569358e+008
689.1641;0.3764462;-0.3997484;2593.982;268.0453;1;1;0;1.185657;1.178683;2380613;2.712234e+008
693.1641;0.3896248;-0.4195244;2729.419;282.0405;1;1;0;1.227165;1.219696;2504910;2.855016e+008
697.1641;0.4031247;-0.4398479;2866.234;296.1781;1;1;0;1.269684;1.261691;2630471;2.999386e+008
701.1641;0.4165176;-0.4601924;3000.01;310.0017;1;1;0;1.311866;1.303336;2753243;3.140685e+008
705.1641;0.4297497;-0.4807482;3132.743;323.7174;1;1;0;1.353542;1.344464;2875058;3.280991e+008
709.1641;0.4431961;-0.5017058;3265.332;337.4183;1;1;0;1.395893;1.386241;2996741;3.421283e+008
713.1641;0.4564819;-0.5229259;3395.021;350.8195;1;1;0;1.437738;1.427501;3115762;3.558634e+008
717.1641;0.469714;-0.5445277;3524.081;364.1558;1;1;0;1.479414;1.468578;3234206;3.695431e+008
721.1641;0.4830533;-0.56675;3653.69;377.5487;1;1;0;1.521428;1.50997;3353154;3.832929e+008
725.1641;0.4963389;-0.5889449;3780.998;390.7039;1;1;0;1.563272;1.551179;3469990;3.968117e+008
729.1641;0.5096782;-0.6114107;3909.322;403.9641;1;1;0;1.605286;1.592537;3587759;4.104488e+008
733.1641;0.5230175;-0.6339893;4039.018;417.3661;1;1;0;1.647299;1.633878;3706787;4.242413e+008
737.1641;0.5363568;-0.656848;4168.135;430.7082;1;1;0;1.689313;1.675203;3825284;4.379842e+008
741.1641;0.5497496;-0.6801964;4298.107;444.1386;1;1;0;1.731495;1.716675;3944564;4.518288e+008
745.1641;0.5630354;-0.7040578;4425.087;457.2599;1;1;0;1.77334;1.7578;4061100;4.653687e+008
749.1641;0.5764818;-0.7285904;4552.846;470.4616;1;1;0;1.815691;1.799404;4178349;4.790038e+008
753.1641;0.589821;-0.7530936;4675.827;483.1697;1;1;0;1.857704;1.840659;4291215;4.921456e+008
757.1641;0.6030532;-0.7779858;4798.129;495.8076;1;1;0;1.89938;1.881567;4403457;5.052249e+008
761.1641;0.6164996;-0.8038187;4920.347;508.4369;1;1;0;1.941731;1.92312;4515622;5.183094e+008
765.1641;0.6298389;-0.829648;5038.492;520.6452;1;1;0;1.983745;1.964325;4624049;5.309734e+008
769.1641;0.643071;-0.8558526;5153.054;532.4833;1;1;0;2.025421;2.005182;4729187;5.432683e+008
773.1641;0.6564103;-0.882979;5269.379;544.5036;1;1;0;2.067434;2.046353;4835945;5.557609e+008
777.1641;0.669696;-0.9099834;5381.218;556.0603;1;1;0;2.109279;2.087342;4938584;5.677892e+008
781.1641;0.6830353;-0.9372977;5492.337;567.5427;1;1;0;2.151292;2.128478;5040563;5.797522e+008
785.1641;0.696321;-0.9645718;5600.806;578.751;1;1;0;2.193137;2.169434;5140109;5.914439e+008
789.1641;0.7097139;-0.9920603;5710.03;590.0376;1;1;0;2.235319;2.210702;5240349;6.032268e+008
793.1641;0.7231066;-1.019586;5817.278;601.1199;1;1;0;2.277501;2.251953;5338776;6.148105e+008
797.1641;0.7363388;-1.046989;5921.386;611.8777;1;1;0;2.319177;2.292693;5434320;6.260683e+008
801.1641;0.7498388;-1.075003;6026.141;622.7025;1;1;0;2.361697;2.33424;5530459;6.374089e+008
805.1641;0.7631781;-1.103018;6129.949;633.4293;1;1;0;2.403711;2.375276;5625727;6.486551e+008
809.1641;0.7764102;-1.130796;6231.931;643.9675;1;1;0;2.445386;2.415965;5719321;6.59715e+008
813.1641;0.7898031;-1.15886;6334.827;654.6001;1;1;0;2.487569;2.457133;5813753;6.708837e+008
817.1641;0.8031423;-1.186466;6434.95;664.9462;1;1;0;2.529582;2.498118;5905641;6.817665e+008
821.1641;0.8163209;-1.214097;6533.715;675.1519;1;1;0;2.57109;2.538593;5996282;6.925107e+008
825.1641;0.8297138;-1.241831;6634.26;685.5416;1;1;0;2.613272;2.579709;6088557;7.034567e+008
829.1641;0.8429994;-1.269726;6733.008;695.7456;1;1;0;2.655116;2.62048;6179182;7.142185e+008
833.1641;0.8563923;-1.297704;6833.641;706.1443;1;1;0;2.697299;2.661563;6271537;7.251911e+008
837.1641;0.8696245;-1.325251;6931.542;716.2607;1;1;0;2.738975;2.702136;6361385;7.358789e+008
841.1641;0.8830708;-1.353105;7031.595;726.5996;1;1;0;2.781325;2.743349;6453209;7.468087e+008
845.1641;0.8964638;-1.38084;7130.494;736.8192;1;1;0;2.823508;2.784382;6543973;7.576234e+008
849.1641;0.9097494;-1.408489;7227.019;746.7934;1;1;0;2.865353;2.825069;6632558;7.681917e+008
853.1641;0.9231423;-1.436222;7324.435;756.8598;1;1;0;2.907535;2.866068;6721961;7.788658e+008
857.1641;0.9365351;-1.463548;7420.199;766.7555;1;1;0;2.949717;2.90705;6809848;7.893726e+008
861.1641;0.9497673;-1.490535;7512.953;776.3401;1;1;0;2.991393;2.947524;6894972;7.995634e+008
865.1641;0.9632137;-1.518096;7608.459;786.209;1;1;0;3.033744;2.988636;6982622;8.100605e+008
869.1641;0.9764458;-1.545717;7699.784;795.646;1;1;0;3.07542;3.029077;7066436;8.201154e+008
873.1641;0.9896779;-1.573652;7790.409;805.0106;1;1;0;3.117096;3.069501;7149606;8.301035e+008
877.1641;1.003017;-1.601854;7881.579;814.4315;1;1;0;3.159109;3.110236;7233277;8.401602e+008
881.1641;1.016303;-1.630575;7968.208;823.3832;1;1;0;3.200954;3.150791;7312780;8.497393e+008
885.1641;1.029749;-1.659904;8055.559;832.4094;1;1;0;3.243305;3.19182;7392946;8.59407e+008
887.7081;1.031732;-1.669918;8031.29;829.9017;1;1;0;3.249548;3.197867;7370673;8.568697e+008
891.7081;1.018285;-1.654074;7815.293;807.5818;1;1;0;3.207197;3.15684;7172443;8.334826e+008
895.7081;1.004946;-1.637263;7618.405;787.2368;1;1;0;3.165183;3.116124;6991750;8.121543e+008
899.7081;0.991553;-1.619795;7429.932;767.7612;1;1;0;3.123001;3.075228;6818780;7.917384e+008
903.7081;0.9782672;-1.602076;7248.925;749.0571;1;1;0;3.081156;3.034642;6652662;7.721367e+008
907.7081;0.9648208;-1.583407;7070.826;730.6534;1;1;0;3.038806;2.993549;6489212;7.528566e+008
911.7081;0.9514816;-1.564704;6899.422;712.9417;1;1;0;2.996792;2.952766;6331907;7.34307e+008
915.7081;0.9382494;-1.545669;6734.716;695.922;1;1;0;2.955116;2.912294;6180749;7.164873e+008
919.7081;0.9247495;-1.525752;6570.708;678.9745;1;1;0;2.912597;2.870987;6030232;6.987504e+008
923.7081;0.9114637;-1.505549;6410.692;662.4395;1;1;0;2.870752;2.830318;5883378;6.814565e+008
927.7081;0.8982851;-1.485087;6255.429;646.3956;1;1;0;2.829245;2.789961;5740886;6.646837e+008
931.7081;0.8848923;-1.463835;6100.118;630.3469;1;1;0;2.787062;2.748931;5598351;6.47915e+008
935.7081;0.8716066;-1.442458;5950.614;614.8981;1;1;0;2.745218;2.708212;5461144;6.317783e+008
939.7081;0.8583209;-1.420858;5803.564;599.7028;1;1;0;2.703373;2.667477;5326189;6.15915e+008
943.7081;0.8449816;-1.398403;5661.53;585.0259;1;1;0;2.66136;2.626561;5195839;6.005956e+008
947.7081;0.8315887;-1.375053;5523.534;570.7664;1;1;0;2.619177;2.585464;5069194;5.857157e+008
951.7081;0.8182495;-1.351597;5390.656;557.0356;1;1;0;2.577164;2.544515;4947246;5.713913e+008
955.7081;0.8049638;-1.32804;5262.093;543.7507;1;1;0;2.535319;2.503713;4829258;5.575365e+008
959.7081;0.7915174;-1.303829;5133.834;530.4973;1;1;0;2.492968;2.462401;4711549;5.437224e+008
963.7081;0.7781244;-1.279481;5008.509;517.5469;1;1;0;2.450786;2.421236;4596532;5.302309e+008
967.7081;0.7648923;-1.255075;4886.725;504.9626;1;1;0;2.40911;2.380548;4484766;5.171277e+008
971.7081;0.7514459;-1.229887;4765.439;492.4297;1;1;0;2.366759;2.339185;4373456;5.040843e+008
975.7081;0.7381602;-1.205081;4648.393;480.3349;1;1;0;2.324914;2.2983;4266038;4.915023e+008
979.7081;0.7249281;-1.17986;4534.135;468.5282;1;1;0;2.283238;2.257562;4161178;4.792258e+008
983.7081;0.7115888;-1.154093;4420.284;456.7635;1;1;0;2.241225;2.216478;4056691;4.670006e+008
987.7081;0.6983031;-1.128157;4308.153;445.1767;1;1;0;2.19938;2.175542;3953784;4.549678e+008
991.7081;0.6849638;-1.10177;4196.865;433.677;1;1;0;2.157366;2.134425;3851651;4.43033e+008
995.7081;0.6716245;-1.075253;4087.778;422.4045;1;1;0;2.115353;2.09329;3751536;4.313399e+008
999.7081;0.6582853;-1.04828;3978.626;411.1255;1;1;0;2.073339;2.052138;3651363;4.196496e+008
1003.708;0.6448924;-1.021004;3868.672;399.7635;1;1;0;2.031157;2.010804;3550453;4.078834e+008
1007.708;0.6316067;-0.9940398;3760.935;388.6307;1;1;0;1.989313;1.969784;3451578;3.963618e+008
1011.708;0.6181603;-0.9668404;3652.617;377.4378;1;1;0;1.946962;1.928251;3352170;3.847864e+008
1015.708;0.604821;-0.9396864;3545.399;366.3586;1;1;0;1.904948;1.887031;3253771;3.733375e+008
1019.708;0.5915889;-0.9125412;3439.748;355.4413;1;1;0;1.863272;1.846126;3156810;3.620642e+008
1023.708;0.5781425;-0.8851482;3333.518;344.4642;1;1;0;1.820921;1.804541;3059318;3.507366e+008
1027.708;0.5648567;-0.8581766;3227.724;333.5321;1;1;0;1.779076;1.763436;2962226;3.394659e+008
1031.708;0.5516247;-0.8314427;3122.158;322.6237;1;1;0;1.737401;1.72248;2865344;3.282289e+008
1035.708;0.5382318;-0.8046658;3015.331;311.5848;1;1;0;1.695218;1.68101;2767304;3.168669e+008
1039.708;0.5249996;-0.778653;2910.649;300.7677;1;1;0;1.653542;1.64002;2671232;3.05741e+008
1043.708;0.5116068;-0.7527675;2804.652;289.8146;1;1;0;1.61136;1.598515;2573955;2.944846e+008
1047.708;0.4982675;-0.7272942;2700.214;279.0227;1;1;0;1.569347;1.55716;2478107;2.834016e+008
1051.708;0.4849283;-0.7019582;2595.347;268.1863;1;1;0;1.527333;1.515787;2381865;2.722824e+008
1055.708;0.4715354;-0.6765954;2490.921;257.3957;1;1;0;1.485151;1.474231;2286029;2.612184e+008
1059.708;0.4582497;-0.6516715;2388.618;246.8244;1;1;0;1.443306;1.43299;2192142;2.503868e+008
1063.708;0.4448033;-0.6264962;2285.469;236.1656;1;1;0;1.400955;1.391233;2097477;2.394741e+008
1067.708;0.431464;-0.6015293;2181.944;225.4679;1;1;0;1.358942;1.349791;2002467;2.285319e+008
1071.708;0.4182319;-0.5772756;2080.429;214.9781;1;1;0;1.317266;1.308665;1909303;2.178099e+008
1075.708;0.404839;-0.5530588;1976.316;204.2197;1;1;0;1.275084;1.267023;1813753;2.068237e+008
1079.708;0.3915533;-0.5295259;1873.081;193.5521;1;1;0;1.233239;1.225696;1719010;1.959391e+008
1083.708;0.3783212;-0.5060932;1769.948;182.895;1;1;0;1.191563;1.18452;1624360;1.850743e+008
1087.708;0.3649283;-0.4833075;1666.14;172.1681;1;1;0;1.14938;1.142825;1529091;1.74147e+008
1091.708;0.3516426;-0.4611303;1563.863;161.5995;1;1;0;1.107536;1.101448;1435227;1.633893e+008
1095.708;0.3382498;-0.4389502;1460.641;150.9332;1;1;0;1.065354;1.059719;1340496;1.525412e+008
1099.708;0.3249641;-0.416931;1360.202;140.5545;1;1;0;1.023509;1.018307;1248318;1.419931e+008
1103.708;0.3115712;-0.3949792;1263.518;130.5638;1;1;0;0.9813268;0.976543;1159587;1.31845e+008
1107.708;0.2981784;-0.372637;1171.445;121.0496;1;1;0;0.9391445;0.934762;1075087;1.221864e+008
1111.708;0.2848927;-0.3494319;1085.545;112.1732;1;1;0;0.8972998;0.8932979;996252.8;1.131797e+008
1115.708;0.2714462;-0.3251918;1001.238;103.4615;1;1;0;0.8549488;0.8513148;918880.8;1.04346e+008
1119.708;0.258107;-0.3014521;918.5784;94.91995;1;1;0;0.8129354;0.8096488;843020.3;9.569159e+007
1123.708;0.2448748;-0.2778347;838.4779;86.64289;1;1;0;0.7712593;0.7683003;769508.6;8.731113e+007
1127.708;0.231482;-0.2539972;758.5198;78.38053;1;1;0;0.7290772;0.7264322;696127.4;7.895199e+007
1131.708;0.2182499;-0.2304835;682.7342;70.54935;1;1;0;0.6874011;0.6850493;626575.6;7.10343e+007
1135.708;0.2050177;-0.2067643;610.2723;63.0616;1;1;0;0.6457251;0.6436492;560074.1;6.34688e+007
1139.708;0.1916249;-0.1825419;539.0152;55.69835;1;1;0;0.6035429;0.6017289;494678.3;5.603451e+007
1143.708;0.1782856;-0.1585971;471.7973;48.75249;1;1;0;0.5615294;0.5599587;432989.4;4.902625e+007
1147.708;0.1649463;-0.1354937;405.7858;41.93128;1;1;0;0.519516;0.5181711;372407.7;4.214912e+007
1151.708;0.151607;-0.1132228;341.5103;35.28946;1;1;0;0.4775025;0.4763661;313419.2;3.545797e+007
1155.708;0.1382142;-0.09246956;278.3813;28.76613;1;1;0;0.4353203;0.4343755;255482.9;2.889135e+007
1159.708;0.1248213;-0.0725161;217.5965;22.48502;1;1;0;0.3931381;0.3923673;199698;2.257341e+007
1163.708;0.1115892;-0.05344934;161.038;16.64063;1;1;0;0.3514621;0.3508459;147791.8;1.669911e+007
1167.708;0.09808922;-0.03658869;108.1057;11.17094;1;1;0;0.3089424;0.3084662;99213.41;1.120545e+007
1171.708;0.08480351;-0.02511654;66.65281;6.887471;1;1;0;0.2670977;0.2667416;61170.26;6905867
1173.954;0.07735709;-0.02127083;49.67725;5.133326;2;2;0;0.2436444;0.243348;45591.02;5145833
1177.954;0.09074994;-0.02557396;108.9434;11.2575;2;2;0;0.2858266;0.2854189;99982.2;1.128968e+007
1181.954;0.1039821;-0.03517757;185.9553;19.21542;2;2;0;0.3275026;0.3269675;170659.5;1.927835e+007
1185.954;0.1174285;-0.04909433;274.2592;28.34017;2;2;0;0.3698535;0.3691713;251699.9;2.844499e+007
1189.954;0.1308213;-0.06432675;366.0866;37.82902;2;2;0;0.4120357;0.4111892;335973.9;3.798489e+007
1193.954;0.1440535;-0.08046138;459.8366;47.51654;2;2;0;0.4537117;0.4526856;422012.6;4.773213e+007
1197.954;0.1575535;-0.0982842;559.2618;57.7905;2;2;0;0.4962314;0.4950042;513259.5;5.807728e+007
1201.954;0.1708392;-0.1170014;658.7845;68.07453;2;2;0;0.5380762;0.5366337;604595.9;6.844082e+007
1205.954;0.1840177;-0.136616;758.7662;78.406;2;2;0;0.5795834;0.5779103;696353.6;7.886043e+007
1209.954;0.1974106;-0.1574991;863.8161;89.26118;2;2;0;0.6217656;0.6198407;792762.6;8.981618e+007
1213.954;0.2106963;-0.1784652;969.5338;100.1854;2;2;0;0.6636104;0.6614182;889784.4;1.008502e+008
1217.954;0.2240356;-0.1993939;1078.477;111.4429;2;2;0;0.7056239;0.703146;989766.6;1.122292e+008
1221.954;0.2372677;-0.2202969;1189.302;122.8948;2;2;0;0.7472998;0.7445214;1091475;1.238131e+008
1225.954;0.2506606;-0.241556;1304.374;134.7856;2;2;0;0.7894821;0.786382;1197082;1.358497e+008
1229.954;0.264107;-0.26266;1420.542;146.7896;2;2;0;0.8318329;0.8283923;1303695;1.480106e+008
1233.954;0.2773391;-0.28357;1536.727;158.7954;2;2;0;0.873509;0.8697159;1410323;1.601825e+008
1237.954;0.2907855;-0.304996;1655.696;171.089;2;2;0;0.9158599;0.9116914;1519506;1.726559e+008
1241.954;0.3041784;-0.3260338;1775.671;183.4864;2;2;0;0.9580421;0.953482;1629612;1.852442e+008
1245.954;0.3174105;-0.346447;1896.954;196.019;2;2;0;0.9997181;0.9947539;1740919;1.979786e+008
1249.954;0.3308569;-0.3671312;2026.266;209.3813;2;2;0;1.042069;1.036677;1859595;2.115632e+008
1253.954;0.3441426;-0.3872727;2157.468;222.9388;2;2;0;1.083914;1.078082;1980005;2.253553e+008
1257.954;0.3573748;-0.4070896;2288.34;236.4622;2;2;0;1.12559;1.119302;2100111;2.391238e+008
1261.954;0.370714;-0.4268086;2421.239;250.1952;2;2;0;1.167603;1.160839;2222079;2.531164e+008
1265.954;0.3839997;-0.4470762;2554.18;263.9324;2;2;0;1.209448;1.202193;2344085;2.671245e+008
1269.954;0.397339;-0.4676452;2688.234;277.7848;2;2;0;1.251462;1.243695;2467112;2.812611e+008
1273.954;0.4106247;-0.4880971;2819.587;291.3579;2;2;0;1.293306;1.285014;2587660;2.95126e+008
1277.954;0.4240176;-0.5093343;2951.258;304.964;2;2;0;1.335489;1.32665;2708502;3.090367e+008
1281.954;0.437464;-0.5308037;3082.878;318.5647;2;2;0;1.377839;1.368433;2829295;3.22954e+008
1285.954;0.4506961;-0.5522399;3209.601;331.6595;2;2;0;1.419515;1.409535;2945595;3.363674e+008
1289.954;0.4641426;-0.5744897;3337.841;344.9109;2;2;0;1.461866;1.451284;3063285;3.49953e+008
1293.954;0.4774818;-0.596766;3464.503;357.9993;2;2;0;1.50388;1.492684;3179529;3.633832e+008
1297.954;0.4907675;-0.6190902;3588.803;370.8437;2;2;0;1.545725;1.5339;3293604;3.765759e+008
1301.954;0.504214;-0.6416469;3715.32;383.9172;2;2;0;1.588076;1.575598;3409715;3.900141e+008
1305.954;0.5174461;-0.6642853;3841.403;396.9458;2;2;0;1.629751;1.616614;3525427;4.03415e+008
1309.954;0.5306782;-0.6871674;3966.272;409.849;2;2;0;1.671427;1.657613;3640025;4.166993e+008
1313.954;0.5440711;-0.7105418;4092.366;422.8787;2;2;0;1.71361;1.699093;3755747;4.301252e+008
1317.954;0.5573032;-0.7344384;4215.61;435.6139;2;2;0;1.755286;1.740058;3868853;4.432601e+008
1321.954;0.5706961;-0.7591535;4341.06;448.5771;2;2;0;1.797468;1.781505;3983985;4.566401e+008
1325.954;0.5839282;-0.7837245;4461.343;461.0064;2;2;0;1.839144;1.822436;4094374;4.69485e+008
1329.954;0.5973746;-0.8089946;4582.808;473.5577;2;2;0;1.881495;1.864014;4205847;4.824677e+008
1333.954;0.6107675;-0.8347865;4703.016;485.9792;2;2;0;1.923677;1.905408;4316167;4.953279e+008
1337.954;0.6240531;-0.8607381;4819.705;498.0372;2;2;0;1.965522;1.946455;4423259;5.078262e+008
1341.954;0.6374996;-0.887441;4936.578;510.1141;2;2;0;2.007873;1.987981;4530518;5.203566e+008
1345.954;0.6508388;-0.9145863;5052.265;522.0684;2;2;0;2.049886;2.029159;4636689;5.327702e+008
1349.954;0.664071;-0.941537;5164.168;533.6318;2;2;0;2.091562;2.069989;4739388;5.44793e+008
1353.954;0.6775175;-0.9686687;5276.207;545.2091;2;2;0;2.133913;2.111464;4842211;5.568434e+008
1357.954;0.6907495;-0.9955613;5384.591;556.4088;2;2;0;2.175589;2.152261;4941679;5.68514e+008
1361.954;0.7040353;-1.022786;5492.662;567.5762;2;2;0;2.217434;2.193206;5040862;5.801619e+008
1365.954;0.7173746;-1.049945;5599.229;578.5882;2;2;0;2.259448;2.2343;5138663;5.916611e+008
1369.954;0.7306602;-1.07745;5704.635;589.4801;2;2;0;2.301292;2.275212;5235398;6.030458e+008
1373.954;0.7440531;-1.105151;5810.624;600.4323;2;2;0;2.343474;2.316437;5332669;6.145033e+008
1377.954;0.7572852;-1.132217;5913.549;611.068;2;2;0;2.38515;2.35715;5427128;6.256429e+008
1381.954;0.7707316;-1.159924;6019.135;621.9786;2;2;0;2.427501;2.398506;5524029;6.370771e+008
1385.954;0.7841245;-1.187492;6124.313;632.847;2;2;0;2.469683;2.43968;5620556;6.484763e+008
1389.954;0.7973566;-1.21465;6226.273;643.3829;2;2;0;2.511359;2.480343;5714129;6.595405e+008
1393.954;0.8108566;-1.242124;6330.374;654.14;2;2;0;2.553879;2.521812;5809667;6.708459e+008
1397.954;0.8241959;-1.269416;6432.025;664.6439;2;2;0;2.595893;2.562771;5902956;6.818973e+008
1401.954;0.8373745;-1.29649;6533.009;675.079;2;2;0;2.6374;2.60322;5995634;6.928835e+008
1405.954;0.8508209;-1.323784;6636.474;685.7703;2;2;0;2.679751;2.644474;6090588;7.041472e+008
1409.954;0.864053;-1.350796;6736.892;696.1469;2;2;0;2.721427;2.685054;6182746;7.15092e+008
1413.954;0.8773388;-1.377698;6838.699;706.6669;2;2;0;2.763272;2.725782;6276179;7.261941e+008
1417.954;0.890678;-1.40458;6940.536;717.1901;2;2;0;2.805285;2.766658;6369640;7.373094e+008
1421.954;0.9039637;-1.431397;7041.77;727.651;2;2;0;2.84713;2.807352;6462546;7.483682e+008
1425.954;0.9174101;-1.458264;7144.838;738.3015;2;2;0;2.889481;2.848522;6557137;7.596345e+008
1429.954;0.9306423;-1.48446;7244.341;748.5834;2;2;0;2.931157;2.88902;6648455;7.705255e+008
1433.954;0.9440887;-1.51065;7345.485;759.035;2;2;0;2.973508;2.930156;6741279;7.816049e+008
1437.954;0.9574815;-1.53683;7446.265;769.4489;2;2;0;3.01569;2.971112;6833770;7.926531e+008
1441.954;0.9707137;-1.563134;7545.649;779.7187;2;2;0;3.057366;3.01156;6924979;8.035575e+008
1445.954;0.9842137;-1.589881;7646.954;790.1868;2;2;0;3.099886;3.05281;7017951;8.146817e+008
1449.954;0.9974994;-1.616509;7744.817;800.2993;2;2;0;3.14173;3.093388;7107764;8.254426e+008
1453.954;1.010731;-1.64315;7840.358;810.1719;2;2;0;3.183406;3.133786;7195446;8.35963e+008
1457.954;1.024178;-1.670738;7936.397;820.096;2;2;0;3.225757;3.174822;7283586;8.465503e+008
1460.402;1.018981;-1.668328;7831.545;809.2613;2;2;0;3.209391;3.158966;7187358;8.352336e+008
1464.402;1.005535;-1.651989;7623.522;787.7655;2;2;0;3.167039;3.117923;6996446;8.127144e+008
1468.402;0.9921958;-1.634963;7430.483;767.8181;2;2;0;3.125026;3.077191;6819285;7.918126e+008
1472.402;0.97891;-1.617633;7246.344;748.7903;2;2;0;3.083181;3.036606;6650293;7.718769e+008
1476.402;0.9654101;-1.599252;7063.791;729.9265;2;2;0;3.040662;2.99535;6482756;7.521211e+008
1480.402;0.9521244;-1.580805;6891.095;712.0812;2;2;0;2.998817;2.954732;6324265;7.334352e+008
1484.402;0.9389458;-1.562142;6724.999;694.9179;2;2;0;2.95731;2.914425;6171831;7.154688e+008
1488.402;0.925553;-1.542633;6558.591;677.7224;2;2;0;2.915128;2.873446;6019111;6.974789e+008
1492.402;0.9122673;-1.522682;6397.131;661.0381;2;2;0;2.873283;2.832778;5870932;6.800317e+008
1496.402;0.8989815;-1.502263;6238.679;644.6648;2;2;0;2.831438;2.792094;5725514;6.629181e+008
1500.402;0.8856423;-1.481241;6082.127;628.4877;2;2;0;2.789425;2.751229;5581839;6.460189e+008
1504.402;0.872303;-1.459937;5929.748;612.7419;2;2;0;2.747411;2.710347;5441995;6.295764e+008
1508.402;0.8589102;-1.438072;5780.194;597.288;2;2;0;2.705229;2.669284;5304742;6.13446e+008
1512.402;0.8456245;-1.415997;5634.988;582.2832;2;2;0;2.663384;2.628533;5171480;5.977917e+008
1516.402;0.832178;-1.392616;5493.376;567.65;2;2;0;2.621033;2.587273;5041516;5.825283e+008
1520.402;0.8188387;-1.369246;5357.641;553.624;2;2;0;2.57902;2.546324;4916946;5.679021e+008
1524.402;0.805553;-1.345981;5227.687;540.1954;2;2;0;2.537175;2.505523;4797681;5.539011e+008
1528.402;0.7921067;-1.32195;5098.051;526.7997;2;2;0;2.494824;2.464211;4678709;5.399424e+008
1532.402;0.7788209;-1.29772;4971.642;513.7374;2;2;0;2.452979;2.423377;4562698;5.263392e+008
1536.402;0.7655888;-1.273722;4849.548;501.121;2;2;0;2.411303;2.38269;4450647;5.132045e+008
1540.402;0.7521959;-1.248994;4727.165;488.4747;2;2;0;2.369121;2.341493;4338330;5.000472e+008
1544.402;0.7389638;-1.224202;4609.916;476.3589;2;2;0;2.327445;2.300773;4230726;4.87446e+008
1548.402;0.7256246;-1.199189;4492.801;464.257;2;2;0;2.285432;2.259707;4123244;4.748673e+008
1552.402;0.7123388;-1.17386;4377.969;452.391;2;2;0;2.243587;2.218789;4017857;4.625408e+008
1556.402;0.698946;-1.147975;4264.118;440.6264;2;2;0;2.201405;2.177524;3913371;4.503264e+008
1560.402;0.6855531;-1.121851;4151.76;429.016;2;2;0;2.159222;2.136241;3810255;4.382794e+008
1564.402;0.6722674;-1.095627;4042.486;417.7243;2;2;0;2.117378;2.095273;3709969;4.265691e+008
1568.402;0.658821;-1.068735;3932.21;406.3292;2;2;0;2.075027;2.053791;3608765;4.147606e+008
1572.402;0.6454817;-1.041738;3822.319;394.9737;2;2;0;2.033013;2.012623;3507912;4.030036e+008
1576.402;0.632196;-1.014891;3713.896;383.77;2;2;0;1.991169;1.971604;3408408;3.914115e+008
1580.402;0.6188032;-0.9878226;3605.631;372.5826;2;2;0;1.948986;1.930237;3309048;3.798442e+008
1584.402;0.6055175;-0.9609453;3498.341;361.4959;2;2;0;1.907142;1.889184;3210584;3.683902e+008
1588.402;0.5922853;-0.9339987;3393.5;350.6624;2;2;0;1.865466;1.848279;3114366;3.572039e+008
1592.402;0.5788925;-0.9067056;3287.568;339.7161;2;2;0;1.823283;1.806861;3017148;3.4591e+008
1596.402;0.5656068;-0.8794837;3181.528;328.7586;2;2;0;1.781439;1.765757;2919830;3.346152e+008
1600.402;0.5523211;-0.8525011;3075.575;317.81;2;2;0;1.739594;1.724636;2822592;3.233386e+008
1604.402;0.5389818;-0.8259106;2969.602;306.8595;2;2;0;1.69758;1.683333;2725336;3.120686e+008
1608.402;0.5255889;-0.7996628;2864.378;295.9863;2;2;0;1.655398;1.641846;2628767;3.008861e+008
1612.402;0.5121961;-0.7736585;2757.615;284.9541;2;2;0;1.613216;1.600342;2530786;2.895511e+008
1616.402;0.4989104;-0.7483402;2653.6;274.2059;2;2;0;1.571371;1.559153;2435327;2.785147e+008
1620.402;0.4855176;-0.7226531;2549.128;263.4104;2;2;0;1.529189;1.517615;2339449;2.674385e+008
1624.402;0.4721247;-0.6974428;2445.424;252.6944;2;2;0;1.487007;1.476059;2244275;2.56452e+008
1628.402;0.4588926;-0.672543;2344.34;242.249;2;2;0;1.445331;1.434986;2151506;2.457503e+008
1632.402;0.4454462;-0.6470776;2241.261;231.5974;2;2;0;1.40298;1.393229;2056905;2.348467e+008
1636.402;0.432214;-0.6223976;2140.725;221.2087;2;2;0;1.361304;1.352121;1964639;2.2422e+008
1640.402;0.4189819;-0.5977718;2039.811;210.7809;2;2;0;1.319628;1.310997;1872026;2.135624e+008
1644.402;0.405589;-0.5734673;1936.989;200.1559;2;2;0;1.277446;1.269355;1777661;2.027128e+008
1648.402;0.3923033;-0.5496151;1834.904;189.6071;2;2;0;1.235601;1.22803;1683973;1.919499e+008
1652.402;0.378964;-0.5258435;1731.657;178.9382;2;2;0;1.193588;1.18652;1589219;1.81074e+008
1656.402;0.3656248;-0.5029361;1629.603;168.3926;2;2;0;1.151574;1.144994;1495559;1.703318e+008
1660.402;0.3522319;-0.4803305;1527.514;157.8435;2;2;0;1.109392;1.103283;1401868;1.595946e+008
1664.402;0.3388391;-0.4580787;1425.87;147.3402;2;2;0;1.06721;1.061555;1308585;1.489126e+008
1668.402;0.3255533;-0.4361414;1325.907;137.0107;2;2;0;1.025365;1.020144;1216844;1.384155e+008
1672.402;0.3121605;-0.4139479;1229.291;127.0269;2;2;0;0.9831827;0.9783809;1128175;1.282759e+008
1676.402;0.2987677;-0.3918811;1137.871;117.5803;2;2;0;0.9410006;0.9366007;1044275;1.186867e+008
1680.402;0.2855355;-0.368853;1052.081;108.7153;2;2;0;0.8993245;0.8953047;965541.8;1.09693e+008
1684.402;0.2721427;-0.3448269;968.5832;100.0871;2;2;0;0.8571423;0.8534897;888912;1.00945e+008
1688.402;0.258857;-0.3208639;888.1362;91.77425;2;2;0;0.8152976;0.811992;815082.2;9.252249e+007
1692.402;0.2456784;-0.2969492;808.8097;83.57717;2;2;0;0.7737903;0.7708119;742280.8;8.422389e+007
1696.402;0.2322856;-0.2730483;729.733;75.40589;2;2;0;0.7316081;0.7289448;669708.5;7.595757e+007
1700.402;0.2189998;-0.2494961;655.2351;67.70776;2;2;0;0.6897633;0.6873953;601338.5;6.817479e+007
1704.402;0.205607;-0.225716;582.8169;60.22454;2;2;0;0.6475812;0.6454933;534877.1;6.061454e+007
1708.402;0.1923213;-0.2017365;513.2452;53.03545;2;2;0;0.6057364;0.6039092;471028;5.33567e+007
1712.402;0.1788749;-0.1778008;446.3405;46.12194;2;2;0;0.5633855;0.5618044;409626.6;4.638179e+007
1716.402;0.1655356;-0.1545629;382.218;39.49594;2;2;0;0.521372;0.5200175;350778.5;3.970186e+007
1720.402;0.1522499;-0.1325969;319.5619;33.02146;2;2;0;0.4795273;0.4783812;293276.2;3.317981e+007
1724.402;0.1388035;-0.1116121;257.9094;26.65069;2;2;0;0.4371763;0.4362234;236694.9;2.67672e+007
1728.402;0.1254642;-0.09131489;199.1908;20.5831;2;2;0;0.3951629;0.3943841;182806.3;2.066443e+007
1732.402;0.1122321;-0.07241053;145.1503;14.9989;2;2;0;0.3534868;0.3528635;133210.9;1.505192e+007
1736.402;0.09883923;-0.05691084;95.45294;9.86349;2;2;0;0.3113047;0.3108211;87601.42;9894196
1738.602;0.09155351;-0.05085471;72.7949;7.522155;2;2;0;0.2883575;0.2879426;66807.13;7543846