File: Ensayos/Resistencia/comp/EspD/RED1.raw
"Test Type";"Manual"
"Method Name:";"C:\INSTRON\USER\TEMPLATE\CYCLE.MTM"
"Name:";""
"Operator ID:";""
"Company:";""
"Lab name:";""
"Test date:";"23/06/2017"
"Temperature:";""
"Humidity:";""
"Note 1:";""
"Note 2:";""
"Note 3:";""
"Geometry:";"Rectangular"
"Specimen";1
"Specimen name:";""
"Width:";0.250000;"in"
"Thickness:";0.060000;"in"
"Length:";1.250000;"in"
"Diameter:";0.039370;"in"
"Inner diameter:";0.019685;"in"
"Outer diameter:";0.039370;"in"
"Wall thickness:";0.019685;"in"
"Area:";0.015000;"in*in"
"Linear density:";1.000000;"den"
"Sled weight:";2.204623;"lbf"
"Loading span:";0.000000;"mm"
"Support span:";1.000000;"mm"
"Span ratio:";"2"
"Fixture type:";"3-point"
"Comment:";""
"Included"
"Final Width:";0.250000;"in"
"Final Thickness:";0.060000;"in"
"Final Length:";1.250000;"in"
"Final Diameter:";0.039370;"in"
"Final Inner diameter:";0.019685;"in"
"Final Outer diameter:";0.039370;"in"
"Final Wall thickness:";0.019685;"in"
"Final Area:";0.015000;"in*in"
"Final Linear density:";1.000000;"den"
"Time sec";"Extension mm";"Strain 1 %";"Load N";"Stress MPa";"Cycle Count ";"Total Cycle Count ";"Repetitions Count ";"Strain [Exten.] %";"True strain %";"Tenacity gf/tex";"True stress Pa"
0;0;0.0003921939;0.205203;0.02120435;0;0;0;0;0;188.3239;21204.35
8;0.0001071428;0.0005281321;0.3668249;0.03790532;0;0;0;0.0003374576;0.000337457;336.6516;37905.45
16;0.000267857;0.0006459025;0.3677353;0.03799939;0;0;0;0.000843644;0.0008436404;337.4871;37999.71
24;0.0004285712;0.0007674308;0.5645651;0.0583385;0;0;0;0.00134983;0.001349821;518.1265;58339.29
32;0.0005357139;0.0002788077;0.4628466;0.04782758;0;0;0;0.001687288;0.001687274;424.775;47828.39
40;0.0006428567;0.0005375268;0.2873941;0.02969745;0;0;0;0.002024746;0.002024725;263.7544;29698.05
48;0.0008571423;0.0006772229;0.5753419;0.05945212;0;0;0;0.002699661;0.002699624;528.0169;59453.72
56;0.0009642851;0.001090048;0.6719509;0.06943506;0;0;0;0.003037118;0.003037072;616.6793;69437.17
64;0.001071428;0.001249791;0.4645792;0.04800661;0;0;0;0.003374576;0.003374519;426.3651;48008.23
72;0.001178571;0.001428954;0.6188599;0.06394899;0;0;0;0.003712033;0.003711965;567.9553;63951.36
80;0.001285713;0.001442735;0.5842393;0.06037151;0;0;0;0.004049491;0.004049409;536.1824;60373.96
88.00001;0.001499999;0.001906301;0.7568435;0.07820732;0;0;0;0.004724406;0.004724294;694.5891;78211.01
96.00001;0.001607142;0.00171649;0.4880707;0.05043407;0;0;0;0.005061864;0.005061736;447.9242;50436.63
104;0.001714285;0.001829248;0.4475184;0.04624366;0;0;0;0.005399322;0.005399176;410.7076;46246.16
112;0.001821427;0.001741548;0.5147043;0.05318622;0;0;0;0.005736779;0.005736615;472.3671;53189.27
120;0.001982142;0.001540459;0.6979678;0.07212349;0;0;0;0.006242966;0.006242771;640.5562;72127.99
128;0.002089284;0.001618138;0.7312083;0.07555834;0;0;0;0.006580424;0.006580207;671.0625;75563.32
136;0.002249999;0.001607488;0.6380643;0.06593344;0;0;0;0.007086609;0.007086358;585.5801;65938.12
144;0.002357141;0.001348143;0.4344219;0.04489036;0;0;0;0.007424067;0.007423791;398.6884;44893.69
152;0.002517856;0.001272969;0.3290329;0.03400014;0;0;0;0.007930254;0.00792994;301.9682;34002.83
160;0.002624998;0.001632546;0.5048672;0.05216972;0;0;0;0.008267712;0.00826737;463.3392;52174.03
168;0.002785712;0.00170772;0.7304155;0.07547642;0;0;0;0.008773897;0.008773512;670.3349;75483.04
176;0.002892855;0.001628161;0.6015936;0.0621648;0;0;0;0.009111355;0.00911094;552.1093;62170.46
184;0.003053569;0.001757208;0.6804666;0.07031502;0;0;0;0.009617541;0.009617079;624.4945;70321.78
192;0.003214284;0.001564263;0.4241443;0.04382833;0;0;0;0.01012373;0.01012322;389.2561;43832.77
200;0.003321426;0.001700828;0.3924895;0.04055733;0;0;0;0.01046119;0.01046064;360.2051;40561.57
208;0.003428569;0.001757834;0.6333366;0.06544492;0;0;0;0.01079864;0.01079806;581.2413;65451.98
216;0.003642855;0.001791662;0.4943841;0.05108646;0;0;0;0.01147356;0.0114729;453.7183;51092.32
224;0.003749998;0.001245406;0.4621419;0.04775476;0;0;0;0.01181102;0.01181032;424.1282;47760.4
232;0.00385714;0.001553614;0.6653439;0.06875234;0;0;0;0.01214847;0.01214774;610.6158;68760.69
240;0.003964283;0.001856813;0.6690732;0.0691377;0;0;0;0.01248593;0.01248515;614.0383;69146.33
248;0.004071426;0.001719622;0.352407;0.03641546;0;0;0;0.01282339;0.01282257;323.4196;36420.13
256;0.004285712;0.001763473;0.6432912;0.06647356;0;0;0;0.0134983;0.01349739;590.377;66482.53
264;0.004392855;0.002620444;0.518551;0.05358371;0;0;0;0.01383576;0.01383481;475.8974;53591.13
272;0.004499997;0.003128487;0.5577819;0.05763758;0;0;0;0.01417322;0.01417221;511.9013;57645.75
280;0.004714283;0.002775174;0.4214134;0.04354614;0;0;0;0.01484813;0.01484703;386.7498;43552.6
288;0.004821425;0.002721301;0.529827;0.0547489;0;0;0;0.01518559;0.01518444;486.2458;54757.21
296;0.004928568;0.003551962;0.6079657;0.06282325;0;0;0;0.01552305;0.01552184;557.9573;62833
304;0.005035711;0.004081305;0.5926376;0.06123934;0;0;0;0.01586051;0.01585925;543.8899;61249.05
312;0.005249997;0.005280313;0.3688217;0.03811166;0;0;0;0.01653542;0.01653406;338.4842;38117.96
320;0.005357139;0.005489544;0.4023266;0.04157383;0;0;0;0.01687288;0.01687146;369.233;41580.84
328;0.005464282;0.005874177;0.5920503;0.06117865;0;0;0;0.01721034;0.01720886;543.351;61189.18
336;0.005571425;0.006713609;0.49873;0.05153554;0;0;0;0.01754779;0.01754625;457.7068;51544.58
344;0.005678568;0.00717279;0.7052208;0.07287296;0;0;0;0.01788525;0.01788365;647.2126;72886
352;0.005892853;0.006830127;0.4884818;0.05047655;0;0;0;0.01856017;0.01855845;448.3015;50485.92
360;0.005999996;0.006897782;0.5482385;0.05665142;0;0;0;0.01889762;0.01889584;503.1429;56662.13
368;0.006107139;0.008113079;0.2005047;0.02071886;0;0;0;0.01923508;0.01923323;184.0121;20722.85
376;0.006214282;0.008455741;0.47979;0.04957839;0;0;0;0.01957254;0.01957063;440.3246;49588.1
384;0.006428567;0.009241926;0.6025333;0.0622619;0;0;0;0.02024746;0.02024541;552.9717;62274.51
392;0.00653571;0.01094522;0.5937828;0.06135767;0;0;0;0.02058491;0.0205828;544.9409;61370.3
400;0.006642853;0.01383311;0.5360816;0.05539522;0;0;0;0.02092237;0.02092018;491.986;55406.8
408;0.006749996;0.01364142;0.7066891;0.07302468;0;0;0;0.02125983;0.02125757;648.5601;73040.21
416;0.006964281;0.01734807;0.4811995;0.04972405;0;0;0;0.02193474;0.02193234;441.6182;49734.95
424;0.007071424;0.01680432;0.454742;0.0469901;0;0;0;0.0222722;0.02226972;417.337;47000.57
432;0.007178567;0.01767194;0.5164074;0.05336221;0;0;0;0.02260966;0.0226071;473.9301;53374.27
440;0.007392853;0.01901065;0.4961166;0.05126548;0;0;0;0.02328457;0.02328186;455.3083;51277.42
448;0.007392853;0.02160912;0.5542581;0.05727345;0;0;0;0.02328457;0.02328186;508.6674;57286.79
456;0.007607138;0.02454588;0.3342304;0.03453721;0;0;0;0.02395949;0.02395662;306.7381;34545.48
464;0.007714281;0.02893222;0.6767373;0.06992966;0;0;0;0.02429695;0.024294;621.072;69946.65
472;0.007821424;0.02835589;0.6263185;0.06471971;0;0;0;0.02463441;0.02463137;574.8004;64735.65
480;0.008035709;0.03081655;0.5818608;0.06012574;0;0;0;0.02530932;0.02530612;533.9996;60140.95
488;0.008142852;0.03238516;0.6173331;0.06379121;0;0;0;0.02564678;0.02564349;566.5541;63807.57
496;0.008249995;0.03620144;0.5003157;0.05169939;0;0;0;0.02598424;0.02598086;459.162;51712.83
504;0.008357138;0.03686923;0.0747955;0.007728884;0;0;0;0.02632169;0.02631823;68.64317;7730.918
512;0.008571423;0.0418582;0.2476052;0.02558593;0;0;0;0.02699661;0.02699296;227.2384;25592.83
520;0.008678566;0.04252599;0.5215756;0.05389625;0;0;0;0.02733407;0.02733033;478.6732;53910.99
528;0.008785709;0.0411497;0.6515426;0.0673262;0;0;0;0.02767153;0.0276677;597.9497;67344.83
536;0.008892851;0.04661852;0.5412497;0.05592925;0;0;0;0.02800898;0.02800506;496.729;55944.91
544;0.009107137;0.04679393;0.5817433;0.06011359;0;0;0;0.0286839;0.02867978;533.8917;60130.83
552;0.00921428;0.04269011;0.5462416;0.05644508;0;0;0;0.02902135;0.02901714;501.3103;56461.46
560;0.009321422;0.05353882;0.6650209;0.06871896;0;0;0;0.02935881;0.0293545;610.3193;68739.13
568;0.009428565;0.05810996;0.7707623;0.0796456;0;0;0;0.02969627;0.02969186;707.3629;79669.25
576;0.009535708;0.06089511;0.6220313;0.0642767;0;0;0;0.03003373;0.03002922;570.8658;64296
584;0.009749994;0.06414321;0.502753;0.05195125;0;0;0;0.03070864;0.03070393;461.3988;51967.2
592;0.009857137;0.06716892;0.4678387;0.04834342;0;0;0;0.0310461;0.03104128;429.3564;48358.43
600;0.00996428;0.0810972;0.6012413;0.06212839;0;0;0;0.03138356;0.03137863;551.786;62147.89
608;0.01017856;0.08418431;0.5914335;0.06111492;0;0;0;0.03205847;0.03205333;542.7849;61134.51
616;0.01028571;0.09602905;0.5003744;0.05170546;0;0;0;0.03239593;0.03239068;459.2159;51722.21
624;0.01039285;0.091441;0.5418076;0.0559869;0;0;0;0.03273339;0.03272803;497.241;56005.23
632;0.01049999;0.08891331;0.7818621;0.08079258;0;0;0;0.03307085;0.03306538;717.5497;80819.29
640;0.01060714;0.08828185;0.5421601;0.05602332;0;0;0;0.0334083;0.03340272;497.5645;56042.03
648.0001;0.01082142;0.09746674;0.7413684;0.07660823;0;0;0;0.03408322;0.03407741;680.3868;76634.33
656.0001;0.01092856;0.1044108;0.5868527;0.06064157;0;0;0;0.03442068;0.03441475;538.5809;60662.44
664.0001;0.01103571;0.1126999;0.5340848;0.05518888;0;0;0;0.03475814;0.03475209;490.1535;55208.06
672.0001;0.01124999;0.112797;0.6940329;0.07171688;0;0;0;0.03543305;0.03542677;636.9449;71742.29
680.0001;0.01135714;0.1213742;0.489862;0.05061917;0;0;0;0.03577051;0.03576411;449.5682;50637.28
688.0001;0.01146428;0.1255382;0.8110797;0.08381173;0;0;0;0.03610796;0.03610145;744.364;83842
696.0001;0.01157142;0.1261302;0.8489891;0.08772905;0;0;0;0.03644542;0.03643878;779.1552;87761.02
704.0001;0.01167856;0.1304839;0.6309581;0.06519914;0;0;0;0.03678288;0.03677611;579.0584;65223.12
712.0001;0.01189285;0.1267716;0.659148;0.06811209;0;0;0;0.03745779;0.03745078;604.9294;68137.6
720.0001;0.01199999;0.1308354;0.8539811;0.08824489;0;0;0;0.03779525;0.03778811;783.7366;88278.25
728.0001;0.01210713;0.1314449;0.5859718;0.06055054;0;0;0;0.0381327;0.03812543;537.7724;60573.63
736.0001;0.01221428;0.1275616;0.6506617;0.06723518;0;0;0;0.03847016;0.03846277;597.1413;67261.04
744.0001;0.01242856;0.1311429;0.962747;0.09948406;0;0;0;0.03914508;0.03913742;883.5559;99523
752.0001;0.01253571;0.1329408;1.14557;0.1183758;0;0;0;0.03948254;0.03947475;1051.341;118422.6
760.0001;0.01264285;0.1330586;0.6026801;0.06227707;0;0;0;0.03982;0.03981207;553.1064;62301.87
768.0001;0.01274999;0.1329421;0.6983789;0.07216596;0;0;0;0.04015746;0.0401494;640.9334;72194.94
776.0001;0.01296428;0.1336243;0.8513971;0.08797787;0;0;0;0.04083237;0.04082404;781.3651;88013.79
784.0001;0.01307142;0.1346028;0.8835218;0.09129743;0;0;0;0.04116983;0.04116136;810.8474;91335.02
792.0001;0.01317856;0.1349555;0.7448041;0.07696325;0;0;0;0.04150729;0.04149867;683.54;76995.19
800.0001;0.01339285;0.1346053;0.7849159;0.08110814;0;0;0;0.0421822;0.04217331;720.3523;81142.35
808.0001;0.01339285;0.1361714;0.7749908;0.08008254;0;0;0;0.0421822;0.04217331;711.2436;80116.32
816.0001;0.01360713;0.1372871;0.9671517;0.0999392;0;0;0;0.04285712;0.04284794;887.5982;99982.04
824.0001;0.01371428;0.1351785;0.8786178;0.09079069;0;0;0;0.04319457;0.04318525;806.3467;90829.91
832.0001;0.01382142;0.1372094;0.7504714;0.07754887;0;0;0;0.04353203;0.04352256;688.7411;77582.63
840.0001;0.01403571;0.1376016;0.829961;0.08576281;0;0;0;0.04420695;0.04419718;761.6922;85800.72
848.0001;0.01414285;0.1421514;0.8001855;0.082686;0;0;0;0.0445444;0.04453448;734.3659;82722.83
856.0001;0.01424999;0.1395586;0.7998624;0.08265261;0;0;0;0.04488186;0.04487179;734.0694;82689.71
864.0001;0.01435713;0.139422;0.8328093;0.08605713;0;0;0;0.04521932;0.0452091;764.3062;86096.05
872.0001;0.01446428;0.1379799;0.641911;0.06633094;0;0;0;0.04555678;0.0455464;589.1104;66361.16
880.0001;0.01467856;0.1375446;0.7788669;0.08048307;0;0;0;0.04623169;0.04622101;714.8008;80520.28
888.0001;0.01478571;0.1365272;0.7792193;0.08051948;0;0;0;0.04656915;0.04655831;715.1243;80556.98
896.0001;0.01489285;0.1356527;0.7530261;0.07781286;0;0;0;0.04690661;0.04689561;691.0857;77849.36
904.0001;0.01510713;0.1347801;0.6737127;0.06961712;0;0;0;0.04758152;0.04757021;618.2962;69650.24
912.0001;0.01521428;0.1337508;1.029228;0.1063538;0;0;0;0.04791898;0.0479075;944.5685;106404.7
920.0001;0.01532142;0.1335911;1.001361;0.1034742;0;0;0;0.04825644;0.0482448;918.9939;103524.1
928.0001;0.01542856;0.1334764;0.7611307;0.07865033;0;0;0;0.04859389;0.04858209;698.5236;78688.55
936.0001;0.0155357;0.133105;1.103432;0.1140215;0;0;0;0.04893135;0.04891938;1012.669;114077.3
944.0001;0.01574999;0.1321929;1.152588;0.119101;0;0;0;0.04960626;0.04959397;1057.782;119160.1
952.0001;0.01585713;0.1323401;1.030226;0.106457;0;0;0;0.04994373;0.04993126;945.4848;106510.1
960.0001;0.01596428;0.1311455;0.90578;0.09359746;0;0;0;0.05028118;0.05026855;831.2747;93644.52
968.0001;0.01617856;0.1309594;0.8480789;0.087635;0;0;0;0.0509561;0.05094312;778.3198;87679.65
976.0001;0.0162857;0.1307057;1.025411;0.1059593;0;0;0;0.05129355;0.0512804;941.0651;106013.7
984.0001;0.01639285;0.1304589;0.8567707;0.08853316;0;0;0;0.05163101;0.05161768;786.2967;88578.86
992.0001;0.01649999;0.1298262;1.110949;0.1147983;0;0;0;0.05196847;0.05195497;1019.568;114858
1000;0.01660713;0.1291402;0.8181565;0.084543;0;0;0;0.05230593;0.05229225;750.8587;84587.23
1008;0.01682142;0.1292743;1.120875;0.1158239;0;0;0;0.05298084;0.05296681;1028.677;115885.3
1016;0.01692856;0.1279775;1.009759;0.104342;0;0;0;0.0533183;0.05330409;926.7013;104397.7
1024;0.0170357;0.1280634;0.9098029;0.09401315;0;0;0;0.05365576;0.05364137;834.9667;94063.6
1032;0.01724999;0.1268293;0.6363612;0.06575745;0;0;0;0.05433067;0.05431592;584.017;65793.18
1040;0.01735713;0.1273286;1.009495;0.1043147;0;0;0;0.05466813;0.0546532;926.4588;104371.7
1048;0.01746427;0.1263093;1.054335;0.1089481;0;0;0;0.05500559;0.05499047;967.61;109008.1
1056;0.01757142;0.1259736;0.9235161;0.09543019;0;0;0;0.05534305;0.05532774;847.5519;95483
1064;0.01767856;0.1253446;0.9724373;0.1004854;0;0;0;0.05568051;0.05566501;892.4491;100541.3
1072;0.01789285;0.1249694;0.9506782;0.09823694;0;0;0;0.05635542;0.05633955;872.4797;98292.3
1080;0.01799999;0.1247107;0.8933882;0.09231696;0;0;0;0.05669288;0.05667681;819.9022;92369.3
1088;0.01810713;0.1245616;0.6634352;0.0685551;0;0;0;0.05703034;0.05701408;608.864;68594.2
1096;0.01821427;0.1234396;0.9357611;0.09669551;0;0;0;0.05736779;0.05735134;858.7897;96750.98
1104;0.01842856;0.1232893;0.7585466;0.07838331;0;0;0;0.05804271;0.05802587;696.152;78428.8
1112;0.0185357;0.1229616;0.9092743;0.09395853;0;0;0;0.05838016;0.05836313;834.4816;94013.39
1120;0.01864284;0.122488;1.036951;0.1071518;0;0;0;0.05871762;0.05870039;951.6562;107214.7
1128;0.01874999;0.1218271;1.259328;0.1301308;0;0;0;0.05905508;0.05903765;1155.741;130207.7
1136;0.01896427;0.121378;1.084962;0.1121129;0;0;0;0.05973;0.05971217;995.7178;112179.9
1144;0.01907142;0.1209896;1.084756;0.1120917;0;0;0;0.06006745;0.06004942;995.5292;112159
1152;0.01917856;0.1203663;0.5019307;0.05186628;0;0;0;0.06040491;0.06038667;460.6442;51897.61
1160;0.0192857;0.1204797;0.7442462;0.07690559;0;0;0;0.06074237;0.06072392;683.028;76952.31
1168;0.01949999;0.1197737;1.014282;0.1048093;0;0;0;0.06141728;0.06139843;930.8515;104873.7
1176;0.01960713;0.1190564;1.008908;0.104254;0;0;0;0.06175474;0.06173568;925.9198;104318.4
1184;0.01971427;0.1189386;1.022122;0.1056195;0;0;0;0.0620922;0.06207293;938.0469;105685.1
1192;0.01982142;0.1185809;0.9034896;0.09336078;0;0;0;0.06242966;0.06241018;829.1727;93419.06
1200;0.0200357;0.1180159;0.9221653;0.09529061;0;0;0;0.06310457;0.06308466;846.3122;95350.74
1208;0.02014285;0.118029;0.9475068;0.09790923;0;0;0;0.06344203;0.06342192;869.5693;97971.35
1216;0.02024999;0.1175285;1.065053;0.1100557;0;0;0;0.06377948;0.06375915;977.4464;110125.9
1224;0.02046427;0.1176175;1.000128;0.1033468;0;0;0;0.0644544;0.06443364;917.862;103413.4
1232;0.02046427;0.1164986;1.055597;0.1090786;0;0;0;0.0644544;0.06443364;968.7687;109148.9
1240;0.02067856;0.1162499;1.088397;0.112468;0;0;0;0.06512932;0.06510812;998.8708;112541.2
1248;0.0207857;0.1153078;1.037274;0.1071852;0;0;0;0.06546678;0.06544535;951.9526;107255.4
1256;0.02089284;0.1140399;1.118848;0.1156146;0;0;0;0.06580423;0.06578258;1026.817;115690.6
1264;0.02110713;0.1134717;0.9811879;0.1013896;0;0;0;0.06647915;0.06645706;900.4799;101457
1272;0.02121427;0.1134178;0.7801295;0.08061354;0;0;0;0.06681661;0.0667943;715.9596;80667.4
1280;0.02132141;0.1126886;0.4969095;0.05134741;0;0;0;0.06715406;0.06713152;456.0359;51381.89
1288;0.02142856;0.1131603;0.4283434;0.04426224;0;0;0;0.06749152;0.06746875;393.1098;44292.11
1296;0.0215357;0.1114232;0.1329665;0.01373989;0;0;0;0.06782898;0.06780598;122.0292;13749.21
1304;0.02174999;0.1088172;-0.1018611;-0.01052567;0;0;0;0.06850389;0.06848044;-93.48245;-10532.88
1312;0.02185713;0.1087414;0.2581765;0.02667829;0;0;0;0.06884135;0.06881767;236.9401;26696.66
1320;0.02196427;0.1079515;0.05838072;0.006032686;0;0;0;0.06917881;0.06915489;53.57859;6036.86
1328;0.02217856;0.1066228;-0.04800659;-0.004960691;0;0;0;0.06985372;0.06982934;-44.05779;-4964.156
1336;0.0222857;0.1065326;0.2435824;0.02517023;0;0;0;0.07019117;0.07016655;223.5464;25187.9
1344;0.02239284;0.1055353;0.02898698;0.002995327;0;0;0;0.07052864;0.07050378;26.60264;2997.44
1352;0.02249998;0.1056261;-0.2467159;-0.02549402;0;0;0;0.07086609;0.070841;-226.4221;-25512.09
1360;0.02260713;0.1043532;-0.006749615;-0.0006974616;0;0;0;0.07120355;0.07117821;-6.194423;-697.9582
1368;0.02282141;0.1038483;-0.05126603;-0.005297501;0;0;0;0.07187847;0.07185265;-47.04913;-5301.308
1376;0.02292856;0.1011872;0.1101797;0.01138526;0;0;0;0.07221593;0.07218986;101.1168;11393.48
1384;0.0230357;0.1014352;0.178863;0.01848255;0;0;0;0.07255339;0.07252708;164.1506;18495.96
1392;0.02324999;0.1004091;0.02528704;0.002613;0;0;0;0.0732283;0.0732015;23.20705;2614.913
1400;0.02335713;0.100458;0.2116925;0.02187493;0;0;0;0.07356575;0.07353871;194.2796;21891.03
1408;0.02346427;0.09970752;-0.105238;-0.01087461;0;0;0;0.07390321;0.07387592;-96.58157;-10882.65
1416;0.02357141;0.09907544;0.06102353;0.006305777;0;0;0;0.07424067;0.07421313;56.00401;6310.459
1424;0.02367856;0.09830805;0.1652967;0.01708069;0;0;0;0.07457813;0.07455033;151.7001;17093.43
1432;0.02389284;0.09671876;0.01119213;0.001156523;0;0;0;0.07525305;0.07522474;10.27152;1157.393
1440;0.02399998;0.09690106;-0.07008864;-0.007242508;0;0;0;0.0755905;0.07556194;-64.32347;-7247.982
1448;0.02410713;0.1000026;0.4906254;0.05069806;0;0;0;0.07592797;0.07589915;450.2688;50736.56
1456;0.02432141;0.0990272;0.02329023;0.002406662;0;0;0;0.07660288;0.07657355;21.37448;2408.506
1464;0.02442855;0.0997307;0.1071551;0.01107272;0;0;0;0.07694033;0.07691075;98.34101;11081.24
1472;0.0245357;0.1050648;-0.2574633;-0.02660459;0;0;0;0.07727779;0.07724794;-236.2855;-26625.15
1480;0.02464284;0.1082302;-0.009216164;-0.0009523389;0;0;0;0.07761525;0.07758514;-8.458085;-953.0781
1488;0.02485713;0.1204189;-0.05273429;-0.005449221;0;0;0;0.07829016;0.07825953;-48.39661;-5453.487
1496;0.02485713;0.1357454;-0.08559309;-0.008844637;0;0;0;0.07829016;0.07825953;-78.5526;-8851.562
1504;0.02507141;0.1544641;-0.0751394;-0.00776442;0;0;0;0.07896508;0.07893392;-68.95878;-7770.551
1512;0.02517856;0.1614451;0.03609315;0.003729633;0;0;0;0.07930254;0.07927112;33.12429;3732.591
1520;0.0252857;0.1627795;0.06269729;0.006478733;0;0;0;0.07963999;0.0796083;57.5401;6483.893
1528;0.02549998;0.1599511;0.07949384;0.00821438;0;0;0;0.08031491;0.08028268;72.95504;8220.977
1536;0.02560713;0.1500527;0.2594391;0.02680876;0;0;0;0.08065236;0.08061986;238.0988;26830.38
1544;0.02571427;0.1350958;0.02314344;0.002391493;0;0;0;0.08098982;0.08095704;21.23977;2393.43
1552;0.02582141;0.1194987;0.02848778;0.002943743;0;0;0;0.08132728;0.08129423;26.1445;2946.137
1560;0.0260357;0.1067706;-0.0215786;-0.002229793;0;0;0;0.0820022;0.08196859;-19.80364;-2231.621
1568;0.02614284;0.1007023;0.4884231;0.05047049;0;0;0;0.08233966;0.08230578;448.2477;50512.05
1576;0.02624998;0.09112402;-0.07916227;-0.008180118;0;0;0;0.08267711;0.08264296;-72.65075;-8186.881
1584;0.02635713;0.08172427;0.1904033;0.01967505;0;0;0;0.08301457;0.08298013;174.7416;19691.38
1592;0.02646427;0.07058616;0.1010767;0.01044461;0;0;0;0.08335202;0.08331731;92.76259;10453.32
1600;0.02667855;0.06708686;0.1431853;0.01479584;0;0;0;0.08402694;0.08399166;131.4075;14808.27
1608;0.0267857;0.06178216;0.1418933;0.01466234;0;0;0;0.0843644;0.08432883;130.2218;14674.71
1616;0.02689284;0.05787442;0.04372789;0.004518557;0;0;0;0.08470186;0.08466601;40.13103;4522.385
1624;0.02710713;0.05416275;0.02003078;0.002069852;0;0;0;0.08537678;0.08534035;18.38314;2071.619
1632;0.02721427;0.05185682;0.02249744;0.00232474;0;0;0;0.08571424;0.08567752;20.64691;2326.733
1640;0.02732141;0.05043793;0.04014539;0.004148365;0;0;0;0.08605169;0.08601469;36.84321;4151.935
1648;0.02742855;0.04680834;-0.06283568;-0.006493033;0;0;0;0.08638915;0.08635186;-57.66711;-6498.642
1656;0.0275357;0.04628087;0.06431233;0.006645621;0;0;0;0.08672661;0.08668902;59.0223;6651.385
1664;0.02774998;0.04135517;-0.158828;-0.01641226;0;0;0;0.08740152;0.08736335;-145.7635;-16426.6
1672;0.02785712;0.03953786;-0.004194881;-0.0004334719;0;0;0;0.08773898;0.08770051;-3.849829;-433.8522
1680;0.02796427;0.03848231;-0.04765428;-0.004924286;0;0;0;0.08807644;0.08803767;-43.73446;-4928.623
1688;0.02817855;0.03438351;-0.03238471;-0.003346426;0;0;0;0.08875135;0.08871199;-29.72089;-3349.396
1696;0.0282857;0.03482953;0.4567095;0.04719341;0;0;0;0.08908881;0.08904914;419.1427;47235.45
1704;0.02839284;0.03242964;0.3007256;0.03107504;0;0;0;0.08942626;0.08938631;275.9893;31102.82
1712;0.02849998;0.0317819;0.3201354;0.03308073;0;0;0;0.08976372;0.08972345;293.8026;33110.42
1720;0.02860713;0.02988002;0.275061;0.02842303;0;0;0;0.09010118;0.09006062;252.4357;28448.64
1728;0.02882141;0.02721264;0.03374404;0.003486891;0;0;0;0.09077609;0.09073492;30.96841;3490.056
1736;0.02892855;0.02716315;0.3934878;0.04066049;0;0;0;0.09111355;0.09107207;361.1213;40697.53
1744;0.0290357;0.02196243;0.2350079;0.0242842;0;0;0;0.09145101;0.09140922;215.6773;24306.41
1752;0.02924998;0.02218357;0.4851343;0.05013064;0;0;0;0.09212593;0.09208352;445.2294;50176.83
1760;0.02935712;0.01816746;0.48302;0.04991217;0;0;0;0.09246338;0.09242066;443.289;49958.32
1768;0.02946427;0.01538418;0.2190924;0.02263959;0;0;0;0.09280084;0.09275781;201.0708;22660.6
1776;0.02957141;0.01387132;0.5618342;0.05805631;0;0;0;0.0931383;0.09309495;515.6202;58110.39
1784;0.02967855;0.01256895;0.3506158;0.03623037;0;0;0;0.09347575;0.09343209;321.7757;36264.24
1792;0.02989284;0.00739455;0.301489;0.03115392;0;0;0;0.09415067;0.09410638;276.6899;31183.26
1800;0.02999998;0.007801112;0.5878805;0.06074777;0;0;0;0.09448814;0.09444352;539.5242;60805.17
1808;0.03010712;0.005832834;0.6195354;0.06401879;0;0;0;0.09482559;0.09478066;568.5753;64079.49
1816;0.03032141;0.001191532;0.5302675;0.05479441;0;0;0;0.09550051;0.09545493;486.6501;54846.74
1824;0.03032141;0.002357338;0.3878499;0.0400779;0;0;0;0.09550051;0.09545493;355.9471;40116.17
1832;0.03053569;-0.00026369;0.4060265;0.04195615;0;0;0;0.0961754;0.09612919;372.6286;41996.51
1840;0.03064284;-0.001788447;0.5628326;0.05815948;0;0;0;0.09651288;0.09646633;516.5366;58215.61
1848;0.03074998;-0.006359587;0.3043374;0.03144826;0;0;0;0.09685033;0.09680346;279.304;31478.72
1856;0.03096426;-0.01136172;0.4978785;0.05144755;0;0;0;0.09752524;0.09747771;456.9253;51497.72
1864;0.03107141;-0.0127117;0.4800542;0.0496057;0;0;0;0.0978627;0.09781484;440.5671;49654.24
1872;0.03117855;-0.01330243;0.3960719;0.04092751;0;0;0;0.09820016;0.09815198;363.4928;40967.7
1880;0.03139284;-0.01515419;0.5166716;0.05338951;0;0;0;0.09887508;0.09882623;474.1726;53442.3
1888;0.03139284;-0.01892474;0.362479;0.03745624;0;0;0;0.09887508;0.09882623;332.6631;37493.27
1896;0.03160712;-0.02120123;0.6819936;0.07047281;0;0;0;0.09954999;0.09950047;625.8959;70542.96
1904;0.03171427;-0.02240963;0.3585441;0.03704963;0;0;0;0.09988745;0.0998376;329.0519;37086.64
1912;0.03182141;-0.02460218;0.6669883;0.06892227;0;0;0;0.1002249;0.1001747;612.1249;68991.34
1920;0.03192855;-0.02489159;0.6163053;0.06368501;0;0;0;0.1005624;0.1005118;565.6108;63749.05
1928;0.03214283;-0.02921717;0.6255551;0.06464082;0;0;0;0.1012373;0.1011861;574.0998;64706.26
1936;0.03224998;-0.03181;0.4145128;0.04283308;0;0;0;0.1015747;0.1015232;380.4169;42876.59
1944;0.03235712;-0.03273463;0.6912727;0.07143165;0;0;0;0.1019122;0.1018603;634.4117;71504.45
1952;0.03251783;-0.03708714;0.492681;0.05091047;0;0;0;0.1024184;0.102366;452.1553;50962.61
1960;0.03262498;-0.03173671;0.8874566;0.09170403;0;0;0;0.1027558;0.1027031;814.4585;91798.26
1968;0.03278569;-0.03493156;0.2141592;0.02212982;0;0;0;0.103262;0.1032087;196.5434;22152.68
1976;0.03289284;-0.03446424;0.3617742;0.03738341;0;0;0;0.1035995;0.1035459;332.0163;37422.14
1984;0.03305355;-0.03901282;0.201415;0.02081292;0;0;0;0.1041057;0.1040515;184.8475;20834.59
1992;0.03316069;-0.04222396;0.4309862;0.04453533;0;0;0;0.1044431;0.1043886;395.5353;44581.85
2000;0.03332141;-0.04635033;0.2952344;0.03050762;0;0;0;0.1049493;0.1048943;270.9498;30539.64
2008;0.03342855;-0.04950884;0.553201;0.05716422;0;0;0;0.1052868;0.1052314;507.6972;57224.41
2016;0.03358926;-0.05176153;0.479232;0.04952074;0;0;0;0.105793;0.105737;439.8126;49573.13
2024;0.03369641;-0.05125223;0.4371235;0.04516951;0;0;0;0.1061304;0.1060741;401.1677;45217.45
2032;0.03391069;-0.05250198;0.3176394;0.03282281;0;0;0;0.1068053;0.1067483;291.5119;32857.86
2040;0.03401783;-0.05547068;0.4306338;0.04449892;0;0;0;0.1071428;0.1070854;395.2119;44546.59
2048;0.03412498;-0.05685261;0.3821238;0.0394862;0;0;0;0.1074802;0.1074225;350.692;39528.64
2056;0.03433926;-0.05802969;0.3182267;0.03288349;0;0;0;0.1081552;0.1080967;292.0508;32919.06
2064;0.03433926;-0.05869309;0.7124444;0.0736194;0;0;0;0.1081552;0.1080967;653.842;73699.03
2072;0.03455355;-0.05886537;0.4595285;0.0474847;0;0;0;0.1088301;0.1087709;421.7298;47536.38
2080;0.03466069;-0.06011073;0.5113861;0.05284334;0;0;0;0.1091675;0.109108;469.3219;52901.03
2088;0.03476783;-0.06140684;0.2264042;0.02339514;0;0;0;0.109505;0.1094451;207.7812;23420.76
2096;0.03492855;-0.05993157;0.5858837;0.06054144;0;0;0;0.1100112;0.1099507;537.6916;60608.04
2104;0.03503569;-0.06100968;0.3112381;0.03216133;0;0;0;0.1103486;0.1102878;285.6371;32196.82
2112;0.03524998;-0.06058307;0.3054826;0.0315666;0;0;0;0.1110236;0.110962;280.355;31601.65
2120;0.03535712;-0.06233084;0.3560482;0.03679172;0;0;0;0.111361;0.111299;326.7613;36832.69
2128;0.03546426;-0.06178709;0.3099166;0.03202478;0;0;0;0.1116985;0.1116361;284.4243;32060.55
2136;0.0355714;-0.06135923;0.5941939;0.06140016;0;0;0;0.1120359;0.1119732;545.3182;61468.95
2144;0.03567855;-0.0614131;0.3034564;0.03135723;0;0;0;0.1123734;0.1123103;278.4955;31392.46
2152;0.03589283;-0.06147888;0.5316769;0.05494006;0;0;0;0.1130483;0.1129844;487.9436;55002.16
2160;0.03599998;-0.06131914;0.4453748;0.04602216;0;0;0;0.1133858;0.1133215;408.7403;46074.34
2168;0.03610712;-0.06059372;0.7745209;0.08003399;0;0;0;0.1137232;0.1136586;710.8124;80125.01
2176;0.03621426;-0.06034565;0.332674;0.03437639;0;0;0;0.1140607;0.1139957;305.3098;34415.59
2184;0.03642855;-0.05988646;0.5950454;0.06148815;0;0;0;0.1147356;0.1146698;546.0997;61558.69
2192;0.03653569;-0.05932705;-0.3222705;-0.03330135;0;0;0;0.115073;0.1150069;-295.7621;-33339.68
2200;0.03664283;-0.05864611;0.4014162;0.04147976;0;0;0;0.1154105;0.1153439;368.3976;41527.63
2208;0.03674998;-0.0578048;0.4877771;0.05040374;0;0;0;0.115748;0.115681;447.6548;50462.08
2216;0.03696426;-0.05751163;0.2991986;0.03091725;0;0;0;0.1164229;0.1163552;274.5879;30953.24
2224;0.0370714;-0.05658951;0.4102256;0.04239007;0;0;0;0.1167603;0.1166922;376.4823;42439.56
2232;0.03717855;-0.0552057;0.4713917;0.04871057;0;0;0;0.1170978;0.1170293;432.6172;48767.61
2240;0.03739284;-0.05437128;0.3330852;0.03441887;0;0;0;0.1177727;0.1177034;305.6871;34459.4
2248;0.03739284;-0.05340218;0.5069227;0.05238211;0;0;0;0.1177727;0.1177034;465.2255;52443.8
2256;0.03760712;-0.05360201;0.4510715;0.04661081;0;0;0;0.1184476;0.1183775;413.9684;46666.02
2264;0.03771426;-0.05259532;0.544333;0.05624786;0;0;0;0.1187851;0.1187146;499.5587;56314.67
2272;0.0378214;-0.05153663;0.4011814;0.04145549;0;0;0;0.1191225;0.1190516;368.182;41504.87
2280;0.03803569;-0.0502186;0.4437891;0.0458583;0;0;0;0.1197975;0.1197258;407.2851;45913.24
2288;0.03814283;-0.04930525;0.778074;0.08040114;0;0;0;0.1201349;0.1200628;714.0732;80497.73
2296;0.03824997;-0.04774917;0.4406178;0.04553059;0;0;0;0.1204724;0.1203998;404.3746;45585.45
2304;0.03835712;-0.04780868;0.5294452;0.05470945;0;0;0;0.1208098;0.1207369;485.8955;54775.54
2312;0.03851783;-0.04487256;0.6546259;0.06764481;0;0;0;0.121316;0.1212425;600.7794;67726.87
2320;0.03862497;-0.04462636;0.4412344;0.04559431;0;0;0;0.1216535;0.1215795;404.9405;45649.78
2328;0.03878569;-0.04239623;0.5134122;0.0530527;0;0;0;0.1221596;0.1220851;471.1813;53117.51
2336;0.03889283;-0.04099238;0.3265369;0.03374222;0;0;0;0.1224971;0.1224221;299.6775;33783.55
2344;0.03910712;-0.03922519;0.6582377;0.06801803;0;0;0;0.123172;0.1230962;604.0941;68101.81
2352;0.03921426;-0.0400759;0.5420426;0.05601118;0;0;0;0.1235095;0.1234333;497.4567;56080.36
2360;0.0393214;-0.03766347;0.9165861;0.09471409;0;0;0;0.1238469;0.1237703;841.192;94831.39
2368;0.03942855;-0.03512074;0.9308278;0.09618574;0;0;0;0.1241844;0.1241074;854.2622;96305.18
2376;0.03964283;-0.03369935;0.6712755;0.06936528;0;0;0;0.1248593;0.1247814;616.0594;69451.88
2384;0.0396964;-0.03116665;0.7818032;0.0807865;0;0;0;0.125028;0.1249499;717.4957;80887.5
2392;0.03985712;-0.02810147;0.9174671;0.09480512;0;0;0;0.1255342;0.1254555;842.0004;94924.13
2400;0.03996426;-0.02712548;0.7072763;0.07308537;0;0;0;0.1258717;0.1257925;649.0991;73177.36
2408;0.04012497;-0.02537583;0.9218717;0.09526027;0;0;0;0.1263779;0.1262981;846.0428;95380.66
2416;0.04023212;-0.02138916;0.9106545;0.09410115;0;0;0;0.1267153;0.1266351;835.7482;94220.39
2424;0.04039283;-0.02012876;0.9398721;0.09712031;0;0;0;0.1272215;0.1271407;862.5625;97243.87
2432;0.04049997;-0.02281995;0.9875013;0.102042;0;0;0;0.127559;0.1274777;906.2739;102172.2
2440;0.04060711;-0.01841858;0.8202414;0.08475845;0;0;0;0.1278964;0.1278147;752.7721;84866.85
2448;0.0408214;-0.01543922;0.9006118;0.09306341;0;0;0;0.1285713;0.1284888;826.5316;93183.06
2456;0.04092854;-0.01570421;0.7443049;0.07691167;0;0;0;0.1289088;0.1288258;683.0818;77010.81
2464;0.04103569;-0.01275492;0.8573874;0.08859687;0;0;0;0.1292463;0.1291628;786.8626;88711.38
2472;0.0411964;-0.01066762;0.6536275;0.06754164;0;0;0;0.1297525;0.1296683;599.8631;67629.28
2480;0.04135712;-0.007998357;0.9733476;0.1005795;0;0;0;0.1302586;0.1301739;893.2845;100710.5
2488;0.04146426;-0.005644818;0.8475503;0.08758038;0;0;0;0.1305961;0.1305109;777.8347;87694.75
2496;0.0415714;-0.003670903;0.8888955;0.09185272;0;0;0;0.1309336;0.1308479;815.7791;91972.98
2504;0.04173211;-0.0003758236;0.6209155;0.06416139;0;0;0;0.1314397;0.1313534;569.8418;64245.73
2512;0.04183926;0.0005826307;0.7664163;0.07919651;0;0;0;0.1317772;0.1316904;703.3745;79300.88
2520;0.04205354;0.0006446498;0.9282145;0.09591569;0;0;0;0.1324521;0.1323645;851.8638;96042.73
2528;0.04205354;0.005483904;0.8075265;0.08344457;0;0;0;0.1324521;0.1323645;741.1031;83555.1
2536;0.04226783;0.004071908;0.6429094;0.06643411;0;0;0;0.133127;0.1330385;590.0267;66522.55
2544;0.04237497;0.006830127;0.996017;0.102922;0;0;0;0.1334645;0.1333755;914.0892;103059.3
2552;0.04248212;0.009377862;0.9312389;0.09622822;0;0;0;0.1338019;0.1337125;854.6395;96356.97
2560;0.0426964;0.009253828;1.093683;0.1130141;0;0;0;0.1344768;0.1343865;1003.722;113166.1
2568;0.04280354;0.01327808;0.8844027;0.09138846;0;0;0;0.1348143;0.1347235;811.6558;91511.66
2576;0.04291069;0.0159035;0.9027554;0.09328491;0;0;0;0.1351518;0.1350605;828.4989;93410.99
2584;0.04301783;0.01647231;0.6948552;0.07180185;0;0;0;0.1354892;0.1353975;637.6996;71899.13
2592;0.04317854;0.01875944;0.8151906;0.08423653;0;0;0;0.1359954;0.135903;748.1368;84351.09
2600;0.04328569;0.02194302;0.9577845;0.09897126;0;0;0;0.1363329;0.13624;879.0015;99106.19
2608;0.0434464;0.02316332;0.8357752;0.08636361;0;0;0;0.1368391;0.1367455;767.0281;86481.79
2616;0.04355354;0.02355046;1.137231;0.1175141;0;0;0;0.1371765;0.1370825;1043.687;117675.3
2624;0.04371426;0.02598043;0.7260402;0.07502431;0;0;0;0.1376827;0.137588;666.3195;75127.6
2632;0.04387497;0.02645339;0.7103596;0.07340398;0;0;0;0.1381889;0.1380935;651.9287;73505.41
2640;0.04398211;0.0295668;0.9249844;0.09558191;0;0;0;0.1385263;0.1384305;848.8994;95714.32
2648;0.04414283;0.02940894;0.7219292;0.0745995;0;0;0;0.1390325;0.138936;662.5466;74703.21
2656;0.04424997;0.0313791;0.9230756;0.09538467;0;0;0;0.13937;0.139273;847.1477;95517.61
2664;0.04435712;0.0352812;0.875329;0.09045085;0;0;0;0.1397074;0.13961;803.3285;90577.21
2672;0.0445714;0.03641505;0.8542454;0.0882722;0;0;0;0.1403823;0.1402839;783.9791;88396.12
2680;0.04467855;0.04094986;0.8757402;0.09049333;0;0;0;0.1407198;0.1406209;803.7058;90620.67
2688;0.04478569;0.04271956;0.9046935;0.09348518;0;0;0;0.1410573;0.1409579;830.2776;93617.05
2696;0.04489283;0.04112777;0.8854011;0.09149162;0;0;0;0.1413947;0.1412949;812.572;91620.99
2704;0.04499997;0.04549469;0.5976882;0.06176124;0;0;0;0.1417322;0.1416318;548.5251;61848.77
2712;0.04521426;0.04473231;0.7618648;0.07872619;0;0;0;0.1424071;0.1423058;699.1973;78838.3
2720;0.0453214;0.04690669;0.9039594;0.09340933;0;0;0;0.1427446;0.1426428;829.6039;93542.67
2728;0.04542854;0.05184931;0.7599268;0.07852593;0;0;0;0.143082;0.1429798;697.4187;78638.28
2736;0.04564283;0.05111011;0.855508;0.08840267;0;0;0;0.1437569;0.1436537;785.1378;88529.76
2744;0.04574997;0.05319553;0.9235161;0.09543019;0;0;0;0.1440944;0.1439907;847.5519;95567.7
2752;0.04585711;0.05819578;0.6699834;0.06923176;0;0;0;0.1444319;0.1443277;614.8737;69331.75
2760;0.04596426;0.05967794;0.9840068;0.1016809;0;0;0;0.1447693;0.1446646;903.067;101828.1
2768;0.0460714;0.05937787;0.6561528;0.06780259;0;0;0;0.1451068;0.1450016;602.1807;67900.98
2776;0.04628568;0.05995483;0.8426465;0.08707365;0;0;0;0.1457817;0.1456755;773.3342;87200.58
2784;0.04639283;0.06509477;0.794195;0.08206698;0;0;0;0.1461191;0.1460125;728.8682;82186.9
2792;0.04649997;0.06649424;1.129508;0.116716;0;0;0;0.1464566;0.1463495;1036.6;116887
2800;0.04671425;0.0750483;0.9288017;0.09597638;0;0;0;0.1471315;0.1470234;852.4028;96117.58
2808;0.0468214;0.0754962;1.168328;0.1207274;0;0;0;0.147469;0.1473603;1072.226;120905.5
2816;0.04692854;0.07967769;1.048491;0.1083443;0;0;0;0.1478064;0.1476973;962.2471;108504.4
2824;0.04703568;0.08172303;0.8260262;0.08535621;0;0;0;0.1481439;0.1480343;758.0811;85482.66
2832;0.04724997;0.08599034;0.8768266;0.0906056;0;0;0;0.1488188;0.1487082;804.7029;90740.44
2840;0.04735711;0.09121987;0.9250137;0.09558494;0;0;0;0.1491563;0.1490451;848.9263;95727.51
2848;0.04746425;0.08791351;0.9738762;0.1006341;0;0;0;0.1494937;0.1493821;893.7696;100784.5
2856;0.0475714;0.09164898;0.864611;0.08934332;0;0;0;0.1498312;0.149719;793.4921;89477.18
2864;0.04767854;0.09126247;0.8716584;0.09007155;0;0;0;0.1501686;0.150056;799.9598;90206.81
2872;0.04789283;0.09383401;1.050018;0.1085021;0;0;0;0.1508435;0.1507299;963.6485;108665.8
2880;0.04799997;0.09618065;0.9209614;0.0951662;0;0;0;0.151181;0.1510668;845.2073;95310.07
2888;0.04810711;0.09407707;0.9716444;0.1004035;0;0;0;0.1515185;0.1514038;891.7214;100555.6
2896;0.04826783;0.1011652;0.7626283;0.07880509;0;0;0;0.1520246;0.1519092;699.898;78924.89
2904;0.04842854;0.1050642;0.8245579;0.08520449;0;0;0;0.1525308;0.1524146;756.7336;85334.45
2912;0.04853568;0.1119645;1.054599;0.1089755;0;0;0;0.1528683;0.1527516;967.8526;109142
2920;0.04864283;0.1240253;0.698144;0.07214169;0;0;0;0.1532058;0.1530885;640.7179;72252.22
2928;0.04874997;0.1271895;0.7635679;0.07890218;0;0;0;0.1535432;0.1534255;700.7603;79023.32
2936;0.04896425;0.1403898;1.036599;0.1071154;0;0;0;0.1542181;0.1540993;951.3328;107280.6
2944;0.0490714;0.1460278;1.062263;0.1097674;0;0;0;0.1545556;0.1544363;974.8862;109937.1
2952;0.04917854;0.153812;0.9825974;0.1015353;0;0;0;0.154893;0.1547732;901.7734;101692.5
2960;0.04928568;0.1566485;0.8492828;0.0877594;0;0;0;0.1552305;0.1551101;779.4247;87895.63
2968;0.04949997;0.1590759;1.187414;0.1226997;0;0;0;0.1559054;0.155784;1089.743;122891
2976;0.04960711;0.1622082;0.9481529;0.097976;0;0;0;0.1562429;0.1561209;870.1622;98129.08
2984;0.04971425;0.1627876;1.029316;0.1063629;0;0;0;0.1565803;0.1564579;944.6494;106529.4
2992;0.0498214;0.1648749;0.9836545;0.1016445;0;0;0;0.1569178;0.1567948;902.7437;101804
3000;0.04998211;0.1709094;1.066227;0.110177;0;0;0;0.157424;0.1573002;978.5244;110350.5
3008;0.05008926;0.1711011;0.8522486;0.08806586;0;0;0;0.1577614;0.1576371;782.1465;88204.79
3016;0.05024996;0.1729335;1.109452;0.1146436;0;0;0;0.1582676;0.1581425;1018.193;114825
3024;0.05041068;0.1766739;1.035718;0.1070244;0;0;0;0.1587738;0.1586479;950.5242;107194.3
3032;0.0505714;0.1798443;0.9429554;0.09743892;0;0;0;0.15928;0.1591533;865.3922;97594.12
3040;0.05067854;0.1782513;1.159371;0.1198019;0;0;0;0.1596174;0.1594902;1064.007;119993.2
3048;0.05078568;0.1763507;0.8730093;0.09021114;0;0;0;0.1599549;0.1598271;801.1995;90355.44
3056;0.05089282;0.1769445;1.037861;0.1072459;0;0;0;0.1602924;0.160164;952.4915;107417.8
3064;0.05099997;0.1786585;1.002976;0.1036411;0;0;0;0.1606298;0.160501;920.4761;103807.6
3072;0.05121425;0.1755914;1.118437;0.1155721;0;0;0;0.1613047;0.1611748;1026.44;115758.5
3080;0.05132139;0.1783622;1.166771;0.1205666;0;0;0;0.1616422;0.1615117;1070.798;120761.5
3088;0.05148211;0.1778065;1.171734;0.1210794;0;0;0;0.1621484;0.1620171;1075.352;121275.7
3096;0.05164282;0.1794434;1.194873;0.1234704;0;0;0;0.1626546;0.1625224;1096.588;123671.3
3104;0.05174997;0.1806293;0.9479473;0.09795475;0;0;0;0.162992;0.1628593;869.9735;98114.41
3112;0.05185711;0.1819655;1.033633;0.1068089;0;0;0;0.1633295;0.1631962;948.611;106983.4
3120;0.05196425;0.1806211;1.154262;0.119274;0;0;0;0.1636669;0.1635331;1059.318;119469.2
3128;0.05217854;0.1832052;0.816189;0.0843397;0;0;0;0.1643419;0.164207;749.053;84478.31
3136;0.05228568;0.1813848;1.248169;0.1289778;0;0;0;0.1646793;0.1645439;1145.501;129190.2
3144;0.05239282;0.1837446;1.127834;0.1165431;0;0;0;0.1650168;0.1648808;1035.063;116735.4
3152;0.05249996;0.1847657;1.132473;0.1170225;0;0;0;0.1653542;0.1652177;1039.321;117216
3160;0.05260711;0.1839294;1.185623;0.1225146;0;0;0;0.1656917;0.1655546;1088.099;122717.6
3168;0.05276782;0.185;1.141665;0.1179722;0;0;0;0.1661979;0.1660599;1047.756;118168.3
3176;0.05292854;0.1844412;1.086871;0.1123102;0;0;0;0.166704;0.1665653;997.4696;112497.4
3184;0.05303568;0.1865435;0.9934916;0.102661;0;0;0;0.1670415;0.1669021;911.7715;102832.5
3192;0.05314282;0.1836368;0.9902028;0.1023212;0;0;0;0.167379;0.167239;908.7532;102492.4
3200;0.05330354;0.1867609;1.007087;0.1040659;0;0;0;0.1678852;0.1677444;924.2489;104240.6
3208;0.05341068;0.186417;1.126072;0.116361;0;0;0;0.1682226;0.1680813;1033.447;116556.8
3216;0.05357139;0.1861645;1.194051;0.1233855;0;0;0;0.1687288;0.1685866;1095.834;123593.7
3224;0.05367854;0.1856502;1.328716;0.1373009;0;0;0;0.1690663;0.1689235;1219.422;137533.1
3232;0.05383925;0.1850357;0.8809964;0.09103648;0;0;0;0.1695724;0.1694288;808.5297;91190.85
3240;0.05399997;0.1846542;1.091921;0.1128321;0;0;0;0.1700786;0.1699342;1002.105;113024
3248;0.05410711;0.1837176;1.301995;0.1345397;0;0;0;0.1704161;0.170271;1194.898;134769
3256;0.05421425;0.1834119;1.18991;0.1229576;0;0;0;0.1707536;0.1706079;1092.034;123167.6
3264;0.05442854;0.1830073;1.11509;0.1152262;0;0;0;0.1714285;0.1712817;1023.368;115423.7
3272;0.05453568;0.1817443;1.128098;0.1165704;0;0;0;0.1717659;0.1716186;1035.306;116770.6
3280;0.05464282;0.1817763;1.027496;0.1061748;0;0;0;0.1721034;0.1719555;942.9785;106357.5
3288;0.05485711;0.1811091;1.200041;0.1240045;0;0;0;0.1727783;0.1726292;1101.331;124218.7
3296;0.05496425;0.1806913;1.153234;0.1191678;0;0;0;0.1731158;0.1729661;1058.374;119374.1
3304;0.0550714;0.1796984;1.427616;0.1475206;0;0;0;0.1734532;0.173303;1310.187;147776.4
3312;0.05517853;0.1797886;1.177519;0.1216772;0;0;0;0.1737907;0.1736398;1080.661;121888.6
3320;0.05528568;0.1784536;1.273775;0.1316237;0;0;0;0.1741281;0.1739767;1169;131852.9
3328;0.05549997;0.1781718;1.139756;0.117775;0;0;0;0.174803;0.1746504;1046.005;117980.9
3336;0.05560711;0.1784179;1.217395;0.1257978;0;0;0;0.1751405;0.1749873;1117.258;126018.1
3344;0.05571425;0.1779437;1.06887;0.1104501;0;0;0;0.175478;0.1753242;980.9498;110643.9
3352;0.05582139;0.177296;1.152735;0.1191162;0;0;0;0.1758154;0.175661;1057.916;119325.6
3360;0.05603568;0.1758859;0.8767386;0.0905965;0;0;0;0.1764903;0.1763348;804.6221;90756.39
3368;0.05614282;0.1760613;1.129889;0.1167555;0;0;0;0.1768278;0.1766716;1036.95;116961.9
3376;0.05624996;0.1755025;1.0938;0.1130263;0;0;0;0.1771652;0.1770085;1003.829;113226.5
3384;0.05635711;0.1743555;1.107044;0.1143948;0;0;0;0.1775027;0.1773454;1015.984;114597.8
3392;0.05657139;0.1739959;1.14002;0.1178023;0;0;0;0.1781776;0.1780191;1046.247;118012.2
3400;0.05667854;0.1741055;1.193875;0.1233673;0;0;0;0.1785151;0.1783559;1095.672;123587.5
3408;0.05678568;0.1721491;0.997632;0.1030888;0;0;0;0.1788525;0.1786928;915.5714;103273.2
3416;0.05689282;0.1727825;0.8632603;0.08920374;0;0;0;0.17919;0.1790296;792.2524;89363.59
3424;0.0571071;0.1721899;1.139286;0.1177265;0;0;0;0.1798649;0.1797033;1045.574;117938.2
3432;0.05721425;0.171534;1.197163;0.1237071;0;0;0;0.1802024;0.1800402;1098.69;123930.1
3440;0.05732139;0.1705248;1.381484;0.1427536;0;0;0;0.1805398;0.180377;1267.849;143011.4
3448;0.05742853;0.1706645;1.280118;0.1322791;0;0;0;0.1808773;0.1807139;1174.821;132518.4
3456;0.05758925;0.1699008;1.074479;0.1110297;0;0;0;0.1813835;0.1812192;986.0971;111231.1
3464;0.05769639;0.1691015;1.106633;0.1143523;0;0;0;0.1817209;0.181556;1015.606;114560.1
3472;0.05785711;0.1685653;1.148565;0.1186853;0;0;0;0.1822271;0.1820613;1054.089;118901.6
3480;0.05801782;0.1682301;1.068195;0.1103803;0;0;0;0.1827333;0.1825665;980.33;110582
3488;0.05812497;0.168046;1.380309;0.1426323;0;0;0;0.1830707;0.1829034;1266.771;142893.4
3496;0.05828568;0.1676995;1.199395;0.1239377;0;0;0;0.1835769;0.1834086;1100.738;124165.3
3504;0.05839282;0.1671257;1.039007;0.1073642;0;0;0;0.1839144;0.1837455;953.5426;107561.7
3512;0.05855354;0.1663032;0.6560354;0.06779046;0;0;0;0.1844206;0.1842507;602.0729;67915.48
3520;0.05866068;0.1658985;1.273658;0.1316116;0;0;0;0.1847581;0.1845876;1168.893;131854.7
3528;0.05882139;0.1652996;2.589978;0.2676316;0;0;0;0.1852642;0.1850928;2376.938;268127.4
3536;0.05892854;0.1649369;1.129655;0.1167312;0;0;0;0.1856017;0.1854297;1036.734;116947.9
3544;0.05903568;0.1644239;1.567273;0.1619519;0;0;0;0.1859391;0.1857665;1438.356;162253
3552;0.05914282;0.1641915;1.084932;0.1121099;0;0;0;0.1862766;0.1861033;995.6909;112318.7
3560;0.0593571;0.16381;1.010552;0.104424;0;0;0;0.1869515;0.186777;927.429;104619.2
3568;0.05946425;0.1636039;1.252838;0.1294602;0;0;0;0.187289;0.1871138;1149.786;129702.7
3576;0.05957139;0.1630996;1.077004;0.1112906;0;0;0;0.1876264;0.1874506;988.4147;111499.5
3584;0.05967853;0.1624556;1.251576;0.1293298;0;0;0;0.1879639;0.1877875;1148.627;129572.8
3592;0.05983925;0.1624581;1.304432;0.1347916;0;0;0;0.1884701;0.1882927;1197.135;135045.6
3600;0.05999997;0.1620484;1.413902;0.1461035;0;0;0;0.1889763;0.1887979;1297.601;146379.6
3608;0.0601071;0.1615861;0.748504;0.07734556;0;0;0;0.1893137;0.1891347;686.9354;77491.99
3616;0.06021425;0.161967;1.203741;0.1243868;0;0;0;0.1896512;0.1894716;1104.727;124622.7
3624;0.06037496;0.1616262;1.01575;0.104961;0;0;0;0.1901574;0.1899768;932.1989;105160.6
3632;0.06053568;0.1604316;1.124721;0.1162214;0;0;0;0.1906635;0.190482;1032.207;116443
3640;0.06074996;0.158546;0.4674569;0.04830397;0;0;0;0.1913385;0.1911556;429.006;48396.4
3648;0.06074996;0.1587533;0.305277;0.03154535;0;0;0;0.1913385;0.1911556;280.1663;31605.71
3656;0.06096425;0.15542;0.7331758;0.07576165;0;0;0;0.1920134;0.1918293;672.8681;75907.12
3664;0.06107138;0.155737;0.3839151;0.0396713;0;0;0;0.1923508;0.1921661;352.336;39747.61
3672;0.0612321;0.1525259;0.3877031;0.04006273;0;0;0;0.192857;0.1926713;355.8124;40140
3680;0.06128568;0.1518637;0.1086821;0.0112305;0;0;0;0.1930258;0.1928397;99.74239;11252.18
3688;0.06144639;0.1501536;0.3976282;0.04108833;0;0;0;0.1935319;0.1933449;364.9211;41167.85
3696;0.0616071;0.1508069;0.3852951;0.03981391;0;0;0;0.1940381;0.1938501;353.6025;39891.16
3704;0.06171425;0.1476277;0.5499416;0.05682741;0;0;0;0.1943756;0.1941869;504.7059;56937.87
3712;0.06182139;0.1468228;0.3451246;0.03566295;0;0;0;0.194713;0.1945237;316.7363;35732.39
3720;0.06203567;0.1479385;0.2810513;0.02904203;0;0;0;0.1953879;0.1951973;257.9333;29098.77
3728;0.06214281;0.1453488;0.6283447;0.06492908;0;0;0;0.1957254;0.1955341;576.6599;65056.16
3736;0.06224996;0.1442293;0.1396321;0.01442868;0;0;0;0.1960629;0.1958709;128.1466;14456.97
3744;0.0623571;0.1437701;0.4190056;0.04329733;0;0;0;0.1964003;0.1962077;384.5401;43382.36
3752;0.06246424;0.1427277;0.3831222;0.03958937;0;0;0;0.1967378;0.1965445;351.6083;39667.26
3760;0.06262496;0.1426845;0.5512043;0.05695789;0;0;0;0.197244;0.1970497;505.8648;57070.24
3768;0.06278567;0.1413508;0.5657397;0.05845989;0;0;0;0.1977502;0.1975549;519.2046;58575.49
3776;0.06289282;0.1431756;0.3813016;0.03940124;0;0;0;0.1980876;0.1978917;349.9375;39479.29
3784;0.06305353;0.1422072;0.2450799;0.02532497;0;0;0;0.1985938;0.1983969;224.9207;25375.26
3792;0.06316067;0.1422422;0.5840925;0.06035635;0;0;0;0.1989313;0.1987336;536.0477;60476.41
3800;0.06332139;0.1396557;0.6077602;0.06280202;0;0;0;0.1994374;0.1992388;557.7687;62927.27
3808;0.06342853;0.135384;0.08298815;0.00857546;0;0;0;0.1997749;0.1995756;76.16193;8592.591
3816;0.06364281;0.1385487;0.225259;0.02327681;0;0;0;0.2004498;0.2002492;206.7302;23323.46
3824;0.06369639;0.1485417;0.2984645;0.0308414;0;0;0;0.2006186;0.2004176;273.9142;30903.27
3832;0.0638571;0.163483;0.3196069;0.03302611;0;0;0;0.2011247;0.2009227;293.3175;33092.53
3840;0.06396425;0.1849993;-0.1488148;-0.01537756;0;0;0;0.2014622;0.2012595;-136.574;-15408.54
3848;0.06412496;0.1995039;0.3690273;0.03813289;0;0;0;0.2019684;0.2017647;338.6728;38209.91
3856;0.0642321;0.2030496;0.3746358;0.03871245;0;0;0;0.2023058;0.2021015;343.82;38790.76
3864;0.06433924;0.2053017;0.4321901;0.04465974;0;0;0;0.2026433;0.2024383;396.6402;44750.24
3872;0.06455353;0.2043545;0.2676906;0.02766142;0;0;0;0.2033182;0.2031118;245.6716;27717.66
3880;0.06466067;0.194369;-0.08344949;-0.008623131;0;0;0;0.2036557;0.2034486;-76.58531;-8640.692
3888;0.06476782;0.1781542;0.2282541;0.0235863;0;0;0;0.2039931;0.2037853;209.4789;23634.42
3896;0.0649821;0.1543964;0.1279745;0.01322406;0;0;0;0.204668;0.2044589;117.4479;13251.13
3904;0.0649821;0.1347682;0.3601886;0.03721957;0;0;0;0.204668;0.2044589;330.5612;37295.74
3912;0.06519639;0.1221936;0.2770872;0.0286324;0;0;0;0.2053429;0.2051324;254.2952;28691.19
3920;0.06530352;0.1130908;0.5053076;0.05221523;0;0;0;0.2056804;0.2054692;463.7433;52322.62
3928;0.06541067;0.09994932;0.04763333;0.00492212;0;0;0;0.2060179;0.2058059;43.71523;4932.261
3936;0.06562495;0.09131509;0.2650478;0.02738832;0;0;0;0.2066928;0.2064795;243.2462;27444.94
3944;0.06578568;0.08183704;0.2574718;0.02660547;0;0;0;0.207199;0.2069846;236.2933;26660.6
3952;0.06589281;0.07158721;0.3269187;0.03378166;0;0;0;0.2075364;0.2073213;300.0278;33851.77
3960;0.06599996;0.0688647;0.3969235;0.04101551;0;0;0;0.2078739;0.2076581;364.2744;41100.77
3968;0.0661071;0.06350925;0.3923132;0.04053912;0;0;0;0.2082113;0.2079949;360.0433;40623.52
3976;0.06621424;0.06148961;0.4211492;0.04351883;0;0;0;0.2085488;0.2083316;386.5074;43609.59
3984;0.06637496;0.05833422;0.1303824;0.01347287;0;0;0;0.209055;0.2088368;119.6577;13501.04
3992;0.0664821;0.05503476;0.2984645;0.0308414;0;0;0;0.2093924;0.2091735;273.9142;30905.97
4000;0.06669638;0.04992488;0.3264195;0.03373008;0;0;0;0.2100673;0.209847;299.5697;33800.93
4008;0.0668571;0.0503258;0.1614206;0.01668016;0;0;0;0.2105736;0.2103522;148.1429;16715.29
4016;0.0668571;0.04445605;0.2147758;0.02219354;0;0;0;0.2105736;0.2103522;197.1093;22240.28
4024;0.06707139;0.04188326;0.2101363;0.02171412;0;0;0;0.2112485;0.2110256;192.8514;21760
4032;0.06717853;0.0387924;0.1837964;0.01899233;0;0;0;0.2115859;0.2113624;168.6781;19032.51
4040;0.06728567;0.03980285;0.4167739;0.04306672;0;0;0;0.2119234;0.2116991;382.492;43157.99
4048;0.06739282;0.03904548;0.4438185;0.04586134;0;0;0;0.2122608;0.2120359;407.312;45958.68
4056;0.0676071;0.03535637;0.3593957;0.03713763;0;0;0;0.2129358;0.2127094;329.8335;37216.71
4064;0.06771424;0.03563012;0.09408795;0.009722441;0;0;0;0.2132732;0.2130461;86.34871;9743.177
4072;0.06792853;0.03225048;0.4828439;0.04989397;0;0;0;0.2139481;0.2137196;443.1274;50000.72
4080;0.06792853;0.03070442;0.3775723;0.03901589;0;0;0;0.2139481;0.2137196;346.515;39099.36
4088;0.06814281;0.02755092;0.3970996;0.04103371;0;0;0;0.214623;0.214393;364.4361;41121.78
4096;0.06824995;0.02717067;0.1409242;0.0145622;0;0;0;0.2149605;0.2147298;129.3325;14593.5
4104;0.06846425;0.02456217;1.056126;0.1091332;0;0;0;0.2156354;0.2154033;969.2538;109368.6
4109.624;0.06846425;0.01878513;0.3797453;0.03924042;0;0;0;0.2156354;0.2154033;348.5092;39325.04