File: Ensayos/Resistencia/comp/EspD/RED2.raw
"Test Type";"Manual"
"Method Name:";"C:\INSTRON\USER\TEMPLATE\CYCLE.MTM"
"Name:";""
"Operator ID:";""
"Company:";""
"Lab name:";""
"Test date:";"23/06/2017"
"Temperature:";""
"Humidity:";""
"Note 1:";""
"Note 2:";""
"Note 3:";""
"Geometry:";"Rectangular"
"Specimen";1
"Specimen name:";""
"Width:";0.250000;"in"
"Thickness:";0.060000;"in"
"Length:";1.250000;"in"
"Diameter:";0.039370;"in"
"Inner diameter:";0.019685;"in"
"Outer diameter:";0.039370;"in"
"Wall thickness:";0.019685;"in"
"Area:";0.015000;"in*in"
"Linear density:";1.000000;"den"
"Sled weight:";2.204623;"lbf"
"Loading span:";0.000000;"mm"
"Support span:";1.000000;"mm"
"Span ratio:";"2"
"Fixture type:";"3-point"
"Comment:";""
"Included"
"Final Width:";0.250000;"in"
"Final Thickness:";0.060000;"in"
"Final Length:";1.250000;"in"
"Final Diameter:";0.039370;"in"
"Final Inner diameter:";0.019685;"in"
"Final Outer diameter:";0.039370;"in"
"Final Wall thickness:";0.019685;"in"
"Final Area:";0.015000;"in*in"
"Final Linear density:";1.000000;"den"
"Time sec";"Extension mm";"Strain 1 %";"Load N";"Stress MPa";"Cycle Count ";"Total Cycle Count ";"Repetitions Count ";"Strain [Exten.] %";"True strain %";"Tenacity gf/tex";"True stress Pa"
0;0;3.280584e-005;51.96917;5.370159;0;0;0;0;0;47694.43;5370159
14;0.007499996;-9.123003e-005;52.75602;5.451467;0;0;0;0.02362203;0.02361924;48416.55;5452754
28;0.03626783;-0.0117612;79.74624;8.240461;0;0;0;0.1142294;0.1141642;73186.68;8249874
42;0.08303566;-0.03941481;120.3106;12.43212;0;0;0;0.2615296;0.2611882;110414.4;1.246463e+007
56;0.1295892;-0.06988991;170.0051;17.56723;0;0;0;0.408155;0.4073243;156021.3;1.763893e+007
70;0.176357;-0.1044839;233.3125;24.109;0;0;0;0.5554552;0.5539182;214121.3;2.424292e+007
84.00001;0.2230713;-0.1429812;311.5401;32.19255;0;0;0;0.7025868;0.7001301;285914.3;3.241873e+007
98.00001;0.2695713;-0.1870782;404.5413;41.80269;0;0;0;0.8490434;0.8454593;371265.6;4.215761e+007
112;0.3162855;-0.234984;513.5329;53.06517;0;0;0;0.9961748;0.9912456;471292;5.359379e+007
126;0.3629462;-0.2866661;639.1912;66.04989;0;0;0;1.143138;1.136653;586614.3;6.680493e+007
140;0.409714;-0.3436096;779.2045;80.51796;0;0;0;1.290438;1.282183;715110.8;8.1557e+007
154;0.4562676;-0.4031722;927.2223;95.81316;0;0;0;1.437063;1.426835;850953.3;9.719006e+007
168;0.5029818;-0.4680308;1091.421;112.7804;0;0;0;1.584195;1.571777;1001646;1.145671e+008
182;0.5497496;-0.5356463;1264.64;130.6798;0;0;0;1.731495;1.716675;1160617;1.329425e+008
196;0.5962496;-0.6041558;1449.077;149.7382;0;0;0;1.877952;1.860536;1329882;1.525503e+008
210;0.6429103;-0.6709325;1636.788;169.1351;0;0;0;2.024914;2.004686;1502153;1.725599e+008
224;0.6896246;-0.7399274;1835.435;189.662;0;0;0;2.172046;2.148793;1684460;1.937815e+008
236.59;0.7315174;-0.7994663;2011.683;207.8743;0;0;0;2.303992;2.277851;1846211;2.126637e+008
250.59;0.6849103;-0.7391889;1594.586;164.7742;0;0;0;2.157198;2.134259;1463423;1.683287e+008
264.59;0.6383567;-0.6792334;1302.776;134.6204;0;0;0;2.010572;1.990627;1195615;1.37327e+008
278.59;0.5915889;-0.6232635;1059.496;109.4814;0;0;0;1.863272;1.846126;972346.4;1.115214e+008
292.59;0.5449818;-0.5690287;853.0178;88.14536;0;0;0;1.716478;1.701913;782852.5;8.965835e+007
306.59;0.4983211;-0.514715;676.8709;69.94347;0;0;0;1.569515;1.557326;621194.6;7.104124e+007
320.59;0.4516605;-0.4566032;523.6461;54.11021;0;0;0;1.422553;1.412529;480573.4;5.487995e+007
334.59;0.404839;-0.3963152;396.4352;40.96505;0;0;0;1.275084;1.267023;363826.3;4.148739e+007
348.59;0.3582319;-0.338588;294.4176;30.42321;0;0;0;1.128289;1.121972;270200.2;3.076647e+007
362.59;0.3116783;-0.286906;214.2135;22.13544;0;0;0;0.9816641;0.976877;196593.3;2.235274e+007
376.59;0.2649105;-0.2408181;151.0207;15.60551;0;0;0;0.8343639;0.8309024;138598.5;1.573571e+007
390.59;0.2182499;-0.1986624;101.9935;10.53935;0;0;0;0.6874011;0.6850493;93603.98;1.06118e+007
404.59;0.1716428;-0.1632309;66.2254;6.843305;0;0;0;0.5406071;0.5391511;60778;6880301
417.544;0.1551963;-0.1511738;68.55283;7.083807;1;1;0;0.4888073;0.4876165;62913.99;7118433
431.544;0.2018034;-0.1770834;120.9414;12.4973;1;1;0;0.6356013;0.6335899;110993.3;1.257673e+007
445.544;0.2484105;-0.2095624;186.4419;19.2657;1;1;0;0.7823954;0.7793506;171106;1.941644e+007
459.544;0.2951248;-0.2477747;272.6134;28.17011;1;1;0;0.929527;0.9252334;250189.5;2.843196e+007
473.544;0.3417319;-0.2889883;377.3369;38.99155;1;1;0;1.076321;1.07057;346298.9;3.941123e+007
487.544;0.3883926;-0.3335558;501.8895;51.86202;1;1;0;1.223284;1.215862;460606.4;5.249644e+007
501.544;0.4349997;-0.3857515;648.9047;67.05362;1;1;0;1.370078;1.360777;595528.8;6.797231e+007
515.544;0.4818211;-0.4452797;822.4376;84.98539;1;1;0;1.517547;1.506147;754787.6;8.627508e+007
529.544;0.5284818;-0.5024787;993.8188;102.6948;1;1;0;1.66451;1.650808;912071.8;1.044042e+008
543.544;0.5750889;-0.5653509;1194.571;123.4393;1;1;0;1.811304;1.795095;1096311;1.256751e+008
557.544;0.6218031;-0.6301155;1411.61;145.8666;1;1;0;1.958435;1.939504;1295497;1.487233e+008
571.544;0.6684103;-0.6916896;1642.312;169.7059;1;1;0;2.105229;2.083375;1507223;1.732786e+008
585.544;0.7150174;-0.7541521;1872.597;193.5021;1;1;0;2.252023;2.22704;1718566;1.978598e+008
599.544;0.7416424;-0.7884566;1984.398;205.0549;1;1;0;2.335881;2.309017;1821171;2.098447e+008
613.544;0.7441067;-0.7886057;1984.97;205.114;1;1;0;2.343643;2.316601;1821696;2.099212e+008
627.544;0.7479638;-0.7915155;2002.027;206.8766;1;1;0;2.355792;2.328471;1837350;2.117501e+008
641.544;0.7509638;-0.7931599;2011.276;207.8323;1;1;0;2.36524;2.337702;1845838;2.12748e+008
655.544;0.7528924;-0.7935646;2014.747;208.1909;1;1;0;2.371315;2.343636;1849023;2.131278e+008
669.544;0.7531067;-0.792016;2006.862;207.3762;1;1;0;2.371989;2.344295;1841787;2.122951e+008
683.544;0.753428;-0.7905552;2002.468;206.9221;1;1;0;2.373002;2.345284;1837754;2.118323e+008
697.544;0.754178;-0.7900503;2000.819;206.7517;1;1;0;2.375364;2.347591;1836241;2.116628e+008
711.544;0.754928;-0.7888424;2001.719;206.8448;1;1;0;2.377726;2.349898;1837067;2.11763e+008
725.544;0.7557852;-0.7880864;2003.633;207.0425;1;1;0;2.380426;2.352535;1838824;2.11971e+008
739.544;0.7564281;-0.786955;2003.646;207.0439;1;1;0;2.382451;2.354513;1838835;2.119766e+008
753.544;0.7580352;-0.7881271;1999.812;206.6477;1;1;0;2.387512;2.359457;1835317;2.115814e+008
767.544;0.7594281;-0.7878176;2005.731;207.2593;1;1;0;2.391899;2.363742;1840749;2.122168e+008
781.5441;0.7601781;-0.7869726;2007.293;207.4207;1;1;0;2.394262;2.366049;1842182;2.123869e+008
795.5441;0.7603387;-0.7851885;2005.488;207.2342;1;1;0;2.394768;2.366543;1840526;2.12197e+008
809.5441;0.7605531;-0.7836837;2004.339;207.1154;1;1;0;2.395443;2.367202;1839471;2.120767e+008
823.5441;0.760821;-0.7819328;2004.586;207.1409;1;1;0;2.396286;2.368026;1839698;2.121046e+008
837.5441;0.7610352;-0.7800579;2004.89;207.1724;1;1;0;2.396961;2.368685;1839977;2.121382e+008
851.5441;0.7612495;-0.7777996;2004.632;207.1457;1;1;0;2.397636;2.369344;1839740;2.121123e+008
865.5441;0.7615174;-0.7758395;2004.94;207.1775;1;1;0;2.39848;2.370168;1840023;2.121466e+008
878.0181;0.7616781;-0.7744256;2007.074;207.398;1;1;0;2.398986;2.370663;1841981;2.123735e+008
892.0181;0.7614638;-0.7721942;2006.261;207.314;1;1;0;2.398311;2.370003;1841235;2.122861e+008
906.0181;0.7609816;-0.7687256;2003.063;206.9836;1;1;0;2.396793;2.36852;1838300;2.119445e+008
920.0181;0.7606066;-0.7652915;2000.801;206.7499;1;1;0;2.395612;2.367367;1836225;2.117028e+008
934.0181;0.7603924;-0.7616418;2000.827;206.7525;1;1;0;2.394937;2.366708;1836248;2.117041e+008
946.2501;0.7602852;-0.7591003;2001.655;206.8381;2;2;0;2.394599;2.366378;1837008;2.11791e+008
960.2501;0.7604995;-0.7540424;2002.757;206.952;2;2;0;2.395274;2.367037;1838019;2.11909e+008
974.2501;0.7607674;-0.7485154;2004.213;207.1025;2;2;0;2.396118;2.367861;1839356;2.120649e+008
984.6261;0.7609281;-0.7451764;1998.207;206.4818;3;3;0;2.396624;2.368356;1833843;2.114304e+008
998.6261;0.7613031;-0.7385092;2000.381;206.7065;3;3;0;2.397805;2.369509;1835839;2.116629e+008
1012.626;0.7617316;-0.7327923;2003.387;207.0171;3;3;0;2.399155;2.370827;1838598;2.119837e+008
1026.626;0.7618924;-0.7275352;2005.317;207.2165;3;3;0;2.399661;2.371322;1840369;2.12189e+008
1038.642;0.7619459;-0.7232886;2008.324;207.5272;3;3;0;2.39983;2.371486;1843128;2.125075e+008
1052.642;0.7615709;-0.7169271;2004.384;207.1201;3;3;0;2.398649;2.370333;1839513;2.120882e+008
1066.642;0.7610352;-0.7091354;1994.874;206.1374;3;3;0;2.396961;2.368685;1830785;2.110784e+008
1079.594;0.7612495;-0.7070612;1998.611;206.5236;4;4;0;2.397636;2.369344;1834215;2.114753e+008
1093.594;0.7615174;-0.7064097;2003.607;207.0398;4;4;0;2.39848;2.370168;1838799;2.120056e+008
1106.076;0.7616781;-0.7048455;2004.768;207.1598;4;4;0;2.398986;2.370663;1839865;2.121296e+008
1120.076;0.7614638;-0.6987528;2001.49;206.8211;4;4;0;2.398311;2.370003;1836857;2.117813e+008
1134.076;0.7612495;-0.691679;1997.608;206.4199;4;4;0;2.397636;2.369344;1833294;2.113691e+008
1147.48;0.7609281;-0.6857497;1995.581;206.2104;4;4;0;2.396624;2.368356;1831434;2.111525e+008
1158.386;0.7610887;-0.6839625;1998.436;206.5055;5;5;0;2.39713;2.36885;1834054;2.114557e+008
1171.388;0.7613031;-0.6814223;1995.187;206.1697;6;6;0;2.397805;2.369509;1831072;2.111133e+008
1185.388;0.7615174;-0.6791101;1997.902;206.4503;6;6;0;2.39848;2.370168;1833564;2.114019e+008
1199.388;0.7617852;-0.6792185;2001.576;206.8299;6;6;0;2.399323;2.370992;1836936;2.117924e+008
1212.138;0.7619995;-0.6805565;2004.697;207.1524;6;6;0;2.399998;2.371651;1839800;2.121241e+008
1226.138;0.7617852;-0.6811328;2002.363;206.9113;6;6;0;2.399323;2.370992;1837658;2.118758e+008
1238.762;0.7616781;-0.6808929;1998.013;206.4618;7;7;0;2.398986;2.370663;1833666;2.114148e+008
1252.762;0.7619459;-0.6825887;1990.307;205.6655;7;7;0;2.39983;2.371486;1826594;2.106011e+008
1266.762;0.7622138;-0.6840527;1990.516;205.687;7;7;0;2.400673;2.37231;1826785;2.106249e+008
1280.762;0.7625352;-0.6881177;1993.463;205.9916;7;7;0;2.401686;2.373299;1829490;2.109389e+008
1294.762;0.7629638;-0.6918795;1980.494;204.6515;7;7;0;2.403036;2.374617;1817588;2.095693e+008
1308.762;0.7682138;-0.7051331;1997.362;206.3945;7;7;0;2.419571;2.390763;1833069;2.113884e+008
1322.762;0.7720174;-0.7140592;2010.866;207.7899;7;7;0;2.431551;2.402459;1845461;2.128424e+008
1336.762;0.774428;-0.7230274;2015.029;208.2201;7;7;0;2.439143;2.409871;1849282;2.132989e+008
1350.762;0.7755531;-0.731619;2007.424;207.4343;7;7;0;2.442687;2.41333;1842303;2.125012e+008
1364.762;0.7766781;-0.7420523;1986.929;205.3164;7;7;0;2.44623;2.416789;1823494;2.103389e+008
1378.762;0.7807495;-0.7534674;1993.079;205.9519;7;7;0;2.459054;2.429306;1829138;2.110164e+008
1392.762;0.7878209;-0.7771769;2001.683;206.841;7;7;0;2.481326;2.451041;1837034;2.119734e+008
1406.762;0.7930709;-0.7982334;2006.028;207.29;7;7;0;2.497861;2.467175;1841022;2.124678e+008
1420.762;0.7999816;-0.8296119;1995.358;206.1874;7;7;0;2.519627;2.488408;1831229;2.113825e+008
1434.762;0.8097852;-0.8603776;2005.656;207.2516;7;7;0;2.550504;2.518522;1840680;2.125375e+008
1448.762;0.8199638;-0.8939756;2006.347;207.323;7;7;0;2.582563;2.549778;1841314;2.126772e+008
1462.762;0.8262852;-0.9236651;1998.652;206.5278;7;7;0;2.602473;2.569185;1834252;2.119026e+008
1476.762;0.8324994;-0.9687789;1971.872;203.7605;7;7;0;2.622046;2.588259;1809675;2.091032e+008
1490.762;0.8510888;-1.041266;1972.824;203.8589;7;7;0;2.680594;2.645296;1810549;2.093236e+008
1504.762;0.8814102;-1.138766;2006.462;207.3348;7;7;0;2.776095;2.73826;1841420;2.130907e+008
1518.762;0.8993566;-1.20612;2006.866;207.3766;7;7;0;2.832619;2.793242;1841790;2.132507e+008
1532.762;0.922553;-1.313619;1993.061;205.95;7;7;0;2.905679;2.864264;1829121;2.119342e+008
1546.762;0.9571601;-1.477153;1999.891;206.6558;7;7;0;3.014678;2.970129;1835389;2.128858e+008
1560.762;0.9856065;-1.610824;1999.241;206.5886;7;7;0;3.104272;3.057064;1834793;2.130017e+008
1574.762;1.013678;-1.755106;1975.457;204.131;7;7;0;3.192686;3.14278;1812965;2.106483e+008
1588.762;1.06816;-1.979711;2001.972;206.8708;7;7;0;3.364284;3.30893;1837299;2.138306e+008
1602.762;1.118517;-2.205898;1992.744;205.9173;7;7;0;3.522889;3.462255;1828830;2.131716e+008
1616.762;1.189285;-2.515942;1996.307;206.2855;7;7;0;3.74578;3.677329;1832100;2.140125e+008
1630.762;1.252821;-2.75043;1999.903;206.6571;7;7;0;3.945891;3.87003;1835400;2.148115e+008
1644.762;1.311106;-2.983553;2000.081;206.6755;7;7;0;4.129468;4.046483;1835564;2.152101e+008
1658.762;1.373838;-3.263593;1975.635;204.1494;7;7;0;4.32705;4.236049;1813128;2.12983e+008
1672.762;1.466624;-3.65042;1993.203;205.9647;7;7;0;4.619288;4.515775;1829251;2.154788e+008
1686.762;1.547088;-3.974463;1991.626;205.8017;7;7;0;4.872719;4.757723;1827804;2.158299e+008
1700.762;1.615606;-4.271903;1988.038;205.431;7;7;0;5.088523;4.963288;1824511;2.158844e+008
1714.762;1.697303;-4.604017;1988.767;205.5063;7;7;0;5.345835;5.207842;1825180;2.164923e+008
1728.762;1.784999;-5.069125;1962.181;202.7591;7;7;0;5.622044;5.469691;1800781;2.141583e+008
1742.762;1.886249;-5.466929;1988.648;205.4941;7;7;0;5.940941;5.771159;1825071;2.177024e+008
1756.762;1.981981;-5.771378;2012.858;207.9957;7;7;0;6.242459;6.055365;1847290;2.209798e+008
1770.762;2.041231;-5.989218;2000.969;206.7672;7;7;0;6.429073;6.23086;1836378;2.200604e+008
1784.762;2.116284;-6.229845;2002.043;206.8782;7;7;0;6.665462;6.452723;1837364;2.206676e+008
1798.762;2.197981;-6.494663;2025.541;209.3063;7;7;0;6.922774;6.693665;1858929;2.237961e+008
1812.762;2.252516;-6.67513;2002.928;206.9697;7;7;0;7.09454;6.854181;1838177;2.216532e+008
1826.762;2.312249;-6.865976;2006.711;207.3605;7;7;0;7.282672;7.029696;1841648;2.224619e+008
1840.762;2.375195;-7.068262;2000.147;206.6822;7;7;0;7.480929;7.214324;1835624;2.22144e+008
1854.762;2.43857;-7.289441;2020.676;208.8036;7;7;0;7.680535;7.399865;1854465;2.248409e+008
1868.762;2.489141;-7.464699;2028.743;209.6372;7;7;0;7.839815;7.547674;1861868;2.260723e+008
1882.762;2.522945;-7.597594;2020.257;208.7603;7;7;0;7.946282;7.646353;1854080;2.25349e+008
1896.762;2.559909;-7.750133;2025.011;209.2516;7;7;0;8.062706;7.754148;1858443;2.261229e+008
1910.762;2.594784;-7.900524;2034.14;210.1949;7;7;0;8.172548;7.855743;1866821;2.273732e+008
1924.762;2.619427;-8.017172;2026.897;209.4464;7;7;0;8.250163;7.927469;1860174;2.267261e+008
1938.762;2.640427;-8.117837;2031.088;209.8796;7;7;0;8.316304;7.988551;1864021;2.273338e+008
1952.762;2.649641;-8.181508;2004.454;207.1274;7;7;0;8.345325;8.01534;1839577;2.244128e+008
1966.762;2.66148;-8.248701;2015.758;208.2954;7;7;0;8.382615;8.049752;1849951;2.25756e+008
1980.762;2.669998;-8.304117;2015.828;208.3027;7;7;0;8.409443;8.074501;1850016;2.258198e+008
1994.762;2.674712;-8.345448;2010.894;207.7928;7;7;0;8.424292;8.088197;1845487;2.252979e+008
2008.762;2.67932;-8.385088;2019.984;208.7321;7;7;0;8.438803;8.10158;1853830;2.263466e+008
2022.762;2.682105;-8.413308;2021.637;208.9029;7;7;0;8.447577;8.10967;1855346;2.265501e+008
2036.762;2.68307;-8.43822;2024.886;209.2386;7;7;0;8.450613;8.11247;1858328;2.269205e+008
2050.762;2.683284;-8.457729;2028.676;209.6302;7;7;0;8.451287;8.113092;1861806;2.273467e+008
2063.266;2.682641;-8.474434;2029.506;209.7161;7;7;0;8.449264;8.111226;1862568;2.274355e+008
2077.266;2.677927;-8.484402;2012.454;207.9539;7;7;0;8.434415;8.097533;1846918;2.254937e+008
2091.266;2.673534;-8.491942;2005.431;207.2283;7;7;0;8.42058;8.084773;1840473;2.246781e+008
2105.266;2.66882;-8.499202;1998.815;206.5446;7;7;0;8.405731;8.071078;1834402;2.239062e+008
2119.266;2.664855;-8.505327;1996.387;206.2938;7;7;0;8.393245;8.059559;1832174;2.236085e+008
2133.266;2.661909;-8.516403;2003.484;207.0271;7;7;0;8.383965;8.050997;1838687;2.243842e+008
2147.266;2.65832;-8.525882;2009.834;207.6833;7;7;0;8.372661;8.040566;1844515;2.250719e+008
2161.266;2.653605;-8.530998;2006.251;207.313;7;7;0;8.357813;8.026864;1841226;2.246399e+008
2175.266;2.648998;-8.536258;2005.074;207.1914;7;7;0;8.343302;8.013472;1840146;2.24478e+008
2189.266;2.644284;-8.53983;2000.01;206.6682;7;7;0;8.328453;7.999766;1835499;2.238804e+008
2203.266;2.640748;-8.542127;2002.424;206.9176;7;7;0;8.317317;7.989486;1837714;2.241276e+008
2217.266;2.63732;-8.544964;2003.816;207.0614;7;7;0;8.306519;7.979515;1838992;2.24261e+008
2231.266;2.633784;-8.547506;2002.815;206.958;7;7;0;8.295382;7.969233;1838073;2.24126e+008
2245.266;2.630248;-8.549661;2001.021;206.7726;7;7;0;8.284247;7.95895;1836426;2.239021e+008
2259.266;2.62682;-8.551152;1996.508;206.3062;7;7;0;8.273448;7.948977;1832284;2.233748e+008
2273.266;2.623606;-8.552292;1991.292;205.7673;7;7;0;8.263325;7.939626;1827498;2.227705e+008
2287.266;2.621356;-8.554594;1994.746;206.1242;7;7;0;8.256238;7.93308;1830668;2.231423e+008
2301.266;2.618998;-8.556342;1994.443;206.0928;7;7;0;8.248813;7.926222;1830389;2.230931e+008
2315.266;2.616641;-8.557444;1991.984;205.8388;7;7;0;8.241389;7.919363;1828133;2.228027e+008
2329.266;2.61482;-8.558998;1994.587;206.1077;7;7;0;8.235653;7.914063;1830521;2.23082e+008
2343.266;2.612891;-8.561177;1993.902;206.037;7;7;0;8.229578;7.908451;1829893;2.229929e+008
2357.266;2.611391;-8.563694;1996.503;206.3057;7;7;0;8.224854;7.904086;1832280;2.232741e+008
2371.266;2.609998;-8.566164;1999.021;206.5659;7;7;0;8.220467;7.900031;1834590;2.235466e+008
2385.266;2.608605;-8.568262;2000.309;206.699;7;7;0;8.21608;7.895978;1835773;2.236815e+008
2399.266;2.607213;-8.570217;2000.802;206.75;7;7;0;8.211693;7.891924;1836225;2.237276e+008
2413.266;2.60582;-8.572039;2000.478;206.7164;7;7;0;8.207307;7.887871;1835928;2.236823e+008
2427.266;2.604373;-8.573888;1998.944;206.5579;7;7;0;8.20275;7.88366;1834520;2.235014e+008
2441.266;2.603462;-8.575974;2003.262;207.0042;7;7;0;8.199882;7.881009;1838483;2.239783e+008
2455.266;2.602284;-8.577661;2001.347;206.8062;7;7;0;8.19617;7.877578;1836725;2.237564e+008
2469.266;2.601159;-8.579718;1999.989;206.666;7;7;0;8.192627;7.874303;1835479;2.235974e+008
2483.266;2.599927;-8.581253;1996.316;206.2864;7;7;0;8.188746;7.870717;1832108;2.231787e+008
2497.266;2.598748;-8.583241;1992.732;205.916;7;7;0;8.185034;7.867285;1828819;2.227703e+008
2511.266;2.597891;-8.584443;1990.86;205.7226;7;7;0;8.182334;7.86479;1827101;2.225555e+008
2525.266;2.597677;-8.586572;1994.215;206.0693;7;7;0;8.181659;7.864165;1830180;2.229291e+008
2539.266;2.597462;-8.588133;1996.022;206.256;7;7;0;8.180984;7.863542;1831838;2.231298e+008
2553.266;2.597195;-8.58889;1995.498;206.2019;7;7;0;8.18014;7.862762;1831358;2.230695e+008
2567.266;2.59698;-8.588699;1994.626;206.1117;7;7;0;8.179466;7.862139;1830557;2.229706e+008
2580.184;2.597088;-8.589038;1995.682;206.2209;8;8;0;8.179804;7.86245;1831526;2.230893e+008
2594.184;2.597248;-8.589181;1997.02;206.3591;8;8;0;8.180309;7.862918;1832754;2.2324e+008
2608.184;2.597462;-8.590109;1997.271;206.3851;8;8;0;8.180984;7.863542;1832985;2.232694e+008
2622.184;2.59773;-8.589998;1998.201;206.4811;8;8;0;8.181828;7.864321;1833838;2.233751e+008
2636.184;2.597945;-8.589234;1997.655;206.4248;8;8;0;8.182503;7.864946;1833338;2.233155e+008
2650.184;2.598159;-8.588642;1997.171;206.3748;8;8;0;8.183178;7.865569;1832893;2.232628e+008
2664.184;2.598427;-8.587949;1996.586;206.3143;8;8;0;8.184022;7.86635;1832356;2.231991e+008
2678.184;2.598641;-8.586859;1994.962;206.1464;8;8;0;8.184696;7.866973;1830865;2.230189e+008
2692.184;2.598855;-8.58458;1993.841;206.0306;8;8;0;8.185371;7.867597;1829837;2.22895e+008
2706.184;2.599123;-8.582506;1993.204;205.9648;8;8;0;8.186215;7.868377;1829252;2.228255e+008
2718.35;2.599927;-8.582411;1998.148;206.4757;8;8;0;8.188746;7.870717;1833789;2.233834e+008
2732.35;2.599177;-8.578188;1987.414;205.3665;8;8;0;8.186384;7.868533;1823939;2.221786e+008
2745.184;2.599391;-8.575422;1987.046;205.3285;9;9;0;8.187058;7.869157;1823601;2.221388e+008
2759.184;2.601695;-8.578904;2004.994;207.1832;9;9;0;8.194314;7.875863;1840073;2.241604e+008
2773.184;2.601748;-8.577721;2001.209;206.792;9;9;0;8.194483;7.876019;1836599;2.237375e+008
2787.184;2.601748;-8.57394;1998.291;206.4905;9;9;0;8.194483;7.876019;1833921;2.234113e+008
2801.184;2.601962;-8.571177;1996.685;206.3245;9;9;0;8.195157;7.876642;1832447;2.232332e+008
2815.184;2.603088;-8.573334;2004.059;207.0865;9;9;0;8.198701;7.879918;1839215;2.240649e+008
2829.184;2.603302;-8.574511;2004.063;207.087;9;9;0;8.199376;7.880541;1839218;2.240668e+008
2842.196;2.603516;-8.575987;2005.409;207.226;9;9;0;8.20005;7.881165;1840453;2.242186e+008
2855.198;2.603355;-8.575595;2005.03;207.1869;9;9;0;8.199545;7.880697;1840106;2.241752e+008
2869.198;2.603088;-8.577749;2007.409;207.4327;9;9;0;8.198701;7.879918;1842289;2.244395e+008
2883.198;2.601748;-8.571135;2007.308;207.4222;9;9;0;8.194483;7.876019;1842196;2.244194e+008
2897.198;2.599391;-8.559127;2004.119;207.0927;9;9;0;8.187058;7.869157;1839270;2.240475e+008
2911.198;2.597141;-8.545554;2006.524;207.3412;9;9;0;8.179972;7.862606;1841476;2.243016e+008
2925.198;2.591248;-8.527539;1992.675;205.9101;9;9;0;8.161411;7.845448;1828766;2.227153e+008
2939.198;2.586534;-8.508207;2006.001;207.2872;9;9;0;8.146564;7.831719;1840997;2.24174e+008
2953.198;2.57882;-8.479471;2007.252;207.4165;9;9;0;8.122267;7.80925;1842145;2.242634e+008
2967.198;2.568588;-8.438343;1997.45;206.4036;9;9;0;8.09004;7.77944;1833149;2.231018e+008
2981.198;2.558302;-8.399617;2006.842;207.3741;9;9;0;8.057644;7.749464;1841769;2.240836e+008
2995.198;2.544481;-8.344163;2013.555;208.0678;9;9;0;8.014112;7.70917;1847929;2.247426e+008
3009.198;2.522891;-8.268785;2001.318;206.8033;9;9;0;7.946114;7.646197;1836699;2.232361e+008
3023.198;2.501248;-8.191158;2004.325;207.114;9;9;0;7.877948;7.583029;1839458;2.234303e+008
3037.198;2.480034;-8.119737;2013.397;208.0514;9;9;0;7.811131;7.521072;1847784;2.243026e+008
3051.198;2.447141;-8.015245;1994.813;206.1311;9;9;0;7.707531;7.424932;1830729;2.220187e+008
3065.198;2.416659;-7.909246;2003.542;207.0331;9;9;0;7.611525;7.335756;1838740;2.227915e+008
3079.198;2.383766;-7.790831;2005.209;207.2053;9;9;0;7.507925;7.239438;1840270;2.227622e+008
3093.198;2.349534;-7.680518;1996.187;206.2731;9;9;0;7.400107;7.139099;1831990;2.215375e+008
3107.198;2.318731;-7.572444;2017.308;208.4555;9;9;0;7.303088;7.048725;1851373;2.236792e+008
3121.198;2.273838;-7.422246;1995.35;206.1866;9;9;0;7.161694;6.916867;1831222;2.20953e+008
3135.198;2.231409;-7.280396;1990.326;205.6674;9;9;0;7.028061;6.792086;1826611;2.201218e+008
3149.198;2.200124;-7.164195;2000.596;206.7286;9;9;0;6.929523;6.699977;1836036;2.21054e+008
3163.198;2.166749;-7.062377;2000.122;206.6797;9;9;0;6.824405;6.601623;1835601;2.207843e+008
3177.198;2.133534;-6.945093;2018.163;208.5439;9;9;0;6.719793;6.503646;1852158;2.225577e+008
3191.198;2.089391;-6.795835;2008.988;207.5959;9;9;0;6.58076;6.373283;1843738;2.212573e+008
3205.198;2.046802;-6.645216;2000.842;206.754;9;9;0;6.446621;6.247346;1836262;2.200827e+008
3219.198;2.011659;-6.511042;2009.046;207.6019;9;9;0;6.335935;6.14331;1843791;2.207554e+008
3233.198;1.974374;-6.406305;2022.319;208.9734;9;9;0;6.2185;6.03281;1855972;2.219684e+008
3247.198;1.928624;-6.273848;2009.772;207.6768;9;9;0;6.074406;5.89706;1844457;2.20292e+008
3261.198;1.883945;-6.137364;1990.732;205.7094;9;9;0;5.933686;5.764311;1826984;2.179155e+008
3275.198;1.851909;-6.033497;1995.555;206.2078;9;9;0;5.832786;5.669017;1831410;2.182354e+008
3289.198;1.817838;-5.924901;2000.066;206.674;9;9;0;5.725474;5.567568;1835550;2.18507e+008
3303.198;1.780606;-5.816861;1998.44;206.5059;9;9;0;5.608208;5.456591;1834058;2.180872e+008
3317.198;1.74482;-5.710472;1994.196;206.0674;9;9;0;5.495497;5.349808;1830163;2.173918e+008
3331.198;1.716053;-5.629128;2000.817;206.7515;9;9;0;5.40489;5.263884;1836239;2.179262e+008
3345.198;1.687231;-5.548574;2000.328;206.701;9;9;0;5.314114;5.177726;1835790;2.176853e+008
3359.198;1.652356;-5.457064;2000.062;206.6735;9;9;0;5.204271;5.073371;1835546;2.174293e+008
3373.198;1.619892;-5.371598;1991.788;205.8185;9;9;0;5.102022;4.976133;1827952;2.163194e+008
3387.198;1.591767;-5.304033;1994.855;206.1354;9;9;0;5.013439;4.891814;1830767;2.164698e+008
3401.198;1.564713;-5.238317;1990.037;205.6376;9;9;0;4.928231;4.810642;1826346;2.157719e+008
3415.198;1.541303;-5.179689;2001.368;206.8084;9;9;0;4.854496;4.740346;1836745;2.16848e+008
3429.198;1.513767;-5.114293;2001.145;206.7854;9;9;0;4.76777;4.6576;1836540;2.166445e+008
3443.198;1.487035;-5.048977;1992.851;205.9283;9;9;0;4.683574;4.577203;1828928;2.155731e+008
3457.198;1.464963;-4.990789;1989.206;205.5517;9;9;0;4.614058;4.510775;1825583;2.15036e+008
3471.198;1.446213;-4.939056;1998.896;206.553;9;9;0;4.555003;4.454309;1834476;2.159615e+008
3485.198;1.427571;-4.88789;2008.008;207.4946;9;9;0;4.496285;4.398134;1842839;2.168242e+008
3499.198;1.408874;-4.82739;2008.016;207.4954;9;9;0;4.437399;4.341765;1842846;2.167028e+008
3513.198;1.390285;-4.77342;1999.195;206.5839;9;9;0;4.37885;4.285688;1834751;2.156299e+008
3527.198;1.376088;-4.727212;1996.289;206.2836;9;9;0;4.334136;4.242841;1832083;2.152242e+008
3541.198;1.363231;-4.681403;2000.845;206.7544;9;9;0;4.293642;4.204021;1836265;2.156317e+008
3555.198;1.349196;-4.630431;2005.601;207.2458;9;9;0;4.249434;4.161625;1840630;2.160526e+008
3569.198;1.33516;-4.578152;2005.384;207.2234;9;9;0;4.205228;4.119212;1840430;2.159376e+008
3583.198;1.322142;-4.52688;1998.612;206.5237;9;9;0;4.164227;4.079857;1834216;2.151238e+008
3597.198;1.314963;-4.498221;2008.106;207.5047;9;9;0;4.141617;4.058149;1842929;2.160988e+008
3611.198;1.300285;-4.446116;2003.175;206.9952;9;9;0;4.095385;4.013746;1838403;2.154725e+008
3625.198;1.287803;-4.400522;2001.053;206.7759;9;9;0;4.056072;3.975972;1836456;2.151629e+008
3639.198;1.278535;-4.36404;2004.569;207.1393;9;9;0;4.026882;3.947916;1839683;2.154805e+008
3653.198;1.266803;-4.320222;2004.31;207.1125;9;9;0;3.98993;3.912388;1839445;2.153761e+008
3667.198;1.256517;-4.285091;2004.414;207.1232;9;9;0;3.957534;3.88123;1839540;2.153202e+008
3681.198;1.249499;-4.257298;2004.742;207.1571;9;9;0;3.935431;3.859966;1839841;2.153096e+008
3695.198;1.239535;-4.222973;1992.156;205.8565;9;9;0;3.904047;3.829766;1828290;2.138933e+008
3709.198;1.234874;-4.201003;1996.195;206.2739;9;9;0;3.889368;3.815637;1831997;2.142966e+008
3723.198;1.229838;-4.177081;2002.914;206.9682;9;9;0;3.873507;3.800369;1838163;2.149851e+008
3737.198;1.223356;-4.151742;1999.029;206.5668;9;9;0;3.853091;3.780713;1834598;2.14526e+008
3751.198;1.218642;-4.129638;1995.933;206.2469;9;9;0;3.838243;3.766415;1831757;2.141631e+008
3765.198;1.214624;-4.106139;1996.755;206.3318;9;9;0;3.825588;3.754227;1832511;2.142252e+008
3779.198;1.210928;-4.084428;1998.943;206.5578;9;9;0;3.813946;3.743013;1834519;2.144358e+008
3793.198;1.206321;-4.060259;1997.688;206.4282;9;9;0;3.799435;3.729034;1833368;2.142713e+008
3807.198;1.201553;-4.03531;1991.706;205.81;9;9;0;3.784418;3.714566;1827877;2.135987e+008
3821.198;1.196999;-4.011156;1981.596;204.7653;9;9;0;3.770076;3.700746;1818599;2.124852e+008
3835.198;1.193303;-3.990328;1977.642;204.3568;9;9;0;3.758434;3.689526;1814970;2.120374e+008
3849.198;1.190892;-3.972097;1977.649;204.3575;9;9;0;3.750841;3.682208;1814977;2.120226e+008
3863.198;1.189767;-3.957649;1975.679;204.1539;9;9;0;3.747298;3.678793;1813169;2.118042e+008
3877.198;1.189553;-3.946387;1981.13;204.7171;9;9;0;3.746623;3.678142;1818171;2.123871e+008
3891.198;1.189339;-3.935643;1977.057;204.2963;9;9;0;3.745948;3.677492;1814433;2.119491e+008
3905.198;1.189071;-3.923857;1970.3;203.5981;9;9;0;3.745105;3.676679;1808232;2.112231e+008
3919.198;1.188856;-3.913677;1957.138;202.238;9;9;0;3.744429;3.676028;1796153;2.098106e+008
3931.646;1.188642;-3.903569;1949.177;201.4154;10;10;0;3.743755;3.675378;1788847;2.089559e+008
3945.646;1.191642;-3.899271;1951.033;201.6071;10;10;0;3.753204;3.684485;1790550;2.091739e+008
3959.646;1.198606;-3.901762;1977.97;204.3907;10;10;0;3.775138;3.705624;1815272;2.121067e+008
3972.49;1.198124;-3.895603;1945.732;201.0594;10;10;0;3.77362;3.704161;1785685;2.086466e+008
3986.49;1.174713;-3.835584;1858.458;192.041;10;10;0;3.699885;3.633082;1705589;1.991463e+008
4000.49;1.15141;-3.781586;1779.963;183.9298;10;10;0;3.626488;3.562279;1633551;1.906e+008
4014.49;1.109946;-3.693829;1656.356;171.1572;10;10;0;3.495892;3.436174;1520112;1.771406e+008
4028.49;1.063392;-3.592588;1528.179;157.9122;10;10;0;3.349267;3.294401;1402478;1.632011e+008
4042.49;1.016624;-3.483546;1403.506;145.0293;10;10;0;3.201966;3.151772;1288060;1.496731e+008
4056.49;0.9698566;-3.365956;1286.142;132.9016;10;10;0;3.054666;3.00894;1180350;1.369613e+008
4070.49;0.9234637;-3.255047;1170.821;120.9851;10;10;0;2.908547;2.867051;1074515;1.24504e+008
4084.49;0.8766958;-3.161227;1053.478;108.8596;10;10;0;2.761247;2.723812;966823.6;1.118655e+008
4098.49;0.8299816;-3.097967;944.0795;97.55507;10;10;0;2.614115;2.580531;866423.8;1.001053e+008
4112.49;0.7832673;-3.048928;832.5576;86.03113;10;10;0;2.466984;2.437045;764075.3;8.81535e+007
4126.49;0.7367138;-2.9928;724.9121;74.90774;10;10;0;2.320358;2.293847;665284.2;7.664587e+007
4140.49;0.689946;-2.935105;622.5666;64.33201;10;10;0;2.173058;2.149784;571357.1;6.572998e+007
4154.49;0.6431781;-2.881227;522.0772;53.94808;10;10;0;2.025758;2.005513;479133.5;5.504094e+007
4168.49;0.5967317;-2.824459;428.9764;44.32764;10;10;0;1.87947;1.862026;393690.8;4.516077e+007
4182.49;0.5500175;-2.757619;343.3337;35.47788;10;10;0;1.732339;1.717505;315092.6;3.609248e+007
4196.49;0.5033033;-2.706709;271.7561;28.08151;10;10;0;1.585207;1.572774;249402.6;2.852667e+007
4210.49;0.456589;-2.647462;206.7647;21.36573;10;10;0;1.438076;1.427833;189757.2;2.167298e+007
4224.49;0.4100354;-2.588309;155.9607;16.11597;10;10;0;1.29145;1.283182;143132;1.63241e+007
4238.49;0.3633212;-2.537897;114.0275;11.78286;10;10;0;1.144319;1.137821;104648.1;1.19177e+007
4252.49;0.3164998;-2.491334;80.73494;8.342627;10;10;0;0.9968497;0.991914;74094.05;8425790
4266.49;0.2700534;-2.452155;56.09494;5.796488;10;10;0;0.8505619;0.846965;51480.82;5845791
4280.49;0.2233927;-2.439174;51.85955;5.358831;10;10;0;0.7035991;0.7011354;47593.82;5396536
4294.49;0.1766785;-2.43436;51.42429;5.313853;10;10;0;0.5564676;0.554925;47194.36;5343423
4308.49;0.1298571;-2.430532;51.48387;5.32001;10;10;0;0.4089986;0.4081645;47249.04;5341769
4322.49;0.08335709;-2.427058;51.05923;5.276131;10;10;0;0.262542;0.262198;46859.33;5289983
4336.49;0.03669641;-2.423747;51.00898;5.270939;10;10;0;0.1155792;0.1155125;46813.22;5277031
4350.49;-0.010125;-2.420856;51.11138;5.28152;10;10;0;-0.03188975;-0.03189483;46907.19;5279835
4364.49;-0.05662497;-2.417912;50.3265;5.200415;10;10;0;-0.1783464;-0.1785056;46186.87;5191140
4378.49;-0.1032857;-2.395387;39.42072;4.073482;10;10;0;-0.3253092;-0.3258395;36178.15;4060231
4392.49;-0.1055892;-2.392248;39.54587;4.086414;10;10;0;-0.3325645;-0.3331187;36293.01;4072825
4406.49;-0.1058571;-2.389682;39.573;4.089218;10;10;0;-0.3334081;-0.3339652;36317.91;4075584
4420.49;-0.1060714;-2.38713;39.59485;4.091475;10;10;0;-0.3340831;-0.3346424;36337.96;4077807
4434.49;-0.1062857;-2.384235;39.54704;4.086536;10;10;0;-0.334758;-0.3353196;36294.08;4072856
4448.49;-0.1066071;-2.381807;39.52566;4.084327;10;10;0;-0.3357703;-0.3363353;36274.46;4070613
4462.49;-0.1068214;-2.379463;39.74919;4.107424;10;10;0;-0.3364453;-0.3370125;36479.6;4093605
4476.49;-0.1070357;-2.376684;39.66517;4.098743;10;10;0;-0.3371202;-0.3376897;36402.5;4084925
4490.49;-0.1071964;-2.374477;39.61047;4.09309;10;10;0;-0.3376264;-0.3381976;36352.29;4079271
4504.49;-0.1074642;-2.371751;39.65499;4.09769;10;10;0;-0.33847;-0.3390441;36393.15;4083821
4518.49;-0.1077321;-2.369151;39.77435;4.110024;10;10;0;-0.3393137;-0.3398907;36502.7;4096079
4532.49;-0.1079464;-2.366482;39.52243;4.083993;10;10;0;-0.3399886;-0.3405678;36271.5;4070108
4546.49;-0.1082142;-2.363908;39.78075;4.110686;10;10;0;-0.3408322;-0.3414144;36508.57;4096676
4560.49;-0.1084285;-2.361237;41.00998;4.237707;10;10;0;-0.3415071;-0.3420916;37636.69;4223234
4574.49;-0.1086428;-2.358397;40.50873;4.18591;10;10;0;-0.3421821;-0.3427689;37176.67;4171587
4588.49;-0.1088571;-2.355458;39.00192;4.030207;10;10;0;-0.342857;-0.3434461;35793.8;4016389
4602.49;-0.1091249;-2.352202;39.84298;4.117116;10;10;0;-0.3437006;-0.3442926;36565.68;4102965
4616.49;-0.1093392;-2.348547;39.8712;4.120032;10;10;0;-0.3443756;-0.3449699;36591.57;4105844
4630.49;-0.1096071;-2.344228;39.74044;4.10652;10;10;0;-0.3452192;-0.3458164;36471.57;4092343
4644.49;-0.1098214;-2.340185;39.65029;4.097205;10;10;0;-0.3458941;-0.3464937;36388.84;4083033
4658.49;-0.1100357;-2.334786;39.86318;4.119204;10;10;0;-0.346569;-0.347171;36584.22;4104928
4672.49;-0.1103035;-2.32984;39.74276;4.10676;10;10;0;-0.3474126;-0.3480175;36473.7;4092492
4686.49;-0.1105714;-2.323522;39.95189;4.12837;10;10;0;-0.3482563;-0.3488641;36665.63;4113993
4700.49;-0.1107321;-2.316612;40.02997;4.136438;10;10;0;-0.3487625;-0.3493721;36737.29;4122012
4714.49;-0.1109999;-2.308509;40.04973;4.138481;10;10;0;-0.3496061;-0.3502187;36755.43;4124012
4728.49;-0.1112142;-2.300607;40.48479;4.183437;10;10;0;-0.350281;-0.350896;37154.7;4168783
4742.49;-0.1114821;-2.293066;40.83958;4.220098;10;10;0;-0.3511247;-0.3517426;37480.3;4205280
4756.49;-0.1116964;-2.28638;42.2424;4.365057;10;10;0;-0.3517996;-0.3524199;38767.74;4349701
4770.49;-0.1119107;-2.280181;43.63968;4.509443;10;10;0;-0.3524745;-0.3530972;40050.08;4493548
4784.49;-0.1121249;-2.274132;44.91108;4.640821;10;10;0;-0.3531494;-0.3537745;41216.9;4624431
4798.49;-0.1123928;-2.267516;46.24457;4.778615;10;10;0;-0.3539931;-0.3546211;42440.71;4761699
4812.49;-0.1126071;-2.261776;48.08681;4.96898;10;10;0;-0.354668;-0.3552985;44131.41;4951357
4826.49;-0.1128749;-2.255716;48.7641;5.038967;10;10;0;-0.3555117;-0.3561451;44752.99;5021053
4840.49;-0.1152857;-2.248295;46.78502;4.834462;10;10;0;-0.3631044;-0.3637653;42936.7;4816908
4854.49;-0.1175892;-2.242135;46.19917;4.773924;10;10;0;-0.3703598;-0.3710473;42399.04;4756244
4868.49;-0.1205357;-2.234115;43.44171;4.488986;10;10;0;-0.3796399;-0.3803623;39868.39;4471943
4882.49;-0.1252499;-2.227403;41.9117;4.330884;10;10;0;-0.394488;-0.3952682;38464.24;4313800
4896.49;-0.1298571;-2.220907;40.29581;4.163908;10;10;0;-0.4089987;-0.4098374;36981.26;4146878
4910.49;-0.1318392;-2.214913;40.58901;4.194206;10;10;0;-0.4152417;-0.4161062;37250.34;4176790
4924.49;-0.1339285;-2.20789;40.49322;4.184308;10;10;0;-0.4218221;-0.4227142;37162.44;4166658
4938.49;-0.1362857;-2.202782;40.62067;4.197477;10;10;0;-0.4292462;-0.4301701;37279.39;4179460
4952.49;-0.1386428;-2.198723;40.54023;4.189166;10;10;0;-0.4366702;-0.4376264;37205.58;4170873
4966.49;-0.1409464;-2.191552;40.61873;4.197277;10;10;0;-0.4439255;-0.4449138;37277.62;4178644
4980.49;-0.1432499;-2.186756;39.87264;4.120181;10;10;0;-0.4511809;-0.4522018;36592.9;4101591
4994.49;-0.1456071;-2.183429;40.73974;4.209781;10;10;0;-0.458605;-0.4596598;37388.67;4190475
5008.49;-0.1497321;-2.180554;40.42516;4.177275;10;10;0;-0.4715971;-0.4727126;37099.97;4157575
5022.49;-0.1543928;-2.177295;40.51255;4.186305;10;10;0;-0.4862765;-0.4874627;37180.17;4165948
5036.49;-0.1591071;-2.17499;40.26938;4.161177;10;10;0;-0.5011246;-0.5023845;36957;4140325
5050.49;-0.1630713;-2.172952;39.29812;4.060814;10;10;0;-0.5136105;-0.514934;36065.64;4039957
5064.49;-0.1653214;-2.17196;40.40974;4.175682;10;10;0;-0.5206972;-0.5220576;37085.82;4153939
5078.49;-0.1676785;-2.166385;40.45855;4.180725;10;10;0;-0.5281212;-0.5295207;37130.61;4158645
5092.49;-0.1700356;-2.158231;41.61274;4.299992;10;10;0;-0.5355453;-0.5369845;38189.87;4276964
5106.49;-0.1723392;-2.15064;40.39888;4.174559;10;10;0;-0.5428007;-0.5442792;37075.85;4151899
5120.49;-0.1746428;-2.14306;40.55263;4.190447;10;10;0;-0.550056;-0.5515744;37216.96;4167397
5134.49;-0.1769999;-2.13663;41.22927;4.260366;10;10;0;-0.5574801;-0.5590398;37837.94;4236616
5148.49;-0.179357;-2.128601;40.55136;4.190316;10;10;0;-0.5649041;-0.5665057;37215.8;4166645
5162.49;-0.1817142;-2.118509;40.79477;4.215468;10;10;0;-0.5723282;-0.5739723;37439.18;4191341
5176.49;-0.1839642;-2.113061;40.7975;4.21575;10;10;0;-0.5794148;-0.5810999;37441.68;4191323
5190.49;-0.1863213;-2.110105;40.87094;4.223339;10;10;0;-0.5868388;-0.5885675;37509.08;4198555
5204.49;-0.1886785;-2.105784;40.91531;4.227923;10;10;0;-0.5942629;-0.5960357;37549.8;4202799
5218.49;-0.1910356;-2.102251;40.81747;4.217813;10;10;0;-0.601687;-0.6035044;37460.01;4192435
5232.49;-0.1933392;-2.103658;40.94188;4.230669;10;10;0;-0.6089423;-0.6108039;37574.19;4204907
5246.49;-0.1956428;-2.134209;40.85978;4.222186;10;10;0;-0.6161976;-0.618104;37498.84;4196169
5260.49;-0.1979463;-2.160025;40.94444;4.230934;10;10;0;-0.623453;-0.6254046;37576.54;4204556
5274.49;-0.200357;-2.174676;41.0685;4.243754;10;10;0;-0.6310458;-0.6330453;37690.4;4216974
5288.49;-0.2027142;-2.188699;40.83488;4.219613;10;10;0;-0.6384699;-0.6405168;37475.99;4192672
5302.49;-0.2049642;-2.220248;40.99315;4.235968;10;10;0;-0.6455564;-0.6476492;37621.25;4208622
5316.49;-0.2073213;-2.250301;40.99074;4.235719;10;10;0;-0.6529805;-0.6551218;37619.04;4208060
5330.49;-0.2096785;-2.306233;41.01339;4.238058;10;10;0;-0.6604046;-0.662595;37639.81;4210070
5344.49;-0.2120356;-2.375764;40.94664;4.231162;10;10;0;-0.6678287;-0.6700687;37578.56;4202904
5358.49;-0.2142856;-2.427021;40.99451;4.236107;10;10;0;-0.6749153;-0.6772032;37622.48;4207517
5372.49;-0.2166427;-2.471157;40.81694;4.217759;10;10;0;-0.6823394;-0.6846779;37459.52;4188979
5386.49;-0.2189999;-2.506409;41.09423;4.246412;10;10;0;-0.6897634;-0.6921533;37714;4217122
5400.49;-0.221357;-2.533574;40.90723;4.227089;10;10;0;-0.6971875;-0.6996292;37542.39;4197618
5414.49;-0.2237142;-2.553358;41.27916;4.265522;10;10;0;-0.7046116;-0.7071057;37883.73;4235467
5428.49;-0.2260713;-2.581587;40.94091;4.230569;10;10;0;-0.7120357;-0.7145827;37573.3;4200446
5442.49;-0.2283213;-2.61375;40.97166;4.233747;10;10;0;-0.7191222;-0.7217204;37601.52;4203301
5456.49;-0.2306785;-2.64958;41.12782;4.249883;10;10;0;-0.7265463;-0.7291985;37744.83;4219006
5470.49;-0.2330356;-2.677461;40.97512;4.234105;10;10;0;-0.7339704;-0.7366772;37604.7;4203027
5484.49;-0.2353392;-2.704799;41.22916;4.260355;10;10;0;-0.7412258;-0.7439865;37837.84;4228776
5498.49;-0.2376427;-2.750531;41.04974;4.241815;10;10;0;-0.7484811;-0.7512963;37673.18;4210066
5512.49;-0.2399999;-2.795959;41.19318;4.256638;10;10;0;-0.7559052;-0.7587766;37804.82;4224461
5526.49;-0.242357;-2.83552;41.00675;4.237373;10;10;0;-0.7633292;-0.7662575;37633.72;4205028
5540.49;-0.2447142;-2.866063;41.08192;4.245141;10;10;0;-0.7707533;-0.773739;37702.71;4212421
5554.49;-0.2470713;-2.899498;41.10098;4.24711;10;10;0;-0.7781774;-0.781221;37720.2;4214060
5568.49;-0.2493213;-2.921736;41.10183;4.247198;10;10;0;-0.785264;-0.7883634;37720.98;4213846
5582.49;-0.2516784;-2.939446;41.12509;4.249601;10;10;0;-0.792688;-0.7958465;37742.33;4215915
5596.49;-0.2540356;-2.95739;41.14221;4.25137;10;10;0;-0.8001121;-0.8033302;37758.04;4217354
5610.49;-0.2563392;-2.975724;41.26607;4.264169;10;10;0;-0.8073674;-0.8106443;37871.71;4229741
5624.49;-0.2586427;-2.993686;41.31414;4.269136;10;10;0;-0.8146228;-0.817959;37915.82;4234358
5638.49;-0.2609999;-3.004804;41.25379;4.2629;10;10;0;-0.8220469;-0.8254443;37860.45;4227857
5652.49;-0.263357;-3.009184;41.20214;4.257563;10;10;0;-0.8294709;-0.8329301;37813.04;4222248
5666.49;-0.2656606;-3.016958;41.08621;4.245584;10;10;0;-0.8367263;-0.8402465;37706.65;4210060
5680.49;-0.2680177;-3.026628;41.25485;4.26301;10;10;0;-0.8441503;-0.8477334;37861.41;4227023
5694.49;-0.2703213;-3.035241;41.30251;4.267934;10;10;0;-0.8514056;-0.8550508;37905.15;4231597
5708.49;-0.2726784;-3.038388;41.19565;4.256892;10;10;0;-0.8588297;-0.8625389;37807.09;4220333
5722.49;-0.274982;-3.043295;41.30471;4.268162;10;10;0;-0.8660851;-0.8698574;37907.17;4231196
5736.49;-0.2773927;-3.050013;41.18126;4.255405;10;10;0;-0.8736779;-0.8775169;37793.88;4218227
5750.49;-0.2796427;-3.054891;41.16908;4.254147;10;10;0;-0.8807645;-0.8846661;37782.7;4216677
5764.49;-0.2819999;-3.053521;41.33584;4.271379;10;10;0;-0.8881886;-0.8921565;37935.74;4233441
5778.49;-0.284357;-3.051797;41.36309;4.274194;10;10;0;-0.8956127;-0.8996474;37960.75;4235914
5792.49;-0.2867141;-3.054249;41.41157;4.279204;10;10;0;-0.9030367;-0.9071387;38005.24;4240561
5806.49;-0.2889641;-3.056739;41.32036;4.269779;10;10;0;-0.9101233;-0.9142902;37921.54;4230919
5820.49;-0.2913213;-3.060026;41.44146;4.282293;10;10;0;-0.9175474;-0.9217828;38032.68;4243001
5834.49;-0.2936784;-3.062987;41.14896;4.252068;10;10;0;-0.9249714;-0.9292758;37764.23;4212737
5848.49;-0.295982;-3.06592;41.32473;4.270231;10;10;0;-0.9322267;-0.9365992;37925.55;4230423
5862.49;-0.2982856;-3.068705;41.47276;4.285527;10;10;0;-0.9394821;-0.943923;38061.4;4245266
5876.49;-0.3006427;-3.071699;41.23435;4.260892;10;10;0;-0.9469062;-0.9514178;37842.61;4220545
5890.49;-0.3029999;-3.074354;41.31055;4.268765;10;10;0;-0.9543303;-0.9589132;37912.54;4228027
5904.49;-0.305357;-3.076705;41.40067;4.278078;10;10;0;-0.9617544;-0.9664091;37995.24;4236933
5918.49;-0.3076606;-3.079056;41.3595;4.273824;10;10;0;-0.9690098;-0.9737352;37957.46;4232410
5932.49;-0.3100177;-3.081989;41.42185;4.280266;10;10;0;-0.9764338;-0.9812321;38014.68;4238472
5946.49;-0.3123213;-3.084415;41.57207;4.29579;10;10;0;-0.9836891;-0.9885593;38152.55;4253532
5960.49;-0.3146784;-3.085937;41.48181;4.286462;10;10;0;-0.9911131;-0.9960573;38069.71;4243978
5974.49;-0.3170356;-3.088297;41.37765;4.275699;10;10;0;-0.9985372;-1.003556;37974.12;4233005
5988.49;-0.3193391;-3.090335;41.53475;4.291933;10;10;0;-1.005792;-1.010885;38118.29;4248765
6002.49;-0.3216427;-3.091994;41.40684;4.278715;10;10;0;-1.013048;-1.018214;38000.9;4235370
6016.49;-0.3239998;-3.093849;41.60948;4.299655;10;10;0;-1.020472;-1.025714;38186.88;4255778
6030.49;-0.326357;-3.094861;41.70915;4.309954;10;10;0;-1.027896;-1.033215;38278.34;4265652
6044.49;-0.3287142;-3.096473;41.6567;4.304534;10;10;0;-1.03532;-1.040717;38230.21;4259969
6058.49;-0.3309641;-3.098082;41.58;4.296609;10;10;0;-1.042407;-1.047878;38159.82;4251821
6072.49;-0.3333213;-3.09933;41.64352;4.303172;10;10;0;-1.049831;-1.05538;38218.11;4257996
6086.49;-0.3356784;-3.10008;41.47717;4.285983;10;10;0;-1.057255;-1.062883;38065.45;4240669
6100.49;-0.3380355;-3.101311;41.42901;4.281006;10;10;0;-1.064679;-1.070387;38021.25;4235427
6114.49;-0.3403927;-3.102285;41.5544;4.293963;10;10;0;-1.072103;-1.077891;38136.32;4247927
6128.49;-0.3426427;-3.103349;41.488;4.287102;10;10;0;-1.07919;-1.085055;38075.39;4240836
6142.49;-0.3449998;-3.104103;41.70216;4.309232;10;10;0;-1.086614;-1.09256;38271.93;4262407
6156.49;-0.3473034;-3.104848;41.58311;4.29693;10;10;0;-1.093869;-1.099896;38162.68;4249928
6170.49;-0.3497141;-3.105025;41.67165;4.306079;10;10;0;-1.101462;-1.107573;38243.93;4258649
6184.49;-0.3520177;-3.105778;41.43653;4.281783;10;10;0;-1.108717;-1.114909;38028.15;4234310
6198.49;-0.3543213;-3.1062;41.52333;4.290752;10;10;0;-1.115973;-1.122246;38107.81;4242869
6212.49;-0.356732;-3.106285;41.47121;4.285367;10;10;0;-1.123565;-1.129925;38059.97;4237218
6226.49;-0.3590355;-3.106756;41.75569;4.314764;10;10;0;-1.130821;-1.137263;38321.06;4265971
6240.49;-0.3612856;-3.107068;42.14785;4.355287;10;10;0;-1.137907;-1.144431;38680.96;4305728
6254.49;-0.3636427;-3.107155;41.44181;4.282329;10;10;0;-1.145331;-1.151941;38033;4233282
6268.49;-0.3660534;-3.107376;41.41339;4.279392;10;10;0;-1.152924;-1.159622;38006.91;4230054
6282.49;-0.3683034;-3.106419;41.69023;4.308;10;10;0;-1.160011;-1.166791;38260.99;4258026
6296.49;-0.3707141;-3.10643;41.72809;4.311911;10;10;0;-1.167603;-1.174474;38295.73;4261565
6310.49;-0.3730713;-3.106658;41.56972;4.295547;10;10;0;-1.175028;-1.181986;38150.39;4245073
6324.49;-0.3753213;-3.106628;41.64677;4.303509;10;10;0;-1.182114;-1.189157;38221.1;4252636
6338.49;-0.3776784;-3.106903;41.51531;4.289924;10;10;0;-1.189538;-1.19667;38100.45;4238894
6352.49;-0.3800355;-3.106874;41.70183;4.309198;10;10;0;-1.196962;-1.204184;38271.63;4257619
6366.49;-0.3822855;-3.106989;41.6858;4.307541;10;10;0;-1.204049;-1.211356;38256.92;4255677
6380.49;-0.3846427;-3.107054;41.7132;4.310372;10;10;0;-1.211473;-1.218871;38282.06;4258153
6394.49;-0.3869998;-3.105156;41.80534;4.319894;10;10;0;-1.218897;-1.226387;38366.63;4267239
6408.49;-0.3893569;-3.10307;41.61982;4.300724;10;10;0;-1.226321;-1.233902;38196.36;4247983
6422.49;-0.3917141;-3.102127;41.73939;4.313079;10;10;0;-1.233745;-1.241419;38306.1;4259867
6436.49;-0.3939641;-3.102767;41.71334;4.310388;10;10;0;-1.240832;-1.248594;38282.2;4256903
6450.49;-0.3963212;-3.108696;41.61636;4.300365;10;10;0;-1.248256;-1.256112;38193.18;4246686
6464.49;-0.398732;-3.111361;41.74938;4.314111;10;10;0;-1.255849;-1.263801;38315.27;4259932
6478.49;-0.4010355;-3.086754;41.87462;4.327052;10;10;0;-1.263104;-1.271149;38430.2;4272397
6492.49;-0.4033927;-3.033491;41.61201;4.299916;10;10;0;-1.270528;-1.278668;38189.2;4245284
6506.49;-0.4056427;-2.971893;42.08443;4.348732;10;10;0;-1.277615;-1.285846;38622.75;4293173
6520.49;-0.4079998;-2.895406;40.61996;4.197404;10;10;0;-1.285039;-1.293367;37278.75;4143466
6534.49;-0.4103569;-2.820534;41.61336;4.300056;10;10;0;-1.292463;-1.300888;38190.43;4244479
6548.49;-0.4127141;-2.753075;41.78003;4.317279;10;10;0;-1.299887;-1.308409;38343.4;4261159
6562.49;-0.4149641;-2.691211;41.81601;4.320996;10;10;0;-1.306973;-1.31559;38376.41;4264522
6576.49;-0.4173212;-2.631494;41.67896;4.306835;10;10;0;-1.314397;-1.323112;38250.64;4250226
6590.49;-0.4196784;-2.583529;41.77824;4.317093;10;10;0;-1.321822;-1.330635;38341.75;4260029
6604.49;-0.4220355;-2.536995;41.68398;4.307353;10;10;0;-1.329246;-1.338159;38255.25;4250098
6618.49;-0.4242855;-2.49495;41.76523;4.315749;10;10;0;-1.336332;-1.345342;38329.82;4258077
6632.49;-0.4266962;-2.445391;41.76661;4.315892;10;10;0;-1.343925;-1.353038;38331.08;4257889
6646.49;-0.4289998;-2.406394;41.68383;4.307338;10;10;0;-1.351181;-1.360392;38255.11;4249138
6660.49;-0.4313569;-2.370669;41.80699;4.320064;10;10;0;-1.358605;-1.367918;38368.14;4261371
6674.49;-0.433714;-2.339166;41.75478;4.314669;10;10;0;-1.366029;-1.375445;38320.22;4255730
6688.49;-0.4359641;-2.303912;41.6441;4.303233;10;10;0;-1.373115;-1.38263;38218.65;4244144
6702.49;-0.4383212;-2.2828;41.86886;4.326458;10;10;0;-1.380539;-1.390157;38424.92;4266729
6716.49;-0.4406783;-2.269425;41.68727;4.307693;10;10;0;-1.387963;-1.397686;38258.27;4247904
6730.49;-0.4430355;-2.258583;42.01744;4.341811;10;10;0;-1.395387;-1.405214;38561.28;4281226
6744.49;-0.4453927;-2.246958;44.15764;4.562965;10;10;0;-1.402812;-1.412744;40525.44;4498956
6758.49;-0.4476426;-2.239801;42.69597;4.411926;10;10;0;-1.409898;-1.419932;39184;4349722
6772.49;-0.4499998;-2.234881;40.96352;4.232906;10;10;0;-1.417322;-1.427462;37594.05;4172912
6786.49;-0.4523034;-2.228946;40.91222;4.227605;10;10;0;-1.424577;-1.434822;37546.97;4167379
6800.49;-0.4547141;-2.221112;41.52997;4.291439;10;10;0;-1.43217;-1.442525;38113.9;4229978
6814.49;-0.4570712;-2.212811;41.81624;4.32102;10;10;0;-1.439594;-1.450057;38376.63;4258815
6828.49;-0.4593212;-2.207516;41.81501;4.320893;10;10;0;-1.446681;-1.457247;38375.5;4258383
6842.49;-0.4616783;-2.206835;41.5499;4.293499;10;10;0;-1.454105;-1.464781;38132.2;4231067
6856.49;-0.4640355;-2.209716;41.7739;4.316645;10;10;0;-1.461529;-1.472315;38337.77;4253556
6870.49;-0.4662855;-2.211915;41.25059;4.262569;10;10;0;-1.468616;-1.479507;37857.51;4199969
6884.49;-0.4686962;-2.213825;43.4721;4.492126;10;10;0;-1.476208;-1.487213;39896.28;4425813
6898.49;-0.4709998;-2.21684;41.58611;4.29724;10;10;0;-1.483464;-1.494577;38165.43;4233492
6912.49;-0.4733569;-2.219661;41.71314;4.310366;10;10;0;-1.490888;-1.502113;38282.01;4246104
6926.49;-0.4757141;-2.221569;41.69129;4.308109;10;10;0;-1.498312;-1.50965;38261.96;4243560
6940.49;-0.4779641;-2.223201;41.49487;4.287812;10;10;0;-1.505399;-1.516845;38081.7;4223264
6954.49;-0.4803212;-2.225069;41.70606;4.309635;10;10;0;-1.512823;-1.524383;38275.51;4244438
6968.49;-0.4826783;-2.2272;41.49731;4.288064;10;10;0;-1.520247;-1.531921;38083.93;4222875
6982.49;-0.4850355;-2.231248;41.58349;4.29697;10;10;0;-1.527671;-1.53946;38163.03;4231326
6996.49;-0.487339;-2.235222;41.44639;4.282803;10;10;0;-1.534926;-1.546828;38037.2;4217065
7010.49;-0.4896426;-2.240595;41.51992;4.290401;10;10;0;-1.542181;-1.554197;38104.68;4224235
7024.49;-0.4919998;-2.247208;41.0525;4.2421;10;10;0;-1.549606;-1.561737;37675.71;4176364
7038.49;-0.4943569;-2.252392;41.57198;4.29578;10;10;0;-1.55703;-1.569279;38152.46;4228894
7052.49;-0.4967141;-2.256432;41.81069;4.320446;10;10;0;-1.564454;-1.57682;38371.54;4252855
7066.49;-0.4990176;-2.258962;42.87368;4.430289;10;10;0;-1.571709;-1.584191;39347.09;4360658
7080.49;-0.5013212;-2.261054;41.56773;4.295341;10;10;0;-1.578964;-1.591563;38148.55;4227518
7094.49;-0.5036248;-2.26179;41.54952;4.293459;10;10;0;-1.58622;-1.598935;38131.85;4225355
7108.49;-0.5060354;-2.262503;41.158;4.253002;10;10;0;-1.593812;-1.60665;37772.54;4185217
7122.49;-0.5083391;-2.262634;41.5073;4.289096;10;10;0;-1.601068;-1.614024;38093.1;4220425
7136.49;-0.5106426;-2.262991;41.39251;4.277235;10;10;0;-1.608323;-1.621397;37987.75;4208443
7150.49;-0.5129998;-2.265528;41.50007;4.288349;10;10;0;-1.615747;-1.628943;38086.46;4219060
7164.49;-0.5153569;-2.269275;41.50421;4.288777;10;10;0;-1.623171;-1.636489;38090.27;4219163
7178.49;-0.5177141;-2.275104;41.51854;4.290258;10;10;0;-1.630595;-1.644036;38103.42;4220301
7192.49;-0.5200176;-2.281913;42.57234;4.399151;10;10;0;-1.637851;-1.651412;39070.54;4327099
7206.49;-0.5223748;-2.289803;41.35995;4.27387;10;10;0;-1.645275;-1.65896;37957.87;4203553
7220.49;-0.5246248;-2.295136;41.14538;4.251698;10;10;0;-1.652362;-1.666165;37760.95;4181444
7234.49;-0.5270355;-2.29997;41.48827;4.287129;10;10;0;-1.659954;-1.673886;38075.63;4215965
7248.49;-0.5293926;-2.305964;41.38922;4.276895;10;10;0;-1.667378;-1.681435;37984.73;4205583
7262.49;-0.5316426;-2.312326;42.69121;4.411434;10;10;0;-1.674465;-1.688643;39179.63;4337566
7276.49;-0.5339997;-2.317477;41.55105;4.293617;10;10;0;-1.681889;-1.696193;38133.25;4221403
7290.49;-0.5363569;-2.322191;41.17556;4.254817;10;10;0;-1.689313;-1.703745;37788.65;4182940
7304.49;-0.5386604;-2.326905;41.25165;4.262679;10;10;0;-1.696568;-1.711125;37858.48;4190360
7318.49;-0.5410176;-2.333372;41.33898;4.271703;10;10;0;-1.703992;-1.718678;37938.62;4198913
7332.49;-0.5433212;-2.339353;41.37982;4.275924;10;10;0;-1.711248;-1.726059;37976.11;4202752
7346.49;-0.5456783;-2.345142;41.16382;4.253603;10;10;0;-1.718672;-1.733612;37777.87;4180498
7360.49;-0.5480355;-2.350021;39.96093;4.129305;10;10;0;-1.726096;-1.741167;36673.93;4058029
7374.49;-0.550339;-2.355386;41.37093;4.275004;10;10;0;-1.733351;-1.74855;37967.95;4200903
7388.49;-0.5526426;-2.361209;41.24443;4.261932;10;10;0;-1.740607;-1.755933;37851.85;4187749
7402.49;-0.5549462;-2.365918;41.2858;4.266208;10;10;0;-1.747862;-1.763317;37889.82;4191640
7416.49;-0.5573033;-2.369678;41.09067;4.246045;10;10;0;-1.755286;-1.770874;37710.74;4171515
7430.49;-0.559714;-2.372278;41.1583;4.253033;10;10;0;-1.762879;-1.778603;37772.8;4178057
7444.49;-0.561964;-2.376038;41.45632;4.283828;10;10;0;-1.769966;-1.785817;38046.31;4208006
7458.49;-0.5643212;-2.379676;41.5176;4.290161;10;10;0;-1.77739;-1.793375;38102.55;4213908
7472.49;-0.5666783;-2.382937;40.73219;4.209002;10;10;0;-1.784814;-1.800933;37381.75;4133879
7476.987;-0.5674283;-2.383831;41.04733;4.241566;10;10;0;-1.787176;-1.803339;37670.96;4165762