File: Ensayos/Resistencia/comp/EspD/RED3.raw
"Test Type";"Manual"
"Method Name:";"C:\INSTRON\USER\TEMPLATE\CYCLE.MTM"
"Name:";""
"Operator ID:";""
"Company:";""
"Lab name:";""
"Test date:";"23/06/2017"
"Temperature:";""
"Humidity:";""
"Note 1:";""
"Note 2:";""
"Note 3:";""
"Geometry:";"Rectangular"
"Specimen";1
"Specimen name:";""
"Width:";0.250000;"in"
"Thickness:";0.060000;"in"
"Length:";1.250000;"in"
"Diameter:";0.039370;"in"
"Inner diameter:";0.019685;"in"
"Outer diameter:";0.039370;"in"
"Wall thickness:";0.019685;"in"
"Area:";0.015000;"in*in"
"Linear density:";1.000000;"den"
"Sled weight:";2.204623;"lbf"
"Loading span:";0.000000;"mm"
"Support span:";1.000000;"mm"
"Span ratio:";"2"
"Fixture type:";"3-point"
"Comment:";""
"Included"
"Final Width:";0.250000;"in"
"Final Thickness:";0.060000;"in"
"Final Length:";1.250000;"in"
"Final Diameter:";0.039370;"in"
"Final Inner diameter:";0.019685;"in"
"Final Outer diameter:";0.039370;"in"
"Final Wall thickness:";0.019685;"in"
"Final Area:";0.015000;"in*in"
"Final Linear density:";1.000000;"den"
"Time sec";"Extension mm";"Strain 1 %";"Load N";"Stress MPa";"Cycle Count ";"Total Cycle Count ";"Repetitions Count ";"Strain [Exten.] %";"True strain %";"Tenacity gf/tex";"True stress Pa"
0;0.6717852;-0.01870966;54.73213;5.655665;0;0;0;2.115859;2.093786;50230.12;5775331
7;0.6834103;-0.01900346;55.09646;5.693312;0;0;0;2.152473;2.129635;50564.48;5815859
14;0.6951424;-0.01918575;55.35707;5.720242;0;0;0;2.189425;2.165801;50803.65;5845482
21;0.7067138;-0.02146725;64.27267;6.641522;0;0;0;2.22587;2.201459;58985.89;6789354
28;0.7332316;-0.04955687;133.1394;13.75776;0;0;0;2.309391;2.283128;122187.9;1.407548e+007
35;0.7604459;-0.07889686;195.0948;20.15984;0;0;0;2.395105;2.366872;179047.2;2.064269e+007
42;0.7838031;-0.1041888;247.2031;25.54437;0;0;0;2.468671;2.438692;226869.3;2.617498e+007
49;0.807053;-0.1296204;300.2904;31.03007;0;0;0;2.541899;2.51013;275589.9;3.181882e+007
56;0.8304102;-0.1549293;356.6618;36.85512;0;0;0;2.615465;2.581847;327324.4;3.781906e+007
63;0.8536066;-0.179559;414.8423;42.86712;0;0;0;2.688525;2.653019;380719.3;4.401961e+007
70;0.8770173;-0.2030775;476.2899;49.21672;0;0;0;2.762259;2.724797;437112.5;5.057622e+007
77;0.9003209;-0.2261249;538.9247;55.689;0;0;0;2.835656;2.796196;494595.3;5.726815e+007
84.00001;0.9237316;-0.2492155;605.1404;62.5313;0;0;0;2.909391;2.867871;555364.4;6.435058e+007
91.00001;0.9471423;-0.2714504;671.1218;69.34939;0;0;0;2.983125;2.939496;615918.4;7.141817e+007
98.00001;0.9703922;-0.2927118;739.2679;76.39117;0;0;0;3.056353;3.010577;678459.1;7.872596e+007
105;0.9937493;-0.3129139;809.9807;83.69817;0;0;0;3.129919;3.081936;743355.4;8.631786e+007
112;1.016999;-0.3313;879.9466;90.92799;0;0;0;3.203148;3.152917;807566.2;9.384055e+007
119;1.040357;-0.3501396;954.5357;98.63555;0;0;0;3.276713;3.224174;876020;1.018676e+008
126;1.06366;-0.3681159;1028.397;106.2679;0;0;0;3.35011;3.295217;943805.8;1.09828e+008
133;1.087071;-0.3851858;1100.445;113.7129;0;0;0;3.423845;3.366536;1009928;1.176063e+008
140;1.110481;-0.4025313;1165.665;120.4523;0;0;0;3.497579;3.437804;1069783;1.246652e+008
147;1.133731;-0.4237489;1238.998;128.0301;0;0;0;3.570808;3.508533;1137084;1.326018e+008
154;1.157089;-0.4459449;1317.27;136.1181;0;0;0;3.644373;3.579537;1208917;1.410788e+008
161;1.180285;-0.4703423;1392.331;143.8745;0;0;0;3.717433;3.650002;1277804;1.492229e+008
168;1.203696;-0.4949846;1467.725;151.6652;0;0;0;3.791167;3.721069;1346997;1.574151e+008
173.9;1.196624;-0.4880812;1343.874;138.8673;0;0;0;3.768895;3.699608;1233333;1.44101e+008
180.9;1.173374;-0.4653621;1157.258;119.5836;0;0;0;3.695667;3.629014;1062067;1.24003e+008
187.9;1.149964;-0.4432468;1009.384;104.3032;0;0;0;3.621933;3.557883;926356.7;1.08081e+008
194.9;1.126714;-0.4218558;889.4224;91.90716;0;0;0;3.548704;3.487189;816262.6;9.516867e+007
201.9;1.103464;-0.4020415;782.9053;80.90038;0;0;0;3.475476;3.416445;718507.1;8.371205e+007
208.9;1.080107;-0.3836028;686.0565;70.89265;0;0;0;3.40191;3.345325;629624.6;7.330435e+007
215.9;1.056696;-0.3663575;599.4818;61.94657;0;0;0;3.328175;3.273991;550171.1;6.400826e+007
222.9;1.033285;-0.3474133;520.0266;53.73619;0;0;0;3.254441;3.202606;477251.6;5.5485e+007
229.9;1.010035;-0.3268779;447.5856;46.2506;0;0;0;3.181213;3.13166;410769.2;4.772193e+007
236.9;0.986678;-0.3045503;381.8434;39.45723;0;0;0;3.107647;3.060337;350434.7;4.068342e+007
243.9;0.963428;-0.2793141;322.2691;33.3012;0;0;0;3.034419;2.989291;295760.7;3.43117e+007
250.9;0.940178;-0.2530161;268.8585;27.7821;0;0;0;2.96119;2.918194;246743.5;2.860479e+007
257.9;0.9168209;-0.2258606;220.5361;22.78877;0;0;0;2.887625;2.846718;202395.8;2.344683e+007
264.9;0.8933566;-0.1977459;178.273;18.42158;0;0;0;2.813722;2.774864;163609.1;1.893991e+007
271.9;0.8699459;-0.1679336;141.8452;14.65737;0;0;0;2.739987;2.703121;130177.7;1.505898e+007
278.9;0.8467495;-0.1385754;109.8138;11.34745;0;0;0;2.666927;2.631985;100781.1;1.165008e+007
285.9;0.8232852;-0.1098675;82.03041;8.476493;0;0;0;2.593024;2.559975;75282.97;8696290
292.9;0.8000352;-0.08539806;59.51938;6.150349;0;0;0;2.519796;2.488572;54623.59;6305325
299.9;0.7768388;-0.0782391;54.41743;5.623146;0;0;0;2.446736;2.417283;49941.3;5760729
305.6;0.777696;-0.07768219;55.2382;5.707959;1;1;0;2.449436;2.419918;50694.56;5847771
312.6;0.8011602;-0.09078421;89.13199;9.210324;1;1;0;2.523339;2.492029;81800.41;9442732
319.6;0.8244638;-0.1182186;144.649;14.94709;1;1;0;2.596736;2.563594;132750.8;1.533523e+007
326.6;0.8477137;-0.145765;198.8833;20.55131;1;1;0;2.669965;2.634943;182524;2.110002e+007
333.6;0.8710709;-0.1714898;255.988;26.45214;1;1;0;2.74353;2.70657;234931.6;2.717787e+007
340.6;0.8942673;-0.1964197;318.5447;32.91636;1;1;0;2.81659;2.777653;292342.7;3.384347e+007
347.6;0.9177316;-0.2210182;385.0083;39.78427;1;1;0;2.890493;2.849506;353339.3;4.093423e+007
354.6;0.9409816;-0.2445254;456.7013;47.19256;1;1;0;2.963722;2.920652;419135.1;4.859121e+007
361.6;0.9644459;-0.2687517;531.4091;54.91239;1;1;0;3.037625;2.992402;487697.9;5.658042e+007
368.6;0.9878029;-0.2916043;610.585;63.09391;1;1;0;3.11119;3.063774;560361.1;6.505689e+007
375.6;1.011053;-0.3125863;693.0008;71.61023;1;1;0;3.184418;3.134767;635997.8;7.38906e+007
382.6;1.034356;-0.3324138;780.3237;80.63361;1;1;0;3.257816;3.205874;716137.8;8.32605e+007
389.6;1.057606;-0.3508957;866.8366;89.5733;1;1;0;3.331044;3.276767;795534.6;9.255702e+007
396.6;1.081071;-0.3691765;954.4579;98.62752;1;1;0;3.404947;3.348262;875948.6;1.019857e+008
403.6;1.104321;-0.3870601;1042.122;107.6862;1;1;0;3.478176;3.419054;956402.1;1.114317e+008
410.6;1.127731;-0.4058684;1133.74;117.1534;1;1;0;3.55191;3.490285;1040484;1.213145e+008
417.6;1.151142;-0.4255323;1222.691;126.345;1;1;0;3.625644;3.561464;1122118;1.309258e+008
424.6;1.174339;-0.4467662;1315.407;135.9257;1;1;0;3.698704;3.631943;1207208;1.409532e+008
431.6;1.197749;-0.4703304;1406.057;145.2928;1;1;0;3.772438;3.703022;1290401;1.507739e+008
438.6;1.220946;-0.496292;1496.994;154.6897;1;1;0;3.845498;3.773401;1373859;1.606383e+008
445.6;1.244356;-0.5235848;1573.938;162.6406;1;1;0;3.919233;3.84438;1444473;1.690149e+008
452.6;1.26766;-0.5500694;1652.774;170.787;1;1;0;3.99263;3.914984;1516825;1.776059e+008
459.6;1.291124;-0.5775915;1725.867;178.3399;1;1;0;4.066533;3.986024;1583905;1.855922e+008
466.6;1.314481;-0.6051793;1796.992;185.6895;1;1;0;4.140098;4.056691;1649180;1.933773e+008
473.6;1.337731;-0.6322673;1871.173;193.3549;1;1;0;4.213327;4.126983;1717259;2.015016e+008
480.6;1.361089;-0.660459;1940.099;200.4773;1;1;0;4.286893;4.19755;1780515;2.090715e+008
487.6;1.384285;-0.6918731;2006.521;207.3409;1;1;0;4.359952;4.267582;1841474;2.163809e+008
494.6;1.411392;-0.7289804;2083.297;215.2744;1;1;0;4.445329;4.349358;1911934;2.248441e+008
501.6;1.446588;-0.7772483;2185.484;225.8338;1;1;0;4.556184;4.455439;2005716;2.361232e+008
508.6;1.481463;-0.8263563;2283.395;235.9513;1;1;0;4.666026;4.560439;2095574;2.469609e+008
515.6;1.516445;-0.8742245;2372.674;245.1768;1;1;0;4.776206;4.665652;2177509;2.56887e+008
522.6;1.551428;-0.9211161;2463.932;254.6069;1;1;0;4.886386;4.770754;2261261;2.670479e+008
529.6001;1.586624;-0.9684368;2547.488;263.2409;1;1;0;4.997241;4.876389;2337943;2.763957e+008
535.44;1.605695;-0.9953487;2552.947;263.8051;1;1;0;5.057309;4.933581;2342954;2.771465e+008
542.44;1.570713;-0.944114;2259.763;233.5093;1;1;0;4.947129;4.82865;2073885;2.450613e+008
549.44;1.535731;-0.9025778;2020.3;208.7647;1;1;0;4.836948;4.723609;1854119;2.188626e+008
556.44;1.500749;-0.8611888;1824.707;188.5535;1;1;0;4.726768;4.618457;1674615;1.97466e+008
563.44;1.465552;-0.8225656;1650.602;170.5625;1;1;0;4.615913;4.512549;1514831;1.784356e+008
570.44;1.430678;-0.7831525;1499.666;154.9658;1;1;0;4.506072;4.407498;1376311;1.619487e+008
577.44;1.395749;-0.7438402;1362.845;140.8276;1;1;0;4.39606;4.302175;1250743;1.470184e+008
584.44;1.360606;-0.7031992;1238.387;127.9669;1;1;0;4.285374;4.196094;1136523;1.334508e+008
591.44;1.325785;-0.663288;1121.668;115.9059;1;1;0;4.1757;4.090871;1029405;1.207458e+008
598.44;1.290749;-0.6252781;1010.743;104.4437;1;1;0;4.065352;3.98489;927604.3;1.086897e+008
605.44;1.255767;-0.5895001;905.4767;93.56612;1;1;0;3.955172;3.878958;830996.4;9.726681e+007
612.44;1.220571;-0.5527963;806.7778;83.36721;1;1;0;3.844317;3.772264;740416;8.657211e+007
619.44;1.185749;-0.5197397;711.0235;73.47258;1;1;0;3.734643;3.666594;652538;7.621652e+007
626.44;1.150714;-0.4885178;617.9403;63.85396;1;1;0;3.624295;3.560162;567111.4;6.616821e+007
633.44;1.115571;-0.4540749;528.2237;54.58323;1;1;0;3.513608;3.45329;484774.5;5.650107e+007
640.44;1.080749;-0.417554;443.7756;45.85691;1;1;0;3.403935;3.347283;407272.7;4.741785e+007
647.44;1.045767;-0.3770433;362.5295;37.46146;1;1;0;3.293755;3.240673;332709.5;3.869535e+007
654.44;1.010731;-0.3334017;287.3105;29.68881;1;1;0;3.183406;3.133786;263677.6;3.063392e+007
661.44;0.9755886;-0.2835;221.1144;22.84854;1;1;0;3.07272;3.026457;202926.6;2.355061e+007
668.44;0.9407137;-0.2353173;166.147;17.16856;1;1;0;2.962878;2.919833;152480.5;1.767724e+007
675.44;0.9057316;-0.1869755;120.5656;12.45847;1;1;0;2.852698;2.812766;110648.5;1.281388e+007
682.44;0.8705887;-0.1425971;83.42023;8.620108;1;1;0;2.742012;2.705092;76558.46;8856472
689.44;0.8357674;-0.1055864;55.55375;5.740566;1;1;0;2.632338;2.598288;50984.15;5891677
696.4401;0.8007317;-0.1015302;54.10476;5.590836;1;1;0;2.521989;2.490712;49654.35;5731837
703.4401;0.7657495;-0.1004671;53.76099;5.555314;1;1;0;2.411809;2.383185;49338.86;5689297
708.6261;0.7798388;-0.1008881;54.31657;5.612723;2;2;0;2.456185;2.426506;49848.73;5750582
715.6261;0.8148744;-0.1018547;55.0298;5.686424;2;2;0;2.566534;2.534151;50503.3;5832368
722.6261;0.8496423;-0.128749;116.3089;12.01861;2;2;0;2.676039;2.640859;106741.9;1.234023e+007
729.6261;0.8847316;-0.1694289;192.4435;19.88587;2;2;0;2.786556;2.748438;176614;2.044e+007
736.6261;0.9197673;-0.2080308;277.7266;28.69847;2;2;0;2.896905;2.855738;254882.1;2.952984e+007
743.6261;0.954803;-0.2456254;374.4315;38.69134;2;2;0;3.007253;2.962922;343632.5;3.985488e+007
750.6261;0.9897316;-0.2825434;480.106;49.61105;2;2;0;3.117265;3.069665;440614.7;5.115756e+007
757.6261;1.024928;-0.3189779;599.5235;61.95089;2;2;0;3.228119;3.17711;550209.4;6.395073e+007
764.6261;1.059856;-0.352468;722.5569;74.66436;2;2;0;3.33813;3.283624;663122.7;7.715675e+007
771.6261;1.094678;-0.3816815;844.8091;87.29711;2;2;0;3.447804;3.389699;775318.9;9.030694e+007
778.6261;1.129713;-0.4101971;970.0127;100.2348;2;2;0;3.558153;3.496313;890223.9;1.038014e+008
785.6261;1.164749;-0.4383738;1100.016;113.6685;2;2;0;3.668502;3.602814;1009534;1.178384e+008
792.6261;1.199785;-0.4716472;1222.394;126.3143;2;2;0;3.77885;3.709201;1121846;1.310876e+008
799.6261;1.234713;-0.5078141;1348.936;139.3903;2;2;0;3.888861;3.81515;1237978;1.44811e+008
806.6261;1.26991;-0.5480373;1475.303;152.4483;2;2;0;3.999716;3.921798;1353951;1.585458e+008
813.6261;1.304838;-0.5888142;1595.169;164.8345;2;2;0;4.109727;4.027523;1463958;1.716087e+008
820.6261;1.33966;-0.6291702;1716.331;177.3545;2;2;0;4.219401;4.132812;1575153;1.848378e+008
827.6261;1.374803;-0.6707326;1833.788;189.4918;2;2;0;4.330087;4.23896;1682949;1.97697e+008
834.6261;1.409731;-0.7159059;1951.052;201.6091;2;2;0;4.440098;4.34435;1790568;2.105608e+008
841.6261;1.444767;-0.7606025;2065.794;213.4658;2;2;0;4.550447;4.449952;1895871;2.231794e+008
848.6261;1.479695;-0.805725;2182.618;225.5377;2;2;0;4.660458;4.555119;2003086;2.360488e+008
855.6261;1.514945;-0.8511639;2296.984;237.3555;2;2;0;4.771482;4.661143;2108045;2.486809e+008
862.6261;1.549874;-0.897736;2407.345;248.7595;2;2;0;4.881493;4.766089;2209328;2.609027e+008
869.6261;1.584642;-0.9469931;2514.777;259.8608;2;2;0;4.990998;4.870443;2307923;2.728304e+008
876.6261;1.619785;-0.9981301;2616.509;270.3732;2;2;0;5.101684;4.975812;2401287;2.841667e+008
883.6261;1.654713;-1.046167;2700.934;279.097;2;2;0;5.211695;5.080428;2478767;2.936427e+008
890.6261;1.689749;-1.093991;2780.224;287.2903;2;2;0;5.322044;5.185255;2551535;3.025801e+008
897.6261;1.724731;-1.144677;2857.039;295.2279;2;2;0;5.432223;5.289813;2622032;3.112654e+008
904.6261;1.759874;-1.197605;2940.867;303.8902;2;2;0;5.54291;5.394741;2698965;3.207346e+008
911.6261;1.794856;-1.247967;3012.285;311.2701;2;2;0;5.65309;5.49908;2764509;3.288665e+008
918.6261;1.829677;-1.306361;3089.031;319.2005;2;2;0;5.762764;5.602832;2834941;3.375952e+008
925.6261;1.86482;-1.363603;3158.221;326.3502;2;2;0;5.87345;5.707433;2898440;3.455182e+008
932.6261;1.899749;-1.416011;3230.864;333.8566;2;2;0;5.983461;5.811287;2965108;3.538328e+008
939.6261;1.934731;-1.46964;3296.508;340.6399;2;2;0;6.093641;5.915192;3025353;3.613973e+008
946.6261;1.969713;-1.521826;3364.253;347.6402;2;2;0;6.203821;6.01899;3087526;3.692072e+008
953.6261;2.004909;-1.575158;3431.762;354.6161;2;2;0;6.314675;6.123314;3149481;3.77009e+008
960.6261;2.039838;-1.617817;3486.121;360.2332;2;2;0;6.424686;6.226738;3199369;3.833771e+008
967.6261;2.074659;-1.679509;3545.257;366.344;2;2;0;6.53436;6.329738;3253640;3.902822e+008
974.6261;2.109802;-1.725067;3597.852;371.7788;2;2;0;6.645046;6.433581;3301909;3.964837e+008
981.6261;2.144731;-1.773823;3642.643;376.4073;2;2;0;6.755057;6.536684;3343016;4.018338e+008
988.6261;2.179713;-1.826996;3672.084;379.4494;2;2;0;6.865237;6.639839;3370035;4.054995e+008
995.6261;2.214749;-1.884021;3729.825;385.416;2;2;0;6.975586;6.743046;3423027;4.12301e+008
1002.626;2.249945;-1.942885;3772.391;389.8145;2;2;0;7.086441;6.846618;3462091;4.174385e+008
1009.626;2.28482;-1.994331;3812.657;393.9754;2;2;0;7.196283;6.949139;3499046;4.22327e+008
1015.606;2.264677;-1.952987;3588.27;370.7886;2;2;0;7.132842;6.889939;3293115;3.972364e+008
1022.606;2.229695;-1.89025;3315.404;342.5924;2;2;0;7.022661;6.787041;3042694;3.666515e+008
1029.606;2.194766;-1.823;3094.732;319.7896;2;2;0;6.91265;6.684196;2840174;3.418955e+008
1036.606;2.159516;-1.755883;2899.34;299.5991;2;2;0;6.801626;6.580297;2660854;3.199767e+008
1043.606;2.124641;-1.694561;2729.371;282.0356;2;2;0;6.691784;6.477397;2504866;3.009088e+008
1050.606;2.089713;-1.63727;2572.551;265.8308;2;2;0;6.581773;6.374232;2360945;2.833272e+008
1057.606;2.05457;-1.580951;2435.809;251.7007;2;2;0;6.471087;6.270328;2235450;2.679885e+008
1064.606;2.019695;-1.525702;2308.627;238.5586;2;2;0;6.361244;6.167108;2118730;2.537339e+008
1071.606;1.984713;-1.47483;2186.547;225.9437;2;2;0;6.251064;6.063464;2006692;2.400676e+008
1078.606;1.949784;-1.425139;2072.455;214.1541;2;2;0;6.141054;5.959872;1901984;2.273054e+008
1085.606;1.914535;-1.378064;1965.716;203.1244;2;2;0;6.03003;5.855217;1804025;2.153729e+008
1092.606;1.87966;-1.332097;1868.355;193.0638;2;2;0;5.920187;5.751568;1714673;2.044935e+008
1099.606;1.844677;-1.286754;1774.775;183.3938;2;2;0;5.810008;5.647492;1628791;1.94049e+008
1106.606;1.809588;-1.24148;1683.852;173.9984;2;2;0;5.69949;5.542988;1545346;1.839154e+008
1113.606;1.774713;-1.196145;1596.679;164.9905;2;2;0;5.589648;5.439015;1465344;1.742129e+008
1120.606;1.739731;-1.154326;1507.359;155.7608;2;2;0;5.479467;5.334613;1383371;1.642956e+008
1127.606;1.704695;-1.110529;1426.974;147.4542;2;2;0;5.369119;5.229942;1309597;1.553712e+008
1134.606;1.669552;-1.069307;1351.402;139.6452;2;2;0;5.258433;5.124841;1240242;1.469883e+008
1141.606;1.634677;-1.030028;1281.132;132.3839;2;2;0;5.148591;5.020431;1175752;1.391998e+008
1148.606;1.599695;-0.9884466;1212.464;125.2882;2;2;0;5.038411;4.915591;1112733;1.316008e+008
1155.606;1.564553;-0.9474748;1143.802;118.1931;2;2;0;4.927725;4.810159;1049718;1.240173e+008
1162.606;1.529731;-0.9082033;1077.673;111.3598;2;2;0;4.818051;4.705581;989028.6;1.167251e+008
1169.606;1.494749;-0.8705629;1010.871;104.4568;2;2;0;4.707871;4.60041;927721.1;1.093745e+008
1176.606;1.459713;-0.8318658;944.3063;97.57851;2;2;0;4.597522;4.494967;866632;1.020647e+008
1183.606;1.424571;-0.792296;879.1164;90.84221;2;2;0;4.486836;4.389091;806804.3;9.491815e+007
1190.606;1.389696;-0.7565262;813.9581;84.10917;2;2;0;4.376994;4.28391;747005.6;8.779062e+007
1197.606;1.35466;-0.7204551;747.8426;77.27722;2;2;0;4.266645;4.178133;686328.5;8.057437e+007
1204.606;1.319571;-0.6830353;681.2997;70.40111;2;2;0;4.156128;4.072082;625259.1;7.332707e+007
1211.606;1.284696;-0.6451851;615.9619;63.64952;2;2;0;4.046285;3.966566;565295.8;6.622497e+007
1218.606;1.249713;-0.6062198;550.3872;56.87346;2;2;0;3.936105;3.860615;505114.8;5.911205e+007
1225.606;1.214678;-0.5668405;484.4663;50.06162;2;2;0;3.825757;3.754389;444616.3;5.197685e+007
1232.606;1.179589;-0.5199458;419.3497;43.33289;2;2;0;3.715239;3.647887;384855.9;4.494281e+007
1239.606;1.144714;-0.4706405;356.4794;36.83628;2;2;0;3.605397;3.541924;327157.1;3.816437e+007
1246.606;1.109678;-0.4192704;296.4541;30.63366;2;2;0;3.495048;3.435358;272069.2;3.170432e+007
1253.606;1.074535;-0.3683909;240.6798;24.8703;2;2;0;3.384362;3.328353;220882.6;2.5712e+007
1260.606;1.039767;-0.3184297;189.1993;19.55064;2;2;0;3.274857;3.222376;173636.7;2.019089e+007
1267.606;1.004732;-0.2682336;142.9605;14.77261;2;2;0;3.164509;3.11547;131201.2;1.524009e+007
1274.606;0.9696958;-0.2202125;104.8198;10.8314;2;2;0;3.05416;3.008449;96197.84;1.116221e+007
1281.606;0.9346066;-0.1757102;75.00091;7.75011;2;2;0;2.943643;2.901149;68831.68;7978245
1288.606;0.8997315;-0.1428922;54.32564;5.613661;2;2;0;2.8338;2.794391;49857.06;5772741
1295.606;0.8646423;-0.1405017;53.88967;5.56861;2;2;0;2.723283;2.686861;49456.95;5720259
1301.18;0.8667851;-0.1402799;54.33248;5.614367;3;3;0;2.730032;2.693431;49863.34;5767642
1308.18;0.9017673;-0.1472491;74.47282;7.69554;3;3;0;2.840212;2.800626;68347.02;7914110
1315.18;0.9369101;-0.1878926;149.4416;15.44233;3;3;0;2.950898;2.908197;137149.3;1.589802e+007
1322.18;0.9717315;-0.2282078;231.0786;23.87816;3;3;0;3.060572;3.01467;212071.1;2.460897e+007
1329.18;1.006714;-0.2678014;325.4012;33.62486;3;3;0;3.170752;3.121521;298635.2;3.469101e+007
1336.18;1.041803;-0.307534;428.8614;44.31577;3;3;0;3.281269;3.228585;393585.3;4.576989e+007
1343.18;1.076892;-0.3480623;536.1729;55.40464;3;3;0;3.391786;3.335534;492069.8;5.728385e+007
1350.18;1.111767;-0.3873915;646.38;66.79273;3;3;0;3.501629;3.441716;593211.7;6.913156e+007
1357.18;1.146803;-0.4236969;760.2028;78.55444;3;3;0;3.611977;3.548275;697672;8.139182e+007
1364.18;1.181892;-0.456741;877.2744;90.65187;3;3;0;3.722495;3.654883;805113.8;9.402638e+007
1371.18;1.216713;-0.4864744;992.6339;102.5724;3;3;0;3.832169;3.760565;910984.4;1.065031e+008
1378.18;1.251749;-0.5202176;1108.43;114.538;3;3;0;3.942517;3.866784;1017256;1.190537e+008
1385.18;1.286785;-0.5585064;1221.84;126.257;3;3;0;4.052866;3.972891;1121337;1.31374e+008
1392.18;1.321874;-0.5992438;1332.79;137.7219;3;3;0;4.163383;4.079047;1223161;1.434558e+008
1399.18;1.356803;-0.6408132;1443.174;149.1283;3;3;0;4.273394;4.184605;1324465;1.555011e+008
1406.18;1.391838;-0.6839173;1551.08;160.2786;3;3;0;4.383743;4.290376;1423496;1.673048e+008
1413.18;1.426928;-0.7272351;1654.942;171.011;3;3;0;4.49426;4.396196;1518814;1.786967e+008
1420.18;1.461696;-0.7696276;1752.245;181.0657;3;3;0;4.603765;4.500936;1608114;1.894015e+008
1427.18;1.496731;-0.8129103;1850.888;191.2588;3;3;0;4.714114;4.606373;1698642;2.002749e+008
1434.18;1.531767;-0.8557364;1947.16;201.207;3;3;0;4.824463;4.711698;1786996;2.109141e+008
1441.18;1.566856;-0.8989232;2040.625;210.865;3;3;0;4.93498;4.817073;1872772;2.212711e+008
1448.18;1.601785;-0.9439468;2128.713;219.9675;3;3;0;5.044991;4.921856;1953615;2.310648e+008
1455.18;1.63682;-0.9872971;2210.131;228.3807;3;3;0;5.15534;5.02685;2028336;2.401545e+008
1462.18;1.67191;-1.034657;2296.447;237.3;3;3;0;5.265857;5.131894;2107552;2.497959e+008
1469.18;1.706677;-1.081387;2383.416;246.2868;3;3;0;5.375362;5.235867;2187367;2.595256e+008
1476.18;1.741767;-1.134407;2470.3;255.2648;3;3;0;5.485879;5.340691;2267105;2.692684e+008
1483.18;1.776802;-1.186166;2558.757;264.4054;3;3;0;5.596228;5.445246;2348286;2.792022e+008
1490.18;1.811838;-1.236487;2646.397;273.4616;3;3;0;5.706577;5.549693;2428717;2.890669e+008
1497.18;1.846767;-1.287418;2733.249;282.4362;3;3;0;5.816588;5.653711;2508424;2.988644e+008
1504.18;1.88191;-1.33718;2813.05;290.6824;3;3;0;5.927274;5.758258;2581662;3.07912e+008
1511.18;1.916892;-1.389769;2895.755;299.2286;3;3;0;6.037454;5.862218;2657563;3.172944e+008
1518.18;1.95166;-1.443043;2977.504;307.6761;3;3;0;6.146959;5.965436;2732588;3.265888e+008
1525.18;1.986749;-1.49861;3063.073;316.5182;3;3;0;6.257476;6.069498;2811119;3.363242e+008
1532.18;2.021784;-1.553797;3149.136;325.4113;3;3;0;6.367825;6.173295;2890102;3.461329e+008
1539.18;2.05682;-1.608988;3229.534;333.7191;3;3;0;6.478174;6.276984;2963887;3.553381e+008
1546.18;2.091802;-1.664969;3310.004;342.0344;3;3;0;6.588353;6.380406;3037738;3.645688e+008
1553.18;2.126945;-1.719336;3395.343;350.8528;3;3;0;6.699039;6.484197;3116058;3.743566e+008
1560.18;2.161874;-1.779194;3435.18;354.9693;3;3;0;6.809051;6.587248;3152618;3.791394e+008
1567.18;2.196695;-1.836482;3518.629;363.5923;3;3;0;6.918725;6.689877;3229203;3.887483e+008
1574.18;2.231784;-1.9166;3590.215;370.9896;3;3;0;7.029242;6.79319;3294900;3.970673e+008
1580.598;2.263927;-1.99664;3553.885;367.2355;3;3;0;7.130479;6.887734;3261559;3.934211e+008
1586.114;2.24132;-1.958078;3331.246;344.2294;3;3;0;7.059276;6.821247;3057233;3.685295e+008
1593.114;2.206445;-1.894254;3066.851;316.9085;3;3;0;6.949433;6.718595;2814586;3.389319e+008
1600.114;2.171516;-1.82823;2849.547;294.4538;3;3;0;6.839422;6.615679;2615157;3.145927e+008
1607.114;2.136427;-1.76471;2663.409;275.2195;3;3;0;6.728905;6.512183;2444330;2.937388e+008
1614.114;2.101499;-1.708353;2500.731;258.4094;3;3;0;6.618894;6.409055;2295033;2.755133e+008
1621.114;2.066517;-1.65227;2352.857;243.1291;3;3;0;6.508714;6.305661;2159322;2.589537e+008
1628.114;2.031535;-1.597299;2222.587;229.6678;3;3;0;6.398534;6.202161;2039767;2.443632e+008
1635.114;1.996338;-1.542061;2098.474;216.8428;3;3;0;6.287679;6.097918;1925863;2.304771e+008
1642.114;1.961463;-1.488687;1983.114;204.9221;3;3;0;6.177836;5.99452;1819992;2.175819e+008
1649.114;1.926534;-1.436235;1875.923;193.8457;3;3;0;6.067825;5.890856;1721618;2.05608e+008
1656.114;1.891392;-1.384356;1774.928;183.4096;3;3;0;5.957139;5.786448;1628931;1.943355e+008
1663.114;1.856517;-1.334771;1682.188;173.8264;3;3;0;5.847296;5.682727;1543819;1.839906e+008
1670.114;1.821535;-1.288264;1592.905;164.6005;3;3;0;5.737117;5.57858;1461880;1.740439e+008
1677.114;1.786552;-1.242471;1506.47;155.6688;3;3;0;5.626937;5.474324;1382554;1.644282e+008
1684.114;1.751302;-1.194113;1424.724;147.2218;3;3;0;5.515913;5.369159;1307533;1.553424e+008
1691.114;1.716481;-1.150701;1349.074;139.4045;3;3;0;5.40624;5.265165;1238105;1.469411e+008
1698.114;1.681499;-1.110306;1276.43;131.898;3;3;0;5.296059;5.160581;1171436;1.388834e+008
1705.114;1.64641;-1.071748;1207.55;124.7804;3;3;0;5.185542;5.055567;1108223;1.31251e+008
1712.114;1.611481;-1.032653;1141.51;117.9563;3;3;0;5.075531;4.950925;1047614;1.239432e+008
1719.114;1.576499;-0.9925949;1075.48;111.1332;3;3;0;4.965352;4.846013;987016.3;1.166513e+008
1726.114;1.541517;-0.9490798;1010.408;104.409;3;3;0;4.855171;4.740989;927296.1;1.094782e+008
1733.114;1.506321;-0.9096359;946.6184;97.81743;3;3;0;4.744317;4.635212;868753.9;1.024582e+008
1740.114;1.471499;-0.8743899;883.6976;91.3156;3;3;0;4.634643;4.53045;811008.7;9.554775e+007
1747.114;1.436463;-0.8408402;820.0045;84.73397;3;3;0;4.524294;4.424934;752554.8;8.856759e+007
1754.114;1.401374;-0.8085465;756.696;78.19208;3;3;0;4.413776;4.319144;694453.6;8.16433e+007
1761.114;1.366499;-0.7722323;693.9787;71.71127;3;3;0;4.303934;4.213889;636895.2;7.479768e+007
1768.114;1.331517;-0.7346565;630.5899;65.16109;3;3;0;4.193754;4.1082;578720.5;6.789378e+007
1775.114;1.296535;-0.6960396;567.5152;58.64335;3;3;0;4.083574;4.002399;520834;6.10381e+007
1782.114;1.261338;-0.6503263;504.6278;52.14497;3;3;0;3.97272;3.895837;463119.4;5.421655e+007
1789.114;1.226464;-0.6066803;442.0114;45.67461;3;3;0;3.862877;3.790135;405653.6;4.743896e+007
1796.114;1.191481;-0.558938;379.1193;39.17574;3;3;0;3.752697;3.683997;347934.7;4.064589e+007
1803.114;1.156338;-0.5100749;319.6972;33.03544;3;3;0;3.642011;3.577257;293400.3;3.423859e+007
1810.114;1.121517;-0.4603706;263.7759;27.2569;3;3;0;3.532338;3.471382;242078.9;2.821971e+007
1817.114;1.086535;-0.4102654;211.1096;21.8147;3;3;0;3.422158;3.364904;193744.7;2.256123e+007
1824.114;1.051499;-0.3588145;163.4403;16.88886;3;3;0;3.311809;3.25815;149996.4;1.744819e+007
1831.114;1.016356;-0.3099984;121.2125;12.52531;3;3;0;3.201123;3.150954;111242.1;1.292626e+007
1838.114;0.9814815;-0.2623382;86.98175;8.988132;3;3;0;3.09128;3.044463;79827.03;9265981
1845.114;0.9464458;-0.2203729;60.12744;6.213181;3;3;0;2.980932;2.937366;55181.63;6398391
1852.114;0.9113565;-0.2085545;54.25614;5.606479;3;3;0;2.870414;2.82999;49793.28;5767408
1857.16;0.8862851;-0.207648;53.99465;5.579458;4;4;0;2.791449;2.753198;49553.29;5735206
1864.16;0.9237851;-0.2083941;55.37116;5.721698;4;4;0;2.909559;2.868035;50816.58;5888174
1871.16;0.9703922;-0.2558771;149.3548;15.43336;4;4;0;3.056353;3.010577;137069.6;1.590506e+007
1878.16;1.016999;-0.3108529;265.2881;27.41316;4;4;0;3.203148;3.152917;243466.7;2.829124e+007
1885.16;1.06366;-0.3643347;396.8864;41.01168;4;4;0;3.35011;3.295217;364240.4;4.238562e+007
1892.16;1.110481;-0.4179981;535.8708;55.37343;4;4;0;3.497579;3.437804;491792.6;5.731016e+007
1899.16;1.157035;-0.4711191;681.1109;70.38161;4;4;0;3.644205;3.579374;625085.9;7.294645e+007
1906.16;1.203749;-0.5187725;831.3344;85.90473;4;4;0;3.791336;3.721231;762952.7;8.916167e+007
1913.16;1.258713;-0.5750456;1009.084;104.2722;4;4;0;3.964452;3.887885;926081.2;1.08406e+008
1920.16;1.317106;-0.6346083;1188.039;122.7642;4;4;0;4.148366;4.064629;1090316;1.27857e+008
1927.16;1.375606;-0.7019607;1361.492;140.6878;4;4;0;4.332618;4.241386;1249502;1.467833e+008
1934.16;1.433945;-0.771579;1526.2;157.7077;4;4;0;4.516364;4.417346;1400662;1.648303e+008
1941.16;1.49207;-0.8391763;1684.109;174.0249;4;4;0;4.699434;4.592353;1545582;1.822031e+008
1948.16;1.550517;-0.9085898;1837.768;189.9031;4;4;0;4.883518;4.768019;1686602;1.991771e+008
1955.16;1.608803;-0.9795236;1983.241;204.9353;4;4;0;5.067095;4.942896;1820109;2.153196e+008
1962.16;1.667088;-1.049456;2124.792;219.5623;4;4;0;5.250671;5.117467;1950017;2.310908e+008
1969.16;1.725428;-1.12365;2264.973;234.0477;4;4;0;5.434418;5.291894;2078667;2.467668e+008
1976.16;1.783927;-1.202417;2407.382;248.7633;4;4;0;5.618669;5.466496;2209362;2.627404e+008
1983.16;1.842213;-1.278037;2549.776;263.4774;4;4;0;5.802246;5.640156;2340043;2.78765e+008
1990.16;1.900392;-1.35831;2688.846;277.848;4;4;0;5.985486;5.813197;2467674;2.944785e+008
1997.16;1.958838;-1.444393;2826.045;292.0253;4;4;0;6.169569;5.986733;2593588;3.10042e+008
2004.16;2.01707;-1.537816;2971.729;307.0793;4;4;0;6.352977;6.159334;2727288;3.265879e+008
2011.16;2.075463;-1.635315;3116.322;322.0206;4;4;0;6.536891;6.332113;2859988;3.430707e+008
2018.16;2.133856;-1.735664;3247.991;335.6264;4;4;0;6.720806;6.504595;2980827;3.581832e+008
2025.16;2.192302;-1.844817;3393.295;350.6412;4;4;0;6.904889;6.676936;3114178;3.748526e+008
2032.16;2.250588;-1.957111;3474.722;359.0554;4;4;0;7.088466;6.848509;3188908;3.845069e+008
2037.566;2.264034;-1.990791;3371.541;348.3933;4;4;0;7.130816;6.888049;3094214;3.732366e+008
2044.566;2.205642;-1.882804;2930.534;302.8224;4;4;0;6.946902;6.716229;2689481;3.238592e+008
2051.566;2.147356;-1.782413;2600.862;268.7563;4;4;0;6.763326;6.544429;2386927;2.869332e+008
2058.566;2.088909;-1.695739;2337.742;241.5672;4;4;0;6.579242;6.371858;2145450;2.574605e+008
2065.566;2.030624;-1.611515;2117.431;218.8016;4;4;0;6.395665;6.199465;1943261;2.327955e+008
2072.566;1.972124;-1.534793;1918.875;198.2842;4;4;0;6.211413;6.026139;1761037;2.106004e+008
2079.566;1.913892;-1.459952;1742.703;180.0796;4;4;0;6.028006;5.853308;1599356;1.909348e+008
2086.566;1.855713;-1.385813;1585.107;163.7947;4;4;0;5.844766;5.680336;1454723;1.733681e+008
2093.566;1.79732;-1.310636;1440.81;148.884;4;4;0;5.660851;5.506426;1322296;1.573122e+008
2100.566;1.738981;-1.235205;1311.412;135.5129;4;4;0;5.477106;5.332374;1203542;1.429351e+008
2107.566;1.680588;-1.163454;1192.685;123.2444;4;4;0;5.293191;5.157857;1094581;1.29768e+008
2114.566;1.622356;-1.09526;1086.31;112.2523;4;4;0;5.109783;4.983517;996955.2;1.179881e+008
2121.566;1.563856;-1.02614;982.3158;101.5062;4;4;0;4.925531;4.808068;901515;1.065059e+008
2128.566;1.50557;-0.9587539;880.5563;90.991;4;4;0;4.741954;4.632956;808125.8;9.530575e+007
2135.566;1.447338;-0.8992144;779.3894;80.53707;4;4;0;4.558546;4.457698;715280.4;8.420839e+007
2142.566;1.389053;-0.8381014;680.6309;70.332;4;4;0;4.374969;4.28197;624645.3;7.3409e+007
2149.566;1.330606;-0.774626;581.7645;60.11579;4;4;0;4.190886;4.105447;533911.3;6.263517e+007
2156.566;1.272213;-0.7027331;482.7421;49.88345;4;4;0;4.006971;3.928774;443033.9;5.188226e+007
2163.566;1.213928;-0.6224954;384.0551;39.68578;4;4;0;3.823395;3.752114;352464.5;4.120312e+007
2170.566;1.155535;-0.5398528;286.711;29.62686;4;4;0;3.63948;3.574816;263127.4;3.070512e+007
2177.566;1.097249;-0.4561565;199.3835;20.603;4;4;0;3.455903;3.397528;182983.1;2.131502e+007
2184.566;1.039017;-0.3744154;124.9623;12.91279;4;4;0;3.272495;3.220089;114683.4;1.333536e+007
2191.566;0.9807315;-0.298678;69.43168;7.174621;4;4;0;3.088918;3.042171;63720.55;7396239
2198.566;0.9222851;-0.2717091;54.09143;5.589459;4;4;0;2.904835;2.863444;49642.12;5751823
2204.2;0.8918566;-0.2707764;54.06195;5.586412;5;5;0;2.808997;2.770268;49615.06;5743335
2211.2;0.9503029;-0.2738046;61.99736;6.406407;5;5;0;2.99308;2.949162;56897.74;6598156
2218.2;1.008803;-0.3416814;193.1343;19.95725;5;5;0;3.177332;3.127899;177248;2.059136e+007
2225.2;1.067035;-0.4079907;348.349;35.99614;5;5;0;3.36074;3.305501;319695.4;3.720588e+007
2232.2;1.125214;-0.4749999;515.7933;53.29875;5;5;0;3.54398;3.482626;473366.5;5.518765e+007
2239.2;1.18366;-0.5434762;693.0933;71.61979;5;5;0;3.728063;3.660251;636082.6;7.428982e+007
2246.2;1.241946;-0.6076569;873.8789;90.301;5;5;0;3.91164;3.837073;801997.6;9.383325e+007
2253.2;1.300338;-0.6683465;1049.985;108.4987;5;5;0;4.095554;4.013908;963618.1;1.129423e+008
2260.2;1.358678;-0.72991;1219.78;126.0442;5;5;0;4.2793;4.190269;1119447;1.31438e+008
2267.2;1.41707;-0.7969736;1383.097;142.9203;5;5;0;4.463214;4.36648;1269330;1.492992e+008
2274.2;1.475356;-0.8656686;1540.531;159.1885;5;5;0;4.646791;4.54206;1413814;1.665857e+008
2281.2;1.533481;-0.9330679;1693.073;174.9512;5;5;0;4.829862;4.716849;1553808;1.834011e+008
2288.2;1.591981;-1.00225;1837.641;189.89;5;5;0;5.014114;4.892457;1686485;1.994113e+008
2295.2;1.65032;-1.068429;1977.965;204.3901;5;5;0;5.197859;5.067277;1815267;2.15014e+008
2302.2;1.708767;-1.137063;2112.215;218.2626;5;5;0;5.381943;5.242111;1938474;2.300094e+008
2309.2;1.766945;-1.211667;2245.988;232.0859;5;5;0;5.565182;5.415842;2061244;2.450019e+008
2316.2;1.825445;-1.285389;2381.212;246.0591;5;5;0;5.749434;5.590227;2185345;2.602061e+008
2323.2;1.883677;-1.361499;2513.538;259.7328;5;5;0;5.932842;5.763514;2306786;2.751423e+008
2330.2;1.941856;-1.445097;2651.025;273.9398;5;5;0;6.116082;5.936342;2432964;2.906942e+008
2337.2;2.000302;-1.532944;2789.321;288.2304;5;5;0;6.300165;6.109665;2559884;3.063894e+008
2344.2;2.058642;-1.624186;2940.262;303.8277;5;5;0;6.483911;6.282371;2698410;3.235276e+008
2351.2;2.117141;-1.719396;3080.444;318.3131;5;5;0;6.668162;6.455254;2827061;3.395388e+008
2358.2;2.17532;-1.813511;3187.467;329.3723;5;5;0;6.851401;6.626891;2925281;3.519389e+008
2365.2;2.233767;-1.928616;3315.277;342.5793;5;5;0;7.035485;6.799023;3042577;3.666814e+008
2370.184;2.243463;-1.98124;3223.459;333.0915;5;5;0;7.066025;6.827551;2958313;3.566278e+008
2377.184;2.18507;-1.87115;2786.246;287.9127;5;5;0;6.882111;6.655627;2557062;3.077271e+008
2384.184;2.126731;-1.777005;2459.494;254.1482;5;5;0;6.698365;6.483565;2257187;2.71172e+008
2391.184;2.068338;-1.691141;2199.932;227.3267;5;5;0;6.514451;6.311048;2018975;2.421358e+008
2398.184;2.010052;-1.605935;1981.956;204.8025;5;5;0;6.330873;6.138549;1818929;2.177683e+008
2405.184;1.951606;-1.528426;1785.7;184.5228;5;5;0;6.146791;5.965277;1638817;1.95865e+008
2412.184;1.89332;-1.453179;1615.115;166.8956;5;5;0;5.963213;5.792181;1482263;1.768479e+008
2419.184;1.835088;-1.378413;1467.623;151.6546;5;5;0;5.779805;5.618943;1346903;1.6042e+008
2426.184;1.776749;-1.309775;1331.005;137.5374;5;5;0;5.596059;5.445087;1221522;1.452341e+008
2433.184;1.71841;-1.238766;1206.26;124.6472;5;5;0;5.412314;5.270927;1107039;1.313934e+008
2440.184;1.659963;-1.17017;1093.373;112.9821;5;5;0;5.22823;5.096143;1003437;1.18889e+008
2447.184;1.601731;-1.103786;988.3826;102.1331;5;5;0;5.044822;4.921695;907082.8;1.072855e+008
2454.184;1.543285;-1.035375;885.9396;91.54728;5;5;0;4.860739;4.746299;813066.3;9.599715e+007
2461.184;1.484999;-0.9677565;786.7312;81.29572;5;5;0;4.677163;4.571078;722018.3;8.509806e+007
2468.184;1.426767;-0.9067017;692.1129;71.51847;5;5;0;4.493754;4.395712;635182.8;7.473234e+007
2475.184;1.368428;-0.8460277;599.7922;61.97865;5;5;0;4.310008;4.219713;550456.1;6.464994e+007
2482.184;1.310035;-0.7770334;505.4834;52.23338;5;5;0;4.126094;4.043242;463904.6;5.438858e+007
2489.184;1.251588;-0.7006866;410.9688;42.46686;5;5;0;3.942011;3.866297;377164.4;4.414091e+007
2496.184;1.19341;-0.6183152;316.9637;32.75298;5;5;0;3.758771;3.689851;290891.7;3.398409e+007
2503.184;1.134964;-0.5343483;227.9703;23.55698;5;5;0;3.574688;3.512279;209218.5;2.439907e+007
2510.184;1.076678;-0.455552;149.3446;15.4323;5;5;0;3.391111;3.334881;137060.2;1.595563e+007
2517.184;1.018392;-0.3794181;86.55115;8.943637;5;5;0;3.207534;3.157167;79431.85;9230507
2524.184;0.9601066;-0.3272945;54.23235;5.604021;5;5;0;3.023958;2.979137;49771.45;5773484
2531.184;0.9016065;-0.3253118;53.8973;5.569399;5;5;0;2.839706;2.800133;49463.96;5727553
2538.184;0.8432673;-0.3237908;53.96598;5.576496;5;5;0;2.65596;2.621302;49526.99;5724606
2544.63;0.7896424;-0.3228217;53.40536;5.518565;5;5;0;2.487062;2.456639;49012.48;5655815
2550.632;0.8395173;-0.3239675;54.13515;5.593977;6;6;0;2.644149;2.609796;49682.25;5741890
2557.632;0.8979101;-0.3252611;54.25519;5.606381;6;6;0;2.828063;2.788812;49792.41;5764933
2564.632;0.9562494;-0.3262502;55.96899;5.783474;6;6;0;3.011809;2.967345;51365.24;5957661
2571.632;1.014642;-0.389735;183.0868;18.919;6;6;0;3.195724;3.145723;168026.9;1.95236e+007
2578.632;1.072981;-0.4560425;335.4975;34.66815;6;6;0;3.379469;3.32362;307901;3.583975e+007
2585.632;1.131428;-0.522585;498.9269;51.55588;6;6;0;3.563552;3.501527;457887.4;5.33931e+007
2592.632;1.18966;-0.5932187;670.4733;69.28238;6;6;0;3.74696;3.678468;615323.3;7.187836e+007
2599.632;1.247839;-0.6613905;843.7543;87.18812;6;6;0;3.9302;3.854933;774350.9;9.061478e+007
2606.632;1.306285;-0.7227679;1012.778;104.654;6;6;0;4.114283;4.031898;929471.8;1.089597e+008
2613.632;1.364624;-0.7816515;1175.835;121.5032;6;6;0;4.298028;4.208227;1079117;1.267255e+008
2620.632;1.42307;-0.845593;1333.324;137.7771;6;6;0;4.482112;4.384569;1223651;1.439524e+008
2627.632;1.481303;-0.9110361;1485.964;153.5499;6;6;0;4.66552;4.559956;1363735;1.607138e+008
2634.632;1.539695;-0.9769088;1632.971;168.7407;6;6;0;4.849434;4.735518;1498650;1.769236e+008
2641.632;1.597981;-1.042664;1772.463;183.1549;6;6;0;5.033011;4.910451;1626668;1.923731e+008
2648.632;1.65616;-1.10554;1904.914;196.8415;6;6;0;5.216251;5.084758;1748224;2.071092e+008
2655.632;1.714606;-1.172794;2032.512;210.0267;6;6;0;5.400334;5.259562;1865327;2.213688e+008
2662.632;1.772999;-1.242367;2162.061;223.4135;6;6;0;5.584249;5.433901;1984220;2.358894e+008
2669.632;1.831445;-1.314192;2293.159;236.9602;6;6;0;5.768332;5.608096;2104534;2.506288e+008
2676.632;1.889624;-1.389138;2411.038;249.1411;6;6;0;5.951571;5.781193;2212717;2.639689e+008
2683.632;1.94807;-1.471358;2539.63;262.429;6;6;0;6.135654;5.954784;2330732;2.785307e+008
2690.632;2.006249;-1.555085;2682.367;277.1785;6;6;0;6.318893;6.127282;2461728;2.946931e+008
2697.632;2.064534;-1.642181;2828.744;292.3041;6;6;0;6.50247;6.299799;2596065;3.113111e+008
2704.632;2.122927;-1.734753;2977.749;307.7014;6;6;0;6.686385;6.472336;2732813;3.282755e+008
2711.632;2.181374;-1.840931;3125.98;323.0186;6;6;0;6.870468;6.644733;2868851;3.452115e+008
2718.632;2.239713;-2.008525;3281.648;339.1043;6;6;0;7.054214;6.816519;3011714;3.630254e+008
2723.83;2.201516;-1.945933;2934.812;303.2645;6;6;0;6.93391;6.70408;2693408;3.242926e+008
2730.83;2.143177;-1.847361;2549.984;263.4989;6;6;0;6.750165;6.532101;2340234;2.812855e+008
2737.83;2.084677;-1.757462;2258.106;233.3381;6;6;0;6.565912;6.35935;2072365;2.486589e+008
2744.83;2.026338;-1.671145;2024.572;209.2062;6;6;0;6.382166;6.186777;1858040;2.225581e+008
2751.83;1.968213;-1.586225;1819.08;187.9719;6;6;0;6.199096;6.014541;1669451;1.996245e+008
2758.83;1.90982;-1.501352;1639.113;169.3753;6;6;0;6.015182;5.841212;1504287;1.795635e+008
2765.83;1.851534;-1.417231;1484.365;153.3847;6;6;0;5.831604;5.667901;1362268;1.623295e+008
2772.83;1.793142;-1.344622;1345.293;139.0139;6;6;0;5.64769;5.49397;1234635;1.468649e+008
2779.83;1.734856;-1.278234;1218.337;125.8951;6;6;0;5.464114;5.320055;1118122;1.327742e+008
2786.83;1.676356;-1.209765;1099.185;113.5827;6;6;0;5.279861;5.145197;1008771;1.195797e+008
2793.83;1.61807;-1.14404;992.2347;102.5311;6;6;0;5.096285;4.970674;910618.1;1.077564e+008
2800.83;1.559892;-1.076798;891.3713;92.10855;6;6;0;4.913045;4.796168;818051.2;9.663389e+007
2807.83;1.501499;-1.009449;793.8254;82.02879;6;6;0;4.729131;4.620713;728528.9;8.590803e+007
2814.83;1.443213;-0.9433685;698.5692;72.18562;6;6;0;4.545554;4.445271;641108.1;7.546686e+007
2821.83;1.384767;-0.8816578;607.5866;62.78408;6;6;0;4.361471;4.269037;557609.3;6.552238e+007
2828.83;1.326535;-0.8135455;514.8562;53.20192;6;6;0;4.178062;4.093139;472506.5;5.542473e+007
2835.83;1.267981;-0.7374762;421.9484;43.60142;6;6;0;3.993642;3.915957;387240.8;4.534271e+007
2842.83;1.209749;-0.6567022;329.9621;34.09615;6;6;0;3.810234;3.739437;302820.9;3.539529e+007
2849.83;1.151571;-0.5746923;240.7205;24.8745;6;6;0;3.626994;3.562767;220919.9;2.57767e+007
2856.83;1.093231;-0.4968571;161.5645;16.69503;6;6;0;3.443249;3.385295;148275;1.726988e+007
2863.83;1.034839;-0.4215563;98.07506;10.13444;6;6;0;3.259334;3.207345;90007.85;1.046476e+007
2870.83;0.9764458;-0.3538224;55.05893;5.689434;6;6;0;3.07542;3.029077;50530.04;5864408
2877.83;0.9182137;-0.3498933;53.9424;5.574059;6;6;0;2.892012;2.850982;49505.35;5735262
2884.83;0.8597138;-0.3483104;53.956;5.575465;6;6;0;2.70776;2.671749;49517.83;5726435
2891.83;0.8014281;-0.3470875;53.69128;5.54811;6;6;0;2.524183;2.492852;49274.88;5688154
2898.83;0.7432495;-0.346245;53.52693;5.531127;6;6;0;2.340944;2.313964;49124.05;5660608
2905.83;0.6848567;-0.3454845;53.35852;5.513725;6;6;0;2.157029;2.134094;48969.5;5632658
2912.83;0.6265174;-0.3267006;42.0054;4.340567;6;6;0;1.973283;1.954066;38550.23;4426219
2919.83;0.568071;-0.3227008;41.98849;4.33882;6;6;0;1.7892;1.773382;38534.71;4416450
2925.564;0.5368925;-0.3218457;42.03045;4.343155;7;7;0;1.691;1.676862;38573.22;4416598
2932.564;0.5952318;-0.3232777;42.24102;4.364914;7;7;0;1.874746;1.857389;38766.47;4446746
2939.564;0.6536781;-0.3282411;53.79896;5.559237;7;7;0;2.058829;2.037921;49373.7;5673692
2946.564;0.712071;-0.3300796;53.82639;5.562071;7;7;0;2.242743;2.217964;49398.88;5686814
2953.564;0.7705174;-0.3317134;54.31492;5.612553;7;7;0;2.426826;2.397847;49847.23;5748760
2960.564;0.8286423;-0.3330364;54.69199;5.651517;7;7;0;2.609897;2.57642;50193.28;5799016
2967.564;0.8870888;-0.3340739;55.12368;5.696125;7;7;0;2.79398;2.755661;50589.46;5855273
2974.564;0.9453209;-0.3409415;72.38938;7.480251;7;7;0;2.977389;2.933925;66434.97;7702968
2981.564;1.003607;-0.4119593;188.03;19.4298;7;7;0;3.160965;3.112035;172563.5;2.004397e+007
2988.564;1.061999;-0.4776178;328.9841;33.99509;7;7;0;3.34488;3.290155;301923.4;3.513219e+007
2995.564;1.120446;-0.5418449;483.3537;49.94665;7;7;0;3.528963;3.468122;443595.2;5.170925e+007
3002.564;1.178839;-0.6125851;646.3278;66.78735;7;7;0;3.712878;3.64561;593163.9;6.926707e+007
3009.564;1.236963;-0.6838842;811.0187;83.80544;7;7;0;3.895948;3.821971;744308;8.707045e+007
3016.564;1.29541;-0.7478287;973.4207;100.587;7;7;0;4.080031;3.998995;893351.6;1.04691e+008
3023.564;1.353588;-0.805653;1129.178;116.682;7;7;0;4.263271;4.174896;1036297;1.216565e+008
3030.564;1.411928;-0.8678987;1280.353;132.3034;7;7;0;4.447016;4.350974;1175037;1.38187e+008
3037.564;1.470374;-0.9327823;1427.98;147.5582;7;7;0;4.631099;4.527064;1310521;1.543918e+008
3044.564;1.52882;-0.9996342;1571.312;162.3693;7;7;0;4.815183;4.702845;1442064;1.701877e+008
3051.564;1.587106;-1.064104;1708.377;176.5327;7;7;0;4.998759;4.877835;1567854;1.853571e+008
3058.564;1.645285;-1.126597;1836.01;189.7214;7;7;0;5.181999;5.052199;1684988;1.995528e+008
3065.564;1.703731;-1.190008;1959.103;202.4411;7;7;0;5.366082;5.22706;1797957;2.133042e+008
3072.564;1.761963;-1.254456;2084.651;215.4144;7;7;0;5.54949;5.400976;1913178;2.273688e+008
3079.564;1.820302;-1.324293;2214.278;228.8092;7;7;0;5.733236;5.574909;2032142;2.419274e+008
3086.564;1.878695;-1.399541;2345.712;242.3907;7;7;0;5.91715;5.7487;2152764;2.567333e+008
3093.564;1.937142;-1.478895;2474.706;255.7201;7;7;0;6.101233;5.922349;2271148;2.713222e+008
3100.564;1.995427;-1.564682;2616.65;270.3877;7;7;0;6.284811;6.09522;2401416;2.87381e+008
3107.564;2.053606;-1.657827;2765.467;285.7655;7;7;0;6.46805;6.267475;2537993;3.04249e+008
3114.564;2.112052;-1.752034;2920.133;301.7477;7;7;0;6.652133;6.440226;2679937;3.218204e+008
3121.564;2.170284;-1.866567;3083.124;318.5901;7;7;0;6.835541;6.612047;2829520;3.403675e+008
3128.564;2.228677;-2.033196;3240.59;334.8617;7;7;0;7.019455;6.784046;2974034;3.583671e+008
3134.03;2.274374;-2.290023;3190.732;329.7097;7;7;0;7.163381;6.918441;2928278;3.53328e+008
3140.97;2.216409;-2.187976;2736.727;282.7957;7;7;0;6.980816;6.747935;2511616;3.025371e+008
3147.97;2.158124;-2.092891;2401.084;248.1125;7;7;0;6.797239;6.576189;2203582;2.649774e+008
3154.97;2.099838;-2.008281;2140.1;221.1441;7;7;0;6.613663;6.404148;1964065;2.357698e+008
3161.97;2.041499;-1.921507;1924.125;198.8266;7;7;0;6.429917;6.231653;1765855;2.11611e+008
3168.97;1.982999;-1.835974;1740.149;179.8158;7;7;0;6.245665;6.058382;1597013;1.910465e+008
3175.97;1.92466;-1.747008;1579.619;163.2276;7;7;0;6.06192;5.885289;1449686;1.731223e+008
3182.97;1.866427;-1.664509;1430.778;147.8474;7;7;0;5.878512;5.712214;1313089;1.565386e+008
3189.97;1.808088;-1.589925;1294.946;133.8114;7;7;0;5.694766;5.538519;1188430;1.414316e+008
3196.97;1.749749;-1.520882;1168.071;120.7009;7;7;0;5.51102;5.364522;1071991;1.273527e+008
3203.97;1.691463;-1.446956;1053.38;108.8495;7;7;0;5.327443;5.190382;966734.1;1.146484e+008
3210.97;1.633124;-1.373179;947.5958;97.91843;7;7;0;5.143697;5.015777;869650.9;1.029551e+008
3217.97;1.574624;-1.294934;850.4771;87.8828;7;7;0;4.959445;4.840385;780520.8;9.224131e+007
3224.97;1.516285;-1.215288;759.9533;78.52866;7;7;0;4.7757;4.665169;697443;8.227896e+007
3231.97;1.45816;-1.146627;674.424;69.69061;7;7;0;4.592629;4.490289;618948.9;7.289125e+007
3238.97;1.399767;-1.087793;590.2231;60.98984;7;7;0;4.408715;4.314296;541674;6.367871e+007
3245.97;1.341428;-1.022959;504.8494;52.16788;7;7;0;4.224969;4.138155;463322.8;5.437195e+007
3252.97;1.283142;-0.9489463;418.1032;43.20408;7;7;0;4.041392;3.961864;383711.9;4.495013e+007
3259.97;1.224803;-0.8733399;332.1462;34.32184;7;7;0;3.857647;3.785099;304825.4;3.564586e+007
3266.97;1.166303;-0.7986976;249.1709;25.74771;7;7;0;3.673395;3.607534;228675.3;2.669353e+007
3273.97;1.107964;-0.7215439;171.7944;17.75212;7;7;0;3.489649;3.430141;157663.4;1.837161e+007
3280.97;1.049839;-0.6471246;107.958;11.15568;7;7;0;3.306578;3.253087;99077.88;1.152455e+007
3287.97;0.9914458;-0.5783257;60.25893;6.226769;7;7;0;3.122664;3.0749;55302.31;6421210
3294.97;0.9331066;-0.5655676;54.39015;5.620327;7;7;0;2.938918;2.89656;49916.27;5785504
3301.97;0.8747137;-0.5643742;54.14884;5.595391;7;7;0;2.755004;2.717737;49694.8;5749544
3302.48;0.8703745;-0.5642239;54.24175;5.604992;7;7;0;2.741337;2.704435;49780.07;5758643