File: Ensayos/Resistencia/comp/EspD/RED4.raw
"Test Type";"Manual"
"Method Name:";"C:\INSTRON\USER\TEMPLATE\CYCLE.MTM"
"Name:";""
"Operator ID:";""
"Company:";""
"Lab name:";""
"Test date:";"23/06/2017"
"Temperature:";""
"Humidity:";""
"Note 1:";""
"Note 2:";""
"Note 3:";""
"Geometry:";"Rectangular"
"Specimen";1
"Specimen name:";""
"Width:";0.250000;"in"
"Thickness:";0.060000;"in"
"Length:";1.250000;"in"
"Diameter:";0.039370;"in"
"Inner diameter:";0.019685;"in"
"Outer diameter:";0.039370;"in"
"Wall thickness:";0.019685;"in"
"Area:";0.015000;"in*in"
"Linear density:";1.000000;"den"
"Sled weight:";2.204623;"lbf"
"Loading span:";0.000000;"mm"
"Support span:";1.000000;"mm"
"Span ratio:";"2"
"Fixture type:";"3-point"
"Comment:";""
"Included"
"Final Width:";0.250000;"in"
"Final Thickness:";0.060000;"in"
"Final Length:";1.250000;"in"
"Final Diameter:";0.039370;"in"
"Final Inner diameter:";0.019685;"in"
"Final Outer diameter:";0.039370;"in"
"Final Wall thickness:";0.019685;"in"
"Final Area:";0.015000;"in*in"
"Final Linear density:";1.000000;"den"
"Time sec";"Extension mm";"Strain 1 %";"Load N";"Stress MPa";"Cycle Count ";"Total Cycle Count ";"Repetitions Count ";"Strain [Exten.] %";"True strain %";"Tenacity gf/tex";"True stress Pa"
0;0;0.0004806602;42.85873;4.428745;0;0;0;0;0;39333.37;4428745
5;0.0001071428;0.0005069701;42.66942;4.409183;0;0;0;0.0003374576;0.000337457;39159.63;4409197
10;0.0001607142;0.0005602185;42.81393;4.424115;0;0;0;0.0005061864;0.0005061851;39292.25;4424137
15;0.000267857;0.000500707;42.61246;4.403296;0;0;0;0.000843644;0.0008436404;39107.35;4403333
20;0.0003749997;0.0005075964;42.88637;4.4316;0;0;0;0.001181102;0.001181095;39358.73;4431652
25;0.0004285712;0.0004981994;42.62746;4.404846;0;0;0;0.00134983;0.001349821;39121.12;4404906
30;0.0005357139;0.0006554369;42.88519;4.431479;0;0;0;0.001687288;0.001687274;39357.66;4431554
35;0.0006428567;0.0005959254;42.95702;4.4389;0;0;0;0.002024746;0.002024725;39423.57;4438990
40;0.0006964281;0.0005940464;42.73652;4.416116;0;0;0;0.002193474;0.00219345;39221.21;4416213
45;0.0008035709;0.0006911438;42.80641;4.423337;0;0;0;0.002530932;0.0025309;39285.35;4423450
50;0.0009107137;0.0006579421;42.73699;4.416164;0;0;0;0.00286839;0.002868348;39221.64;4416291
55;0.0009642851;0.0005019596;42.80787;4.423489;0;0;0;0.003037118;0.003037072;39286.7;4423624
60;0.001071428;0.0006472925;42.84963;4.427804;0;0;0;0.003374576;0.003374519;39325.02;4427954
65;0.001124999;0.0007869885;42.69979;4.41232;0;0;0;0.003543305;0.003543242;39187.5;4412476
70;0.001178571;0.0006761099;42.93599;4.436728;0;0;0;0.003712033;0.003711965;39404.27;4436893
75;0.001285713;0.0006648339;42.85368;4.428223;0;0;0;0.004049491;0.004049409;39328.74;4428402
80;0.001339285;0.0007080589;42.65768;4.407969;0;0;0;0.00421822;0.004218131;39148.85;4408155
85.00001;0.001446428;0.0008621626;43.0427;4.447755;0;0;0;0.004555678;0.004555574;39502.21;4447958
90.00001;0.001499999;0.0006491714;42.95473;4.438664;0;0;0;0.004724406;0.004724294;39421.47;4438874
95.00001;0.001607142;0.0008496339;43.06549;4.450109;0;0;0;0.005061864;0.005061736;39523.12;4450335
100;0.001714285;0.001021279;43.13922;4.457729;0;0;0;0.005399322;0.005399176;39590.79;4457970
105;0.001821427;0.0009899563;43.02221;4.445637;0;0;0;0.005736779;0.005736615;39483.4;4445892
110;0.00192857;0.001006243;42.83072;4.42585;0;0;0;0.006074237;0.006074052;39307.66;4426119
115;0.001982142;0.001048842;42.96186;4.439402;0;0;0;0.006242966;0.006242771;39428.02;4439679
120;0.002035713;0.001251183;43.02177;4.445591;0;0;0;0.006411694;0.006411489;39482.99;4445876
125;0.002142856;0.001290021;43.02338;4.445758;0;0;0;0.006749152;0.006748924;39484.47;4446058
130;0.002196427;0.001352665;43.25536;4.469729;0;0;0;0.006917881;0.006917642;39697.37;4470039
135;0.00230357;0.001541851;43.17837;4.461774;0;0;0;0.007255339;0.007255075;39626.71;4462097
140;0.002357141;0.001321344;42.83762;4.426563;0;0;0;0.007424067;0.007423791;39314;4426892
145;0.002464284;0.001641456;42.95614;4.438809;0;0;0;0.007761525;0.007761224;39422.76;4439154
150;0.002571427;0.001690318;43.15843;4.459713;0;0;0;0.008098982;0.008098654;39608.41;4460075
155;0.002624998;0.00154373;43.02864;4.446301;0;0;0;0.008267712;0.00826737;39489.3;4446669
160;0.002732141;0.001805583;43.1414;4.457953;0;0;0;0.008605169;0.008604799;39592.79;4458337
165;0.002785712;0.001727904;43.14986;4.458827;0;0;0;0.008773897;0.008773512;39600.55;4459219
170;0.002892855;0.001812472;43.09647;4.453311;0;0;0;0.009111355;0.00911094;39551.55;4453717
175;0.002999998;0.001807462;43.14286;4.458105;0;0;0;0.009448812;0.009448366;39594.13;4458526
180;0.002999998;0.001571293;42.9929;4.442609;0;0;0;0.009448812;0.009448366;39456.5;4443028
185;0.003107141;0.001922101;43.22791;4.466893;0;0;0;0.009786271;0.009785792;39672.18;4467330
190;0.003214284;0.002063049;43.06294;4.449846;0;0;0;0.01012373;0.01012322;39520.78;4450296
195;0.003267855;0.00189767;43.06869;4.45044;0;0;0;0.01029246;0.01029193;39526.06;4450898
200;0.003374998;0.001952797;43.1441;4.458232;0;0;0;0.01062991;0.01062935;39595.27;4458707
205;0.003428569;0.002311121;43.04085;4.447564;0;0;0;0.01079864;0.01079806;39500.51;4448044
210;0.003535712;0.002348081;43.11864;4.455602;0;0;0;0.0111361;0.01113548;39571.9;4456098
215;0.003589283;0.002134463;41.88066;4.327677;0;0;0;0.01130483;0.01130419;38435.75;4328167
220;0.003696426;0.002537265;43.10954;4.454661;0;0;0;0.01164229;0.01164161;39563.54;4455180
225;0.003803569;0.002717681;43.4075;4.48545;0;0;0;0.01197974;0.01197903;39837;4485988
230;0.00385714;0.002746496;42.84068;4.426878;0;0;0;0.01214847;0.01214774;39316.8;4427416
235;0.003964283;0.002977026;43.05971;4.449512;0;0;0;0.01248593;0.01248515;39517.81;4450067
240;0.004017854;0.00313489;43.34219;4.478702;0;0;0;0.01265466;0.01265386;39777.06;4479269
245;0.004124997;0.003323448;43.09905;4.453578;0;0;0;0.01299212;0.01299127;39553.93;4454156
250;0.004178569;0.003393611;42.98677;4.441975;0;0;0;0.01316085;0.01315998;39450.87;4442559
255;0.004285712;0.003745044;43.08367;4.451988;0;0;0;0.0134983;0.01349739;39539.8;4452589
260;0.004392855;0.003885992;43.10093;4.453772;0;0;0;0.01383576;0.01383481;39555.65;4454388
265;0.004446426;0.004008149;43.09923;4.453596;0;0;0;0.01400449;0.01400351;39554.09;4454220
270;0.004499997;0.00438652;43.14936;4.458776;0;0;0;0.01417322;0.01417221;39600.09;4459408
275;0.00460714;0.004462318;43.07433;4.451023;0;0;0;0.01451068;0.01450962;39531.23;4451669
280;0.004714283;0.00484382;43.09397;4.453053;0;0;0;0.01484813;0.01484703;39549.26;4453714
285;0.004767854;0.004905839;43.22098;4.466177;0;0;0;0.01501686;0.01501574;39665.82;4466847
290;0.004874997;0.0054546;43.27395;4.471651;0;0;0;0.01535432;0.01535314;39714.43;4472337
295;0.00498214;0.005712695;42.97017;4.44026;0;0;0;0.01569178;0.01569055;39435.64;4440957
300;0.005089282;0.005871183;43.04793;4.448295;0;0;0;0.01602923;0.01602795;39507.01;4449008
305;0.005089282;0.00631721;43.03698;4.447163;0;0;0;0.01602923;0.01602795;39496.95;4447876
310;0.005303568;0.006832145;43.13464;4.457255;0;0;0;0.01670415;0.01670276;39586.59;4458000
315;0.005303568;0.007224923;43.14692;4.458524;0;0;0;0.01670415;0.01670276;39597.85;4459269
320;0.005357139;0.00781503;43.09022;4.452664;0;0;0;0.01687288;0.01687146;39545.81;4453416
325;0.005464282;0.008321195;43.04981;4.448489;0;0;0;0.01721034;0.01720886;39508.73;4449255
330;0.005571425;0.008762209;43.32114;4.476526;0;0;0;0.01754779;0.01754625;39757.74;4477312
335;0.005624996;0.009315982;43.2881;4.473113;0;0;0;0.01771652;0.01771495;39727.42;4473905
340;0.005678568;0.009937412;43.30246;4.474597;0;0;0;0.01788525;0.01788365;39740.6;4475397
345;0.00578571;0.01082195;43.18494;4.462453;0;0;0;0.01822271;0.01822105;39632.75;4463266
350;0.005892853;0.0116382;43.4208;4.486825;0;0;0;0.01856017;0.01855845;39849.21;4487658
355;0.005946425;0.01253025;43.60691;4.506056;0;0;0;0.0187289;0.01872714;40020.01;4506900
360;0.005999996;0.01328261;43.19141;4.463121;0;0;0;0.01889762;0.01889584;39638.68;4463964
365;0.006107139;0.01440456;43.13617;4.457413;0;0;0;0.01923508;0.01923323;39587.98;4458270
370;0.006214282;0.01538119;43.29891;4.474229;0;0;0;0.01957254;0.01957063;39737.34;4475105
375;0.006321425;0.01634465;43.3932;4.483973;0;0;0;0.01991;0.01990802;39823.87;4484865
380;0.006374996;0.01713835;43.35185;4.479701;0;0;0;0.02007873;0.02007671;39785.93;4480600
385;0.006428567;0.01842569;43.40133;4.484813;0;0;0;0.02024746;0.02024541;39831.34;4485721
390;0.00653571;0.01993854;43.29139;4.473453;0;0;0;0.02058491;0.0205828;39730.44;4474374
395;0.006642853;0.02131358;43.30651;4.475015;0;0;0;0.02092237;0.02092018;39744.32;4475952
400;0.006696424;0.02269614;43.15003;4.458846;0;0;0;0.0210911;0.02108888;39600.71;4459786
405;0.006803567;0.0242992;43.25166;4.469347;0;0;0;0.02142856;0.02142626;39693.98;4470305
410;0.006857139;0.02572623;43.20509;4.464535;0;0;0;0.02159729;0.02159496;39651.24;4465499
415;0.006964281;0.02762623;43.40166;4.484847;0;0;0;0.02193474;0.02193234;39831.63;4485830
420;0.007071424;0.0295256;43.38912;4.483551;0;0;0;0.0222722;0.02226972;39820.13;4484550
425;0.007124995;0.03195305;43.41319;4.486039;0;0;0;0.02244093;0.02243841;39842.22;4487046
430;0.007232138;0.03384553;43.52575;4.49767;0;0;0;0.02277839;0.02277579;39945.52;4498694
435;0.00728571;0.03571671;43.51612;4.496675;0;0;0;0.02294712;0.02294448;39936.68;4497706
440;0.007392853;0.03805772;43.32672;4.477103;0;0;0;0.02328457;0.02328186;39762.86;4478146
445;0.007446424;0.04014941;43.39601;4.484264;0;0;0;0.0234533;0.02345055;39826.46;4485316
450;0.007499996;0.04240334;43.55312;4.500498;0;0;0;0.02362203;0.02361924;39970.64;4501561
455;0.007607138;0.04499868;43.4349;4.488282;0;0;0;0.02395949;0.02395662;39862.14;4489357
460;0.007714281;0.04869531;43.19713;4.463712;0;0;0;0.02429695;0.024294;39643.93;4464797
465;0.007767852;0.05120547;43.24265;4.468416;0;0;0;0.02446567;0.02446268;39685.71;4469509
470;0.007874995;0.05344562;42.42593;4.384022;0;0;0;0.02480313;0.02480006;38936.17;4385109
475;0.007928567;0.05599147;43.51074;4.496119;0;0;0;0.02497186;0.02496875;39931.75;4497242
480;0.008035709;0.05826608;43.62183;4.507598;0;0;0;0.02530932;0.02530612;40033.7;4508739
485;0.008142852;0.05971191;42.49227;4.390876;0;0;0;0.02564678;0.02564349;38997.05;4392003
490;0.008196423;0.06281341;43.53644;4.498774;0;0;0;0.0258155;0.02581217;39955.33;4499935
495;0.008303566;0.06572574;43.35426;4.479949;0;0;0;0.02615296;0.02614954;39788.14;4481121
500;0.008357138;0.07059006;43.41822;4.486558;0;0;0;0.02632169;0.02631823;39846.83;4487739
505;0.00846428;0.07219187;43.55335;4.500522;0;0;0;0.02665915;0.0266556;39970.85;4501722
510;0.008571423;0.0750641;43.5503;4.500206;0;0;0;0.02699661;0.02699296;39968.05;4501421
515;0.008678566;0.07675799;43.57984;4.503259;0;0;0;0.02733407;0.02733033;39995.16;4504490
520;0.008678566;0.0786962;43.52331;4.497418;0;0;0;0.02733407;0.02733033;39943.29;4498647
525;0.008785709;0.08150516;43.59141;4.504455;0;0;0;0.02767153;0.0276677;40005.78;4505701
530;0.008946423;0.08423707;41.52541;4.290968;0;0;0;0.02817771;0.02817374;38109.72;4292177
535;0.008946423;0.0847282;43.57711;4.502976;0;0;0;0.02817771;0.02817374;39992.65;4504245
540;0.009053566;0.08669334;43.46247;4.491131;0;0;0;0.02851517;0.0285111;39887.45;4492411
545;0.009160708;0.08837346;43.39854;4.484525;0;0;0;0.02885262;0.02884846;39828.78;4485819
550;0.00921428;0.0898838;43.45768;4.490636;0;0;0;0.02902135;0.02901714;39883.05;4491939
555;0.009321422;0.09279425;43.48152;4.4931;0;0;0;0.02935881;0.0293545;39904.93;4494419
560;0.009374994;0.09476065;43.62021;4.507431;0;0;0;0.02952754;0.02952318;40032.21;4508762
565;0.009482137;0.09762662;43.56248;4.501466;0;0;0;0.029865;0.02986054;39979.23;4502810
570;0.009535708;0.1001587;43.60477;4.505835;0;0;0;0.03003373;0.03002922;40018.04;4507188
575;0.009642851;0.10292;43.56331;4.501551;0;0;0;0.03037118;0.03036657;39979.99;4502918
580;0.009696422;0.1067965;43.68267;4.513885;0;0;0;0.03053991;0.03053525;40089.54;4515264
585;0.009803565;0.1086695;43.75168;4.521016;0;0;0;0.03087737;0.0308726;40152.87;4522412
590;0.009857137;0.1119502;43.64053;4.509531;0;0;0;0.0310461;0.03104128;40050.86;4510931
595;0.00996428;0.1139936;43.62747;4.508181;0;0;0;0.03138356;0.03137863;40038.87;4509595
600;0.01001785;0.1154677;43.73958;4.519766;0;0;0;0.03155228;0.03154731;40141.77;4521192
605;0.01012499;0.1173144;43.56313;4.501533;0;0;0;0.03188974;0.03188466;39979.82;4502968
610;0.01017856;0.1211088;43.79179;4.525161;0;0;0;0.03205847;0.03205333;40189.68;4526611
615;0.01028571;0.125034;43.52413;4.497503;0;0;0;0.03239593;0.03239068;39944.04;4498960
620;0.01039285;0.1279965;43.58389;4.503678;0;0;0;0.03273339;0.03272803;39998.88;4505152
625;0.01044642;0.1309595;43.84946;4.53112;0;0;0;0.03290211;0.0328967;40242.61;4532611
630;0.01049999;0.1355783;43.76137;4.522017;0;0;0;0.03307085;0.03306538;40161.76;4523513
635;0.01060714;0.1388063;43.58703;4.504002;0;0;0;0.0334083;0.03340272;40001.76;4505507
640;0.01071428;0.1425568;43.55861;4.501065;0;0;0;0.03374576;0.03374007;39975.68;4502584
645.0001;0.01076785;0.1440089;43.83704;4.529837;0;0;0;0.03391449;0.03390874;40231.21;4531373
650.0001;0.01087499;0.1443854;43.65222;4.510738;0;0;0;0.03425195;0.03424608;40061.59;4512284
655.0001;0.01092856;0.1459948;43.72096;4.517842;0;0;0;0.03442068;0.03441475;40124.68;4519397
660.0001;0.01103571;0.146593;43.76125;4.522005;0;0;0;0.03475814;0.03475209;40161.65;4523577
665.0001;0.01108928;0.1468473;43.92346;4.538767;0;0;0;0.03492686;0.03492077;40310.52;4540352
670.0001;0.01119642;0.1471155;43.65704;4.511236;0;0;0;0.03526432;0.03525811;40066.01;4512827
675.0001;0.01130356;0.1479123;43.76624;4.522521;0;0;0;0.03560178;0.03559544;40166.23;4524131
680.0001;0.01135714;0.1489221;43.8531;4.531497;0;0;0;0.03577051;0.03576411;40245.95;4533117
685.0001;0.01146428;0.149526;43.98551;4.545178;0;0;0;0.03610796;0.03610145;40367.46;4546819
690.0001;0.01157142;0.1497258;43.76727;4.522627;0;0;0;0.03644542;0.03643878;40167.18;4524275
695.0001;0.01162499;0.15019;43.7024;4.515924;0;0;0;0.03661415;0.03660745;40107.64;4517578
700.0001;0.01173213;0.1507989;43.75444;4.521301;0;0;0;0.03695161;0.03694478;40155.4;4522972
705.0001;0.01183928;0.1510821;43.83223;4.529339;0;0;0;0.03728906;0.03728211;40226.79;4531028
710.0001;0.01189285;0.1510758;43.73409;4.519198;0;0;0;0.03745779;0.03745078;40136.72;4520891
715.0001;0.01194642;0.1517217;43.83786;4.529922;0;0;0;0.03762652;0.03761945;40231.96;4531626
720.0001;0.01205356;0.1525893;43.61041;4.506418;0;0;0;0.03796398;0.03795678;40023.21;4508129
725.0001;0.01216071;0.1532208;43.70088;4.515767;0;0;0;0.03830144;0.03829411;40106.25;4517496
730.0001;0.01221428;0.1533742;43.69677;4.515342;0;0;0;0.03847016;0.03846277;40102.47;4517079
735.0001;0.01232142;0.1532878;43.86047;4.532258;0;0;0;0.03880762;0.0388001;40252.71;4534017
740.0001;0.01237499;0.1537802;43.68012;4.513621;0;0;0;0.03897635;0.03896876;40087.19;4515380
745.0001;0.01242856;0.1542813;43.75447;4.521304;0;0;0;0.03914508;0.03913742;40155.43;4523074
750.0001;0.01253571;0.1553983;43.46717;4.491616;0;0;0;0.03948254;0.03947475;39891.76;4493390
755.0001;0.01264285;0.1557904;43.79411;4.525401;0;0;0;0.03982;0.03981207;40191.81;4527202
760.0001;0.01269642;0.1562389;43.76783;4.522685;0;0;0;0.03998872;0.03998073;40167.69;4524493
765.0001;0.01280356;0.1567595;43.75139;4.520986;0;0;0;0.04032618;0.04031805;40152.6;4522809
770.0001;0.01291071;0.1586106;43.58192;4.503474;0;0;0;0.04066364;0.04065538;39997.07;4505306
775.0001;0.01296428;0.1594964;43.67413;4.513002;0;0;0;0.04083237;0.04082404;40081.7;4514845
780.0001;0.01301785;0.1609554;43.64732;4.510232;0;0;0;0.0410011;0.0409927;40057.09;4512081
785.0001;0.01312499;0.1624301;43.85419;4.531609;0;0;0;0.04133856;0.04133002;40246.95;4533482
790.0001;0.01323213;0.1625647;43.87648;4.533912;0;0;0;0.04167601;0.04166733;40267.4;4535801
795.0001;0.01328571;0.1631643;43.77103;4.523015;0;0;0;0.04184474;0.04183599;40170.63;4524908
800.0001;0.01339285;0.1640901;43.7594;4.521814;0;0;0;0.0421822;0.04217331;40159.95;4523721
805.0001;0.01344642;0.164622;43.75617;4.52148;0;0;0;0.04235093;0.04234196;40156.99;4523395
810.0001;0.01349999;0.1658485;43.84086;4.530231;0;0;0;0.04251966;0.04251062;40234.71;4532158
815.0001;0.01360713;0.1675669;43.73168;4.51895;0;0;0;0.04285712;0.04284794;40134.52;4520886
820.0001;0.01371428;0.1680254;43.80583;4.526611;0;0;0;0.04319457;0.04318525;40202.56;4528566
825.0001;0.01376785;0.1679396;43.61722;4.507122;0;0;0;0.0433633;0.0433539;40029.47;4509076
830.0001;0.01387499;0.1690578;43.77617;4.523547;0;0;0;0.04370076;0.04369122;40175.34;4525523
835.0001;0.01392856;0.169564;43.75288;4.52114;0;0;0;0.04386949;0.04385987;40153.97;4523124
840.0001;0.01403571;0.1705782;43.78386;4.524342;0;0;0;0.04420695;0.04419718;40182.4;4526342
845.0001;0.01414285;0.1781944;43.69506;4.515166;0;0;0;0.0445444;0.04453448;40100.91;4517177
850.0001;0.01419642;0.1807334;43.52672;4.49777;0;0;0;0.04471313;0.04470314;39946.41;4499781
855.0001;0.01430356;0.1852695;43.70566;4.516261;0;0;0;0.04505059;0.04504045;40110.64;4518296
860.0001;0.01435713;0.1855081;43.77294;4.523213;0;0;0;0.04521932;0.0452091;40172.38;4525258
865.0001;0.01446428;0.1849462;43.78571;4.524532;0;0;0;0.04555678;0.0455464;40184.1;4526594
870.0001;0.01451785;0.182359;43.5456;4.499721;0;0;0;0.04572551;0.04571505;39963.74;4501779
875.0001;0.01462499;0.1764128;43.72681;4.518446;0;0;0;0.04606296;0.04605236;40130.04;4520527
880.0001;0.01473213;0.1691035;43.77758;4.523692;0;0;0;0.04640042;0.04638966;40176.63;4525791
885.0001;0.01478571;0.1620673;44.10808;4.557844;0;0;0;0.04656915;0.04655831;40479.95;4559966
890.0001;0.01489285;0.1592584;43.94634;4.541131;0;0;0;0.04690661;0.04689561;40331.51;4543261
895.0001;0.01494642;0.1500503;43.77831;4.523768;0;0;0;0.04707533;0.04706426;40177.31;4525898
900.0001;0.01505356;0.1448133;43.75086;4.520931;0;0;0;0.04741279;0.04740156;40152.11;4523074
905.0001;0.0151607;0.1381429;43.91122;4.537501;0;0;0;0.04775025;0.04773885;40299.28;4539668
910.0001;0.01521428;0.1214138;43.8576;4.53196;0;0;0;0.04791898;0.0479075;40250.07;4534132
915.0001;0.01532142;0.1045964;43.74783;4.520618;0;0;0;0.04825644;0.0482448;40149.34;4522800
920.0001;0.01542856;0.07893737;43.87348;4.533602;0;0;0;0.04859389;0.04858209;40264.65;4535805
925.0001;0.01548213;0.05833311;44.09046;4.556023;0;0;0;0.04876262;0.04875073;40463.78;4558244
930.0001;0.01558928;0.02407994;43.68364;4.513985;0;0;0;0.04910008;0.04908803;40090.43;4516202
935.0001;0.01564285;-0.01106277;43.74225;4.520042;0;0;0;0.04926881;0.04925668;40144.22;4522269
940.0001;0.01574999;-0.04398537;43.95691;4.542223;0;0;0;0.04960626;0.04959397;40341.21;4544476
945.0001;0.01574999;-0.07486015;44.08617;4.55558;0;0;0;0.04960626;0.04959397;40459.84;4557840
950.0001;0.01585713;-0.1043329;43.90352;4.536706;0;0;0;0.04994373;0.04993126;40292.22;4538972
955.0001;0.01596428;-0.1452514;43.94029;4.540505;0;0;0;0.05028118;0.05026855;40325.96;4542788
960.0001;0.01607142;-0.1680827;44.09104;4.556084;0;0;0;0.05061864;0.05060583;40464.32;4558390
965.0001;0.01612499;-0.1892069;43.88546;4.53484;0;0;0;0.05078737;0.05077448;40275.64;4537143
970.0001;0.01623213;-0.2261056;43.85037;4.531214;0;0;0;0.05112483;0.05111176;40243.44;4533531
975.0001;0.0162857;-0.2549914;43.95705;4.542238;0;0;0;0.05129355;0.0512804;40341.35;4544568
980.0001;0.01639285;-0.291469;44.18428;4.565718;0;0;0;0.05163101;0.05161768;40549.88;4568075
985.0001;0.01644642;-0.3258494;43.82573;4.528668;0;0;0;0.05179974;0.05178633;40220.83;4531014
990.0001;0.01655356;-0.3467117;43.92055;4.538466;0;0;0;0.0521372;0.05212361;40307.85;4540833
995.0001;0.01660713;-0.3765372;43.86514;4.532741;0;0;0;0.05230593;0.05229225;40257;4535111
1000;0.01671428;-0.3962432;43.92742;4.539176;0;0;0;0.05264339;0.05262954;40314.16;4541566
1005;0.01676785;-0.4211799;43.93738;4.540205;0;0;0;0.05281211;0.05279818;40323.29;4542603
1010;0.01687499;-0.439192;43.87668;4.533933;0;0;0;0.05314957;0.05313545;40267.59;4536343
1015;0.01692856;-0.4657531;43.99925;4.546598;0;0;0;0.0533183;0.05330409;40380.07;4549022
1020;0.0170357;-0.4849453;44.11853;4.558924;0;0;0;0.05365576;0.05364137;40489.54;4561370
1025;0.01708927;-0.5039365;44.0884;4.55581;0;0;0;0.05382449;0.05381001;40461.89;4558263
1030;0.01719642;-0.526281;43.98797;4.545433;0;0;0;0.05416194;0.05414728;40369.72;4547895
1035;0.01730356;-0.5501841;44.04159;4.550974;0;0;0;0.0544994;0.05448456;40418.93;4553454
1040;0.01735713;-0.5774788;43.7917;4.525152;0;0;0;0.05466813;0.0546532;40189.6;4527626
1045;0.01746427;-0.6074427;44.27566;4.575161;0;0;0;0.05500559;0.05499047;40633.75;4577677
1050;0.01751784;-0.6340596;43.90414;4.53677;0;0;0;0.05517431;0.0551591;40292.79;4539273
1055;0.01762499;-0.6566331;43.9284;4.539277;0;0;0;0.05551178;0.05549637;40315.05;4541796
1060;0.01767856;-0.6826335;44.21109;4.568488;0;0;0;0.05568051;0.05566501;40574.48;4571032
1065;0.0177857;-0.7074274;44.0147;4.548194;0;0;0;0.05601796;0.05600228;40394.25;4550742
1070;0.01789285;-0.7310928;43.8946;4.535784;0;0;0;0.05635542;0.05633955;40284.03;4538340
1075;0.01794642;-0.7569066;43.94149;4.54063;0;0;0;0.05652415;0.05650818;40327.07;4543196
1080;0.01805356;-0.7795812;43.94396;4.540884;0;0;0;0.05686161;0.05684545;40329.33;4543467
1085;0.01810713;-0.8024817;44.00465;4.547156;0;0;0;0.05703034;0.05701408;40385.03;4549750
1090;0.01821427;-0.8244118;44.03936;4.550743;0;0;0;0.05736779;0.05735134;40416.89;4553354
1095;0.01832142;-0.8444833;44.06926;4.553832;0;0;0;0.05770525;0.0576886;40444.32;4556460
1100;0.01842856;-0.8627287;44.01009;4.547718;0;0;0;0.05804271;0.05802587;40390.02;4550358
1105;0.01848213;-0.8793846;43.8534;4.531527;0;0;0;0.05821144;0.0581945;40246.22;4534165
1110;0.0185357;-0.8989367;44.13647;4.560778;0;0;0;0.05838016;0.05836313;40506;4563440
1115;0.01858927;-0.9146006;44.06171;4.553052;0;0;0;0.05854889;0.05853176;40437.39;4555718
1120;0.01869642;-0.9314374;44.09301;4.556287;0;0;0;0.05888636;0.05886902;40466.13;4558970
1125;0.01880356;-0.9505598;43.92599;4.539028;0;0;0;0.05922381;0.05920628;40312.84;4541716
1130;0.0189107;-0.9729012;44.09959;4.556967;0;0;0;0.05956126;0.05954353;40472.16;4559681
1135;0.01896427;-0.9914266;44.14182;4.56133;0;0;0;0.05973;0.05971217;40510.91;4564055
1140;0.01901785;-1.010964;43.97097;4.543676;0;0;0;0.05989873;0.05988079;40354.12;4546398
1145;0.01912499;-1.031046;43.92;4.538409;0;0;0;0.06023618;0.06021804;40307.34;4541142
1150;0.01923213;-1.051441;44.10432;4.557455;0;0;0;0.06057364;0.0605553;40476.5;4560216
1155;0.0192857;-1.066378;43.7594;4.521814;0;0;0;0.06074237;0.06072392;40159.95;4524561
1160;0.01939284;-1.082747;43.96122;4.542669;0;0;0;0.06107982;0.06106118;40345.18;4545444
1165;0.01949999;-1.097716;43.98266;4.544884;0;0;0;0.06141728;0.06139843;40364.85;4547675
1170;0.01955356;-1.111415;43.91858;4.538263;0;0;0;0.06158601;0.06156705;40306.04;4541058
1175;0.0196607;-1.126007;43.88972;4.53528;0;0;0;0.06192347;0.0619043;40279.55;4538088
1180;0.01971427;-1.138751;43.96134;4.542681;0;0;0;0.0620922;0.06207293;40345.28;4545501
1185;0.01982142;-1.150539;43.9335;4.539804;0;0;0;0.06242966;0.06241018;40319.73;4542639
1190;0.01992856;-1.161458;43.92302;4.538721;0;0;0;0.06276712;0.06274743;40310.11;4541570
1195;0.01998213;-1.17255;44.19059;4.56637;0;0;0;0.06293584;0.06291604;40555.67;4569244
1200;0.0200357;-1.181576;43.93101;4.539546;0;0;0;0.06310457;0.06308466;40317.45;4542411
1205;0.02014285;-1.190385;43.86532;4.532759;0;0;0;0.06344203;0.06342192;40257.16;4535634
1210;0.02019641;-1.199471;43.97326;4.543913;0;0;0;0.06361075;0.06359053;40356.22;4546803
1215;0.02030356;-1.208455;44.00098;4.546777;0;0;0;0.06394821;0.06392777;40381.66;4549685
1220;0.02035713;-1.217346;43.77003;4.522913;0;0;0;0.06411694;0.0640964;40169.71;4525812
1225;0.02046427;-1.226274;43.98325;4.544945;0;0;0;0.0644544;0.06443364;40365.39;4547874
1230;0.02051784;-1.233818;44.06529;4.553422;0;0;0;0.06462313;0.06460226;40440.68;4556365
1235;0.02062499;-1.239426;44.11888;4.55896;0;0;0;0.06496058;0.0649395;40489.86;4561922
1240;0.02067856;-1.24562;44.062;4.553082;0;0;0;0.06512932;0.06510812;40437.66;4556048
1245;0.0207857;-1.251147;44.07325;4.554245;0;0;0;0.06546678;0.06544535;40447.98;4557226
1250;0.02089284;-1.255232;44.01056;4.547767;0;0;0;0.06580423;0.06578258;40390.45;4550759
1255;0.02094642;-1.260507;43.98921;4.545561;0;0;0;0.06597296;0.06595121;40370.86;4548560
1260;0.02099999;-1.266557;44.05422;4.552279;0;0;0;0.06614169;0.06611983;40430.52;4555290
1265;0.02110713;-1.270979;44.0366;4.550458;0;0;0;0.06647915;0.06645706;40414.35;4553483
1270;0.02121427;-1.275861;43.8923;4.535547;0;0;0;0.06681661;0.0667943;40281.93;4538578
1275;0.02126784;-1.279901;44.17605;4.564868;0;0;0;0.06698534;0.06696291;40542.33;4567926
1280;0.02137499;-1.283929;44.11274;4.558326;0;0;0;0.06732279;0.06730014;40484.23;4561395
1285;0.02148213;-1.287297;44.03687;4.550486;0;0;0;0.06766025;0.06763737;40414.6;4553564
1290;0.0215357;-1.2918;44.01085;4.547797;0;0;0;0.06782898;0.06780598;40390.72;4550881
1295;0.02164284;-1.294345;44.09836;4.556839;0;0;0;0.06816643;0.06814321;40471.03;4559945
1300;0.02174999;-1.297679;44.08159;4.555107;0;0;0;0.06850389;0.06848044;40455.64;4558227
1305;0.02180356;-1.300606;44.16355;4.563576;0;0;0;0.06867262;0.06864905;40530.86;4566709
1310;0.02185713;-1.30291;44.2305;4.570494;0;0;0;0.06884135;0.06881767;40592.3;4573640
1315;0.02196427;-1.306015;43.89504;4.53583;0;0;0;0.06917881;0.06915489;40284.43;4538967
1320;0.02207142;-1.309607;43.92076;4.538487;0;0;0;0.06951627;0.06949212;40308.04;4541643
1325;0.02217856;-1.311231;43.94035;4.540512;0;0;0;0.06985372;0.06982934;40326.02;4543683
1330;0.02217856;-1.313512;43.92769;4.539204;0;0;0;0.06985372;0.06982934;40314.4;4542374
1335;0.0222857;-1.315579;44.03525;4.550318;0;0;0;0.07019117;0.07016655;40413.11;4553512
1340;0.02239284;-1.317996;44.03161;4.549942;0;0;0;0.07052864;0.07050378;40409.77;4553151
1345;0.02249998;-1.320806;43.99831;4.546501;0;0;0;0.07086609;0.070841;40379.21;4549723
1350;0.02260713;-1.323154;43.99567;4.546228;0;0;0;0.07120355;0.07117821;40376.79;4549465
1355;0.02260713;-1.324844;44.13653;4.560784;0;0;0;0.07120355;0.07117821;40506.06;4564031
1360;0.02271427;-1.326444;44.11982;4.559057;0;0;0;0.07154101;0.07151543;40490.73;4562319
1365;0.02276784;-1.329278;44.13262;4.56038;0;0;0;0.07170974;0.07168404;40502.48;4563650
1370;0.02287499;-1.330744;43.9597;4.542511;0;0;0;0.0720472;0.07202126;40343.77;4545784
1375;0.02298213;-1.33286;44.19772;4.567107;0;0;0;0.07238466;0.07235847;40562.22;4570413
1380;0.02308927;-1.334837;44.12243;4.559327;0;0;0;0.07272211;0.07269568;40493.13;4562643
1385;0.02314284;-1.336112;44.21241;4.568624;0;0;0;0.07289084;0.07286428;40575.7;4571954
1390;0.02324999;-1.335395;44.08253;4.555203;0;0;0;0.0732283;0.0732015;40456.5;4558539
1395;0.02330356;-1.334873;44.13045;4.560156;0;0;0;0.07339703;0.0733701;40500.48;4563503
1400;0.0234107;-1.334884;44.02213;4.548962;0;0;0;0.07373448;0.07370731;40401.07;4552316
1405;0.02346427;-1.335369;44.17435;4.564692;0;0;0;0.07390321;0.07387592;40540.77;4568066
1410;0.02357141;-1.336059;44.07686;4.554618;0;0;0;0.07424067;0.07421313;40451.3;4557999
1415;0.02367856;-1.336864;44.20483;4.567842;0;0;0;0.07457813;0.07455033;40568.74;4571248
1420;0.02367856;-1.337752;44.22691;4.570124;0;0;0;0.07457813;0.07455033;40589.01;4573532
1425;0.0237857;-1.338834;44.0586;4.552731;0;0;0;0.07491559;0.07488754;40434.54;4556142
1430;0.02389284;-1.339864;43.8423;4.53038;0;0;0;0.07525305;0.07522474;40236.03;4533789
1435;0.02394641;-1.340835;44.04691;4.551523;0;0;0;0.07542177;0.07539335;40423.81;4554956
1440;0.02399998;-1.341598;44.10684;4.557716;0;0;0;0.0755905;0.07556194;40478.82;4561161
1445;0.02410713;-1.342639;44.01381;4.548103;0;0;0;0.07592797;0.07589915;40393.44;4551556
1450;0.02421427;-1.343829;44.22683;4.570115;0;0;0;0.07626541;0.07623634;40588.93;4573600
1455;0.02426784;-1.344673;44.09762;4.556763;0;0;0;0.07643414;0.07640495;40470.36;4560246
1460;0.02437499;-1.345425;44.21781;4.569183;0;0;0;0.07677161;0.07674215;40580.66;4572690
1465;0.02442855;-1.346868;43.96481;4.543039;0;0;0;0.07694033;0.07691075;40348.46;4546535
1470;0.0245357;-1.347791;43.86356;4.532577;0;0;0;0.07727779;0.07724794;40255.54;4536079
1475;0.02458927;-1.348896;44.29845;4.577515;0;0;0;0.07744652;0.07741654;40654.66;4581060
1480;0.02469641;-1.349908;44.22036;4.569447;0;0;0;0.07778398;0.07775375;40583;4573001
1485;0.02480356;-1.350956;44.13791;4.560926;0;0;0;0.07812143;0.07809094;40507.32;4564489
1490;0.02485713;-1.351885;44.09756;4.556757;0;0;0;0.07829016;0.07825953;40470.3;4560325
1495;0.02496427;-1.352963;44.25857;4.573395;0;0;0;0.07862762;0.07859673;40618.06;4576991
1500;0.02501784;-1.353786;44.06256;4.553141;0;0;0;0.07879635;0.07876532;40438.18;4556728
1505;0.02512498;-1.353705;43.97373;4.543962;0;0;0;0.0791338;0.07910251;40356.66;4547557
1510;0.02523213;-1.354826;44.12916;4.560022;0;0;0;0.07947127;0.07943971;40499.3;4563646
1515;0.0252857;-1.35607;44.18798;4.5661;0;0;0;0.07963999;0.0796083;40553.28;4569736
1520;0.02539284;-1.357144;44.14243;4.561394;0;0;0;0.07997745;0.07994548;40511.48;4565042
1525;0.02549998;-1.357909;43.97726;4.544326;0;0;0;0.08031491;0.08028268;40359.89;4547976
1530;0.02555355;-1.358782;44.04729;4.551562;0;0;0;0.08048364;0.08045126;40424.16;4555226
1535;0.0256607;-1.359722;44.04964;4.551805;0;0;0;0.0808211;0.08078845;40426.32;4555484
1540;0.0256607;-1.360496;44.24368;4.571856;0;0;0;0.0808211;0.08078845;40604.4;4575551
1545;0.02576784;-1.361326;43.97585;4.54418;0;0;0;0.08115855;0.08112564;40358.6;4547868
1550;0.02587498;-1.3619;44.10731;4.557765;0;0;0;0.08149601;0.08146282;40479.25;4561479
1555;0.02592855;-1.362728;44.13779;4.560915;0;0;0;0.08166474;0.08163141;40507.22;4564639
1560;0.0260357;-1.363431;43.9108;4.537459;0;0;0;0.0820022;0.08196859;40298.9;4541180
1565;0.02608927;-1.36342;44.0874;4.555707;0;0;0;0.08217093;0.08213719;40460.98;4559451
1570;0.02619641;-1.364394;44.14804;4.561973;0;0;0;0.08250839;0.08247437;40516.63;4565737
1575;0.02630356;-1.365184;44.26097;4.573643;0;0;0;0.08284584;0.08281155;40620.27;4577432
1580;0.02635713;-1.365715;44.2665;4.574214;0;0;0;0.08301457;0.08298013;40625.34;4578011
1585;0.02646427;-1.366476;44.11083;4.558129;0;0;0;0.08335202;0.08331731;40482.48;4561928
1590;0.02651784;-1.367147;44.194;4.566722;0;0;0;0.08352076;0.08348589;40558.8;4570536
1595;0.02662498;-1.367707;43.98219;4.544835;0;0;0;0.08385822;0.08382308;40364.42;4548647
1600;0.02667855;-1.368312;44.22826;4.570263;0;0;0;0.08402694;0.08399166;40590.25;4574103
1605;0.0267857;-1.368819;43.97617;4.544213;0;0;0;0.0843644;0.08432883;40358.89;4548047
1610;0.02689284;-1.36947;44.09104;4.556084;0;0;0;0.08470186;0.08466601;40464.32;4559943
1615;0.02694641;-1.370029;44.24659;4.572156;0;0;0;0.08487058;0.08483459;40607.07;4576037
1620;0.02699998;-1.370622;44.18269;4.565554;0;0;0;0.08503932;0.08500318;40548.43;4569436
1625;0.02710713;-1.371032;44.2499;4.572499;0;0;0;0.08537678;0.08534035;40610.11;4576403
1630;0.02721427;-1.371535;44.20351;4.567705;0;0;0;0.08571424;0.08567752;40567.53;4571620
1635;0.02726784;-1.371298;44.00031;4.546708;0;0;0;0.08588296;0.0858461;40381.05;4550612
1640;0.02737498;-1.371983;44.12931;4.560038;0;0;0;0.08622041;0.08618326;40499.43;4563969
1645;0.02742855;-1.372523;44.14449;4.561606;0;0;0;0.08638915;0.08635186;40513.36;4565547
1650;0.0275357;-1.373092;44.26488;4.574047;0;0;0;0.08672661;0.08668902;40623.86;4578014
1655;0.02758927;-1.373629;43.96921;4.543494;0;0;0;0.08689533;0.0868576;40352.51;4547442
1660;0.02769641;-1.374288;44.38853;4.586824;0;0;0;0.08723279;0.08719476;40737.34;4590826
1665;0.02780355;-1.374705;44.10954;4.557995;0;0;0;0.08757024;0.08753192;40481.29;4561987
1670;0.02785712;-1.375154;43.8733;4.533584;0;0;0;0.08773898;0.08770051;40264.49;4537562
1675;0.02796427;-1.375539;44.10552;4.55758;0;0;0;0.08807644;0.08803767;40477.6;4561594
1680;0.02801784;-1.376003;44.07571;4.5545;0;0;0;0.08824516;0.08820625;40450.25;4558519
1685;0.02812498;-1.376408;44.18334;4.565621;0;0;0;0.08858262;0.08854341;40549.02;4569665
1690;0.02823213;-1.376643;44.06106;4.552986;0;0;0;0.08892008;0.08888057;40436.8;4557034
1695;0.0282857;-1.377074;44.16513;4.563739;0;0;0;0.08908881;0.08904914;40532.31;4567805
1700;0.02839284;-1.377351;44.07442;4.554366;0;0;0;0.08942626;0.08938631;40449.06;4558439
1705;0.02849998;-1.377541;44.08144;4.555091;0;0;0;0.08976372;0.08972345;40455.5;4559180
1710;0.02860713;-1.377845;44.20069;4.567414;0;0;0;0.09010118;0.09006062;40564.95;4571529
1715;0.02860713;-1.378333;44.15844;4.563047;0;0;0;0.09010118;0.09006062;40526.17;4567159
1720;0.02871427;-1.378433;44.19526;4.566853;0;0;0;0.09043863;0.09039776;40559.96;4570983
1725;0.02882141;-1.378879;44.08479;4.555437;0;0;0;0.09077609;0.09073492;40458.57;4559572
1730;0.02892855;-1.37913;44.03484;4.550276;0;0;0;0.09111355;0.09107207;40412.74;4554422
1735;0.02898212;-1.379523;44.16428;4.563651;0;0;0;0.09128228;0.09124064;40531.53;4567817
1740;0.0290357;-1.378723;44.07372;4.554294;0;0;0;0.09145101;0.09140922;40448.42;4558458
1745;0.02914284;-1.378606;43.96187;4.542736;0;0;0;0.09178847;0.09174637;40345.77;4546905
1750;0.02919641;-1.379108;44.17655;4.564919;0;0;0;0.0919572;0.09191494;40542.79;4569117
1755;0.02930355;-1.379246;44.14918;4.562091;0;0;0;0.09229466;0.09225209;40517.68;4566302
1760;0.02935712;-1.379752;44.17702;4.564968;0;0;0;0.09246338;0.09242066;40543.22;4569189
1765;0.02951784;-1.38009;44.21916;4.569322;0;0;0;0.09296957;0.09292638;40581.89;4573570
1770;0.02957141;-1.380143;44.16777;4.564012;0;0;0;0.0931383;0.09309495;40534.73;4568263
1775;0.02967855;-1.380603;44.16337;4.563557;0;0;0;0.09347575;0.09343209;40530.69;4567823
1780;0.02967855;-1.380785;44.1212;4.5592;0;0;0;0.09347575;0.09343209;40491.99;4563462
1785;0.0297857;-1.381048;44.16237;4.563454;0;0;0;0.09381322;0.09376924;40529.77;4567735
1790;0.02989284;-1.381153;44.31322;4.579041;0;0;0;0.09415067;0.09410638;40668.21;4583353
1795;0.02994641;-1.381347;44.31163;4.578877;0;0;0;0.0943194;0.09427495;40666.76;4583196
1800;0.02999998;-1.380661;44.11777;4.558845;0;0;0;0.09448814;0.09444352;40488.84;4563153
1805;0.03010712;-1.380985;44.25275;4.572793;0;0;0;0.09482559;0.09478066;40612.73;4577130
1810;0.03021427;-1.381058;44.22879;4.570318;0;0;0;0.09516305;0.09511779;40590.73;4574667
1815;0.03026784;-1.381388;44.26896;4.574469;0;0;0;0.09533177;0.09528636;40627.6;4578830
1820;0.03037498;-1.3815;44.1402;4.561163;0;0;0;0.09566923;0.0956235;40509.43;4565527
1825;0.03042855;-1.38184;44.18874;4.566179;0;0;0;0.09583796;0.09579207;40553.98;4570555
1830;0.03053569;-1.382003;44.335;4.581293;0;0;0;0.0961754;0.09612919;40688.21;4585699
1835;0.03058926;-1.382162;44.12449;4.55954;0;0;0;0.09634414;0.09629776;40495.01;4563933
1840;0.03069641;-1.382118;44.2445;4.571941;0;0;0;0.0966816;0.09663489;40605.15;4576361
1845;0.03080355;-1.382387;44.14276;4.561427;0;0;0;0.09701905;0.09697202;40511.77;4565853
1850;0.03085712;-1.382359;44.09704;4.556703;0;0;0;0.09718779;0.09714059;40469.82;4561131
1855;0.03096426;-1.382343;44.19534;4.566862;0;0;0;0.09752524;0.09747771;40560.04;4571315
1860;0.03101784;-1.38264;44.15609;4.562805;0;0;0;0.09769397;0.09764629;40524.01;4567262
1865;0.03112498;-1.383125;44.2586;4.573398;0;0;0;0.09803143;0.09798341;40618.09;4577881
1870;0.03123212;-1.381641;44.25114;4.572627;0;0;0;0.09836888;0.09832053;40611.25;4577125
1875;0.03128569;-1.381789;44.07437;4.55436;0;0;0;0.09853762;0.0984891;40449.01;4558848
1880;0.03133926;-1.381701;44.37503;4.585429;0;0;0;0.09870634;0.09865766;40724.94;4589955
1885;0.03144641;-1.381841;44.12499;4.559591;0;0;0;0.09904381;0.09899479;40495.47;4564107
1890;0.03149998;-1.381635;44.39318;4.587304;0;0;0;0.09921253;0.09916335;40741.6;4591855
1895;0.03160712;-1.381653;44.39174;4.587155;0;0;0;0.09954999;0.09950047;40740.28;4591722
1900;0.03171427;-1.381813;44.28673;4.576304;0;0;0;0.09988745;0.0998376;40643.91;4580876
1905;0.03176784;-1.382028;44.31034;4.578744;0;0;0;0.1000562;0.1000062;40665.57;4583325
1910;0.03187498;-1.38257;44.37165;4.58508;0;0;0;0.1003936;0.1003433;40721.84;4589683
1915;0.03198212;-1.382778;44.03322;4.550109;0;0;0;0.1007311;0.1006804;40411.25;4554692
1920;0.03208927;-1.382596;44.15012;4.562189;0;0;0;0.1010685;0.1010175;40518.54;4566800
1925;0.03208927;-1.382536;44.28382;4.576004;0;0;0;0.1010685;0.1010175;40641.24;4580629
1930;0.03224998;-1.382548;44.41349;4.589404;0;0;0;0.1015747;0.1015232;40760.24;4594065
1935;0.03230355;-1.382232;44.24339;4.571826;0;0;0;0.1017435;0.1016917;40604.13;4576477
1940;0.03241069;-1.382476;44.10849;4.557886;0;0;0;0.1020809;0.1020289;40480.32;4562539
1945;0.03246427;-1.382075;44.3294;4.580713;0;0;0;0.1022497;0.1021974;40683.06;4585397
1950;0.03251783;-1.382475;44.1461;4.561773;0;0;0;0.1024184;0.102366;40514.84;4566445
1955;0.03262498;-1.382897;44.26177;4.573725;0;0;0;0.1027558;0.1027031;40621;4578425
1960;0.03273212;-1.383054;43.09632;4.453296;0;0;0;0.1030933;0.1030402;39551.42;4457887
1965;0.03278569;-1.383328;44.17529;4.564789;0;0;0;0.103262;0.1032087;40541.63;4569503
1970;0.03289284;-1.383458;44.08291;4.555243;0;0;0;0.1035995;0.1035459;40456.85;4559962
1975;0.03299998;-1.383588;44.23396;4.570852;0;0;0;0.1039369;0.103883;40595.48;4575603
1980;0.03305355;-1.383266;44.51838;4.600242;0;0;0;0.1041057;0.1040515;40856.5;4605031
1985;0.03316069;-1.383406;44.26573;4.574135;0;0;0;0.1044431;0.1043886;40624.64;4578912
1990;0.03321426;-1.383648;44.37291;4.58521;0;0;0;0.1046119;0.1045572;40723;4590007
1995;0.03326784;-1.383124;44.23;4.570442;0;0;0;0.1047806;0.1047257;40591.84;4575231
2000;0.03337498;-1.383105;44.22821;4.570257;0;0;0;0.105118;0.1050628;40590.2;4575061
2005;0.03342855;-1.383521;44.19916;4.567256;0;0;0;0.1052868;0.1052314;40563.54;4572065
2010;0.03353569;-1.383094;44.35303;4.583156;0;0;0;0.1056242;0.1055685;40704.76;4587997
2015;0.03358926;-1.383053;44.31683;4.579414;0;0;0;0.105793;0.105737;40671.53;4584259
2020;0.03369641;-1.382804;44.29724;4.577391;0;0;0;0.1061304;0.1060741;40653.55;4582249
2025;0.03380355;-1.382273;44.25907;4.573446;0;0;0;0.1064679;0.1064112;40618.52;4578315
2030;0.03385712;-1.382461;44.25263;4.572782;0;0;0;0.1066366;0.1065798;40612.62;4577658
2035;0.03396427;-1.382094;44.45772;4.593973;0;0;0;0.1069741;0.1069169;40800.83;4598888
2040;0.03407141;-1.381122;44.3518;4.583028;0;0;0;0.1073115;0.107254;40703.63;4587947
2045;0.03412498;-1.380919;44.20057;4.567402;0;0;0;0.1074802;0.1074225;40564.84;4572311
2050;0.03423212;-1.380738;44.19085;4.566397;0;0;0;0.1078177;0.1077596;40555.92;4571321
2055;0.03428569;-1.379888;44.25669;4.5732;0;0;0;0.1079864;0.1079282;40616.34;4578139
2060;0.03439283;-1.379187;44.32379;4.580134;0;0;0;0.1083239;0.1082653;40677.91;4585095
2065;0.03444641;-1.378612;44.43831;4.591968;0;0;0;0.1084926;0.1084338;40783.02;4596950
2070;0.03455355;-1.377371;44.00624;4.54732;0;0;0;0.1088301;0.1087709;40386.49;4552269
2075;0.03460712;-1.376922;44.0766;4.554591;0;0;0;0.1089988;0.1089394;40451.06;4559555
2080;0.03471426;-1.376158;44.13162;4.560277;0;0;0;0.1093363;0.1092765;40501.56;4565263
2085;0.03482141;-1.375357;44.27119;4.574699;0;0;0;0.1096737;0.1096136;40629.65;4579716
2090;0.03487498;-1.375021;44.34995;4.582837;0;0;0;0.1098425;0.1097822;40701.93;4587871
2095;0.03492855;-1.374515;44.25572;4.5731;0;0;0;0.1100112;0.1099507;40615.45;4578131
2100;0.03503569;-1.374082;44.21672;4.56907;0;0;0;0.1103486;0.1102878;40579.66;4574112
2105;0.03508926;-1.37503;44.08176;4.555125;0;0;0;0.1105174;0.1104563;40455.8;4560159
2110;0.03519641;-1.377467;44.45816;4.594019;0;0;0;0.1108548;0.1107934;40801.23;4599112
2115;0.03530355;-1.382648;44.32311;4.580064;0;0;0;0.1111923;0.1111305;40677.29;4585156
2120;0.03535712;-1.385846;44.38169;4.586117;0;0;0;0.111361;0.111299;40731.06;4591224
2125;0.03546426;-1.384644;44.27754;4.575355;0;0;0;0.1116985;0.1116361;40635.47;4580465
2130;0.0355714;-1.379655;44.29683;4.577348;0;0;0;0.1120359;0.1119732;40653.18;4582476
2135;0.03562498;-1.368098;44.29803;4.577473;0;0;0;0.1122047;0.1121418;40654.28;4582609
2140;0.03573212;-1.351912;44.16704;4.563936;0;0;0;0.1125421;0.1124788;40534.06;4569073
2145;0.03578569;-1.335938;44.31427;4.579151;0;0;0;0.1127108;0.1126474;40669.18;4584312
2150;0.03589283;-1.316297;44.18586;4.565882;0;0;0;0.1130483;0.1129844;40551.34;4571043
2155;0.03594641;-1.295432;44.73515;4.622642;0;0;0;0.113217;0.113153;41055.45;4627875
2160;0.03605355;-1.278211;43.38366;4.482986;0;0;0;0.1135545;0.1134901;39815.11;4488077
2165;0.03610712;-1.261855;44.15714;4.562914;0;0;0;0.1137232;0.1136586;40524.98;4568103
2170;0.03621426;-1.246538;44.18134;4.565414;0;0;0;0.1140607;0.1139957;40547.19;4570622
2175;0.03632141;-1.229721;44.04897;4.551735;0;0;0;0.1143981;0.1143327;40425.7;4556943
2180;0.03637497;-1.209115;44.09636;4.556633;0;0;0;0.1145668;0.1145013;40469.2;4561853
2185;0.03648212;-1.191216;44.24468;4.571959;0;0;0;0.1149043;0.1148384;40605.32;4577213
2190;0.03653569;-1.172176;44.2208;4.569492;0;0;0;0.115073;0.1150069;40583.41;4574751
2195;0.03664283;-1.151959;44.2687;4.574441;0;0;0;0.1154105;0.1153439;40627.36;4579721
2200;0.03669641;-1.128999;44.29254;4.576905;0;0;0;0.1155792;0.1155125;40649.24;4582195
2205;0.03680355;-1.107419;44.31739;4.579472;0;0;0;0.1159167;0.1158496;40672.04;4584781
2210;0.03685712;-1.08313;44.1328;4.560398;0;0;0;0.1160854;0.1160181;40502.64;4565692
2215;0.03696426;-1.062678;44.24297;4.571783;0;0;0;0.1164229;0.1163552;40603.75;4577106
2220;0.03701783;-1.040374;44.28452;4.576077;0;0;0;0.1165916;0.1165237;40641.88;4581412
2225;0.03712498;-1.019699;44.13894;4.561033;0;0;0;0.1169291;0.1168608;40508.27;4566366
2230;0.03717855;-0.9971078;44.18577;4.565872;0;0;0;0.1170978;0.1170293;40551.25;4571219
2235;0.03728569;-0.9722078;43.79849;4.525853;0;0;0;0.1174352;0.1173663;40195.82;4531168
2240;0.03739284;-0.9443756;44.26535;4.574095;0;0;0;0.1177727;0.1177034;40624.29;4579482
2245;0.0374464;-0.90909;44.29533;4.577193;0;0;0;0.1179414;0.1178719;40651.8;4582592
2250;0.03749998;-0.8780055;44.31413;4.579135;0;0;0;0.1181102;0.1180405;40669.05;4584544
2255;0.03760712;-0.8401922;44.39376;4.587365;0;0;0;0.1184476;0.1183775;40742.14;4592798
2260;0.03771426;-0.8074716;44.28097;4.57571;0;0;0;0.1187851;0.1187146;40638.63;4581145
2265;0.03776783;-0.7727596;44.32053;4.579797;0;0;0;0.1189538;0.1188831;40674.93;4585245
2270;0.03787498;-0.7411644;44.44756;4.592923;0;0;0;0.1192913;0.1192202;40791.5;4598402
2275;0.03792855;-0.7091079;44.15835;4.563038;0;0;0;0.11946;0.1193887;40526.08;4568489
2280;0.03803569;-0.6784395;44.36619;4.584516;0;0;0;0.1197975;0.1197258;40716.83;4590007
2285;0.03814283;-0.6491963;44.35744;4.583611;0;0;0;0.1201349;0.1200628;40708.8;4589117
2290;0.0381964;-0.617893;44.39699;4.587698;0;0;0;0.1203036;0.1202313;40745.1;4593218
2295;0.03830355;-0.5836718;44.42594;4.59069;0;0;0;0.1206411;0.1205684;40771.67;4596228
2300;0.03835712;-0.5470607;44.22689;4.570121;0;0;0;0.1208098;0.1207369;40588.98;4575642
2305;0.03846426;-0.5071383;44.59203;4.607852;0;0;0;0.1211473;0.121074;40924.09;4613434
2310;0.0385714;-0.4689354;44.57174;4.605756;0;0;0;0.1214847;0.121411;40905.47;4611351
2315;0.03867855;-0.4480924;49.33914;5.098388;0;0;0;0.1218222;0.121748;45280.73;5104599
2320;0.03873211;-0.43535;54.41203;5.622588;0;0;0;0.1219909;0.1219166;49936.34;5629447
2325;0.03878569;-0.4123947;55.56447;5.741673;0;0;0;0.1221596;0.1220851;50993.99;5748687
2330;0.03889283;-0.3867758;55.99651;5.786317;0;0;0;0.1224971;0.1224221;51390.49;5793405
2335;0.03899997;-0.3596377;55.88222;5.774508;0;0;0;0.1228346;0.1227592;51285.61;5781601
2340;0.03910712;-0.3355955;55.77043;5.762956;0;0;0;0.123172;0.1230962;51183.01;5770054
2345;0.03910712;-0.3160205;55.88207;5.774492;0;0;0;0.123172;0.1230962;51285.47;5781605
2350;0.03921426;-0.2922828;55.7509;5.760938;0;0;0;0.1235095;0.1234333;51165.09;5768053
2355;0.0393214;-0.2688708;55.86584;5.772815;0;0;0;0.1238469;0.1237703;51270.57;5779964
2360;0.03937498;-0.2437912;55.80934;5.766976;0;0;0;0.1240157;0.1239388;51218.72;5774128
2365;0.03942855;-0.2207088;55.91769;5.778173;0;0;0;0.1241844;0.1241074;51318.16;5785349
2370;0.03953568;-0.1945561;55.77627;5.76356;0;0;0;0.1245218;0.1244444;51188.38;5770737
2375;0.03964283;-0.1742719;56.05852;5.792726;0;0;0;0.1248593;0.1247814;51447.41;5799959
2380;0.0396964;-0.1533444;56.04478;5.791306;0;0;0;0.125028;0.1249499;51434.8;5798546
2385;0.03980354;-0.1362251;56.08944;5.795921;0;0;0;0.1253655;0.125287;51475.79;5803187
2390;0.03985712;-0.1199432;55.86469;5.772696;0;0;0;0.1255342;0.1254555;51269.52;5779943
2395;0.03996426;-0.1058088;55.88633;5.774932;0;0;0;0.1258717;0.1257925;51289.38;5782202
2400;0.04001783;-0.0924005;55.90503;5.776865;0;0;0;0.1260404;0.125961;51306.54;5784146
2405;0.04012497;-0.08137138;55.88263;5.77455;0;0;0;0.1263779;0.1262981;51285.98;5781848
2410;0.04023212;-0.07088663;55.97284;5.783871;0;0;0;0.1267153;0.1266351;51368.77;5791200
2415;0.04028569;-0.05935949;56.11452;5.798512;0;0;0;0.1268841;0.1268036;51498.8;5805870
2420;0.04033926;-0.04772585;55.87291;5.773546;0;0;0;0.1270528;0.1269721;51277.06;5780881
2425;0.0404464;-0.03809558;55.89799;5.776137;0;0;0;0.1273903;0.1273092;51300.08;5783495
2430;0.04049997;-0.0291738;56.11811;5.798882;0;0;0;0.127559;0.1274777;51502.09;5806280
2435;0.04060711;-0.02318503;56.28481;5.816109;0;0;0;0.1278964;0.1278147;51655.08;5823547
2440;0.04071426;-0.01844788;55.77281;5.763202;0;0;0;0.1282339;0.1281517;51185.19;5770592
2445;0.04076783;-0.01647522;56.01709;5.788444;0;0;0;0.1284026;0.1283203;51409.38;5795877
2450;0.04087497;-0.01647209;55.8545;5.771643;0;0;0;0.1287401;0.1286573;51260.16;5779073
2455;0.04092854;-0.0148045;55.84692;5.77086;0;0;0;0.1289088;0.1288258;51253.21;5778299
2460;0.04103569;-0.01363494;55.63036;5.748482;0;0;0;0.1292463;0.1291628;51054.46;5755912
2465;0.04114283;-0.01180447;55.89047;5.77536;0;0;0;0.1295837;0.1294998;51293.18;5782844
2470;0.04124997;-0.01074579;55.8654;5.772769;0;0;0;0.1299212;0.1298369;51270.16;5780269
2475;0.04130354;-0.009581235;55.74638;5.760471;0;0;0;0.1300899;0.1300054;51160.94;5767964
2480;0.04135712;-0.008469303;56.00734;5.787437;0;0;0;0.1302586;0.1301739;51400.44;5794976
2485;0.04146426;-0.006184673;55.81459;5.767519;0;0;0;0.1305961;0.1305109;51223.54;5775052
2490;0.04151783;-0.003944519;55.60752;5.746121;0;0;0;0.1307648;0.1306794;51033.5;5753635
2495;0.04162498;-0.002583263;56.01028;5.787741;0;0;0;0.1311023;0.1310164;51403.13;5795328
2500;0.04167855;-0.001399915;55.85676;5.771877;0;0;0;0.131271;0.1311849;51262.24;5779454
2505;0.04178568;-0.0003875885;55.84278;5.770432;0;0;0;0.1316085;0.1315219;51249.41;5778027
2510;0.04189283;0.0006391504;55.76899;5.762807;0;0;0;0.1319459;0.131859;51181.69;5770411
2515;0.0419464;0.001636443;55.93493;5.779954;0;0;0;0.1321146;0.1320275;51333.98;5787590
2520;0.04205354;0.002812273;55.74441;5.760268;0;0;0;0.1324521;0.1323645;51159.13;5767897
2525;0.04216069;0.003155563;55.8027;5.766291;0;0;0;0.1327896;0.1327015;51212.63;5773948
2530;0.04221426;0.003793905;55.98632;5.785264;0;0;0;0.1329583;0.13287;51381.14;5792956
2535;0.0423214;0.003837757;55.93378;5.779836;0;0;0;0.1332957;0.133207;51332.93;5787540
2540;0.04237497;0.004243064;55.98623;5.785255;0;0;0;0.1334645;0.1333755;51381.06;5792976
2545;0.04248212;0.004348932;55.97571;5.784169;0;0;0;0.1338019;0.1337125;51371.41;5791908
2550;0.04258926;0.004630205;55.91431;5.777824;0;0;0;0.1341394;0.1340495;51315.06;5785574
2555;0.04264283;0.005223444;55.92759;5.779196;0;0;0;0.1343081;0.134218;51327.24;5786958
2560;0.04274997;0.005764689;55.97569;5.784166;0;0;0;0.1346456;0.134555;51371.38;5791954
2565;0.04285711;0.005777844;56.00232;5.786918;0;0;0;0.134983;0.134892;51395.83;5794729
2570;0.04285711;0.005715201;55.94794;5.781298;0;0;0;0.134983;0.134892;51345.91;5789102
2575;0.04296426;0.005195881;55.89197;5.775515;0;0;0;0.1353205;0.135229;51294.55;5783330
2580;0.0430714;0.004548768;55.78646;5.764613;0;0;0;0.135658;0.135566;51197.72;5772433
2585;0.0430714;0.003807687;55.84919;5.771094;0;0;0;0.135658;0.135566;51255.29;5778923
2590;0.04323211;0.00324765;56.00297;5.786985;0;0;0;0.1361641;0.1360715;51396.42;5794865
2595;0.04333926;0.002492161;55.78978;5.764956;0;0;0;0.1365016;0.1364085;51200.77;5772825
2600;0.04339283;0.002123814;56.00605;5.787303;0;0;0;0.1366703;0.136577;51399.25;5795213
2605;0.0434464;0.002141355;55.78347;5.764303;0;0;0;0.1368391;0.1367455;51194.98;5772191
2610;0.04349997;0.001801823;56.04464;5.791291;0;0;0;0.1370078;0.136914;51434.66;5799225
2615;0.04360712;0.001624541;55.68698;5.754333;0;0;0;0.1373452;0.137251;51106.42;5762236
2620;0.04371426;0.001510528;55.91649;5.778049;0;0;0;0.1376827;0.137588;51317.05;5786004
2625;0.0438214;0.000455603;55.98925;5.785568;0;0;0;0.1380202;0.137925;51383.83;5793553
2630;0.04387497;0.0004224014;55.93916;5.780391;0;0;0;0.1381889;0.1380935;51337.86;5788379
2635;0.04392854;-0.000513501;55.93737;5.780206;0;0;0;0.1383576;0.138262;51336.21;5788204
2640;0.04403568;-0.001644855;55.82199;5.768284;0;0;0;0.1386951;0.138599;51230.33;5776285
2645;0.04408926;-0.002411618;55.92979;5.779423;0;0;0;0.1388638;0.1387675;51329.26;5787449
2650;0.0441964;-0.0027618;55.92897;5.779338;0;0;0;0.1392013;0.1391045;51328.51;5787383
2655;0.04430354;-0.003677655;55.84269;5.770423;0;0;0;0.1395387;0.1394415;51249.33;5778475
2660;0.04435712;-0.004319132;55.76955;5.762865;0;0;0;0.1397074;0.13961;51182.2;5770916
2665;0.04446425;-0.004897963;55.78235;5.764188;0;0;0;0.1400449;0.1399469;51193.95;5772260
2670;0.04451783;-0.005690411;55.70498;5.756192;0;0;0;0.1402136;0.1401154;51122.94;5764263
2675;0.04462497;-0.007285329;55.63374;5.748831;0;0;0;0.1405511;0.1404524;51057.56;5756911
2680;0.04467855;-0.008995512;55.90615;5.77698;0;0;0;0.1407198;0.1406209;51307.57;5785110
2685;0.04478569;-0.01073263;55.66569;5.752132;0;0;0;0.1410573;0.1409579;51086.88;5760246
2690;0.04489283;-0.01149;55.74999;5.760844;0;0;0;0.1413947;0.1412949;51164.25;5768989
2695;0.0449464;-0.01355788;55.94911;5.78142;0;0;0;0.1415634;0.1414633;51347;5789604
2700;0.04499997;-0.01483958;55.76943;5.762853;0;0;0;0.1417322;0.1416318;51182.09;5771021
2705;0.04510711;-0.01628039;55.76153;5.762037;0;0;0;0.1420697;0.1419688;51174.84;5770223
2710;0.04521426;-0.01736852;55.48322;5.733277;0;0;0;0.1424071;0.1423058;50919.42;5741442
2715;0.04526783;-0.0185763;55.74077;5.759891;0;0;0;0.1425758;0.1424743;51155.79;5768103
2720;0.04537497;-0.01971768;55.51648;5.736715;0;0;0;0.1429133;0.1428113;50949.95;5744913
2725;0.04542854;-0.02138464;55.66307;5.751863;0;0;0;0.143082;0.1429798;51084.48;5760092
2730;0.04558926;-0.0229;55.88163;5.774447;0;0;0;0.1435882;0.1434852;51285.07;5782738
2735;0.04564283;-0.02449178;55.68927;5.754569;0;0;0;0.1437569;0.1436537;51108.52;5762842
2740;0.04574997;-0.02685096;55.57084;5.742332;0;0;0;0.1440944;0.1439907;50999.84;5750606
2745;0.04580354;-0.02853107;55.52488;5.737583;0;0;0;0.1442631;0.1441592;50957.66;5745860
2750;0.04591068;-0.03005709;55.73308;5.759096;0;0;0;0.1446006;0.1444961;51148.73;5767424
2755;0.04601783;-0.0323555;55.57882;5.743157;0;0;0;0.144938;0.1448331;51007.16;5751481
2760;0.0460714;-0.03436825;55.37063;5.721643;0;0;0;0.1451068;0.1450016;50816.1;5729946
2765;0.04612497;-0.03595189;55.58514;5.743809;0;0;0;0.1452755;0.1451701;51012.96;5752154
2770;0.04623211;-0.03705568;55.56497;5.741724;0;0;0;0.145613;0.145507;50994.45;5750085
2775;0.04628568;-0.03891747;55.56194;5.741412;0;0;0;0.1457817;0.1456755;50991.67;5749782
2780;0.04639283;-0.04071598;55.51875;5.736948;0;0;0;0.1461191;0.1460125;50952.03;5745332
2785;0.0464464;-0.04281393;55.67238;5.752824;0;0;0;0.1462879;0.146181;51093.03;5761240
2790;0.04649997;-0.04421215;55.47608;5.73254;0;0;0;0.1464566;0.1463495;50912.87;5740935
2795;0.04660711;-0.04617541;55.53331;5.738453;0;0;0;0.1467941;0.1466864;50965.39;5746877
2796.6;0.04666068;-0.04712259;55.63174;5.748625;0;0;0;0.1469628;0.1468549;51055.73;5757073