File: Ensayos/Resistencia/comp/Clavo7/Clavo7d.raw
"Test Type";"Manual"
"Method Name:";"C:\INSTRON\USER\TEMPLATE\CYCLE.MTM"
"Name:";""
"Operator ID:";""
"Company:";""
"Lab name:";""
"Test date:";"13/06/2017"
"Temperature:";""
"Humidity:";""
"Note 1:";""
"Note 2:";""
"Note 3:";""
"Geometry:";"Rectangular"
"Specimen";1
"Specimen name:";""
"Width:";0.250000;"in"
"Thickness:";0.060000;"in"
"Length:";1.250000;"in"
"Diameter:";0.039370;"in"
"Inner diameter:";0.019685;"in"
"Outer diameter:";0.039370;"in"
"Wall thickness:";0.019685;"in"
"Area:";0.015000;"in*in"
"Linear density:";1.000000;"den"
"Sled weight:";2.204623;"lbf"
"Loading span:";0.000000;"mm"
"Support span:";1.000000;"mm"
"Span ratio:";"2"
"Fixture type:";"3-point"
"Comment:";""
"Included"
"Final Width:";0.250000;"in"
"Final Thickness:";0.060000;"in"
"Final Length:";1.250000;"in"
"Final Diameter:";0.039370;"in"
"Final Inner diameter:";0.019685;"in"
"Final Outer diameter:";0.039370;"in"
"Final Wall thickness:";0.019685;"in"
"Final Area:";0.015000;"in*in"
"Final Linear density:";1.000000;"den"
"Time sec";"Extension mm";"Strain 1 %";"Load N";"Stress MPa";"Cycle Count ";"Total Cycle Count ";"Repetitions Count ";"Strain [Exten.] %";"True strain %";"Corrected Position mm";"Tenacity gf/tex";"True stress Pa"
0;-0.328607;-0.01299954;53.54722;5.533224;0;0;0;-1.034983;-1.040376;-0.328607;49142.68;5475956
7;-0.3284998;-0.01283724;53.45895;5.524103;0;0;0;-1.034645;-1.040035;-0.3284998;49061.67;5466948
14;-0.3284463;-0.0129722;53.466;5.524831;0;0;0;-1.034476;-1.039864;-0.3284463;49068.13;5467678
21;-0.3282856;-0.01272867;53.68479;5.54744;0;0;0;-1.03397;-1.039353;-0.3282856;49268.93;5490081
28;-0.3281784;-0.01274623;53.6473;5.543565;0;0;0;-1.033633;-1.039012;-0.3281784;49234.52;5486265
35;-0.3280713;-0.01271381;53.89258;5.568911;0;0;0;-1.033295;-1.038671;-0.3280713;49459.62;5511368
42;-0.3279642;-0.01264079;53.72831;5.551937;0;0;0;-1.032958;-1.03833;-0.3279642;49308.87;5494588
49;-0.327857;-0.01249549;53.777;5.556968;0;0;0;-1.03262;-1.037989;-0.327857;49353.55;5499585
56;-0.3276963;-0.01251662;53.82615;5.562047;0;0;0;-1.032114;-1.037477;-0.3276963;49398.66;5504640
63;-0.3275356;-0.01264224;54.17718;5.59832;0;0;0;-1.031608;-1.036966;-0.3275356;49720.81;5540567
70;-0.327482;-0.01276596;53.89963;5.569639;0;0;0;-1.031439;-1.036796;-0.327482;49466.09;5512192
77;-0.3273212;-0.01257431;54.10427;5.590786;0;0;0;-1.030933;-1.036284;-0.3273212;49653.9;5533148
84.00001;-0.3272677;-0.01257762;54.09757;5.590094;0;0;0;-1.030764;-1.036114;-0.3272677;49647.75;5532473
91.00001;-0.327107;-0.01254583;54.29147;5.610129;0;0;0;-1.030258;-1.035602;-0.327107;49825.7;5552331
98.00001;-0.3269998;-0.01223807;54.3445;5.61561;0;0;0;-1.029921;-1.035261;-0.3269998;49874.37;5557773
105;-0.3268927;-0.01227955;54.43641;5.625107;0;0;0;-1.029583;-1.03492;-0.3268927;49958.72;5567191
112;-0.3267856;-0.01209029;54.12488;5.592916;0;0;0;-1.029246;-1.034579;-0.3267856;49672.82;5535350
119;-0.3266784;-0.01198015;54.2125;5.60197;0;0;0;-1.028908;-1.034238;-0.3266784;49753.23;5544331
126;-0.3265713;-0.01178732;54.49431;5.631091;0;0;0;-1.028571;-1.033897;-0.3265713;50011.86;5573171
133;-0.3264641;-0.01157091;54.30909;5.61195;0;0;0;-1.028234;-1.033556;-0.3264641;49841.87;5554246
140;-0.3262498;-0.01118365;54.34761;5.615931;0;0;0;-1.027559;-1.032874;-0.3262498;49877.23;5558224
147;-0.3261427;-0.01106177;54.10826;5.591198;0;0;0;-1.027221;-1.032533;-0.3261427;49657.57;5533764
154;-0.3260356;-0.01077247;54.18091;5.598705;0;0;0;-1.026884;-1.032193;-0.3260356;49724.23;5541213
161;-0.3259284;-0.01057586;54.38235;5.61952;0;0;0;-1.026546;-1.031852;-0.3259284;49909.11;5561833
168;-0.3258213;-0.01027736;54.27957;5.608901;0;0;0;-1.026209;-1.031511;-0.3258213;49814.79;5551341
175;-0.3257141;-0.009932;54.27261;5.608181;0;0;0;-1.025871;-1.03117;-0.3257141;49808.4;5550649
182;-0.325607;-0.009488655;54.42833;5.624272;0;0;0;-1.025534;-1.030829;-0.325607;49951.31;5566593
189;-0.3254999;-0.009127258;54.44266;5.625753;0;0;0;-1.025196;-1.030488;-0.3254999;49964.46;5568078
196;-0.3253927;-0.008716235;53.9573;5.575599;0;0;0;-1.024859;-1.030147;-0.3253927;49519.02;5518456
203;-0.3252856;-0.008280838;54.05476;5.58567;0;0;0;-1.024521;-1.029806;-0.3252856;49608.46;5528443
210;-0.3251249;-0.008158584;54.19283;5.599937;0;0;0;-1.024015;-1.029294;-0.3251249;49735.18;5542593
217;-0.3250177;-0.007651833;54.27326;5.608248;0;0;0;-1.023678;-1.028953;-0.3250177;49808.99;5550838
224;-0.3249106;-0.007233605;54.22081;5.602829;0;0;0;-1.02334;-1.028613;-0.3249106;49760.86;5545493
231;-0.3248034;-0.006678676;54.31419;5.612478;0;0;0;-1.023003;-1.028272;-0.3248034;49846.56;5555062
238;-0.3246963;-0.006063159;54.42966;5.624409;0;0;0;-1.022665;-1.027931;-0.3246963;49952.52;5566890
245;-0.3245356;-0.005897935;54.57028;5.63894;0;0;0;-1.022159;-1.027419;-0.3245356;50081.58;5581301
252;-0.3244284;-0.005325329;54.41577;5.622974;0;0;0;-1.021822;-1.027078;-0.3244284;49939.77;5565517
259;-0.3243213;-0.004786178;54.39421;5.620746;0;0;0;-1.021484;-1.026737;-0.3243213;49919.99;5563331
266;-0.3242141;-0.004330188;54.49464;5.631124;0;0;0;-1.021147;-1.026396;-0.3242141;50012.16;5573622
273;-0.324107;-0.00379785;54.32054;5.613133;0;0;0;-1.02081;-1.026056;-0.324107;49852.38;5555834
280;-0.3239463;-0.003071179;54.23086;5.603867;0;0;0;-1.020303;-1.025544;-0.3239463;49770.08;5546690
287;-0.3238391;-0.002700287;54.18848;5.599488;0;0;0;-1.019966;-1.025203;-0.3238391;49731.19;5542375
294;-0.323732;-0.002126055;54.16673;5.597239;0;0;0;-1.019628;-1.024862;-0.323732;49711.22;5540168
301;-0.3235713;-0.001546715;54.55163;5.637013;0;0;0;-1.019122;-1.024351;-0.3235713;50064.46;5579565
306.212;-0.3235713;-0.001029803;54.31728;5.612796;0;0;0;-1.019122;-1.024351;-0.3235713;49849.39;5555595
313.212;-0.3247499;-0.0005110514;54.03244;5.583364;0;0;0;-1.022834;-1.028101;-0.3247499;49587.98;5526255
320.212;-0.3259284;0.000196964;53.86089;5.565637;0;0;0;-1.026546;-1.031852;-0.3259284;49430.54;5508503
327.212;-0.327107;0.0009493196;53.24489;5.501983;0;0;0;-1.030258;-1.035602;-0.327107;48865.21;5445298
334.212;-0.3282856;0.001594965;53.51383;5.529774;0;0;0;-1.03397;-1.039353;-0.3282856;49112.03;5472598
341.212;-0.3294641;0.002741508;53.59923;5.538598;0;0;0;-1.037682;-1.043104;-0.3294641;49190.4;5481125
348.212;-0.3306427;0.003197029;53.48843;5.527149;0;0;0;-1.041394;-1.046855;-0.3306427;49088.72;5469590
355.212;-0.3318213;0.004158166;53.65123;5.543972;0;0;0;-1.045106;-1.050606;-0.3318213;49238.13;5486031
362.212;-0.3329998;0.005247664;53.35483;5.513343;0;0;0;-1.048818;-1.054357;-0.3329998;48966.1;5455518
369.212;-0.3341784;0.006037606;52.83634;5.459766;0;0;0;-1.05253;-1.058109;-0.3341784;48490.27;5402300
376.212;-0.3352499;0.006977952;54.08336;5.588625;0;0;0;-1.055905;-1.061519;-0.3352499;49634.71;5529615
383.212;-0.3364284;0.008156073;53.23855;5.501328;0;0;0;-1.059617;-1.065271;-0.3364284;48859.39;5443034
390.212;-0.337607;0.009156949;52.9715;5.473733;0;0;0;-1.063329;-1.069023;-0.337607;48614.31;5415529
397.212;-0.3387855;0.01028942;53.17212;5.494463;0;0;0;-1.067041;-1.072775;-0.3387855;48798.43;5435835
404.212;-0.3399641;0.01125678;52.84882;5.461055;0;0;0;-1.070753;-1.076527;-0.3399641;48501.72;5402581
411.212;-0.3411427;0.01252113;52.41487;5.416214;0;0;0;-1.074465;-1.080279;-0.3411427;48103.46;5358019
418.212;-0.3423213;0.01350709;52.0605;5.379596;0;0;0;-1.078177;-1.084032;-0.3423213;47778.24;5321594
425.212;-0.3434999;0.01482413;52.2603;5.400241;0;0;0;-1.081889;-1.087784;-0.3434999;47961.61;5341817
432.212;-0.3446784;0.01638021;51.99032;5.372344;0;0;0;-1.085601;-1.091537;-0.3446784;47713.84;5314021
439.212;-0.3457498;0.01795316;52.10742;5.384445;0;0;0;-1.088976;-1.094949;-0.3457498;47821.31;5325809
446.212;-0.3469284;0.01915483;48.09586;4.969915;0;0;0;-1.092688;-1.098702;-0.3469284;44139.71;4915610
453.212;-0.348107;0.02029166;52.89348;5.465671;0;0;0;-1.0964;-1.102455;-0.348107;48542.71;5405745
460.212;-0.3492855;0.02124726;52.10096;5.383777;0;0;0;-1.100112;-1.106208;-0.3492855;47815.38;5324549
467.212;-0.3505177;0.02221392;51.93594;5.366724;0;0;0;-1.103993;-1.110132;-0.3505177;47663.93;5307476
474.212;-0.3515891;0.02354837;51.9525;5.368436;0;0;0;-1.107367;-1.113544;-0.3515891;47679.13;5308987
481.212;-0.3528213;0.02458325;51.52284;5.324038;0;0;0;-1.111248;-1.117469;-0.3528213;47284.81;5264874
488.212;-0.3539999;0.02603644;51.54105;5.325919;0;0;0;-1.11496;-1.121222;-0.3539999;47301.52;5266537
495.212;-0.3551248;0.02779852;49.31055;5.095434;0;0;0;-1.118503;-1.124806;-0.3551248;45254.49;5038441
502.212;-0.3562498;0.02917254;52.39561;5.414224;0;0;0;-1.122047;-1.128389;-0.3562498;48085.79;5353474
509.212;-0.3574284;0.03074935;52.11159;5.384876;0;0;0;-1.125759;-1.132143;-0.3574284;47825.13;5324255
516.212;-0.358607;0.03262895;51.67483;5.339743;0;0;0;-1.129471;-1.135898;-0.358607;47424.29;5279432
523.212;-0.3597856;0.03429769;51.3214;5.303222;0;0;0;-1.133183;-1.139652;-0.3597856;47099.93;5243127
530.2121;-0.3609641;0.03571583;51.36175;5.307391;0;0;0;-1.136895;-1.143407;-0.3609641;47136.96;5247052
537.2121;-0.3620891;0.03764087;50.77766;5.247035;0;0;0;-1.140438;-1.146991;-0.3620891;46600.92;5187196
544.2121;-0.3633212;0.03935688;49.92479;5.158906;0;0;0;-1.144319;-1.150917;-0.3633212;45818.21;5099871
551.2121;-0.3639641;0.04083939;50.69876;5.238882;0;0;0;-1.146344;-1.152965;-0.3639641;46528.51;5178826
558.2121;-0.3644462;0.04223215;51.25321;5.296176;0;0;0;-1.147862;-1.154501;-0.3644462;47037.36;5235383
565.2121;-0.3650891;0.04343689;52.40101;5.414782;0;0;0;-1.149887;-1.156549;-0.3650891;48090.75;5352518
572.2121;-0.3655712;0.04487336;52.57984;5.433261;0;0;0;-1.151405;-1.158085;-0.3655712;48254.86;5370702
579.2121;-0.3662141;0.04589581;52.88397;5.464688;0;0;0;-1.15343;-1.160134;-0.3662141;48533.98;5401656
586.2121;-0.3667498;0.04785853;53.34587;5.512418;0;0;0;-1.155118;-1.161841;-0.3667498;48957.89;5448743
593.2121;-0.3673927;0.04957889;53.51387;5.529777;0;0;0;-1.157142;-1.163889;-0.3673927;49112.06;5465790
600.2121;-0.3679284;0.05139093;53.74323;5.553478;0;0;0;-1.15883;-1.165596;-0.3679284;49322.56;5489123
607.2121;-0.3687855;0.05253458;53.38704;5.516672;0;0;0;-1.161529;-1.168328;-0.3687855;48995.67;5452594
614.2121;-0.3699641;0.05422129;53.23179;5.500629;0;0;0;-1.165241;-1.172083;-0.3699641;48853.19;5436534
621.2121;-0.3711427;0.05449585;52.64224;5.439709;0;0;0;-1.168953;-1.175839;-0.3711427;48312.13;5376121
628.2121;-0.3722141;0.05570952;52.86729;5.462964;0;0;0;-1.172328;-1.179254;-0.3722141;48518.67;5398920
635.2121;-0.3733927;0.05749077;52.62418;5.437843;0;0;0;-1.17604;-1.18301;-0.3733927;48295.55;5373892
642.2121;-0.3745712;0.05946668;52.50035;5.425047;0;0;0;-1.179752;-1.186766;-0.3745712;48181.91;5361045
649.2121;-0.3757498;0.06032821;52.46594;5.421491;0;0;0;-1.183464;-1.190523;-0.3757498;48150.33;5357330
656.2121;-0.3769284;0.06200094;52.0886;5.3825;0;0;0;-1.187176;-1.194279;-0.3769284;47804.04;5318600
663.2121;-0.378107;0.0633206;51.99884;5.373224;0;0;0;-1.190888;-1.198036;-0.378107;47721.65;5309235
670.2121;-0.3792855;0.0639953;52.04606;5.378103;0;0;0;-1.1946;-1.201793;-0.3792855;47764.98;5313856
677.2121;-0.3804641;0.06575362;52.45589;5.420453;0;0;0;-1.198312;-1.20555;-0.3804641;48141.11;5355499
684.2121;-0.3815891;0.06540753;52.28858;5.403163;0;0;0;-1.201855;-1.209136;-0.3815891;47987.56;5338225
691.2121;-0.3827676;0.066258;51.76424;5.348982;0;0;0;-1.205567;-1.212893;-0.3827676;47506.35;5284497
698.2121;-0.3838927;0.06807756;50.22784;5.19022;0;0;0;-1.209111;-1.21648;-0.3838927;46096.32;5127465
705.2121;-0.384857;0.06935781;48.98155;5.061437;0;0;0;-1.212148;-1.219554;-0.384857;44952.55;5000085
712.2121;-0.3852855;0.07050124;48.4344;5.004898;0;0;0;-1.213498;-1.220921;-0.3852855;44450.41;4944164
719.2121;-0.3853927;0.07039721;47.31306;4.889026;0;0;0;-1.213835;-1.221262;-0.3853927;43421.31;4829682
726.2121;-0.3854462;0.07057542;46.72395;4.828151;0;0;0;-1.214004;-1.221433;-0.3854462;42880.65;4769537
732.7221;-0.3855534;0.07141904;46.03762;4.75723;0;0;0;-1.214341;-1.221775;-0.3855534;42250.77;4699461
738.7241;-0.3853927;0.07080459;45.26175;4.677057;1;1;0;-1.213835;-1.221262;-0.3853927;41538.73;4620285
745.7241;-0.384107;0.07092279;46.67248;4.822832;1;1;0;-1.209786;-1.217163;-0.384107;42833.41;4764486
752.7241;-0.3829284;0.06868342;45.45065;4.696577;1;1;0;-1.206074;-1.213406;-0.3829284;41712.09;4639933
759.7241;-0.3812141;0.06576343;44.79424;4.628747;1;1;0;-1.200674;-1.207941;-0.3812141;41109.67;4573171
766.7241;-0.3789641;0.0641532;45.48551;4.700179;1;1;0;-1.193588;-1.200768;-0.3789641;41744.08;4644078
773.7241;-0.3766069;0.0608618;46.47242;4.802159;1;1;0;-1.186164;-1.193255;-0.3766069;42649.81;4745198
780.7241;-0.3716248;0.05889977;51.73153;5.345602;1;1;0;-1.170472;-1.177376;-0.3716248;47476.33;5283033
787.7241;-0.3678212;0.05684817;53.31701;5.509435;1;1;0;-1.158492;-1.165255;-0.3678212;48931.39;5445609
794.7241;-0.3654106;0.05592507;53.74667;5.553833;1;1;0;-1.150899;-1.157574;-0.3654106;49325.71;5489914
801.7241;-0.363857;0.05995828;54.15269;5.595789;1;1;0;-1.146006;-1.152623;-0.363857;49698.34;5531661
808.7241;-0.3624641;0.06150631;53.77456;5.556716;1;1;0;-1.141619;-1.148186;-0.3624641;49351.32;5493280
815.7241;-0.3610713;0.06306564;54.43688;5.625155;1;1;0;-1.137232;-1.143748;-0.3610713;49959.15;5561184
822.7241;-0.3596784;0.06686974;53.99723;5.579725;1;1;0;-1.132845;-1.139311;-0.3596784;49555.67;5516516
829.7241;-0.3583927;0.07426634;54.34679;5.615846;1;1;0;-1.128796;-1.135215;-0.3583927;49876.47;5552454
836.7241;-0.3576963;0.08173752;54.34012;5.615157;1;1;0;-1.126602;-1.132997;-0.3576963;49870.36;5551897
843.7241;-0.3573748;0.0922044;54.2002;5.600698;1;1;0;-1.12559;-1.131973;-0.3573748;49741.94;5537658
850.7241;-0.357107;0.1015305;54.37348;5.618604;1;1;0;-1.124746;-1.13112;-0.357107;49900.96;5555409
857.7241;-0.3568927;0.1167463;53.84283;5.563771;1;1;0;-1.124071;-1.130437;-0.3568927;49413.97;5501230
864.7241;-0.3566784;0.1331239;54.06416;5.58664;1;1;0;-1.123397;-1.129754;-0.3566784;49617.09;5523880
871.7241;-0.3565713;0.1471756;54.36734;5.61797;1;1;0;-1.123059;-1.129413;-0.3565713;49895.34;5554877
877.142;-0.3566248;0.159165;54.09314;5.589635;1;1;0;-1.123228;-1.129584;-0.3566248;49643.68;5526851
884.142;-0.3566784;0.1702557;54.42587;5.624017;1;1;0;-1.123397;-1.129754;-0.3566784;49949.04;5560837
891.142;-0.3568927;0.1793694;53.95783;5.575654;1;1;0;-1.124071;-1.130437;-0.3568927;49519.5;5512979
896.5481;-0.3567855;0.1857859;54.33939;5.615081;2;2;0;-1.123734;-1.130096;-0.3567855;49869.68;5551983
903.5481;-0.3566784;0.1926201;54.48618;5.63025;2;2;0;-1.123397;-1.129754;-0.3566784;50004.4;5567000
910.5481;-0.3565713;0.1992193;54.65758;5.647961;2;2;0;-1.123059;-1.129413;-0.3565713;50161.7;5584531
915.6261;-0.3565713;0.2035394;54.56808;5.638713;2;2;0;-1.123059;-1.129413;-0.3565713;50079.56;5575387
922.6261;-0.3570534;0.2103007;54.36934;5.618176;2;2;0;-1.124578;-1.130949;-0.3570534;49897.17;5554996
929.6261;-0.3575891;0.2158589;54.52303;5.634058;2;2;0;-1.126265;-1.132655;-0.3575891;50038.22;5570604
936.6261;-0.3587141;0.2228653;53.94182;5.573999;2;2;0;-1.129808;-1.136239;-0.3587141;49504.82;5511024
943.6261;-0.3598927;0.2288694;53.51601;5.529998;2;2;0;-1.13352;-1.139994;-0.3598927;49114.03;5467315
950.6261;-0.3616606;0.2352218;53.06089;5.48297;2;2;0;-1.139088;-1.145626;-0.3616606;48696.34;5420514
957.6261;-0.3640712;0.2415683;52.50264;5.425284;2;2;0;-1.146681;-1.153306;-0.3640712;48184.02;5363073
964.6261;-0.3663213;0.2468879;50.97775;5.267711;2;2;0;-1.153768;-1.160475;-0.3663213;46784.55;5206934
971.6261;-0.3679284;0.253531;49.95651;5.162183;2;2;0;-1.15883;-1.165596;-0.3679284;45847.32;5102362
978.6261;-0.3695356;0.260804;48.64923;5.027098;2;2;0;-1.163892;-1.170718;-0.3695356;44647.57;4968588
985.6261;-0.3709284;0.2708586;46.97452;4.854043;2;2;0;-1.168278;-1.175156;-0.3709284;43110.61;4797335
991.3281;-0.3709284;0.2794934;46.19821;4.773825;3;3;0;-1.168278;-1.175156;-0.3709284;42398.16;4718053
998.3281;-0.3697498;0.2885054;47.27565;4.88516;3;3;0;-1.164566;-1.1714;-0.3697498;43386.97;4828270
1005.328;-0.3685712;0.2965547;50.58191;5.226809;3;3;0;-1.160854;-1.167645;-0.3685712;46421.28;5166133
1012.328;-0.3684641;0.3030209;52.66688;5.442255;3;3;0;-1.160517;-1.167304;-0.3684641;48334.74;5379097
1018.016;-0.3684641;0.3087353;53.70333;5.549355;3;3;0;-1.160517;-1.167304;-0.3684641;49285.94;5484953
1025.016;-0.3693748;0.3143622;54.15527;5.596056;3;3;0;-1.163385;-1.170205;-0.3693748;49700.71;5530952
1032.016;-0.3709284;0.319384;53.87502;5.567096;3;3;0;-1.168278;-1.175156;-0.3709284;49443.51;5502057
1039.016;-0.3726427;0.3263294;52.88913;5.465221;3;3;0;-1.173678;-1.18062;-0.3726427;48538.72;5401077
1046.016;-0.3743569;0.3300007;51.72155;5.344571;3;3;0;-1.179077;-1.186083;-0.3743569;47467.17;5281554
1053.016;-0.3760713;0.3350821;50.50357;5.218712;3;3;0;-1.184476;-1.191547;-0.3760713;46349.38;5156898
1060.016;-0.3778927;0.3382735;48.77574;5.04017;3;3;0;-1.190213;-1.197353;-0.3778927;44763.67;4980181
1067.016;-0.3778927;0.3400708;52.13376;5.387167;3;3;0;-1.190213;-1.197353;-0.3778927;47845.48;5323048
1074.016;-0.3785355;0.3429312;53.23388;5.500845;3;3;0;-1.192238;-1.199402;-0.3785355;48855.1;5435262
1081.016;-0.3791784;0.3438877;53.6949;5.548484;3;3;0;-1.194263;-1.201451;-0.3791784;49278.2;5482220
1088.016;-0.3797141;0.3452338;54.60299;5.642321;3;3;0;-1.19595;-1.203159;-0.3797141;50111.6;5574841
1095.016;-0.3803034;0.3477691;54.76635;5.6592;3;3;0;-1.197806;-1.205037;-0.3803034;50261.52;5591414
1102.016;-0.381107;0.3486354;54.72691;5.655125;3;3;0;-1.200337;-1.207599;-0.381107;50225.32;5587245
1109.016;-0.3822855;0.3507257;54.21679;5.602413;3;3;0;-1.204049;-1.211356;-0.3822855;49757.16;5534957
1116.016;-0.3834641;0.3533072;54.76185;5.658736;3;3;0;-1.207761;-1.215114;-0.3834641;50257.39;5590392
1123.016;-0.3846427;0.3556591;54.60863;5.642903;3;3;0;-1.211473;-1.218871;-0.3846427;50116.77;5574541
1130.016;-0.3867855;0.3589823;54.35853;5.61706;3;3;0;-1.218222;-1.225703;-0.3867855;49887.25;5548632
1137.016;-0.3891427;0.3604735;53.93868;5.573675;3;3;0;-1.225646;-1.233219;-0.3891427;49501.93;5505361
1144.016;-0.3914998;0.3625519;54.00534;5.580563;3;3;0;-1.23307;-1.240736;-0.3914998;49563.11;5511751
1151.016;-0.3938569;0.3644622;53.66985;5.545896;3;3;0;-1.240494;-1.248253;-0.3938569;49255.21;5477099
1158.016;-0.396107;0.3651351;53.77048;5.556294;3;3;0;-1.247581;-1.255429;-0.396107;49347.57;5486975
1165.016;-0.3984641;0.3667235;53.45038;5.523217;3;3;0;-1.255005;-1.262947;-0.3984641;49053.8;5453900
1172.016;-0.4008212;0.3673553;52.994;5.476057;3;3;0;-1.262429;-1.270465;-0.4008212;48634.95;5406926
1179.016;-0.4031784;0.3682554;52.98983;5.475626;3;3;0;-1.269853;-1.277985;-0.4031784;48631.13;5406094
1186.016;-0.4055355;0.3695302;53.22768;5.500205;3;3;0;-1.277277;-1.285505;-0.4055355;48849.41;5429952
1193.016;-0.4077855;0.3687349;53.05205;5.482056;3;3;0;-1.284364;-1.292683;-0.4077855;48688.23;5411647
1200.016;-0.4101427;0.3691271;52.85199;5.461383;3;3;0;-1.291788;-1.300204;-0.4101427;48504.63;5390834
1207.016;-0.4124998;0.3702162;52.81241;5.457293;3;3;0;-1.299212;-1.307726;-0.4124998;48468.3;5386391
1214.016;-0.4148569;0.3696641;52.25249;5.399435;3;3;0;-1.306636;-1.315248;-0.4148569;47954.44;5328884
1221.016;-0.417107;0.3697011;51.92983;5.366093;3;3;0;-1.313723;-1.322428;-0.417107;47658.32;5295598
1228.016;-0.4194641;0.3703113;50.75555;5.24475;3;3;0;-1.321147;-1.329952;-0.4194641;46580.63;5175459
1235.016;-0.4218212;0.3696634;50.05929;5.172803;3;3;0;-1.328571;-1.337475;-0.4218212;45941.64;5104079
1242.016;-0.4238569;0.3691209;50.2999;5.197666;3;3;0;-1.334983;-1.343974;-0.4238569;46162.46;5128278
1249.016;-0.4258926;0.3698032;49.85588;5.151784;3;3;0;-1.341394;-1.350472;-0.4258926;45754.96;5082679
1256.016;-0.4278748;0.3695353;49.8096;5.147002;3;3;0;-1.347637;-1.3568;-0.4278748;45712.49;5077639
1263.016;-0.4298569;0.3689709;49.80346;5.146368;3;3;0;-1.35388;-1.363129;-0.4298569;45706.86;5076692
1270.016;-0.4318927;0.3692063;49.2073;5.084765;3;3;0;-1.360292;-1.369629;-0.4318927;45159.74;5015597
1277.016;-0.4338212;0.3696291;49.09117;5.072764;3;3;0;-1.366366;-1.375787;-0.4338212;45053.16;5003452
1284.016;-0.4358569;0.3683772;48.7299;5.035433;3;3;0;-1.372778;-1.382287;-0.4358569;44721.6;4966308
1291.016;-0.4377855;0.3686814;48.38707;5.000007;3;3;0;-1.378852;-1.388447;-0.4377855;44406.97;4931064
1298.016;-0.4398212;0.3682506;49.8236;5.148449;3;3;0;-1.385264;-1.394948;-0.4398212;45725.34;5077130
1305.016;-0.4418033;0.3672279;50.55681;5.224214;3;3;0;-1.391507;-1.401279;-0.4418033;46398.24;5151519
1312.016;-0.4437855;0.3679114;49.94849;5.161355;3;3;0;-1.39775;-1.40761;-0.4437855;45839.96;5089212
1319.016;-0.4457677;0.3676971;50.47767;5.216036;3;3;0;-1.403993;-1.413942;-0.4457677;46325.61;5142803
1326.016;-0.4477498;0.3676252;50.79201;5.248518;3;3;0;-1.410236;-1.420274;-0.4477498;46614.1;5174502
1333.016;-0.4496784;0.3683752;50.18632;5.18593;3;3;0;-1.41631;-1.426435;-0.4496784;46058.22;5112481
1340.016;-0.451714;0.3684373;50.31241;5.198959;3;3;0;-1.422721;-1.432939;-0.451714;46173.94;5124992
1347.016;-0.4536426;0.3683037;50.46105;5.214319;3;3;0;-1.428796;-1.439101;-0.4536426;46310.36;5139817
1354.016;-0.4556783;0.3692565;49.5812;5.123401;3;3;0;-1.435207;-1.445606;-0.4556783;45502.88;5049870
1361.016;-0.4576069;0.3684119;50.29534;5.197196;3;3;0;-1.441282;-1.451769;-0.4576069;46158.28;5122290
1368.016;-0.4596427;0.3684616;50.08882;5.175856;3;3;0;-1.447693;-1.458275;-0.4596427;45968.75;5100925
1375.016;-0.4615712;0.3690458;49.62319;5.12774;3;3;0;-1.453768;-1.464438;-0.4615712;45541.42;5053195
1382.016;-0.4636069;0.3678755;49.26609;5.09084;3;3;0;-1.460179;-1.470945;-0.4636069;45213.69;5016504
1389.016;-0.4656426;0.3677103;49.20863;5.084902;3;3;0;-1.466591;-1.477452;-0.4656426;45160.95;5010327
1396.016;-0.4675712;0.3682183;48.48761;5.010396;3;3;0;-1.472665;-1.483617;-0.4675712;44499.25;4936610
1403.016;-0.4695533;0.3683308;48.38014;4.999291;3;3;0;-1.478908;-1.489953;-0.4695533;44400.61;4925356
1410.016;-0.4715355;0.3673395;48.41802;5.003205;3;3;0;-1.485151;-1.49629;-0.4715355;44435.38;4928900
1417.016;-0.4735712;0.3683473;47.37508;4.895435;3;3;0;-1.491563;-1.502798;-0.4735712;43478.22;4822416
1424.016;-0.4754998;0.3684092;47.12716;4.869816;3;3;0;-1.497637;-1.508965;-0.4754998;43250.69;4796884
1431.016;-0.4774283;0.3665772;46.96639;4.853203;3;3;0;-1.503711;-1.515132;-0.4774283;43103.15;4780225
1438.016;-0.4794641;0.3675132;46.53121;4.808234;3;3;0;-1.510123;-1.521642;-0.4794641;42703.76;4735624
1445.016;-0.4805355;0.3677497;48.39596;5.000926;3;3;0;-1.513498;-1.525068;-0.4805355;44415.13;4925237
1452.016;-0.4820355;0.3667376;49.36655;5.10122;3;3;0;-1.518222;-1.529865;-0.4820355;45305.88;5023772
1459.016;-0.4835355;0.3660186;50.61454;5.230179;3;3;0;-1.522946;-1.534662;-0.4835355;46451.22;5150527
1466.016;-0.484714;0.36621;51.42332;5.313754;3;3;0;-1.526658;-1.538432;-0.484714;47193.48;5232631
1473.016;-0.4861069;0.3660417;52.07004;5.380582;3;3;0;-1.531045;-1.542887;-0.4861069;47787;5298203
1480.016;-0.4876069;0.364561;52.60882;5.436256;3;3;0;-1.53577;-1.547685;-0.4876069;48281.46;5352768
1487.016;-0.4892141;0.3648405;52.63073;5.438519;3;3;0;-1.540832;-1.552826;-0.4892141;48301.57;5354721
1494.016;-0.4908748;0.365776;51.95091;5.368272;3;3;0;-1.546062;-1.558139;-0.4908748;47677.67;5285275
1501.016;-0.4926426;0.3649122;51.88317;5.361272;3;3;0;-1.55163;-1.563794;-0.4926426;47615.5;5278085
1508.016;-0.4945712;0.3641575;51.2745;5.298376;3;3;0;-1.557705;-1.569964;-0.4945712;47056.9;5215843
1515.016;-0.4963926;0.3650199;50.5233;5.220752;3;3;0;-1.563441;-1.575792;-0.4963926;46367.48;5139128
1522.016;-0.498214;0.3648929;49.87138;5.153386;3;3;0;-1.569178;-1.58162;-0.498214;45769.19;5072521
1529.016;-0.5000355;0.365834;48.30496;4.991523;3;3;0;-1.574915;-1.587448;-0.5000355;44331.62;4912911
1536.016;-0.5018569;0.3661872;46.61815;4.817219;3;3;0;-1.580652;-1.593277;-0.5018569;42783.56;4741076
1541.104;-0.501589;0.3662204;50.37995;5.205938;4;4;0;-1.579808;-1.59242;-0.501589;46235.92;5123694
1548.104;-0.5008926;0.3657919;53.89387;5.569045;4;4;0;-1.577615;-1.590191;-0.5008926;49460.81;5481186
1555.104;-0.5008926;0.3649991;54.59415;5.641407;4;4;0;-1.577615;-1.590191;-0.5008926;50103.49;5552408
1562.104;-0.5008926;0.3638268;54.98218;5.681503;4;4;0;-1.577615;-1.590191;-0.5008926;50459.59;5591871
1569.104;-0.5008391;0.3628438;55.03512;5.686974;4;4;0;-1.577446;-1.59002;-0.5008391;50508.18;5597265
1576.104;-0.5008391;0.3617819;54.99427;5.682753;4;4;0;-1.577446;-1.59002;-0.5008391;50470.7;5593111
1583.104;-0.5007855;0.3605496;54.96047;5.67926;4;4;0;-1.577277;-1.589848;-0.5007855;50439.68;5589683
1588.194;-0.5007855;0.3596406;54.83054;5.665833;4;4;0;-1.577277;-1.589848;-0.5007855;50320.43;5576468
1595.194;-0.5007855;0.3585165;55.01997;5.685408;4;4;0;-1.577277;-1.589848;-0.5007855;50494.28;5595733
1602.194;-0.5008926;0.35709;54.52744;5.634513;4;4;0;-1.577615;-1.590191;-0.5008926;50042.26;5545622
1609.194;-0.5009998;0.355849;55.14706;5.698541;4;4;0;-1.577952;-1.590534;-0.5009998;50610.91;5608620
1616.194;-0.5011069;0.354707;55.15731;5.6996;4;4;0;-1.578289;-1.590877;-0.5011069;50620.32;5609643
1623.194;-0.5022855;0.3534373;54.56752;5.638655;4;4;0;-1.582001;-1.594649;-0.5022855;50079.05;5549451
1630.194;-0.5035176;0.3523223;54.2165;5.602383;4;4;0;-1.585882;-1.598592;-0.5035176;49756.9;5513535
1637.194;-0.5046426;0.3510441;54.21485;5.602212;4;4;0;-1.589425;-1.602192;-0.5046426;49755.39;5513170
1644.194;-0.5058212;0.3500126;53.67302;5.546223;4;4;0;-1.593138;-1.605964;-0.5058212;49258.13;5457864
1651.194;-0.5069998;0.348942;53.15873;5.49308;4;4;0;-1.59685;-1.609737;-0.5069998;48786.14;5405364
1658.194;-0.5081783;0.34796;53.09906;5.486914;4;4;0;-1.600562;-1.613509;-0.5081783;48731.38;5399093
1665.194;-0.5093569;0.3468512;52.66265;5.441818;4;4;0;-1.604274;-1.617281;-0.5093569;48330.86;5354516
1672.194;-0.5105355;0.3458767;52.42421;5.417179;4;4;0;-1.607986;-1.621054;-0.5105355;48112.04;5330072
1679.194;-0.5116069;0.3447946;52.17946;5.391888;4;4;0;-1.61136;-1.624484;-0.5116069;47887.41;5305005
1686.194;-0.5127855;0.3440686;51.79901;5.352575;4;4;0;-1.615072;-1.628257;-0.5127855;47538.26;5266127
1693.194;-0.513964;0.3429914;51.75658;5.348191;4;4;0;-1.618784;-1.63203;-0.513964;47499.32;5261615
1700.194;-0.5151426;0.3423342;51.0003;5.270041;4;4;0;-1.622496;-1.635803;-0.5151426;46805.25;5184535
1707.194;-0.5163747;0.3412585;50.40291;5.208311;4;4;0;-1.626377;-1.639748;-0.5163747;46257;5123604
1714.194;-0.5174997;0.340529;53.03393;5.480184;4;4;0;-1.62992;-1.64335;-0.5174997;48671.61;5390861
1721.194;-0.5186783;0.3395287;52.35922;5.410464;4;4;0;-1.633633;-1.647123;-0.5186783;48052.39;5322077
1728.194;-0.5198569;0.3387911;51.68678;5.340978;4;4;0;-1.637345;-1.650897;-0.5198569;47435.26;5253528
1735.194;-0.5209819;0.338107;50.38729;5.206697;4;4;0;-1.640888;-1.654499;-0.5209819;46242.66;5121261
1742.194;-0.5221069;0.3375294;48.39127;5.000441;4;4;0;-1.644431;-1.658102;-0.5221069;44410.82;4918212
1747.426;-0.5216783;0.336614;50.52104;5.220518;5;5;0;-1.643081;-1.65673;-0.5216783;46365.41;5134741
1754.426;-0.5209283;0.3357486;52.52231;5.427317;5;5;0;-1.640719;-1.654328;-0.5209283;48202.07;5338270
1761.426;-0.5207676;0.3351261;53.02838;5.47961;5;5;0;-1.640213;-1.653813;-0.5207676;48666.51;5389733
1767.41;-0.5207676;0.3346057;53.88342;5.567964;5;5;0;-1.640213;-1.653813;-0.5207676;49451.21;5476638
1774.41;-0.5209283;0.3337853;53.77747;5.557016;5;5;0;-1.640719;-1.654328;-0.5209283;49353.98;5465841
1781.41;-0.5210354;0.3333412;54.0752;5.587781;5;5;0;-1.641057;-1.654671;-0.5210354;49627.22;5496083
1788.41;-0.5215712;0.3325491;53.76138;5.555353;5;5;0;-1.642744;-1.656387;-0.5215712;49339.21;5464093
1795.41;-0.522214;0.3318387;53.44953;5.523129;5;5;0;-1.644769;-1.658445;-0.522214;49053.02;5432286
1802.41;-0.5227498;0.3313089;53.12772;5.489876;5;5;0;-1.646456;-1.660161;-0.5227498;48757.68;5399487
1809.41;-0.5233926;0.3308488;52.71897;5.447638;5;5;0;-1.648481;-1.662219;-0.5233926;48382.55;5357834
1816.41;-0.5239283;0.3303812;52.53271;5.428391;5;5;0;-1.650168;-1.663935;-0.5239283;48211.61;5338814
1823.41;-0.5245712;0.3298301;51.92639;5.365738;5;5;0;-1.652193;-1.665994;-0.5245712;47655.17;5277086
1830.41;-0.5251069;0.329547;51.52619;5.324383;5;5;0;-1.65388;-1.667709;-0.5251069;47287.88;5236324
1837.41;-0.5256426;0.3287694;51.09761;5.280097;5;5;0;-1.655567;-1.669425;-0.5256426;46894.55;5192682
1844.41;-0.5261783;0.3284828;50.419;5.209974;5;5;0;-1.657255;-1.671141;-0.5261783;46271.76;5123631
1851.41;-0.5264998;0.3280529;50.39709;5.20771;5;5;0;-1.658267;-1.67217;-0.5264998;46251.66;5121352
1858.41;-0.526714;0.327805;50.12814;5.179918;5;5;0;-1.658942;-1.672856;-0.526714;46004.83;5093987
1865.41;-0.5269283;0.327263;50.27693;5.195293;5;5;0;-1.659617;-1.673543;-0.5269283;46141.38;5109071
1872.41;-0.5271426;0.326721;49.9968;5.166346;5;5;0;-1.660292;-1.674229;-0.5271426;45884.29;5080570
1879.41;-0.5272498;0.3263906;51.89251;5.362236;5;5;0;-1.660629;-1.674572;-0.5272498;47624.07;5273189
1886.41;-0.5273569;0.32603;52.13432;5.387224;5;5;0;-1.660967;-1.674915;-0.5273569;47845.99;5297744
1893.41;-0.5275712;0.3257085;52.10945;5.384654;5;5;0;-1.661641;-1.675602;-0.5275712;47823.17;5295180
1900.41;-0.5277855;0.325426;51.6462;5.336784;5;5;0;-1.662316;-1.676288;-0.5277855;47398.02;5248070
1907.41;-0.5278926;0.3251264;51.8366;5.356459;5;5;0;-1.662654;-1.676631;-0.5278926;47572.76;5267400
1914.41;-0.5281069;0.3247728;51.49036;5.320681;5;5;0;-1.663329;-1.677318;-0.5281069;47255;5232181
1921.41;-0.5283212;0.3244236;51.30114;5.301128;5;5;0;-1.664004;-1.678004;-0.5283212;47081.34;5212917
1928.41;-0.5284284;0.3241237;51.62338;5.334426;5;5;0;-1.664341;-1.678347;-0.5284284;47377.08;5245644
1935.41;-0.5286426;0.3239968;51.98944;5.372253;5;5;0;-1.665016;-1.679033;-0.5286426;47713.03;5282804
1942.41;-0.5288569;0.3236092;51.49567;5.32123;5;5;0;-1.665691;-1.67972;-0.5288569;47259.88;5232595
1949.41;-0.528964;0.3234178;51.3268;5.30378;5;5;0;-1.666028;-1.680063;-0.528964;47104.89;5215418
1956.41;-0.5291784;0.3233319;51.10666;5.281032;5;5;0;-1.666703;-1.680749;-0.5291784;46902.86;5193013
1963.41;-0.5293926;0.323194;50.61319;5.23004;5;5;0;-1.667378;-1.681435;-0.5293926;46449.98;5142835
1970.41;-0.5294998;0.3228704;50.73725;5.24286;5;5;0;-1.667716;-1.681779;-0.5294998;46563.84;5155424
1977.41;-0.529714;0.3228381;50.16946;5.184188;5;5;0;-1.668391;-1.682465;-0.529714;46042.75;5097695
1984.41;-0.5299283;0.3226689;49.64272;5.129758;5;5;0;-1.669065;-1.683151;-0.5299283;45559.34;5044139
1991.41;-0.5299283;0.3225054;49.8762;5.153884;5;5;0;-1.669065;-1.683151;-0.5299283;45773.61;5067862
1998.41;-0.5301426;0.3225906;49.23884;5.088024;5;5;0;-1.66974;-1.683838;-0.5301426;45188.68;5003067
2005.41;-0.5302498;0.3222078;50.4454;5.212702;5;5;0;-1.670078;-1.684181;-0.5302498;46295.99;5125645
2012.41;-0.5303033;0.3223435;50.25262;5.192781;5;5;0;-1.670247;-1.684353;-0.5303033;46119.07;5106049
2019.41;-0.530464;0.3222113;49.83896;5.150036;5;5;0;-1.670753;-1.684867;-0.530464;45739.44;5063992
2026.41;-0.5305712;0.3219636;49.32344;5.096766;5;5;0;-1.67109;-1.685211;-0.5305712;45266.32;5011594
2032.144;-0.5305712;0.3214276;49.06953;5.070528;6;6;0;-1.67109;-1.685211;-0.5305712;45033.29;4985795
2039.144;-0.5300355;0.3208153;49.85573;5.151769;6;6;0;-1.669403;-1.683495;-0.5300355;45754.83;5065765
2046.144;-0.5293926;0.3202146;51.18291;5.288912;6;6;0;-1.667378;-1.681435;-0.5293926;46972.84;5200726
2053.144;-0.5288569;0.3197555;52.09665;5.383331;6;6;0;-1.665691;-1.67972;-0.5288569;47811.42;5293662
2060.144;-0.5282676;0.3188947;52.50073;5.425086;6;6;0;-1.663835;-1.677832;-0.5282676;48182.26;5334822
2067.144;-0.5281605;0.3185774;52.37361;5.411951;6;6;0;-1.663497;-1.677489;-0.5281605;48065.6;5321923
2074.144;-0.5280533;0.3179113;52.01507;5.374902;6;6;0;-1.66316;-1.677146;-0.5280533;47736.55;5285508
2081.144;-0.5279462;0.3175047;51.68246;5.340532;6;6;0;-1.662823;-1.676803;-0.5279462;47431.3;5251728
2088.144;-0.5277855;0.3173165;51.61868;5.333941;6;6;0;-1.662316;-1.676288;-0.5277855;47372.77;5245274
2095.144;-0.5276783;0.3168706;51.30848;5.301887;6;6;0;-1.661979;-1.675945;-0.5276783;47088.08;5213771
2102.144;-0.5275712;0.316063;50.96914;5.266822;6;6;0;-1.661641;-1.675602;-0.5275712;46776.65;5179306
2109.144;-0.5274104;0.3149194;50.67597;5.236527;6;6;0;-1.661135;-1.675087;-0.5274104;46507.59;5149541
2116.144;-0.5273569;0.3131794;50.28712;5.196346;6;6;0;-1.660967;-1.674915;-0.5273569;46150.73;5110037
2123.144;-0.5271962;0.3111073;51.40811;5.312182;6;6;0;-1.66046;-1.674401;-0.5271962;47179.52;5223976
2130.144;-0.527089;0.3094011;51.00928;5.27097;6;6;0;-1.660123;-1.674057;-0.527089;46813.5;5183465
2137.144;-0.5269819;0.3077084;50.66965;5.235875;6;6;0;-1.659786;-1.673714;-0.5269819;46501.8;5148970
2144.144;-0.5268212;0.3053076;51.37564;5.308826;6;6;0;-1.659279;-1.6732;-0.5268212;47149.71;5220738
2151.144;-0.5267676;0.3029514;51.61977;5.334054;6;6;0;-1.659111;-1.673028;-0.5267676;47373.77;5245556
2158.144;-0.5266604;0.3007917;52.54099;5.429247;6;6;0;-1.658773;-1.672685;-0.5266604;48219.21;5339188
2165.144;-0.5264998;0.298639;53.14235;5.491387;6;6;0;-1.658267;-1.67217;-0.5264998;48771.1;5400325
2170.452;-0.5264998;0.297335;53.22436;5.499862;6;6;0;-1.658267;-1.67217;-0.5264998;48846.37;5408659
2177.452;-0.5269283;0.2954688;52.86071;5.462285;6;6;0;-1.659617;-1.673543;-0.5269283;48512.63;5371632
2184.452;-0.5275712;0.2935814;52.10719;5.38442;6;6;0;-1.661641;-1.675602;-0.5275712;47821.09;5294951
2191.452;-0.5281069;0.291293;52.13101;5.386881;6;6;0;-1.663329;-1.677318;-0.5281069;47842.95;5297280
2198.452;-0.5286426;0.2903664;51.11799;5.282203;6;6;0;-1.665016;-1.679033;-0.5286426;46913.26;5194253
2205.452;-0.5292855;0.2892625;50.02866;5.169638;6;6;0;-1.667041;-1.681092;-0.5292855;45913.53;5083458
2212.452;-0.5294462;0.2876924;49.91273;5.157659;6;6;0;-1.667547;-1.681607;-0.5294462;45807.14;5071653
2219.452;-0.529714;0.2844096;49.63518;5.128978;6;6;0;-1.668391;-1.682465;-0.529714;45552.41;5043407
2226.452;-0.5299283;0.2789482;50.11396;5.178453;6;6;0;-1.669065;-1.683151;-0.5299283;45991.82;5092021
2233.452;-0.5301426;0.2724303;50.92216;5.261967;6;6;0;-1.66974;-1.683838;-0.5301426;46733.54;5174106
2240.452;-0.5306783;0.2674149;52.27651;5.401917;6;6;0;-1.671428;-1.685554;-0.5306783;47976.48;5311627
2247.452;-0.5321783;0.2627754;52.34666;5.409165;6;6;0;-1.676152;-1.690359;-0.5321783;48040.86;5318500
2254.452;-0.5345355;0.2589394;51.83246;5.356031;6;6;0;-1.683576;-1.69791;-0.5345355;47568.96;5265858
2261.452;-0.5368926;0.2550605;50.56247;5.224799;6;6;0;-1.691;-1.705461;-0.5368926;46403.43;5136448
2268.452;-0.5386069;0.2513515;49.67564;5.13316;6;6;0;-1.6964;-1.710953;-0.5386069;45589.55;5046081
2275.452;-0.5397855;0.2476022;48.69589;5.031919;6;6;0;-1.700112;-1.71473;-0.5397855;44690.39;4946371
2282.452;-0.540964;0.2442701;47.26855;4.884426;6;6;0;-1.703824;-1.718506;-0.540964;43380.45;4801204
2289.452;-0.5416069;0.2414482;46.50419;4.805442;6;6;0;-1.705848;-1.720566;-0.5416069;42678.97;4723469
2294.684;-0.5416069;0.2393625;46.28223;4.782506;7;7;0;-1.705848;-1.720566;-0.5416069;42475.26;4700924
2301.684;-0.5414998;0.2368521;45.85295;4.738147;7;7;0;-1.705511;-1.720222;-0.5414998;42081.29;4657338
2308.684;-0.5402141;0.2342866;47.3091;4.888617;7;7;0;-1.701462;-1.716103;-0.5402141;43417.67;4805439
2315.684;-0.5384462;0.2321847;49.62851;5.128289;7;7;0;-1.695894;-1.710438;-0.5384462;45546.3;5041319
2322.684;-0.5373212;0.2303359;50.07264;5.174183;7;7;0;-1.69235;-1.706834;-0.5373212;45953.9;5086618
2329.684;-0.5365176;0.2286894;50.00188;5.166871;7;7;0;-1.689819;-1.704259;-0.5365176;45888.95;5079560
2336.684;-0.5359819;0.2270551;49.54881;5.120054;7;7;0;-1.688132;-1.702543;-0.5359819;45473.16;5033621
2343.684;-0.5350176;0.2247993;50.18132;5.185414;7;7;0;-1.685095;-1.699454;-0.5350176;46053.64;5098035
2350.684;-0.5341069;0.2216682;50.72665;5.241764;7;7;0;-1.682227;-1.696537;-0.5341069;46554.11;5153586
2357.684;-0.533464;0.2184439;51.02617;5.272715;7;7;0;-1.680202;-1.694477;-0.533464;46828.99;5184122
2364.684;-0.5329283;0.2147456;50.98861;5.268834;7;7;0;-1.678514;-1.692761;-0.5329283;46794.52;5180396
2371.684;-0.5324997;0.210565;51.04608;5.274772;7;7;0;-1.677164;-1.691388;-0.5324997;46847.26;5186305
2378.684;-0.5320711;0.2067084;51.07104;5.277351;7;7;0;-1.675815;-1.690015;-0.5320711;46870.17;5188912
2385.684;-0.5315355;0.2028864;51.08182;5.278465;7;7;0;-1.674127;-1.688299;-0.5315355;46880.06;5190097
2392.684;-0.5311069;0.1998147;50.78247;5.247533;7;7;0;-1.672778;-1.686927;-0.5311069;46605.34;5159753
2399.684;-0.5305712;0.1970118;50.58547;5.227175;7;7;0;-1.67109;-1.685211;-0.5305712;46424.54;5139825
2406.684;-0.5300355;0.194443;50.84452;5.253944;7;7;0;-1.669403;-1.683495;-0.5300355;46662.28;5166235
2413.684;-0.5293926;0.1921639;50.27676;5.195275;7;7;0;-1.667378;-1.681435;-0.5293926;46141.22;5108650
2420.684;-0.5286961;0.1874335;52.01431;5.374823;7;7;0;-1.665185;-1.679205;-0.5286961;47735.86;5285322
2427.684;-0.528214;0.184839;51.05812;5.276016;7;7;0;-1.663666;-1.677661;-0.528214;46858.31;5188241
2434.684;-0.5277855;0.1818645;49.81556;5.147618;7;7;0;-1.662316;-1.676288;-0.5277855;45717.96;5062049
2441.684;-0.5272498;0.1784085;49.3213;5.096544;7;7;0;-1.660629;-1.674572;-0.5272498;45264.36;5011910
2448.684;-0.5260712;0.174349;50.50424;5.218782;7;7;0;-1.656917;-1.670797;-0.5260712;46350;5132311
2455.684;-0.5252141;0.1699252;50.89779;5.259449;7;7;0;-1.654217;-1.668052;-0.5252141;46711.17;5172446
2462.684;-0.5244104;0.1653332;51.49479;5.321139;7;7;0;-1.651686;-1.665479;-0.5244104;47259.07;5233251
2469.684;-0.5236605;0.1603944;51.80579;5.353276;7;7;0;-1.649324;-1.663077;-0.5236605;47544.49;5264983
2476.684;-0.5232319;0.1551561;52.06626;5.38019;7;7;0;-1.647974;-1.661705;-0.5232319;47783.52;5291526
2483.684;-0.522964;0.1495253;53.21024;5.498402;7;7;0;-1.647131;-1.660847;-0.522964;48833.41;5407836
2490.684;-0.5227498;0.143823;52.47727;5.422662;7;7;0;-1.646456;-1.660161;-0.5227498;48160.73;5333380
2497.684;-0.5225354;0.136196;52.25625;5.399823;7;7;0;-1.645781;-1.659474;-0.5225354;47957.89;5310954
2504.684;-0.5223212;0.1252519;52.26303;5.400524;7;7;0;-1.645106;-1.658788;-0.5223212;47964.11;5311679
2511.684;-0.5221069;0.1113711;52.43813;5.418618;7;7;0;-1.644431;-1.658102;-0.5221069;48124.81;5329512
2518.684;-0.5219462;0.09475394;52.98845;5.475484;7;7;0;-1.643925;-1.657587;-0.5219462;48629.86;5385471
2523.744;-0.5219462;0.08218037;53.07008;5.483919;7;7;0;-1.643925;-1.657587;-0.5219462;48704.78;5393768
2530.744;-0.5224283;0.06379362;52.50197;5.425214;7;7;0;-1.645443;-1.659131;-0.5224283;48183.4;5335945
2537.744;-0.5226426;0.04576859;52.78974;5.454951;7;7;0;-1.646119;-1.659818;-0.5226426;48447.5;5365156
2544.744;-0.5227498;0.02842316;52.8213;5.458212;7;7;0;-1.646456;-1.660161;-0.5227498;48476.46;5368345
2551.726;-0.5228569;0.01163648;52.04735;5.378237;7;7;0;-1.646793;-1.660504;-0.5228569;47766.17;5289668
2557.728;-0.5228569;-0.002233236;51.77106;5.349687;8;8;0;-1.646793;-1.660504;-0.5228569;47512.61;5261588
2564.728;-0.5224283;-0.01572564;52.83699;5.459833;8;8;0;-1.645443;-1.659131;-0.5224283;48490.86;5369994
2571.728;-0.5222676;-0.0248939;54.47916;5.629525;8;8;0;-1.644937;-1.658617;-0.5222676;49997.96;5536922
2576.978;-0.5221605;-0.02674578;55.1687;5.700777;8;8;0;-1.6446;-1.658274;-0.5221605;50630.77;5607022
2583.978;-0.5222676;-0.02667726;55.07365;5.690955;8;8;0;-1.644937;-1.658617;-0.5222676;50543.54;5597342
2590.978;-0.5223212;-0.02503473;55.1884;5.702813;8;8;0;-1.645106;-1.658788;-0.5223212;50648.86;5608996
2597.978;-0.5225354;-0.02140333;55.21545;5.705608;8;8;0;-1.645781;-1.659474;-0.5225354;50673.68;5611706
2604.978;-0.5226426;-0.01870791;55.25362;5.709552;8;8;0;-1.646119;-1.659818;-0.5226426;50708.71;5615566
2611.978;-0.5228569;-0.01609119;55.0735;5.690939;8;8;0;-1.646793;-1.660504;-0.5228569;50543.41;5597221
2618.978;-0.5233926;-0.01403135;55.20488;5.704515;8;8;0;-1.648481;-1.662219;-0.5233926;50663.98;5610477
2625.978;-0.5240355;-0.01193227;55.20805;5.704843;8;8;0;-1.650505;-1.664278;-0.5240355;50666.89;5610684
2632.978;-0.5245712;-0.009265153;54.95396;5.678587;8;8;0;-1.652193;-1.665994;-0.5245712;50433.7;5584766
2639.978;-0.5251069;-0.006969443;54.93349;5.676472;8;8;0;-1.65388;-1.667709;-0.5251069;50414.91;5582590
2646.978;-0.5257497;-0.004700474;54.97683;5.680951;8;8;0;-1.655905;-1.669768;-0.5257497;50454.69;5586879
2653.978;-0.5262855;-0.003426077;54.92559;5.675656;8;8;0;-1.657592;-1.671484;-0.5262855;50407.66;5581577
2660.978;-0.5273569;-0.001924596;54.62082;5.644162;8;8;0;-1.660967;-1.674915;-0.5273569;50127.96;5550415
2667.978;-0.5284284;-0.0009743436;53.86368;5.565925;8;8;0;-1.664341;-1.678347;-0.5284284;49433.11;5473289
2674.978;-0.5296069;-0.000211593;53.81424;5.560815;8;8;0;-1.668053;-1.682122;-0.5296069;49387.72;5468058
2681.978;-0.5307855;0.0004641215;53.68295;5.547249;8;8;0;-1.671765;-1.685897;-0.5307855;49267.23;5454512
2688.978;-0.531964;0.001223759;53.55885;5.534426;8;8;0;-1.675477;-1.689672;-0.531964;49153.35;5441698
2695.978;-0.5331426;0.001221567;54.04806;5.584978;8;8;0;-1.679189;-1.693447;-0.5331426;49602.32;5491195
2702.978;-0.5352854;0.0006200074;53.97404;5.577328;8;8;0;-1.685938;-1.700312;-0.5352854;49534.38;5483298
2709.978;-0.5376426;-0.0002541714;53.3878;5.516751;8;8;0;-1.693363;-1.707864;-0.5376426;48996.37;5423332
2716.978;-0.5398926;-0.0008775976;53.49587;5.527917;8;8;0;-1.700449;-1.715073;-0.5398926;49095.54;5433918
2723.978;-0.5422498;-0.001702934;53.89464;5.569123;8;8;0;-1.707873;-1.722626;-0.5422498;49461.51;5474010
2730.978;-0.5446069;-0.001869959;53.18096;5.495377;8;8;0;-1.715297;-1.730179;-0.5446069;48806.54;5401115
2737.978;-0.5468569;-0.002294137;52.72998;5.448775;8;8;0;-1.722384;-1.73739;-0.5468569;48392.65;5354927
2744.978;-0.549214;-0.002579481;52.32405;5.406829;8;8;0;-1.729808;-1.744944;-0.549214;48020.11;5313301
2751.978;-0.5515712;-0.003339746;51.21225;5.291943;8;8;0;-1.737232;-1.752499;-0.5515712;46999.77;5200010
2758.978;-0.5539283;-0.003569513;49.75466;5.141325;8;8;0;-1.744656;-1.760055;-0.5539283;45662.07;5051627
2765.978;-0.5554283;-0.004445747;47.23137;4.880585;8;8;0;-1.74938;-1.764863;-0.5554283;43346.34;4795205
2772.978;-0.5555355;-0.005320024;45.90665;4.743697;8;8;0;-1.749718;-1.765207;-0.5555355;42130.58;4660696
2779.978;-0.5556426;-0.006115976;44.87584;4.63718;8;8;0;-1.750055;-1.76555;-0.5556426;41184.56;4556027
2784.994;-0.5557497;-0.00676029;43.59076;4.504388;9;9;0;-1.750393;-1.765893;-0.5557497;40005.19;4425544
2791.994;-0.555214;-0.007606631;43.89117;4.535429;9;9;0;-1.748706;-1.764176;-0.555214;40280.88;4456118
2798.994;-0.5539818;-0.008219192;43.80551;4.526578;9;9;0;-1.744825;-1.760226;-0.5539818;40202.27;4447597
2805.994;-0.5525355;-0.009371139;44.17028;4.564271;9;9;0;-1.740269;-1.75559;-0.5525355;40537.03;4484840
2812.994;-0.5502854;-0.01066625;44.76646;4.625877;9;9;0;-1.733182;-1.748378;-0.5502854;41084.18;4545702
2819.994;-0.5478748;-0.01190848;46.72783;4.828552;9;9;0;-1.72559;-1.740652;-0.5478748;42884.21;4745231
2826.994;-0.5455712;-0.01328812;48.50846;5.012551;9;9;0;-1.718334;-1.733269;-0.5455712;44518.38;4926418
2833.994;-0.5434283;-0.0144587;49.76194;5.142077;9;9;0;-1.711585;-1.726402;-0.5434283;45668.75;5054066
2840.994;-0.5418747;-0.01552126;49.43849;5.108654;9;9;0;-1.706692;-1.721424;-0.5418747;45371.91;5021465
2847.994;-0.5401069;-0.0161653;50.06983;5.173892;9;9;0;-1.701124;-1.715759;-0.5401069;45951.31;5085878
2854.994;-0.5383926;-0.01691967;51.12504;5.282931;9;9;0;-1.695725;-1.710267;-0.5383926;46919.73;5193347
2861.994;-0.5366247;-0.01754843;51.11808;5.282212;9;9;0;-1.690157;-1.704603;-0.5366247;46913.34;5192934
2868.994;-0.5348569;-0.01806565;51.32016;5.303094;9;9;0;-1.684589;-1.698939;-0.5348569;47098.8;5213759
2875.994;-0.5331426;-0.01876049;51.55053;5.326899;9;9;0;-1.679189;-1.693447;-0.5331426;47310.22;5237450
2882.994;-0.5316426;-0.01961006;51.61111;5.333158;9;9;0;-1.674465;-1.688643;-0.5316426;47365.82;5243857
2889.994;-0.530464;-0.02045149;51.10064;5.28041;9;9;0;-1.670753;-1.684867;-0.530464;46897.33;5192187
2896.994;-0.5293926;-0.0210248;52.17963;5.391906;9;9;0;-1.667378;-1.681435;-0.5293926;47887.57;5302003
2903.994;-0.528214;-0.02175629;52.09586;5.383249;9;9;0;-1.663666;-1.677661;-0.528214;47810.69;5293690
2910.994;-0.5269283;-0.02290413;51.66508;5.338736;9;9;0;-1.659617;-1.673543;-0.5269283;47415.35;5250133
2917.994;-0.5258569;-0.02373314;50.75325;5.244514;9;9;0;-1.656242;-1.670111;-0.5258569;46578.52;5157652
2924.994;-0.5246783;-0.02468142;50.26886;5.194459;9;9;0;-1.65253;-1.666337;-0.5246783;46133.97;5108619
2931.994;-0.5234997;-0.02602662;49.61664;5.127063;9;9;0;-1.648818;-1.662562;-0.5234997;45535.41;5042528
2938.994;-0.5212497;-0.02716263;50.64625;5.233456;9;9;0;-1.641732;-1.655357;-0.5212497;46480.32;5147537
2945.994;-0.519589;-0.02848979;50.81051;5.25043;9;9;0;-1.636501;-1.65004;-0.519589;46631.07;5164507
2952.994;-0.518089;-0.02945713;50.67139;5.236054;9;9;0;-1.631776;-1.645237;-0.518089;46503.39;5150613
2959.994;-0.5164819;-0.03049491;50.12245;5.17933;9;9;0;-1.626715;-1.640091;-0.5164819;45999.61;5095077
2966.994;-0.514714;-0.03154142;50.80203;5.249554;9;9;0;-1.621147;-1.634431;-0.514714;46623.29;5164451
2973.994;-0.5129998;-0.03245841;50.7194;5.241015;9;9;0;-1.615747;-1.628943;-0.5129998;46547.45;5156333
2980.994;-0.5117141;-0.03264227;48.22641;4.983406;9;9;0;-1.611698;-1.624827;-0.5117141;44259.53;4903089
2987.994;-0.5103212;-0.03320912;52.46312;5.4212;9;9;0;-1.607311;-1.620368;-0.5103212;48147.74;5334064
2994.994;-0.5089819;-0.03349211;51.77552;5.350148;9;9;0;-1.603093;-1.616081;-0.5089819;47516.7;5264380
3001.994;-0.5074819;-0.03395184;51.41998;5.313408;9;9;0;-1.598368;-1.61128;-0.5074819;47190.41;5228480
3008.994;-0.5061426;-0.0344665;50.28504;5.196131;9;9;0;-1.59415;-1.606993;-0.5061426;46148.82;5113297
3015.994;-0.5046426;-0.03495607;49.80637;5.146668;9;9;0;-1.589425;-1.602192;-0.5046426;45709.53;5064866
3022.994;-0.5027141;-0.03563924;50.57034;5.225613;9;9;0;-1.583351;-1.59602;-0.5027141;46410.66;5142873
3029.994;-0.5009998;-0.0367325;51.02261;5.272347;9;9;0;-1.577952;-1.590534;-0.5009998;46825.73;5189152
3036.994;-0.4992855;-0.03760838;50.21219;5.188603;9;9;0;-1.572553;-1.585048;-0.4992855;46081.96;5107009
3043.994;-0.4975176;-0.03833106;50.25485;5.193012;9;9;0;-1.566985;-1.579392;-0.4975176;46121.12;5111638
3050.994;-0.4957497;-0.03935431;50.39193;5.207176;9;9;0;-1.561417;-1.573735;-0.4957497;46246.92;5125870
3057.994;-0.4940355;-0.0406001;50.4141;5.209467;9;9;0;-1.556017;-1.56825;-0.4940355;46267.26;5128407
3064.994;-0.492214;-0.04164677;50.28762;5.196398;9;9;0;-1.55028;-1.562423;-0.492214;46151.2;5115839
3071.994;-0.4904998;-0.04302514;49.96752;5.163321;9;9;0;-1.544881;-1.556939;-0.4904998;45857.42;5083554
3078.994;-0.4887855;-0.04413918;49.88633;5.154931;9;9;0;-1.539482;-1.551455;-0.4887855;45782.91;5075572
3085.994;-0.4869641;-0.04520355;49.94421;5.160912;9;9;0;-1.533745;-1.545629;-0.4869641;45836.02;5081756
3092.994;-0.4852498;-0.04583676;50.28616;5.196247;9;9;0;-1.528346;-1.540145;-0.4852498;46149.85;5116830
3099.994;-0.4834819;-0.04656856;52.04767;5.37827;9;9;0;-1.522778;-1.534491;-0.4834819;47766.46;5296371
3106.994;-0.4817141;-0.04702312;51.5823;5.330182;9;9;0;-1.51721;-1.528837;-0.4817141;47339.38;5249312
3113.994;-0.4799998;-0.04766315;51.53544;5.325339;9;9;0;-1.51181;-1.523355;-0.4799998;47296.37;5244830
3120.994;-0.4782855;-0.04786995;51.12445;5.28287;9;9;0;-1.506411;-1.517873;-0.4782855;46919.19;5203289
3122.28;-0.4779641;-0.047949;51.02858;5.272964;9;9;0;-1.505399;-1.516845;-0.4779641;46831.2;5193584