File: Ensayos/Resistencia/comp/Clavo7/Clavo7f.raw
"Test Type";"Manual"
"Method Name:";"C:\INSTRON\USER\TEMPLATE\CYCLE.MTM"
"Name:";""
"Operator ID:";""
"Company:";""
"Lab name:";""
"Test date:";"14/06/2017"
"Temperature:";""
"Humidity:";""
"Note 1:";""
"Note 2:";""
"Note 3:";""
"Geometry:";"Rectangular"
"Specimen";1
"Specimen name:";""
"Width:";0.250000;"in"
"Thickness:";0.060000;"in"
"Length:";1.250000;"in"
"Diameter:";0.039370;"in"
"Inner diameter:";0.019685;"in"
"Outer diameter:";0.039370;"in"
"Wall thickness:";0.019685;"in"
"Area:";0.015000;"in*in"
"Linear density:";1.000000;"den"
"Sled weight:";2.204623;"lbf"
"Loading span:";0.000000;"mm"
"Support span:";1.000000;"mm"
"Span ratio:";"2"
"Fixture type:";"3-point"
"Comment:";""
"Included"
"Final Width:";0.250000;"in"
"Final Thickness:";0.060000;"in"
"Final Length:";1.250000;"in"
"Final Diameter:";0.039370;"in"
"Final Inner diameter:";0.019685;"in"
"Final Outer diameter:";0.039370;"in"
"Final Wall thickness:";0.019685;"in"
"Final Area:";0.015000;"in*in"
"Final Linear density:";1.000000;"den"
"Time sec";"Extension mm";"Strain 1 %";"Load N";"Stress MPa";"Cycle Count ";"Total Cycle Count ";"Repetitions Count ";"Strain [Exten.] %";"True strain %";"Corrected Position mm";"Tenacity gf/tex";"True stress Pa"
0;0;-0.0001553548;62.67166;6.476085;0;0;0;0;0;0;57516.58;6476085
6;0.00996428;-8.581985e-005;62.80897;6.490273;0;0;0;0.03138356;0.03137863;0.00996428;57642.6;6492311
12;0.01992856;-0.0003028425;62.87175;6.496761;0;0;0;0.06276712;0.06274743;0.01992856;57700.21;6500839
18;0.02994641;-0.0001111124;63.04644;6.514812;0;0;0;0.0943194;0.09427495;0.02994641;57860.53;6520957
24;0.03996426;-0.0003167025;63.1533;6.525854;0;0;0;0.1258717;0.1257925;0.03996426;57958.6;6534069
30;0.04998211;-0.0002429782;63.08259;6.518548;0;0;0;0.157424;0.1573002;0.04998211;57893.71;6528810
36;0.06771424;-0.0004640336;63.73316;6.585773;0;0;0;0.2132732;0.2130461;0.06771424;58490.77;6599819
42;0.08774995;-0.0005423975;64.12365;6.626123;0;0;0;0.2763778;0.2759966;0.08774995;58849.13;6644437
48;0.1077321;-0.0001956232;82.18423;8.492387;0;0;0;0.3393136;0.3387393;0.1077321;75424.13;8521203
54;0.1277678;-0.002360427;149.1623;15.41347;0;0;0;0.4024182;0.4016106;0.1277678;136892.9;1.547549e+007
60;0.1477499;-0.009268994;231.4785;23.91949;0;0;0;0.465354;0.4642746;0.1477499;212438.1;2.40308e+007
66;0.1676785;-0.01975742;323.3589;33.41382;0;0;0;0.5281212;0.5267315;0.1676785;296760.9;3.359029e+007
72;0.1875535;-0.03231149;422.8901;43.69873;0;0;0;0.5907195;0.5889816;0.1875535;388105.1;4.395687e+007
78;0.2075891;-0.0460836;526.5201;54.40718;0;0;0;0.6538241;0.6516959;0.2075891;483211;5.476291e+007
84.00001;0.2276248;-0.06053505;633.1263;65.42318;0;0;0;0.7169287;0.7143709;0.2276248;581048.2;6.589222e+007
90.00001;0.2477141;-0.07535789;741.9667;76.67005;0;0;0;0.7802019;0.7771741;0.2477141;680935.9;7.726823e+007
96.00001;0.2677498;-0.09116654;852.2641;88.06747;0;0;0;0.8433066;0.8397706;0.2677498;782160.8;8.881014e+007
102;0.287732;-0.1076456;963.0597;99.51637;0;0;0;0.9062424;0.9021607;0.287732;883842.8;1.004182e+008
108;0.3078212;-0.1249794;1068.984;110.4619;0;0;0;0.9695156;0.964846;0.3078212;981054.4;1.115329e+008
114;0.3277498;-0.139457;1154.343;119.2823;0;0;0;1.032283;1.026991;0.3277498;1059392;1.205136e+008
120;0.3476783;-0.1583276;1253.533;129.532;0;0;0;1.09505;1.089098;0.3476783;1150423;1.309504e+008
126;0.3675533;-0.1735253;1322.28;136.6359;0;0;0;1.157648;1.150999;0.3675533;1213516;1.382177e+008
132;0.3875355;-0.1825864;1354.096;139.9235;0;0;0;1.220584;1.213195;0.3875355;1242714;1.416314e+008
138;0.4075712;-0.1888415;1367.217;141.2794;0;0;0;1.283689;1.275519;0.4075712;1254757;1.43093e+008
144;0.4276069;-0.1959355;1384.164;143.0306;0;0;0;1.346793;1.337805;0.4276069;1270309;1.449569e+008
150;0.4476961;-0.2031946;1397.021;144.3592;0;0;0;1.410067;1.400218;0.4476961;1282109;1.463947e+008
156;0.4676247;-0.21203;1417.104;146.4344;0;0;0;1.472834;1.462093;0.4676247;1300539;1.485911e+008
162;0.4876604;-0.2215424;1438.133;148.6074;0;0;0;1.535938;1.524262;0.4876604;1319839;1.508899e+008
168;0.5076425;-0.2305121;1455.11;150.3616;0;0;0;1.598874;1.586227;0.5076425;1335419;1.527657e+008
174;0.5276246;-0.2405602;1476.081;152.5287;0;0;0;1.66181;1.648153;0.5276246;1354665;1.550634e+008
180;0.547714;-0.2510842;1498.272;154.8217;0;0;0;1.725083;1.710373;0.547714;1375031;1.574925e+008
186;0.5676961;-0.2572429;1499.457;154.9442;0;0;0;1.788019;1.772222;0.5676961;1376119;1.577146e+008
192;0.5877318;-0.2673131;1517.736;156.833;0;0;0;1.851124;1.834199;0.5877318;1392894;1.597362e+008
198;0.6077675;-0.2787939;1541.104;159.2477;0;0;0;1.914228;1.896138;0.6077675;1414340;1.622961e+008
204;0.6277496;-0.2857069;1544.6;159.609;0;0;0;1.977164;1.957872;0.6277496;1417548;1.627647e+008
210;0.6477853;-0.2954584;1561.627;161.3684;0;0;0;2.040269;2.019734;0.6477853;1433174;1.646608e+008
216;0.6676603;-0.3046248;1569.947;162.2282;0;0;0;2.102867;2.081062;0.6676603;1440811;1.656396e+008
222;0.6875888;-0.3162901;1591.787;164.485;0;0;0;2.165634;2.142517;0.6875888;1460854;1.680471e+008
228;0.7075709;-0.326455;1603.896;165.7362;0;0;0;2.22857;2.2041;0.7075709;1471967;1.694298e+008
234;0.7288924;-0.3399628;1624.224;167.8368;0;0;0;2.295724;2.269769;0.7288924;1490623;1.716899e+008
240;0.7587852;-0.3619786;1657.237;171.2482;0;0;0;2.389874;2.361764;0.7587852;1520921;1.753408e+008
246;0.7888387;-0.3824177;1677.364;173.328;0;0;0;2.484531;2.454169;0.7888387;1539392;1.776344e+008
252;0.8189459;-0.409163;1707.279;176.4192;0;0;0;2.579357;2.546653;0.8189459;1566846;1.809697e+008
258;0.8489995;-0.4302111;1727.059;178.4632;0;0;0;2.674014;2.638887;0.8489995;1584999;1.832353e+008
264;0.8789994;-0.4543889;1746.857;180.5089;0;0;0;2.768502;2.730872;0.8789994;1603168;1.855063e+008
270;0.9088387;-0.48986;1773.344;183.2459;0;0;0;2.862484;2.822281;0.9088387;1627477;1.884913e+008
274.654;0.9119994;-0.480845;1704.277;176.109;0;0;0;2.872439;2.831958;0.9119994;1564091;1.811676e+008
280.654;0.8821065;-0.4372659;1545.811;159.7342;0;0;0;2.778288;2.740394;0.8821065;1418660;1.64172e+008
286.654;0.8522137;-0.4168413;1501.091;155.1131;0;0;0;2.684138;2.648747;0.8522137;1377618;1.592765e+008
292.654;0.8222138;-0.3897517;1461.117;150.9824;0;0;0;2.58965;2.556686;0.8222138;1340933;1.548924e+008
298.654;0.7922138;-0.3657911;1425.106;147.2612;0;0;0;2.495162;2.464541;0.7922138;1307883;1.509356e+008
304.654;0.7622138;-0.3382285;1380.307;142.632;0;0;0;2.400673;2.37231;0.7622138;1266770;1.460562e+008
310.654;0.7322138;-0.3149205;1341.093;138.5798;0;0;0;2.306185;2.279995;0.7322138;1230781;1.417758e+008
316.654;0.7022674;-0.2955686;1309.004;135.264;0;0;0;2.211866;2.187759;0.7022674;1201331;1.382558e+008
322.654;0.6722139;-0.2786914;1281.79;132.452;0;0;0;2.117209;2.095108;0.6722139;1176356;1.352562e+008
328.654;0.6421603;-0.2633415;1258.451;130.0402;0;0;0;2.022552;2.00237;0.6421603;1154937;1.326704e+008
334.654;0.6120531;-0.2484912;1237.27;127.8515;0;0;0;1.927726;1.909381;0.6120531;1135498;1.303161e+008
340.654;0.5820532;-0.2325409;1212.669;125.3094;0;0;0;1.833238;1.816637;0.5820532;1112921;1.276066e+008
346.654;0.5521604;-0.2177516;1191.263;123.0974;0;0;0;1.739088;1.724139;0.5521604;1093275;1.252382e+008
352.654;0.5222139;-0.2024839;1166.372;120.5253;0;0;0;1.644768;1.631388;0.5222139;1070431;1.225077e+008
358.654;0.4921604;-0.1887124;1143.983;118.2118;0;0;0;1.550112;1.53822;0.4921604;1049884;1.200442e+008
364.654;0.4621068;-0.1745807;1118.4;115.5682;0;0;0;1.455455;1.444965;0.4621068;1026405;1.172502e+008
370.654;0.4320533;-0.160717;1088.663;112.4954;0;0;0;1.360798;1.351622;0.4320533;999114.6;1.140262e+008
376.654;0.4020533;-0.1460183;1044.209;107.9018;0;0;0;1.26631;1.258359;0.4020533;958317.2;1.092682e+008
382.654;0.3721605;-0.1268362;972.838;100.5268;0;0;0;1.172159;1.165342;0.3721605;892816.8;1.017051e+008
388.654;0.3422676;-0.09734087;851.2151;87.95907;0;0;0;1.078008;1.072239;0.3422676;781198;8.890727e+007
394.654;0.3122677;-0.06587834;693.5764;71.6697;0;0;0;0.9835202;0.9787151;0.3122677;636526;7.237459e+007
400.654;0.2822141;-0.04261024;536.4387;55.43211;0;0;0;0.8888633;0.8849362;0.2822141;492313.7;5.592482e+007
406.654;0.2521605;-0.02364681;398.4699;41.17531;0;0;0;0.7942064;0.7910692;0.2521605;365693.6;4.150232e+007
412.654;0.2222141;-0.009928421;278.4574;28.77399;0;0;0;0.6998871;0.6974492;0.2222141;255552.8;2.897538e+007
418.654;0.1922677;-0.003160255;178.3836;18.43301;0;0;0;0.6055676;0.6037414;0.1922677;163710.6;1.854464e+007
424.654;0.1622678;-0.001745693;103.8449;10.73066;0;0;0;0.5110795;0.509778;0.1622678;95303.05;1.07855e+007
430.654;0.1321071;-0.002574063;62.83517;6.49298;0;0;0;0.4160852;0.415222;0.1321071;57666.64;6519997
434.884;0.1509642;-0.002548203;99.57772;10.28972;1;1;0;0.4754778;0.4743509;0.1509642;91386.91;1.033864e+007
440.884;0.1809642;-0.004573721;195.3099;20.18207;1;1;0;0.5699658;0.5683477;0.1809642;179244.6;2.02971e+007
446.884;0.2110713;-0.01357116;323.4542;33.42367;1;1;0;0.6647915;0.6625915;0.2110713;296848.3;3.364587e+007
452.884;0.2410713;-0.03074367;473.8058;48.96003;1;1;0;0.7592796;0.7564116;0.2410713;434832.7;4.933177e+007
458.884;0.2710712;-0.05316679;641.13;66.25024;1;1;0;0.8537677;0.8501437;0.2710712;588393.6;6.681586e+007
464.884;0.3011248;-0.07782754;820.7338;84.80933;1;1;0;0.9484246;0.9439553;0.3011248;753224.1;8.561368e+007
470.884;0.3310177;-0.1054766;1001.087;103.4458;1;1;0;1.042575;1.037178;0.3310177;918741.9;1.045243e+008
476.884;0.3609105;-0.1350691;1165.265;120.4109;1;1;0;1.136726;1.130314;0.3609105;1069416;1.217797e+008
482.884;0.390964;-0.1563189;1262.313;130.4393;1;1;0;1.231383;1.223863;0.390964;1158481;1.320455e+008
488.884;0.4210712;-0.1686508;1296.422;133.9639;1;1;0;1.326208;1.317491;0.4210712;1189785;1.357406e+008
494.884;0.4511783;-0.179323;1311.107;135.4813;1;1;0;1.421034;1.411032;0.4511783;1203262;1.374066e+008
500.884;0.4811247;-0.1951197;1350.804;139.5834;1;1;0;1.515353;1.503986;0.4811247;1239693;1.416986e+008
506.884;0.510964;-0.2074297;1368.454;141.4072;1;1;0;1.609335;1.596523;0.510964;1255891;1.436829e+008
512.884;0.5408568;-0.2240355;1405.624;145.2481;1;1;0;1.703486;1.689139;0.5408568;1290004;1.477224e+008
518.884;0.5709103;-0.2406575;1438.102;148.6042;1;1;0;1.798143;1.782167;0.5709103;1319810;1.512763e+008
524.8841;0.6010175;-0.2548771;1459.603;150.826;1;1;0;1.892968;1.875275;0.6010175;1339543;1.53681e+008
530.8841;0.6310174;-0.2726952;1488.995;153.8631;1;1;0;1.987456;1.967964;0.6310174;1366517;1.569211e+008
536.8841;0.6609639;-0.2873198;1508.756;155.9051;1;1;0;2.081776;2.060403;0.6609639;1384653;1.591507e+008
542.8841;0.6909639;-0.3038561;1533.039;158.4144;1;1;0;2.176264;2.152922;0.6909639;1406938;1.618619e+008
548.8841;0.7210174;-0.3237635;1562.475;161.456;1;1;0;2.270921;2.245519;0.7210174;1433953;1.651226e+008
554.8841;0.7510709;-0.3435525;1587.688;164.0615;1;1;0;2.365578;2.338031;0.7510709;1457093;1.679425e+008
560.8841;0.7810709;-0.3714869;1624.264;167.841;1;1;0;2.460066;2.430294;0.7810709;1490660;1.7197e+008
566.8841;0.8111245;-0.3940432;1644.119;169.8926;1;1;0;2.554723;2.522635;0.8111245;1508881;1.742329e+008
572.8841;0.8409638;-0.4282226;1673.826;172.9624;1;1;0;2.648705;2.614234;0.8409638;1536145;1.775436e+008
578.8841;0.8709637;-0.4492444;1687.736;174.3997;1;1;0;2.743193;2.706241;0.8709637;1548910;1.791838e+008
584.8841;0.9010173;-0.4861623;1715.517;177.2705;1;1;0;2.83785;2.798329;0.9010173;1574407;1.823011e+008
590.8841;0.9311244;-0.5263026;1743.284;180.1398;1;1;0;2.932675;2.890495;0.9311244;1599890;1.854227e+008
596.8841;0.9611779;-0.5705995;1762.71;182.1471;1;1;0;3.027332;2.982413;0.9611779;1617718;1.876613e+008
602.8841;0.9910708;-0.6103981;1782.95;184.2386;1;1;0;3.121483;3.073755;0.9910708;1636293;1.899895e+008
608.8841;1.02091;-0.690026;1810.77;187.1133;1;1;0;3.215465;3.164851;1.02091;1661824;1.931298e+008
614.8841;1.05091;-0.7587959;1828.741;188.9703;1;1;0;3.309953;3.256353;1.05091;1678317;1.952251e+008
620.8841;1.080964;-0.9248514;1858.656;192.0615;1;1;0;3.40461;3.347936;1.080964;1705771;1.986004e+008
626.348;1.108392;-1.062308;1880.541;194.323;1;1;0;3.490999;3.431446;1.108392;1725856;2.011068e+008
631.3501;1.083428;-0.9535712;1717.049;177.4288;1;1;0;3.412371;3.355441;1.083428;1575813;1.834833e+008
637.3501;1.053428;-0.776218;1592.241;164.5319;1;1;0;3.317883;3.264029;1.053428;1461271;1.699909e+008
643.3501;1.023321;-0.7212427;1558.007;160.9943;1;1;0;3.223058;3.172207;1.023321;1429852;1.661833e+008
649.3501;0.9932136;-0.6789944;1525.392;157.6242;1;1;0;3.128232;3.0803;0.9932136;1399920;1.62555e+008
655.3501;0.9632672;-0.6302989;1486.403;153.5953;1;1;0;3.033912;2.988799;0.9632672;1364139;1.582553e+008
661.3501;0.9333744;-0.5831326;1452.033;150.0437;1;1;0;2.939762;2.897379;0.9333744;1332595;1.544546e+008
667.3501;0.903428;-0.544021;1421.42;146.8804;1;1;0;2.845443;2.805712;0.903428;1304501;1.510598e+008
673.3501;0.8734281;-0.5011254;1388.535;143.4822;1;1;0;2.750955;2.713796;0.8734281;1274321;1.474294e+008
679.3501;0.8433744;-0.4626472;1360.556;140.591;1;1;0;2.656297;2.62163;0.8433744;1248643;1.443255e+008
685.3501;0.8133745;-0.4224939;1329.898;137.4231;1;1;0;2.56181;2.529545;0.8133745;1220507;1.409436e+008
691.3501;0.7833745;-0.3865237;1297.834;134.1098;1;1;0;2.467321;2.437374;0.7833745;1191080;1.374187e+008
697.3501;0.753428;-0.3534837;1261.895;130.3961;1;1;0;2.373002;2.345284;0.753428;1158097;1.334904e+008
703.3501;0.7234281;-0.3287005;1232.064;127.3135;1;1;0;2.278514;2.252943;0.7234281;1130720;1.302144e+008
709.3501;0.693321;-0.3081208;1207.133;124.7373;1;1;0;2.183688;2.160187;0.693321;1107840;1.274612e+008
715.3501;0.6632138;-0.2891235;1184.418;122.3901;1;1;0;2.088862;2.067345;0.6632138;1086993;1.249466e+008
721.3501;0.6332674;-0.2711553;1163.249;120.2026;1;1;0;1.994543;1.974913;0.6332674;1067565;1.226001e+008
727.3501;0.6033746;-0.2541035;1143.3;118.1412;1;1;0;1.900393;1.882561;0.6033746;1049257;1.203864e+008
733.3501;0.5734282;-0.2357779;1116.497;115.3716;1;1;0;1.806073;1.789957;0.5734282;1024659;1.174553e+008
739.3501;0.5433211;-0.2186346;1092.249;112.8659;1;1;0;1.711247;1.696771;0.5433211;1002405;1.147974e+008
745.3501;0.5132676;-0.2021805;1067.406;110.2989;1;1;0;1.616591;1.603663;0.5132676;979606.4;1.12082e+008
751.3501;0.483214;-0.18602;1036.244;107.0787;1;1;0;1.521934;1.510469;0.483214;951006.9;1.087084e+008
757.3501;0.4532676;-0.168908;996.0189;102.9222;1;1;0;1.427614;1.41752;0.4532676;914090.9;1.043915e+008
763.3501;0.4233747;-0.1522955;959.8421;99.18388;1;1;0;1.333464;1.324651;0.4233747;880889.9;1.005065e+008
769.3501;0.3908569;-0.1306608;909.9216;94.02542;1;1;0;1.231045;1.22353;0.3908569;835075.7;9.518292e+007
775.3501;0.3507855;-0.09977574;823.2003;85.06421;1;1;0;1.104836;1.098777;0.3507855;755487.7;8.600403e+007
781.3501;0.3109283;-0.05897726;645.5927;66.71138;1;1;0;0.9793019;0.9745378;0.3109283;592489.3;6.736469e+007
787.3501;0.2709641;-0.03015096;447.0406;46.19429;1;1;0;0.8534303;0.8498092;0.2709641;410269.1;4.658853e+007
793.3501;0.2601427;-0.0245024;402.9459;41.63783;1;1;0;0.819347;0.8160086;0.2601427;369801.5;4.197899e+007
799.3501;0.2301427;-0.01138693;279.6899;28.90135;1;1;0;0.7248589;0.7222444;0.2301427;256683.9;2.911085e+007
805.3501;0.2001427;-0.004355857;180.3789;18.63919;1;1;0;0.6303708;0.6283923;0.2001427;165541.7;1.875668e+007
811.3501;0.1701428;-0.002935265;106.6584;11.02139;1;1;0;0.5358827;0.534452;0.1701428;97885.15;1.108045e+007
817.3501;0.1400892;-0.00414179;62.59955;6.468633;1;1;0;0.4412258;0.4402553;0.1400892;57450.39;6497174
822.9101;0.1121785;-0.004300789;62.3405;6.441864;1;1;0;0.3533181;0.3526954;0.1121785;57212.65;6464624
827.9121;0.1373035;-0.004380915;64.03685;6.617154;2;2;0;0.4324519;0.4315195;0.1373035;58769.47;6645770
833.9121;0.1672499;-0.004860905;131.5022;13.58859;2;2;0;0.5267713;0.5253887;0.1672499;120685.5;1.366017e+007
839.9121;0.1972499;-0.00810816;235.4193;24.32671;2;2;0;0.6212594;0.6193376;0.1972499;216054.8;2.447784e+007
845.9121;0.2273034;-0.01874444;367.9347;38.02;2;2;0;0.7159163;0.7133658;0.2273034;337670.1;3.829219e+007
851.9121;0.2574106;-0.03642733;520.5494;53.79021;2;2;0;0.8107419;0.8074731;0.2574106;477731.4;5.422631e+007
857.9121;0.287357;-0.05902072;690.296;71.33073;2;2;0;0.9050613;0.9009902;0.287357;633515.4;7.197632e+007
863.9121;0.3172498;-0.0847697;871.0902;90.01284;2;2;0;0.999212;0.9942528;0.3172498;799438.4;9.091226e+007
869.9121;0.3471426;-0.114122;1042.803;107.7566;2;2;0;1.093363;1.087429;0.3471426;957027.2;1.089347e+008
875.9121;0.3771962;-0.1426;1184.298;122.3777;2;2;0;1.18802;1.181018;0.3771962;1086883;1.238315e+008
881.9121;0.4072498;-0.1550652;1225.831;126.6695;2;2;0;1.282676;1.27452;0.4072498;1125000;1.282942e+008
887.9121;0.4372497;-0.1664173;1251.391;129.3107;2;2;0;1.377164;1.367768;0.4372497;1148458;1.310915e+008
893.9121;0.4673033;-0.1788893;1270.401;131.2751;2;2;0;1.471821;1.461095;0.4673033;1165904;1.332072e+008
899.9121;0.4972497;-0.1930114;1297.703;134.0963;2;2;0;1.566141;1.554003;0.4972497;1190960;1.361964e+008
905.9121;0.5272496;-0.209466;1330.47;137.4822;2;2;0;1.660629;1.646991;0.5272496;1221032;1.397653e+008
911.9121;0.5573568;-0.2238942;1354.18;139.9322;2;2;0;1.755454;1.740224;0.5573568;1242791;1.423887e+008
917.9121;0.5874104;-0.2404201;1385.126;143.13;2;2;0;1.850111;1.833205;0.5874104;1271192;1.457781e+008
923.9121;0.6173567;-0.2587148;1418.025;146.5296;2;2;0;1.944431;1.925768;0.6173567;1301385;1.493788e+008
929.9121;0.6473032;-0.2707492;1427.726;147.532;2;2;0;2.03875;2.018246;0.6473032;1310288;1.505398e+008
935.9121;0.677196;-0.2894939;1459.947;150.8615;2;2;0;2.132901;2.110473;0.677196;1339858;1.540792e+008
941.9121;0.7072496;-0.3097401;1489.564;153.9219;2;2;0;2.227558;2.20311;0.7072496;1367039;1.573506e+008
947.9121;0.7373566;-0.3294765;1511.18;156.1555;2;2;0;2.322383;2.295826;0.7373566;1386877;1.597821e+008
953.9121;0.7674102;-0.3528697;1539.679;159.1005;2;2;0;2.41704;2.388292;0.7674102;1413032;1.62946e+008
959.9121;0.7973566;-0.3869496;1574.906;162.7406;2;2;0;2.511359;2.480343;0.7973566;1445361;1.668276e+008
965.9121;0.8272495;-0.4161869;1590.772;164.3801;2;2;0;2.60551;2.572145;0.8272495;1459923;1.686631e+008
971.9121;0.8571959;-0.4528554;1620.88;167.4912;2;2;0;2.69983;2.664027;0.8571959;1487554;1.720132e+008
977.9121;0.8871959;-0.4862522;1641.082;169.5788;2;2;0;2.794318;2.755989;0.8871959;1506094;1.743174e+008
983.9121;0.9172494;-0.5351203;1674.686;173.0512;2;2;0;2.888974;2.84803;0.9172494;1536934;1.780506e+008
989.9121;0.947303;-0.5784067;1699.823;175.6487;2;2;0;2.983631;2.939987;0.947303;1560003;1.808894e+008
995.9121;0.9772494;-0.6387065;1723.236;178.0681;2;2;0;3.077951;3.031532;0.9772494;1581491;1.83549e+008
1001.912;1.007249;-0.6823447;1747.115;180.5355;2;2;0;3.172439;3.123156;1.007249;1603405;1.862629e+008
1007.912;1.037303;-0.7829542;1778.785;183.8081;2;2;0;3.267096;3.214861;1.037303;1632470;1.898133e+008
1013.912;1.067356;-0.8969659;1798.491;185.8444;2;2;0;3.361753;3.306481;1.067356;1650555;1.92092e+008
1019.912;1.097356;-1.072614;1828.833;188.9798;2;2;0;3.456241;3.397854;1.097356;1678402;1.955114e+008
1025.912;1.127356;-1.212763;1848.982;191.0619;2;2;0;3.550729;3.489144;1.127356;1696893;1.97846e+008
1031.912;1.157249;-1.331922;1863.706;192.5833;2;2;0;3.644879;3.580025;1.157249;1710406;1.996028e+008
1037.912;1.187196;-1.469911;1885.119;194.796;2;2;0;3.739199;3.670986;1.187196;1730057;2.020798e+008
1043.912;1.217303;-1.637291;1908.256;197.1869;2;2;0;3.834024;3.762352;1.217303;1751292;2.047471e+008
1049.912;1.24741;-1.814783;1925.801;198.9999;2;2;0;3.92885;3.853635;1.24741;1767394;2.068183e+008
1055.912;1.27741;-1.983368;1963.64;202.9099;2;2;0;4.023338;3.944509;1.27741;1802120;2.110737e+008
1060.378;1.259571;-1.876662;1853.867;191.5667;2;2;0;3.967151;3.890481;1.259571;1701377;1.991664e+008
1066.378;1.229624;-1.673622;1789.423;184.9075;2;2;0;3.872832;3.79972;1.229624;1642234;1.920686e+008
1072.378;1.199678;-1.524421;1739.696;179.769;2;2;0;3.778513;3.708876;1.199678;1596597;1.865615e+008
1078.378;1.169678;-1.428359;1691.842;174.8241;2;2;0;3.684025;3.617786;1.169678;1552679;1.812646e+008
1084.378;1.139624;-1.305572;1640.476;169.5162;2;2;0;3.589368;3.526451;1.139624;1505538;1.756007e+008
1090.378;1.109624;-1.111287;1584.419;163.7236;2;2;0;3.49488;3.435195;1.109624;1454092;1.694456e+008
1096.378;1.079678;-1.062166;1582.733;163.5494;2;2;0;3.40056;3.344019;1.079678;1452545;1.69111e+008
1102.378;1.049678;-0.9791277;1560.881;161.2914;2;2;0;3.306072;3.252597;1.049678;1432490;1.666238e+008
1108.378;1.019624;-0.8950894;1542.77;159.4199;2;2;0;3.211415;3.160927;1.019624;1415869;1.645395e+008
1114.378;0.9895708;-0.8010301;1526.969;157.7871;2;2;0;3.116758;3.069174;0.9895708;1401367;1.627049e+008
1120.378;0.9595172;-0.7246724;1515.802;156.6332;2;2;0;3.022101;2.977336;0.9595172;1391119;1.613668e+008
1126.378;0.9295708;-0.6621928;1509.27;155.9583;2;2;0;2.927782;2.885741;0.9295708;1385125;1.605244e+008
1132.378;0.899678;-0.5891641;1474.487;152.364;2;2;0;2.833632;2.794227;0.899678;1353202;1.566814e+008
1138.378;0.869678;-0.5248818;1434.328;148.2142;2;2;0;2.739143;2.7023;0.869678;1316347;1.52274e+008
1144.378;0.8396245;-0.4663833;1417.589;146.4845;2;2;0;2.644487;2.610124;0.8396245;1300985;1.503583e+008
1150.378;0.8095173;-0.4276415;1405.921;145.2788;2;2;0;2.549661;2.517699;0.8095173;1290277;1.489829e+008
1156.378;0.7795174;-0.3978836;1395.035;144.1539;2;2;0;2.455173;2.425518;0.7795174;1280286;1.476931e+008
1162.378;0.7496245;-0.3746367;1382.996;142.9099;2;2;0;2.361022;2.333581;0.7496245;1269237;1.46284e+008
1168.378;0.7196781;-0.3521977;1359.789;140.5118;2;2;0;2.266703;2.241395;0.7196781;1247939;1.436968e+008
1174.378;0.6897318;-0.3321616;1341.021;138.5724;2;2;0;2.172384;2.149123;0.6897318;1230715;1.415828e+008
1180.378;0.6596246;-0.3132386;1326.725;137.0952;2;2;0;2.077558;2.056271;0.6596246;1217594;1.399434e+008
1186.378;0.6296246;-0.2947242;1314.238;135.8049;2;2;0;1.983069;1.963663;0.6296246;1206135;1.38498e+008
1192.378;0.5996246;-0.2764046;1301.126;134.45;2;2;0;1.888581;1.870969;0.5996246;1194101;1.369892e+008
1198.378;0.5697317;-0.2565582;1277.323;131.9903;2;2;0;1.794431;1.778521;0.5697317;1172256;1.343588e+008
1204.378;0.5396782;-0.2349339;1247.365;128.8946;2;2;0;1.699774;1.685489;0.5396782;1144762;1.310855e+008
1210.378;0.5095711;-0.2136996;1218.041;125.8645;2;2;0;1.604948;1.592205;0.5095711;1117851;1.278846e+008
1216.378;0.4795175;-0.1947631;1201.491;124.1543;2;2;0;1.510291;1.499;0.4795175;1102662;1.260294e+008
1222.378;0.4495176;-0.176833;1179.127;121.8434;2;2;0;1.415803;1.405874;0.4495176;1082138;1.235685e+008
1228.378;0.4196247;-0.1572593;1146.821;118.5051;2;2;0;1.321653;1.312995;0.4196247;1052489;1.200713e+008
1234.378;0.3896783;-0.1315749;1080.295;111.6307;2;2;0;1.227333;1.219863;0.3896783;991434.9;1.130008e+008
1240.378;0.3596783;-0.09491456;934.7656;96.59264;2;2;0;1.132845;1.126477;0.3596783;857876.1;9.768688e+007
1246.378;0.3295712;-0.06399249;758.0539;78.33239;2;2;0;1.03802;1.032669;0.3295712;695699.9;7.91455e+007
1252.378;0.2994641;-0.03943771;594.0045;61.38058;2;2;0;0.943194;0.9387737;0.2994641;545144.4;6.195952e+007
1258.378;0.2695713;-0.01980963;449.7108;46.4702;2;2;0;0.8490434;0.8454593;0.2695713;412719.6;4.686476e+007
1264.378;0.2396249;-0.005170055;321.7251;33.245;2;2;0;0.754724;0.7518902;0.2396249;295261.5;3.34959e+007
1270.378;0.2096784;0.004405547;216.1311;22.3336;2;2;0;0.6604045;0.6582334;0.2096784;198353.2;2.248109e+007
1276.378;0.1796785;0.007408039;133.7453;13.82038;2;2;0;0.5659164;0.5643211;0.1796785;122744;1.389859e+007
1282.378;0.1496249;0.006863152;74.39046;7.687029;2;2;0;0.4712595;0.4701526;0.1496249;68271.45;7723255
1288.378;0.1196785;0.006267485;62.23493;6.430955;2;2;0;0.3769402;0.3762315;0.1196785;57115.77;6455196
1292.874;0.1371428;0.006634952;65.96786;6.816692;3;3;0;0.4319457;0.4310155;0.1371428;60541.64;6846136
1298.874;0.1670892;0.006306854;139.0469;14.36821;3;3;0;0.5262651;0.5248852;0.1670892;127609.5;1.444382e+007
1304.874;0.1971427;0.002567118;244.4595;25.26086;3;3;0;0.620922;0.6190022;0.1971427;224351.4;2.541771e+007
1310.874;0.2271963;-0.007940235;379.3295;39.19746;3;3;0;0.7155789;0.7130307;0.2271963;348127.6;3.947795e+007
1316.874;0.2573034;-0.02577049;533.9393;55.17384;3;3;0;0.8104044;0.8071382;0.2573034;490019.9;5.562097e+007
1322.874;0.2871963;-0.04840862;705.2698;72.87802;3;3;0;0.9045551;0.9004885;0.2871963;647257.5;7.353724e+007
1328.874;0.3170891;-0.07428302;892.9169;92.26826;3;3;0;0.9987057;0.9937516;0.3170891;819469.7;9.318976e+007
1334.874;0.3470355;-0.1023023;1091.42;112.7803;3;3;0;1.093025;1.087095;0.3470355;1001645;1.14013e+008
1340.874;0.3770355;-0.1319355;1289.624;133.2615;3;3;0;1.187513;1.180518;0.3770355;1183546;1.34844e+008
1346.874;0.4071426;-0.1642208;1469.315;151.8295;3;3;0;1.282339;1.274186;0.4071426;1348456;1.537765e+008
1352.874;0.4371426;-0.1945513;1613.239;166.7017;3;3;0;1.376827;1.367435;0.4371426;1480541;1.689969e+008
1358.874;0.467089;-0.2113753;1669.037;172.4675;3;3;0;1.471146;1.46043;0.467089;1531750;1.750047e+008
1364.874;0.4970889;-0.2236715;1702.163;175.8905;3;3;0;1.565634;1.553505;0.4970889;1562151;1.786443e+008
1370.874;0.5271425;-0.2370074;1733.108;179.0882;3;3;0;1.660291;1.646659;0.5271425;1590551;1.820616e+008
1376.874;0.557196;-0.2501998;1745.805;180.4002;3;3;0;1.754948;1.739727;0.557196;1602203;1.835661e+008
1382.874;0.5872496;-0.257108;1691.85;174.8249;3;3;0;1.849605;1.832708;0.5872496;1552687;1.780585e+008
1388.874;0.617196;-0.2690941;1677.095;173.3001;3;3;0;1.943924;1.925271;0.617196;1539145;1.76669e+008
1394.874;0.6470888;-0.2822772;1670.006;172.5676;3;3;0;2.038075;2.017584;0.6470888;1532639;1.760847e+008
1400.874;0.6770888;-0.2986197;1673.888;172.9688;3;3;0;2.132563;2.110142;0.6770888;1536202;1.766575e+008
1406.874;0.7071424;-0.3118579;1665.747;172.1275;3;3;0;2.22722;2.20278;0.7071424;1528730;1.759612e+008
1412.874;0.737196;-0.3290946;1672.52;172.8274;3;3;0;2.321877;2.295332;0.737196;1534946;1.768403e+008
1418.874;0.7672494;-0.3469265;1680.665;173.669;3;3;0;2.416534;2.387798;0.7672494;1542421;1.778658e+008
1424.874;0.7971423;-0.3745462;1702.217;175.8961;3;3;0;2.510684;2.479685;0.7971423;1562200;1.803123e+008
1430.874;0.8270352;-0.39807;1708.276;176.5222;3;3;0;2.604835;2.571487;0.8270352;1567761;1.811203e+008
1436.874;0.8570352;-0.4340967;1725.241;178.2753;3;3;0;2.699323;2.663534;0.8570352;1583331;1.830875e+008
1442.874;0.8870888;-0.4579132;1728.247;178.5859;3;3;0;2.79398;2.755661;0.8870888;1586090;1.835756e+008
1448.874;0.9171423;-0.5010776;1748.775;180.7071;3;3;0;2.888637;2.847703;0.9171423;1604929;1.859271e+008
1454.874;0.9471423;-0.5475374;1764.399;182.3216;3;3;0;2.983125;2.939496;0.9471423;1619267;1.877604e+008
1460.874;0.9770886;-0.6045371;1795.657;185.5516;3;3;0;3.077444;3.031041;0.9770886;1647954;1.912618e+008
1466.874;1.007142;-0.6476919;1804.03;186.4168;3;3;0;3.172101;3.122829;1.007142;1655639;1.923301e+008
1472.874;1.037142;-0.729797;1827.811;188.8742;3;3;0;3.266589;3.214371;1.037142;1677464;1.95044e+008
1478.874;1.067249;-0.8500825;1846.656;190.8215;3;3;0;3.361415;3.306155;1.067249;1694759;1.972358e+008
1484.874;1.097249;-1.013079;1866.501;192.8721;3;3;0;3.455903;3.397528;1.097249;1712971;1.995376e+008
1490.874;1.127142;-1.155027;1897.431;196.0683;3;3;0;3.550054;3.488492;1.127142;1741357;2.030288e+008
1496.874;1.157089;-1.242262;1945.281;201.0128;3;3;0;3.644373;3.579537;1.157089;1785271;2.083384e+008
1502.874;1.187089;-1.357445;2001.057;206.7763;3;3;0;3.738862;3.670661;1.187089;1836459;2.145074e+008
1508.874;1.217142;-1.465894;2041.426;210.9477;3;3;0;3.833519;3.761865;1.217142;1873507;2.190345e+008
1514.874;1.247249;-1.699735;2008.14;207.5082;3;3;0;3.928344;3.853147;1.247249;1842960;2.156598e+008
1520.874;1.277249;-1.887549;1993.664;206.0123;3;3;0;4.022832;3.944023;1.277249;1829674;2.142998e+008
1526.874;1.307142;-2.048369;1982.75;204.8846;3;3;0;4.116982;4.034491;1.307142;1819658;2.133197e+008
1532.874;1.337035;-2.29466;1984.292;205.044;3;3;0;4.211133;4.124878;1.337035;1821074;2.136786e+008
1538.874;1.367035;-2.521354;2006.533;207.3422;3;3;0;4.305622;4.215507;1.367035;1841485;2.162695e+008
1544.874;1.397088;-2.738826;2022.528;208.995;3;3;0;4.400278;4.306215;1.397088;1856164;2.181913e+008
1550.874;1.427142;-2.944914;2039.1;210.7074;3;3;0;4.494936;4.396842;1.427142;1871373;2.201785e+008
1556.874;1.457088;-3.143208;2062.534;213.129;3;3;0;4.589255;4.487063;1.457088;1892880;2.2291e+008
1562.874;1.487142;-3.339982;2080.221;214.9566;3;3;0;4.683911;4.577526;1.487142;1909112;2.25025e+008
1568.874;1.517088;-3.537612;2100.193;217.0203;3;3;0;4.778231;4.667585;1.517088;1927441;2.273901e+008
1574.874;1.547195;-3.729769;2123.069;219.3842;3;3;0;4.873056;4.758045;1.547195;1948435;2.30075e+008
1580.874;1.577249;-3.91731;2145.404;221.6922;3;3;0;4.967713;4.848262;1.577249;1968933;2.327053e+008
1585.134;1.588553;-4.003206;2120.491;219.1178;3;3;0;5.003315;4.882174;1.588553;1946069;2.30081e+008
1591.134;1.558446;-3.850677;1974.441;204.026;3;3;0;4.90849;4.791826;1.558446;1812033;2.140406e+008
1597.134;1.528499;-3.677174;1886.007;194.8878;3;3;0;4.81417;4.701879;1.528499;1730873;2.0427e+008
1603.134;1.498553;-3.491578;1832.926;189.4027;3;3;0;4.719851;4.611851;1.498553;1682158;1.983422e+008
1609.134;1.468499;-3.303521;1785.285;184.4799;3;3;0;4.625194;4.521419;1.468499;1638436;1.930124e+008
1615.134;1.438392;-3.111947;1736.98;179.4883;3;3;0;4.530368;4.430745;1.438392;1594104;1.876198e+008
1621.134;1.408338;-2.912538;1701.352;175.8068;3;3;0;4.435711;4.34015;1.408338;1561407;1.836051e+008
1627.134;1.378392;-2.707691;1672.613;172.837;3;3;0;4.341392;4.249796;1.378392;1535031;1.803405e+008
1633.134;1.348499;-2.504649;1636.11;169.065;3;3;0;4.247241;4.159521;1.348499;1501531;1.762456e+008
1639.134;1.318499;-2.300328;1599.95;165.3285;3;3;0;4.152753;4.068842;1.318499;1468346;1.721942e+008
1645.134;1.288445;-2.09321;1568.653;162.0945;3;3;0;4.058096;3.977917;1.288445;1439623;1.686724e+008
1651.134;1.258338;-1.941709;1537.825;158.9089;3;3;0;3.963271;3.886748;1.258338;1411331;1.652069e+008
1657.134;1.228285;-1.826495;1507.997;155.8266;3;3;0;3.868614;3.795658;1.228285;1383956;1.61855e+008
1663.134;1.198392;-1.711137;1465.727;151.4588;3;3;0;3.774463;3.704974;1.198392;1345163;1.571755e+008
1669.134;1.168499;-1.580076;1416.923;146.4156;3;3;0;3.680312;3.614206;1.168499;1300373;1.518042e+008
1675.134;1.138499;-1.424876;1359.476;140.4794;3;3;0;3.585824;3.523031;1.138499;1247651;1.455168e+008
1681.134;1.108499;-1.267629;1301.456;134.484;3;3;0;3.491336;3.431772;1.108499;1194404;1.391793e+008
1687.134;1.078446;-1.118378;1249.099;129.0738;3;3;0;3.396679;3.340266;1.078446;1146354;1.33458e+008
1693.134;1.048446;-1.043904;1232.85;127.3948;3;3;0;3.302191;3.24884;1.048446;1131442;1.316016e+008
1699.134;1.018553;-0.9737978;1216.683;125.7242;3;3;0;3.208041;3.157658;1.018553;1116605;1.297575e+008
1705.134;0.9884994;-0.8945145;1199.762;123.9756;3;3;0;3.113384;3.065901;0.9884994;1101075;1.278354e+008
1711.134;0.9584458;-0.8155616;1174.358;121.3505;3;3;0;3.018727;2.97406;0.9584458;1077760;1.250138e+008
1717.134;0.9283387;-0.7270738;1155.397;119.3912;3;3;0;2.923901;2.881971;0.9283387;1060359;1.228821e+008
1723.134;0.8983387;-0.6322423;1138.391;117.6339;3;3;0;2.829413;2.790125;0.8983387;1044752;1.209623e+008
1729.134;0.8684459;-0.5433357;1110.699;114.7724;3;3;0;2.735263;2.698523;0.8684459;1019338;1.179117e+008
1735.134;0.8384995;-0.4632254;1084.859;112.1023;3;3;0;2.640943;2.606672;0.8384995;995623.4;1.150629e+008
1741.134;0.8084995;-0.3995453;1062.713;109.8139;3;3;0;2.546455;2.514573;0.8084995;975299;1.126102e+008
1747.134;0.778446;-0.355514;1046.357;108.1237;3;3;0;2.451798;2.422224;0.778446;960288.2;1.107747e+008
1753.134;0.7482852;-0.3257803;1022.875;105.6973;3;3;0;2.356804;2.32946;0.7482852;938738.3;1.081884e+008
1759.134;0.7183388;-0.3039383;1008.155;104.1762;3;3;0;2.262484;2.23727;0.7183388;925228.4;1.065332e+008
1765.134;0.6884459;-0.2839581;988.1644;102.1105;3;3;0;2.168334;2.14516;0.6884459;906882.5;1.043246e+008
1771.134;0.6584996;-0.2659527;971.3019;100.3681;3;3;0;2.074014;2.0528;0.6584996;891407.1;1.024497e+008
1777.134;0.6284996;-0.2485856;950.2317;98.1908;3;3;0;1.979526;1.960189;0.6284996;872070;1.001345e+008
1783.134;0.5984996;-0.2318133;926.9537;95.78541;3;3;0;1.885038;1.867491;0.5984996;850706.8;9.7591e+007
1789.134;0.5684461;-0.2160022;903.2874;93.33988;3;3;0;1.790381;1.774543;0.5684461;828987.1;9.501102e+007
1795.134;0.5384996;-0.2001248;879.9535;90.92871;3;3;0;1.696062;1.681839;0.5384996;807572.6;9.247092e+007
1801.134;0.5085532;-0.1833378;863.1526;89.19262;3;3;0;1.601743;1.58905;0.5085532;792153.7;9.062125e+007
1807.134;0.4784997;-0.1668213;851.5836;87.99715;3;3;0;1.507086;1.495842;0.4784997;781536.3;8.932335e+007
1813.134;0.4483926;-0.1520509;837.4659;86.53831;3;3;0;1.41226;1.402381;0.4483926;768579.8;8.776046e+007
1819.134;0.418339;-0.1383877;821.1792;84.85536;3;3;0;1.317603;1.308998;0.418339;753632.8;8.597342e+007
1825.134;0.388339;-0.1239462;797.6208;82.42098;3;3;0;1.223115;1.215695;0.388339;732012.2;8.342909e+007
1831.134;0.3584462;-0.1051006;755.7889;78.09835;3;3;0;1.128964;1.122639;0.3584462;693621.2;7.898005e+007
1837.134;0.3284998;-0.07872171;669.7889;69.21166;3;3;0;1.034645;1.029329;0.3284998;614695.2;6.992776e+007
1843.134;0.2984462;-0.0487114;526.2696;54.38131;3;3;0;0.9399882;0.9355978;0.2984462;482981.1;5.489248e+007
1849.134;0.2683927;-0.02822246;386.6008;39.94883;3;3;0;0.8453313;0.8417783;0.2683927;354800.8;4.028653e+007
1855.134;0.2383391;-0.01476703;268.0221;27.69567;3;3;0;0.7506744;0.7478709;0.2383391;245975.8;2.790358e+007
1861.134;0.2083927;-0.008002546;173.3938;17.9174;3;3;0;0.656355;0.6542104;0.2083927;159131.3;1.8035e+007
1867.134;0.1784463;-0.007120048;101.8555;10.52509;3;3;0;0.5620356;0.5604621;0.1784463;93477.36;1.058425e+007
1873.134;0.1484999;-0.008939056;62.42207;6.450293;3;3;0;0.4677162;0.4666259;0.1484999;57287.51;6480462
1878.1;0.1534821;-0.008646586;69.22596;7.153363;4;4;0;0.483408;0.4822434;0.1534821;63531.75;7187943
1884.1;0.183482;-0.008909476;143.5805;14.83668;4;4;0;0.5778961;0.5762327;0.183482;131770.2;1.492242e+007
1890.1;0.2135356;-0.01338365;248.0706;25.63401;4;4;0;0.672553;0.6703015;0.2135356;227665.5;2.580642e+007
1896.1;0.2435891;-0.02422845;381.7886;39.45157;4;4;0;0.7672098;0.7642818;0.2435891;350384.4;3.975425e+007
1902.1;0.2736427;-0.04144841;534.877;55.27074;4;4;0;0.8618667;0.8581738;0.2736427;490880.5;5.57471e+007
1908.1;0.3035355;-0.06465761;705.3811;72.88953;4;4;0;0.9560174;0.9514764;0.3035355;647359.7;7.358637e+007
1914.1;0.3335891;-0.09271597;884.2812;91.3759;4;4;0;1.050674;1.045193;0.3335891;811544.3;9.233597e+007
1920.1;0.3636426;-0.1241168;1051.826;108.6889;4;4;0;1.145331;1.138822;0.3636426;965307.9;1.099338e+008
1926.1;0.3936962;-0.1488151;1151.892;119.0291;4;4;0;1.239988;1.232363;0.3936962;1057143;1.20505e+008
1932.1;0.4236962;-0.1619228;1187.121;122.6694;4;4;0;1.334476;1.32565;0.4236962;1089474;1.243064e+008
1938.1;0.4536426;-0.1743744;1225.023;126.586;4;4;0;1.428795;1.418684;0.4536426;1124258;1.283946e+008
1944.1;0.4835354;-0.1873323;1252.751;129.4512;4;4;0;1.522946;1.511466;0.4835354;1149705;1.314226e+008
1950.1;0.5135353;-0.2061932;1300.672;134.403;4;4;0;1.617434;1.604493;0.5135353;1193684;1.365769e+008
1956.1;0.5436425;-0.22173;1332.304;137.6717;4;4;0;1.71226;1.697766;0.5436425;1222715;1.40029e+008
1962.1;0.5736961;-0.2404566;1378.71;142.4669;4;4;0;1.806917;1.790786;0.5736961;1265303;1.450412e+008
1968.1;0.6038032;-0.2542957;1404.006;145.0809;4;4;0;1.901742;1.883885;0.6038032;1288519;1.4784e+008
1974.1;0.6335889;-0.2731515;1444.326;149.2473;4;4;0;1.995556;1.975905;0.6335889;1325522;1.522256e+008
1980.1;0.6635353;-0.2901544;1478.636;152.7927;4;4;0;2.089875;2.068337;0.6635353;1357010;1.559858e+008
1986.1;0.6935353;-0.3052329;1481.615;153.1006;4;4;0;2.184363;2.160848;0.6935353;1359745;1.564448e+008
1992.1;0.7235353;-0.3232968;1488.519;153.8139;4;4;0;2.278851;2.253273;0.7235353;1366080;1.573191e+008
1998.1;0.7535888;-0.3464303;1517.472;156.8058;4;4;0;2.373508;2.345778;0.7535888;1392652;1.605276e+008
2004.1;0.7835888;-0.3778164;1549.482;160.1134;4;4;0;2.467996;2.438033;0.7835888;1422028;1.64065e+008
2010.1;0.8135888;-0.4107743;1579.999;163.2669;4;4;0;2.562484;2.530203;0.8135888;1450036;1.674506e+008
2016.1;0.8436423;-0.4477365;1632.684;168.711;4;4;0;2.657141;2.622452;0.8436423;1498387;1.731939e+008
2022.1;0.8736423;-0.4822703;1674.288;173.0101;4;4;0;2.751629;2.714452;0.8736423;1536569;1.777707e+008
2028.1;0.9036958;-0.5124195;1716.331;177.3546;4;4;0;2.846286;2.806532;0.9036958;1575154;1.824026e+008
2034.1;0.9337494;-0.5614991;1766.94;182.5842;4;4;0;2.940943;2.898527;0.9337494;1621600;1.879539e+008
2040.1;0.9636422;-0.6036316;1801.947;186.2016;4;4;0;3.035094;2.989946;0.9636422;1653727;1.91853e+008
2046.1;0.9934815;-0.6524551;1818.257;187.8869;4;4;0;3.129076;3.081118;0.9934815;1668696;1.937661e+008
2052.1;1.023589;-0.7126222;1862.909;192.501;4;4;0;3.223901;3.173024;1.023589;1709675;1.987071e+008
2058.1;1.053642;-0.7866501;1899.753;196.3082;4;4;0;3.318558;3.264682;1.053642;1743488;2.028228e+008
2064.1;1.083696;-0.9272522;1904.038;196.751;4;4;0;3.413215;3.356257;1.083696;1747421;2.034665e+008
2070.1;1.113696;-1.098567;1917.659;198.1585;4;4;0;3.507703;3.447585;1.113696;1759921;2.051093e+008
2076.1;1.143535;-1.25414;1948.699;201.366;4;4;0;3.601685;3.538341;1.143535;1788408;2.086186e+008
2082.1;1.173481;-1.376661;1936.417;200.0968;4;4;0;3.696004;3.62934;1.173481;1777136;2.074924e+008
2088.1;1.203535;-1.453895;1964.996;203.05;4;4;0;3.790661;3.720581;1.203535;1803364;2.107469e+008
2094.1;1.233588;-1.622213;1976.2;204.2078;4;4;0;3.885318;3.811739;1.233588;1813647;2.121419e+008
2100.1;1.263642;-1.765729;1925.915;199.0116;4;4;0;3.979975;3.902815;1.263642;1767498;2.069323e+008
2106.1;1.293588;-2.006547;1931.017;199.5388;4;4;0;4.074294;3.993483;1.293588;1772181;2.076686e+008
2112.1;1.323588;-2.23862;1948.238;201.3184;4;4;0;4.168782;4.08423;1.323588;1787985;2.097109e+008
2118.1;1.353588;-2.458891;1966.935;203.2504;4;4;0;4.263271;4.174896;1.353588;1805144;2.119155e+008
2124.1;1.383695;-2.671048;1986.077;205.2284;4;4;0;4.358096;4.265803;1.383695;1822711;2.141724e+008
2130.1;1.413749;-2.881519;2001.129;206.7837;4;4;0;4.452753;4.356466;1.413749;1836525;2.159913e+008
2136.1;1.443696;-3.082655;2020.19;208.7534;4;4;0;4.547072;4.446724;1.443696;1854018;2.182456e+008
2142.1;1.473535;-3.27674;2040.586;210.8609;4;4;0;4.641055;4.536578;1.473535;1872736;2.206471e+008
2148.1;1.503535;-3.473013;2055.237;212.3749;4;4;0;4.735542;4.626834;1.503535;1886183;2.22432e+008
2154.1;1.533588;-3.671375;2076.372;214.5588;4;4;0;4.8302;4.717171;1.533588;1905579;2.249224e+008
2160.1;1.563695;-3.863376;2099.033;216.9005;4;4;0;4.925025;4.807586;1.563695;1926377;2.275829e+008
2166.1;1.593695;-4.048408;2119.672;219.0332;4;4;0;5.019513;4.897599;1.593695;1945317;2.300276e+008
2172.1;1.623642;-4.220926;2143.791;221.5255;4;4;0;5.113832;4.987369;1.623642;1967452;2.328539e+008
2178.1;1.653481;-4.380224;2163.175;223.5285;4;4;0;5.207815;5.07674;1.653481;1985242;2.351695e+008
2184.1;1.683481;-4.519397;2187.719;226.0647;4;4;0;5.302303;5.16651;1.683481;2007767;2.380513e+008
2190.1;1.713535;-4.640105;2211.84;228.5573;4;4;0;5.396959;5.25636;1.713535;2029904;2.408924e+008
2196.1;1.743588;-4.74764;2235.638;231.0164;4;4;0;5.491616;5.34613;1.743588;2051745;2.437029e+008
2202.1;1.773588;-4.860581;2252.691;232.7785;4;4;0;5.586104;5.435659;1.773588;2067395;2.457818e+008
2208.1;1.803588;-4.959742;2273.772;234.9569;4;4;0;5.680593;5.525108;1.803588;2086742;2.483039e+008
2214.1;1.833588;-5.070469;2291.124;236.75;4;4;0;5.775081;5.614478;1.833588;2102667;2.504225e+008
2220.1;1.863642;-5.178762;2309.95;238.6953;4;4;0;5.869738;5.703926;1.863642;2119944;2.527061e+008
2226.1;1.893695;-5.278485;2332.115;240.9857;4;4;0;5.964395;5.793295;1.893695;2140286;2.553591e+008
2232.1;1.923695;-5.384287;2353.252;243.1699;4;4;0;6.058883;5.882425;1.923695;2159684;2.579032e+008
2238.1;1.953641;-5.495023;2373.888;245.3023;4;4;0;6.153202;5.971316;1.953641;2178623;2.603962e+008
2244.1;1.983534;-5.605797;2396.431;247.6317;4;4;0;6.247352;6.05997;1.983534;2199311;2.631021e+008
2250.1;2.013534;-5.724726;2419.002;249.9641;4;4;0;6.341841;6.148863;2.013534;2220026;2.658164e+008
2256.1;2.043641;-5.848038;2444.101;252.5576;4;4;0;6.436666;6.237994;2.043641;2243060;2.688139e+008
2262.1;2.073748;-5.977973;2469.305;255.162;4;4;0;6.531491;6.327045;2.073748;2266191;2.718279e+008
2268.1;2.103749;-6.102498;2500.297;258.3646;4;4;0;6.62598;6.415701;2.103749;2294634;2.754838e+008
2274.1;2.133588;-6.238858;2529.95;261.4286;4;4;0;6.719962;6.503804;2.133588;2321848;2.789966e+008
2280.1;2.163481;-6.391769;2558.199;264.3477;4;4;0;6.814113;6.591987;2.163481;2347773;2.823607e+008
2286.1;2.193534;-6.551969;2587.174;267.3419;4;4;0;6.90877;6.680566;2.193534;2374365;2.858119e+008
2292.1;2.223588;-6.716937;2620.152;270.7495;4;4;0;7.003426;6.769067;2.223588;2404630;2.897113e+008
2298.1;2.253588;-6.886508;2653.088;274.153;4;4;0;7.097915;6.857332;2.253588;2434857;2.936121e+008
2304.1;2.283588;-7.063981;2683.182;277.2627;4;4;0;7.192402;6.945519;2.283588;2462476;2.972045e+008
2310.1;2.313588;-7.246615;2709.386;279.9704;4;4;0;7.286891;7.033628;2.313588;2486524;3.003715e+008
2316.1;2.343641;-7.424963;2743.033;283.4473;4;4;0;7.381547;7.121817;2.343641;2517404;3.043701e+008
2322.1;2.373641;-7.603518;2775.42;286.7939;4;4;0;7.476036;7.209771;2.373641;2547127;3.082348e+008
2328.1;2.403695;-7.692831;2809.953;290.3624;4;4;0;7.570693;7.297805;2.403695;2578819;3.123448e+008
2334.1;2.433748;-7.746732;2856.526;295.175;4;4;0;7.665349;7.385761;2.433748;2621561;3.178011e+008
2340.1;2.463588;-7.798685;2918.26;301.5542;4;4;0;7.759331;7.473014;2.463588;2678218;3.249528e+008
2346.1;2.493534;-7.876433;3014.16;311.4638;4;4;0;7.85365;7.560503;2.493534;2766229;3.359251e+008
2352.1;2.523588;-7.936774;3109.161;321.2807;4;4;0;7.948308;7.648229;2.523588;2853416;3.46817e+008
2358.1;2.553695;-7.986531;3204.77;331.1603;4;4;0;8.043134;7.736035;2.553695;2941161;3.577959e+008
2362.64;2.556373;-7.987441;3111.293;321.5009;4;4;0;8.05157;7.743842;2.556373;2855373;3.473868e+008
2368.64;2.526373;-7.922581;2805.167;289.8678;4;4;0;7.957082;7.656357;2.526373;2574427;3.129328e+008
2374.64;2.496373;-7.872804;2618.631;270.5925;4;4;0;7.862593;7.568794;2.496373;2403235;2.91868e+008
2380.64;2.466373;-7.862283;2521.873;260.5941;4;4;0;7.768105;7.481155;2.466373;2314435;2.808373e+008
2386.64;2.43632;-7.825928;2465.423;254.7608;4;4;0;7.673449;7.393284;2.43632;2262628;2.743098e+008
2392.64;2.406427;-7.672071;2410.079;249.042;4;4;0;7.579298;7.305804;2.406427;2211838;2.679177e+008
2398.64;2.376373;-7.48908;2358.35;243.6967;4;4;0;7.484641;7.217777;2.376373;2164363;2.619365e+008
2404.64;2.346266;-7.308798;2311.504;238.8559;4;4;0;7.389815;7.129516;2.346266;2121371;2.565069e+008
2410.64;2.316213;-7.126185;2271.492;234.7213;4;4;0;7.295158;7.041334;2.316213;2084649;2.518445e+008
2416.64;2.286213;-6.950915;2228.462;230.2748;4;4;0;7.20067;6.953232;2.286213;2045159;2.468561e+008
2422.64;2.256266;-6.786831;2188.787;226.1751;4;4;0;7.10635;6.865209;2.256266;2008748;2.422479e+008
2428.64;2.226373;-6.631541;2154.449;222.6268;4;4;0;7.0122;6.777266;2.226373;1977234;2.382379e+008
2434.64;2.196374;-6.506463;2124.471;219.5291;4;4;0;6.917712;6.688931;2.196374;1949722;2.347155e+008
2440.64;2.166266;-6.402733;2102.201;217.2279;4;4;0;6.822886;6.600201;2.166266;1929284;2.320491e+008
2446.64;2.136213;-6.307498;2081.484;215.0871;4;4;0;6.72823;6.511551;2.136213;1910271;2.295587e+008
2452.64;2.106213;-6.213601;2062.273;213.102;4;4;0;6.633741;6.42298;2.106213;1892640;2.272386e+008
2458.64;2.07632;-6.124678;2041.751;210.9813;4;4;0;6.539591;6.334647;2.07632;1873806;2.247786e+008
2464.64;2.046374;-6.015198;2026.979;209.4549;4;4;0;6.445271;6.246078;2.046374;1860249;2.229548e+008
2470.64;2.016374;-5.915723;2005.173;207.2016;4;4;0;6.350783;6.157272;2.016374;1840237;2.203605e+008
2476.64;1.98632;-5.812775;1986.144;205.2353;4;4;0;6.256126;6.068228;1.98632;1822773;2.180751e+008
2482.64;1.95632;-5.708448;1964.942;203.0444;4;4;0;6.161638;5.979264;1.95632;1803315;2.155553e+008
2488.64;1.92632;-5.608883;1940.381;200.5064;4;4;0;6.067151;5.89022;1.92632;1780774;2.126714e+008
2494.64;1.896427;-5.511011;1914.627;197.8452;4;4;0;5.973;5.801416;1.896427;1757138;2.096624e+008
2500.64;1.866374;-5.400344;1886.79;194.9687;4;4;0;5.878343;5.712054;1.866374;1731591;2.064296e+008
2506.64;1.836267;-5.273237;1854.928;191.6763;4;4;0;5.783517;5.622453;1.836267;1702350;2.027619e+008
2512.64;1.806213;-5.119744;1823.096;188.387;4;4;0;5.68886;5.532931;1.806213;1673137;1.991041e+008
2518.64;1.776267;-4.952594;1790.798;185.0495;4;4;0;5.594541;5.443649;1.776267;1643495;1.954021e+008
2524.64;1.74632;-4.781111;1757.238;181.5816;4;4;0;5.500222;5.354287;1.74632;1612696;1.91569e+008
2530.64;1.716374;-4.603059;1725.218;178.2729;4;4;0;5.405902;5.264845;1.716374;1583310;1.879101e+008
2536.64;1.68632;-4.423775;1694.225;175.0703;4;4;0;5.311245;5.175002;1.68632;1554866;1.843687e+008
2542.64;1.656213;-4.244179;1663.355;171.8804;4;4;0;5.21642;5.084918;1.656213;1526535;1.808464e+008
2548.64;1.62616;-4.062065;1633.065;168.7504;4;4;0;5.121763;4.994914;1.62616;1498737;1.773934e+008
2554.64;1.596267;-3.8772;1603.562;165.7017;4;4;0;5.027612;4.90531;1.596267;1471660;1.740326e+008
2560.64;1.566374;-3.682345;1578.031;163.0635;4;4;0;4.933461;4.815626;1.566374;1448229;1.711082e+008
2566.64;1.536374;-3.488373;1549.922;160.1589;4;4;0;4.838974;4.72554;1.536374;1422432;1.679089e+008
2572.64;1.506374;-3.294992;1519.169;156.9812;4;4;0;4.744485;4.635373;1.506374;1394210;1.644291e+008
2578.64;1.47632;-3.101577;1489.65;153.9308;4;4;0;4.649828;4.544962;1.47632;1367118;1.610883e+008
2584.64;1.446321;-2.903511;1461.513;151.0233;4;4;0;4.55534;4.454632;1.446321;1341296;1.57903e+008
2590.64;1.416374;-2.708838;1428.182;147.5791;4;4;0;4.461021;4.364381;1.416374;1310707;1.541627e+008
2596.64;1.386374;-2.512125;1395.891;144.2424;4;4;0;4.366532;4.273887;1.386374;1281072;1.505408e+008
2602.64;1.356321;-2.313082;1361.894;140.7294;4;4;0;4.271876;4.183149;1.356321;1249871;1.467412e+008
2608.64;1.326213;-2.112452;1333.564;137.8019;4;4;0;4.17705;4.092167;1.326213;1223871;1.435579e+008
2614.64;1.296213;-1.933776;1308.404;135.202;4;4;0;4.082562;4.001426;1.296213;1200781;1.407217e+008
2620.64;1.266267;-1.860881;1294.429;133.7579;4;4;0;3.988243;3.910766;1.266267;1187955;1.390925e+008
2626.64;1.236374;-1.744724;1260.51;130.253;4;4;0;3.894092;3.820185;1.236374;1156826;1.353251e+008
2632.64;1.206374;-1.652337;1236.886;127.8118;4;4;0;3.799604;3.729197;1.206374;1135145;1.326681e+008
2638.64;1.176267;-1.530394;1204.796;124.4958;4;4;0;3.704778;3.6378;1.176267;1105695;1.291081e+008
2644.64;1.146214;-1.441876;1183.648;122.3105;4;4;0;3.610121;3.546484;1.146214;1086286;1.26726e+008
2650.64;1.11616;-1.325892;1153.871;119.2336;4;4;0;3.515465;3.455083;1.11616;1058959;1.234252e+008
2656.64;1.086321;-1.190514;1119.872;115.7204;4;4;0;3.421483;3.364252;1.086321;1027757;1.196797e+008
2662.64;1.056374;-1.040815;1097.201;113.3776;4;4;0;3.327163;3.273011;1.056374;1006950;1.171499e+008
2668.64;1.026374;-0.907505;1064.338;109.9818;4;4;0;3.232675;3.181523;1.026374;976790.8;1.135372e+008
2674.64;0.9963743;-0.8037741;1038.241;107.2851;4;4;0;3.138187;3.089952;0.9963743;952839.9;1.106519e+008
2680.64;0.9663208;-0.69089;1014.422;104.8238;4;4;0;3.04353;2.998134;0.9663208;930980.4;1.080142e+008
2686.64;0.9363744;-0.57849;986.2409;101.9118;4;4;0;2.949211;2.906558;0.9363744;905117.3;1.049174e+008
2692.64;0.9063745;-0.4677435;960.6446;99.2668;4;4;0;2.854723;2.814735;0.9063745;881626.4;1.021006e+008
2698.64;0.8763745;-0.3643573;940.449;97.17992;4;4;0;2.760235;2.722827;0.8763745;863091.9;9.986232e+007
2704.64;0.8462673;-0.2900387;912.3989;94.28141;4;4;0;2.665409;2.630506;0.8462673;837349.2;9.67944e+007
2710.64;0.8162137;-0.2567739;893.1804;92.29549;4;4;0;2.570752;2.538264;0.8162137;819711.4;9.466818e+007
2716.64;0.7862138;-0.2348861;875.8674;90.50648;4;4;0;2.476264;2.446101;0.7862138;803822.6;9.274765e+007
2722.64;0.756321;-0.2180084;869.3199;89.8299;4;4;0;2.382113;2.354184;0.756321;797813.6;9.196975e+007
2728.64;0.7263746;-0.2015398;857.3909;88.59723;4;4;0;2.287794;2.262016;0.7263746;786865.8;9.062415e+007
2734.64;0.696321;-0.1860327;840.151;86.81578;4;4;0;2.193137;2.169434;0.696321;771044.1;8.871977e+007
2740.64;0.6662674;-0.1709374;822.4291;84.98451;4;4;0;2.09848;2.076765;0.6662674;754779.9;8.676789e+007
2746.64;0.6361603;-0.1589552;805.0745;83.19119;4;4;0;2.003654;1.983846;0.6361603;738852.8;8.485806e+007
2752.64;0.6062139;-0.1490999;788.1265;81.4399;4;4;0;1.909335;1.891336;0.6062139;723298.8;8.299486e+007
2758.64;0.576321;-0.1406101;768.4384;79.40546;4;4;0;1.815184;1.798907;0.576321;705230.1;8.084681e+007
2764.64;0.5463746;-0.1311181;740.0202;76.46891;4;4;0;1.720865;1.706226;0.5463746;679149.6;7.778484e+007
2770.64;0.5163747;-0.1212755;708.6791;73.23032;4;4;0;1.626377;1.613293;0.5163747;650386.4;7.442132e+007
2776.64;0.4863747;-0.1104093;681.0799;70.3784;4;4;0;1.531889;1.520274;0.4863747;625057.4;7.145652e+007
2782.64;0.4563211;-0.09767413;663.9935;68.61279;4;4;0;1.437232;1.427002;0.4563211;609376.4;6.959892e+007
2788.64;0.4263748;-0.08593899;649.9838;67.16512;4;4;0;1.342913;1.333975;0.4263748;596519.1;6.806709e+007
2794.64;0.3963747;-0.07465413;630.5686;65.15889;4;4;0;1.248424;1.240696;0.3963747;578700.9;6.597235e+007
2800.64;0.3663747;-0.06347417;604.8071;62.49686;4;4;0;1.153936;1.147329;0.3663747;555058.4;6.321803e+007
2806.64;0.3362676;-0.05208272;556.5185;57.50702;4;4;0;1.059111;1.053541;0.3362676;510741.8;5.811609e+007
2812.64;0.3062141;-0.04411724;478.5975;49.45517;4;4;0;0.9644539;0.9598327;0.3062141;439230.3;4.993215e+007
2818.64;0.2762677;-0.03567088;387.4321;40.03473;4;4;0;0.8701344;0.8663706;0.2762677;355563.7;4.038309e+007
2824.64;0.2463213;-0.02617869;292.8325;30.25942;4;4;0;0.775815;0.7728211;0.2463213;268745.4;3.049417e+007
2830.64;0.2163749;-0.01686097;205.245;21.2087;4;4;0;0.6814957;0.679184;0.2163749;188362.5;2.135323e+007
2836.64;0.1863213;-0.009647012;129.1961;13.35029;4;4;0;0.5868388;0.5851236;0.1863213;118569;1.342863e+007
2842.64;0.1562677;-0.005499484;71.84383;7.423877;4;4;0;0.4921819;0.4909746;0.1562677;65934.28;7460416
2848.64;0.1261606;-0.005121564;62.05178;6.41203;4;4;0;0.3973563;0.3965689;0.1261606;56947.69;6437509
2848.804;0.1254106;-0.005210362;62.15244;6.422432;4;4;0;0.3949941;0.3942161;0.1254106;57040.07;6447800