File: Ensayos/Resistencia/comp/Clavo7/Clavo7c.raw
"Test Type";"Manual"
"Method Name:";"C:\INSTRON\USER\TEMPLATE\CYCLE.MTM"
"Name:";""
"Operator ID:";""
"Company:";""
"Lab name:";""
"Test date:";"13/06/2017"
"Temperature:";""
"Humidity:";""
"Note 1:";""
"Note 2:";""
"Note 3:";""
"Geometry:";"Rectangular"
"Specimen";1
"Specimen name:";""
"Width:";0.250000;"in"
"Thickness:";0.060000;"in"
"Length:";1.250000;"in"
"Diameter:";0.039370;"in"
"Inner diameter:";0.019685;"in"
"Outer diameter:";0.039370;"in"
"Wall thickness:";0.019685;"in"
"Area:";0.015000;"in*in"
"Linear density:";1.000000;"den"
"Sled weight:";2.204623;"lbf"
"Loading span:";0.000000;"mm"
"Support span:";1.000000;"mm"
"Span ratio:";"2"
"Fixture type:";"3-point"
"Comment:";""
"Included"
"Final Width:";0.250000;"in"
"Final Thickness:";0.060000;"in"
"Final Length:";1.250000;"in"
"Final Diameter:";0.039370;"in"
"Final Inner diameter:";0.019685;"in"
"Final Outer diameter:";0.039370;"in"
"Final Wall thickness:";0.019685;"in"
"Final Area:";0.015000;"in*in"
"Final Linear density:";1.000000;"den"
"Time sec";"Extension mm";"Strain 1 %";"Load N";"Stress MPa";"Cycle Count ";"Total Cycle Count ";"Repetitions Count ";"Strain [Exten.] %";"True strain %";"Corrected Position mm";"Tenacity gf/tex";"True stress Pa"
0;0;-9.491836e-005;52.25551;5.399747;0;0;0;0;0;0;47957.21;5399747
6;5.35714e-005;-1.140594e-005;52.33609;5.408073;0;0;0;0.0001687288;0.0001687287;5.35714e-005;48031.16;5408082
12;0.0001607142;5.149261e-005;52.29307;5.403628;0;0;0;0.0005061864;0.0005061851;0.0001607142;47991.68;5403655
18;0.004928568;-4.987334e-005;52.39323;5.413978;0;0;0;0.01552305;0.01552184;0.004928568;48083.61;5414818
24;0.01499999;4.702924e-005;52.9572;5.472255;0;0;0;0.04724407;0.04723291;0.01499999;48601.19;5474841
30;0.02501784;-2.263841e-006;55.05529;5.689058;0;0;0;0.07879635;0.07876532;0.02501784;50526.7;5693541
36;0.03498212;-0.0003733518;65.67054;6.78597;0;0;0;0.1101799;0.1101193;0.03498212;60268.79;6793446
42;0.04499997;-0.00165967;93.76779;9.689358;0;0;0;0.1417322;0.1416318;0.04499997;86054.88;9703091
48;0.0550714;-0.003188871;118.5302;12.24815;0;0;0;0.1734532;0.173303;0.0550714;108780.5;1.226939e+007
54;0.06503567;-0.005069095;143.4241;14.82052;0;0;0;0.2048368;0.2046273;0.06503567;131626.7;1.485087e+007
60;0.07499995;-0.007169826;168.6435;17.42653;0;0;0;0.2362203;0.2359418;0.07499995;154771.6;1.746769e+007
66;0.08507138;-0.009150945;194.0168;20.04845;0;0;0;0.2679414;0.267583;0.08507138;178057.9;2.010216e+007
72;0.09503565;-0.01159223;219.3091;22.66199;0;0;0;0.2993249;0.2988778;0.09503565;201269.8;2.272982e+007
78;0.1049999;-0.01396691;245.0472;25.32159;0;0;0;0.3307084;0.3301628;0.1049999;224890.8;2.540534e+007
84.00001;0.1150178;-0.01656805;270.8761;27.99059;0;0;0;0.3622607;0.3616062;0.1150178;248595.1;2.809198e+007
90.00001;0.1249285;-0.01919422;296.9602;30.68595;0;0;0;0.3934755;0.3927034;0.1249285;272533.7;3.080669e+007
96.00001;0.1349463;-0.02186741;323.1482;33.39204;0;0;0;0.4250278;0.4241272;0.1349463;296567.5;3.353397e+007
102;0.1449106;-0.0249547;350.2753;36.19518;0;0;0;0.4564114;0.455373;0.1449106;321463.2;3.636038e+007
108;0.1549285;-0.02793292;378.6234;39.1245;0;0;0;0.4879636;0.486777;0.1549285;347479.6;3.931541e+007
114;0.1648928;-0.03128547;406.4145;41.99625;0;0;0;0.5193473;0.5180033;0.1648928;372984.7;4.221435e+007
120;0.1749106;-0.03467479;435.4556;44.99717;0;0;0;0.5508995;0.5493876;0.1749106;399637;4.524506e+007
126;0.1849284;-0.03816008;465.201;48.07087;0;0;0;0.5824518;0.5807621;0.1849284;426935.7;4.835086e+007
132;0.1949463;-0.04183658;495.7179;51.22429;0;0;0;0.6140041;0.6121268;0.1949463;454942.5;5.153881e+007
138;0.2049642;-0.04565697;526.4745;54.40248;0;0;0;0.6455564;0.6434816;0.2049642;483169.2;5.475368e+007
144;0.2149284;-0.04958984;558.2815;57.68921;0;0;0;0.67694;0.674659;0.2149284;512359.8;5.807973e+007
150;0.2249999;-0.05344034;590.0317;60.97006;0;0;0;0.708661;0.7061618;0.2249999;541498.4;6.140213e+007
156;0.2349641;-0.05749224;622.6156;64.33708;0;0;0;0.7400445;0.7373196;0.2349641;571402.1;6.48132e+007
162;0.2449284;-0.06171042;655.018;67.68533;0;0;0;0.771428;0.7684677;0.2449284;601139.3;6.820747e+007
168;0.2549998;-0.0660042;689.1413;71.21141;0;0;0;0.803149;0.7999409;0.2549998;632455.7;7.178334e+007
174;0.2649641;-0.07017211;723.5835;74.77045;0;0;0;0.8345326;0.8310696;0.2649641;664064.9;7.539443e+007
180;0.2749284;-0.07485707;759.0823;78.43866;0;0;0;0.8659163;0.8621887;0.2749284;696643.6;7.911787e+007
186;0.2849462;-0.07961356;794.8455;82.1342;0;0;0;0.8974684;0.8934651;0.2849462;729465.2;8.287133e+007
192;0.2883212;-0.07943952;795.3416;82.18546;0;0;0;0.9080983;0.9039999;0.2883212;729920.4;8.293179e+007
198;0.2912141;-0.07990223;797.0703;82.3641;0;0;0;0.9172097;0.9130289;0.2912141;731507;8.311955e+007
204;0.2942141;-0.08064209;800.4673;82.71512;0;0;0;0.9266586;0.9223914;0.2942141;734624.5;8.34816e+007
210;0.2967855;-0.08085246;802.7246;82.94837;0;0;0;0.9347576;0.9304157;0.2967855;736696.1;8.372374e+007
216;0.2993569;-0.08112321;806.0629;83.29333;0;0;0;0.9428565;0.9384394;0.2993569;739759.8;8.407867e+007
222;0.3012855;-0.08153803;805.5684;83.24223;0;0;0;0.9489308;0.9444567;0.3012855;739306.1;8.403215e+007
228;0.3034284;-0.08210848;806.6183;83.35072;0;0;0;0.95568;0.9511422;0.3034284;740269.6;8.414729e+007
234;0.305357;-0.08249045;808.6654;83.56226;0;0;0;0.9617542;0.9571588;0.305357;742148.3;8.436592e+007
240;0.3073927;-0.08307409;809.9692;83.69698;0;0;0;0.9681659;0.9635092;0.3073927;743344.8;8.450731e+007
246;0.3088391;-0.08309809;809.9615;83.69619;0;0;0;0.9727215;0.968021;0.3088391;743337.8;8.451032e+007
252;0.3098569;-0.0828725;807.5794;83.45004;0;0;0;0.9759273;0.9711959;0.3098569;741151.6;8.426445e+007
258;0.3108212;-0.08269549;804.2689;83.10796;0;0;0;0.9789645;0.9742037;0.3108212;738113.4;8.392155e+007
264;0.3117855;-0.08243901;802.2355;82.89783;0;0;0;0.9820016;0.9772113;0.3117855;736247.3;8.37119e+007
270;0.3127498;-0.08221638;800.8015;82.74966;0;0;0;0.9850388;0.9802189;0.3127498;734931.3;8.356477e+007
276;0.3138212;-0.08229794;799.1659;82.58064;0;0;0;0.9884133;0.9835604;0.3138212;733430.1;8.339687e+007
282;0.3147855;-0.08190097;799.4964;82.61479;0;0;0;0.9914504;0.9865678;0.3147855;733733.5;8.343388e+007
288;0.3158034;-0.08187396;799.1862;82.58274;0;0;0;0.9946563;0.9897421;0.3158034;733448.8;8.340415e+007
294;0.3168212;-0.08193597;798.3041;82.49158;0;0;0;0.997862;0.9929163;0.3168212;732639.3;8.331474e+007
300;0.3177855;-0.08160125;798.3369;82.49498;0;0;0;1.000899;0.9959234;0.3177855;732669.4;8.332067e+007
306;0.3188034;-0.08151571;799.4872;82.61385;0;0;0;1.004105;0.9990974;0.3188034;733725.1;8.344337e+007
312;0.3198212;-0.08145232;800.558;82.72449;0;0;0;1.007311;1.002271;0.3198212;734707.8;8.355778e+007
318;0.3207855;-0.08119787;800.4197;82.71021;0;0;0;1.010348;1.005278;0.3207855;734580.9;8.354587e+007
324;0.3218033;-0.08113111;801.2848;82.79959;0;0;0;1.013554;1.008452;0.3218033;735374.8;8.363881e+007
330;0.3228212;-0.08112379;803.5298;83.03158;0;0;0;1.01676;1.011626;0.3228212;737435.1;8.387581e+007
336;0.3237855;-0.08077165;803.7096;83.05016;0;0;0;1.019797;1.014632;0.3237855;737600.2;8.38971e+007
342;0.3247498;-0.08089362;804.7999;83.16283;0;0;0;1.022834;1.017638;0.3247498;738600.8;8.401344e+007
348;0.3258212;-0.08075905;805.8251;83.26875;0;0;0;1.026209;1.020979;0.3258212;739541.6;8.412327e+007
354;0.3263033;-0.08020786;805.6393;83.24957;0;0;0;1.027727;1.022482;0.3263033;739371.1;8.410514e+007
360;0.3263569;-0.07926792;801.9491;82.86825;0;0;0;1.027896;1.022649;0.3263569;735984.5;8.372004e+007
366;0.3265712;-0.07859372;799.914;82.65794;0;0;0;1.028571;1.023317;0.3265712;734116.7;8.350814e+007
372;0.3269998;-0.07787037;799.5054;82.61572;0;0;0;1.02992;1.024653;0.3269998;733741.8;8.34666e+007
378;0.3273212;-0.07761505;797.3957;82.39771;0;0;0;1.030933;1.025655;0.3273212;731805.6;8.324718e+007
384;0.3275355;-0.07697432;795.571;82.20917;0;0;0;1.031608;1.026323;0.3275355;730130.9;8.305724e+007
390;0.3276427;-0.07595479;794.1523;82.06257;0;0;0;1.031945;1.026657;0.3276427;728829;8.290941e+007
394.494;0.3276962;-0.07535944;792.5361;81.89556;0;0;0;1.032114;1.026824;0.3276962;727345.8;8.274082e+007
399.354;0.3277498;-0.07500107;790.6083;81.69635;1;1;0;1.032283;1.026991;0.3277498;725576.4;8.253969e+007
405.354;0.3287141;-0.07478358;795.1753;82.16828;1;1;0;1.03532;1.029997;0.3287141;729767.9;8.301899e+007
411.354;0.3297855;-0.07465481;798.5079;82.51264;1;1;0;1.038695;1.033337;0.3297855;732826.3;8.33697e+007
417.354;0.3304283;-0.07409763;800.2765;82.6954;1;1;0;1.040719;1.035341;0.3304283;734449.4;8.355603e+007
423.354;0.3308569;-0.07337749;801.0555;82.7759;1;1;0;1.042069;1.036677;0.3308569;735164.4;8.363849e+007
429.354;0.3313927;-0.07284396;801.4235;82.81393;1;1;0;1.043756;1.038347;0.3313927;735502.1;8.367831e+007
435.354;0.3318212;-0.07222394;802.378;82.91255;1;1;0;1.045106;1.039683;0.3318212;736378.1;8.377908e+007
441.354;0.3322498;-0.07147237;803.2572;83.00341;1;1;0;1.046456;1.041019;0.3322498;737184.9;8.3872e+007
447.354;0.3327319;-0.07086073;804.5027;83.13211;1;1;0;1.047974;1.042521;0.3327319;738328;8.400331e+007
453.354;0.3329462;-0.06971959;803.7824;83.05769;1;1;0;1.04865;1.043189;0.3329462;737667;8.392867e+007
459.354;0.333214;-0.06913872;804.583;83.14041;1;1;0;1.049493;1.044024;0.333214;738401.7;8.401296e+007
465.354;0.3333748;-0.0680861;804.8671;83.16976;1;1;0;1.049999;1.044525;0.3333748;738662.4;8.404304e+007
471.354;0.3334819;-0.06737083;804.26;83.10704;1;1;0;1.050337;1.044859;0.3334819;738105.3;8.397994e+007
477.354;0.3335891;-0.06585785;803.6684;83.0459;1;1;0;1.050674;1.045193;0.3335891;737562.3;8.391844e+007
483.354;0.3336962;-0.06441226;803.4174;83.01996;1;1;0;1.051012;1.045527;0.3336962;737331.9;8.389251e+007
489.354;0.3338034;-0.06317711;803.4532;83.02367;1;1;0;1.051349;1.045861;0.3338034;737364.8;8.389653e+007
495.354;0.3339105;-0.06188218;803.1527;82.99261;1;1;0;1.051687;1.046195;0.3339105;737089.1;8.386544e+007
501.354;0.3340176;-0.06048115;803.5082;83.02934;1;1;0;1.052024;1.046529;0.3340176;737415.3;8.390283e+007
507.354;0.3340712;-0.05932607;803.3554;83.01355;1;1;0;1.052193;1.046696;0.3340712;737275;8.388701e+007
513.354;0.3341784;-0.05803091;803.614;83.04028;1;1;0;1.05253;1.04703;0.3341784;737512.4;8.391431e+007
519.354;0.3342855;-0.05701172;803.4818;83.02661;1;1;0;1.052868;1.047364;0.3342855;737391;8.390077e+007
525.354;0.3343926;-0.05595476;804.3133;83.11255;1;1;0;1.053205;1.047698;0.3343926;738154.3;8.398789e+007
531.354;0.3344998;-0.05498217;804.9922;83.18269;1;1;0;1.053543;1.048032;0.3344998;738777.3;8.405906e+007
535.57;0.3344998;-0.05431897;804.4104;83.12257;1;1;0;1.053543;1.048032;0.3344998;738243.3;8.39983e+007
541.57;0.3344998;-0.05333263;804.8402;83.16699;1;1;0;1.053543;1.048032;0.3344998;738637.8;8.404319e+007
547.57;0.3341248;-0.05207905;802.913;82.96784;1;1;0;1.052361;1.046863;0.3341248;736869.1;8.384097e+007
553.57;0.3337498;-0.05105772;800.3337;82.70132;1;1;0;1.05118;1.045694;0.3337498;734501.9;8.357066e+007
558.538;0.3336426;-0.05029914;799.806;82.64679;2;2;0;1.050843;1.04536;0.3336426;734017.6;8.351527e+007
564.538;0.3337498;-0.04912699;800.3728;82.70536;2;2;0;1.05118;1.045694;0.3337498;734537.9;8.357474e+007
570.538;0.3338569;-0.04823;800.2658;82.69431;2;2;0;1.051518;1.046028;0.3338569;734439.6;8.356385e+007
576.538;0.3339641;-0.04690762;800.0892;82.67605;2;2;0;1.051855;1.046362;0.3339641;734277.6;8.354568e+007
582.538;0.3340712;-0.04552354;799.9258;82.65916;2;2;0;1.052193;1.046696;0.3340712;734127.6;8.35289e+007
588.538;0.3341784;-0.04427007;799.3876;82.60355;2;2;0;1.05253;1.04703;0.3341784;733633.7;8.347298e+007
594.538;0.3342319;-0.04269543;799.5433;82.61964;2;2;0;1.052699;1.047197;0.3342319;733776.5;8.348937e+007
600.538;0.3343391;-0.04135407;798.8288;82.54581;2;2;0;1.053036;1.047531;0.3343391;733120.8;8.341504e+007
606.538;0.3345534;-0.03991611;798.8544;82.54845;2;2;0;1.053711;1.048199;0.3345534;733144.3;8.341827e+007
612.538;0.3348748;-0.0381351;798.9356;82.55685;2;2;0;1.054724;1.0492;0.3348748;733218.9;8.342759e+007
618.538;0.3351962;-0.03687243;800.3945;82.7076;2;2;0;1.055736;1.050202;0.3351962;734557.7;8.358077e+007
624.538;0.3355712;-0.03514259;799.9612;82.66282;2;2;0;1.056917;1.051371;0.3355712;734160.1;8.35365e+007
630.538;0.3358391;-0.03335594;799.8482;82.65115;2;2;0;1.057761;1.052206;0.3358391;734056.4;8.35254e+007
636.538;0.3361605;-0.0318201;798.3951;82.50099;2;2;0;1.058773;1.053207;0.3361605;732722.8;8.337449e+007
642.538;0.3364819;-0.02990723;796.5704;82.31244;2;2;0;1.059786;1.054209;0.3364819;731048.2;8.318478e+007
648.538;0.336964;-0.02777118;793.9431;82.04095;2;2;0;1.061304;1.055712;0.336964;728637;8.291165e+007
654.538;0.3377676;-0.02513277;789.3213;81.56336;2;2;0;1.063835;1.058216;0.3377676;724395.3;8.243106e+007
660.538;0.3395355;-0.02284763;782.7633;80.8857;2;2;0;1.069403;1.063726;0.3395355;718376.8;8.175069e+007
666.538;0.3449998;-0.02097727;776.1607;80.20344;2;2;0;1.086613;1.080752;0.3449998;712317.3;8.107494e+007
672.538;0.3538391;-0.0182974;760.7837;78.61447;2;2;0;1.114454;1.108289;0.3538391;698205.1;7.94906e+007
678.538;0.3748926;-0.01768262;759.6466;78.49698;2;2;0;1.180764;1.173847;0.3748926;697161.6;7.942384e+007
684.538;0.4075712;-0.01729664;764.976;79.04768;2;2;0;1.283689;1.275519;0.4075712;702052.6;8.006241e+007
690.538;0.4548211;-0.02091666;790.4543;81.68044;2;2;0;1.432508;1.422344;0.4548211;725435.1;8.285052e+007
696.538;0.5049639;-0.02321175;792.3105;81.87225;2;2;0;1.590438;1.577923;0.5049639;727138.6;8.317437e+007
702.538;0.5549996;-0.024998;784.5469;81.07001;2;2;0;1.74803;1.732928;0.5549996;720013.6;8.248713e+007
708.538;0.6083567;-0.03334239;796.5644;82.31182;2;2;0;1.916084;1.897959;0.6083567;731042.7;8.388898e+007
714.538;0.6612853;-0.04668469;816.2531;84.34633;2;2;0;2.082788;2.061395;0.6612853;749111.9;8.610308e+007
720.538;0.7124995;-0.06350432;824.9396;85.24393;2;2;0;2.244093;2.219284;0.7124995;757083.9;8.715689e+007
726.538;0.7543924;-0.08419546;824.2059;85.16811;2;2;0;2.376039;2.348251;0.7543924;756410.5;8.719174e+007
732.538;0.7913567;-0.1088013;826.7364;85.4296;2;2;0;2.492462;2.461907;0.7913567;758732.9;8.75589e+007
738.538;0.822428;-0.1390534;831.5705;85.92912;2;2;0;2.590325;2.557344;0.822428;763169.3;8.815496e+007
744.538;0.8428388;-0.1589587;814.5261;84.16786;2;2;0;2.65461;2.619987;0.8428388;747526.9;8.640219e+007
750.538;0.8661423;-0.188657;803.4858;83.02704;2;2;0;2.728007;2.69146;0.8661423;737394.8;8.529202e+007
756.538;0.8919637;-0.2249125;792.2495;81.86594;2;2;0;2.809335;2.770597;0.8919637;727082.7;8.416583e+007
762.538;0.9219637;-0.2969246;789.9235;81.62559;2;2;0;2.903822;2.86246;0.9219637;724948;8.399585e+007
768.538;0.9518029;-0.4007183;794.8525;82.13492;2;2;0;2.997805;2.953749;0.9518029;729471.6;8.459716e+007
774.538;0.9817494;-0.533666;804.6615;83.14852;2;2;0;3.092124;3.045281;0.9817494;738473.7;8.571957e+007
780.538;1.011749;-0.6700572;812.1217;83.91941;2;2;0;3.186612;3.136893;1.011749;745320.3;8.65936e+007
786.538;1.039714;-0.8787067;809.1799;83.61543;2;2;0;3.274688;3.222213;1.039714;742620.4;8.635357e+007
792.538;1.063231;-1.09072;792.7684;81.91956;2;2;0;3.34876;3.29391;1.063231;727558.9;8.466285e+007
798.538;1.093392;-1.354612;784.0212;81.01569;2;2;0;3.443755;3.385785;1.093392;719531.3;8.380567e+007
804.538;1.133464;-1.687836;792.0722;81.84763;2;2;0;3.569964;3.507718;1.133464;726920;8.476956e+007
810.538;1.177231;-2.050839;807.6462;83.45694;2;2;0;3.707816;3.640729;1.177231;741212.9;8.655137e+007
816.538;1.214089;-2.367678;814.6226;84.17783;2;2;0;3.823901;3.752602;1.214089;747615.5;8.739671e+007
822.538;1.248053;-2.657907;825.859;85.33893;2;2;0;3.930875;3.855583;1.248053;757927.6;8.86935e+007
828.538;1.276017;-2.903997;826.683;85.42408;2;2;0;4.018951;3.940292;1.276017;758683.8;8.885723e+007
834.538;1.295999;-3.090566;815.5967;84.27849;2;2;0;4.081887;4.000778;1.295999;748509.4;8.771864e+007
840.538;1.315124;-3.258049;818.0355;84.5305;2;2;0;4.142124;4.058635;1.315124;750747.6;8.803186e+007
846.538;1.330285;-3.403455;806.0632;83.29337;2;2;0;4.189874;4.104476;1.330285;739760.1;8.678325e+007
852.538;1.350053;-3.57717;802.6398;82.93961;2;2;0;4.252135;4.164215;1.350053;736618.4;8.646632e+007
858.538;1.369981;-3.744459;805.685;83.25429;2;2;0;4.314902;4.224404;1.369981;739413.1;8.684663e+007
864.538;1.38991;-3.910401;810.4163;83.74319;2;2;0;4.377669;4.284557;1.38991;743755.2;8.740919e+007
870.538;1.40566;-4.048021;805.8868;83.27514;2;2;0;4.427275;4.332071;1.40566;739598.3;8.696196e+007
876.538;1.420499;-4.178237;802.7434;82.95032;2;2;0;4.474013;4.376817;1.420499;736713.4;8.666153e+007
882.538;1.43657;-4.321692;797.6887;82.428;2;2;0;4.524632;4.425256;1.43657;732074.5;8.615756e+007
888.538;1.456606;-4.492954;796.0831;82.26208;2;2;0;4.587736;4.485611;1.456606;730600.9;8.603605e+007
894.538;1.476642;-4.66242;793.9924;82.04605;2;2;0;4.650841;4.54593;1.476642;728682.3;8.586188e+007
900.538;1.499142;-4.840855;797.134;82.37067;2;2;0;4.721706;4.613623;1.499142;731565.4;8.625998e+007
906.538;1.52432;-5.020425;797.3547;82.39349;2;2;0;4.801009;4.689321;1.52432;731767.9;8.63492e+007
912.538;1.549231;-5.164331;797.6403;82.423;2;2;0;4.879468;4.764159;1.549231;732030.1;8.64448e+007
918.538;1.574142;-5.293637;797.6716;82.42623;2;2;0;4.957927;4.838939;1.574142;732058.8;8.651286e+007
924.538;1.599267;-5.418263;796.1723;82.27131;2;2;0;5.037061;4.914306;1.599267;730682.9;8.641536e+007
930.538;1.62616;-5.548977;793.8777;82.03419;2;2;0;5.121763;4.994914;1.62616;728577;8.623579e+007
936.538;1.656052;-5.682936;798.9872;82.56218;2;2;0;5.215913;5.084437;1.656052;733266.2;8.686855e+007
942.538;1.684445;-5.806909;804.5612;83.13815;2;2;0;5.305339;5.169394;1.684445;738381.7;8.754892e+007
948.538;1.710427;-5.903499;807.7382;83.46645;2;2;0;5.387173;5.247075;1.710427;741297.4;8.796293e+007
954.538;1.736356;-6.01257;808.1147;83.50535;2;2;0;5.468838;5.324535;1.736356;741642.9;8.807212e+007
960.538;1.756499;-6.105057;802.3695;82.91168;2;2;0;5.53228;5.384669;1.756499;736370.3;8.749859e+007
966.538;1.779213;-6.231937;791.2341;81.76102;2;2;0;5.603821;5.452437;1.779213;726150.8;8.634276e+007
972.538;1.80857;-6.391719;790.3174;81.6663;2;2;0;5.696284;5.539955;1.80857;725309.5;8.631824e+007
978.538;1.847945;-6.597;793.6958;82.0154;2;2;0;5.8203;5.657219;1.847945;728410;8.678894e+007
984.538;1.885767;-6.789402;805.9036;83.27687;2;2;0;5.939423;5.769726;1.885767;739613.7;8.822304e+007
990.538;1.918981;-6.977623;803.7484;83.05416;2;2;0;6.044034;5.868424;1.918981;737635.7;8.807398e+007
996.538;1.950481;-7.152851;805.0765;83.19141;2;2;0;6.143247;5.961938;1.950481;738854.6;8.830206e+007
1002.538;1.984338;-7.358075;803.6743;83.04651;2;2;0;6.249884;6.062353;1.984338;737567.7;8.823682e+007
1008.538;2.014392;-7.545157;811.6857;83.87435;2;2;0;6.344541;6.151402;2.014392;744920.1;8.91958e+007
1014.538;2.040802;-7.700191;812.366;83.94466;2;2;0;6.427724;6.229592;2.040802;745544.5;8.934039e+007
1020.538;2.063517;-7.786314;800.269;82.69463;2;2;0;6.499265;6.29679;2.063517;734442.6;8.806917e+007
1026.538;2.088106;-7.833095;805.8038;83.26656;2;2;0;6.576711;6.369483;2.088106;739522.1;8.874276e+007
1032.538;2.110017;-7.842032;810.257;83.72672;2;2;0;6.645721;6.434214;2.110017;743608.9;8.929096e+007
1038.538;2.130052;-7.850652;818.0984;84.53701;2;2;0;6.708826;6.493368;2.130052;750805.4;9.020845e+007
1044.538;2.147034;-7.867063;842.4655;87.05495;2;2;0;6.762312;6.54348;2.147034;773168.2;9.294187e+007
1050.538;2.154106;-7.877261;836.4819;86.43663;2;2;0;6.784585;6.56434;2.154106;767676.7;9.2301e+007
1056.538;2.15507;-7.882377;819.1384;84.64447;2;2;0;6.787622;6.567183;2.15507;751759.9;9.038982e+007
1062.538;2.156356;-7.886469;799.2189;82.58612;2;2;0;6.791671;6.570975;2.156356;733478.9;8.81951e+007
1068.538;2.161338;-7.890673;795.2215;82.17305;2;2;0;6.807363;6.585668;2.161338;729810.3;8.776687e+007
1074.538;2.166213;-7.893385;777.6623;80.3586;2;2;0;6.822718;6.600043;2.166213;713695.4;8.584124e+007
1080.538;2.167981;-7.8938;748.4767;77.34275;2;2;0;6.828286;6.605255;2.167981;686910.5;8.262394e+007
1086.538;2.168302;-7.893366;723.6018;74.77233;2;2;0;6.829298;6.606203;2.168302;664081.6;7.987876e+007
1092.538;2.190856;-7.890943;735.4807;75.99982;2;2;0;6.900333;6.672675;2.190856;674983.4;8.124407e+007
1098.538;2.231302;-7.885554;720.7392;74.47653;2;2;0;7.027723;6.791771;2.231302;661454.5;7.971054e+007
1104.538;2.287124;-7.878814;695.5611;71.87479;2;2;0;7.203539;6.955908;2.287124;638347.4;7.705231e+007
1110.538;2.346373;-7.876093;985.7248;101.8584;2;2;0;7.390152;7.12983;2.346373;904643.6;1.093859e+008
1116.538;2.373963;-7.888654;1154.247;119.2724;2;2;0;7.477047;7.210713;2.373963;1059304;1.281905e+008
1122.538;2.383873;-7.896561;1218.728;125.9355;2;2;0;7.508263;7.239752;2.383873;1118482;1.353911e+008
1126.908;2.383981;-7.898723;1214.378;125.486;2;2;0;7.508601;7.240067;2.383981;1114489;1.349083e+008
1132.908;2.373373;-7.894526;1106.741;114.3635;2;2;0;7.475192;7.208986;2.373373;1015706;1.229124e+008
1138.908;2.353391;-7.885904;915.2711;94.57821;2;2;0;7.412257;7.150411;2.353391;839985.1;1.015886e+008
1144.908;2.348516;-7.886147;889.8379;91.9501;2;2;0;7.396902;7.136115;2.348516;816643.9;9.875156e+007
1150.908;2.339623;-7.883099;820.2905;84.76353;2;2;0;7.368893;7.110032;2.339623;752817.2;9.100966e+007
1156.908;2.333784;-7.88258;789.3666;81.56805;2;2;0;7.350502;7.092901;2.333784;724436.9;8.756371e+007
1162.908;2.33282;-7.883319;798.1588;82.47657;2;2;0;7.347464;7.090072;2.33282;732505.9;8.853651e+007
1168.908;2.329927;-7.883164;786.8012;81.30296;2;2;0;7.338353;7.081583;2.329927;722082.6;8.726925e+007
1174.908;2.328427;-7.883584;789.1804;81.54881;2;2;0;7.333629;7.077182;2.328427;724266.1;8.752929e+007
1180.908;2.327356;-7.884227;795.5662;82.20866;2;2;0;7.330254;7.074038;2.327356;730126.6;8.823477e+007
1186.908;2.326338;-7.884657;801.8087;82.85373;2;2;0;7.327048;7.071051;2.326338;735855.6;8.892446e+007
1192.908;2.324463;-7.884215;799.1206;82.57597;2;2;0;7.321143;7.065549;2.324463;733388.6;8.862147e+007
1198.908;2.322642;-7.883888;797.6692;82.42599;2;2;0;7.315406;7.060204;2.322642;732056.6;8.845578e+007
1204.908;2.321195;-7.883633;798.9185;82.55508;2;2;0;7.31085;7.055958;2.321195;733203.2;8.859056e+007
1210.908;2.319641;-7.883258;799.0422;82.56786;2;2;0;7.305957;7.051398;2.319641;733316.6;8.860023e+007
1216.908;2.318516;-7.882975;802.6128;82.93682;2;2;0;7.302413;7.048096;2.318516;736593.5;8.899321e+007
1222.908;2.316856;-7.882965;801.7705;82.84978;2;2;0;7.297183;7.043221;2.316856;735820.6;8.889548e+007
1228.908;2.315141;-7.883117;800.4832;82.71676;2;2;0;7.291784;7.038189;2.315141;734639.1;8.874828e+007
1234.908;2.313534;-7.883261;800.6169;82.73058;2;2;0;7.286722;7.033471;2.313534;734761.9;8.875893e+007
1240.908;2.311927;-7.883426;800.7126;82.74047;2;2;0;7.28166;7.028753;2.311927;734849.7;8.876535e+007
1246.908;2.31032;-7.883506;800.5894;82.72774;2;2;0;7.276598;7.024034;2.31032;734736.6;8.874751e+007
1252.908;2.308713;-7.884595;801.7547;82.84815;2;2;0;7.271536;7.019315;2.308713;735806.1;8.887249e+007
1258.908;2.307106;-7.885121;802.8303;82.9593;2;2;0;7.266474;7.014597;2.307106;736793.2;8.898751e+007
1264.908;2.305499;-7.8854;803.2077;82.9983;2;2;0;7.261413;7.009878;2.305499;737139.6;8.902515e+007
1270.908;2.303891;-7.886237;802.9284;82.96943;2;2;0;7.256351;7.005158;2.303891;736883.2;8.898998e+007
1276.908;2.302177;-7.886769;801.9645;82.86983;2;2;0;7.250951;7.000124;2.302177;735998.6;8.887868e+007
1282.908;2.300463;-7.887397;801.411;82.81263;2;2;0;7.245552;6.995089;2.300463;735490.6;8.881286e+007
1288.908;2.298641;-7.887751;799.9663;82.66335;2;2;0;7.239815;6.98974;2.298641;734164.8;8.864803e+007
1294.908;2.297034;-7.889085;800.2357;82.69118;2;2;0;7.234754;6.98502;2.297034;734411.9;8.867369e+007
1300.908;2.295427;-7.889925;800.3078;82.69864;2;2;0;7.229692;6.9803;2.295427;734478.2;8.867749e+007
1306.908;2.29382;-7.891192;801.2727;82.79835;2;2;0;7.22463;6.975579;2.29382;735363.7;8.878022e+007
1312.908;2.292213;-7.891939;802.4634;82.92139;2;2;0;7.219568;6.970858;2.292213;736456.4;8.890795e+007
1318.908;2.290606;-7.892038;800.3388;82.70184;2;2;0;7.214506;6.966137;2.290606;734506.6;8.866837e+007
1324.908;2.288999;-7.890745;797.599;82.41872;2;2;0;7.209445;6.961416;2.288999;731992.2;8.836066e+007
1330.908;2.287391;-7.889462;794.9398;82.14394;2;2;0;7.204382;6.956694;2.287391;729551.7;8.80619e+007
1336.908;2.286213;-7.889365;796.3199;82.28655;2;2;0;7.20067;6.953232;2.286213;730818.3;8.821173e+007
1342.908;2.285195;-7.889373;798.5995;82.52212;2;2;0;7.197464;6.95024;2.285195;732910.4;8.846161e+007
1348.908;2.284177;-7.889049;800.4447;82.71278;2;2;0;7.194259;6.947251;2.284177;734603.8;8.866335e+007
1354.908;2.282892;-7.888874;799.388;82.60359;2;2;0;7.190209;6.943473;2.282892;733634;8.854296e+007
1360.908;2.281713;-7.888706;799.5905;82.62451;2;2;0;7.186497;6.940009;2.281713;733819.8;8.856232e+007
1366.908;2.280534;-7.888851;799.2174;82.58597;2;2;0;7.182785;6.936546;2.280534;733477.5;8.851794e+007
1372.908;2.279356;-7.888549;798.1648;82.47719;2;2;0;7.179073;6.933083;2.279356;732511.4;8.839829e+007
1378.908;2.278231;-7.888192;797.5056;82.40908;2;2;0;7.175529;6.929777;2.278231;731906.5;8.832237e+007
1384.908;2.277213;-7.888194;798.844;82.54739;2;2;0;7.172324;6.926785;2.277213;733134.8;8.846795e+007
1390.908;2.276249;-7.888101;799.2955;82.59404;2;2;0;7.169287;6.923952;2.276249;733549.2;8.851544e+007
1396.908;2.275177;-7.888004;798.8235;82.54526;2;2;0;7.165912;6.920803;2.275177;733115.9;8.846038e+007
1402.908;2.274213;-7.887672;798.6933;82.53181;2;2;0;7.162875;6.917969;2.274213;732996.5;8.844346e+007
1408.908;2.273249;-7.887979;798.6088;82.52307;2;2;0;7.159838;6.915135;2.273249;732918.9;8.843159e+007
1414.908;2.272177;-7.887769;797.7701;82.43641;2;2;0;7.156463;6.911985;2.272177;732149.2;8.833594e+007
1420.908;2.271213;-7.887372;796.7364;82.32959;2;2;0;7.153426;6.909151;2.271213;731200.5;8.821898e+007
1426.908;2.270249;-7.887322;796.1776;82.27186;2;2;0;7.150389;6.906317;2.270249;730687.8;8.815461e+007
1432.908;2.269231;-7.887398;794.8337;82.13298;2;2;0;7.147183;6.903325;2.269231;729454.3;8.800317e+007
1438.908;2.268213;-7.887043;792.5649;81.89854;2;2;0;7.143978;6.900333;2.268213;727372.1;8.774935e+007
1444.908;2.267195;-7.886941;790.5572;81.69108;2;2;0;7.140771;6.89734;2.267195;725529.6;8.752445e+007
1450.908;2.266284;-7.886873;789.5974;81.5919;2;2;0;7.137903;6.894663;2.266284;724648.8;8.741585e+007
1456.908;2.265213;-7.886747;787.0555;81.32923;2;2;0;7.134529;6.891514;2.265213;722315.9;8.713169e+007
1462.908;2.264356;-7.887003;786.0732;81.22773;2;2;0;7.131829;6.888993;2.264356;721414.4;8.702075e+007
1468.908;2.264248;-7.887178;792.866;81.92965;2;2;0;7.131491;6.888678;2.264248;727648.5;8.777246e+007
1474.908;2.264141;-7.887709;799.4773;82.61282;2;2;0;7.131154;6.888364;2.264141;733715.9;8.850406e+007
1480.908;2.263606;-7.887436;801.4199;82.81356;2;2;0;7.129467;6.886788;2.263606;735498.8;8.871772e+007
1486.908;2.262856;-7.887034;800.196;82.68708;2;2;0;7.127105;6.884584;2.262856;734375.6;8.858028e+007
1492.908;2.262106;-7.886781;799.2992;82.59441;2;2;0;7.124743;6.882379;2.262106;733552.5;8.847905e+007
1498.908;2.261409;-7.887048;798.7422;82.53686;2;2;0;7.122549;6.880331;2.261409;733041.3;8.841558e+007
1504.908;2.260713;-7.886915;798.3835;82.49979;2;2;0;7.120356;6.878284;2.260713;732712.1;8.837407e+007
1510.908;2.26007;-7.886463;796.8886;82.34532;2;2;0;7.11833;6.876393;2.26007;731340.2;8.820693e+007
1516.908;2.259427;-7.886053;796.444;82.29938;2;2;0;7.116305;6.874503;2.259427;730932.2;8.815606e+007
1522.908;2.258999;-7.885608;797.3161;82.3895;2;2;0;7.114956;6.873243;2.258999;731732.6;8.825148e+007
1528.908;2.258463;-7.885475;796.7229;82.32819;2;2;0;7.113269;6.871668;2.258463;731188.1;8.818442e+007
1534.908;2.258034;-7.885609;797.5611;82.41481;2;2;0;7.111919;6.870407;2.258034;731957.3;8.827608e+007
1540.908;2.257659;-7.886152;798.3241;82.49366;2;2;0;7.110738;6.869305;2.257659;732657.7;8.835957e+007
1546.908;2.257284;-7.886494;798.7969;82.54252;2;2;0;7.109557;6.868202;2.257284;733091.6;8.841092e+007
1552.908;2.256909;-7.887649;799.6505;82.63071;2;2;0;7.108376;6.867099;2.256909;733874.9;8.850442e+007
1558.908;2.256427;-7.888201;798.9019;82.55337;2;2;0;7.106857;6.865682;2.256427;733187.9;8.842031e+007
1564.908;2.255945;-7.888917;797.4642;82.40479;2;2;0;7.105339;6.864264;2.255945;731868.4;8.825993e+007
1570.908;2.25557;-7.889502;797.4988;82.40837;2;2;0;7.104157;6.863161;2.25557;731900.2;8.82628e+007
1576.908;2.255249;-7.889865;797.9518;82.45518;2;2;0;7.103146;6.862216;2.255249;732315.9;8.83121e+007
1582.908;2.255141;-7.890801;800.3601;82.70404;2;2;0;7.102807;6.8619;2.255141;734526.1;8.857835e+007
1588.908;2.254981;-7.891533;802.0522;82.87889;2;2;0;7.102301;6.861428;2.254981;736079.1;8.87652e+007
1594.908;2.254874;-7.892273;803.6673;83.04579;2;2;0;7.101964;6.861113;2.254874;737561.3;8.894367e+007
1600.908;2.254659;-7.892959;804.3188;83.11311;2;2;0;7.101289;6.860483;2.254659;738159.2;8.901521e+007
1606.908;2.254284;-7.893432;803.1751;82.99493;2;2;0;7.100108;6.85938;2.254284;737109.6;8.888765e+007
1612.908;2.253856;-7.893806;801.3724;82.80865;2;2;0;7.098758;6.858119;2.253856;735455.2;8.868703e+007
1618.908;2.253481;-7.894447;800.1329;82.68056;2;2;0;7.097577;6.857017;2.253481;734317.6;8.854888e+007
1624.908;2.253266;-7.894684;800.141;82.6814;2;2;0;7.096902;6.856386;2.253266;734325.1;8.854922e+007
1630.908;2.253106;-7.895228;800.6166;82.73055;2;2;0;7.096395;6.855914;2.253106;734761.6;8.860143e+007
1636.908;2.252891;-7.895541;800.7123;82.74044;2;2;0;7.095721;6.855284;2.252891;734849.4;8.861147e+007
1642.908;2.252677;-7.895986;800.5089;82.71941;2;2;0;7.095046;6.854653;2.252677;734662.7;8.858839e+007
1648.908;2.252463;-7.896715;801.0019;82.77036;2;2;0;7.094371;6.854023;2.252463;735115.1;8.86424e+007
1654.908;2.252302;-7.89748;801.5168;82.82357;2;2;0;7.093865;6.853551;2.252302;735587.7;8.869896e+007
1660.908;2.252088;-7.898322;801.2834;82.79945;2;2;0;7.09319;6.85292;2.252088;735373.5;8.867257e+007
1666.908;2.25182;-7.899141;800.6748;82.73656;2;2;0;7.092346;6.852133;2.25182;734814.9;8.860452e+007
1672.908;2.251606;-7.89958;800.5347;82.72208;2;2;0;7.091671;6.851502;2.251606;734686.4;8.858847e+007
1678.908;2.251498;-7.900408;801.1671;82.78744;2;2;0;7.091333;6.851187;2.251498;735266.8;8.865817e+007
1684.908;2.251284;-7.901191;800.8813;82.7579;2;2;0;7.090659;6.850557;2.251284;735004.5;8.862599e+007
1690.908;2.25107;-7.901942;800.7862;82.74807;2;2;0;7.089984;6.849927;2.25107;734917.2;8.86149e+007
1696.908;2.250856;-7.902516;801.0359;82.77388;2;2;0;7.089309;6.849296;2.250856;735146.4;8.864197e+007
1702.908;2.250641;-7.903354;801.7529;82.84797;2;2;0;7.088634;6.848666;2.250641;735804.4;8.872075e+007
1708.908;2.250481;-7.904732;803.4969;83.02818;2;2;0;7.088129;6.848194;2.250481;737404.9;8.891332e+007
1714.908;2.25032;-7.905915;805.2444;83.20876;2;2;0;7.087622;6.847721;2.25032;739008.7;8.910628e+007
1720.908;2.250052;-7.907495;806.5609;83.34479;2;2;0;7.086778;6.846933;2.250052;740216.9;8.925125e+007
1726.908;2.249195;-7.909948;804.7902;83.16182;2;2;0;7.084079;6.844413;2.249195;738591.9;8.905307e+007
1732.908;2.248391;-7.912372;802.736;82.94955;2;2;0;7.081547;6.842048;2.248391;736706.6;8.882366e+007
1738.908;2.247641;-7.915333;802.0527;82.87895;2;2;0;7.079185;6.839843;2.247641;736079.6;8.87461e+007
1744.908;2.246998;-7.91769;802.1764;82.89173;2;2;0;7.07716;6.837952;2.246998;736193.1;8.875811e+007
1750.908;2.246302;-7.920529;802.9218;82.96876;2;2;0;7.074967;6.835903;2.246302;736877.2;8.883877e+007
1756.908;2.245445;-7.924682;807.5876;83.45088;2;2;0;7.072268;6.833382;2.245445;741159.1;8.935276e+007
1762.908;2.244213;-7.928745;809.4391;83.6422;2;2;0;7.068387;6.829757;2.244213;742858.4;8.955436e+007
1768.908;2.242177;-7.932051;811.2737;83.83178;2;2;0;7.061975;6.823768;2.242177;744542.1;8.975196e+007
1774.908;2.238374;-7.937102;812.6875;83.97787;2;2;0;7.049995;6.812579;2.238374;745839.6;8.989831e+007
1780.908;2.231945;-7.94407;815.2558;84.24327;2;2;0;7.029748;6.793663;2.231945;748196.6;9.016536e+007
1786.908;2.223748;-7.951857;816.9485;84.41818;2;2;0;7.003932;6.76954;2.223748;749750.1;9.033077e+007
1792.908;2.211374;-7.960775;809.9873;83.69885;2;2;0;6.964956;6.733108;2.211374;743361.4;8.952844e+007
1798.908;2.195088;-7.97244;811.6657;83.87229;2;2;0;6.913662;6.685143;2.195088;744901.8;8.967094e+007
1804.908;2.179927;-7.98011;806.656;83.35462;2;2;0;6.865912;6.640471;2.179927;740304.2;8.907768e+007
1810.908;2.164981;-7.986903;809.33;83.63093;2;2;0;6.818837;6.59641;2.164981;742758.2;8.933359e+007
1816.908;2.150034;-7.992402;813.22;84.0329;2;2;0;6.771761;6.55233;2.150034;746328.2;8.97234e+007
1822.908;2.131499;-7.997031;819.5617;84.68821;2;2;0;6.713381;6.497638;2.131499;752148.3;9.037365e+007
1828.908;2.106963;-8.001967;822.0084;84.94103;2;2;0;6.636104;6.425195;2.106963;754393.8;9.057781e+007
1834.908;2.07857;-7.994435;823.8191;85.12814;2;2;0;6.546677;6.341299;2.07857;756055.5;9.070121e+007
1840.908;2.040106;-7.982082;816.7864;84.40143;2;2;0;6.42553;6.227531;2.040106;749601.3;8.982467e+007
1846.908;2.000195;-7.928424;811.9649;83.90321;2;2;0;6.299827;6.109347;2.000195;745176.4;8.918896e+007
1852.908;1.960177;-7.807934;802.1345;82.8874;2;2;0;6.173786;5.990706;1.960177;736154.6;8.800469e+007
1858.908;1.924285;-7.667426;795.1848;82.16926;2;2;0;6.060739;5.884175;1.924285;729776.6;8.714932e+007
1864.908;1.893106;-7.541601;788.889;81.51869;2;2;0;5.962538;5.791543;1.893106;723998.6;8.637928e+007
1870.908;1.86782;-7.438762;788.414;81.46961;2;2;0;5.882898;5.716357;1.86782;723562.7;8.626238e+007
1876.908;1.84441;-7.341499;791.8909;81.82889;2;2;0;5.809164;5.646695;1.84441;726753.6;8.658246e+007
1882.908;1.823677;-7.248906;800.8769;82.75745;2;2;0;5.743866;5.584963;1.823677;735000.4;8.751092e+007
1888.908;1.799624;-7.144604;806.1065;83.29784;2;2;0;5.668107;5.513293;1.799624;739799.8;8.801924e+007
1894.908;1.771177;-7.021559;808.0274;83.49633;2;2;0;5.578512;5.428468;1.771177;741562.8;8.815418e+007
1900.908;1.737856;-6.877728;804.3119;83.1124;2;2;0;5.473562;5.329014;1.737856;738152.9;8.766161e+007
1906.908;1.705606;-6.738147;800.5939;82.7282;2;2;0;5.371988;5.232664;1.705606;734740.8;8.717235e+007
1912.908;1.677803;-6.623425;795.5462;82.2066;2;2;0;5.284417;5.149524;1.677803;730108.2;8.655074e+007
1918.908;1.655892;-6.540058;790.1067;81.64452;2;2;0;5.215407;5.083956;1.655892;725116.1;8.590262e+007
1924.908;1.638535;-6.461432;789.2865;81.55977;2;2;0;5.160739;5.031984;1.638535;724363.4;8.576885e+007
1930.908;1.623695;-6.383477;791.7598;81.81535;2;2;0;5.114001;4.98753;1.623695;726633.3;8.599938e+007
1936.908;1.61057;-6.297197;800.8392;82.75355;2;2;0;5.072663;4.948195;1.61057;734965.8;8.695135e+007
1942.908;1.589249;-6.149766;805.7358;83.25953;2;2;0;5.005509;4.884263;1.589249;739459.6;8.742709e+007
1948.908;1.559249;-5.937043;800.3625;82.70429;2;2;0;4.91102;4.794238;1.559249;734528.4;8.676592e+007
1954.908;1.533535;-5.751033;792.878;81.93089;2;2;0;4.83003;4.717009;1.533535;727659.5;8.588818e+007
1960.908;1.51366;-5.598322;794.1334;82.06062;2;2;0;4.767432;4.657277;1.51366;728811.6;8.59728e+007
1966.908;1.493678;-5.446405;792.7475;81.9174;2;2;0;4.704496;4.597187;1.493678;727539.8;8.577121e+007
1972.908;1.473695;-5.294587;792.3022;81.8714;2;2;0;4.641561;4.537061;1.473695;727131.1;8.567151e+007
1978.908;1.45366;-5.148433;786.8101;81.30388;2;2;0;4.578456;4.476738;1.45366;722090.8;8.502634e+007
1984.908;1.434106;-5.003858;784.012;81.01474;2;2;0;4.51687;4.417831;1.434106;719522.8;8.467407e+007
1990.908;1.419267;-4.889309;789.6351;81.59579;2;2;0;4.470132;4.373103;1.419267;724683.4;8.524323e+007
1996.908;1.404106;-4.770724;794.9691;82.14697;2;2;0;4.422382;4.327385;1.404106;729578.6;8.577982e+007
2002.908;1.385249;-4.62585;799.0037;82.56388;2;2;0;4.362989;4.270492;1.385249;733281.3;8.616613e+007
2008.908;1.362481;-4.455167;799.1568;82.5797;2;2;0;4.29128;4.201756;1.362481;733421.8;8.612343e+007
2014.908;1.33516;-4.253977;795.0452;82.15483;2;2;0;4.205228;4.119212;1.33516;729648.4;8.560963e+007
2020.908;1.314696;-4.102788;793.59;82.00447;2;2;0;4.140773;4.057339;1.314696;728313;8.540009e+007
2026.908;1.29466;-3.953219;792.6227;81.9045;2;2;0;4.077669;3.996725;1.29466;727425.2;8.52443e+007
2032.908;1.278749;-3.829524;796.8579;82.34215;2;2;0;4.027556;3.948564;1.278749;731312.1;8.565853e+007
2038.908;1.263749;-3.710665;796.9963;82.35645;2;2;0;3.980312;3.903139;1.263749;731439.1;8.56345e+007
2044.908;1.248803;-3.593;796.8269;82.33894;2;2;0;3.933237;3.857855;1.248803;731283.6;8.557753e+007
2050.908;1.233696;-3.472599;798.5559;82.51761;2;2;0;3.885656;3.812064;1.233696;732870.4;8.572396e+007
2056.908;1.217999;-3.34662;799.8884;82.6553;2;2;0;3.836218;3.764465;1.217999;734093.3;8.582613e+007
2062.908;1.199249;-3.195902;800.6061;82.72947;2;2;0;3.777163;3.707575;1.199249;734751.9;8.585429e+007
2068.908;1.184303;-3.071031;806.8533;83.37502;2;2;0;3.730088;3.662203;1.184303;740485.3;8.648497e+007
2074.908;1.164267;-2.908864;807.4666;83.43839;2;2;0;3.666983;3.601349;1.164267;741048.1;8.649806e+007
2080.908;1.140749;-2.723965;806.1352;83.3008;2;2;0;3.592911;3.529871;1.140749;739826.3;8.629373e+007
2086.908;1.115678;-2.534401;801.3298;82.80424;2;2;0;3.513946;3.453616;1.115678;735416.1;8.571394e+007
2092.908;1.094624;-2.37278;803.5938;83.03819;2;2;0;3.447636;3.389536;1.094624;737493.9;8.590105e+007
2098.908;1.073678;-2.211462;803.7997;83.05947;2;2;0;3.381663;3.325742;1.073678;737682.8;8.586826e+007
2104.908;1.051874;-2.046249;802.4041;82.91525;2;2;0;3.31299;3.259293;1.051874;736402;8.566223e+007
2110.908;1.029374;-1.876831;798.5204;82.51395;2;2;0;3.242124;3.190676;1.029374;732837.8;8.518915e+007
2116.908;1.009285;-1.729149;796.5774;82.31316;2;2;0;3.17885;3.129371;1.009285;731054.6;8.492977e+007
2122.908;0.9893564;-1.590369;795.8058;82.23343;2;2;0;3.116083;3.068519;0.9893564;730346.4;8.479589e+007
2128.908;0.9694279;-1.472369;796.2802;82.28245;2;2;0;3.053316;3.00763;0.9694279;730781.8;8.479479e+007
2134.908;0.9494458;-1.379734;802.9607;82.97277;2;2;0;2.990381;2.946541;0.9494458;736912.8;8.545397e+007
2140.908;0.9265708;-1.284308;805.7624;83.26228;2;2;0;2.918333;2.876561;0.9265708;739484.1;8.569215e+007
2146.908;0.901928;-1.177054;801.6216;82.8344;2;2;0;2.840718;2.801118;0.901928;735683.9;8.518749e+007
2152.908;0.8746066;-1.076794;798.8377;82.54672;2;2;0;2.754666;2.717408;0.8746066;733128.9;8.482061e+007
2158.908;0.8480887;-1.004905;802.8741;82.96382;2;2;0;2.671146;2.636093;0.8480887;736833.4;8.517991e+007
2164.908;0.8206067;-0.8935551;793.1327;81.95721;2;2;0;2.584588;2.551752;0.8206067;727893.2;8.407546e+007
2170.908;0.7958031;-0.8044072;791.8051;81.82003;2;2;0;2.506466;2.47557;0.7958031;726674.9;8.387082e+007
2176.908;0.7724995;-0.7227626;797.4404;82.40234;2;2;0;2.433069;2.403942;0.7724995;731846.6;8.440725e+007
2182.908;0.7494638;-0.6286174;799.8394;82.65023;2;2;0;2.360516;2.333087;0.7494638;734048.3;8.460121e+007
2188.908;0.7263746;-0.5281255;803.5906;83.03786;2;2;0;2.287794;2.262016;0.7263746;737490.9;8.49376e+007
2194.908;0.7021603;-0.4209872;805.9035;83.27686;2;2;0;2.211528;2.187429;0.7021603;739613.6;8.511855e+007
2200.908;0.6771424;-0.3167078;806.097;83.29685;2;2;0;2.132732;2.110307;0.6771424;739791.1;8.507335e+007
2206.908;0.652071;-0.2273881;803.9385;83.07381;2;2;0;2.053767;2.032962;0.652071;737810.2;8.477995e+007
2212.908;0.6271067;-0.1491955;807.147;83.40536;2;2;0;1.975139;1.955886;0.6271067;740754.8;8.505273e+007
2218.908;0.6021961;-0.1092826;810.7724;83.77998;2;2;0;1.89668;1.878918;0.6021961;744082;8.536903e+007
2224.908;0.575571;-0.1035379;810.4158;83.74313;2;2;0;1.812822;1.796586;0.575571;743754.7;8.526124e+007
2230.908;0.5474461;-0.1010256;807.1623;83.40694;2;2;0;1.72424;1.709543;0.5474461;740768.8;8.484507e+007
2236.908;0.5194818;-0.09875877;802.3386;82.90849;2;2;0;1.636163;1.622922;0.5194818;736341.9;8.426501e+007
2242.908;0.4966068;-0.09852907;808.1482;83.50882;2;2;0;1.564116;1.55201;0.4966068;741673.7;8.481499e+007
2248.908;0.474589;-0.09862589;815.2481;84.24247;2;2;0;1.494769;1.483707;0.474589;748189.6;8.55017e+007
2254.908;0.4484997;-0.09849523;813.955;84.10885;2;2;0;1.412598;1.402713;0.4484997;747002.8;8.529697e+007
2260.908;0.4185533;-0.09904877;811.7572;83.88174;2;2;0;1.318278;1.309664;0.4185533;744985.8;8.498754e+007
2266.908;0.3885533;-0.09938145;799.0908;82.57288;2;2;0;1.22379;1.216362;0.3885533;733361.3;8.35834e+007
2272.908;0.369214;-0.1001292;795.8825;82.24136;2;2;0;1.162879;1.156169;0.369214;730416.9;8.319773e+007
2278.908;0.3552319;-0.1011842;797.8278;82.44237;2;2;0;1.118841;1.112628;0.3552319;732202.1;8.336477e+007
2284.908;0.3426426;-0.1021457;800.4592;82.71428;2;2;0;1.079189;1.073408;0.3426426;734617.1;8.360692e+007
2290.908;0.3297319;-0.1018728;802.2601;82.90038;2;2;0;1.038526;1.03317;0.3297319;736269.8;8.376131e+007
2296.908;0.3170891;-0.1007357;805.8424;83.27055;2;2;0;0.9987057;0.9937516;0.3170891;739557.6;8.410218e+007
2302.908;0.3008034;-0.09851141;805.5343;83.23871;2;2;0;0.9474122;0.9429524;0.3008034;739274.8;8.402733e+007
2308.908;0.282857;-0.09604855;798.3668;82.49807;2;2;0;0.8908881;0.8869431;0.282857;732696.8;8.323304e+007
2314.908;0.2694105;-0.09511954;791.0938;81.74652;2;2;0;0.8485371;0.8449572;0.2694105;726022.1;8.244017e+007
2320.908;0.2608927;-0.09522055;785.4279;81.16105;2;2;0;0.8217092;0.8183516;0.2608927;720822.3;8.182795e+007
2326.908;0.2579998;-0.09597455;786.0665;81.22704;2;2;0;0.8125979;0.8093141;0.2579998;721408.3;8.188708e+007
2332.908;0.2570356;-0.09637939;786.8309;81.30602;2;2;0;0.8095608;0.8063014;0.2570356;722109.8;8.196425e+007
2338.908;0.2560713;-0.09672123;787.6526;81.39094;2;2;0;0.8065236;0.8032886;0.2560713;722863.9;8.204737e+007
2344.908;0.2549998;-0.09737406;786.1694;81.23766;2;2;0;0.803149;0.7999409;0.2549998;721502.7;8.189012e+007
2350.908;0.254732;-0.09789307;787.3411;81.35874;2;2;0;0.8023055;0.7991041;0.254732;722578;8.201148e+007
2356.908;0.254732;-0.09811647;787.5842;81.38387;2;2;0;0.8023055;0.7991041;0.254732;722801.1;8.203681e+007
2362.908;0.2546248;-0.09894036;786.3444;81.25575;2;2;0;0.8019679;0.7987692;0.2546248;721663.3;8.190739e+007
2368.908;0.2544641;-0.09924665;785.9737;81.21745;2;2;0;0.8014618;0.7982671;0.2544641;721323.1;8.186838e+007
2374.418;0.2544106;-0.0994367;788.7233;81.50157;2;2;0;0.8012931;0.7980998;0.2544106;723846.5;8.215464e+007
2379.42;0.2544106;-0.1002399;786.9486;81.31818;3;3;0;0.8012931;0.7980998;0.2544106;722217.8;8.196978e+007
2385.42;0.2554284;-0.1006498;789.2226;81.55317;3;3;0;0.8044989;0.8012801;0.2554284;724304.8;8.220926e+007
2391.42;0.2563927;-0.1013721;790.7816;81.71426;3;3;0;0.8075361;0.804293;0.2563927;725735.6;8.237413e+007
2397.42;0.2574106;-0.1017852;792.7021;81.91271;3;3;0;0.8107419;0.8074731;0.2574106;727498.1;8.257681e+007
2403.42;0.2584284;-0.1021297;797.8307;82.44267;3;3;0;0.8139477;0.810653;0.2584284;732204.8;8.311371e+007
2409.42;0.2594462;-0.1025345;800.0836;82.67547;3;3;0;0.8171535;0.8138329;0.2594462;734272.4;8.335105e+007
2415.42;0.2599284;-0.1026025;797.4492;82.40325;3;3;0;0.8186721;0.8153392;0.2599284;731854.8;8.307787e+007
2421.42;0.260357;-0.1025551;796.2852;82.28297;3;3;0;0.8200219;0.816678;0.260357;730786.4;8.295771e+007
2427.42;0.2610534;-0.1028492;795.9521;82.24855;3;3;0;0.8222154;0.8188536;0.2610534;730480.8;8.292481e+007
2433.42;0.261857;-0.1027238;796.0041;82.25393;3;3;0;0.8247464;0.8213639;0.261857;730528.5;8.293231e+007
2439.42;0.2628212;-0.1027422;797.0489;82.36189;3;3;0;0.8277835;0.8243761;0.2628212;731487.3;8.304366e+007
2445.42;0.2638927;-0.102887;798.5793;82.52003;3;3;0;0.831158;0.8277229;0.2638927;732891.8;8.32059e+007
2451.42;0.264857;-0.1028216;798.9368;82.55697;3;3;0;0.8341952;0.830735;0.264857;733219.9;8.324565e+007
2457.42;0.2658748;-0.1028876;799.7013;82.63597;3;3;0;0.837401;0.8339143;0.2658748;733921.6;8.332797e+007
2463.42;0.2668391;-0.10274;800.7668;82.74607;3;3;0;0.8404381;0.8369261;0.2668391;734899.4;8.34415e+007
2469.42;0.267857;-0.1027084;802.1206;82.88596;3;3;0;0.843644;0.8401052;0.267857;736141.9;8.358523e+007
2475.42;0.2688748;-0.102921;803.1731;82.99472;3;3;0;0.8468498;0.8432841;0.2688748;737107.8;8.369756e+007
2481.42;0.269732;-0.1027564;803.8058;83.0601;3;3;0;0.8495495;0.8459612;0.269732;737688.4;8.376573e+007
2487.42;0.2705891;-0.1026707;804.2615;83.10719;3;3;0;0.8522492;0.848638;0.2705891;738106.7;8.381547e+007
2493.42;0.2713927;-0.1026608;804.1467;83.09532;3;3;0;0.8547801;0.8511475;0.2713927;738001.3;8.38056e+007
2499.42;0.2720891;-0.1028347;804.3093;83.11213;3;3;0;0.8569735;0.8533223;0.2720891;738150.6;8.382438e+007
2505.42;0.2727855;-0.1028634;811.592;83.86467;3;3;0;0.8591671;0.8554972;0.2727855;744834.1;8.458521e+007
2511.42;0.2728927;-0.1025779;807.7049;83.46301;3;3;0;0.8595045;0.8558318;0.2728927;741266.9;8.418038e+007
2517.42;0.2729998;-0.1026797;804.9907;83.18254;3;3;0;0.8598419;0.8561663;0.2729998;738775.9;8.389778e+007
2523.42;0.273107;-0.1025733;802.1775;82.89184;3;3;0;0.8601795;0.856501;0.273107;736194.1;8.360486e+007
2529.42;0.273107;-0.1023377;802.6313;82.93874;3;3;0;0.8601795;0.856501;0.273107;736610.6;8.365216e+007
2535.42;0.2732677;-0.1022651;799.883;82.65474;3;3;0;0.8606856;0.8570028;0.2732677;734088.3;8.336613e+007
2541.42;0.2734284;-0.101849;797.099;82.36706;3;3;0;0.8611918;0.8575047;0.2734284;731533.3;8.30764e+007
2547.42;0.2736427;-0.101548;794.469;82.09529;3;3;0;0.8618667;0.8581738;0.2736427;729119.6;8.280284e+007
2553.42;0.273857;-0.1011796;791.8655;81.82626;3;3;0;0.8625417;0.858843;0.273857;726730.3;8.253205e+007
2559.42;0.2740712;-0.1006951;793.2595;81.97031;3;3;0;0.8632165;0.8595121;0.2740712;728009.6;8.26779e+007
2565.42;0.274232;-0.1002121;789.8992;81.62308;3;3;0;0.8637227;0.8600139;0.274232;724925.7;8.232807e+007
2571.42;0.2743391;-0.09959965;786.4489;81.26656;3;3;0;0.8640602;0.8603486;0.2743391;721759.3;8.196874e+007
2577.42;0.2744998;-0.0992196;783.4936;80.96117;3;3;0;0.8645663;0.8608504;0.2744998;719047;8.166113e+007
2581.87;0.2744998;-0.09842813;780.2761;80.62868;3;3;0;0.8645663;0.8608504;0.2744998;716094.1;8.132578e+007
2587.87;0.265607;-0.09666623;754.9523;78.01189;3;3;0;0.8365574;0.8330777;0.265607;692853.4;7.866451e+007
2593.87;0.2556427;-0.09565813;721.4976;74.5549;3;3;0;0.8051739;0.8019496;0.2556427;662150.6;7.51552e+007
2599.87;0.2456248;-0.09321739;688.9044;71.18693;3;3;0;0.7736215;0.7706444;0.2456248;632238.3;7.173765e+007
2605.87;0.235607;-0.09077709;652.0042;67.3739;3;3;0;0.7420693;0.7393295;0.235607;598373.3;6.787386e+007
2611.87;0.2256427;-0.08771662;617.514;63.80991;3;3;0;0.7106857;0.7081723;0.2256427;566720.1;6.426339e+007
2617.87;0.2155713;-0.08461135;582.7708;60.21977;3;3;0;0.6789647;0.6766701;0.2155713;534834.8;6.062864e+007
2623.87;0.205607;-0.08094651;547.3097;56.55545;3;3;0;0.6475812;0.6454933;0.205607;502290.5;5.692169e+007
2629.87;0.1955892;-0.07718347;514.0298;53.11652;3;3;0;0.6160288;0.6141392;0.1955892;471748.1;5.344373e+007
2635.87;0.1855713;-0.07321752;478.923;49.48881;3;3;0;0.5844766;0.5827751;0.1855713;439529;4.977806e+007
2641.87;0.1754999;-0.06944474;446.1935;46.10676;3;3;0;0.5527556;0.5512335;0.1754999;409491.7;4.636162e+007
2647.87;0.165482;-0.06559326;413.8886;42.76857;3;3;0;0.5212033;0.5198497;0.165482;379844;4.299149e+007
2653.87;0.1554642;-0.06174679;382.3664;39.51127;3;3;0;0.4896509;0.488456;0.1554642;350914.7;3.970474e+007
2659.87;0.1454999;-0.05768656;351.6396;36.33616;3;3;0;0.4582674;0.4572205;0.1454999;322715.3;3.650268e+007
2665.87;0.1354285;-0.05376868;321.3853;33.20988;3;3;0;0.4265464;0.4256393;0.1354285;294949.6;3.335154e+007
2671.87;0.1254642;-0.04997045;292.1663;30.19058;3;3;0;0.3951629;0.3943841;0.1254642;268134.1;3.030988e+007
2677.87;0.1154999;-0.0463412;264.2214;27.30293;3;3;0;0.3637793;0.3631192;0.1154999;242487.8;2.740226e+007
2683.87;0.1054821;-0.04249771;236.9672;24.48666;3;3;0;0.332227;0.3316764;0.1054821;217475.3;2.456801e+007
2689.87;0.09557137;-0.03854052;210.2883;21.72984;3;3;0;0.3010122;0.30056;0.09557137;192991;2.179525e+007
2695.87;0.08549994;-0.03483051;184.5698;19.07225;3;3;0;0.2692912;0.2689292;0.08549994;169388;1.912361e+007
2701.87;0.07558924;-0.03141018;159.5938;16.49139;3;3;0;0.2380763;0.2377934;0.07558924;146466.3;1.653065e+007
2707.87;0.06557138;-0.02808025;135.9889;14.05222;3;3;0;0.206524;0.2063111;0.06557138;124803.1;1.408124e+007
2713.87;0.05560711;-0.02517446;113.4141;11.71948;3;3;0;0.1751405;0.1749873;0.05560711;104085.2;1.174001e+007
2719.87;0.04558926;-0.02249659;92.21335;9.528732;3;3;0;0.1435882;0.1434852;0.04558926;84628.3;9542414
2725.87;0.0355714;-0.01978602;73.36044;7.580594;3;3;0;0.1120359;0.1119732;0.0355714;67326.15;7589087
2731.87;0.02549998;-0.0176317;58.26312;6.020535;3;3;0;0.08031491;0.08028268;0.02549998;53470.66;6025370
2737.87;0.0155357;-0.01671986;53.02926;5.479702;3;3;0;0.04893135;0.04891938;0.0155357;48667.32;5482383
2743.87;0.005517854;-0.0162948;52.83105;5.459219;3;3;0;0.01737907;0.01737756;0.005517854;48485.41;5460168
2745.1;0.003482141;-0.01643683;52.84694;5.460861;3;3;0;0.01096737;0.01096677;0.003482141;48499.99;5461460