File: Ensayos/Resistencia/comp/Clavo7/clavo7a.raw
"Test Type";"Manual"
"Method Name:";"C:\INSTRON\user\template\CYCLE.MTM"
"Name:";""
"Operator ID:";""
"Company:";""
"Lab name:";""
"Test date:";"13/06/2017"
"Temperature:";""
"Humidity:";""
"Note 1:";""
"Note 2:";""
"Note 3:";""
"Geometry:";"Rectangular"
"Specimen";1
"Specimen name:";""
"Width:";0.250000;"in"
"Thickness:";0.060000;"in"
"Length:";1.250000;"in"
"Diameter:";0.039370;"in"
"Inner diameter:";0.019685;"in"
"Outer diameter:";0.039370;"in"
"Wall thickness:";0.019685;"in"
"Area:";0.015000;"in*in"
"Linear density:";1.000000;"den"
"Sled weight:";2.204623;"lbf"
"Loading span:";0.000000;"mm"
"Support span:";1.000000;"mm"
"Span ratio:";"2"
"Fixture type:";"3-point"
"Comment:";""
"Included"
"Final Width:";0.250000;"in"
"Final Thickness:";0.060000;"in"
"Final Length:";1.250000;"in"
"Final Diameter:";0.039370;"in"
"Final Inner diameter:";0.019685;"in"
"Final Outer diameter:";0.039370;"in"
"Final Wall thickness:";0.019685;"in"
"Final Area:";0.015000;"in*in"
"Final Linear density:";1.000000;"den"
"Time sec";"Extension mm";"Strain 1 %";"Load N";"Stress MPa";"Cycle Count ";"Total Cycle Count ";"Repetitions Count ";"Strain [Exten.] %";"True strain %";"Tenacity gf/tex";"True stress Pa"
0;0;0.0002532608;0.0121077;0.001251132;0;0;0;0;0;11.11178;1251.132
6;5.35714e-005;0.0002544354;0.1816874;0.0187744;0;0;0;0.0001687288;0.0001687287;166.7426;18774.43
12;0.0001607142;0.0002329015;-0.05989394;-0.006189052;0;0;0;0.0005061864;0.0005061851;-54.96733;-6189.084
18;0.000267857;0.0004978469;0.1215196;0.01255705;0;0;0;0.000843644;0.0008436404;111.5239;12557.16
24;0.0003749997;0.0005261542;0.07506507;0.00775674;0;0;0;0.001181102;0.001181095;68.89056;7756.831
30;0.0004821425;0.0004924047;0.0007436756;7.684663e-005;0;0;0;0.001518559;0.001518548;0.6825043;76.8478
36;0.0005892853;0.0006265804;-0.06864451;-0.007093281;0;0;0;0.001856017;0.001856;-62.99813;-7093.412
42;0.0006964281;0.0005239616;0.2313132;0.02390242;0;0;0;0.002193474;0.00219345;212.2865;23902.94
48;0.0008035709;0.0006111935;-0.02771048;-0.002863423;0;0;0;0.002530932;0.0025309;-25.43115;-2863.495
54;0.0008571423;0.000654144;-0.01778535;-0.001837823;0;0;0;0.002699661;0.002699624;-16.32241;-1837.873
60;0.0009642851;0.0006336279;0.1858865;0.01920831;0;0;0;0.003037118;0.003037072;170.5963;19208.89
66;0.001071428;0.0009420326;0.1282147;0.01324888;0;0;0;0.003374576;0.003374519;117.6684;13249.33
72;0.001178571;0.0009031541;0.03093031;0.003196139;0;0;0;0.003712033;0.003711965;28.38613;3196.257
78;0.001285713;0.0007714449;0.1718503;0.0177579;0;0;0;0.004049491;0.004049409;157.7147;17758.62
84.00001;0.001446428;0.0007564887;0.07007304;0.007240895;0;0;0;0.004555678;0.004555574;64.30915;7241.225
90.00001;0.001446428;0.001005734;0.1270694;0.01313053;0;0;0;0.004555678;0.004555574;116.6173;13131.13
96.00001;0.00155357;0.00104336;-0.1509237;-0.01559548;0;0;0;0.004893135;0.004893015;-138.5094;-15596.24
102;0.001660713;0.001000096;-0.1777335;-0.01836583;0;0;0;0.005230593;0.005230456;-163.1139;-18366.79
108;0.001767856;0.001151186;0.07694434;0.007950932;0;0;0;0.00556805;0.005567895;70.61526;7951.374
114;0.001874999;0.001136386;0.04261728;0.004403795;0;0;0;0.005905509;0.005905334;39.11178;4404.055
120;0.001982142;0.001084274;0.5653925;0.05842401;0;0;0;0.006242966;0.006242771;518.8859;58427.66
126;0.002089284;0.001190103;0.21252;0.02196044;0;0;0;0.006580424;0.006580207;195.0391;21961.89
132;0.002196427;0.001343503;0.5648346;0.05836636;0;0;0;0.006917881;0.006917642;518.3739;58370.4
138;0.00230357;0.001222991;0.5193785;0.05366922;0;0;0;0.007255339;0.007255075;476.6568;53673.11
144;0.002410713;0.0012762;0.4185116;0.04324628;0;0;0;0.007592796;0.007592507;384.0868;43249.57
150;0.002464284;0.001455519;0.7976653;0.08242559;0;0;0;0.007761525;0.007761224;732.053;82431.98
156;0.002571427;0.001461666;0.6479948;0.0669596;0;0;0;0.008098982;0.008098654;594.6937;66965.02
162;0.00267857;0.001661148;0.8232125;0.08506546;0;0;0;0.00843644;0.008436084;755.4988;85072.63
168;0.002785712;0.002040458;0.8408017;0.08688302;0;0;0;0.008773897;0.008773512;771.6412;86890.64
174;0.002892855;0.002370005;0.7361175;0.07606563;0;0;0;0.009111355;0.00911094;675.5679;76072.56
180;0.002946427;0.00273753;0.4542482;0.04693907;0;0;0;0.009280084;0.009279653;416.8838;46943.43
186;0.003053569;0.002830282;0.6796203;0.07022757;0;0;0;0.009617541;0.009617079;623.7179;70234.33
192;0.003160712;0.003248079;0.831317;0.08590294;0;0;0;0.009954999;0.009954504;762.9367;85911.49
198;0.003267855;0.00358855;0.8706947;0.08997197;0;0;0;0.01029246;0.01029193;799.0754;89981.23
204;0.003374998;0.003930313;0.8546911;0.08831826;0;0;0;0.01062991;0.01062935;784.3881;88327.64
210;0.003482141;0.00427646;0.6687555;0.06910487;0;0;0;0.01096737;0.01096677;613.7468;69112.45
216;0.003589283;0.004315496;0.666788;0.06890157;0;0;0;0.01130483;0.01130419;611.9411;68909.36
222;0.003696426;0.004706356;0.413549;0.04273348;0;0;0;0.01164229;0.01164161;379.5324;42738.46
228;0.003803569;0.005211972;0.5883849;0.0607999;0;0;0;0.01197974;0.01197903;539.9871;60807.18
234;0.00385714;0.005453934;0.7065181;0.07300702;0;0;0;0.01214847;0.01214774;648.4032;73015.89
240;0.003964283;0.005710305;0.1765192;0.01824035;0;0;0;0.01248593;0.01248515;161.9995;18242.63
246;0.004071426;0.005732348;0.02952078;0.003050487;0;0;0;0.01282339;0.01282257;27.09254;3050.878
252;0.004178569;0.005618728;-0.09222418;-0.009529851;0;0;0;0.01316085;0.01315998;-84.63824;-9531.105
258;0.004285712;0.005309188;-0.002427696;-0.0002508624;0;0;0;0.0134983;0.01349739;-2.228005;-250.8963
264;0.004392855;0.005309775;-0.08194664;-0.008467836;0;0;0;0.01383576;0.01383481;-75.20609;-8469.008
270;0.004499997;0.005148075;-0.02377568;-0.002456825;0;0;0;0.01417322;0.01417221;-21.82001;-2457.174
276;0.00460714;0.005033514;0.05427501;0.005608428;0;0;0;0.01451068;0.01450962;49.81059;5609.242
282;0.004714283;0.004820994;0.1301234;0.01344611;0;0;0;0.01484813;0.01484703;119.42;13448.11
288;0.004821425;0.004863788;-0.1573545;-0.01626;0;0;0;0.01518559;0.01518444;-144.4113;-16262.47
294;0.004928568;0.00468165;-0.3479592;-0.03595586;0;0;0;0.01552305;0.01552184;-319.3377;-35961.44
300;0.005035711;0.004441215;-0.3047935;-0.03149539;0;0;0;0.01586051;0.01585925;-279.7226;-31500.39
306;0.005089282;0.004669004;-0.2637419;-0.02725339;0;0;0;0.01602923;0.01602795;-242.0477;-27257.76
312;0.005196425;0.00461513;0.4109649;0.04246646;0;0;0;0.01636669;0.01636535;377.1608;42473.41
318;0.005303568;0.004445521;0.4478761;0.04628062;0;0;0;0.01670415;0.01670276;411.0359;46288.35
324;0.005410711;0.004495363;0.3052236;0.03153984;0;0;0;0.01704161;0.01704016;280.1173;31545.21
330;0.005517854;0.004348619;0.6971215;0.07203603;0;0;0;0.01737907;0.01737756;639.7795;72048.55
336;0.005624996;0.004409188;0.1171443;0.01210494;0;0;0;0.01771652;0.01771495;107.5085;12107.08
342;0.005732139;0.004443133;0.4029484;0.04163809;0;0;0;0.01805398;0.01805235;369.8037;41645.6
348;0.005839282;0.004426454;0.4898966;0.05062275;0;0;0;0.01839144;0.01838975;449.5999;50632.06
354;0.005946425;0.004585374;0.4214481;0.04354972;0;0;0;0.0187289;0.01872714;386.7817;43557.88
360;0.005999996;0.004491095;0.5950507;0.0614887;0;0;0;0.01889762;0.01889584;546.1046;61500.32
366;0.006107139;0.004545243;0.4333994;0.04478469;0;0;0;0.01923508;0.01923323;397.75;44793.31
372;0.006214282;0.00478051;0.4625289;0.04779475;0;0;0;0.01957254;0.01957063;424.4834;47804.1
378;0.006267853;0.004717201;0.3749641;0.03874637;0;0;0;0.01974127;0.01973932;344.1213;38754.02
384;0.006374996;0.00488219;0.2904239;0.03001053;0;0;0;0.02007873;0.02007671;266.5349;30016.55
390;0.006482139;0.004385148;0.4110824;0.04247859;0;0;0;0.02041619;0.0204141;377.2686;42487.27
396;0.006589282;0.004710819;0.1572562;0.01624984;0;0;0;0.02075364;0.02075149;144.321;16253.21
402;0.006696424;0.00484108;0.5247816;0.05422754;0;0;0;0.0210911;0.02108888;481.6154;54238.97
408;0.006803567;0.004995928;0.5361162;0.05539879;0;0;0;0.02142856;0.02142626;492.0178;55410.66
414;0.00691071;0.004990016;0.5345306;0.05523494;0;0;0;0.02176601;0.02176365;490.5625;55246.96
420;0.007017853;0.005228259;0.5413138;0.05593587;0;0;0;0.02210347;0.02210103;496.7878;55948.23
426;0.007071424;0.005240396;0.5397575;0.05577505;0;0;0;0.0222722;0.02226972;495.3595;55787.47
432;0.007232138;0.005316627;0.4578599;0.04731229;0;0;0;0.02277839;0.02277579;420.1985;47323.06
438;0.00728571;0.005624914;0.6038894;0.06240203;0;0;0;0.02294712;0.02294448;554.2162;62416.35
444;0.007446424;0.005503736;0.6716919;0.0694083;0;0;0;0.0234533;0.02345055;616.4416;69424.58
450;0.007446424;0.005320385;0.696916;0.07201479;0;0;0;0.0234533;0.02345055;639.5909;72031.68
456;0.007553567;0.005673776;0.5732623;0.05923722;0;0;0;0.02379076;0.02378793;526.1083;59251.31
462;0.00766071;0.005538582;0.6225065;0.0643258;0;0;0;0.02412822;0.02412531;571.3019;64341.32
468;0.007767852;0.005689672;0.9001473;0.09301541;0;0;0;0.02446567;0.02446268;826.1053;93038.17
474;0.007874995;0.005919615;0.6696364;0.0691959;0;0;0;0.02480313;0.02480006;614.5551;69213.06
480;0.007982138;0.005992322;0.7715898;0.0797311;0;0;0;0.02514059;0.02513743;708.1223;79751.15
486;0.008089281;0.006188084;0.4546887;0.04698459;0;0;0;0.02547805;0.0254748;417.2881;46996.56
492;0.008196423;0.006210871;1.009001;0.1042637;0;0;0;0.0258155;0.02581217;926.0055;104290.6
498;0.008303566;0.006290781;0.4565386;0.04717575;0;0;0;0.02615296;0.02614954;418.9858;47188.09
504;0.008410709;0.006424761;0.3569344;0.03688329;0;0;0;0.02649042;0.02648691;327.5746;36893.07
510;0.008517852;0.006840992;0.4979718;0.05145719;0;0;0;0.02682788;0.02682428;457.0109;51471
516;0.008624995;0.006782107;0.7709731;0.07966738;0;0;0;0.02716534;0.02716165;707.5564;79689.02
522;0.008732137;0.007042158;0.5601364;0.05788088;0;0;0;0.02750279;0.02749901;514.0621;57896.8
528;0.008785709;0.006899995;0.4743921;0.04902062;0;0;0;0.02767153;0.0276677;435.3708;49034.18
534;0.008892851;0.00665028;0.805858;0.08327216;0;0;0;0.02800898;0.02800506;739.5718;83295.48
540;0.008999994;0.007239408;0.9171786;0.09477531;0;0;0;0.02834644;0.02834242;841.7357;94802.18
546;0.009107137;0.006821338;0.9444289;0.09759118;0;0;0;0.0286839;0.02867978;866.7445;97619.17
552;0.00921428;0.00724168;1.043123;0.1077896;0;0;0;0.02902135;0.02901714;957.3203;107820.9
558;0.009321422;0.007352129;1.163135;0.1201909;0;0;0;0.02935881;0.0293545;1067.461;120226.2
564;0.009428565;0.00769534;1.236517;0.1277737;0;0;0;0.02969627;0.02969186;1134.807;127811.6
570;0.009482137;0.007629055;1.086289;0.11225;0;0;0;0.029865;0.02986054;996.9354;112283.6
576;0.009642851;0.007526006;1.187743;0.1227337;0;0;0;0.03037118;0.03036657;1090.044;122770.9
582;0.009696422;0.007545151;1.309958;0.1353626;0;0;0;0.03053991;0.03053525;1202.206;135403.9
588;0.009749994;0.007934602;1.089049;0.1125353;0;0;0;0.03070864;0.03070393;999.4686;112569.8
594;0.009857137;0.007557289;1.398579;0.1445202;0;0;0;0.0310461;0.03104128;1283.539;144565
600;0.00996428;0.007847527;1.26594;0.1308141;0;0;0;0.03138356;0.03137863;1161.81;130855.1
606;0.01007142;0.008374167;1.452081;0.1500487;0;0;0;0.03172101;0.03171599;1332.64;150096.3
612;0.01017856;0.0085556;1.187097;0.1226669;0;0;0;0.03205847;0.03205333;1089.452;122706.2
618;0.01028571;0.008363557;1.229528;0.1270515;0;0;0;0.03239593;0.03239068;1128.393;127092.7
624;0.01039285;0.008575529;1.093865;0.1130329;0;0;0;0.03273339;0.03272803;1003.888;113069.9
630;0.01049999;0.008160277;1.543141;0.1594582;0;0;0;0.03307085;0.03306538;1416.209;159510.9
636;0.01055356;0.008588763;1.329896;0.1374229;0;0;0;0.03323957;0.03323405;1220.505;137468.5
642;0.01066071;0.008938317;1.020483;0.1054501;0;0;0;0.03357703;0.03357139;936.5425;105485.5
648.0001;0.01076785;0.008869526;1.404305;0.1451119;0;0;0;0.03391449;0.03390874;1288.794;145161.1
654.0001;0.01087499;0.008566132;1.457044;0.1505615;0;0;0;0.03425195;0.03424608;1337.194;150613.1
660.0001;0.01098214;0.008997868;1.21282;0.125325;0;0;0;0.03458941;0.03458342;1113.059;125368.3
666.0001;0.01108928;0.009038743;1.395907;0.144244;0;0;0;0.03492686;0.03492077;1281.086;144294.4
672.0001;0.01119642;0.008917918;1.332274;0.1376686;0;0;0;0.03526432;0.03525811;1222.688;137717.2
678.0001;0.01130356;0.009346051;1.562286;0.1614366;0;0;0;0.03560178;0.03559544;1433.78;161494
684.0001;0.01141071;0.009500039;1.449116;0.1497422;0;0;0;0.03593924;0.03593278;1329.918;149796.1
690.0001;0.01151785;0.009154556;0.6775061;0.0700091;0;0;0;0.03627669;0.03627011;621.7775;70034.5
696.0001;0.01162499;0.009519654;0.9951119;0.1028284;0;0;0;0.03661415;0.03660745;913.2585;102866.1
702.0001;0.01173213;0.009425374;1.399079;0.1445717;0;0;0;0.03695161;0.03694478;1283.997;144625.2
708.0001;0.01183928;0.01015436;1.710694;0.1767721;0;0;0;0.03728906;0.03728211;1569.98;176838
714.0001;0.01194642;0.009736089;1.451406;0.1499789;0;0;0;0.03762652;0.03761945;1332.02;150035.4
720.0001;0.01194642;0.01038402;1.632467;0.1686886;0;0;0;0.03762652;0.03761945;1498.188;168752.1
726.0001;0.01205356;0.0099629;1.384484;0.1430637;0;0;0;0.03796398;0.03795678;1270.603;143118
732.0001;0.01221428;0.01079838;1.520442;0.1571126;0;0;0;0.03847016;0.03846277;1395.377;157173.1
738.0001;0.01226785;0.01078722;1.328956;0.1373258;0;0;0;0.03863889;0.03863143;1219.642;137378.8
744.0001;0.01237499;0.01067583;1.498242;0.1548187;0;0;0;0.03897635;0.03896876;1375.004;154879
750.0001;0.01248213;0.0100331;0.903994;0.09341291;0;0;0;0.03931381;0.03930608;829.6356;93449.63
756.0001;0.01258928;0.01076725;1.313657;0.1357449;0;0;0;0.03965127;0.03964341;1205.602;135798.7
762.0001;0.01269642;0.01115921;1.43922;0.1487197;0;0;0;0.03998872;0.03998073;1320.836;148779.1
768.0001;0.01280356;0.01168812;1.651378;0.1706427;0;0;0;0.04032618;0.04031805;1515.543;170711.5
774.0001;0.01285713;0.01097033;1.450143;0.1498484;0;0;0;0.04049491;0.04048671;1330.861;149909.1
780.0001;0.01296428;0.01162544;1.528635;0.1579592;0;0;0;0.04083237;0.04082404;1402.896;158023.7
786.0001;0.01307142;0.01324306;1.580756;0.1633452;0;0;0;0.04116983;0.04116136;1450.731;163412.4
792.0001;0.01317856;0.01420598;1.729752;0.1787414;0;0;0;0.04150729;0.04149867;1587.47;178815.6
798.0001;0.01328571;0.01317161;1.543845;0.159531;0;0;0;0.04184474;0.04183599;1416.856;159597.8
804.0001;0.01339285;0.01464312;1.60601;0.1659547;0;0;0;0.0421822;0.04217331;1473.907;166024.7
810.0001;0.01349999;0.0137419;1.611178;0.1664887;0;0;0;0.04251966;0.04251062;1478.65;166559.5
816.0001;0.01355356;0.01505547;1.255075;0.1296914;0;0;0;0.04268839;0.04267928;1151.839;129746.7
822.0001;0.01366071;0.0140545;1.396495;0.1443047;0;0;0;0.04302584;0.04301659;1281.625;144366.8
828.0001;0.01376785;0.01429697;1.6707;0.1726393;0;0;0;0.0433633;0.0433539;1533.276;172714.2
834.0001;0.01387499;0.01583504;1.527019;0.1577923;0;0;0;0.04370076;0.04369122;1401.414;157861.3
840.0001;0.01398213;0.01567812;1.511251;0.1561629;0;0;0;0.04403822;0.04402852;1386.942;156231.7
846.0001;0.01408928;0.01623659;1.507492;0.1557745;0;0;0;0.04437568;0.04436583;1383.493;155843.6
852.0001;0.01419642;0.01588179;1.439132;0.1487106;0;0;0;0.04471313;0.04470314;1320.755;148777.1
858.0001;0.01430356;0.01684565;1.585543;0.1638398;0;0;0;0.04505059;0.04504045;1455.123;163913.6
864.0001;0.0144107;0.01631211;1.487847;0.1537445;0;0;0;0.04538805;0.04537775;1365.464;153814.3
870.0001;0.01451785;0.01792657;0.8572165;0.08857922;0;0;0;0.04572551;0.04571505;786.7058;88619.72
876.0001;0.01462499;0.01642804;1.661597;0.1716987;0;0;0;0.04606296;0.04605236;1524.921;171777.8
882.0001;0.01473213;0.01857603;1.610268;0.1663947;0;0;0;0.04640042;0.04638966;1477.814;166471.9
888.0001;0.01483928;0.01876154;1.596613;0.1649837;0;0;0;0.04673788;0.04672696;1465.283;165060.8
894.0001;0.01494642;0.01806204;1.346135;0.1391008;0;0;0;0.04707533;0.04706426;1235.408;139166.3
900.0001;0.01494642;0.02017189;1.244651;0.1286142;0;0;0;0.04707533;0.04706426;1142.272;128674.7
906.0001;0.01510713;0.02099891;1.427092;0.1474665;0;0;0;0.04758152;0.04757021;1309.706;147536.7
912.0001;0.01521428;0.01877457;1.403131;0.1449905;0;0;0;0.04791898;0.0479075;1287.716;145060
918.0001;0.01526785;0.02123582;1.382723;0.1428816;0;0;0;0.0480877;0.04807614;1268.986;142950.3
924.0001;0.01542856;0.02091876;1.541379;0.1592761;0;0;0;0.04859389;0.04858209;1414.592;159353.5
930.0001;0.0155357;0.02067856;1.426887;0.1474453;0;0;0;0.04893135;0.04891938;1309.518;147517.4
936.0001;0.01558928;0.0210132;1.518504;0.1569124;0;0;0;0.04910008;0.04908803;1393.599;156989.4
942.0001;0.01569642;0.02221421;1.575999;0.1628536;0;0;0;0.04943754;0.04942532;1446.365;162934.1
948.0001;0.01580356;0.024175;1.174764;0.1213925;0;0;0;0.04977499;0.04976261;1078.133;121452.9
954.0001;0.0159107;0.02344426;1.441569;0.1489624;0;0;0;0.05011245;0.0500999;1322.992;149037.1
960.0001;0.01601785;0.02412493;1.447882;0.1496148;0;0;0;0.05044991;0.05043719;1328.786;149690.3
966.0001;0.01612499;0.02293571;1.515979;0.1566514;0;0;0;0.05078737;0.05077448;1391.281;156731
972.0001;0.01623213;0.02424787;1.388272;0.1434551;0;0;0;0.05112483;0.05111176;1274.08;143528.4
978.0001;0.01633927;0.02396628;1.461184;0.1509894;0;0;0;0.05146228;0.05144905;1340.994;151067.1
984.0001;0.01639285;0.02316596;1.54088;0.1592245;0;0;0;0.05163101;0.05161768;1414.134;159306.7
990.0001;0.01649999;0.02486609;1.188183;0.1227792;0;0;0;0.05196847;0.05195497;1090.449;122843
996.0001;0.01660713;0.02613392;1.487994;0.1537597;0;0;0;0.05230593;0.05229225;1365.599;153840.1
1002;0.01671428;0.0267238;1.603808;0.1657271;0;0;0;0.05264339;0.05262954;1471.886;165814.4
1008;0.01676785;0.03385183;1.41059;0.1457612;0;0;0;0.05281211;0.05279818;1294.561;145838.2
1014;0.01687499;0.04151125;1.530367;0.1581382;0;0;0;0.05314957;0.05313545;1404.486;158222.3
1020;0.01698213;0.05154969;1.299005;0.1342307;0;0;0;0.05348703;0.05347273;1192.154;134302.5
1026;0.01708927;0.06612063;1.701944;0.1758679;0;0;0;0.05382449;0.05381001;1561.949;175962.5
1032;0.01719642;0.07937741;1.727637;0.1785229;0;0;0;0.05416194;0.05414728;1585.53;178619.6
1038;0.01730356;0.09617797;1.665209;0.1720719;0;0;0;0.0544994;0.05448456;1528.236;172165.7
1044;0.01735713;0.1117495;1.569069;0.1621375;0;0;0;0.05466813;0.0546532;1440.005;162226.1
1050;0.01751784;0.1255081;1.447001;0.1495238;0;0;0;0.05517431;0.0551591;1327.978;149606.3
1056;0.01757142;0.1400715;1.685382;0.1741565;0;0;0;0.05534305;0.05532774;1546.75;174252.9
1062;0.01773213;0.1528525;1.741145;0.1799187;0;0;0;0.05584923;0.05583364;1597.926;180019.2
1068;0.0177857;0.1666194;1.540821;0.1592185;0;0;0;0.05601796;0.05600228;1414.08;159307.7
1074;0.01789285;0.1785456;1.437458;0.1485376;0;0;0;0.05635542;0.05633955;1319.219;148621.3
1080;0.01799999;0.1923706;1.713631;0.1770755;0;0;0;0.05669288;0.05667681;1572.675;177175.9
1086;0.01805356;0.2087933;1.717771;0.1775034;0;0;0;0.05686161;0.05684545;1576.475;177604.3
1092;0.01821427;0.2246207;1.625449;0.1679634;0;0;0;0.05736779;0.05735134;1491.747;168059.8
1098;0.01832142;0.2399005;1.81485;0.1875349;0;0;0;0.05770525;0.0576886;1665.569;187643.1
1104;0.01842856;0.2570613;1.85226;0.1914006;0;0;0;0.05804271;0.05802587;1699.902;191511.7
1110;0.0185357;0.2729241;1.308959;0.1352594;0;0;0;0.05838016;0.05836313;1201.29;135338.3
1116;0.01858927;0.2933649;1.782373;0.1841789;0;0;0;0.05854889;0.05853176;1635.763;184286.7
1122;0.01869642;0.3159953;1.701855;0.1758587;0;0;0;0.05888636;0.05886902;1561.869;175962.3
1128;0.01880356;0.3434904;1.889054;0.1952026;0;0;0;0.05922381;0.05920628;1733.669;195318.2
1134;0.0189107;0.3746889;1.709108;0.1766082;0;0;0;0.05956126;0.05954353;1568.525;176713.4
1140;0.01896427;0.4077405;1.703617;0.1760408;0;0;0;0.05973;0.05971217;1563.486;176146
1146;0.01907142;0.4441534;1.711575;0.1768631;0;0;0;0.06006745;0.06004942;1570.789;176969.3
1152;0.01917856;0.4753314;1.798788;0.1858751;0;0;0;0.06040491;0.06038667;1650.828;185987.4
1158;0.0192857;0.5053125;1.543845;0.159531;0;0;0;0.06074237;0.06072392;1416.856;159627.9
1164;0.01939284;0.5332063;1.70582;0.1762684;0;0;0;0.06107982;0.06106118;1565.507;176376
1170;0.01949999;0.5621222;1.615289;0.1669135;0;0;0;0.06141728;0.06139843;1482.423;167016
1176;0.01960713;0.5891848;1.768953;0.1827922;0;0;0;0.06175474;0.06173568;1623.447;182905.1
1182;0.01971427;0.6220289;1.945815;0.201068;0;0;0;0.0620922;0.06207293;1785.761;201192.8
1188;0.01976784;0.6511789;1.882183;0.1944926;0;0;0;0.06226092;0.06224155;1727.363;194613.7
1194;0.01987499;0.6740138;1.767133;0.1826041;0;0;0;0.06259838;0.0625788;1621.776;182718.4
1200;0.01998213;0.6890131;1.705438;0.1762289;0;0;0;0.06293584;0.06291604;1565.156;176339.8
1206;0.02008927;0.6970958;1.673401;0.1729185;0;0;0;0.0632733;0.06325329;1535.755;173027.9
1212;0.02019641;0.701677;1.70767;0.1764595;0;0;0;0.06361075;0.06359053;1567.204;176571.8
1218;0.02030356;0.70328;1.803956;0.1864091;0;0;0;0.06394821;0.06392777;1655.571;186528.3
1224;0.02035713;0.710545;1.62818;0.1682456;0;0;0;0.06411694;0.0640964;1494.253;168353.5
1230;0.02051784;0.7179482;1.599696;0.1653023;0;0;0;0.06462313;0.06460226;1468.113;165409.1
1236;0.02062499;0.7266825;1.565193;0.161737;0;0;0;0.06496058;0.0649395;1436.448;161842
1242;0.02067856;0.7318158;1.835522;0.189671;0;0;0;0.06512932;0.06510812;1684.541;189794.6
1248;0.0207857;0.7336578;1.764578;0.1823401;0;0;0;0.06546678;0.06544535;1619.432;182459.5
1254;0.02089284;0.7341114;1.697568;0.1754157;0;0;0;0.06580423;0.06578258;1557.934;175531.2
1260;0.02099999;0.7330158;1.828974;0.1889944;0;0;0;0.06614169;0.06611983;1678.531;189119.4
1266;0.02105356;0.7331742;1.787189;0.1846765;0;0;0;0.06631042;0.06628845;1640.183;184799
1272;0.02121427;0.7342491;1.830442;0.1891461;0;0;0;0.06681661;0.0667943;1679.879;189272.5
1278;0.02126784;0.7361988;1.72382;0.1781284;0;0;0;0.06698534;0.06696291;1582.026;178247.7
1284;0.02137499;0.7377277;1.536446;0.1587664;0;0;0;0.06732279;0.06730014;1410.065;158873.2
1290;0.02148213;0.7371377;1.800256;0.1860268;0;0;0;0.06766025;0.06763737;1652.175;186152.7
1296;0.02158927;0.7401013;1.66885;0.1724482;0;0;0;0.06799771;0.0679746;1531.578;172565.4
1302;0.02169641;0.7410808;1.613821;0.1667618;0;0;0;0.06833516;0.06831183;1481.075;166875.8
1308;0.02180356;0.7464198;1.997497;0.2064084;0;0;0;0.06867262;0.06864905;1833.192;206550.1
1314;0.0219107;0.7458743;1.768806;0.182777;0;0;0;0.06901008;0.06898628;1623.313;182903.2
1320;0.02201784;0.7466026;1.669232;0.1724876;0;0;0;0.06934753;0.0693235;1531.928;172607.2
1326;0.02212499;0.7469563;1.71827;0.1775549;0;0;0;0.069685;0.06966073;1576.933;177678.7
1332;0.02223213;0.7472339;1.870437;0.1932788;0;0;0;0.07002245;0.06999794;1716.583;193414.2
1338;0.02233927;0.7470133;1.617726;0.1671654;0;0;0;0.07035992;0.07033517;1484.66;167283
1344;0.02244641;0.7476555;1.721882;0.1779282;0;0;0;0.07069737;0.07067239;1580.248;178054
1350;0.02244641;0.7487032;1.671581;0.1727304;0;0;0;0.07069737;0.07067239;1534.084;172852.5
1356;0.02255356;0.7507055;2.03987;0.2107869;0;0;0;0.07103483;0.07100961;1872.079;210936.7
1362;0.0226607;0.7505051;1.886675;0.1949568;0;0;0;0.07137228;0.07134682;1731.486;195096
1368;0.02276784;0.7487734;1.740734;0.1798762;0;0;0;0.07170974;0.07168404;1597.549;180005.2
1374;0.02287499;0.7487184;1.900917;0.1964285;0;0;0;0.0720472;0.07202126;1744.556;196570
1380;0.02298213;0.7509361;1.834788;0.1895951;0;0;0;0.07238466;0.07235847;1683.867;189732.4
1386;0.02308927;0.7495869;1.89017;0.1953179;0;0;0;0.07272211;0.07269568;1734.693;195460
1392;0.02319641;0.7504459;1.878336;0.1940951;0;0;0;0.07305957;0.0730329;1723.832;194236.9
1398;0.02330356;0.7501745;1.612206;0.1665949;0;0;0;0.07339703;0.0733701;1479.593;166717.2
1404;0.02335713;0.7522364;1.662096;0.1717503;0;0;0;0.07356575;0.07353871;1525.38;171876.6
1410;0.02346427;0.749625;1.552948;0.1604716;0;0;0;0.07390321;0.07387592;1425.21;160590.2
1416;0.02357141;0.7531574;1.859689;0.1921683;0;0;0;0.07424067;0.07421313;1706.72;192311
1422;0.02367856;0.7522101;1.848766;0.1910395;0;0;0;0.07457813;0.07455033;1696.695;191182
1428;0.0237857;0.7527089;1.814556;0.1875045;0;0;0;0.07491559;0.07488754;1665.299;187645
1434;0.02389284;0.7511542;1.657163;0.1712405;0;0;0;0.07525305;0.07522474;1520.852;171369.4
1440;0.02399998;0.7522476;1.815261;0.1875773;0;0;0;0.0755905;0.07556194;1665.946;187719.1
1446;0.02405356;0.7519801;1.828387;0.1889337;0;0;0;0.07575923;0.07573055;1677.992;189076.8
1452;0.0241607;0.7520069;1.749191;0.1807501;0;0;0;0.07609669;0.07606775;1605.31;180887.6
1458;0.02426784;0.7531159;1.861774;0.1923837;0;0;0;0.07643414;0.07640495;1708.633;192530.8
1464;0.02437499;0.7526667;1.886646;0.1949538;0;0;0;0.07677161;0.07674215;1731.459;195103.5
1470;0.02448213;0.7543518;1.553741;0.1605536;0;0;0;0.07710906;0.07707935;1425.938;160677.4
1476;0.02458927;0.7530637;1.911224;0.1974935;0;0;0;0.07744652;0.07741654;1754.015;197646.5
1482;0.02469641;0.7539999;1.896424;0.1959642;0;0;0;0.07778398;0.07775375;1740.433;196116.6
1488;0.02480356;0.7531152;1.89754;0.1960795;0;0;0;0.07812143;0.07809094;1741.457;196232.7
1494;0.0249107;0.7531203;1.928197;0.1992474;0;0;0;0.07845889;0.07842813;1769.592;199403.7
1500;0.02501784;0.7537352;1.648265;0.1703211;0;0;0;0.07879635;0.07876532;1512.687;170455.3
1506;0.02512498;0.7529662;1.704146;0.1760954;0;0;0;0.0791338;0.07910251;1563.971;176234.8
1512;0.02517856;0.7536711;1.532834;0.1583931;0;0;0;0.07930254;0.07927112;1406.75;158518.7
1518;0.0252857;0.7525704;1.855637;0.1917495;0;0;0;0.07963999;0.0796083;1703.001;191902.3
1524;0.02544641;0.7528635;1.931985;0.1996388;0;0;0;0.08014618;0.08011408;1773.068;199798.8
1530;0.02549998;0.7533678;1.653962;0.1709097;0;0;0;0.08031491;0.08028268;1517.915;171047
1536;0.02560713;0.7535756;1.966106;0.2031647;0;0;0;0.08065236;0.08061986;1804.383;203328.6
1542;0.02571427;0.753938;1.822015;0.1882752;0;0;0;0.08098982;0.08095704;1672.144;188427.7
1548;0.02582141;0.7534987;2.017406;0.2084657;0;0;0;0.08132728;0.08129423;1851.463;208635.2
1554;0.02592855;0.7533497;1.525904;0.157677;0;0;0;0.08166474;0.08163141;1400.39;157805.8
1560;0.02598213;0.7533354;1.869233;0.1931544;0;0;0;0.08183347;0.0818;1715.478;193312.5
1566;0.02608927;0.7529907;1.919593;0.1983583;0;0;0;0.08217093;0.08213719;1761.696;198521.3
1572;0.02619641;0.7534187;1.814116;0.187459;0;0;0;0.08250839;0.08247437;1664.895;187613.7
1578;0.02630356;0.7533543;1.854374;0.1916191;0;0;0;0.08284584;0.08281155;1701.842;191777.8
1584;0.0264107;0.7533248;1.718975;0.1776278;0;0;0;0.0831833;0.08314872;1577.58;177775.5
1590;0.02651784;0.7530969;0.8859936;0.09155285;0;0;0;0.08352076;0.08348589;813.1158;91629.32
1596;0.02662498;0.753033;1.322114;0.1366188;0;0;0;0.08385822;0.08382308;1213.363;136733.3
1602;0.02667855;0.7529078;1.789391;0.1849041;0;0;0;0.08402694;0.08399166;1642.204;185059.5
1608;0.0267857;0.7519376;1.883621;0.1946412;0;0;0;0.0843644;0.08432883;1728.683;194805.5
1614;0.02689284;0.7523097;1.849764;0.1911427;0;0;0;0.08470186;0.08466601;1697.611;191304.6
1620;0.02699998;0.751754;1.892636;0.1955728;0;0;0;0.08503932;0.08500318;1736.957;195739.1
1626;0.02705355;0.7517118;2.055051;0.2123557;0;0;0;0.08520804;0.08517176;1886.012;212536.6
1632;0.0271607;0.7511888;1.900036;0.1963374;0;0;0;0.0855455;0.08550893;1743.748;196505.4
1638;0.02726784;0.7506737;2.003458;0.2070244;0;0;0;0.08588296;0.0858461;1838.662;207202.2
1644;0.02737498;0.7508375;1.786425;0.1845976;0;0;0;0.08622041;0.08618326;1639.482;184756.8
1650;0.02748213;0.7512733;1.328369;0.1372651;0;0;0;0.08655788;0.08652044;1219.104;137383.9
1656;0.02758927;0.7500107;1.981757;0.204782;0;0;0;0.08689533;0.0868576;1818.747;204960
1662;0.02769641;0.749746;1.953127;0.2018235;0;0;0;0.08723279;0.08719476;1792.472;201999.6
1668;0.02780355;0.7492676;1.901886;0.1965286;0;0;0;0.08757024;0.08753192;1745.446;196700.7
1674;0.02785712;0.7489558;2.006629;0.2073521;0;0;0;0.08773898;0.08770051;1841.573;207534
1680;0.02796427;0.7488232;2.03247;0.2100223;0;0;0;0.08807644;0.08803767;1865.288;210207.3
1686;0.02807141;0.7482344;2.06709;0.2135998;0;0;0;0.08841389;0.08837483;1897.061;213788.6
1692;0.02817855;0.7480182;2.045067;0.211324;0;0;0;0.08875135;0.08871199;1876.849;211511.6
1698;0.0282857;0.7474615;2.178029;0.2250635;0;0;0;0.08908881;0.08904914;1998.875;225264
1704;0.02839284;0.747305;1.846358;0.1907907;0;0;0;0.08942626;0.08938631;1694.485;190961.3
1710;0.02849998;0.7468482;2.010329;0.2077344;0;0;0;0.08976372;0.08972345;1844.969;207920.9
1716;0.02860713;0.7466617;1.182516;0.1221935;0;0;0;0.09010118;0.09006062;1085.248;122303.6
1722;0.02871427;0.746043;1.517094;0.1567667;0;0;0;0.09043863;0.09039776;1392.305;156908.5
1728;0.02882141;0.7463511;2.035524;0.2103379;0;0;0;0.09077609;0.09073492;1868.091;210528.8
1734;0.02887498;0.7455619;2.209919;0.2283588;0;0;0;0.09094483;0.0909035;2028.141;228566.4
1740;0.02898212;0.744987;2.013119;0.2080227;0;0;0;0.09128228;0.09124064;1847.529;208212.6
1746;0.02908927;0.7452383;1.873579;0.1936035;0;0;0;0.09161974;0.09157779;1719.467;193780.9
1752;0.02919641;0.7450124;1.968279;0.2033892;0;0;0;0.0919572;0.09191494;1806.377;203576.3
1758;0.02930355;0.7447416;2.064301;0.2133115;0;0;0;0.09229466;0.09225209;1894.501;213508.4
1764;0.0294107;0.7447259;1.98669;0.2052918;0;0;0;0.09263211;0.09258924;1823.274;205481.9
1770;0.02951784;0.7445218;1.50065;0.1550675;0;0;0;0.09296957;0.09292638;1377.214;155211.7
1776;0.02957141;0.7441703;1.651437;0.1706488;0;0;0;0.0931383;0.09309495;1515.597;170807.7
1782;0.02967855;0.7443011;1.695337;0.1751851;0;0;0;0.09347575;0.09343209;1555.886;175348.9
1788;0.0297857;0.7442966;1.87349;0.1935944;0;0;0;0.09381322;0.09376924;1719.386;193776
1794;0.02989284;0.7436606;1.988834;0.2055133;0;0;0;0.09415067;0.09410638;1825.242;205706.8
1800;0.02999998;0.74495;2.146697;0.2218258;0;0;0;0.09448814;0.09444352;1970.12;222035.4
1806;0.03010712;0.7431313;2.151131;0.222284;0;0;0;0.09482559;0.09478066;1974.189;222494.8
1812;0.0301607;0.743411;1.895044;0.1958216;0;0;0;0.09499431;0.09494922;1739.167;196007.6
1818;0.03026784;0.743414;2.189922;0.2262924;0;0;0;0.09533177;0.09528636;2009.789;226508.1
1824;0.03037498;0.7429902;1.820077;0.188075;0;0;0;0.09566923;0.0956235;1670.365;188254.9
1830;0.03048212;0.7427599;1.941234;0.2005946;0;0;0;0.09600669;0.09596063;1781.557;200787.2
1836;0.03058926;0.7424426;2.251117;0.2326159;0;0;0;0.09634414;0.09629776;2065.951;232840
1842;0.03069641;0.7424674;2.210565;0.2284255;0;0;0;0.0966816;0.09663489;2028.734;228646.4
1848;0.03080355;0.7426617;1.900917;0.1964285;0;0;0;0.09701905;0.09697202;1744.556;196619.1
1854;0.03085712;0.7420836;1.1486;0.1186889;0;0;0;0.09718779;0.09714059;1054.121;118804.2
1860;0.03096426;0.7417981;1.141112;0.1179151;0;0;0;0.09752524;0.09747771;1047.249;118030.1
1866;0.03107141;0.7408535;1.165426;0.1204276;0;0;0;0.0978627;0.09781484;1069.563;120545.4
1872;0.03123212;0.7410058;1.163869;0.1202667;0;0;0;0.09836888;0.09832053;1068.135;120385
1878;0.03133926;0.7412961;1.050082;0.1085087;0;0;0;0.09870634;0.09865766;963.7073;108615.8
1884;0.03144641;0.7424881;1.261271;0.1303316;0;0;0;0.09904381;0.09899479;1157.525;130460.7
1890;0.03149998;0.7438127;1.27055;0.1312905;0;0;0;0.09921253;0.09916335;1166.041;131420.7
1896;0.03160712;0.7448136;0.9510358;0.0982739;0;0;0;0.09954999;0.09950047;872.808;98371.73
1902;0.03166069;0.7463393;1.138087;0.1176026;0;0;0;0.09971872;0.09966903;1044.474;117719.9
1908;0.03176784;0.7448058;0.595403;0.0615251;0;0;0;0.1000562;0.1000062;546.4279;61586.66
1914;0.03187498;0.7362744;0.8151079;0.08422799;0;0;0;0.1003936;0.1003433;748.0609;84312.54
1920;0.03198212;0.7232393;0.8985323;0.09284852;0;0;0;0.1007311;0.1006804;824.6231;92942.05
1926;0.03208927;0.7130486;0.6458805;0.06674112;0;0;0;0.1010685;0.1010175;592.7534;66808.58
1932;0.03219641;0.706854;0.9209373;0.09516371;0;0;0;0.101406;0.1013546;845.1852;95260.21
1938;0.03230355;0.7035737;0.8541919;0.08826667;0;0;0;0.1017435;0.1016917;783.93;88356.48
1944;0.03241069;0.7016555;0.7504473;0.07754637;0;0;0;0.1020809;0.1020289;688.7189;77625.53
1950;0.03251783;0.6984145;0.9392313;0.09705409;0;0;0;0.1024184;0.102366;861.9745;97153.5
1956;0.03257141;0.6895042;0.8239465;0.08514132;0;0;0;0.1025871;0.1025345;756.1725;85228.66
1962;0.03267855;0.6731194;0.8189546;0.08462548;0;0;0;0.1029246;0.1028716;751.5912;84712.58
1968;0.03278569;0.6546776;0.7114807;0.07351982;0;0;0;0.103262;0.1032087;652.9576;73595.74
1974;0.03289284;0.6349451;0.8128467;0.08399433;0;0;0;0.1035995;0.1035459;745.9857;84081.35
1980;0.03299998;0.6159669;0.5705314;0.05895502;0;0;0;0.1039369;0.103883;523.6021;59016.3
1986;0.03305355;0.5974336;0.9196159;0.09502717;0;0;0;0.1041057;0.1040515;843.9725;95126.1
1992;0.03316069;0.5794315;0.7109815;0.07346824;0;0;0;0.1044431;0.1043886;652.4995;73544.97
1998;0.03326784;0.5635247;0.7372921;0.076187;0;0;0;0.1047806;0.1047257;676.6458;76266.83
2004;0.03337498;0.5494474;0.7841284;0.08102676;0;0;0;0.105118;0.1050628;719.6296;81111.93
2010;0.03348212;0.536068;1.089753;0.1126081;0;0;0;0.1054555;0.1053999;1000.115;112726.8
2016;0.03358926;0.5232783;0.7917631;0.08181568;0;0;0;0.105793;0.105737;726.6363;81902.24
2022;0.03369641;0.5105561;1.038865;0.1073496;0;0;0;0.1061304;0.1060741;953.4127;107463.5
2028;0.03380355;0.4977831;0.8830572;0.09124942;0;0;0;0.1064679;0.1064112;810.421;91346.58
2034;0.03385712;0.4849832;0.8214799;0.08488642;0;0;0;0.1066366;0.1065798;753.9087;84976.94
2040;0.03396427;0.4756566;0.8222728;0.08496836;0;0;0;0.1069741;0.1069169;754.6364;85059.25
2046;0.03407141;0.4627676;0.7093665;0.07330135;0;0;0;0.1073115;0.107254;651.0172;73380.01
2052;0.03417855;0.4499644;0.8057993;0.08326609;0;0;0;0.107649;0.1075911;739.5179;83355.73
2058;0.03428569;0.4382802;0.6894574;0.07124407;0;0;0;0.1079864;0.1079282;632.7458;71321.01
2064;0.03439283;0.428076;0.8301718;0.0857846;0;0;0;0.1083239;0.1082653;761.8857;85877.52
2070;0.03449998;0.4185089;0.9673332;0.09995797;0;0;0;0.1086613;0.1086024;887.7648;100066.6
2076;0.03455355;0.4092944;0.8352225;0.0863065;0;0;0;0.1088301;0.1087709;766.5209;86400.42
2082;0.03466069;0.4008636;0.6822631;0.07050066;0;0;0;0.1091675;0.109108;626.1433;70577.63
2088;0.03476783;0.3924218;0.6748339;0.06973298;0;0;0;0.109505;0.1094451;619.3251;69809.34
2094;0.03487498;0.3842316;0.8297901;0.08574515;0;0;0;0.1098425;0.1097822;761.5353;85839.33
2100;0.03498212;0.377848;0.6754505;0.0697967;0;0;0;0.1101799;0.1101193;619.8911;69873.6
2106;0.03508926;0.3718648;0.7200258;0.07440282;0;0;0;0.1105174;0.1104563;660.7997;74485.04
2112;0.03519641;0.3657721;0.8247101;0.08522021;0;0;0;0.1108548;0.1107934;756.8732;85314.68
2118;0.03530355;0.3602271;0.8040374;0.08308403;0;0;0;0.1111923;0.1111305;737.901;83176.42
2124;0.03541069;0.3551893;0.6408005;0.06621619;0;0;0;0.1115297;0.1114676;588.0912;66290.04
2130;0.03551783;0.3507344;1.428825;0.1476455;0;0;0;0.1118672;0.1118047;1311.296;147810.7
2136;0.03562498;0.344521;1.17585;0.1215047;0;0;0;0.1122047;0.1121418;1079.13;121641.1
2142;0.03573212;0.3344548;1.011204;0.1044912;0;0;0;0.1125421;0.1124788;928.0266;104608.8
2148;0.03578569;0.3201025;0.8004549;0.08271384;0;0;0;0.1127108;0.1126474;734.6132;82807.07
2154;0.03589283;0.3040482;0.7717366;0.07974627;0;0;0;0.1130483;0.1129844;708.2571;79836.42
2160;0.03599998;0.2843907;0.7353833;0.07598976;0;0;0;0.1133858;0.1133215;674.894;76075.92
2166;0.03610712;0.2648831;1.006858;0.1040422;0;0;0;0.1137232;0.1136586;924.0382;104160.5
2172;0.03621426;0.2477947;0.8377479;0.08656745;0;0;0;0.1140607;0.1139957;768.8386;86666.19
2178;0.03626783;0.2334318;0.8640878;0.08928925;0;0;0;0.1142294;0.1141642;793.0119;89391.24
2184;0.03637497;0.218913;0.6535153;0.06753004;0;0;0;0.1145668;0.1145013;599.7601;67607.41
2190;0.03648212;0.2041789;0.9972261;0.1030469;0;0;0;0.1149043;0.1148384;915.1989;103165.3
2196;0.03658926;0.1910977;0.8801208;0.090946;0;0;0;0.1152418;0.1151754;807.7261;91050.8
2202;0.03669641;0.1750241;0.7862132;0.0812422;0;0;0;0.1155792;0.1155125;721.543;81336.1
2208;0.03680355;0.1547027;0.7231972;0.07473052;0;0;0;0.1159167;0.1158496;663.7103;74817.15
2214;0.03691069;0.1293332;0.727866;0.07521297;0;0;0;0.1162541;0.1161866;667.9951;75300.41
2220;0.03701783;0.1034852;0.8116428;0.08386993;0;0;0;0.1165916;0.1165237;744.8808;83967.71
2226;0.03712498;0.07977767;0.5712067;0.05902481;0;0;0;0.1169291;0.1168608;524.2219;59093.83
2232;0.03723212;0.05806374;0.8370724;0.08649766;0;0;0;0.1172665;0.1171978;768.2187;86599.09
2238;0.03728569;0.04077776;0.9390845;0.09703893;0;0;0;0.1174352;0.1173663;861.8397;97152.89
2244;0.03739284;0.02970797;0.9099844;0.09403191;0;0;0;0.1177727;0.1177034;835.1332;94142.65
2250;0.03749998;0.02744808;1.171005;0.1210041;0;0;0;0.1181102;0.1180405;1074.683;121147
2256;0.03755355;0.02673038;0.8375422;0.0865462;0;0;0;0.1182789;0.118209;768.6498;86648.57
2262;0.03766069;0.02901501;0.8704305;0.08994467;0;0;0;0.1186163;0.1185461;798.8329;90051.36
2268;0.03776783;0.02962257;0.8640584;0.08928622;0;0;0;0.1189538;0.1188831;792.9849;89392.42
2274;0.03787498;0.02993482;0.7857728;0.08119668;0;0;0;0.1192913;0.1192202;721.1387;81293.54
2280;0.03798212;0.03011108;0.9677736;0.1000035;0;0;0;0.1196287;0.1195572;888.1689;100123.1
2286;0.03808926;0.02977637;0.7710025;0.07967041;0;0;0;0.1199662;0.1198943;707.5834;79765.99
2292;0.0381964;0.02812722;0.8272353;0.08548116;0;0;0;0.1203036;0.1202313;759.1907;85583.99
2298;0.03830355;0.02824335;0.9199683;0.09506358;0;0;0;0.1206411;0.1205684;844.296;95178.27
2304;0.03841069;0.02894755;0.9813694;0.1014084;0;0;0;0.1209785;0.1209054;900.6464;101531.1
2310;0.0385714;0.02671526;1.376703;0.1422596;0;0;0;0.1214847;0.121411;1263.462;142432.4
2316;0.0385714;0.02830078;0.9543541;0.09861679;0;0;0;0.1214847;0.121411;875.8533;98736.59
2322;0.03867855;0.02715671;0.9022909;0.09323692;0;0;0;0.1218222;0.121748;828.0726;93350.5
2328;0.03883926;0.02816962;0.932595;0.09636834;0;0;0;0.1223284;0.1222536;855.884;96486.23
2334;0.0389464;0.02814801;0.8890769;0.09187146;0;0;0;0.1226658;0.1225907;815.9455;91984.16
2340;0.0389464;0.0276393;0.7843632;0.08105103;0;0;0;0.1226658;0.1225907;719.8451;81150.45
2346;0.03910712;0.02773409;0.8629719;0.08917394;0;0;0;0.123172;0.1230962;791.9879;89283.78
2352;0.03921426;0.02754796;0.8713114;0.09003569;0;0;0;0.1235095;0.1234333;799.6413;90146.89
2358;0.0393214;0.02495375;0.9743219;0.1006801;0;0;0;0.1238469;0.1237703;894.1786;100804.8
2364;0.03937498;0.02661965;0.9056384;0.09358282;0;0;0;0.1240157;0.1239388;831.1448;93698.88
2370;0.03948212;0.02652862;1.117121;0.1154361;0;0;0;0.1243531;0.1242759;1025.232;115579.6
2376;0.03958926;0.02470352;0.7181758;0.07421164;0;0;0;0.1246906;0.1246129;659.1019;74304.18
2382;0.0396964;0.02490332;0.830348;0.0858028;0;0;0;0.125028;0.1249499;762.0474;85910.08
2388;0.03980354;0.02465114;0.9966095;0.1029832;0;0;0;0.1253655;0.125287;914.633;103112.3
2394;0.03991069;0.02458149;0.800778;0.08274723;0;0;0;0.1257029;0.125624;734.9097;82851.24
2400;0.04001783;0.02426306;0.9629579;0.09950585;0;0;0;0.1260404;0.125961;883.7494;99631.27
2406;0.04012497;0.02309929;0.9060496;0.09362531;0;0;0;0.1263779;0.1262981;831.5221;93743.63
2412;0.04023212;0.02351654;1.086054;0.1122258;0;0;0;0.1267153;0.1266351;996.7198;112368
2418;0.04028569;0.02277483;0.9444876;0.09759725;0;0;0;0.1268841;0.1268036;866.7984;97721.08
2424;0.04039283;0.02204158;0.9132145;0.09436569;0;0;0;0.1272215;0.1271407;838.0977;94485.74
2430;0.04049997;0.02139846;1.029586;0.1063907;0;0;0;0.127559;0.1274777;944.8967;106526.4
2436;0.04055355;0.01979532;1.066468;0.1102019;0;0;0;0.1277277;0.1276462;978.7448;110342.6
2442;0.04066069;0.02074242;0.8515491;0.08799358;0;0;0;0.1280652;0.1279832;781.5046;88106.27
2448;0.04076783;0.01970265;1.017106;0.1051011;0;0;0;0.1284026;0.1283203;933.4434;105236.1
2454;0.04087497;0.02025055;0.9491272;0.09807667;0;0;0;0.1287401;0.1286573;871.0563;98202.94
2460;0.04098211;0.01954087;0.7088966;0.0732528;0;0;0;0.1290775;0.1289943;650.5861;73347.35
2466;0.04108926;0.01911614;0.6936859;0.07168102;0;0;0;0.129415;0.1293313;636.6265;71773.78
2472;0.0411964;0.01849534;0.9510065;0.09827086;0;0;0;0.1297525;0.1296683;872.7811;98398.37
2478;0.04130354;0.01836833;0.866613;0.0895502;0;0;0;0.1300899;0.1300054;795.3294;89666.69
2484;0.04135712;0.01690285;0.7866244;0.08128468;0;0;0;0.1302586;0.1301739;721.9203;81390.56
2490;0.04151783;0.01748591;1.398609;0.1445232;0;0;0;0.1307648;0.1306794;1283.566;144712.2
2496;0.0415714;0.01672611;0.7821609;0.08082345;0;0;0;0.1309336;0.1308479;717.8239;80929.28
2502;0.04167855;0.01569601;0.8587728;0.08874004;0;0;0;0.131271;0.1311849;788.1341;88856.52
2508;0.04178568;0.01516353;1.118032;0.1155302;0;0;0;0.1316085;0.1315219;1026.067;115682.2
2514;0.04189283;0.01455506;0.9257237;0.0956583;0;0;0;0.1319459;0.131859;849.5779;95784.52
2520;0.04199997;0.01356212;1.016019;0.1049889;0;0;0;0.1322834;0.132196;932.4463;105127.8
2526;0.04205354;0.01450068;0.8505801;0.08789346;0;0;0;0.1324521;0.1323645;780.6154;88009.87
2532;0.04216069;0.01407451;0.9530326;0.09848024;0;0;0;0.1327896;0.1327015;874.6406;98611.01
2538;0.04226783;0.01379993;0.874101;0.09032395;0;0;0;0.133127;0.1330385;802.2015;90444.19
2544;0.04242855;0.01325406;0.9149763;0.09454774;0;0;0;0.1336332;0.133544;839.7145;94674.09
2550;0.04248212;0.01222271;0.9736758;0.1006134;0;0;0;0.1338019;0.1337125;893.5857;100748
2556;0.04264283;0.01153135;0.8961243;0.0925997;0;0;0;0.1343081;0.134218;822.4133;92724.07
2562;0.0426964;0.01116766;1.019514;0.10535;0;0;0;0.1344768;0.1343865;935.6533;105491.6
2568;0.04280354;0.01024163;0.9663935;0.09986086;0;0;0;0.1348143;0.1347235;886.9024;99995.49
2574;0.04291069;0.01019613;1.003716;0.1037175;0;0;0;0.1351518;0.1350605;921.1546;103857.7
2580;0.04301783;0.01020925;1.229675;0.1270667;0;0;0;0.1354892;0.1353975;1128.528;127238.8
2586;0.04312497;0.00935584;1.106462;0.1143346;0;0;0;0.1358267;0.1357345;1015.449;114489.9
2592;0.04317854;0.008812245;1.205361;0.1245543;0;0;0;0.1359954;0.135903;1106.214;124723.6
2598;0.04328569;0.009125897;1.000809;0.1034171;0;0;0;0.1363329;0.13624;918.4867;103558.1
2604;0.04339283;0.008678813;1.045766;0.1080627;0;0;0;0.1366703;0.136577;959.7458;108210.4
2610;0.04349997;0.007669108;1.137706;0.1175632;0;0;0;0.1370078;0.136914;1044.123;117724.2
2616;0.04355354;0.007776895;1.147807;0.118607;0;0;0;0.1371765;0.1370825;1053.394;118769.7
2622;0.04366068;0.007537359;1.087434;0.1123684;0;0;0;0.137514;0.1374195;997.9865;112522.9
2628;0.04376783;0.007586692;0.8284099;0.08560253;0;0;0;0.1378514;0.1377565;760.2687;85720.53
2634;0.04387497;0.006858532;0.8351051;0.08629436;0;0;0;0.1381889;0.1380935;766.4131;86413.61
2640;0.04398211;0.006528202;1.004949;0.1038449;0;0;0;0.1385263;0.1384305;922.2866;103988.8
2646;0.04408926;0.006421864;1.005595;0.1039117;0;0;0;0.1388638;0.1387675;922.8794;104056
2652;0.0441964;0.006347083;1.151066;0.1189438;0;0;0;0.1392013;0.1391045;1056.385;119109.3
2658;0.04430354;0.005511332;1.064559;0.1100046;0;0;0;0.1395387;0.1394415;976.993;110158.1
2664;0.04435712;0.005581219;0.9969619;0.1030196;0;0;0;0.1397074;0.13961;914.9564;103163.5
2670;0.04451783;0.005667433;0.8593307;0.08879769;0;0;0;0.1402136;0.1401154;788.6461;88922.19
2676;0.0445714;0.005550171;1.015961;0.1049828;0;0;0;0.1403823;0.1402839;932.3924;105130.2
2682;0.04467855;0.004959751;0.9028195;0.09329154;0;0;0;0.1407198;0.1406209;828.5577;93422.81
2688;0.04478569;0.004794331;0.9430488;0.09744857;0;0;0;0.1410573;0.1409579;865.4779;97586.03
2694;0.04489283;0.004708548;0.8524594;0.08808765;0;0;0;0.1413947;0.1412949;782.34;88212.2
2700;0.04499997;0.00465162;1.123699;0.1161158;0;0;0;0.1417322;0.1416318;1031.268;116280.3
2706;0.04505354;0.003839714;0.8579212;0.08865203;0;0;0;0.1419009;0.1418003;787.3525;88777.83
2712;0.04521426;0.004218515;0.903671;0.09337952;0;0;0;0.1424071;0.1423058;829.3392;93512.5
2718;0.04526783;0.003775895;0.9763773;0.1008925;0;0;0;0.1425758;0.1424743;896.065;101036.4
2724;0.04542854;0.003945112;1.015461;0.1049312;0;0;0;0.143082;0.1429798;931.9343;105081.4
2730;0.04553568;0.004050198;0.8671416;0.08960481;0;0;0;0.1434195;0.1433167;795.8145;89733.32
2736;0.04558926;0.00390686;1.04233;0.1077076;0;0;0;0.1435882;0.1434852;956.5927;107862.3
2742;0.0456964;0.003660121;0.9748798;0.1007378;0;0;0;0.1439257;0.1438222;894.6907;100882.8
2748;0.04580354;0.003728051;1.101499;0.1138218;0;0;0;0.1442631;0.1441592;1010.895;113986
2754;0.04591068;0.00326327;1.006535;0.1040088;0;0;0;0.1446006;0.1444961;923.7418;104159.2
2760;0.04601783;0.003350463;0.872163;0.09012369;0;0;0;0.144938;0.1448331;800.4229;90254.31
2766;0.0460714;0.003252895;0.9836011;0.101639;0;0;0;0.1451068;0.1450016;902.6946;101786.5
2772;0.04617854;0.003354653;1.017693;0.1051618;0;0;0;0.1454442;0.1453385;933.9824;105314.8
2778;0.04628568;0.002906982;1.054428;0.1089578;0;0;0;0.1457817;0.1456755;967.6957;109116.6
2784;0.04639283;0.003051612;0.9960516;0.1029255;0;0;0;0.1461191;0.1460125;914.1209;103075.9
2790;0.04655354;0.002753073;0.8513729;0.08797538;0;0;0;0.1466253;0.1465179;781.3429;88104.37
2796;0.04655354;0.003194519;0.8510793;0.08794504;0;0;0;0.1466253;0.1465179;781.0735;88073.99
2802;0.04671425;0.002976517;0.8984736;0.09284245;0;0;0;0.1471315;0.1470234;824.5693;92979.05
2808;0.04676783;0.003059873;1.103114;0.1139887;0;0;0;0.1473002;0.1471919;1012.377;114156.6
2814;0.04687497;0.002215548;0.8631774;0.08919518;0;0;0;0.1476377;0.1475288;792.1765;89326.87
2820;0.04698211;0.002862035;0.8128467;0.08399433;0;0;0;0.1479752;0.1478658;745.9857;84118.62
2826;0.04708925;0.002219502;0.7643367;0.07898162;0;0;0;0.1483126;0.1482027;701.4659;79098.76
2832;0.04719639;0.002301566;0.924373;0.09551873;0;0;0;0.1486501;0.1485397;848.3383;95660.72
2838;0.04730354;0.0025005;0.8829985;0.09124336;0;0;0;0.1489875;0.1488767;810.3671;91379.3
2844;0.04735711;0.002230034;1.035312;0.1069824;0;0;0;0.1491563;0.1490451;950.1519;107142
2850;0.04751782;0.002116531;0.8557776;0.08843052;0;0;0;0.1496624;0.1495506;785.3853;88562.87
2856;0.0475714;0.002151377;1.026385;0.10606;0;0;0;0.1498312;0.149719;941.9593;106218.9
2862;0.04767854;0.002146757;0.8995894;0.09295776;0;0;0;0.1501686;0.150056;825.5933;93097.35
2868;0.04778568;0.001731701;0.9392901;0.09706017;0;0;0;0.1505061;0.1503929;862.0284;97206.26
2874;0.04789283;0.002018493;1.03123;0.1065607;0;0;0;0.1508435;0.1507299;946.4059;106721.4
2880;0.04799997;0.002393183;0.8676408;0.0896564;0;0;0;0.151181;0.1510668;796.2726;89791.94
2886;0.04805354;0.001849511;0.9947596;0.102792;0;0;0;0.1513497;0.1512353;912.9352;102947.6
2892;0.04816068;0.001868617;0.9623118;0.09943908;0;0;0;0.1516872;0.1515723;883.1564;99589.92
2898;0.04826783;0.001955418;0.7917044;0.08180962;0;0;0;0.1520246;0.1519092;726.5824;81933.99
2904;0.04837497;0.001677044;0.8067977;0.08336926;0;0;0;0.1523621;0.1522462;740.4342;83496.28
2910;0.04848211;0.001918811;0.8635592;0.08923463;0;0;0;0.1526996;0.1525831;792.5268;89370.89
2916;0.04858925;0.001917284;0.8820588;0.09114625;0;0;0;0.153037;0.15292;809.5047;91285.74
2922;0.0486964;0.001968221;0.8950085;0.09248439;0;0;0;0.1533745;0.153257;821.3892;92626.24
2928;0.04880354;0.001817719;1.10517;0.1142011;0;0;0;0.1537119;0.1535939;1014.264;114376.7
2934;0.04891068;0.001893401;0.7994272;0.08260764;0;0;0;0.1540494;0.1539308;733.67;82734.9
2940;0.04901783;0.001591809;0.5872985;0.06068763;0;0;0;0.1543868;0.1542678;538.99;60781.32
2946;0.0490714;0.001411394;0.7157092;0.07395677;0;0;0;0.1545556;0.1544363;656.8383;74071.07
2952;0.04923211;0.001609271;1.046881;0.108178;0;0;0;0.1550618;0.1549417;960.7698;108345.7
2958;0.04933925;0.001595097;0.7527084;0.07778003;0;0;0;0.1553992;0.1552786;690.7941;77900.9
2964;0.04944639;0.001318798;0.8437088;0.08718342;0;0;0;0.1557367;0.1556155;774.3092;87319.2
2970;0.04944639;0.001337826;1.055808;0.1091004;0;0;0;0.1557367;0.1556155;968.9623;109270.3
2976;0.04960711;0.001151147;0.9333879;0.09645028;0;0;0;0.1562429;0.1561209;856.6117;96600.97
2982;0.04971425;0.001458338;0.7664216;0.07919706;0;0;0;0.1565803;0.1564579;703.3793;79321.06
2988;0.0498214;0.0012928;0.8087358;0.08356953;0;0;0;0.1569178;0.1567948;742.2129;83700.67
2994;0.04992854;0.001423022;0.777169;0.08030762;0;0;0;0.1572552;0.1571317;713.2426;80433.91
3000;0.04998211;0.001088111;0.8647925;0.08936207;0;0;0;0.157424;0.1573002;793.6586;89502.75
3006;0.05008926;0.001271032;0.8112905;0.08383352;0;0;0;0.1577614;0.1576371;744.5575;83965.78
3012;0.0501964;0.001243664;0.8095286;0.08365145;0;0;0;0.1580989;0.157974;742.9405;83783.71
3018;0.05030354;0.0007263804;0.9561747;0.09880491;0;0;0;0.1584363;0.158311;877.5241;98961.46
3024;0.05041068;0.001073115;0.8845254;0.09140114;0;0;0;0.1587738;0.1586479;811.7684;91546.27
3030;0.05051782;0.0009091446;0.9531501;0.09849237;0;0;0;0.1591113;0.1589848;874.7484;98649.08
3033;0.0505714;0.001060391;0.7968138;0.0823376;0;0;0;0.15928;0.1591533;731.2716;82468.74