File: Ensayos/Resistencia/comp/Clavo7/Clavo7b.raw
"Test Type";"Manual"
"Method Name:";"C:\INSTRON\user\template\CYCLE.MTM"
"Name:";""
"Operator ID:";""
"Company:";""
"Lab name:";""
"Test date:";"13/06/2017"
"Temperature:";""
"Humidity:";""
"Note 1:";""
"Note 2:";""
"Note 3:";""
"Geometry:";"Rectangular"
"Specimen";1
"Specimen name:";""
"Width:";0.250000;"in"
"Thickness:";0.060000;"in"
"Length:";1.250000;"in"
"Diameter:";0.039370;"in"
"Inner diameter:";0.019685;"in"
"Outer diameter:";0.039370;"in"
"Wall thickness:";0.019685;"in"
"Area:";0.015000;"in*in"
"Linear density:";1.000000;"den"
"Sled weight:";2.204623;"lbf"
"Loading span:";0.000000;"mm"
"Support span:";1.000000;"mm"
"Span ratio:";"2"
"Fixture type:";"3-point"
"Comment:";""
"Included"
"Final Width:";0.250000;"in"
"Final Thickness:";0.060000;"in"
"Final Length:";1.250000;"in"
"Final Diameter:";0.039370;"in"
"Final Inner diameter:";0.019685;"in"
"Final Outer diameter:";0.039370;"in"
"Final Wall thickness:";0.019685;"in"
"Final Area:";0.015000;"in*in"
"Final Linear density:";1.000000;"den"
"Time sec";"Extension mm";"Strain 1 %";"Load N";"Stress MPa";"Cycle Count ";"Total Cycle Count ";"Repetitions Count ";"Strain [Exten.] %";"True strain %";"Tenacity gf/tex";"True stress Pa"
0;0;0.0001954689;53.08056;5.485003;0;0;0;0;0;48714.4;5485003
6;0.0001071428;0.0002151627;52.5064;5.425672;0;0;0;0.0003374576;0.000337457;48187.46;5425690
12;0.0002142856;0.0001184166;52.22717;5.396819;0;0;0;0.0006749152;0.000674913;47931.21;5396855
18;0.0003214284;0.0003186429;51.97831;5.371103;0;0;0;0.001012373;0.001012368;47702.81;5371157
24;0.0004285712;0.0003601838;51.84593;5.357424;0;0;0;0.00134983;0.001349821;47581.32;5357496
30;0.0005357139;0.000380269;51.58004;5.329948;0;0;0;0.001687288;0.001687274;47337.3;5330038
36;0.0006428567;0.0004229453;51.43113;5.314561;0;0;0;0.002024746;0.002024725;47200.64;5314669
42;0.0006964281;0.0005087677;51.59698;5.331699;0;0;0;0.002193474;0.00219345;47352.85;5331816
48;0.0008035709;0.0005238414;51.53626;5.325424;0;0;0;0.002530932;0.0025309;47297.12;5325559
54;0.0009107137;0.0006393415;51.45971;5.317513;0;0;0;0.00286839;0.002868348;47226.87;5317666
60;0.001017856;0.0006574692;51.57123;5.329038;0;0;0;0.003205847;0.003205796;47329.22;5329209
66;0.001124999;0.0006978746;51.47929;5.319538;0;0;0;0.003543305;0.003543242;47244.84;5319726
72;0.001232142;0.0006479942;51.28736;5.299705;0;0;0;0.003880762;0.003880687;47068.7;5299911
78;0.001339285;0.0009193998;51.3813;5.309412;0;0;0;0.00421822;0.004218131;47154.91;5309636
84.00001;0.001392856;0.0007104817;51.45985;5.317529;0;0;0;0.004386948;0.004386852;47227;5317762
90.00001;0.001499999;0.0007832272;51.40045;5.31139;0;0;0;0.004724406;0.004724294;47172.48;5311641
96.00001;0.001607142;0.0007887086;51.25448;5.296306;0;0;0;0.005061864;0.005061736;47038.52;5296574
102;0.001714285;0.0009819264;51.30287;5.301307;0;0;0;0.005399322;0.005399176;47082.93;5301593
108;0.001821427;0.0009434395;51.42649;5.314082;0;0;0;0.005736779;0.005736615;47196.39;5314386
114;0.00192857;0.001094099;51.27932;5.298873;0;0;0;0.006074237;0.006074052;47061.32;5299195
120;0.002035713;0.00114163;51.5214;5.323889;0;0;0;0.006411694;0.006411489;47283.49;5324230
126;0.002142856;0.001132311;51.55743;5.327611;0;0;0;0.006749152;0.006748924;47316.55;5327971
132;0.002249999;0.001195817;51.33106;5.30422;0;0;0;0.007086609;0.007086358;47108.8;5304596
138;0.002357141;0.001176867;51.15564;5.286093;0;0;0;0.007424067;0.007423791;46947.81;5286485
144;0.002464284;0.001341934;51.27606;5.298537;0;0;0;0.007761525;0.007761224;47058.32;5298948
150;0.002571427;0.001342717;51.15863;5.286403;0;0;0;0.008098982;0.008098654;46950.56;5286831
156;0.00267857;0.001526499;51.50328;5.322016;0;0;0;0.00843644;0.008436084;47266.86;5322465
162;0.002732141;0.001595839;51.34753;5.305922;0;0;0;0.008605169;0.008604799;47123.92;5306379
168;0.002839284;0.001529984;51.48481;5.320107;0;0;0;0.008942626;0.008942227;47249.91;5320583
174;0.002946427;0.001398705;51.2205;5.292796;0;0;0;0.009280084;0.009279653;47007.34;5293287
180;0.002999998;0.001631546;51.24731;5.295566;0;0;0;0.009448812;0.009448366;47031.95;5296067
186;0.003107141;0.001554846;51.39622;5.310953;0;0;0;0.009786271;0.009785792;47168.6;5311473
192;0.004553569;0.00163041;52.04001;5.377478;0;0;0;0.01434195;0.01434092;47759.43;5378249
198;0.01457142;0.001717329;53.31351;5.509074;0;0;0;0.04589424;0.04588371;48928.19;5511602
204;0.02458927;0.003163507;67.41367;6.966093;0;0;0;0.07744652;0.07741654;61868.53;6971488
210;0.03455355;0.004290905;80.48996;8.317312;0;0;0;0.1088301;0.1087709;73869.22;8326364
216;0.04451783;0.00531541;95.3651;9.854414;0;0;0;0.1402136;0.1401154;87520.8;9868231
222;0.05458925;0.006486072;110.6744;11.43638;0;0;0;0.1719347;0.171787;101570.8;1.145604e+007
228;0.06455353;0.007330123;127.5266;13.17777;0;0;0;0.2033182;0.2031118;117036.8;1.320456e+007
234;0.07457138;0.008029505;144.4447;14.92598;0;0;0;0.2348705;0.2345951;132563.3;1.496103e+007
240;0.08458924;0.008584727;162.551;16.79697;0;0;0;0.2664228;0.2660685;149180.3;1.684172e+007
246;0.09466065;0.009002759;181.2817;18.73248;0;0;0;0.2981438;0.2977002;166370.3;1.878833e+007
252;0.1046249;0.009165164;200.8869;20.75835;0;0;0;0.3295273;0.3289856;184362.8;2.082676e+007
258;0.1146428;0.009349024;221.0166;22.83842;0;0;0;0.3610797;0.3604293;202836.8;2.292089e+007
264;0.1246071;0.008832406;242.0508;25.01196;0;0;0;0.3924632;0.391695;222140.8;2.511013e+007
270;0.1345713;0.008263911;263.8669;27.2663;0;0;0;0.4238467;0.422951;242162.4;2.738186e+007
276;0.1445892;0.007161688;286.5069;29.60577;0;0;0;0.4553991;0.4543653;262940.1;2.974059e+007
282;0.1545535;0.006228213;309.7976;32.01249;0;0;0;0.4867826;0.4856016;284315.1;3.216832e+007
288;0.1645713;0.004738145;334.2785;34.54218;0;0;0;0.5183349;0.5169961;306782.3;3.472122e+007
294;0.1745892;0.003194163;359.562;37.15481;0;0;0;0.5498871;0.5483808;329986.1;3.735912e+007
300;0.184607;0.001183327;385.8329;39.86948;0;0;0;0.5814394;0.5797556;354096.1;4.01013e+007
306;0.1945713;-0.00111485;413.4829;42.72665;0;0;0;0.612823;0.6109529;379471.7;4.298849e+007
312;0.2046427;-0.003520931;441.7901;45.65174;0;0;0;0.6445439;0.6424757;405450.5;4.594598e+007
318;0.2069463;-0.002270007;433.7445;44.82036;0;0;0;0.6517994;0.6496843;398066.7;4.51125e+007
324;0.2103213;-0.002623163;438.5104;45.31283;0;0;0;0.6624293;0.6602449;402440.5;4.5613e+007
330;0.2151963;-0.004185115;451.3733;46.64199;0;0;0;0.6777836;0.675497;414245.4;4.695813e+007
336;0.2173391;-0.003815711;449.2686;46.42451;0;0;0;0.6845328;0.6822005;412313.8;4.67423e+007
342;0.2193749;-0.003808155;448.7333;46.3692;0;0;0;0.6909444;0.6885683;411822.5;4.668958e+007
348;0.2223749;-0.004418269;454.1203;46.92586;0;0;0;0.7003933;0.6979519;416766.4;4.725452e+007
354;0.2246249;-0.004536275;455.3841;47.05645;0;0;0;0.7074798;0.704989;417926.3;4.738937e+007
360;0.226232;-0.004360637;454.9418;47.01075;0;0;0;0.7125418;0.7100152;417520.4;4.734572e+007
366;0.2273034;-0.0040879;451.649;46.67049;0;0;0;0.7159163;0.7133658;414498.4;4.700461e+007
372;0.2288034;-0.00430226;451.3853;46.64324;0;0;0;0.7206407;0.7180565;414256.4;4.697937e+007
378;0.2303034;-0.004567753;451.5313;46.65833;0;0;0;0.7253651;0.722747;414390.4;4.699677e+007
384;0.2318034;-0.004792607;452.6825;46.77729;0;0;0;0.7300895;0.7274373;415446.9;4.71188e+007
390;0.2333034;-0.005154572;453.2912;46.84018;0;0;0;0.734814;0.7321274;416005.5;4.718437e+007
396;0.2343749;-0.00524983;452.028;46.70965;0;0;0;0.7381885;0.7354772;414846.2;4.705445e+007
402;0.2353391;-0.005443009;450.6214;46.5643;0;0;0;0.7412257;0.7384921;413555.3;4.690945e+007
408;0.2366248;-0.005639868;451.0968;46.61343;0;0;0;0.7452751;0.7425116;413991.6;4.696082e+007
414;0.2380177;-0.005957669;452.5313;46.76166;0;0;0;0.7496621;0.7468661;415308.1;4.711221e+007
420;0.2396249;-0.00639426;455.2193;47.03942;0;0;0;0.754724;0.7518902;417775;4.739444e+007
426;0.2409641;-0.00669918;456.7331;47.19585;0;0;0;0.7589422;0.7560767;419164.3;4.755404e+007
432;0.2418749;-0.006683519;455.6295;47.08181;0;0;0;0.7618106;0.7589235;418151.5;4.744048e+007
438;0.2429463;-0.006688726;455.7651;47.09582;0;0;0;0.7651851;0.7622724;418276;4.745619e+007
444;0.2430534;-0.006214393;450.7456;46.57713;0;0;0;0.7655226;0.7626073;413669.3;4.693369e+007
450;0.2438034;-0.006038598;450.3659;46.53791;0;0;0;0.7678848;0.7649516;413320.9;4.689526e+007
456;0.2448213;-0.006425895;450.7286;46.57538;0;0;0;0.7710906;0.7681329;413653.7;4.693452e+007
462;0.245732;-0.0063896;451.2134;46.62548;0;0;0;0.773959;0.7709793;414098.7;4.698634e+007
468;0.2468034;-0.006500598;452.169;46.72422;0;0;0;0.7773335;0.7743278;414975.6;4.708742e+007
474;0.2476606;-0.006429066;452.7272;46.7819;0;0;0;0.7800332;0.7770067;415487.9;4.714682e+007
480;0.2484105;-0.006420687;452.9163;46.80145;0;0;0;0.7823954;0.7793506;415661.5;4.716762e+007
486;0.2492141;-0.006419043;453.3324;46.84444;0;0;0;0.7849264;0.7818618;416043.4;4.721214e+007
492;0.2499106;-0.006338076;452.8792;46.79762;0;0;0;0.7871199;0.7840382;415627.5;4.716597e+007
498;0.2504463;-0.008022771;449.733;46.47251;0;0;0;0.7888072;0.7857123;412740.1;4.683908e+007
504;0.2510891;-0.007773879;450.3704;46.53837;0;0;0;0.7908319;0.7877212;413325;4.690641e+007
510;0.2518391;-0.00744488;451.4459;46.6495;0;0;0;0.7931941;0.7900648;414312;4.701952e+007
516;0.2526427;-0.007204326;453.1009;46.82052;0;0;0;0.795725;0.7925758;415830.9;4.719309e+007
522;0.2533927;-0.00703041;454.159;46.92985;0;0;0;0.7980872;0.7949193;416801.9;4.730439e+007
528;0.2540891;-0.006812605;454.8505;47.00131;0;0;0;0.8002806;0.7970954;417436.6;4.737745e+007
534;0.254732;-0.006399467;455.3437;47.05228;0;0;0;0.8023055;0.7991041;417889.3;4.742978e+007
540;0.2553748;-0.006056569;456.476;47.16928;0;0;0;0.8043301;0.8011126;418928.3;4.754867e+007
546;0.2558034;-0.005435453;456.2923;47.1503;0;0;0;0.80568;0.8024517;418759.8;4.753017e+007
552;0.2561784;-0.00485529;456.6324;47.18544;0;0;0;0.8068611;0.8036234;419071.9;4.756616e+007
558;0.2565534;-0.00425884;456.3486;47.15611;0;0;0;0.8080422;0.8047951;418811.4;4.753716e+007
564;0.2569284;-0.003789831;456.9069;47.21381;0;0;0;0.8092234;0.8059667;419323.8;4.759587e+007
570;0.256982;-0.002923698;454.9827;47.01498;0;0;0;0.809392;0.806134;417557.9;4.739551e+007
576;0.2570891;-0.002371373;454.6409;46.97965;0;0;0;0.8097295;0.8064688;417244.2;4.736006e+007
582;0.2571963;-0.001397179;453.7164;46.88412;0;0;0;0.8100669;0.8068035;416395.8;4.726392e+007
588;0.2573034;-0.000721719;453.3752;46.84887;0;0;0;0.8104044;0.8071382;416082.7;4.722853e+007
594;0.2574106;-7.241295e-005;453.0763;46.81797;0;0;0;0.8107419;0.8074731;415808.3;4.719755e+007
600;0.2575177;0.0005053614;453.6436;46.8766;0;0;0;0.8110793;0.8078077;416329;4.725681e+007
606;0.2576248;0.001541534;453.5846;46.8705;0;0;0;0.8114168;0.8081425;416274.8;4.725081e+007
612;0.257732;0.00234698;454.1021;46.92398;0;0;0;0.8117542;0.8084772;416749.8;4.730488e+007
616.8501;0.2578391;0.002904983;454.769;46.99289;0;0;0;0.8120917;0.808812;417361.8;4.737452e+007
622.8501;0.2574106;0.00410587;453.3063;46.84174;0;0;0;0.8107419;0.8074731;416019.4;4.722151e+007
628.8501;0.2570891;0.004949451;452.3856;46.74661;0;0;0;0.8097295;0.8064688;415174.5;4.712513e+007
634.8501;0.2568748;0.006024541;451.9779;46.70447;0;0;0;0.8090546;0.8057993;414800.3;4.708234e+007
638.9901;0.2567677;0.007036713;452.2516;46.73276;1;1;0;0.8087171;0.8054645;415051.5;4.711069e+007
644.9901;0.2570891;0.008141403;454.9228;47.00878;1;1;0;0.8097295;0.8064688;417502.9;4.738942e+007
650.9901;0.2571963;0.009091126;456.6937;47.19177;1;1;0;0.8100669;0.8068035;419128.2;4.757406e+007
655.3961;0.2572498;0.009363941;458.2974;47.35749;1;1;0;0.8102357;0.8069709;420599.9;4.77412e+007
661.3961;0.2570356;0.01081047;458.9891;47.42897;1;1;0;0.8095608;0.8063014;421234.8;4.781294e+007
667.3961;0.2567141;0.0116299;458.8916;47.41889;1;1;0;0.8085484;0.8052972;421145.3;4.78023e+007
673.3961;0.256232;0.01310591;458.0109;47.32788;1;1;0;0.8070298;0.8037907;420337;4.770983e+007
679.3961;0.2556962;0.01405501;457.038;47.22735;1;1;0;0.8053425;0.8021169;419444.2;4.76077e+007
685.3961;0.2551605;0.01572353;456.8366;47.20654;1;1;0;0.8036553;0.8004431;419259.3;4.758592e+007
691.3961;0.2544106;0.01730232;454.7468;46.9906;1;1;0;0.8012931;0.7980998;417341.4;4.736713e+007
697.3961;0.2535534;0.01903834;452.6454;46.77345;1;1;0;0.7985933;0.7954215;415412.8;4.714698e+007
703.3961;0.2528034;0.02011214;451.5895;46.66434;1;1;0;0.7962313;0.7930781;414443.8;4.70359e+007
709.3961;0.2519462;0.02148405;450.7116;46.57362;1;1;0;0.7935315;0.7903996;413638.1;4.69432e+007
715.3961;0.2513034;0.0227565;450.092;46.5096;1;1;0;0.7915068;0.7883908;413069.5;4.687772e+007
721.3961;0.2507677;0.02369671;451.0719;46.61085;1;1;0;0.7898195;0.7867167;413968.8;4.697899e+007
727.3961;0.2501248;0.02514344;451.193;46.62337;1;1;0;0.7877948;0.7847079;414079.9;4.699067e+007
733.3961;0.2495891;0.02640885;451.8614;46.69244;1;1;0;0.7861075;0.7830337;414693.4;4.705949e+007
739.3961;0.2489463;0.02736523;452.3138;46.73919;1;1;0;0.7840827;0.7810247;415108.5;4.710566e+007
745.3961;0.2481963;0.02835771;452.4254;46.75072;1;1;0;0.7817206;0.778681;415211;4.711618e+007
751.3961;0.2473927;0.02963788;451.4609;46.65105;1;1;0;0.7791896;0.7761696;414325.8;4.701455e+007
757.3961;0.2465355;0.03093626;451.0777;46.61146;1;1;0;0.7764899;0.7734907;413974.2;4.697339e+007
763.3961;0.2456784;0.0319814;450.3474;46.536;1;1;0;0.7737903;0.7708119;413303.9;4.689609e+007
769.3961;0.2447677;0.03362651;449.601;46.45887;1;1;0;0.7709219;0.7679655;412618.9;4.681703e+007
775.3961;0.2440177;0.03401796;449.989;46.49895;1;1;0;0.7685597;0.7656213;412974.9;4.685632e+007
781.3961;0.2431606;0.0350647;449.9391;46.4938;1;1;0;0.76586;0.7629422;412929.2;4.684988e+007
787.3961;0.2424106;0.03691767;449.7085;46.46997;1;1;0;0.7634978;0.760598;412717.5;4.682477e+007
793.3961;0.2416606;0.03660602;446.7852;46.1679;1;1;0;0.7611356;0.7582536;410034.7;4.65193e+007
799.3961;0.2408034;0.03818535;443.0206;45.77889;1;1;0;0.758436;0.7555743;406579.8;4.612609e+007
804.7061;0.2406963;0.03800455;442.8653;45.76284;1;1;0;0.7580985;0.7552394;406437.3;4.610977e+007
809.7081;0.240857;0.03698533;445.2735;46.01168;2;2;0;0.7586047;0.7557418;408647.3;4.636073e+007
815.7081;0.2416606;0.03843072;432.7461;44.71719;2;2;0;0.7611356;0.7582536;397150.4;4.505754e+007
821.7081;0.2422498;0.03825246;433.5133;44.79646;2;2;0;0.7629916;0.7600956;397854.4;4.513825e+007
827.7081;0.2434284;0.03832262;431.7151;44.61065;2;2;0;0.7667037;0.7637795;396204.2;4.495268e+007
833.7081;0.2461605;0.04140706;407.8178;42.14125;2;2;0;0.7753088;0.7723187;374272.6;4.246798e+007
839.7081;0.251732;0.04214332;392.2737;40.53503;2;2;0;0.7928566;0.78973;360007.1;4.085642e+007
845.7081;0.2608391;0.04082306;388.326;40.1271;2;2;0;0.8215406;0.8181843;356384.1;4.045676e+007
851.7081;0.2804463;0.03438748;390.1521;40.3158;2;2;0;0.8832953;0.8794171;358060;4.06719e+007
857.7081;0.3204105;0.01465118;429.0301;44.3332;2;2;0;1.009167;1.004109;393740;4.478059e+007
863.7081;0.3582855;-0.005415093;455.8159;47.10107;2;2;0;1.128458;1.122139;418322.6;4.763259e+007
869.7081;0.383464;-0.02328495;470.9121;48.66102;2;2;0;1.207761;1.200525;432177.1;4.924873e+007
875.7081;0.3934819;-0.02924138;448.814;46.37753;2;2;0;1.239313;1.231696;411896.6;4.69523e+007
881.7081;0.4045712;-0.03708165;437.6379;45.22267;2;2;0;1.27424;1.26619;401639.8;4.579891e+007
887.7081;0.4211783;-0.05554091;432.502;44.69196;2;2;0;1.326546;1.317824;396926.4;4.528482e+007
893.7081;0.4411604;-0.08547531;439.0454;45.36811;2;2;0;1.389482;1.379917;402931.5;4.59985e+007
899.7081;0.4631247;-0.13552;445.0625;45.98988;2;2;0;1.45866;1.448124;408453.7;4.666072e+007
905.7081;0.486589;-0.1895005;453.4825;46.85995;2;2;0;1.532564;1.520939;416181.1;4.757811e+007
911.7081;0.5090354;-0.2467128;453.5771;46.86972;2;2;0;1.603261;1.590545;416267.9;4.762117e+007
917.7081;0.5304639;-0.2929149;459.5749;47.4895;2;2;0;1.670753;1.656949;421772.4;4.828294e+007
923.7081;0.5512497;-0.3246902;430.7537;44.5113;2;2;0;1.736219;1.721319;395321.8;4.528411e+007
929.7081;0.5712853;-0.3144734;341.2447;35.26202;2;2;0;1.799324;1.783328;313175.4;3.58965e+007
935.7081;0.6113032;-0.3238962;329.5046;34.04887;2;2;0;1.925364;1.907064;302401;3.470444e+007
941.7081;0.6562495;-0.365879;333.7352;34.48604;2;2;0;2.066928;2.045857;306283.7;3.519884e+007
947.7081;0.721446;-0.50305;343.1052;35.45427;2;2;0;2.272271;2.246839;314882.9;3.625989e+007
953.7081;0.8012674;-0.8240565;358.3989;37.03463;2;2;0;2.523677;2.492358;328918.7;3.796926e+007
959.7081;0.8813565;-1.245634;388.7999;40.17607;2;2;0;2.775926;2.738096;356819;4.129133e+007
965.7081;0.960803;-1.579093;437.5607;45.2147;2;2;0;3.026151;2.981267;401569;4.658297e+007
971.7081;1.014803;-1.903418;453.8214;46.89497;2;2;0;3.196229;3.146213;416492.1;4.839384e+007
977.7081;1.045017;-2.139015;430.3075;44.46519;2;2;0;3.291393;3.238386;394912.4;4.592872e+007
983.7081;1.086803;-2.439869;424.8096;43.89708;2;2;0;3.423001;3.36572;389866.8;4.539968e+007
989.7081;1.136731;-2.809512;448.006;46.29405;2;2;0;3.580256;3.517655;411155.1;4.795149e+007
995.7081;1.16641;-3.068731;443.785;45.85788;2;2;0;3.673732;3.607859;407281.3;4.754257e+007
1001.708;1.198714;-3.343002;447.3075;46.22187;2;2;0;3.775476;3.705949;410514;4.796696e+007
1007.708;1.232892;-3.625198;457.8843;47.3148;2;2;0;3.883124;3.809628;420220.8;4.91521e+007
1013.708;1.257749;-3.847356;457.9203;47.31853;2;2;0;3.961415;3.884963;420253.9;4.919301e+007
1019.708;1.279874;-4.044601;463.626;47.90812;2;2;0;4.0311;3.95197;425490.3;4.983934e+007
1025.708;1.299856;-4.240596;459.3;47.46109;2;2;0;4.094036;4.01245;421520.1;4.940417e+007
1031.708;1.319624;-4.42377;460.0284;47.53636;2;2;0;4.156296;4.072243;422188.5;4.951211e+007
1037.708;1.334571;-4.577858;449.6761;46.46662;2;2;0;4.203372;4.11743;412687.8;4.841978e+007
1043.708;1.350642;-4.7192;450.7533;46.57793;2;2;0;4.253991;4.165995;413676.4;4.855935e+007
1049.708;1.368642;-4.872134;444.8197;45.96479;2;2;0;4.310683;4.22036;408230.9;4.794619e+007
1055.708;1.387338;-5.014934;431.5033;44.58877;2;2;0;4.36957;4.276797;396009.8;4.65371e+007
1061.708;1.406463;-5.158302;415.3557;42.92017;2;2;0;4.429806;4.334495;381190.4;4.482145e+007
1067.708;1.427088;-5.271091;403.1861;41.66265;2;2;0;4.494767;4.39668;370021.9;4.353529e+007
1073.708;1.453445;-5.395152;405.8024;41.933;2;2;0;4.577781;4.476092;372423;4.38526e+007
1079.708;1.486767;-5.575386;412.1209;42.58591;2;2;0;4.68273;4.576397;378221.8;4.45801e+007
1085.708;1.526838;-5.779794;424.1421;43.82811;2;2;0;4.808939;4.696888;389254.2;4.593577e+007
1091.708;1.566749;-5.943322;439.0475;45.36834;2;2;0;4.934642;4.816752;402933.5;4.76071e+007
1097.708;1.606606;-6.102187;453.0539;46.81566;2;2;0;5.060177;4.936311;415787.8;4.918462e+007
1103.708;1.636017;-6.223044;456.8503;47.20796;2;2;0;5.152809;5.024443;419271.9;4.964049e+007
1109.708;1.656374;-6.326845;441.937;45.66692;2;2;0;5.216926;5.085399;405585.3;4.804933e+007
1115.708;1.682785;-6.481309;431.1185;44.549;2;2;0;5.300109;5.164427;395656.7;4.691014e+007
1121.708;1.711767;-6.754836;405.7031;41.92274;2;2;0;5.391392;5.251077;372331.9;4.418296e+007
1127.708;1.747981;-7.034683;391.3379;40.43833;2;2;0;5.505452;5.359244;359148.3;4.266465e+007
1133.708;1.787945;-7.223278;402.0463;41.54486;2;2;0;5.631324;5.478477;368975.8;4.388439e+007
1139.708;1.827963;-7.407766;416.396;43.02768;2;2;0;5.757364;5.597727;382145.2;4.550493e+007
1145.708;1.867981;-7.615584;450.2022;46.52099;2;2;0;5.883405;5.716835;413170.7;4.925801e+007
1151.708;1.894927;-7.719092;455.4913;47.06753;2;2;0;5.968275;5.796957;418024.7;4.987665e+007
1157.708;1.921713;-7.727563;478.9342;49.48997;2;2;0;6.05264;5.876539;439539.3;5.248542e+007
1163.708;1.938535;-7.732658;488.3776;50.46578;2;2;0;6.105621;5.926483;448205.9;5.354703e+007
1169.708;1.94657;-7.738912;492.0065;50.84077;2;2;0;6.130929;5.950333;451536.3;5.395778e+007
1175.708;1.948231;-7.744154;470.531;48.62163;2;2;0;6.13616;5.955262;431827.3;5.160513e+007
1181.708;1.951017;-7.748176;452.9359;46.80347;2;2;0;6.144934;5.963528;415679.5;4.967951e+007
1187.708;1.958088;-7.750003;445.5152;46.03667;2;2;0;6.167207;5.984509;408869.2;4.887584e+007
1193.708;1.966338;-7.754377;416.5295;43.04147;2;2;0;6.19319;6.00898;382267.7;4.570711e+007
1199.708;1.985677;-7.757385;385.4397;39.82885;2;2;0;6.254102;6.066323;353735.2;4.231979e+007
1205.708;2.019963;-7.765123;353.3962;36.51768;2;2;0;6.362088;6.167901;324327.5;3.884097e+007
1211.708;2.065766;-7.770802;384.0352;39.68371;2;2;0;6.506351;6.303443;352446.2;4.226567e+007
1217.708;2.113391;-7.759323;516.9541;53.4187;2;2;0;6.656351;6.444181;474431.8;5.697443e+007
1223.708;2.135516;-7.746517;576.3098;59.55214;2;2;0;6.726036;6.509495;528905.3;6.355763e+007
1229.708;2.145534;-7.741022;599.5039;61.94886;2;2;0;6.757588;6.539055;550191.5;6.613511e+007
1235.708;2.149552;-7.735524;588.6849;60.8309;2;2;0;6.770243;6.550908;540262.4;6.49493e+007
1241.708;2.149659;-7.732181;569.2492;58.82253;2;2;0;6.77058;6.551224;522425.4;6.280516e+007
1247.708;2.149874;-7.728041;555.2359;57.37449;2;2;0;6.771255;6.551856;509564.8;6.125947e+007
1253.708;2.150731;-7.724148;547.917;56.61821;2;2;0;6.773955;6.554384;502847.9;6.04535e+007
1259.708;2.152231;-7.720771;548.9738;56.72741;2;2;0;6.77868;6.558809;503817.8;6.057278e+007
1265.708;2.154374;-7.717313;554.4581;57.29412;2;2;0;6.785429;6.56513;508850.9;6.118177e+007
1271.708;2.156195;-7.714423;560.2683;57.8945;2;2;0;6.791165;6.570501;514183.2;6.182621e+007
1277.708;2.156784;-7.712343;560.5403;57.92262;2;2;0;6.793022;6.57224;514432.9;6.185731e+007
1282.248;2.156838;-7.71133;560.9929;57.96938;2;2;0;6.79319;6.572398;514848.2;6.190735e+007
1288.248;2.15657;-7.710923;561.0469;57.97496;2;2;0;6.792347;6.571608;514897.8;6.191282e+007
1294.248;2.155231;-7.709988;555.3338;57.38461;2;2;0;6.788128;6.567657;509654.6;6.127995e+007
1300.248;2.152766;-7.708912;543.1163;56.12213;2;2;0;6.780366;6.560389;498442.1;5.992742e+007
1306.248;2.149552;-7.708274;526.669;54.42257;2;2;0;6.770243;6.550908;483347.6;5.810711e+007
1312.248;2.14382;-7.708586;492.4741;50.8891;2;2;0;6.752189;6.533997;451965.5;5.432522e+007
1318.248;2.136266;-7.707905;446.9164;46.18146;2;2;0;6.728398;6.511709;410155.1;4.928873e+007
1324.248;2.136159;-7.708985;462.0902;47.74942;2;2;0;6.728061;6.511393;424080.8;5.096203e+007
1330.248;2.135302;-7.709874;470.1193;48.57909;2;2;0;6.725361;6.508863;431449.5;5.184621e+007
1336.248;2.133374;-7.710823;469.5158;48.51673;2;2;0;6.719287;6.503172;430895.6;5.177671e+007
1342.248;2.130267;-7.710755;456.9151;47.21465;2;2;0;6.709501;6.494001;419331.3;5.038252e+007
1348.248;2.127374;-7.711856;448.0277;46.29629;2;2;0;6.700389;6.485462;411175;4.939832e+007
1354.248;2.125445;-7.712462;446.4685;46.13517;2;2;0;6.694315;6.479769;409744.1;4.92236e+007
1360.248;2.123409;-7.714528;446.077;46.09472;2;2;0;6.687903;6.473759;409384.8;4.917749e+007
1366.248;2.121374;-7.71598;445.5266;46.03784;2;2;0;6.681491;6.467749;408879.6;4.911385e+007
1372.248;2.119445;-7.717724;445.2499;46.00925;2;2;0;6.675417;6.462055;408625.7;4.908056e+007
1378.248;2.117945;-7.718803;448.859;46.38219;2;2;0;6.670693;6.457627;411937.9;4.94762e+007
1384.248;2.116981;-7.720072;455.9483;47.11476;2;2;0;6.667656;6.45478;418444.1;5.025621e+007
1390.248;2.116391;-7.720357;463.7337;47.91924;2;2;0;6.6658;6.453039;425589.1;5.111344e+007
1396.248;2.114356;-7.722132;462.5934;47.80141;2;2;0;6.659389;6.447029;424542.6;5.098469e+007
1402.248;2.112159;-7.722303;458.1488;47.34214;2;2;0;6.65247;6.440542;420463.6;5.049156e+007
1408.248;2.109159;-7.724372;449.4031;46.43842;2;2;0;6.643021;6.431682;412437.3;4.952333e+007
1414.248;2.106159;-7.726756;441.9356;45.66677;2;2;0;6.633573;6.422821;405584.1;4.869611e+007
1420.248;2.103159;-7.727839;434.9904;44.9491;2;2;0;6.624124;6.41396;399210.1;4.792658e+007
1426.248;2.100909;-7.730092;433.3358;44.77812;2;2;0;6.617037;6.407314;397691.6;4.774111e+007
1432.248;2.099409;-7.731385;437.1939;45.17679;2;2;0;6.612313;6.402882;401232.3;4.816402e+007
1438.248;2.098445;-7.732139;444.9886;45.98225;2;2;0;6.609276;6.400034;408385.9;4.902134e+007
1444.248;2.097374;-7.733626;450.3346;46.53467;2;2;0;6.605901;6.396868;413292.2;4.960871e+007
1450.248;2.095981;-7.734963;453.8961;46.90269;2;2;0;6.601515;6.392753;416560.7;4.999898e+007
1456.248;2.093945;-7.735091;451.927;46.69921;2;2;0;6.595102;6.386738;414753.5;4.977907e+007
1462.248;2.092016;-7.733622;448.0333;46.29687;2;2;0;6.589028;6.381039;411180.2;4.934739e+007
1468.248;2.090302;-7.73146;446.899;46.17966;2;2;0;6.583629;6.375974;410139.2;4.921996e+007
1474.248;2.089231;-7.730659;448.9198;46.38847;2;2;0;6.580255;6.372808;411993.7;4.944095e+007
1480.248;2.088052;-7.730035;450.1756;46.51824;2;2;0;6.576542;6.369325;413146.2;4.957753e+007
1486.248;2.08666;-7.729486;449.0939;46.40646;2;2;0;6.572156;6.365209;412153.5;4.945637e+007
1492.248;2.085266;-7.729206;448.3454;46.32912;2;2;0;6.567769;6.361092;411466.6;4.937191e+007
1498.248;2.083927;-7.728789;447.1783;46.20852;2;2;0;6.56355;6.357134;410395.5;4.924144e+007
1504.248;2.082588;-7.728413;445.9199;46.07848;2;2;0;6.559332;6.353175;409240.6;4.910092e+007
1510.248;2.081516;-7.728102;446.6671;46.15569;2;2;0;6.555957;6.350008;409926.3;4.918164e+007
1516.248;2.080445;-7.727745;447.1066;46.20111;2;2;0;6.552583;6.346841;410329.7;4.922847e+007
1522.248;2.079481;-7.727317;448.2166;46.3158;2;2;0;6.549546;6.343991;411348.3;4.934928e+007
1528.248;2.078516;-7.727155;448.7013;46.3659;2;2;0;6.546508;6.34114;411793.2;4.940124e+007
1534.248;2.077445;-7.726609;448.3319;46.32772;2;2;0;6.543134;6.337973;411454.1;4.9359e+007
1540.248;2.076481;-7.726337;448.6789;46.36358;2;2;0;6.540097;6.335122;411772.6;4.93958e+007
1546.248;2.075516;-7.725726;448.6734;46.36301;2;2;0;6.537059;6.332272;411767.6;4.939379e+007
1552.248;2.074552;-7.725392;448.3234;46.32685;2;2;0;6.534023;6.329421;411446.4;4.935385e+007
1558.248;2.073481;-7.725106;446.839;46.17345;2;2;0;6.530648;6.326253;410084.1;4.918888e+007
1564.248;2.072302;-7.72442;444.3345;45.91466;2;2;0;6.526936;6.322769;407785.6;4.891148e+007
1570.248;2.071499;-7.724086;444.8565;45.96859;2;2;0;6.524405;6.320393;408264.6;4.896777e+007
1576.248;2.071338;-7.72369;450.5793;46.55996;2;2;0;6.5239;6.319918;413516.8;4.959748e+007
1582.248;2.070427;-7.723379;449.6896;46.46802;2;2;0;6.52103;6.317225;412700.2;4.949821e+007
1588.248;2.069409;-7.722845;448.2449;46.31874;2;2;0;6.517824;6.314215;411374.4;4.933771e+007
1594.248;2.068659;-7.722264;447.7705;46.26971;2;2;0;6.515462;6.311998;410939;4.92844e+007
1600.248;2.067909;-7.722188;447.2066;46.21144;2;2;0;6.5131;6.30978;410421.4;4.922124e+007
1606.248;2.067052;-7.721582;446.1318;46.10038;2;2;0;6.510401;6.307245;409435;4.910169e+007
1612.248;2.066302;-7.721155;445.9307;46.07959;2;2;0;6.508038;6.305027;409250.4;4.907847e+007
1618.248;2.065874;-7.720928;447.9417;46.2874;2;2;0;6.506689;6.303761;411096.1;4.929918e+007
1624.248;2.065445;-7.720407;449.5853;46.45724;2;2;0;6.505339;6.302493;412604.5;4.947944e+007
1630.248;2.064909;-7.720138;450.1136;46.51183;2;2;0;6.503652;6.300908;413089.3;4.95368e+007
1636.248;2.064481;-7.72012;451.4516;46.65009;2;2;0;6.502301;6.299641;414317.3;4.968342e+007
1642.248;2.064159;-7.719494;453.6427;46.8765;2;2;0;6.501289;6.29869;416328.1;4.992408e+007
1648.248;2.063624;-7.719241;453.869;46.89989;2;2;0;6.499602;6.297106;416535.8;4.99482e+007
1654.248;2.063195;-7.719083;454.7049;46.98627;2;2;0;6.498252;6.295839;417303;5.003955e+007
1660.248;2.062659;-7.718781;454.6978;46.98553;2;2;0;6.496565;6.294254;417296.5;5.003798e+007
1666.248;2.062124;-7.718467;454.3318;46.94771;2;2;0;6.494877;6.29267;416960.5;4.999691e+007
1672.248;2.061481;-7.718142;452.8962;46.79936;2;2;0;6.492852;6.290768;415643;4.983798e+007
1678.248;2.060731;-7.71801;450.7747;46.58014;2;2;0;6.49049;6.288551;413696;4.960342e+007
1684.248;2.060195;-7.717785;450.0277;46.50295;2;2;0;6.488803;6.286966;413010.4;4.952044e+007
1690.248;2.059659;-7.717611;449.3756;46.43558;2;2;0;6.487116;6.285381;412412.1;4.944791e+007
1696.248;2.059177;-7.717285;449.0441;46.40132;2;2;0;6.485598;6.283956;412107.8;4.941072e+007
1702.248;2.058749;-7.717152;449.0926;46.40633;2;2;0;6.484248;6.282688;412152.3;4.941543e+007
1708.248;2.058374;-7.716829;449.515;46.44997;2;2;0;6.483066;6.281578;412539.9;4.946135e+007
1714.248;2.057945;-7.71679;449.7742;46.47676;2;2;0;6.481717;6.280311;412777.9;4.948926e+007
1720.248;2.057517;-7.716346;449.7005;46.46915;2;2;0;6.480367;6.279044;412710.2;4.948052e+007
1726.248;2.057088;-7.716097;449.1013;46.40723;2;2;0;6.479017;6.277775;412160.3;4.941396e+007
1732.248;2.056659;-7.715839;448.4524;46.34017;2;2;0;6.477667;6.276508;411564.8;4.934193e+007
1738.248;2.056338;-7.715425;448.6958;46.36533;2;2;0;6.476655;6.275557;411788.2;4.936825e+007
1744.248;2.055909;-7.715032;448.1574;46.30969;2;2;0;6.475305;6.274289;411294;4.930838e+007
1750.248;2.055481;-7.715055;447.1297;46.2035;2;2;0;6.473956;6.273022;410350.8;4.919469e+007
1756.248;2.055159;-7.714579;447.6191;46.25406;2;2;0;6.472943;6.272071;410800;4.924806e+007
1762.248;2.054731;-7.714346;446.4555;46.13383;2;2;0;6.471593;6.270803;409732.2;4.911942e+007
1768.248;2.054302;-7.714163;445.2064;46.00475;2;2;0;6.470243;6.269536;408585.7;4.898137e+007
1774.248;2.053981;-7.713996;445.1617;46.00013;2;2;0;6.469231;6.268584;408544.7;4.897599e+007
1780.248;2.053767;-7.713494;446.0639;46.09336;2;2;0;6.468556;6.267951;409372.7;4.907493e+007
1786.248;2.053659;-7.713193;447.5102;46.24282;2;2;0;6.468219;6.267634;410700.1;4.92339e+007
1792.248;2.053552;-7.712938;449.1268;46.40986;2;2;0;6.467881;6.267317;412183.7;4.94116e+007
1798.248;2.053445;-7.712648;450.2605;46.52702;2;2;0;6.467544;6.267;413224.2;4.953617e+007
1804.248;2.053338;-7.712547;451.3638;46.64102;2;2;0;6.467206;6.266683;414236.7;4.965739e+007
1810.248;2.053231;-7.71217;452.4697;46.7553;2;2;0;6.466869;6.266366;415251.6;4.97789e+007
1816.248;2.053124;-7.711768;453.5076;46.86254;2;2;0;6.466531;6.266049;416204.1;4.989292e+007
1822.248;2.053017;-7.711588;454.4947;46.96455;2;2;0;6.466194;6.265732;417110.1;5.000137e+007
1828.248;2.052909;-7.711261;455.0946;47.02654;2;2;0;6.465856;6.265415;417660.6;5.00672e+007
1834.248;2.052588;-7.710899;454.1842;46.93246;2;2;0;6.464844;6.264464;416825.1;4.996657e+007
1840.248;2.052266;-7.710565;453.0935;46.81975;2;2;0;6.463831;6.263513;415824.1;4.98461e+007
1846.248;2.052052;-7.710322;453.2498;46.8359;2;2;0;6.463156;6.262879;415967.5;4.986298e+007
1852.248;2.051945;-7.709965;453.6631;46.87862;2;2;0;6.462819;6.262562;416346.9;4.990829e+007
1858.248;2.051784;-7.709563;454.0387;46.91743;2;2;0;6.462313;6.262087;416691.6;4.994938e+007
1864.248;2.051784;-7.709466;455.6294;47.0818;2;2;0;6.462313;6.262087;418151.4;5.012437e+007
1870.248;2.051516;-7.709177;454.4034;46.95511;2;2;0;6.461469;6.261294;417026.3;4.99891e+007
1876.248;2.051088;-7.708871;452.0598;46.71294;2;2;0;6.460119;6.260026;414875.4;4.973065e+007
1882.248;2.050713;-7.708529;450.2669;46.52768;2;2;0;6.458939;6.258917;413230;4.953287e+007
1888.248;2.050499;-7.708147;449.5901;46.45773;2;2;0;6.458263;6.258283;412608.8;4.94581e+007
1894.248;2.050177;-7.707812;448.1843;46.31247;2;2;0;6.457251;6.257332;411318.8;4.930299e+007
1900.248;2.049856;-7.70737;446.995;46.18958;2;2;0;6.456238;6.256381;410227.3;4.917169e+007
1906.248;2.049856;-7.706934;448.4921;46.34428;2;2;0;6.456238;6.256381;411601.3;4.933638e+007
1912.248;2.049749;-7.706844;448.532;46.3484;2;2;0;6.455901;6.256064;411637.8;4.934061e+007
1918.248;2.049641;-7.706817;449.0683;46.40381;2;2;0;6.455564;6.255747;412130;4.939944e+007
1924.248;2.049481;-7.70662;448.4742;46.34243;2;2;0;6.455058;6.255272;411584.8;4.933386e+007
1930.248;2.049374;-7.70663;448.3538;46.32998;2;2;0;6.45472;6.254955;411474.3;4.932045e+007
1936.248;2.049266;-7.706401;448.4855;46.34359;2;2;0;6.454382;6.254637;411595.1;4.933479e+007
1942.248;2.049266;-7.706274;449.4984;46.44826;2;2;0;6.454382;6.254637;412524.7;4.944621e+007
1948.248;2.049159;-7.70604;449.2151;46.41899;2;2;0;6.454045;6.25432;412264.8;4.941489e+007
1954.248;2.049159;-7.705603;449.6385;46.46273;2;2;0;6.454045;6.25432;412653.3;4.946146e+007
1960.248;2.049159;-7.705083;450.2232;46.52316;2;2;0;6.454045;6.25432;413189.9;4.952578e+007
1966.248;2.049159;-7.704362;450.67;46.56932;2;2;0;6.454045;6.25432;413599.9;4.957493e+007
1972.248;2.049052;-7.704338;450.2304;46.5239;2;2;0;6.453708;6.254003;413196.5;4.952642e+007
1978.248;2.048945;-7.704291;449.5659;46.45523;2;2;0;6.45337;6.253686;412586.6;4.945316e+007
1984.248;2.048838;-7.704301;448.8689;46.38321;2;2;0;6.453033;6.25337;411947;4.937633e+007
1990.248;2.048731;-7.704563;448.483;46.34333;2;2;0;6.452695;6.253053;411592.8;4.933373e+007
1996.248;2.048624;-7.704981;447.3369;46.22491;2;2;0;6.452358;6.252735;410541;4.92075e+007
2002.248;2.048516;-7.705842;446.9906;46.18912;2;2;0;6.45202;6.252418;410223.2;4.916925e+007
2008.248;2.048409;-7.706208;445.9824;46.08494;2;2;0;6.451683;6.252102;409297.9;4.905819e+007
2014.248;2.048302;-7.706667;445.4383;46.02872;2;2;0;6.451346;6.251785;408798.6;4.899819e+007
2020.248;2.048302;-7.707184;445.7046;46.05624;2;2;0;6.451346;6.251785;409043;4.902748e+007
2026.248;2.048195;-7.70835;445.5442;46.03966;2;2;0;6.451008;6.251468;408895.8;4.900968e+007
2032.248;2.048088;-7.709063;446.1121;46.09834;2;2;0;6.450671;6.251151;409416.9;4.907199e+007
2038.248;2.047981;-7.710383;446.7461;46.16385;2;2;0;6.450333;6.250833;409998.8;4.914157e+007
2044.248;2.047874;-7.71162;447.7478;46.26736;2;2;0;6.449996;6.250516;410918.1;4.925161e+007
2050.248;2.047766;-7.713324;449.4677;46.44509;2;2;0;6.449658;6.2502;412496.5;4.944064e+007
2056.248;2.047659;-7.714357;450.3254;46.53372;2;2;0;6.449321;6.249883;413283.7;4.953483e+007
2062.248;2.047338;-7.716222;451.3785;46.64254;2;2;0;6.448308;6.248931;414250.2;4.965019e+007
2068.248;2.04707;-7.716789;452.2232;46.72983;2;2;0;6.447465;6.248139;415025.4;4.974272e+007
2074.248;2.04691;-7.717799;457.0687;47.23053;2;2;0;6.446959;6.247664;419472.3;5.027546e+007
2079.118;2.046802;-7.718619;462.6338;47.80558;3;3;0;6.446621;6.247346;424579.6;5.088743e+007
2083.862;2.046802;-7.719352;469.8982;48.55624;3;3;0;6.446621;6.247346;431246.5;5.168648e+007
2089.862;2.044981;-7.720177;472.9371;48.87027;3;3;0;6.440884;6.241956;434035.5;5.201794e+007
2095.862;2.040588;-7.723656;476.3405;49.22195;3;3;0;6.427048;6.228957;437159;5.238547e+007
2101.862;2.033302;-7.729068;480.6169;49.66385;3;3;0;6.404101;6.207394;441083.6;5.284437e+007
2107.862;2.004159;-7.748666;450.1982;46.52057;3;3;0;6.312313;6.121093;413167;4.94571e+007
2113.862;1.976463;-7.770546;442.1322;45.68708;3;3;0;6.22508;6.039006;405764.4;4.853114e+007
2119.862;1.962052;-7.780722;445.5514;46.04041;3;3;0;6.179692;5.996268;408902.4;4.888556e+007
2125.862;1.948659;-7.78819;444.694;45.95181;3;3;0;6.13751;5.956533;408115.5;4.87721e+007
2131.862;1.936499;-7.79303;450.9518;46.59844;3;3;0;6.099209;5.92044;413858.5;4.944058e+007
2137.862;1.922838;-7.798716;454.8498;47.00124;3;3;0;6.056183;5.87988;417436;4.984772e+007
2143.862;1.905749;-7.796708;456.3964;47.16105;3;3;0;6.002358;5.829116;418855.3;4.999183e+007
2149.862;1.885874;-7.793011;464.6604;48.015;3;3;0;5.93976;5.770044;426439.5;5.086698e+007
2155.862;1.860802;-7.710153;463.1034;47.85411;3;3;0;5.860795;5.695479;425010.7;5.065875e+007
2161.862;1.830213;-7.638954;466.7798;48.23401;3;3;0;5.764451;5.604427;428384.7;5.101444e+007
2167.862;1.793142;-7.532675;467.5135;48.30983;3;3;0;5.64769;5.49397;429058;5.103822e+007
2173.862;1.748249;-7.393871;460.6202;47.59751;3;3;0;5.506296;5.360044;422731.7;5.021837e+007
2179.862;1.700195;-7.208095;445.1247;45.99631;3;3;0;5.354946;5.21649;408510.8;4.845939e+007
2185.862;1.660713;-7.036735;438.2231;45.28315;3;3;0;5.230593;5.098388;402176.9;4.765173e+007
2191.862;1.625838;-6.880165;433.9725;44.84391;3;3;0;5.120751;4.993951;398275.9;4.714026e+007
2197.862;1.595624;-6.735441;433.7576;44.82171;3;3;0;5.025587;4.903382;398078.8;4.707427e+007
2203.862;1.57457;-6.633245;443.2867;45.80639;3;3;0;4.959277;4.840225;406824;4.807805e+007
2209.862;1.553356;-6.52666;451.0785;46.61154;3;3;0;4.89246;4.776545;413974.9;4.889199e+007
2215.862;1.523356;-6.379925;447.783;46.271;3;3;0;4.797972;4.686424;410950.4;4.849107e+007
2221.862;1.494213;-6.249881;438.2984;45.29092;3;3;0;4.706184;4.598799;402246;4.74224e+007
2227.862;1.469571;-6.116988;435.6954;45.02195;3;3;0;4.628569;4.524645;399857.1;4.710582e+007
2233.862;1.449588;-5.995423;439.2163;45.38578;3;3;0;4.565632;4.464475;403088.4;4.745792e+007
2239.862;1.434535;-5.882451;449.5889;46.45762;3;3;0;4.51822;4.419122;412607.8;4.855667e+007
2245.862;1.413963;-5.730932;453.9368;46.90689;3;3;0;4.453428;4.357112;416598;4.899586e+007
2251.862;1.389856;-5.568603;448.2636;46.32066;3;3;0;4.3775;4.284395;411391.5;4.834835e+007
2257.862;1.366874;-5.408525;444.7787;45.96056;3;3;0;4.305115;4.215022;408193.3;4.793921e+007
2263.862;1.344588;-5.239967;440.4882;45.5172;3;3;0;4.234924;4.147705;404255.7;4.744482e+007
2269.862;1.327981;-5.099716;444.0344;45.88365;3;3;0;4.182618;4.097511;407510.2;4.780279e+007
2275.862;1.313035;-4.967776;447.4344;46.23498;3;3;0;4.135543;4.052316;410630.5;4.814705e+007
2281.862;1.297392;-4.827332;452.435;46.75171;3;3;0;4.086274;4.004993;415219.8;4.866211e+007
2287.862;1.27741;-4.654803;451.6799;46.67369;3;3;0;4.023338;3.944509;414526.8;4.855153e+007
2293.862;1.257856;-4.49266;446.0108;46.08788;3;3;0;3.961752;3.885288;409324;4.791377e+007
2299.862;1.244088;-4.373523;450.3105;46.53218;3;3;0;3.918389;3.843568;413270.1;4.835549e+007
2305.862;1.230535;-4.257564;451.1108;46.61488;3;3;0;3.8757;3.802481;414004.5;4.842153e+007
2311.862;1.217571;-4.14635;452.9179;46.80161;3;3;0;3.834868;3.763164;415663;4.859639e+007
2317.862;1.204553;-4.03158;459.6107;47.4932;3;3;0;3.793867;3.72367;421805.2;4.929503e+007
2323.862;1.190303;-3.909392;463.943;47.94087;3;3;0;3.748985;3.680419;425781.1;4.973816e+007
2329.862;1.170214;-3.747605;461.7141;47.71056;3;3;0;3.685712;3.619414;423735.6;4.946903e+007
2335.862;1.147392;-3.568007;455.8055;47.09999;3;3;0;3.613833;3.550066;418313;4.880211e+007
2341.862;1.124089;-3.378192;455.1731;47.03465;3;3;0;3.540436;3.479204;417732.6;4.869988e+007
2347.862;1.102285;-3.200429;453.7643;46.88908;3;3;0;3.471764;3.412858;416439.8;4.851695e+007
2353.862;1.078553;-3.004697;449.8576;46.48538;3;3;0;3.397017;3.340592;412854.4;4.806449e+007
2359.862;1.055464;-2.814413;447.7167;46.26416;3;3;0;3.324295;3.270235;410889.6;4.780211e+007
2365.862;1.032749;-2.628224;446.455;46.13378;3;3;0;3.252754;3.200972;409731.7;4.763439e+007
2371.862;1.010731;-2.44939;445.0783;45.99151;3;3;0;3.183406;3.133786;408468.2;4.745561e+007
2377.862;0.9884458;-2.266381;447.2724;46.21824;3;3;0;3.113215;3.065737;410481.8;4.765711e+007
2383.862;0.966428;-2.088255;449.1827;46.41563;3;3;0;3.043868;2.998461;412235;4.782847e+007
2389.862;0.9445173;-1.914492;450.9222;46.59538;3;3;0;2.974858;2.931467;413831.4;4.798153e+007
2395.862;0.9223923;-1.746152;448.7018;46.36594;3;3;0;2.905173;2.863772;411793.7;4.771296e+007
2401.862;0.9009102;-1.588247;444.3713;45.91846;3;3;0;2.837512;2.798001;407819.4;4.722141e+007
2407.862;0.8800173;-1.438871;439.686;45.43431;3;3;0;2.771708;2.733992;403519.5;4.669362e+007
2413.862;0.8619102;-1.304711;442.5464;45.72989;3;3;0;2.714678;2.678484;406144.6;4.697131e+007
2419.862;0.8570887;-1.252074;457.5609;47.28138;3;3;0;2.699492;2.663699;419924;4.855774e+007
2425.862;0.8451423;-1.158653;460.3569;47.57031;3;3;0;2.661866;2.627054;422490.1;4.883657e+007
2431.862;0.8302495;-1.046136;463.6923;47.91497;3;3;0;2.614959;2.581354;425551.1;4.916793e+007
2437.862;0.8152495;-0.9313309;471.744;48.74697;3;3;0;2.567715;2.535303;432940.5;4.999866e+007
2443.862;0.8037317;-0.8370232;486.7824;50.30095;3;3;0;2.531438;2.499928;446741.9;5.157428e+007
2449.862;0.7996602;-0.7858446;511.1687;52.82088;3;3;0;2.518615;2.48742;469122.3;5.415123e+007
2455.862;0.7813387;-0.679324;514.7573;53.19169;3;3;0;2.460909;2.431117;472415.7;5.450069e+007
2461.862;0.7579281;-0.6013769;513.2459;53.03551;3;3;0;2.387175;2.359127;471028.7;5.430157e+007
2467.862;0.7178567;-0.5150663;492.2881;50.86987;3;3;0;2.260966;2.235785;451794.8;5.202002e+007
2473.862;0.6777317;-0.4126043;480.4522;49.64683;3;3;0;2.134588;2.112125;440932.4;5.070658e+007
2479.862;0.6377674;-0.3121825;472.1703;48.79103;3;3;0;2.008716;1.988808;433331.8;4.97711e+007
2485.862;0.5979103;-0.2051084;463.4741;47.89242;3;3;0;1.883182;1.86567;425350.8;4.879432e+007
2491.862;0.5578389;-0.113525;461.8393;47.72349;3;3;0;1.756973;1.741717;423850.5;4.856198e+007
2497.862;0.5177675;-0.05803167;465.8811;48.14114;3;3;0;1.630764;1.61761;427559.8;4.892621e+007
2503.862;0.4777497;-0.03524594;464.5818;48.00688;3;3;0;1.504724;1.493515;426367.4;4.872925e+007
2509.862;0.4440533;-0.02334622;461.748;47.71405;3;3;0;1.398593;1.388903;423766.7;4.838138e+007
2515.862;0.419089;-0.01639132;464.0686;47.95385;3;3;0;1.319965;1.31133;425896.4;4.858682e+007
2521.862;0.3890354;-0.009213322;456.5096;47.17276;3;3;0;1.225309;1.217862;418959.3;4.775077e+007
2527.862;0.3633212;-0.003625312;453.531;46.86496;3;3;0;1.144319;1.137821;416225.6;4.740125e+007
2533.862;0.3403391;-0.005725651;478.258;49.42009;3;3;0;1.071934;1.06623;438918.7;4.994984e+007
2539.862;0.3029462;-0.005430285;482.256;49.83323;3;3;0;0.9541613;0.949638;442587.9;5.030871e+007
2545.862;0.2557498;-0.00265981;470.712;48.64034;3;3;0;0.8055112;0.8022843;431993.4;4.903214e+007
2551.862;0.2057677;0.006034055;459.4637;47.47801;3;3;0;0.6480873;0.6459962;421670.3;4.778571e+007
2557.862;0.1557856;0.01905996;454.4067;46.95546;3;3;0;0.4906634;0.4894635;417029.3;4.718585e+007
2563.862;0.1184464;0.03054724;446.4587;46.13416;3;3;0;0.3730594;0.3723652;409735.1;4.630627e+007
2569.862;0.1050535;0.03398906;444.6865;45.95103;3;3;0;0.3308772;0.330331;408108.6;4.610307e+007
2575.862;0.09830351;0.03437965;436.7108;45.12687;3;3;0;0.3096173;0.309139;400789;4.52666e+007
2581.862;0.09524993;0.03364471;430.8896;44.52534;3;3;0;0.2999998;0.2995507;395446.6;4.465892e+007
2587.862;0.09498208;0.03330326;431.2458;44.56215;3;3;0;0.2991562;0.2987096;395773.5;4.469546e+007
2593.862;0.09487494;0.03282388;430.9224;44.52874;3;3;0;0.2988187;0.2983731;395476.7;4.46618e+007
2599.862;0.09476779;0.03249606;430.8648;44.52279;3;3;0;0.2984812;0.2980367;395423.9;4.465568e+007
2605.862;0.09471422;0.03227351;430.0794;44.44163;3;3;0;0.2983125;0.2978684;394703;4.45742e+007
2610.842;0.09471422;0.03229047;429.5203;44.38386;4;4;0;0.2983125;0.2978684;394190;4.451626e+007
2616.842;0.09508923;0.03188402;429.3251;44.36369;4;4;0;0.2994936;0.2990461;394010.8;4.449655e+007
2622.842;0.09541065;0.03170478;429.7914;44.41187;4;4;0;0.300506;0.3000554;394438.7;4.454533e+007
2628.842;0.09594637;0.03163768;429.6867;44.40105;4;4;0;0.3021933;0.3017376;394342.7;4.453523e+007
2634.842;0.09674994;0.03134814;431.2599;44.56361;4;4;0;0.3047242;0.3042609;395786.4;4.469941e+007
2640.842;0.0977678;0.0311754;432.8933;44.7324;4;4;0;0.3079301;0.3074569;397285.5;4.487015e+007
2646.842;0.09873208;0.03091128;434.3357;44.88144;4;4;0;0.3109672;0.3104847;398609.2;4.502101e+007
2652.842;0.09969636;0.03070929;436.1008;45.06384;4;4;0;0.3140043;0.3135123;400229.1;4.520534e+007
2658.842;0.1007678;0.03042798;438.3372;45.29493;4;4;0;0.3173789;0.3168763;402281.6;4.543869e+007
2664.842;0.1017321;0.03015775;439.5497;45.42022;4;4;0;0.320416;0.3199037;403394.3;4.556576e+007
2670.842;0.1026964;0.02998845;440.4767;45.51602;4;4;0;0.3234531;0.3229311;404245.1;4.566324e+007
2676.842;0.1037678;0.02975103;442.696;45.74535;4;4;0;0.3268277;0.3262948;406281.8;4.589485e+007
2682.842;0.1047321;0.02967801;443.7293;45.85212;4;4;0;0.3298648;0.3293219;407230.1;4.600337e+007
2688.842;0.1056964;0.02942896;445.4897;46.03403;4;4;0;0.3329019;0.332349;408845.8;4.618728e+007
2694.842;0.1067142;0.02937822;446.7823;46.1676;4;4;0;0.3361078;0.3355442;410032.1;4.632277e+007
2700.842;0.1077321;0.02920955;448.1245;46.30629;4;4;0;0.3393136;0.3387393;411263.9;4.646342e+007
2706.842;0.1084821;0.02922975;447.8897;46.28202;4;4;0;0.3416758;0.3410934;411048.3;4.644016e+007
2712.842;0.1089106;0.02910309;447.1352;46.20406;4;4;0;0.3430257;0.3424387;410355.9;4.636255e+007
2718.842;0.1093928;0.02922279;446.5181;46.1403;4;4;0;0.3445442;0.343952;409789.6;4.629927e+007
2724.842;0.1099285;0.02917749;446.503;46.13874;4;4;0;0.3462315;0.3456335;409775.8;4.629849e+007
2730.842;0.1104642;0.02910975;446.1033;46.09743;4;4;0;0.3479188;0.347315;409408.9;4.625782e+007
2736.842;0.1110535;0.02926018;445.9383;46.08038;4;4;0;0.3497748;0.3491645;409257.5;4.624156e+007
2742.842;0.1119106;0.02898748;447.0196;46.19212;4;4;0;0.3524745;0.3518547;410249.8;4.635493e+007
2748.842;0.1126606;0.02896501;447.3168;46.22282;4;4;0;0.3548366;0.3542086;410522.6;4.638684e+007
2754.842;0.1135178;0.02895905;448.3585;46.33047;4;4;0;0.3575363;0.3568987;411478.6;4.649612e+007
2760.842;0.1142678;0.02873416;448.9142;46.3879;4;4;0;0.3598985;0.3592525;411988.6;4.655485e+007
2766.842;0.1151249;0.02829734;450.3995;46.54137;4;4;0;0.3625982;0.3619424;413351.7;4.671013e+007
2772.842;0.1158749;0.02775186;451.7246;46.6783;4;4;0;0.3649604;0.364296;414567.8;4.684866e+007
2778.842;0.1166785;0.02692144;453.4294;46.85447;4;4;0;0.3674913;0.3668177;416132.4;4.702665e+007
2784.842;0.1174821;0.0255971;455.5701;47.07567;4;4;0;0.3700223;0.3693394;418097;4.724986e+007
2790.842;0.1179106;0.02420679;455.9942;47.11949;4;4;0;0.3713721;0.3706842;418486.2;4.729448e+007
2796.842;0.1179642;0.02294021;455.0127;47.01808;4;4;0;0.3715408;0.3708523;417585.5;4.719277e+007
2802.842;0.1181249;0.02188019;454.2888;46.94328;4;4;0;0.372047;0.3713566;416921.1;4.711793e+007
2808.842;0.1181785;0.02098657;452.0626;46.71322;4;4;0;0.3722157;0.3715247;414878;4.68871e+007
2814.842;0.1182856;0.02010083;450.1308;46.51361;4;4;0;0.3725532;0.3718609;413105.1;4.66869e+007
2820.842;0.1186071;0.01936699;448.8536;46.38163;4;4;0;0.3735656;0.3728695;411933;4.65549e+007
2826.842;0.1188749;0.0186133;447.0987;46.20029;4;4;0;0.3744092;0.37371;410322.4;4.637327e+007
2832.842;0.1191964;0.01811223;445.4073;46.02552;4;4;0;0.3754216;0.3747186;408770.2;4.619831e+007
2838.842;0.1199464;0.01761029;445.697;46.05545;4;4;0;0.3777838;0.377072;409036;4.622944e+007
2844.842;0.1208035;0.01693213;445.7198;46.05781;4;4;0;0.3804834;0.3797614;409057;4.623305e+007
2850.842;0.1215535;0.01670497;445.3244;46.01694;4;4;0;0.3828456;0.3821147;408694.1;4.619312e+007
2856.842;0.1224106;0.01637154;444.9059;45.9737;4;4;0;0.3855453;0.384804;408309.9;4.615095e+007
2862.842;0.1235892;0.01601432;447.4558;46.23719;4;4;0;0.3892573;0.3885017;410650.2;4.641717e+007
2868.842;0.1249821;0.01566645;450.705;46.57294;4;4;0;0.3936443;0.3928716;413632;4.675627e+007
2874.842;0.1259463;0.015835;450.2976;46.53084;4;4;0;0.3966814;0.3958967;413258.2;4.671542e+007
2880.842;0.1269642;0.01565486;450.4042;46.54186;4;4;0;0.3998872;0.3990898;413356;4.672798e+007
2886.842;0.1279821;0.01556661;451.0471;46.6083;4;4;0;0.4030931;0.4022828;413946.1;4.679617e+007
2892.842;0.1289463;0.0158135;451.1502;46.61895;4;4;0;0.4061302;0.4053077;414040.7;4.680828e+007
2898.842;0.1299106;0.01606028;451.0457;46.60815;4;4;0;0.4091673;0.4083325;413944.8;4.679886e+007
2904.842;0.1309821;0.016258;452.0247;46.70931;4;4;0;0.4125419;0.4116933;414843.2;4.6902e+007
2910.842;0.1317856;0.01638537;451.165;46.62048;4;4;0;0.4150728;0.4142138;414054.3;4.681399e+007
2916.842;0.1321606;0.01692998;447.7512;46.26771;4;4;0;0.416254;0.41539;410921.2;4.64603e+007
2922.842;0.1330178;0.01724171;448.4646;46.34144;4;4;0;0.4189536;0.4180784;411576;4.653559e+007
2928.842;0.1337678;0.01767102;448.5759;46.35294;4;4;0;0.4213158;0.4204308;411678.1;4.654823e+007
2934.842;0.1346249;0.01825666;448.8853;46.38491;4;4;0;0.4240155;0.423119;411962.1;4.658159e+007
2940.842;0.1353749;0.01849992;448.1856;46.31261;4;4;0;0.4263777;0.4254713;411319.9;4.651007e+007
2946.842;0.1361785;0.01889775;447.8543;46.27837;4;4;0;0.4289086;0.4279914;411015.9;4.647687e+007
2952.842;0.1369821;0.01910353;447.867;46.27969;4;4;0;0.4314395;0.4305115;411027.5;4.647935e+007
2958.842;0.1378392;0.01933586;447.6959;46.262;4;4;0;0.4341392;0.4331995;410870.5;4.646284e+007
2964.842;0.1385892;0.01965962;447.7874;46.27146;4;4;0;0.4365014;0.4355515;410954.5;4.647343e+007
2970.842;0.1393928;0.01988682;447.4779;46.23948;4;4;0;0.4390323;0.4380714;410670.4;4.644248e+007
2976.842;0.1401963;0.01984187;447.4968;46.24143;4;4;0;0.4415633;0.4405913;410687.8;4.644561e+007
2982.842;0.1409463;0.02001516;447.2361;46.21449;4;4;0;0.4439254;0.442943;410448.5;4.641965e+007
2988.842;0.1418035;0.02002049;447.482;46.2399;4;4;0;0.4466251;0.4456307;410674.2;4.644642e+007
2994.842;0.1425535;0.02030845;446.7186;46.16101;4;4;0;0.4489873;0.4479824;409973.6;4.636827e+007
3000.842;0.1434106;0.02042528;447.6632;46.25863;4;4;0;0.451687;0.45067;410840.5;4.646757e+007
3006.842;0.1441606;0.02033515;447.2864;46.21969;4;4;0;0.4540492;0.4530215;410494.7;4.642955e+007
3012.842;0.1450178;0.02030618;447.582;46.25023;4;4;0;0.4567489;0.4557089;410766;4.646148e+007
3018.842;0.1457678;0.02036816;447.4426;46.23583;4;4;0;0.4591111;0.4580604;410638;4.64481e+007
3024.842;0.1465713;0.02037184;447.7905;46.27178;4;4;0;0.461642;0.4605797;410957.3;4.648539e+007
3030.842;0.1473749;0.02046647;447.7253;46.26504;4;4;0;0.4641729;0.463099;410897.5;4.647979e+007
3036.842;0.1482321;0.02034651;447.6154;46.25368;4;4;0;0.4668726;0.4657861;410796.6;4.646963e+007
3041.27;0.1483392;0.02054051;445.2445;46.00869;4;4;0;0.46721;0.466122;408620.8;4.622365e+007
3047.27;0.1444285;0.0220951;429.8184;44.41465;4;4;0;0.4548928;0.4538613;394463.5;4.461669e+007
3053.27;0.1344106;0.02556124;391.1035;40.41411;4;4;0;0.4233406;0.422447;358933.1;4.05852e+007
3059.27;0.1244464;0.02875307;353.8163;36.56109;4;4;0;0.391957;0.3911909;324713;3.670439e+007
3065.27;0.1143749;0.03205669;318.6337;32.92555;4;4;0;0.360236;0.3595887;292424.4;3.304416e+007
3071.27;0.1044106;0.03548355;284.1509;29.36232;4;4;0;0.3288524;0.3283129;260778;2.945888e+007
3077.27;0.09449994;0.03897541;250.8909;25.92544;4;4;0;0.2976376;0.2971955;230253.8;2.600261e+007
3083.27;0.08448209;0.04283777;219.3806;22.66937;4;4;0;0.2660853;0.2657319;201335.3;2.272969e+007
3089.27;0.07446424;0.04633684;189.1664;19.54723;4;4;0;0.234533;0.2342584;173606.4;1.959308e+007
3095.27;0.06444639;0.04999306;160.208;16.55486;4;4;0;0.2029808;0.202775;147030;1.658846e+007
3101.27;0.05437496;0.05324225;133.441;13.78893;4;4;0;0.1712597;0.1711132;122464.7;1.381254e+007
3107.27;0.04441069;0.05611386;108.8249;11.24526;4;4;0;0.1398762;0.1397784;99873.45;1.126099e+007
3113.27;0.03444641;0.05846959;86.71017;8.960069;4;4;0;0.1084926;0.1084338;79577.79;8969789
3119.27;0.02437499;0.06055349;66.50111;6.871795;4;4;0;0.07677161;0.07674215;61031.04;6877071
3125.27;0.01430356;0.06190186;53.59277;5.53793;4;4;0;0.04505059;0.04504045;49184.47;5540425
3131.27;0.004392855;0.06209234;51.92801;5.365905;4;4;0;0.01383576;0.01383481;47656.65;5366648
3137.08;0.0009107137;0.06180739;51.88446;5.361405;4;4;0;0.00286839;0.002868348;47616.68;5361559