File: Ensayos/Resistencia/comp/EsponjaB/REB1_com.raw
"Test Type";"Manual"
"Method Name:";"C:\INSTRON\user\template\CYCLE.MTM"
"Name:";""
"Operator ID:";""
"Company:";""
"Lab name:";""
"Test date:";"09/05/2017"
"Temperature:";""
"Humidity:";""
"Note 1:";""
"Note 2:";""
"Note 3:";""
"Geometry:";"Rectangular"
"Specimen";1
"Specimen name:";""
"Width:";0.250000;"in"
"Thickness:";0.060000;"in"
"Length:";1.250000;"in"
"Diameter:";0.039370;"in"
"Inner diameter:";0.019685;"in"
"Outer diameter:";0.039370;"in"
"Wall thickness:";0.019685;"in"
"Area:";0.015000;"in*in"
"Linear density:";1.000000;"den"
"Sled weight:";2.204623;"lbf"
"Loading span:";0.000000;"mm"
"Support span:";1.000000;"mm"
"Span ratio:";"2"
"Fixture type:";"3-point"
"Comment:";""
"Included"
"Final Width:";0.250000;"in"
"Final Thickness:";0.060000;"in"
"Final Length:";1.250000;"in"
"Final Diameter:";0.039370;"in"
"Final Inner diameter:";0.019685;"in"
"Final Outer diameter:";0.039370;"in"
"Final Wall thickness:";0.019685;"in"
"Final Area:";0.015000;"in*in"
"Final Linear density:";1.000000;"den"
"Time sec";"Extension mm";"Strain 1 %";"Load N";"Stress MPa";"Cycle Count ";"Total Cycle Count ";"Repetitions Count ";"Strain [Exten.] %";"True strain %";"Tenacity gf/tex";"True stress Pa"
0;0.1032321;0.0008323442;94.71226;9.786953;0;0;0;0.3251404;0.324613;86921.66;9818774
12;0.1432499;-0.004866932;234.4985;24.23157;0;0;0;0.4511808;0.4501661;215209.8;2.434089e+007
24;0.1832677;-0.01158678;369.3864;38.17;0;0;0;0.5772212;0.5755617;339002.3;3.839033e+007
36;0.2231784;-0.02085592;495.9344;51.24666;0;0;0;0.7029242;0.7004652;455141.1;5.160688e+007
48;0.2632498;-0.03265775;632.694;65.37851;0;0;0;0.8291333;0.8257149;580651.5;6.592058e+007
60;0.3033212;-0.0468255;780.7714;80.67987;0;0;0;0.9553425;0.9508079;716548.7;8.145064e+007
72;0.3433391;-0.06248436;942.2423;97.36523;0;0;0;1.081383;1.075578;864737.8;9.841812e+007
84.00001;0.3832498;-0.07866817;1111.815;114.8877;0;0;0;1.207086;1.199859;1020362;1.162745e+008
96.00001;0.4231605;-0.09572703;1288.354;133.1302;0;0;0;1.332789;1.323985;1182380;1.349045e+008
108;0.4632854;-0.1112845;1474.526;152.3679;0;0;0;1.459167;1.448623;1353238;1.545912e+008
120;0.5033568;-0.1276968;1661.926;171.7327;0;0;0;1.585376;1.57294;1525224;1.744554e+008
132;0.5433211;-0.1440567;1843.773;190.5236;0;0;0;1.711247;1.696771;1692113;1.937839e+008
144;0.5831782;-0.1575184;2031.771;209.9501;0;0;0;1.836782;1.820117;1864647;2.138064e+008
156;0.623196;-0.1739509;2227.74;230.2002;0;0;0;1.962822;1.943807;2044496;2.347186e+008
168;0.6632674;-0.1907046;2433.166;251.4277;0;0;0;2.089031;2.06751;2233025;2.566801e+008
180;0.7032317;-0.207843;2640.523;272.8546;0;0;0;2.214903;2.19073;2423326;2.788981e+008
192;0.7432495;-0.2253467;2850.863;294.5898;0;0;0;2.340944;2.313964;2616364;3.01486e+008
204;0.7832673;-0.2456445;3069.486;317.1808;0;0;0;2.466984;2.437045;2817004;3.250057e+008
216;0.8233388;-0.268607;3288.189;339.7802;0;0;0;2.593193;2.56014;3017718;3.485914e+008
228;0.863303;-0.2920607;3497.346;361.3931;0;0;0;2.719064;2.682755;3209670;3.712197e+008
240;0.9032137;-0.3153722;3696.774;382.0008;0;0;0;2.844768;2.805056;3392695;3.928678e+008
252;0.9432316;-0.3394129;3891.811;402.1546;0;0;0;2.970808;2.927535;3571689;4.141019e+008
264;0.9833565;-0.3663829;4080.094;421.6106;0;0;0;3.097186;3.050191;3744484;4.346686e+008
276;1.023374;-0.3966716;4259.969;440.1977;0;0;0;3.223226;3.17237;3909563;4.543862e+008
288;1.063231;-0.4276234;4436.174;458.4055;0;0;0;3.34876;3.29391;4071275;4.737565e+008
300;1.103142;-0.4614824;4604.681;475.818;0;0;0;3.474464;3.415467;4225921;4.923501e+008
312;1.143214;-0.498377;4767.547;492.6475;0;0;0;3.600672;3.537364;4375390;5.103861e+008
324;1.183285;-0.5377099;4921.561;508.5623;0;0;0;3.726882;3.659112;4516736;5.275158e+008
336;1.223196;-0.5796325;5069.759;523.8761;0;0;0;3.852585;3.780226;4652744;5.440589e+008
348;1.263213;-0.6225324;5213.787;538.759;0;0;0;3.978625;3.901516;4784925;5.601942e+008
360;1.303338;-0.6714068;5362.529;554.1291;0;0;0;4.105003;4.022985;4921432;5.768761e+008
372;1.343356;-0.7271759;5512.43;569.619;0;0;0;4.231043;4.143982;5059003;5.937198e+008
384;1.383267;-0.7882443;5658.273;584.6893;0;0;0;4.356746;4.26451;5192850;6.101628e+008
396;1.423178;-0.8534124;5803.753;599.7224;0;0;0;4.482449;4.384892;5326363;6.266046e+008
408;1.463249;-0.9184479;5945.389;614.3581;0;0;0;4.608658;4.505614;5456349;6.426718e+008
420;1.503428;-0.9845922;6082.083;628.4832;0;0;0;4.735205;4.626512;5581799;6.582432e+008
430.446;1.49132;-0.9727846;5733.556;592.4686;0;0;0;4.697072;4.590097;5261940;6.202973e+008
442.446;1.45141;-0.911285;5231.135;540.5518;0;0;0;4.571369;4.469961;4800847;5.652624e+008
454.446;1.411499;-0.8475006;4808.199;496.8482;0;0;0;4.445666;4.349681;4412699;5.189364e+008
466.446;1.371428;-0.7814898;4422.148;456.9562;0;0;0;4.319457;4.228771;4058402;4.766942e+008
478.446;1.331303;-0.7176181;4080.68;421.6711;0;0;0;4.193079;4.107552;3745022;4.393521e+008
490.446;1.291338;-0.6575843;3779.954;390.596;0;0;0;4.067208;3.986673;3469032;4.064823e+008
502.446;1.251428;-0.6006989;3508.519;362.5477;0;0;0;3.941505;3.86581;3219925;3.768375e+008
514.446;1.211463;-0.5463503;3254.244;336.2725;0;0;0;3.815633;3.744638;2986565;3.491035e+008
526.4461;1.171446;-0.4950576;3006.016;310.6223;0;0;0;3.689593;3.623156;2758755;3.220829e+008
538.4461;1.131428;-0.4468852;2768.297;286.0579;0;0;0;3.563552;3.501527;2540590;2.962517e+008
550.4461;1.091517;-0.4016427;2542.045;262.6785;0;0;0;3.43785;3.380076;2332948;2.71709e+008
562.4461;1.051446;-0.3595368;2319.97;239.7307;0;0;0;3.31164;3.257987;2129140;2.476698e+008
574.4461;1.011374;-0.318726;2102.257;217.2337;0;0;0;3.185431;3.135748;1929335;2.241535e+008
586.4461;0.9713029;-0.2842071;1890.405;195.3422;0;0;0;3.059222;3.013361;1734909;2.013182e+008
598.4461;0.9314458;-0.2569401;1690.158;174.65;0;0;0;2.933688;2.891479;1551134;1.797737e+008
610.4461;0.8914815;-0.2318221;1495.236;154.508;0;0;0;2.807816;2.769119;1372244;1.588463e+008
622.4461;0.8513566;-0.2096887;1301.346;134.4727;0;0;0;2.681438;2.646118;1194303;1.380785e+008
634.4461;0.8112852;-0.189917;1112.756;114.985;0;0;0;2.555229;2.523129;1021226;1.179231e+008
646.4461;0.7713745;-0.170148;932.1746;96.3249;0;0;0;2.429526;2.400482;855498.2;9.866514e+007
658.4461;0.7314638;-0.1534018;762.3586;78.77721;0;0;0;2.303823;2.277686;699650.5;8.05921e+007
670.4461;0.691446;-0.1361363;604.7523;62.4912;0;0;0;2.177783;2.154408;555008.1;6.385212e+007
682.4461;0.6514281;-0.1215314;463.7585;47.9218;0;0;0;2.051742;2.030977;425611.8;4.890504e+007
694.4461;0.6114639;-0.1097029;341.2733;35.26498;0;0;0;1.925871;1.90756;313201.7;3.594414e+007
706.4461;0.5714997;-0.1021018;244.7936;25.29539;0;0;0;1.799999;1.783991;224658;2.575071e+007
718.4461;0.5314282;-0.09520452;166.631;17.21857;0;0;0;1.67379;1.659936;152924.7;1.750678e+007
730.4461;0.4913568;-0.09065015;106.3445;10.98895;0;0;0;1.547581;1.535728;97597.09;1.115902e+007
742.4461;0.4513926;-0.08725158;81.62631;8.434735;0;0;0;1.421709;1.411697;74912.11;8554653
754.4461;0.4114819;-0.08676865;81.40741;8.412116;0;0;0;1.296006;1.28768;74711.21;8521138
766.4461;0.3714105;-0.08694002;81.43255;8.414714;0;0;0;1.169797;1.163007;74734.28;8513149
778.4461;0.3313391;-0.08710349;81.53028;8.424812;0;0;0;1.043588;1.03818;74823.98;8512733
789.3181;0.3484283;-0.0875193;81.8142;8.454151;1;1;0;1.097412;1.091434;75084.54;8546928
801.3181;0.3884462;-0.08724554;82.28068;8.502354;1;1;0;1.223452;1.216029;75512.65;8606376
813.3181;0.4285176;-0.0902573;155.8885;16.10851;1;1;0;1.349662;1.340635;143065.8;1.632592e+007
825.3181;0.4684818;-0.1016069;304.2338;31.43756;1;1;0;1.475533;1.464753;279209;3.190143e+007
837.3181;0.5084997;-0.1152934;465.949;48.14816;1;1;0;1.601574;1.588884;427622.2;4.891929e+007
849.3181;0.5485175;-0.1296355;646.1282;66.76671;1;1;0;1.727614;1.712861;592980.6;6.792018e+007
861.3181;0.5885889;-0.1460661;847.2467;87.549;1;1;0;1.853823;1.836849;777556.1;8.917201e+007
873.3181;0.6285532;-0.1629777;1061.543;109.6929;1;1;0;1.979695;1.960354;974224.9;1.118645e+008
885.3181;0.6684638;-0.1790286;1286.475;132.936;1;1;0;2.105398;2.083541;1180655;1.357348e+008
897.3181;0.7084817;-0.1953392;1513.057;156.3495;1;1;0;2.231438;2.206906;1388600;1.598384e+008
909.3181;0.7485531;-0.2146775;1748.069;180.6342;1;1;0;2.357647;2.330284;1604281;1.848929e+008
921.3181;0.7885709;-0.2362237;1989.8;205.613;1;1;0;2.483688;2.453346;1826128;2.107198e+008
933.3181;0.8284816;-0.2568847;2231.72;230.6115;1;1;0;2.609391;2.575927;2048149;2.366291e+008
945.3181;0.8683923;-0.2793291;2469.563;255.1887;1;1;0;2.735094;2.698359;2266428;2.621683e+008
957.3181;0.9084637;-0.3024819;2704.447;279.46;1;1;0;2.861303;2.821132;2481991;2.874562e+008
969.3181;0.9484815;-0.3256231;2933.501;303.1291;1;1;0;2.987343;2.943591;2692205;3.121846e+008
981.3181;0.9884458;-0.3517368;3161.027;326.6401;1;1;0;3.113215;3.065737;2901015;3.368091e+008
993.3181;1.028517;-0.3801407;3386.956;349.9862;1;1;0;3.239424;3.188061;3108361;3.613237e+008
1005.318;1.068589;-0.4118912;3604.543;372.4702;1;1;0;3.365633;3.310236;3308050;3.850061e+008
1017.318;1.108606;-0.4444369;3815.192;394.2372;1;1;0;3.491674;3.432098;3501372;4.080027e+008
1029.318;1.148464;-0.4796842;4016.37;415.0258;1;1;0;3.617208;3.553323;3686002;4.300381e+008
1041.318;1.188428;-0.5168644;4213.837;435.4307;1;1;0;3.74308;3.674727;3867226;4.517292e+008
1053.318;1.228499;-0.5558679;4407.65;455.4581;1;1;0;3.869289;3.796308;4045097;4.730811e+008
1065.318;1.268624;-0.5980248;4598.455;475.1747;1;1;0;3.995667;3.917905;4220208;4.94161e+008
1077.318;1.308535;-0.6445052;4795.104;495.4951;1;1;0;4.121369;4.038704;4400681;5.159163e+008
1089.318;1.348446;-0.696541;4996.938;516.3513;1;1;0;4.247073;4.159359;4585913;5.382811e+008
1101.318;1.38841;-0.7532724;5207.253;538.0839;1;1;0;4.372944;4.28003;4778928;5.61614e+008
1113.318;1.428535;-0.8130407;5416.296;559.6851;1;1;0;4.499322;4.40104;4970777;5.848671e+008
1125.318;1.468445;-0.8719539;5614.48;580.1641;1;1;0;4.625025;4.521258;5152659;6.069968e+008
1137.318;1.508463;-0.9343962;5810.597;600.4296;1;1;0;4.751066;4.641655;5332644;6.289564e+008
1149.318;1.548535;-0.9990892;5994.73;619.4567;1;1;0;4.877275;4.762067;5501631;6.496693e+008
1161.318;1.588553;-1.069483;6166.31;637.1866;1;1;0;5.003315;4.882174;5659098;6.69067e+008
1173.318;1.628517;-1.139291;6322.276;653.3032;1;1;0;5.129187;5.001976;5802235;6.868123e+008
1185.318;1.668428;-1.209707;6461.807;667.7214;1;1;0;5.25489;5.121475;5930289;7.028094e+008
1197.318;1.708499;-1.284292;6600.334;682.0359;1;1;0;5.381099;5.241311;6057421;7.187369e+008
1209.318;1.748624;-1.356362;6719.947;694.3959;1;1;0;5.507477;5.361164;6167195;7.326396e+008
1221.318;1.788642;-1.428816;6815.492;704.2689;1;1;0;5.633517;5.480553;6254881;7.43944e+008
1233.318;1.828445;-1.502916;6934.325;716.5483;1;1;0;5.758883;5.599163;6363939;7.578135e+008
1245.318;1.868409;-1.580361;7045.8;728.0674;1;1;0;5.884754;5.718109;6466245;7.709124e+008
1257.318;1.908481;-1.644155;7145.389;738.3583;1;1;0;6.010963;5.837233;6557643;7.827408e+008
1269.318;1.948499;-1.722209;7230.488;747.1519;1;1;0;6.137004;5.956057;6635742;7.930047e+008
1281.318;1.988409;-1.8015;7340.47;758.5168;1;1;0;6.262707;6.074421;6736677;8.060205e+008
1293.318;2.028535;-1.878708;7449.018;769.7335;1;1;0;6.389085;6.19328;6836297;8.189124e+008
1305.318;2.068552;-1.961635;7553.059;780.4844;1;1;0;6.515125;6.311681;6931780;8.313339e+008
1315.402;2.068874;-1.977958;7310.527;755.4226;1;1;0;6.516137;6.312631;6709196;8.04647e+008
1327.402;2.028802;-1.923306;6744.362;696.9188;1;1;0;6.389928;6.194073;6189602;7.414514e+008
1339.402;1.988838;-1.863647;6296.343;650.6234;1;1;0;6.264057;6.075691;5778435;6.913788e+008
1351.402;1.948874;-1.802207;5892.662;608.9096;1;1;0;6.138186;5.957169;5407959;6.462856e+008
1363.402;1.908802;-1.738453;5522.45;570.6544;1;1;0;6.011976;5.838188;5068199;6.049619e+008
1375.402;1.868677;-1.67129;5175.636;534.8168;1;1;0;5.885598;5.718906;4749912;5.662939e+008
1387.402;1.828713;-1.601788;4847.684;500.9283;1;1;0;5.759727;5.59996;4448936;5.297804e+008
1399.402;1.788856;-1.530557;4544.808;469.6311;1;1;0;5.634192;5.481192;4170973;4.96091e+008
1411.402;1.748838;-1.459699;4262.9;440.5005;1;1;0;5.508152;5.361803;3912254;4.64764e+008
1423.402;1.708713;-1.387235;3997.756;413.1023;1;1;0;5.381774;5.241951;3668919;4.353345e+008
1435.402;1.668695;-1.314802;3747.27;387.2187;1;1;0;5.255733;5.122276;3439037;4.075699e+008
1447.402;1.628785;-1.238413;3517.195;363.4442;1;1;0;5.130031;5.002778;3227887;3.82089e+008
1459.402;1.58882;-1.163548;3298.465;340.842;1;1;0;5.004159;4.882977;3027148;3.578983e+008
1471.402;1.548856;-1.088562;3090.301;319.3317;1;1;0;4.878287;4.763032;2836107;3.349096e+008
1483.402;1.508785;-1.016309;2892.698;298.9128;1;1;0;4.752078;4.642621;2654758;3.131173e+008
1495.402;1.468874;-0.9458686;2705.845;279.6045;1;1;0;4.626375;4.522548;2483275;2.925401e+008
1507.402;1.428856;-0.8797103;2527.927;261.2197;1;1;0;4.500334;4.402009;2319992;2.729755e+008
1519.402;1.388785;-0.8128883;2352.395;243.0813;1;1;0;4.374125;4.281162;2158897;2.537139e+008
1531.402;1.348713;-0.7507629;2185.32;225.8168;1;1;0;4.247916;4.160169;2005566;2.354094e+008
1543.402;1.308803;-0.6932549;2033.553;210.1343;1;1;0;4.122213;4.039515;1866283;2.187965e+008
1555.402;1.268838;-0.6400093;1890.994;195.4032;1;1;0;3.996341;3.918553;1735450;2.032121e+008
1567.402;1.228767;-0.5883352;1752.589;181.1012;1;1;0;3.870132;3.797121;1608429;1.881101e+008
1579.402;1.188642;-0.5376809;1614.467;166.8286;1;1;0;3.743755;3.675378;1481669;1.730743e+008
1591.402;1.148731;-0.4907211;1477.107;152.6347;1;1;0;3.618051;3.554137;1355607;1.581571e+008
1603.402;1.108821;-0.4451809;1340.372;138.5054;1;1;0;3.492348;3.43275;1230120;1.433425e+008
1615.402;1.068856;-0.4031464;1204.222;124.4366;1;1;0;3.366477;3.311052;1105169;1.286257e+008
1627.402;1.028785;-0.3696877;1069.739;110.54;1;1;0;3.240268;3.188878;981747.6;1.141218e+008
1639.402;0.9888208;-0.3376321;939.8118;97.11408;1;1;0;3.114396;3.066883;862507.3;1.001386e+008
1651.402;0.9488565;-0.3086939;814.8489;84.20122;1;1;0;2.988524;2.944738;747823.2;8.67176e+007
1663.402;0.9087852;-0.2824643;693.8347;71.6964;1;1;0;2.862315;2.822116;636763;7.374857e+007
1675.402;0.8687138;-0.2575658;577.9021;59.71667;1;1;0;2.736106;2.699344;530366.5;6.135058e+007
1687.402;0.8287495;-0.2321574;470.711;48.64024;1;1;0;2.610234;2.576749;431992.5;4.990986e+007
1699.402;0.7888387;-0.2146989;367.1981;37.94388;1;1;0;2.484531;2.454169;336994.1;3.888661e+007
1711.402;0.7488209;-0.1987353;272.9162;28.2014;1;1;0;2.358491;2.331108;250467.4;2.886653e+007
1723.402;0.708696;-0.1885228;194.4251;20.09064;1;1;0;2.232113;2.207566;178432.6;2.053908e+007
1735.402;0.6686781;-0.1812347;134.1941;13.86675;1;1;0;2.106073;2.084202;123155.9;1.41588e+007
1747.402;0.628821;-0.1773577;87.63022;9.05514;1;1;0;1.980539;1.961181;80422.16;9234481
1759.402;0.5888567;-0.1761128;81.30454;8.401486;1;1;0;1.854667;1.837678;74616.8;8557306
1771.402;0.5488389;-0.1756532;81.40806;8.412183;1;1;0;1.728627;1.713856;74711.8;8557598
1783.402;0.5087675;-0.1743218;81.4495;8.416465;1;1;0;1.602417;1.589714;74749.84;8551332
1795.402;0.4688569;-0.1750939;81.30933;8.40198;1;1;0;1.476714;1.465917;74621.2;8526054
1807.402;0.428839;-0.1746725;81.16153;8.386708;1;1;0;1.350674;1.341634;74485.55;8499985
1817.774;0.4341962;-0.1742467;81.38312;8.409606;2;2;0;1.367547;1.35828;74688.92;8524612
1829.774;0.4741604;-0.1747657;81.79567;8.452236;2;2;0;1.493419;1.482377;75067.53;8578463
1841.774;0.5142318;-0.1745522;82.04808;8.478318;2;2;0;1.619628;1.606652;75299.18;8615635
1853.608;0.655821;-0.2143969;547.3784;56.56255;2;2;0;2.065578;2.044534;502353.6;5.773089e+007
1863.42;0.8193745;-0.3093718;1448.711;149.7005;2;2;0;2.580707;2.547969;1329547;1.535638e+008
1873.096;0.9805708;-0.4218761;2349.658;242.7984;2;2;0;3.088412;3.04168;2156386;2.502971e+008
1883.622;1.156124;-0.5761166;3251.098;335.9475;2;2;0;3.641336;3.576606;2983678;3.481805e+008
1895.286;1.350535;-0.7938489;4147.831;428.61;2;2;0;4.253653;4.165672;3806649;4.468416e+008
1906.436;1.536267;-1.082447;5048.71;521.7011;2;2;0;4.838635;4.725218;4633427;5.469443e+008
1917.514;1.720981;-1.395674;5949.607;614.7939;2;2;0;5.420413;5.27861;5460220;6.481183e+008
1928.87;1.910088;-1.722881;6843.233;707.1356;2;2;0;6.016025;5.842008;6280341;7.49677e+008
1938.46;2.060731;-2.008637;7381.666;762.7737;2;2;0;6.49049;6.288551;6774485;8.122815e+008
1942.232;1.996767;-1.920302;6478.868;669.4844;2;2;0;6.289028;6.099188;5945947;7.115885e+008
1947.474;1.909177;-1.782895;5577.041;576.2954;2;2;0;6.013157;5.839302;5118300;6.10949e+008
1953.752;1.80466;-1.601588;4674.532;483.0359;2;2;0;5.683967;5.528301;4290026;5.104915e+008
1961.442;1.676517;-1.368953;3773.284;389.9068;2;2;0;5.280368;5.145678;3462911;4.104953e+008
1970.97;1.517731;-1.067577;2872.098;296.784;2;2;0;4.780256;4.669517;2635852;3.10971e+008
1982.62;1.323588;-0.7367346;1996.125;206.2667;2;2;0;4.168782;4.08423;1831933;2.148655e+008
1994.62;1.123392;-0.4801871;1271.457;131.3842;2;2;0;3.538243;3.477086;1166873;1.360329e+008
2006.62;0.9234637;-0.3057715;597.9574;61.78905;2;2;0;2.908547;2.867051;548772.1;6.358622e+007
2018.62;0.7235353;-0.2252675;120.9568;12.49889;2;2;0;2.278851;2.253273;111007.4;1.278372e+007
2030.62;0.5235532;-0.2198279;79.95777;8.26232;2;2;0;1.648987;1.635538;73380.81;8398564
2042.62;0.3236248;-0.2172943;68.38966;7.066946;2;2;0;1.019291;1.014131;62764.24;7138978
2053.346;0.4781783;-0.2183024;80.73918;8.343065;3;3;0;1.506073;1.494845;74097.95;8468718
2065.346;0.6781067;-0.2296346;284.964;29.44634;3;3;0;2.135769;2.113281;261524.2;3.007525e+007
2075.7;0.8507673;-0.3255777;1182.02;122.1423;3;3;0;2.679582;2.64431;1084793;1.254152e+008
2085.456;1.013303;-0.4472769;2083.497;215.2951;3;3;0;3.191505;3.141635;1912118;2.221663e+008
2095.964;1.188428;-0.6098439;2984.784;308.4283;3;3;0;3.74308;3.674727;2739270;3.19973e+008
2107.476;1.380213;-0.8364926;3885.043;401.4553;3;3;0;4.347129;4.255293;3565478;4.189071e+008
2118.506;1.56407;-1.127898;4786.089;494.5635;3;3;0;4.926206;4.808712;4392408;5.189267e+008
2129.258;1.743374;-1.438183;5687.199;587.6784;3;3;0;5.490942;5.34549;5219396;6.199475e+008
2139.738;1.917963;-1.739665;6588.347;680.7972;3;3;0;6.040829;5.865401;6046420;7.21923e+008
2149.266;2.066999;-2.015886;7225.359;746.6219;3;3;0;6.510231;6.307087;6631035;7.952288e+008
2153.07;2.002392;-1.926176;6322.128;653.2879;3;3;0;6.306745;6.115855;5802099;6.944891e+008
2158.394;1.913677;-1.78628;5420.351;560.1041;3;3;0;6.02733;5.852671;4974499;5.938634e+008
2164.752;1.80766;-1.602956;4518.342;466.8963;3;3;0;5.693416;5.537242;4146684;4.934787e+008
2172.576;1.677267;-1.366305;3617.355;373.7941;3;3;0;5.28273;5.147921;3319808;3.935407e+008
2182.346;1.51441;-1.061328;2716.709;280.7271;3;3;0;4.769794;4.659533;2493245;2.941173e+008
2194.17;1.317267;-0.7343981;1851.685;191.3411;3;3;0;4.148872;4.065116;1699374;1.992796e+008
2206.17;1.117339;-0.4826585;1141.646;117.9704;3;3;0;3.519176;3.458669;1047740;1.221219e+008
2218.17;0.9174637;-0.3162193;496.4325;51.29812;3;3;0;2.889649;2.848686;455598.2;5.278046e+007
2230.17;0.7174281;-0.2501792;80.78294;8.347587;3;3;0;2.259616;2.234465;74138.1;8536210
2242.17;0.5174996;-0.2479649;79.93425;8.259889;3;3;0;1.62992;1.61678;73359.23;8394519
2252.376;0.5806604;-0.2471884;80.77357;8.34662;4;4;0;1.828852;1.812329;74129.51;8499266
2264.226;0.7780709;-0.2797302;542.3714;56.04515;4;4;0;2.450617;2.421071;497758.4;5.741861e+007
2273.954;0.940178;-0.395223;1443.364;149.1479;4;4;0;2.96119;2.918194;1324640;1.535645e+008
2283.978;1.107321;-0.532918;2344.22;242.2366;4;4;0;3.487624;3.428185;2151396;2.506849e+008
2295.18;1.294124;-0.726851;3245.269;335.3451;4;4;0;4.075981;3.995103;2978328;3.490137e+008
2306.212;1.477981;-0.9913304;4146.19;428.4405;4;4;0;4.655059;4.54996;3805144;4.483846e+008
2316.998;1.657713;-1.294339;5047.76;521.6028;4;4;0;5.221144;5.089408;4632554;5.488365e+008
2327.53;1.83332;-1.596509;5948.846;614.7153;4;4;0;5.774237;5.61368;5459521;6.502104e+008
2337.67;2.002124;-1.889067;6849.765;707.8105;4;4;0;6.305902;6.115062;6286335;7.524443e+008
2343.664;2.045463;-1.988438;6749.397;697.4391;4;4;0;6.442403;6.243383;6194223;7.423709e+008
2348.212;1.969659;-1.874789;5847.133;604.2049;4;4;0;6.203652;6.018831;5366174;6.416877e+008
2354.04;1.872535;-1.716102;4945.118;510.9966;4;4;0;5.897747;5.730379;4538356;5.411338e+008
2360.992;1.756606;-1.509646;4042.931;417.7704;4;4;0;5.532617;5.384989;3710378;4.40884e+008
2369.722;1.611267;-1.239932;3141.616;324.6343;4;4;0;5.074856;4.950282;2883201;3.41109e+008
2380.656;1.42891;-0.9090527;2241.326;231.6041;4;4;0;4.500503;4.40217;2056965;2.420275e+008
2392.656;1.228928;-0.6163809;1464.061;151.2866;4;4;0;3.870639;3.797608;1343634;1.571423e+008
2404.656;1.028999;-0.4018421;780.0107;80.60126;4;4;0;3.240943;3.189532;715850.6;8.321351e+007
2416.656;0.8289637;-0.2837368;227.0465;23.46152;4;4;0;2.610909;2.577407;208370.7;2.407408e+007
2428.656;0.6290889;-0.264863;80.36896;8.304809;4;4;0;1.981382;1.962008;73758.17;8469359
2439.076;0.6551782;-0.2649108;80.82159;8.351581;5;5;0;2.063553;2.04255;74173.57;8523920
2450.436;0.8447673;-0.3193342;742.3847;76.71323;5;5;0;2.660684;2.625904;681319.5;7.875433e+007
2460.168;1.006928;-0.4441905;1643.776;169.8572;5;5;0;3.171427;3.122175;1508567;1.752441e+008
2470.458;1.178356;-0.602263;2544.919;262.9754;5;5;0;3.711359;3.644146;2335585;2.727354e+008
2481.808;1.367517;-0.825488;3445.648;356.051;5;5;0;4.30714;4.216963;3162224;3.713866e+008
2492.634;1.548053;-1.106325;4346.537;449.143;5;5;0;4.875756;4.760619;3989011;4.710421e+008
2503.266;1.725106;-1.413689;5247.155;542.2071;5;5;0;5.433405;5.290934;4815548;5.716674e+008
2513.438;1.89482;-1.708793;6148.229;635.3183;5;5;0;5.967937;5.796639;5642504;6.732337e+008
2523.312;2.059338;-1.990576;7049.57;728.457;5;5;0;6.486104;6.284431;6469705;7.757055e+008
2527.082;2.032713;-1.968358;6463.481;667.8943;5;5;0;6.402245;6.205649;5931825;7.106546e+008
2532.022;1.950267;-1.841987;5560.512;574.5873;5;5;0;6.142572;5.961302;5103130;6.098818e+008
2538.13;1.848534;-1.670971;4659.179;481.4495;5;5;0;5.822156;5.658972;4275937;5.094802e+008
2545.53;1.72516;-1.446979;3757.599;388.286;5;5;0;5.433574;5.291094;3448516;4.093838e+008
2554.854;1.56991;-1.155146;2856.471;295.1693;5;5;0;4.944597;4.826238;2621511;3.097642e+008
2566.336;1.378445;-0.8240042;1967.843;203.3441;5;5;0;4.34156;4.249957;1805977;2.121725e+008
2578.336;1.17841;-0.5543858;1237.259;127.8503;5;5;0;3.711527;3.644308;1135488;1.325955e+008
2590.336;0.9785886;-0.3650489;576.633;59.58553;5;5;0;3.082169;3.035624;529201.8;6.142205e+007
2602.336;0.7785531;-0.2824727;105.3924;10.89057;5;5;0;2.452136;2.422553;96723.29;1.115762e+007
2614.336;0.5786246;-0.278923;79.90233;8.256591;5;5;0;1.82244;1.806032;73329.93;8407062
2624.87;0.4028569;-0.2779647;70.58095;7.29338;6;6;0;1.268841;1.260858;64775.29;7385921
2636.87;0.6028925;-0.2781612;81.27268;8.398193;6;6;0;1.898874;1.88107;74587.56;8557665
2648.744;0.8008388;-0.3111782;523.0984;54.05361;6;6;0;2.522327;2.491041;480070.7;5.541702e+007
2658.748;0.9676602;-0.4299577;1424.496;147.1982;6;6;0;3.047749;3.002227;1307324;1.516845e+008
2669.116;1.140481;-0.5795246;2325.563;240.3086;6;6;0;3.592068;3.529057;2134273;2.489407e+008
2680.676;1.333124;-0.7903292;3226.355;333.3907;6;6;0;4.198816;4.113058;2960970;3.473891e+008
2691.612;1.515267;-1.065617;4127.105;426.4684;6;6;0;4.772494;4.662109;3787628;4.468215e+008
2702.334;1.694035;-1.370729;5028.219;519.5836;6;6;0;5.335542;5.198071;4614621;5.473062e+008
2712.592;1.865088;-1.665257;5929.542;612.7205;6;6;0;5.874293;5.708229;5441805;6.487135e+008
2722.354;2.027784;-1.935879;6830.654;705.8357;6;6;0;6.386722;6.191059;6268796;7.509155e+008
2727.104;2.027731;-1.959122;6437.957;665.2569;6;6;0;6.386553;6.1909;5908400;7.077439e+008
2731.95;1.946892;-1.835142;5536.003;572.0547;6;6;0;6.131942;5.951287;5080637;6.071328e+008
2738.016;1.845802;-1.664826;4633.841;478.8312;6;6;0;5.81355;5.65084;4252683;5.066683e+008
2745.394;1.722802;-1.441439;3732.083;385.6493;6;6;0;5.426149;5.284052;3425099;4.065752e+008
2754.676;1.568195;-1.153662;2831.031;292.5405;6;6;0;4.939198;4.821092;2598164;3.069896e+008
2766.14;1.377053;-0.8258703;1945.048;200.9887;6;6;0;4.337174;4.245752;1785057;2.097059e+008
2778.14;1.177017;-0.5575838;1214.388;125.487;6;6;0;3.70714;3.640078;1114498;1.30139e+008
2790.14;0.9770886;-0.3703034;554.4599;57.29431;6;6;0;3.077444;3.031041;508852.6;5.905751e+007
2802.14;0.776946;-0.2916928;93.91399;9.704465;6;6;0;2.447074;2.417613;86189.05;9941940
2814.14;0.577071;-0.2884914;80.18736;8.286043;6;6;0;1.817547;1.801227;73591.52;8436646
2825.038;0.4286783;-0.289381;80.55362;8.323891;7;7;0;1.350168;1.341134;73927.65;8436277
2837.038;0.6287674;-0.2887001;81.3063;8.401669;7;7;0;1.98037;1.961016;74618.42;8568052
2848.76;0.8242495;-0.3306497;600.2247;62.02334;7;7;0;2.596061;2.562936;550852.9;6.36335e+007
2858.866;0.9925172;-0.4545064;1501.376;155.1425;7;7;0;3.126039;3.078173;1377880;1.599924e+008
2869.414;1.168338;-0.6123134;2402.47;248.2557;7;7;0;3.679806;3.613718;2204854;2.57391e+008
2881.002;1.361517;-0.8345162;3303.123;341.3233;7;7;0;4.288242;4.198844;3031423;3.559601e+008
2891.95;1.543928;-1.116187;4204.203;434.4352;7;7;0;4.862764;4.74823;3858385;4.555607e+008
2902.64;1.72216;-1.421411;5105.363;527.5552;7;7;0;5.424125;5.282131;4685420;5.561705e+008
2912.738;1.890374;-1.705665;5999.984;619.9996;7;7;0;5.953933;5.783422;5506453;6.569139e+008
2922.334;2.050338;-1.971905;6901.382;713.1443;7;7;0;6.457757;6.257808;6333707;7.591974e+008
2926.68;2.033141;-1.958535;6363.257;657.5379;7;7;0;6.403595;6.206918;5839845;6.99644e+008
2931.622;1.950642;-1.831449;5461.404;564.3462;7;7;0;6.143754;5.962415;5012174;5.990183e+008
2937.762;1.84832;-1.658911;4559.923;471.1929;7;7;0;5.821481;5.658335;4184844;4.986233e+008
2945.242;1.723767;-1.433656;3658.768;378.0734;7;7;0;5.429187;5.286933;3357814;3.985997e+008
2954.678;1.566428;-1.142039;2757.781;284.9713;7;7;0;4.93363;4.815787;2530938;2.990307e+008
2966.262;1.373463;-0.815304;1879.271;194.1917;7;7;0;4.325869;4.234917;1724691;2.025922e+008
2978.262;1.173428;-0.551482;1159.317;119.7963;7;7;0;3.695836;3.629177;1063957;1.242238e+008
2990.262;0.9733387;-0.3699575;515.16;53.23331;7;7;0;3.065634;3.019582;472785.3;5.486525e+007
3002.262;0.7734638;-0.2983958;81.92482;8.465582;7;7;0;2.436106;2.406907;75186.06;8671812
3014.262;0.5733211;-0.2969998;80.55925;8.324472;7;7;0;1.805736;1.789626;73932.82;8474791
3024.304;0.439339;-0.2951482;80.79192;8.348516;8;8;0;1.383745;1.374259;74146.35;8464037
3036.304;0.6394817;-0.296235;81.75602;8.448139;8;8;0;2.014116;1.9941;75031.15;8618294
3048.02;0.8347494;-0.3400889;607.0135;62.72486;8;8;0;2.629132;2.595165;557083.4;6.437397e+007
3058.186;1.004142;-0.4653068;1508.116;155.839;8;8;0;3.162653;3.113671;1384066;1.607677e+008
3068.944;1.183446;-0.6284993;2408.904;248.9206;8;8;0;3.727388;3.6596;2210759;2.581988e+008
3080.594;1.377588;-0.856514;3306.906;341.7143;8;8;0;4.338861;4.247369;3034895;3.565408e+008
3091.61;1.561124;-1.139387;4207.761;434.8028;8;8;0;4.916926;4.799867;3861650;4.561817e+008
3102.17;1.737053;-1.438669;5108.927;527.9235;8;8;0;5.471032;5.326615;4688690;5.568064e+008
3112.082;1.902427;-1.719025;6009.912;621.0255;8;8;0;5.991897;5.819246;5515564;6.582367e+008
3121.648;2.061749;-1.982312;6911.412;714.1806;8;8;0;6.493697;6.291561;6342911;7.605573e+008
3125.542;2.036891;-1.953163;6336.397;654.7623;8;8;0;6.415406;6.218017;5815194;6.96768e+008
3130.498;1.954177;-1.826465;5434.579;561.5743;8;8;0;6.154889;5.972905;4987556;5.961386e+008
3136.666;1.85132;-1.652483;4532.512;468.3605;8;8;0;5.83093;5.667263;4159689;4.956703e+008
3144.168;1.726285;-1.427016;3630.926;375.1965;8;8;0;5.437117;5.294454;3332263;3.955964e+008
3153.658;1.568303;-1.13498;2729.661;282.0656;8;8;0;4.939536;4.821415;2505132;2.959983e+008
3165.274;1.374696;-0.8106399;1853.101;191.4875;8;8;0;4.32975;4.238636;1700674;1.997784e+008
3177.274;1.174499;-0.549217;1137.908;117.5841;8;8;0;3.69921;3.632432;1044309;1.219338e+008
3189.274;0.9745709;-0.3722911;498.8584;51.54881;8;8;0;3.069515;3.023347;457824.6;5.31311e+007
3201.274;0.7746959;-0.3036877;81.45945;8.417493;8;8;0;2.439987;2.410695;74758.97;8622879
3213.274;0.5746068;-0.302926;80.5905;8.327702;8;8;0;1.809785;1.793603;73961.49;8478415
3224.034;0.461839;-0.3025606;81.1317;8.383625;9;9;0;1.454611;1.444133;74458.17;8505574
3236.034;0.6619817;-0.3019941;81.98699;8.472006;9;9;0;2.084982;2.063543;75243.12;8648646
3247.64;0.855428;-0.3542622;673.7627;69.62228;9;9;0;2.694262;2.658605;618342.1;7.149809e+007
3257.904;1.026428;-0.4828275;1574.769;162.7265;9;9;0;3.232844;3.181687;1445236;1.679872e+008
3268.844;1.208839;-0.6520139;2475.596;255.8121;9;9;0;3.807366;3.736674;2271965;2.655518e+008
3280.398;1.401374;-0.8864955;3372.888;348.5325;9;9;0;4.413776;4.319144;3095450;3.639159e+008
3291.424;1.585178;-1.17291;4273.862;441.6333;9;9;0;4.992685;4.87205;3922314;4.636827e+008
3301.948;1.760463;-1.468836;5174.869;534.7375;9;9;0;5.544766;5.3965;4749208;5.643875e+008
3311.79;1.924606;-1.746225;6076.327;627.8884;9;9;0;6.061751;5.88513;5576516;6.659494e+008
3321.37;2.084195;-2.020322;6977.528;721.0127;9;9;0;6.564394;6.357925;6403589;7.683428e+008
3324.824;2.041874;-1.971277;6266.103;647.4987;9;9;0;6.431098;6.232762;5750683;6.891399e+008
3329.928;1.956963;-1.837682;5363.301;554.2089;9;9;0;6.163663;5.981171;4922141;5.883684e+008
3336.202;1.852338;-1.660353;4462.135;461.0883;9;9;0;5.834136;5.670293;4095101;4.879888e+008
3343.81;1.725428;-1.432315;3560.869;367.9572;9;9;0;5.434418;5.291894;3267968;3.879535e+008
3353.484;1.564338;-1.131851;2659.836;274.8503;9;9;0;4.92705;4.809516;2441050;2.883923e+008
3365.188;1.369178;-0.8097501;1789.547;184.9202;9;9;0;4.31237;4.221977;1642347;1.928947e+008
3377.188;1.169249;-0.5489773;1088.534;112.4821;9;9;0;3.682675;3.616484;998996.1;1.166244e+008
3389.188;0.9692673;-0.3742138;462.4048;47.78193;9;9;0;3.05281;3.007139;424369.5;4.924062e+007
3401.188;0.7691781;-0.3120943;81.31182;8.402239;9;9;0;2.422608;2.393728;74623.48;8605792
3411.374;0.5995175;-0.3109949;80.82023;8.35144;10;10;0;1.888244;1.870638;74172.33;8509136
3423.374;0.799553;-0.3197243;274.1466;28.32854;10;10;0;2.518277;2.487091;251596.6;2.904193e+007
3433.838;0.973928;-0.4333611;1174.985;121.4154;10;10;0;3.06749;3.021383;1078336;1.251398e+008
3444.372;1.149535;-0.5824696;2075.98;214.5183;10;10;0;3.620583;3.55658;1905219;2.222851e+008
3455.97;1.342767;-0.7930253;2976.253;307.5467;10;10;0;4.229187;4.142202;2731440;3.205535e+008
3466.874;1.524535;-1.070261;3877.173;400.642;10;10;0;4.801684;4.689966;3558255;4.198796e+008
3477.534;1.702231;-1.37217;4778.217;493.7501;10;10;0;5.361358;5.222576;4385183;5.202218e+008
3487.578;1.869481;-1.657556;5679.553;586.8882;10;10;0;5.888129;5.721297;5212379;6.21445e+008
3497.066;2.027838;-1.920728;6580.356;679.9715;10;10;0;6.386891;6.191218;6039086;7.234005e+008
3502.048;2.053338;-1.97967;6447.2;666.212;10;10;0;6.467206;6.266683;5916883;7.092973e+008
3506.68;1.976195;-1.863794;5545.676;573.0544;10;10;0;6.224236;6.038211;5089515;6.087226e+008
3512.66;1.876499;-1.69806;4644.027;479.8838;10;10;0;5.910233;5.742169;4262031;5.08246e+008
3519.836;1.756767;-1.482181;3742.979;386.7753;10;10;0;5.533123;5.385468;3435099;4.08176e+008
3528.986;1.604356;-1.19989;2841.994;293.6733;10;10;0;5.05309;4.929566;2608225;3.085129e+008
3540.314;1.415624;-0.8744336;1954.133;201.9275;10;10;0;4.458659;4.36212;1793395;2.109307e+008
3552.314;1.215374;-0.5969182;1216.364;125.6912;10;10;0;3.82795;3.756502;1116312;1.305026e+008
3564.314;1.015499;-0.4020176;572.8352;59.19309;10;10;0;3.198423;3.148339;525716.4;6.108634e+007
3576.314;0.8155709;-0.316295;103.9292;10.73937;10;10;0;2.568727;2.53629;95380.44;1.101523e+007
3588.314;0.6155353;-0.3131796;80.9206;8.361813;10;10;0;1.938694;1.920141;74264.45;8523922
3598.56;0.4448569;-0.3126938;69.37235;7.16849;11;11;0;1.401124;1.391399;63666.1;7268930
3610.56;0.6446781;-0.3127068;82.23473;8.497605;11;11;0;2.030482;2.010143;75470.48;8670148
3622.426;0.8425709;-0.3464978;520.5746;53.79282;11;11;0;2.653767;2.619165;477754.6;5.522036e+007
3632.806;1.015499;-0.4741531;1421.485;146.8871;11;11;0;3.198423;3.148339;1304560;1.515851e+008
3643.758;1.198178;-0.6410185;2322.508;239.993;11;11;0;3.773788;3.704323;2131470;2.490499e+008
3655.412;1.39232;-0.8736008;3219.427;332.6748;11;11;0;4.385261;4.29183;2954612;3.472635e+008
3666.482;1.576767;-1.162794;4120.418;425.7774;11;11;0;4.966195;4.846816;3781491;4.469223e+008
3676.99;1.752052;-1.459185;5021.408;518.8799;11;11;0;5.518275;5.371398;4608370;5.475131e+008
3686.838;1.916195;-1.736842;5922.355;611.9779;11;11;0;6.03526;5.86015;5435210;6.489124e+008
3696.162;2.071499;-1.993101;6823.528;705.0992;11;11;0;6.524405;6.320393;6262256;7.511028e+008
3699.67;2.039838;-1.958139;6220.99;642.837;11;11;0;6.424686;6.226738;5709281;6.841372e+008
3704.688;1.956213;-1.82826;5319.169;549.6486;11;11;0;6.161301;5.978946;4881639;5.83514e+008
3710.932;1.852017;-1.652531;4417.78;456.5049;11;11;0;5.833124;5.669336;4054394;4.831334e+008
3718.544;1.725052;-1.421306;3516.237;363.3453;11;11;0;5.433236;5.290773;3227008;3.830867e+008
3728.236;1.563642;-1.123642;2615.266;270.2447;11;11;0;4.924856;4.807425;2400147;2.835539e+008
3739.948;1.368374;-0.801532;1746.561;180.4783;11;11;0;4.30984;4.219551;1602897;1.882567e+008
3751.948;1.168338;-0.5447176;1051.263;108.6307;11;11;0;3.679806;3.613718;964790.8;1.126281e+008
3763.948;0.9685173;-0.3756231;433.4302;44.78787;11;11;0;3.050448;3.004847;397778.2;4.61541e+007
3775.948;0.7684281;-0.3208142;81.25139;8.395993;11;11;0;2.420246;2.391422;74568.02;8599197
3787.948;0.5685532;-0.3181931;80.9019;8.359879;11;11;0;1.790719;1.774874;74247.28;8509582
3798.478;0.492964;-0.3174623;81.26578;8.397481;12;12;0;1.552642;1.540712;74581.23;8527863
3810.478;0.6929995;-0.3183907;82.37706;8.512314;12;12;0;2.182676;2.159196;75601.11;8698110
3822.014;0.8853745;-0.3773751;723.6602;74.77837;12;12;0;2.788581;2.750408;664135.2;7.686362e+007
3832.498;1.059964;-0.5141982;1624.59;167.8747;12;12;0;3.338468;3.283951;1490959;1.734791e+008
3843.826;1.248803;-0.6961482;2524.729;260.8892;12;12;0;3.933237;3.857855;2317057;2.711506e+008
3855.232;1.438874;-0.9456208;3419.798;353.3798;12;12;0;4.531887;4.432197;3138501;3.693946e+008
3866.236;1.622303;-1.243296;4320.618;446.4648;12;12;0;5.109614;4.983356;3965224;4.692774e+008
3876.648;1.79582;-1.534046;5221.578;539.5641;12;12;0;5.656127;5.501955;4792076;5.700826e+008
3886.308;1.956909;-1.804833;6122.733;632.6837;12;12;0;6.163494;5.981012;5619105;6.716791e+008
3894.052;2.075784;-2.005543;6771.14;699.6859;12;12;0;6.537904;6.333064;6214177;7.454307e+008
3897.936;2.009999;-1.913342;5868.946;606.459;12;12;0;6.330704;6.13839;5386194;6.448521e+008
3903.442;1.918231;-1.765088;4966.904;513.2477;12;12;0;6.041672;5.866197;4558349;5.442565e+008
3910.088;1.807338;-1.57159;4065.399;420.0921;12;12;0;5.692403;5.536284;3730998;4.440054e+008
3918.404;1.668856;-1.319022;3164.453;326.9941;12;12;0;5.25624;5.122757;2904160;3.441817e+008
3928.948;1.493088;-1.00127;2263.245;233.8691;12;12;0;4.70264;4.595415;2077081;2.448671e+008
3940.948;1.293213;-0.6969763;1456.129;150.4669;12;12;0;4.073113;3.992348;1336354;1.565956e+008
3952.948;1.092964;-0.4699732;793.5015;81.99532;12;12;0;3.442405;3.38448;728231.7;8.481793e+007
3964.948;0.8930352;-0.3422209;240.4765;24.84929;12;12;0;2.812709;2.773879;220696;2.554823e+007
3976.948;0.6931603;-0.3235934;81.29456;8.400455;12;12;0;2.183182;2.159692;74607.64;8583851
3988.948;0.4931246;-0.3222404;81.36295;8.407522;12;12;0;1.553149;1.541211;74670.41;8538103
3999.194;0.5891246;-0.3234084;81.62563;8.434666;13;13;0;1.855511;1.838506;74911.48;8591172
4011.194;0.7890531;-0.3294776;236.3764;24.42561;13;13;0;2.485207;2.454828;216933.2;2.503264e+007
4021.974;0.9686779;-0.4413049;1134.743;117.257;13;13;0;3.050954;3.005338;1041404;1.208345e+008
4032.838;1.149856;-0.5954304;2035.859;210.3725;13;13;0;3.621595;3.557557;1868399;2.179914e+008
4044.65;1.346624;-0.8084536;2930.582;302.8274;13;13;0;4.241335;4.153856;2689526;3.156713e+008
4055.73;1.531285;-1.089684;3831.757;395.949;13;13;0;4.822944;4.710249;3516574;4.150454e+008
4066.388;1.708927;-1.389051;4733.267;489.1053;13;13;0;5.382449;5.242591;4343931;5.154311e+008
4076.396;1.875802;-1.670057;5634.359;582.2183;13;13;0;5.908039;5.740098;5170903;6.16616e+008
4085.818;2.032606;-1.92672;6535.554;675.3419;13;13;0;6.401908;6.205332;5997969;7.185767e+008
4090.766;2.046695;-1.964753;6293.073;650.2856;13;13;0;6.446283;6.247029;5775434;6.922048e+008
4095.53;1.967249;-1.842171;5391.71;557.1444;13;13;0;6.196059;6.011682;4948212;5.916654e+008
4101.638;1.865409;-1.672313;4489.815;463.9485;13;13;0;5.875305;5.709185;4120504;4.912069e+008
4109.062;1.741767;-1.448475;3588.461;370.8084;13;13;0;5.485879;5.340691;3293291;3.911505e+008
4118.49;1.584588;-1.15782;2687.333;277.6916;13;13;0;4.990829;4.870282;2466285;2.915507e+008
4130.058;1.391678;-0.8364584;1811.484;187.187;13;13;0;4.383237;4.289891;1662479;1.953919e+008
4142.058;1.191803;-0.5712304;1103.605;114.0395;13;13;0;3.75371;3.684973;1012828;1.183202e+008
4154.058;0.9917136;-0.3932244;477.1235;49.30286;13;13;0;3.123507;3.075719;437877.5;5.084284e+007
4166.058;0.7917852;-0.3270078;82.00085;8.473438;13;13;0;2.493812;2.463224;75255.84;8684750
4178.058;0.5917496;-0.324032;81.17025;8.387609;13;13;0;1.863778;1.846623;74493.56;8543936
4188.988;0.5096247;-0.3241458;81.5625;8.428142;14;14;0;1.605117;1.592371;74853.54;8563423
4200.989;0.7095531;-0.3259721;82.88848;8.56516;14;14;0;2.234813;2.210207;76070.45;8756575
4212.487;0.9012315;-0.3886206;757.5309;78.27835;14;14;0;2.838525;2.798985;695219.9;8.05003e+007
4223.071;1.077642;-0.5283826;1658.466;171.3751;14;14;0;3.394148;3.337818;1522048;1.771919e+008
4234.593;1.269695;-0.718016;2555.756;264.0954;14;14;0;3.999041;3.921149;2345532;2.746566e+008
4245.95;1.458963;-0.9754279;3452.581;356.7674;14;14;0;4.59516;4.49271;3168588;3.731615e+008
4256.886;1.641267;-1.275761;4353.508;449.8634;14;14;0;5.169344;5.040167;3995408;4.731184e+008
4267.21;1.813392;-1.564419;5254.523;542.9684;14;14;0;5.71147;5.554322;4822310;5.739799e+008
4276.792;1.973034;-1.830692;6155.324;636.0514;14;14;0;6.214282;6.028839;5649015;6.755774e+008
4284.195;2.078034;-2.012027;6662.314;688.4406;14;14;0;6.54499;6.339715;6114303;7.334989e+008
4288.244;2.009999;-1.913448;5760.087;595.2101;14;14;0;6.330704;6.13839;5286289;6.328912e+008
4293.885;1.916035;-1.762575;4858.234;502.0185;14;14;0;6.034754;5.859673;4458618;5.323141e+008
4300.693;1.80257;-1.561366;3956.71;408.8609;14;14;0;5.677386;5.522074;3631250;4.320735e+008
4309.253;1.65991;-1.299818;3055.787;315.7653;14;14;0;5.228062;5.095983;2804432;3.322737e+008
4320.089;1.479267;-0.977683;2154.7;222.6528;14;14;0;4.659108;4.553829;1977465;2.330264e+008
4332.089;1.279231;-0.6792832;1374.497;142.0316;14;14;0;4.029075;3.950024;1261437;1.477542e+008
4344.089;1.079303;-0.4592296;726.0812;75.02854;14;14;0;3.399379;3.342877;666357.1;7.757905e+007
4356.089;0.8791066;-0.3418164;195.2084;20.17158;14;14;0;2.76884;2.7312;179151.5;2.07301e+007
4368.089;0.6792852;-0.3294158;81.67923;8.440204;14;14;0;2.139481;2.116915;74960.67;8620781
4380.089;0.4792497;-0.328798;80.90912;8.360626;14;14;0;1.509448;1.498169;74253.91;8486825
4391.082;0.6294638;-0.3278919;82.37994;8.512611;15;15;0;1.982563;1.963166;75603.75;8681379
4403.076;0.829178;-0.3471597;377.9293;39.05278;15;15;0;2.611584;2.578065;346842.6;4.007267e+007
4413.691;1.006124;-0.4701387;1279.03;132.1667;15;15;0;3.168895;3.119722;1173823;1.36355e+008
4424.848;1.192178;-0.6382436;2179.952;225.2621;15;15;0;3.754891;3.686111;2000639;2.337205e+008
4436.582;1.387713;-0.8714484;3069.858;317.2193;15;15;0;4.37075;4.277928;2817346;3.310842e+008
4447.717;1.573178;-1.161173;3970.869;410.324;15;15;0;4.95489;4.836045;3644244;4.306551e+008
4458.242;1.748785;-1.45782;4871.905;503.4312;15;15;0;5.507983;5.361643;4471165;5.311601e+008
4468.162;1.913999;-1.736204;5773.143;596.5593;15;15;0;6.028343;5.853626;5298271;6.325219e+008
4475.418;2.015677;-1.905557;6262.381;647.114;15;15;0;6.34859;6.15521;5747267;6.881967e+008
4479.671;1.944427;-1.801922;5359.7;553.8367;15;15;0;6.124181;5.943974;4918836;5.877547e+008
4485.45;1.847999;-1.640787;4457.582;460.6178;15;15;0;5.820469;5.657378;4090922;4.874279e+008
4492.662;1.727892;-1.424765;3555.895;367.4432;15;15;0;5.442179;5.299255;3263404;3.874402e+008
4501.885;1.574195;-1.144238;2655.021;274.3527;15;15;0;4.958096;4.839099;2436631;2.879553e+008
4513.434;1.381606;-0.824187;1777.436;183.6688;15;15;0;4.351515;4.259497;1631232;1.916611e+008
4525.434;1.181731;-0.5611349;1071.949;110.7683;15;15;0;3.721988;3.654395;983775.7;1.148911e+008
4537.434;0.9816422;-0.3896619;445.0112;45.98458;15;15;0;3.091786;3.044953;408406.6;4.740633e+007
4549.434;0.7817673;-0.3325541;82.22809;8.49692;15;15;0;2.462259;2.432434;75464.38;8706136
4561.434;0.5816782;-0.3299515;81.86492;8.459392;15;15;0;1.832057;1.815477;75131.09;8614373
4571.658;0.5112318;-0.3300058;81.94869;8.468049;16;16;0;1.610179;1.597353;75207.97;8604399
4583.658;0.7114281;-0.3298865;83.10688;8.587728;16;16;0;2.240718;2.215983;76270.89;8780155
4595.184;0.9033745;-0.3916766;740.9392;76.56387;16;16;0;2.845274;2.805548;679993;7.874233e+007
4605.846;1.081071;-0.5340582;1641.655;169.6381;16;16;0;3.404947;3.348262;1506620;1.754142e+008
4617.467;1.274785;-0.7284512;2536.856;262.1423;16;16;0;4.01507;3.936561;2328186;2.726675e+008
4628.894;1.465231;-0.9886547;3435.644;355.0173;16;16;0;4.614902;4.511582;3153044;3.71401e+008
4639.806;1.64716;-1.288973;4336.758;448.1326;16;16;0;5.187904;5.057813;3980037;4.713813e+008
4650.12;1.81891;-1.575989;5237.32;541.1909;16;16;0;5.728849;5.570761;4806523;5.721948e+008
4659.624;1.977481;-1.838031;6138.484;634.3113;16;16;0;6.228286;6.042023;5633561;6.73818e+008
4666.594;2.075195;-2.006111;6602.553;682.2652;16;16;0;6.536047;6.331322;6059458;7.268583e+008
4670.684;2.006677;-1.908207;5700.106;589.0121;16;16;0;6.320243;6.128552;5231242;6.262391e+008
4676.326;1.912445;-1.754825;4798.294;495.8246;16;16;0;6.02345;5.849011;4403608;5.256904e+008
4683.186;1.798231;-1.551944;3896.513;402.6405;16;16;0;5.66372;5.509141;3576004;4.25445e+008
4691.865;1.653481;-1.289085;2995.28;309.5128;16;16;0;5.207815;5.07674;2748902;3.256317e+008
4702.846;1.470428;-0.9636807;2096.317;216.6199;16;16;0;4.631268;4.527225;1923884;2.266521e+008
4714.846;1.270499;-0.6694102;1328.617;137.2907;16;16;0;4.001572;3.923583;1219331;1.427845e+008
4726.846;1.070624;-0.4535126;685.7391;70.85986;16;16;0;3.372045;3.316438;629333.4;7.324928e+007
4738.846;0.8705352;-0.3442202;168.2977;17.3908;16;16;0;2.741843;2.704928;154454.3;1.786763e+007
4750.846;0.6706068;-0.3352192;82.09356;8.483018;16;16;0;2.112147;2.090151;75340.92;8662192
4762.846;0.4704104;-0.3343042;70.74537;7.31037;16;16;0;1.481608;1.470739;64926.18;7418681
4773.124;0.6326246;-0.334797;82.71486;8.547219;17;17;0;1.992518;1.972928;75911.12;8717524
4785.104;0.8322316;-0.3527807;365.1042;37.72752;17;17;0;2.621202;2.587437;335072.4;3.871643e+007
4795.784;1.010303;-0.4753949;1265.981;130.8183;17;17;0;3.182056;3.132478;1161847;1.34981e+008
4807.023;1.197642;-0.6456218;2166.803;223.9035;17;17;0;3.772101;3.702697;1988572;2.323493e+008
4818.821;1.394249;-0.8817207;3061.147;316.3192;17;17;0;4.391336;4.29765;2809351;3.302098e+008
4829.936;1.579553;-1.174808;3962.066;409.4143;17;17;0;4.974969;4.855174;3636165;4.297825e+008
4840.536;1.75607;-1.474103;4863.216;502.5333;17;17;0;5.530931;5.38339;4463190;5.30328e+008
4850.396;1.92032;-1.748986;5764.284;595.6439;17;17;0;6.048253;5.872402;5290141;6.316699e+008
4859.587;2.073481;-1.997717;6665.387;688.758;17;17;0;6.530648;6.326253;6117123;7.337384e+008
4863.323;2.033891;-1.951543;5978.52;617.7816;17;17;0;6.405957;6.209138;5486754;6.573564e+008
4868.56;1.946624;-1.81268;5075.595;524.4792;17;17;0;6.131098;5.950492;4658100;5.566355e+008
4875.012;1.838999;-1.627736;4174.154;431.3301;17;17;0;5.792122;5.630587;3830808;4.563133e+008
4883.014;1.705553;-1.386636;3272.907;338.2011;17;17;0;5.371819;5.232504;3003693;3.563686e+008
4893.246;1.535035;-1.074357;2371.993;245.1065;17;17;0;4.834755;4.721516;2176884;2.569568e+008
4905.208;1.335856;-0.759004;1542.984;159.442;17;17;0;4.207421;4.121316;1416065;1.661503e+008
4917.208;1.135767;-0.5141623;881.2598;91.06369;17;17;0;3.577219;3.514723;808771.4;9.432124e+007
4929.208;0.9358922;-0.370412;301.5545;31.16069;17;17;0;2.947692;2.905083;276750;3.207922e+007
4941.208;0.7356959;-0.3395794;82.39034;8.513685;17;17;0;2.317153;2.290714;75613.29;8710960
4953.208;0.5357139;-0.3386656;82.13785;8.487595;17;17;0;1.687288;1.673211;75381.56;8630804
4963.215;0.5691425;-0.3390538;82.42011;8.516762;18;18;0;1.792575;1.776698;75640.61;8669431
4975.215;0.7691245;-0.3397202;92.14272;9.521434;18;18;0;2.422439;2.393564;84563.48;9752085
4986.366;0.9548565;-0.4360513;963.8768;99.60081;18;18;0;3.007422;2.963086;884592.8;1.025962e+008
4997.321;1.137481;-0.5890265;1864.742;192.6904;18;18;0;3.582619;3.519936;1711357;1.995937e+008
5009.151;1.334731;-0.8037484;2757.32;284.9236;18;18;0;4.203878;4.117916;2530516;2.969015e+008
5020.461;1.523035;-1.081886;3658.356;378.0309;18;18;0;4.79696;4.685458;3357437;3.961649e+008
5031.211;1.702338;-1.387078;4559.237;471.1221;18;18;0;5.361695;5.222896;4184215;4.963823e+008
5041.315;1.870767;-1.669524;5460.363;564.2386;18;18;0;5.892179;5.725121;5011219;5.974846e+008
5050.719;2.027516;-1.930817;6361.651;657.3719;18;18;0;6.385879;6.190266;5838371;6.993509e+008
5055.74;2.053392;-1.98642;6242.063;645.0145;18;18;0;6.467375;6.266841;5728620;6.8673e+008
5060.432;1.975231;-1.869599;5340.538;551.8568;18;18;0;6.2212;6.035352;4901250;5.861888e+008
5066.511;1.873981;-1.698435;4438.801;458.677;18;18;0;5.902302;5.734681;4073685;4.857495e+008
5073.939;1.750017;-1.475236;3537.701;365.5632;18;18;0;5.511864;5.365322;3246706;3.857126e+008
5083.487;1.590963;-1.17913;2636.39;272.4275;18;18;0;5.010908;4.889404;2419533;2.860786e+008
5095.155;1.396553;-0.8526386;1767.677;182.6603;18;18;0;4.398591;4.304599;1622276;1.906948e+008
5107.155;1.196463;-0.5798445;1069.46;110.511;18;18;0;3.768389;3.69912;981490.7;1.146755e+008
5119.155;0.9965886;-0.4010665;453.399;46.85132;18;18;0;3.138862;3.090607;416104.5;4.832192e+007
5131.155;0.7963923;-0.3383958;82.41298;8.516026;18;18;0;2.508322;2.47738;75634.07;8729634
5143.155;0.5964103;-0.3362622;81.96206;8.469429;18;18;0;1.878458;1.861033;75220.23;8628524
5153.321;0.527089;-0.3375317;82.41953;8.516702;19;19;0;1.660123;1.646493;75640.08;8658089
5165.321;0.7269638;-0.3377701;83.41766;8.619843;19;19;0;2.28965;2.263831;76556.11;8817207
5176.85;0.919178;-0.4043067;760.5712;78.59251;19;19;0;2.895049;2.853934;698010.1;8.08678e+007
5187.618;1.098803;-0.5515294;1661.708;171.7101;19;19;0;3.460797;3.402258;1525023;1.776527e+008
5199.377;1.29466;-0.7541519;2553.275;263.8389;19;19;0;4.077669;3.996725;2343254;2.745974e+008
5210.759;1.48441;-1.02316;3452.905;356.8009;19;19;0;4.675306;4.569305;3168885;3.734824e+008
5221.698;1.666767;-1.332471;4353.983;449.9125;19;19;0;5.249659;5.116505;3995844;4.735313e+008
5231.99;1.838088;-1.623133;5254.988;543.0165;19;19;0;5.789254;5.627876;4822737;5.744532e+008
5241.461;1.99607;-1.883255;6156.106;636.1322;19;19;0;6.286835;6.097125;5649733;6.761248e+008
5247.485;2.059284;-2.000343;6341.659;655.3061;19;19;0;6.485935;6.284273;5820023;6.978088e+008
5251.936;1.984981;-1.890567;5438.809;562.0114;19;19;0;6.251908;6.064258;4991438;5.971478e+008
5257.837;1.886677;-1.727323;4537.524;468.8784;19;19;0;5.942291;5.772433;4164288;4.967405e+008
5265.038;1.766463;-1.509938;3635.914;375.7118;19;19;0;5.563664;5.414403;3336840;3.966152e+008
5274.308;1.612124;-1.223064;2734.731;282.5894;19;19;0;5.077556;4.952852;2509784;2.96938e+008
5285.793;1.420713;-0.8933321;1856.916;191.8817;19;19;0;4.474688;4.377463;1704174;2.004678e+008
5297.793;1.220838;-0.6119609;1140.932;117.8966;19;19;0;3.84516;3.773076;1047084;1.224299e+008
5309.793;1.020696;-0.4182823;515.2895;53.24669;19;19;0;3.21479;3.164197;472904.2;5.495846e+007
5321.793;0.8206067;-0.3393058;83.10136;8.587157;19;19;0;2.584588;2.551752;76265.82;8809100
5333.793;0.6207317;-0.338691;82.22994;8.497111;19;19;0;1.955061;1.936195;75466.09;8663235
5344.598;0.5073746;-0.339151;82.24418;8.498583;20;20;0;1.59803;1.585396;75479.16;8634393
5356.598;0.7073031;-0.3377566;83.55389;8.63392;20;20;0;2.227726;2.203275;76681.13;8826259
5368.306;0.9024637;-0.3918206;662.5157;68.4601;20;20;0;2.842405;2.802758;608020.3;7.040601e+007
5379.051;1.081499;-0.5380469;1563.316;161.543;20;20;0;3.406297;3.349567;1434725;1.670456e+008
5390.742;1.276338;-0.7374009;2458.058;253.9999;20;20;0;4.019964;3.941265;2255870;2.642106e+008
5402.261;1.468338;-1.00198;3357.007;346.8914;20;20;0;4.624688;4.520936;3080876;3.629341e+008
5413.257;1.65166;-1.310928;4258.19;440.0139;20;20;0;5.202078;5.071286;3907931;4.629037e+008
5423.605;1.82416;-1.605571;5159.044;533.1023;20;20;0;5.745384;5.586398;4734685;5.637311e+008
5433.149;1.983213;-1.869907;6060.005;626.2018;20;20;0;6.24634;6.059018;5561537;6.653165e+008
5439.469;2.060624;-2.002189;6375.951;658.8495;20;20;0;6.490153;6.288234;5851494;7.016099e+008
5443.79;1.988409;-1.897436;5474.094;565.6575;20;20;0;6.262707;6.074421;5023820;6.01083e+008
5449.598;1.891552;-1.738182;4572.574;472.5003;20;20;0;5.957645;5.786926;4196456;5.006502e+008
5456.735;1.772785;-1.523823;3670.278;379.2628;20;20;0;5.583573;5.433262;3368378;4.004392e+008
5465.892;1.620106;-1.242249;2769.095;286.1404;20;20;0;5.102696;4.976775;2541322;3.007413e+008
5477.31;1.429606;-0.9113919;1885.704;194.8564;20;20;0;4.502697;4.404269;1730594;2.036302e+008
5489.31;1.229731;-0.6251816;1163.222;120.1999;20;20;0;3.873169;3.800044;1067541;1.248554e+008
5501.31;1.029803;-0.4271542;536.9176;55.4816;20;20;0;3.243474;3.191983;492753.3;5.728113e+007
5513.31;0.8297674;-0.3444635;85.10658;8.794365;20;20;0;2.613441;2.579874;78106.11;9024200
5525.31;0.6298389;-0.3423965;82.34837;8.509349;20;20;0;1.983745;1.964325;75574.77;8678152
5537.31;0.429589;-0.3409376;70.97907;7.334519;20;20;0;1.353036;1.343964;65140.66;7433758
5544.439;0.3108212;-0.3402403;70.9051;7.326875;20;20;0;0.9789645;0.9742037;65072.77;7398602