File: Ensayos/Resistencia/comp/EsponjaB/REB2_com.raw
"Test Type";"Manual"
"Method Name:";"C:\INSTRON\user\template\CYCLE.MTM"
"Name:";""
"Operator ID:";""
"Company:";""
"Lab name:";""
"Test date:";"09/05/2017"
"Temperature:";""
"Humidity:";""
"Note 1:";""
"Note 2:";""
"Note 3:";""
"Geometry:";"Rectangular"
"Specimen";1
"Specimen name:";""
"Width:";0.250000;"in"
"Thickness:";0.060000;"in"
"Length:";1.250000;"in"
"Diameter:";0.039370;"in"
"Inner diameter:";0.019685;"in"
"Outer diameter:";0.039370;"in"
"Wall thickness:";0.019685;"in"
"Area:";0.015000;"in*in"
"Linear density:";1.000000;"den"
"Sled weight:";2.204623;"lbf"
"Loading span:";0.000000;"mm"
"Support span:";1.000000;"mm"
"Span ratio:";"2"
"Fixture type:";"3-point"
"Comment:";""
"Included"
"Final Width:";0.250000;"in"
"Final Thickness:";0.060000;"in"
"Final Length:";1.250000;"in"
"Final Diameter:";0.039370;"in"
"Final Inner diameter:";0.019685;"in"
"Final Outer diameter:";0.039370;"in"
"Final Wall thickness:";0.019685;"in"
"Final Area:";0.015000;"in*in"
"Final Linear density:";1.000000;"den"
"Time sec";"Extension mm";"Strain 1 %";"Load N";"Stress MPa";"Cycle Count ";"Total Cycle Count ";"Repetitions Count ";"Strain [Exten.] %";"True strain %";"Tenacity gf/tex";"True stress Pa"
0;0.3109819;-0.3308233;105.786;10.93124;0;0;0;0.9794706;0.9747049;97084.54;1.103831e+007
44.038;1.044964;-0.7251545;2543.754;262.8551;0;0;0;3.291224;3.238223;2334516;2.715062e+008
88.57401;1.787035;-1.753932;5782.164;597.4915;0;0;0;5.628455;5.475761;5306550;6.311211e+008
115.528;1.903767;-1.967188;5114.73;528.5232;0;0;0;5.996116;5.823226;4694016;5.60214e+008
151.248;1.308374;-0.8745389;1738.523;179.6477;0;0;0;4.120863;4.038219;1595520;1.870508e+008
197.248;0.5416068;-0.3436734;103.3279;10.67724;0;0;0;1.705848;1.691462;94828.62;1.085937e+007
241.81;0.8209816;-0.4017597;754.5204;77.96726;1;1;0;2.585769;2.552903;692457;7.998331e+007
285.784;1.553785;-1.283478;4159.707;429.8372;1;1;0;4.89381;4.777832;3817548;4.508726e+008
319.128;2.03057;-2.119823;6261.883;647.0626;1;1;0;6.395496;6.199306;5746810;6.884454e+008
345.844;1.585231;-1.320702;2805.234;289.8748;1;1;0;4.992854;4.87221;2574489;3.043478e+008
391.49;0.8245173;-0.3611405;211.8713;21.89341;1;1;0;2.596905;2.563758;194443.8;2.246196e+007
436.362;0.5431604;-0.347809;103.364;10.68097;2;2;0;1.710741;1.696273;94861.77;1.086369e+007
480.618;1.280838;-0.8303501;2751.508;284.3231;2;2;0;4.034137;3.95489;2525182;2.957931e+008
521.914;1.969124;-1.975763;6194.55;640.1047;2;2;0;6.201964;6.017242;5685015;6.798038e+008
544.5061;1.794481;-1.694967;3985.89;411.8761;2;2;0;5.651909;5.497963;3658029;4.35155e+008
586.1261;1.100785;-0.5467398;903.2801;93.33913;2;2;0;3.467039;3.408292;828980.4;9.657523e+007
632.1261;0.3341248;-0.3506921;91.4616;9.451051;2;2;0;1.052361;1.046863;83938.38;9550510
675.452;1.008053;-0.5212246;1417.19;146.4433;3;3;0;3.17497;3.12561;1300619;1.510928e+008
719.064;1.73491;-1.562245;4844.824;500.6328;3;3;0;5.464282;5.320215;4446311;5.279888e+008
746.5681;1.946892;-1.952229;5190.956;536.3999;3;3;0;6.131942;5.951287;4763972;5.692916e+008
780.7061;1.377856;-0.9152862;1779.344;183.8659;3;3;0;4.339705;4.248178;1632983;1.918452e+008
826.7061;0.6112496;-0.3563044;102.8201;10.62477;3;3;0;1.925195;1.906898;94362.61;1.082931e+007
870.78;0.7434102;-0.3553419;122.8748;12.69709;4;4;0;2.341449;2.314458;112767.7;1.299439e+007
914.926;1.479106;-1.099996;3513.497;363.0621;4;4;0;4.658602;4.553346;3224493;3.799757e+008
951.2221;2.056231;-2.107998;6425.086;663.9269;4;4;0;6.476318;6.275241;5896588;7.069249e+008
975.968;1.643517;-1.386132;2966.594;306.5487;4;4;0;5.176431;5.046905;2722576;3.224169e+008
1021.15;0.8906244;-0.3803849;270.5692;27.95887;4;4;0;2.805116;2.766494;248313.4;2.874315e+007
1065.988;0.4767854;-0.3575595;103.391;10.68376;5;5;0;1.501686;1.490523;94886.54;1.08442e+007
1110.58;1.219821;-0.7307633;2292.509;236.8931;5;5;0;3.841955;3.769989;2103938;2.459944e+008
1152.46;1.91791;-1.864274;5728.503;591.9465;5;5;0;6.04066;5.865242;5257303;6.27704e+008
1175.932;1.830963;-1.728957;4136.757;427.4658;5;5;0;5.766813;5.606661;3796487;4.521169e+008
1216.476;1.155267;-0.5886373;992.6564;102.5747;5;5;0;3.638637;3.574002;911005;1.06307e+008
1262.476;0.3885533;-0.3599709;91.49472;9.454473;5;5;0;1.22379;1.216362;83968.79;9570177
1306.538;0.9657315;-0.4712702;1062.686;109.8111;6;6;0;3.041674;2.996332;975274.4;1.131512e+008
1350.234;1.693981;-1.46782;4496.981;464.689;6;6;0;5.335373;5.197911;4127080;4.894819e+008
1378.852;1.969177;-1.961289;5309.326;548.6315;6;6;0;6.202133;6.017401;4872606;5.826583e+008
1411.8;1.41991;-0.9622008;1879.683;194.2343;6;6;0;4.472157;4.375041;1725069;2.029207e+008
1457.8;0.6533031;-0.3631568;103.0663;10.6502;6;6;0;2.057648;2.036764;94588.52;1.086935e+007
1502.404;0.7099817;-0.3626531;104.4616;10.79439;7;7;0;2.236163;2.211527;95869.08;1.103577e+007
1546.846;1.450553;-1.035243;3268.639;337.76;7;7;0;4.56867;4.46738;2999776;3.531911e+008
1584.35;2.065445;-2.099664;6486.834;670.3075;7;7;0;6.505339;6.302493;5953257;7.139132e+008
1608.186;1.667035;-1.410532;3029.659;313.0653;7;7;0;5.250503;5.117306;2780453;3.295029e+008
1653.12;0.9181601;-0.3908056;294.5706;30.43902;7;7;0;2.891843;2.850818;270340.5;3.131927e+007
1697.612;0.4433568;-0.3631612;91.69092;9.474747;8;8;0;1.396399;1.38674;84148.84;9607052
1742.404;1.189874;-0.6836316;2063.243;213.2022;8;8;0;3.747635;3.679118;1893530;2.211922e+008
1784.616;1.893374;-1.809139;5499.69;568.3024;8;8;0;5.963382;5.79234;5047311;6.021925e+008
1808.494;1.848695;-1.745739;4207.512;434.7771;8;8;0;5.822662;5.659451;3861421;4.600927e+008
1848.45;1.18291;-0.611966;1035.869;107.04;8;8;0;3.725701;3.657974;950663.3;1.11028e+008
1894.45;0.4161962;-0.3660314;91.4944;9.45444;8;8;0;1.310854;1.302337;83968.48;9578374
1938.48;0.9376602;-0.4411906;842.4074;87.04894;9;9;0;2.95326;2.910492;773114.9;8.961972e+007
1982.226;1.66682;-1.408497;4278.398;442.1021;9;9;0;5.249828;5.116665;3926477;4.653116e+008
2011.606;1.983641;-1.975964;5389.122;556.8771;9;9;0;6.24769;6.060288;4945838;5.91669e+008
2043.736;1.448196;-0.9984887;1949.431;201.4416;9;9;0;4.561246;4.46028;1789080;2.106298e+008
2089.736;0.6815352;-0.3678991;103.3693;10.68151;9;9;0;2.146568;2.123853;94866.59;1.09108e+007
2134.028;0.6766603;-0.3663034;104.35;10.78285;10;10;0;2.131213;2.108821;95766.64;1.101266e+007
2178.772;1.422481;-0.9812652;3057.812;315.9745;10;10;0;4.480256;4.382793;2806290;3.30131e+008
2217.63;2.070052;-2.095919;6499.676;671.6345;10;10;0;6.519849;6.316116;5965043;7.154241e+008
2240.36;1.691302;-1.448003;3118.176;322.2122;10;10;0;5.326937;5.189901;2861689;3.393762e+008
2284.996;0.9473565;-0.4051344;338.3258;34.9604;10;10;0;2.9838;2.940151;310496.7;3.600355e+007
2329.236;0.4098747;-0.3677426;92.00717;9.507426;11;11;0;1.290944;1.282682;84439.08;9630162
2374.194;1.159285;-0.6426507;1860.493;192.2514;11;11;0;3.651291;3.586211;1707458;1.99271e+008
2416.702;1.867767;-1.759522;5296.747;547.3317;11;11;0;5.88273;5.716197;4861061;5.795297e+008
2441.014;1.867177;-1.773577;4306.566;445.0128;11;11;0;5.880874;5.714444;3952328;4.711834e+008
2480.256;1.213124;-0.6449731;1098.433;113.505;11;11;0;3.820864;3.749676;1008081;1.178419e+008
2526.256;0.4465176;-0.3699287;91.31638;9.436045;11;11;0;1.406355;1.396557;83805.11;9568749
2570.314;0.9078744;-0.4181837;645.1095;66.66145;12;12;0;2.859447;2.819328;592045.8;6.85676e+007
2614.192;1.639177;-1.352406;4080.912;421.6951;12;12;0;5.162764;5.03391;3745235;4.434662e+008
2644.39;1.997677;-1.992829;5492.668;567.5768;12;12;0;6.291897;6.101887;5040866;6.032882e+008
2675.532;1.478678;-1.045714;2043.103;211.1211;12;12;0;4.657252;4.552056;1875047;2.209535e+008
2721.532;0.7120174;-0.3730085;103.7461;10.72045;12;12;0;2.242575;2.217799;95212.4;1.096086e+007
2765.65;0.6433389;-0.3714506;104.4516;10.79335;13;13;0;2.026264;2.006009;95859.89;1.101206e+007
2810.59;1.392374;-0.9345525;2866.115;296.1658;13;13;0;4.38543;4.291992;2630362;3.09154e+008
2849.93;2.048142;-2.054709;6320.129;653.0814;13;13;0;6.45084;6.251309;5800265;6.952106e+008
2872.526;1.715356;-1.488516;3224.011;333.1485;13;13;0;5.402696;5.261803;2958819;3.511475e+008
2916.806;0.9775173;-0.4241408;395.8875;40.90845;13;13;0;3.078794;3.032351;363323.6;4.216794e+007
2960.856;0.3766605;-0.3721275;92.08693;9.515668;14;14;0;1.186332;1.17935;84512.28;9628556
3005.972;1.128642;-0.608328;1674.506;173.0326;14;14;0;3.554778;3.493055;1536769;1.791835e+008
3048.81;1.842535;-1.711193;5107.797;527.8068;14;14;0;5.803258;5.641113;4687654;5.584368e+008
3073.584;1.884695;-1.799416;4411.983;455.9058;14;14;0;5.936048;5.76654;4049073;4.829686e+008
3112.106;1.242642;-0.6798986;1167.167;120.6075;14;14;0;3.913833;3.839184;1071162;1.253279e+008
3158.106;0.4760354;-0.3746644;91.75024;9.480877;14;14;0;1.499324;1.488195;84203.29;9623026
3203.032;0.8927673;-0.4075797;538.2071;55.61485;15;15;0;2.811865;2.773058;493936.7;5.717866e+007
3247.034;1.626267;-1.325318;3970.838;410.3208;15;15;0;5.1221;4.995235;3644216;4.313378e+008
3277.606;2.00432;-2.00152;5524.853;570.9026;15;15;0;6.312819;6.121569;5070405;6.069427e+008
3308.374;1.491481;-1.06579;2073.445;214.2564;15;15;0;4.697578;4.59058;1902893;2.243213e+008
3354.374;0.7248746;-0.3766885;103.8906;10.73539;15;15;0;2.283069;2.257397;95345.08;1.098048e+007
3399.272;0.6433389;-0.3747924;104.5512;10.80364;16;16;0;2.026264;2.006009;95951.26;1.102255e+007
3444.354;1.394785;-0.9350191;2836.064;293.0605;16;16;0;4.393023;4.299266;2602783;3.059348e+008
3483.672;2.050017;-2.057494;6289.623;649.929;16;16;0;6.456745;6.256857;5772268;6.918933e+008
3506.264;1.713588;-1.48542;3182.34;328.8425;16;16;0;5.397128;5.25652;2920576;3.465906e+008
3550.644;0.9738209;-0.4216347;373.7342;38.61927;16;16;0;3.067152;3.021055;342992.5;3.980379e+007
3595.48;0.3933212;-0.3745378;92.31522;9.539259;17;17;0;1.238807;1.231196;84721.8;9657432
3640.68;1.146749;-0.6247909;1722.582;178.0005;17;17;0;3.611809;3.548112;1580891;1.844296e+008
3683.424;1.858927;-1.740802;5156.368;532.8258;17;17;0;5.854889;5.6899;4732230;5.640222e+008
3707.8;1.874838;-1.781194;4297.822;444.1092;17;17;0;5.905002;5.73723;3944303;4.703338e+008
3746.928;1.22266;-0.6504866;1088.422;112.4705;17;17;0;3.850897;3.778601;998893.4;1.168016e+008
3792.928;0.4560533;-0.376504;91.94353;9.50085;17;17;0;1.436388;1.42617;84380.67;9637319
3837.632;0.9089994;-0.4177036;588.8351;60.84642;18;18;0;2.86299;2.822773;540400.3;6.258844e+007
3881.696;1.64341;-1.355461;4021.156;415.5203;18;18;0;5.176093;5.046584;3690394;4.37028e+008
3911.672;1.997141;-1.98693;5415.956;559.6499;18;18;0;6.290209;6.100299;4970464;5.94853e+008
3943.184;1.471874;-1.025328;1970.864;203.6563;18;18;0;4.635824;4.531579;1808750;2.130975e+008
3989.184;0.7050532;-0.3796621;104.0389;10.7507;18;18;0;2.22064;2.196343;95481.1;1.098944e+007
4033.896;0.6600531;-0.378622;104.6128;10.81001;19;19;0;2.078907;2.057593;96007.83;1.103474e+007
4079.05;1.412624;-0.9591823;2887.905;298.4175;19;19;0;4.44921;4.353074;2650360;3.116947e+008
4118.109;2.063409;-2.075161;6342.995;655.4442;19;19;0;6.498928;6.296473;5821250;6.98041e+008
4140.73;1.699553;-1.453359;3078.525;318.1149;19;19;0;5.352921;5.214568;2825300;3.351433e+008
4185.418;0.9547494;-0.4124858;317.1625;32.77353;19;19;0;3.007085;2.962758;291074.2;3.375905e+007
4230.104;0.4098747;-0.3781234;92.52631;9.56107;20;20;0;1.290944;1.282682;84915.52;9684499
4275.386;1.164642;-0.6425555;1776.568;183.5791;20;20;0;3.668164;3.602488;1630436;1.903131e+008
4317.916;1.873552;-1.762114;5209.069;538.2715;20;20;0;5.900952;5.733406;4780595;5.700347e+008
4341.994;1.865302;-1.760297;4197.52;433.7446;20;20;0;5.874968;5.708866;3852251;4.592269e+008
4381.655;1.204231;-0.6242567;1018.236;105.218;20;20;0;3.792855;3.722695;934480.9;1.092087e+008
4427.655;0.4376783;-0.3795627;92.3897;9.546954;20;20;0;1.378514;1.369099;84790.14;9678560
4472.219;0.9251244;-0.4297197;643.5373;66.49899;21;21;0;2.913778;2.872134;590602.9;6.843662e+007
4516.295;1.659749;-1.382187;4075.934;421.1806;21;21;0;5.227556;5.095502;3740666;4.431981e+008
4545.72;1.98991;-1.971264;5314.616;549.178;21;21;0;6.267432;6.078867;4877460;5.835974e+008
4577.936;1.452963;-0.9897105;1878.376;194.0992;21;21;0;4.576262;4.47464;1723869;2.029817e+008
4623.936;0.6863567;-0.3818209;103.8452;10.73069;21;21;0;2.161753;2.138719;95303.36;1.096266e+007
4668.52;0.6766603;-0.3810517;105.0161;10.85168;22;22;0;2.131213;2.108821;96377.91;1.108295e+007
4713.739;1.430196;-0.9836403;2942.489;304.0578;22;22;0;4.504553;4.406045;2700453;3.177542e+008
4752.124;2.070052;-2.083308;6360.664;657.27;22;22;0;6.519849;6.316116;5837465;7.00123e+008
4775.217;1.685142;-1.421656;2979.632;307.896;22;22;0;5.307533;5.171477;2734542;3.242377e+008
4820.151;0.936428;-0.404535;266.2255;27.51002;22;22;0;2.949379;2.906722;244327;2.83214e+007
4864.733;0.4266962;-0.3802813;92.73507;9.582644;23;23;0;1.343925;1.334974;85107.11;9711427
4910.096;1.182749;-0.6614143;1832.556;189.3645;23;23;0;3.725195;3.657486;1681818;1.964187e+008
4952.408;1.88791;-1.78564;5263.131;543.8579;23;23;0;5.946172;5.776097;4830210;5.761967e+008
4976.219;1.855338;-1.739468;4097.593;423.4188;23;23;0;5.843585;5.67922;3760544;4.481616e+008
5016.392;1.185696;-0.6020301;950.4265;98.21093;23;23;0;3.734474;3.666432;872248.8;1.018786e+008
5062.392;0.4189819;-0.3821885;92.73261;9.582389;23;23;0;1.319628;1.310997;85104.84;9708840
5106.835;0.9415173;-0.4414425;701.0672;72.44376;24;24;0;2.965409;2.922291;643400.7;7.459201e+007
5150.897;1.67582;-1.409786;4131.058;426.8768;24;24;0;5.278174;5.143594;3791256;4.494081e+008
5179.782;1.982731;-1.959503;5218.552;539.2515;24;24;0;6.244822;6.057588;4789298;5.729268e+008
5212.624;1.435445;-0.9599198;1795.933;185.5801;24;24;0;4.521088;4.421866;1648208;1.939703e+008
5258.624;0.6686781;-0.384367;104.0976;10.75678;24;24;0;2.106073;2.084202;95535.05;1.098332e+007
5303.147;0.6933745;-0.383292;105.5873;10.91071;25;25;0;2.183857;2.160352;96902.16;1.114898e+007
5348.383;1.447338;-1.008207;2998.507;309.8463;25;25;0;4.558546;4.457698;2751863;3.239708e+008
5385.748;2.070052;-2.081522;6339.058;655.0373;25;25;0;6.519849;6.316116;5817636;6.977447e+008
5409.733;1.67041;-1.391139;2881.792;297.7858;25;25;0;5.261133;5.127406;2644749;3.134527e+008
5454.866;0.9181065;-0.3973825;220.0452;22.73804;25;25;0;2.891674;2.850654;201945.3;2.339556e+007
5499.352;0.4433568;-0.3839035;93.0344;9.613574;26;26;0;1.396399;1.38674;85381.82;9747818
5544.764;1.200214;-0.6808908;1887.896;195.083;26;26;0;3.7802;3.710502;1732607;2.024575e+008
5586.868;1.901999;-1.80749;5320.793;549.8164;26;26;0;5.990547;5.817973;4883129;5.827534e+008
5610.443;1.84532;-1.719207;4001.218;413.46;26;26;0;5.812032;5.649405;3672096;4.374904e+008
5651.113;1.167374;-0.5791215;883.9125;91.33781;26;26;0;3.676769;3.610788;811205.9;9.469609e+007
5697.113;0.4008212;-0.3844826;93.01373;9.611438;26;26;0;1.262429;1.254527;85362.84;9732775
5741.406;0.9574815;-0.4529636;760.1126;78.54512;27;27;0;3.01569;2.971112;697589.2;8.09138e+007
5785.432;1.691356;-1.435647;4187.913;432.7518;27;27;0;5.327106;5.190061;3843434;4.55805e+008
5813.859;1.975177;-1.944955;5123.05;529.3829;27;27;0;6.221031;6.035193;4701651;5.623159e+008
5847.333;1.417285;-0.9257874;1711.838;176.8902;27;27;0;4.463889;4.367127;1571030;1.847864e+008
5893.333;0.6506246;-0.3856622;104.2594;10.77349;27;27;0;2.049211;2.028497;95683.48;1.099426e+007
5937.766;0.7099817;-0.3846572;105.7207;10.9245;28;28;0;2.236163;2.211527;97024.63;1.116879e+007
5983.014;1.464106;-1.031881;3055.309;315.7159;28;28;0;4.611358;4.508195;2803994;3.302747e+008
6019.719;2.065284;-2.076863;6237.608;644.5541;28;28;0;6.504833;6.302018;5724531;6.864812e+008
6044.282;1.654713;-1.357677;2780.146;287.2823;28;28;0;5.211695;5.080428;2551464;3.022546e+008
6089.642;0.8987138;-0.3931115;175.9703;18.18363;28;28;0;2.830595;2.791274;161495.8;1.869833e+007
6133.97;0.459964;-0.3854871;93.28972;9.639956;29;29;0;1.448705;1.438312;85616.13;9779611
6179.423;1.217571;-0.6980039;1942.034;200.6772;29;29;0;3.834868;3.763164;1782291;2.08373e+008
6221.326;1.916035;-1.83024;5377.965;555.7241;29;29;0;6.034754;5.859673;4935598;5.892607e+008
6244.715;1.834392;-1.698732;3893.102;402.288;29;29;0;5.777612;5.61687;3572873;4.255306e+008
6285.95;1.146964;-0.5548352;811.8034;83.88651;29;29;0;3.612484;3.548764;745028.1;8.69169e+007
6331.95;0.3804105;-0.384613;93.19266;9.629928;29;29;0;1.198143;1.191022;85527.06;9745308
6375.996;0.9737137;-0.4640551;820.848;84.82113;30;30;0;3.066815;3.020728;753328.8;8.742244e+007
6420.083;1.708499;-1.466697;4246.309;438.7862;30;30;0;5.381099;5.241311;3897027;4.623977e+008
6447.969;1.966981;-1.931723;5012.873;517.9979;30;30;0;6.195215;6.010887;4600537;5.500889e+008
6482.207;1.396392;-0.8897283;1617.762;167.1691;30;30;0;4.398085;4.304115;1484692;1.745213e+008
6528.207;0.6297853;-0.3861881;104.5614;10.8047;30;30;0;1.983576;1.964159;95960.66;1.101902e+007
6572.388;0.7265353;-0.3863618;106.1443;10.96827;31;31;0;2.2883;2.262511;97413.37;1.121925e+007
6617.687;1.481463;-1.05624;3113.597;321.739;31;31;0;4.666026;4.560439;2857487;3.367514e+008
6653.583;2.060677;-2.067676;6135.346;633.987;31;31;0;6.490322;6.288392;5630681;6.751348e+008
6678.885;1.638535;-1.31947;2678.205;276.7484;31;31;0;5.160739;5.031984;2457909;2.910307e+008
6724.423;0.8794816;-0.3879497;137.2781;14.18543;31;31;0;2.770021;2.73235;125986.2;1.457837e+007
6768.596;0.4767854;-0.3818123;93.34748;9.645926;32;32;0;1.501686;1.490523;85669.15;9790777
6814.12;1.235356;-0.7128461;1999.691;206.6352;32;32;0;3.890886;3.817099;1835206;2.146751e+008
6855.875;1.931249;-1.850806;5435.324;561.6512;32;32;0;6.082673;5.904854;4988239;5.958147e+008
6878.981;1.823838;-1.671053;3800.252;392.6935;32;32;0;5.744372;5.585441;3487661;4.152512e+008
6920.64;1.129553;-0.5327437;751.0862;77.6124;32;32;0;3.557647;3.495824;689305.4;8.037358e+007
6966.64;0.3627855;-0.3821954;93.32193;9.643286;32;32;0;1.142631;1.136153;85645.7;9753473
7010.596;0.9898922;-0.4717124;883.4407;91.28906;33;33;0;3.117771;3.070155;810772.9;9.413524e+007
7054.651;1.724035;-1.486778;4305.359;444.888;33;33;0;5.43003;5.287733;3951220;4.690455e+008
7082.045;1.959427;-1.910986;4921.221;508.5271;33;33;0;6.171424;5.988481;4516424;5.399105e+008
7116.875;1.378874;-0.8522145;1542.918;159.4352;33;33;0;4.342911;4.251251;1416005;1.663593e+008
7162.875;0.6122675;-0.3836768;105.0511;10.85531;33;33;0;1.928401;1.910043;96410.13;1.106464e+007
7207.012;0.7434102;-0.3838392;106.36;10.99056;34;34;0;2.341449;2.314458;97611.35;1.12479e+007
7252.293;1.49807;-1.07641;3174.467;328.029;34;34;0;4.718332;4.610401;2913350;3.435065e+008
7287.481;2.055802;-2.056309;6043.316;624.4773;34;34;0;6.474967;6.273972;5546221;6.64912e+008
7313.435;1.623053;-1.283379;2586.095;267.2304;34;34;0;5.111977;4.985604;2373375;2.808911e+008
7359.115;0.8616959;-0.3861105;107.8595;11.1455;34;34;0;2.714003;2.677827;98987.46;1.144799e+007
7403.222;0.4933925;-0.3828539;93.79896;9.692578;35;35;0;1.553992;1.542041;86083.48;9843200
7448.784;1.252821;-0.7308783;2059.429;212.8081;35;35;0;3.945891;3.87003;1890030;2.212053e+008
7490.335;1.945284;-1.870987;5499.548;568.2877;35;35;0;6.12688;5.946518;5047180;6.03106e+008
7513.261;1.812856;-1.645636;3706.643;383.0205;35;35;0;5.709783;5.552726;3401751;4.048901e+008
7555.335;1.111606;-0.5140963;690.1298;71.31355;35;35;0;3.501122;3.441227;633362.9;7.381033e+007
7601.335;0.3448927;-0.3838398;93.62599;9.674706;35;35;0;1.086276;1.080418;85924.75;9779799
7645.175;1.005696;-0.4837275;946.0446;97.75814;36;36;0;3.167546;3.118414;868227.3;1.008547e+008
7689.2;1.739517;-1.511994;4366.43;451.1987;36;36;0;5.478793;5.333973;4007268;4.759189e+008
7716.156;1.951338;-1.895699;4827.765;498.8701;36;36;0;6.145947;5.964482;4430656;5.295304e+008
7751.573;1.361035;-0.8220273;1468.169;151.7111;36;36;0;4.286724;4.197388;1347405;1.582146e+008
7797.573;0.5944818;-0.3843398;104.9825;10.84822;36;36;0;1.872384;1.85507;96347.14;1.105134e+007
7841.64;0.7600174;-0.3840027;106.7141;11.02715;37;37;0;2.393755;2.365554;97936.32;1.129111e+007
7886.899;1.514356;-1.101052;3235.867;334.3736;37;37;0;4.769626;4.659371;2969700;3.50322e+008
7921.395;2.050927;-2.047815;5950.174;614.8525;37;37;0;6.459613;6.259551;5460740;6.545696e+008
7948.021;1.607035;-1.249826;2492.911;257.6013;37;37;0;5.061526;4.937596;2287855;2.706398e+008
7993.823;0.8438566;-0.3859224;105.7333;10.92579;37;37;0;2.657816;2.62311;97036.13;1.121618e+007
8037.846;0.5100533;-0.3834613;94.2246;9.736562;38;38;0;1.606467;1.5937;86474.12;9892976
8083.423;1.269695;-0.7504192;2115.141;218.565;38;38;0;3.999041;3.921149;1941159;2.273055e+008
8124.777;1.958892;-1.891485;5558.978;574.4288;38;38;0;6.169737;5.986892;5101722;6.098696e+008
8147.545;1.801874;-1.624002;3615.081;373.5591;38;38;0;5.675193;5.519999;3317721;3.947593e+008
8190.039;1.093499;-0.4982653;630.8131;65.18415;38;38;0;3.444092;3.386111;578925.3;6.742915e+007
8236.038;0.3268927;-0.3833767;93.76252;9.688813;38;38;0;1.029583;1.024319;86050.05;9788567
8279.79;1.022089;-0.4972918;1011.048;104.4751;39;39;0;3.219177;3.168447;927883.5;1.078384e+008
8323.761;1.755106;-1.538942;4427.467;457.5059;39;39;0;5.527893;5.380512;4063284;4.827963e+008
8350.277;1.943088;-1.880655;4734.227;489.2044;39;39;0;6.119963;5.939999;4344811;5.191435e+008
8386.301;1.342874;-0.7923295;1395.785;144.2314;39;39;0;4.229525;4.142525;1280974;1.503317e+008
8432.301;0.5760532;-0.385497;105.1599;10.86654;39;39;0;1.814341;1.798078;96509.92;1.10637e+007
8477.269;0.7933923;-0.3849451;107.0808;11.06504;40;40;0;2.498873;2.468162;98272.8;1.134154e+007
8522.454;1.546338;-1.156811;3371.355;348.3741;40;40;0;4.870357;4.755471;3094043;3.653411e+008
8555.654;2.040481;-2.032895;5781.874;597.4615;40;40;0;6.426711;6.22864;5306284;6.358586e+008
8583.559;1.575267;-1.186423;2326.272;240.3819;40;40;0;4.961471;4.842315;2134923;2.523084e+008
8629.522;0.809303;-0.3868699;105.9441;10.94758;40;40;0;2.548986;2.517041;97229.64;1.122663e+007
8674.48;0.5599818;-0.3851368;106.1685;10.97077;41;41;0;1.763722;1.748349;97435.58;1.116426e+007
8720.082;1.320053;-0.8129308;2318.103;239.5378;41;41;0;4.157646;4.073539;2127426;2.494969e+008
8760.717;1.997356;-1.953495;5770.327;596.2683;41;41;0;6.290884;6.100934;5295687;6.337789e+008
8783.252;1.76716;-1.557264;3369.511;348.1835;41;41;0;5.565857;5.416481;3092350;3.675629e+008
8826.772;1.041803;-0.4586842;483.3433;49.94557;41;41;0;3.281269;3.228585;443585.7;5.158442e+007
8871.688;0.3265712;-0.3848015;94.12742;9.72652;42;42;0;1.028571;1.023317;86384.94;9826564
8917.326;1.087231;-0.554416;1298.858;134.2155;42;42;0;3.424351;3.367025;1192020;1.388116e+008
8960.851;1.812695;-1.639128;4714.028;487.1172;42;42;0;5.709276;5.552246;4326274;5.149281e+008
8985.965;1.908802;-1.818718;4414.997;456.2172;42;42;0;6.011976;5.838188;4051839;4.836449e+008
9024.013;1.274838;-0.6946378;1160.513;119.9199;42;42;0;4.015239;3.936723;1065054;1.24735e+008
9070.013;0.5081246;-0.3852034;94.0864;9.722281;42;42;0;1.600393;1.587721;86347.28;9877875
9114.9;0.8599816;-0.3931767;258.7172;26.73416;43;43;0;2.708603;2.67257;237436.3;2.745828e+007
9159.788;1.60816;-1.268665;3660.287;378.2304;43;43;0;5.06507;4.940968;3359209;3.97388e+008
9190.696;2.016963;-1.997513;5462.721;564.4823;43;43;0;6.352639;6.159017;5013383;6.003418e+008
9221.24;1.507874;-1.059009;2013.166;208.0276;43;43;0;4.74921;4.639883;1847572;2.179072e+008
9267.24;0.7412674;-0.3874945;106.1727;10.9712;43;43;0;2.3347;2.307863;97439.38;1.122734e+007
9312.11;0.6267317;-0.3864078;106.3244;10.98688;44;44;0;1.973958;1.954728;97578.66;1.120375e+007
9357.757;1.387499;-0.9050538;2604.311;269.1127;44;44;0;4.370076;4.277282;2390093;2.808731e+008
9397.311;2.046695;-2.030845;6058.532;626.0495;44;44;0;6.446283;6.247029;5560185;6.664065e+008
9419.856;1.717713;-1.462536;3053.136;315.4914;44;44;0;5.41012;5.268846;2802000;3.325599e+008
9464.49;0.9737672;-0.4189053;309.2124;31.95201;44;44;0;3.066983;3.020892;283778;3.293198e+007
9509.318;0.3933212;-0.3863777;94.52408;9.767508;45;45;0;1.238807;1.231196;86748.96;9888508
9554.977;1.154249;-0.6188147;1585.217;163.8061;45;45;0;3.635431;3.570908;1454825;1.697612e+008
9597.805;1.868088;-1.736435;5002.486;516.9246;45;45;0;5.883742;5.717153;4591005;5.473391e+008
9621.797;1.872052;-1.750764;4099.097;423.5742;45;45;0;5.896228;5.728945;3761924;4.485491e+008
9661.738;1.206428;-0.6091562;946.0545;97.75916;45;45;0;3.799773;3.72936;868236.4;1.014738e+008
9707.738;0.4396068;-0.3882502;94.12064;9.72582;45;45;0;1.384588;1.375091;86378.71;9860482
9752.513;0.9265172;-0.4259885;536.8373;55.4733;46;46;0;2.918164;2.876397;492679.5;5.70921e+007
9796.965;1.667356;-1.377595;3946.445;407.8001;46;46;0;5.251515;5.118268;3621828;4.292158e+008
9826.423;1.98182;-1.941699;5066.52;523.5414;46;46;0;6.241952;6.054888;4649771;5.562206e+008
9860.009;1.422106;-0.9135621;1661.831;171.7229;46;46;0;4.479075;4.381663;1525136;1.794145e+008
9906.009;0.6553924;-0.3901223;105.6822;10.92052;46;46;0;2.064228;2.043212;96989.29;1.114594e+007
9950.734;0.7099817;-0.3889602;107.14;11.07116;47;47;0;2.236163;2.211527;98327.16;1.131873e+007
9996.292;1.469356;-1.026468;2966.781;306.568;47;47;0;4.627893;4.524;2722748;3.207557e+008
10032.93;2.060624;-2.057897;6039.181;624.05;47;47;0;6.490153;6.288234;5542426;6.645518e+008
10058.56;1.632856;-1.296257;2581.761;266.7825;47;47;0;5.142854;5.014975;2369398;2.805028e+008
10104.23;0.8717137;-0.3925959;109.3317;11.29763;47;47;0;2.745555;2.708541;100338.6;1.160782e+007
10148.94;0.493339;-0.3893966;94.76579;9.792484;48;48;0;1.553824;1.541875;86970.79;9944643
10194.66;1.255338;-0.7309593;2005.224;207.2069;48;48;0;3.953822;3.877659;1840283;2.153995e+008
10236.27;1.948927;-1.873419;5442.161;562.3578;48;48;0;6.138354;5.957328;4994514;5.968773e+008
10259.76;1.799838;-1.616821;3553.742;367.2208;48;48;0;5.668781;5.513931;3261428;3.880377e+008
10302.46;1.088196;-0.4958293;596.6915;61.65824;48;48;0;3.427388;3.369962;547610.4;6.377151e+007
10348.46;0.3213748;-0.3901784;94.46573;9.761477;48;48;0;1.012204;1.007116;86695.41;9860284
10392.93;1.039767;-0.5134549;1054.182;108.9324;49;49;0;3.274857;3.222376;967469.9;1.124998e+008
10436.87;1.772195;-1.566585;4461.206;460.9922;49;49;0;5.581717;5.431504;4094247;4.867234e+008
10463.41;1.925731;-1.84856;4525.973;467.6848;49;49;0;6.065294;5.88847;4153687;4.960513e+008
10500.7;1.304303;-0.7344398;1239.89;128.1222;49;49;0;4.10804;4.025902;1137902;1.333855e+008
10546.7;0.5377496;-0.3917176;94.53071;9.768193;49;49;0;1.6937;1.679516;86755.05;9933637
10591.35;0.8267138;-0.3926631;122.9938;12.70939;50;50;0;2.603823;2.570501;112876.9;1.304032e+007
10636.55;1.579981;-1.215554;3481.317;359.7368;50;50;0;4.976319;4.85646;3194960;3.776385e+008
10668.78;2.02307;-2.007258;5498.041;568.1321;50;50;0;6.371874;6.177102;5045798;6.043327e+008
10698.93;1.52041;-1.080881;2044.595;211.2753;50;50;0;4.788692;4.677568;1876416;2.213926e+008
10744.93;0.7538031;-0.3927475;106.4372;10.99853;50;50;0;2.374183;2.346438;97682.12;1.125965e+007
10789.56;0.6100711;-0.3917835;106.7144;11.02718;51;51;0;1.921484;1.903256;97936.56;1.123906e+007
10835.32;1.372553;-0.8833785;2502.358;258.5775;51;51;0;4.323;4.232167;2296526;2.697558e+008
10875.16;2.036624;-2.016454;5955.322;615.3845;51;51;0;6.414563;6.217225;5465464;6.548587e+008
10898.41;1.715785;-1.458312;3015.126;311.5637;51;51;0;5.404046;5.263084;2767116;3.284007e+008
10943.14;0.9703387;-0.4211389;293.5141;30.32985;51;51;0;3.056185;3.010414;269371;3.125679e+007
10987.77;0.3932676;-0.3923523;95.06865;9.82378;52;52;0;1.238638;1.23103;87248.74;9945461
11033.54;1.156124;-0.6217011;1564.579;161.6735;52;52;0;3.641336;3.576606;1435884;1.675606e+008
11076.39;1.870231;-1.740663;4976.632;514.253;52;52;0;5.890491;5.723527;4567277;5.44545e+008
11100.87;1.861713;-1.732951;3987.211;412.0126;52;52;0;5.863663;5.698189;3659241;4.361716e+008
11141.38;1.186767;-0.5873005;875.3196;90.44987;52;52;0;3.737849;3.669685;803319.9;9.383076e+007
11187.38;0.4199462;-0.3927061;94.6739;9.78299;52;52;0;1.322665;1.313994;86886.46;9912386
11231.98;0.9432851;-0.4396312;591.9378;61.16703;53;53;0;2.970977;2.927698;543247.7;6.298428e+007
11276.45;1.684338;-1.410247;3995.855;412.9059;53;53;0;5.305002;5.169074;3667175;4.348105e+008
11305.34;1.974159;-1.930842;4960.65;512.6015;53;53;0;6.217825;6.032175;4552610;5.444742e+008
11339.6;1.403195;-0.8830296;1573.922;162.6389;53;53;0;4.419513;4.324638;1444459;1.698268e+008
11385.6;0.6365353;-0.394405;106.225;10.97661;53;53;0;2.004835;1.985003;97487.43;1.119667e+007
11430.19;0.7265353;-0.3934234;107.7039;11.12942;54;54;0;2.2883;2.262511;98844.65;1.13841e+007
11475.81;1.487088;-1.053229;3016.944;311.7515;54;54;0;4.683743;4.577364;2768784;3.263531e+008
11511.66;2.055642;-2.055756;5931.332;612.9056;54;54;0;6.474462;6.273497;5443448;6.525879e+008
11538.02;1.616249;-1.264312;2474.989;255.7494;54;54;0;5.090548;4.965215;2271408;2.687685e+008
11583.84;0.8527495;-0.3963808;107.0637;11.06328;54;54;0;2.685825;2.65039;98257.17;1.136042e+007
11628.4;0.5099996;-0.3937124;95.28701;9.846344;55;55;0;1.606298;1.593534;87449.14;1.000451e+007
11674.19;1.273231;-0.753183;2050.938;211.9307;55;55;0;4.010178;3.931857;1882238;2.204295e+008
11715.59;1.963177;-1.900017;5490.759;567.3796;55;55;0;6.183235;5.999605;5039115;6.02462e+008
11738.95;1.787624;-1.597251;3447.596;356.2523;55;55;0;5.630311;5.477519;3164013;3.763105e+008
11782.06;1.069124;-0.4838525;534.632;55.24542;55;55;0;3.367321;3.311868;490655.7;5.710571e+007
11827.6;0.3099641;-0.394759;95.17249;9.83451;55;55;0;0.9762648;0.9715302;87344.04;9930521
11872.44;1.057178;-0.5303092;1109.818;114.6814;56;56;0;3.329694;3.275461;1018529;1.184999e+008
11916.28;1.787892;-1.596833;4510.482;466.0841;56;56;0;5.631155;5.478317;4139471;4.9233e+008
11942.41;1.916677;-1.836057;4420.102;456.7448;56;56;0;6.036779;5.861582;4056525;4.843175e+008
11980.28;1.285499;-0.7085465;1164.804;120.3634;56;56;0;4.048816;3.968999;1068993;1.252366e+008
12026.28;0.5188389;-0.395834;94.81874;9.797956;56;56;0;1.634138;1.62093;87019.38;9958068
12070.81;0.8434281;-0.3979691;166.5682;17.21208;57;57;0;2.656466;2.621795;152867.1;1.766931e+007
12115.96;1.595945;-1.245602;3530.736;364.8434;57;57;0;5.026599;4.904346;3240314;3.831827e+008
12147.62;2.016642;-2.000053;5392.304;557.2059;57;57;0;6.351627;6.158065;4948758;5.925975e+008
12178.51;1.501767;-1.048079;1946.611;201.1502;57;57;0;4.729975;4.621518;1786492;2.106645e+008
12224.51;0.7351067;-0.3976651;107.0077;11.05749;57;57;0;2.315297;2.2889;98205.77;1.13135e+007
12269.02;0.6267317;-0.3965029;107.211;11.07849;58;58;0;1.973958;1.954728;98392.28;1.129717e+007
12314.82;1.389963;-0.9083121;2551.036;263.6076;58;58;0;4.377838;4.284718;2341199;2.751479e+008
12354.37;2.049266;-2.038653;6005.759;620.5964;58;58;0;6.454382;6.254637;5511753;6.60652e+008
12377.72;1.701642;-1.432247;2909.462;300.645;58;58;0;5.359501;5.220814;2670143;3.167581e+008
12422.72;0.9515887;-0.4150591;245.0493;25.32181;58;58;0;2.99713;2.953094;224892.6;2.608074e+007
12467.22;0.4098747;-0.3963492;95.43203;9.861329;59;59;0;1.290944;1.282682;87582.23;9988633
12513.02;1.173481;-0.6418282;1615.228;166.9073;59;59;0;3.696004;3.62934;1482367;1.730762e+008
12555.69;1.884642;-1.768014;5025.7;519.3234;59;59;0;5.935879;5.766381;4612309;5.501498e+008
12579.94;1.851267;-1.714835;3881.016;401.0391;59;59;0;5.830761;5.667104;3561782;4.244228e+008
12620.97;1.167428;-0.5671734;808.1843;83.51255;59;59;0;3.676938;3.610952;741706.8;8.658325e+007
12666.97;0.4008747;-0.3970228;95.24728;9.842238;59;59;0;1.262598;1.254693;87412.68;9966507
12711.41;0.9597316;-0.4547581;649.5882;67.12424;60;60;0;3.022777;2.977991;596156;6.915326e+007
12755.83;1.700035;-1.438863;4045.131;417.9977;60;60;0;5.35444;5.21601;3712397;4.403791e+008
12784.26;1.966338;-1.919859;4854.579;501.6408;60;60;0;6.19319;6.00898;4455264;5.327084e+008
12819.19;1.384124;-0.8522297;1488.823;153.8454;60;60;0;4.359446;4.267097;1366359;1.605522e+008
12865.19;0.6173567;-0.3992309;106.9834;11.05497;60;60;0;1.944431;1.925768;98183.44;1.126993e+007
12909.63;0.7433566;-0.3991092;108.2584;11.18672;61;61;0;2.341281;2.314293;99353.56;1.144864e+007
12955.25;1.503749;-1.079163;3065.796;316.7996;61;61;0;4.736217;4.627479;2813618;3.318039e+008
12990.4;2.050713;-2.04827;5828.217;602.2503;61;61;0;6.458939;6.258917;5348815;6.411493e+008
13017.51;1.598892;-1.228764;2371.083;245.0124;61;61;0;5.03588;4.913182;2176049;2.573509e+008
13063.43;0.8335173;-0.400856;107.6305;11.12184;61;61;0;2.625252;2.591383;98777.33;1.141382e+007
13107.84;0.5266604;-0.3990638;99.22032;10.25279;62;62;0;1.658773;1.645165;91058.91;1.042286e+007
13153.66;1.290321;-0.77553;2102.531;217.2619;62;62;0;4.064002;3.983593;1929586;2.260915e+008
13194.84;1.976784;-1.922145;5542.511;572.7273;62;62;0;6.226093;6.039959;5086610;6.083858e+008
13218.12;1.775463;-1.571435;3345.24;345.6754;62;62;0;5.59201;5.441252;3070076;3.650057e+008
13261.64;1.050214;-0.4719196;477.6487;49.35713;62;62;0;3.30776;3.25423;438359.5;5.098974e+007
13306.05;0.3099641;-0.3986446;95.53725;9.872202;63;63;0;0.9762648;0.9715302;87678.79;9968581
13351.89;1.073999;-0.5482123;1167.93;120.6864;63;63;0;3.382675;3.326721;1071862;1.247688e+008
13395.6;1.802624;-1.622097;4561.813;471.3882;63;63;0;5.677556;5.522234;4186579;4.981516e+008
13421.4;1.907677;-1.817717;4315.444;445.9301;63;63;0;6.008433;5.834846;3960476;4.727235e+008
13459.88;1.266106;-0.682755;1091.471;112.7856;63;63;0;3.987737;3.910279;1001692;1.172832e+008
13505.88;0.4995532;-0.3996766;95.64945;9.883797;63;63;0;1.573396;1.561146;87781.77;1.003931e+007
13550.26;0.8599816;-0.4049757;213.8826;22.10124;64;64;0;2.708603;2.67257;196289.6;2.269988e+007
13595.38;1.611963;-1.273427;3585.489;370.5013;64;64;0;5.07705;4.95237;3290563;3.893118e+008
13626.46;2.010052;-1.988449;5289.624;546.5956;64;64;0;6.330873;6.138549;4854524;5.811999e+008
13658.1;1.482803;-1.013158;1853.483;191.527;64;64;0;4.670245;4.564469;1701024;2.004717e+008
13704.1;0.7160352;-0.4019142;107.384;11.09637;64;64;0;2.255229;2.230175;98551.13;1.134662e+007
13748.46;0.6433389;-0.400955;108.1028;11.17064;65;65;0;2.026264;2.006009;99210.75;1.139699e+007
13794.3;1.407213;-0.9336297;2606.586;269.3477;65;65;0;4.432168;4.336757;2392180;2.812857e+008
13833.6;2.062231;-2.056609;6060.67;626.2704;65;65;0;6.495215;6.292987;5562147;6.669481e+008
13857.12;1.685678;-1.396948;2803.581;289.704;65;65;0;5.309221;5.17308;2572972;3.05085e+008
13902.36;0.9318208;-0.4114024;198.4002;20.50139;65;65;0;2.934869;2.892626;182080.7;2.110308e+007
13946.67;0.4266962;-0.4011619;95.93725;9.913535;66;66;0;1.343925;1.334974;88045.89;1.004677e+007
13992.51;1.190785;-0.6605076;1671.343;172.7058;66;66;0;3.750504;3.681883;1533866;1.791831e+008
14035.05;1.899588;-1.790695;5081.637;525.1035;66;66;0;5.982955;5.810809;4663645;5.565202e+008
14059.05;1.840445;-1.691569;3777.037;390.2946;66;66;0;5.796678;5.634894;3466356;4.129187e+008
14100.57;1.148303;-0.5508316;743.3271;76.81062;66;66;0;3.616702;3.552835;682184.4;7.958863e+007
14146.57;0.3816426;-0.4006368;96.07729;9.928007;66;66;0;1.202024;1.194857;88174.41;1.004734e+007
14190.86;0.9763923;-0.4687971;714.1762;73.79836;67;67;0;3.075251;3.028913;655431.4;7.606784e+007
14235.3;1.71691;-1.466895;4104.495;424.132;67;67;0;5.407589;5.266445;3766878;4.470673e+008
14263.2;1.958035;-1.902189;4749.7;490.8033;67;67;0;6.167038;5.98435;4359012;5.210714e+008
14298.82;1.364517;-0.8202626;1407.496;145.4415;67;67;0;4.297691;4.207904;1291721;1.516921e+008
14344.82;0.5978032;-0.4029837;107.3591;11.0938;67;67;0;1.882845;1.865338;98528.24;1.130268e+007
14389.09;0.7600174;-0.4018009;108.8187;11.24462;68;68;0;2.393755;2.365554;99867.79;1.151379e+007
14434.74;1.520945;-1.105932;3126.062;323.027;68;68;0;4.790379;4.679178;2868926;3.385013e+008
14469.15;2.045516;-2.039094;5723.684;591.4485;68;68;0;6.442572;6.243542;5252881;6.295531e+008
14497.06;1.580624;-1.189123;2267.483;234.3071;68;68;0;4.978343;4.858389;2080970;2.459717e+008
14543.03;0.8143388;-0.4044676;107.9456;11.1544;68;68;0;2.564847;2.532506;99066.48;1.144049e+007
14587.29;0.5432139;-0.4018217;108.2912;11.19012;69;69;0;1.71091;1.696439;99383.7;1.138157e+007
14633.15;1.307571;-0.797879;2161.399;223.345;69;69;0;4.118333;4.035788;1983612;2.325431e+008
14674.21;1.991838;-1.943779;5601.882;578.8622;69;69;0;6.273506;6.084583;5141097;6.151772e+008
14697.41;1.761481;-1.541739;3230.285;333.7968;69;69;0;5.547972;5.399537;2964577;3.523158e+008
14741.32;1.029589;-0.4605315;417.5843;43.15047;69;69;0;3.242799;3.19133;383235.8;4.454975e+007
14785.5;0.3266248;-0.4023969;96.39198;9.960525;70;70;0;1.028739;1.023484;88463.22;1.006299e+007
14831.37;1.091249;-0.5662576;1235.86;127.7057;70;70;0;3.437006;3.37926;1134204;1.32095e+008
14875.06;1.819338;-1.649209;4622.016;477.6093;70;70;0;5.730199;5.572037;4241831;5.049772e+008
14900.4;1.898249;-1.796785;4205.823;434.6026;70;70;0;5.978737;5.806829;3859872;4.605863e+008
14939.51;1.246392;-0.6567191;1018.605;105.256;70;70;0;3.925644;3.85055;934819;1.09388e+008
14985.51;0.4797854;-0.4026634;96.31173;9.952231;70;70;0;1.511135;1.499831;88389.57;1.010262e+007
15029.7;0.8766958;-0.4116562;273.0792;28.21824;71;71;0;2.761247;2.723812;250616.9;2.899741e+007
15074.79;1.628088;-1.302594;3642.276;376.3692;71;71;0;5.127837;5.000692;3342679;3.956688e+008
15105.33;2.002927;-1.973779;5179.895;535.2568;71;71;0;6.308432;6.117442;4753820;5.690232e+008
15137.72;1.463088;-0.9782256;1756.868;181.5434;71;71;0;4.608152;4.50513;1612357;1.899092e+008
15183.72;0.6964281;-0.4041824;107.753;11.1345;71;71;0;2.193474;2.169764;98889.73;1.137873e+007
15227.9;0.6600531;-0.4032747;108.7313;11.23559;72;72;0;2.078907;2.057593;99787.58;1.146917e+007
15273.74;1.423874;-0.9596732;2664.107;275.2916;72;72;0;4.484643;4.386991;2444970;2.876374e+008
15312.51;2.070052;-2.067071;6081.56;628.4291;72;72;0;6.519849;6.316116;5581319;6.694018e+008
15336.48;1.670624;-1.364133;2699.371;278.9355;72;72;0;5.261807;5.128047;2477333;2.936126e+008
15381.91;0.9133387;-0.4101417;158.9036;16.42007;72;72;0;2.876657;2.836058;145832.9;1.689242e+007
15426.11;0.4434104;-0.4035937;96.64503;9.986673;73;73;0;1.396568;1.386906;88695.46;1.012614e+007
15471.99;1.208142;-0.6816604;1727.668;178.5261;73;73;0;3.805172;3.734561;1585558;1.853193e+008
15514.41;1.915017;-1.816252;5139.989;531.1332;73;73;0;6.031549;5.856649;4717197;5.631688e+008
15538.13;1.829785;-1.668387;3672.669;379.5099;73;73;0;5.763101;5.603151;3370572;4.013814e+008
15580.15;1.129606;-0.5346446;679.4636;70.21137;73;73;0;3.557815;3.495987;623574;7.270937e+007
15626.15;0.3628391;-0.4039485;96.60871;9.982921;73;73;0;1.1428;1.13632;88662.13;1.009701e+007
15670.3;0.9931065;-0.4842249;778.9961;80.49643;74;74;0;3.127895;3.079973;714919.5;8.301427e+007
15714.69;1.733035;-1.494967;4160.469;429.916;74;74;0;5.458377;5.314616;3818248;4.533824e+008
15742.12;1.949892;-1.887472;4645.088;479.9934;74;74;0;6.141391;5.96019;4263005;5.094717e+008
15778.37;1.345928;-0.792551;1330.176;137.4518;74;74;0;4.239142;4.151752;1220762;1.432785e+008
15824.37;0.5792675;-0.405083;108.1292;11.17337;74;74;0;1.824464;1.808021;99234.98;1.137723e+007
15868.52;0.7765709;-0.4039215;109.7806;11.34402;75;75;0;2.445893;2.41646;100750.5;1.162148e+007
15914.18;1.537713;-1.136077;3180.288;328.6305;75;75;0;4.843191;4.729563;2918693;3.445466e+008
15947.92;2.040106;-2.031253;5619.86;580.72;75;75;0;6.42553;6.227531;5157596;6.180343e+008
15976.57;1.56241;-1.155423;2163.721;223.585;75;75;0;4.920976;4.803727;1985744;2.345875e+008
16022.57;0.7959102;-0.4056694;108.6805;11.23034;75;75;0;2.506804;2.475899;99740.9;1.151186e+007
16066.73;0.5600354;-0.4043433;108.8396;11.24678;76;76;0;1.763891;1.748515;99886.95;1.144516e+007
16112.63;1.325035;-0.8228469;2212.934;228.6703;76;76;0;4.173338;4.088604;2030908;2.382134e+008
16153.42;2.004909;-1.967298;5653.32;584.1776;76;76;0;6.314675;6.123314;5188304;6.210665e+008
16176.57;1.749267;-1.520478;3137.512;324.2103;76;76;0;5.509501;5.363082;2879435;3.420726e+008
16220.78;1.012499;-0.4514804;368.6743;38.09642;76;76;0;3.188974;3.139182;338348.8;3.93113e+007
16264.93;0.3433926;-0.4035776;96.92795;10.01591;77;77;0;1.081552;1.075745;88955.1;1.012424e+007
16310.83;1.108339;-0.5823598;1291.124;133.4165;77;77;0;3.49083;3.431282;1184923;1.380738e+008
16354.34;1.833588;-1.676313;4673.724;482.9524;77;77;0;5.775081;5.614478;4289285;5.108433e+008
16379.39;1.888981;-1.781767;4111.806;424.8875;77;77;0;5.949546;5.779282;3773588;4.501664e+008
16418.99;1.229089;-0.6369312;955.8902;98.77552;77;77;0;3.871145;3.798095;877263.1;1.025993e+008
16464.99;0.4624818;-0.4049418;96.81686;10.00443;77;77;0;1.456636;1.446129;88853.15;1.015016e+007
16509.14;0.893303;-0.4200338;325.5532;33.64056;78;78;0;2.813553;2.774699;298774.7;3.458706e+007
16554.15;1.643517;-1.332875;3694.251;381.7401;78;78;0;5.176431;5.046905;3390379;4.015006e+008
16584.21;1.995534;-1.966061;5086.657;525.6223;78;78;0;6.285148;6.095537;4668252;5.586584e+008
16617.19;1.445892;-0.9515166;1678.168;173.411;78;78;0;4.55399;4.45334;1540129;1.813081e+008
16663.19;0.6791246;-0.4069953;108.3536;11.19656;78;78;0;2.138975;2.11642;99440.93;1.143605e+007
16707.34;0.6766603;-0.4055359;109.2488;11.28907;79;79;0;2.131213;2.108821;100262.5;1.152966e+007
16753.22;1.441285;-0.9861685;2714.804;280.5303;79;79;0;4.539479;4.439461;2491497;2.932649e+008
16790.94;2.070052;-2.071348;6062.757;626.4861;79;79;0;6.519849;6.316116;5564063;6.673321e+008
16815.82;1.65541;-1.337288;2605.073;269.1914;79;79;0;5.213889;5.082512;2390792;2.832267e+008
16861.4;0.8957673;-0.4087391;125.0971;12.92673;79;79;0;2.821314;2.782248;114807.2;1.329143e+007
16905.54;0.459964;-0.4054542;97.24464;10.04863;80;80;0;1.448705;1.438312;89245.74;1.019421e+007
16951.45;1.225071;-0.7001838;1774.655;183.3814;80;80;0;3.85849;3.785911;1628680;1.904572e+008
16993.62;1.927981;-1.84188;5190.112;536.3126;80;80;0;6.072381;5.895151;4763197;5.688795e+008
17017.22;1.818749;-1.652676;3579.766;369.9099;80;80;0;5.728343;5.570282;3285311;3.910996e+008
17059.61;1.112303;-0.5230446;621.8726;64.26029;80;80;0;3.503316;3.443347;570720.2;6.651153e+007
17105.61;0.3456427;-0.4060528;97.06509;10.03008;80;80;0;1.088638;1.082755;89080.96;1.013927e+007
17149.74;1.009928;-0.4979698;832.6013;86.03564;81;81;0;3.180875;3.131333;764115.3;8.877232e+007
17194.03;1.747981;-1.523703;4213.984;435.4459;81;81;0;5.505452;5.359244;3867361;4.594192e+008
17221.06;1.941535;-1.877462;4553.834;470.5638;81;81;0;6.115069;5.935388;4179257;4.993391e+008
17257.82;1.328678;-0.7714085;1262.63;130.472;81;81;0;4.184812;4.099617;1158772;1.35932e+008
17303.82;0.5619639;-0.4078631;107.6709;11.12601;81;81;0;1.769965;1.754484;98814.36;1.132294e+007
17347.95;0.7933923;-0.4071805;110.1407;11.38123;82;82;0;2.498873;2.468162;101081.1;1.166563e+007
17393.59;1.553785;-1.16404;3234.189;334.2002;82;82;0;4.89381;4.777832;2968159;3.505553e+008
17426.7;2.03432;-2.026887;5526.632;571.0865;82;82;0;6.407307;6.210407;5072037;6.076777e+008
17456.08;1.544624;-1.123916;2070.213;213.9225;82;82;0;4.864958;4.750322;1899927;2.243297e+008
17502.08;0.7779637;-0.4085051;109.0988;11.27357;82;82;0;2.450279;2.420742;100124.8;1.15498e+007
17546.16;0.5766425;-0.406582;109.2699;11.29125;83;83;0;1.816197;1.799901;100281.9;1.149632e+007
17592.08;1.34191;-0.846158;2265.52;234.1042;83;83;0;4.226488;4.139611;2079169;2.439986e+008
17632.58;2.017124;-1.989161;5709.336;589.9659;83;83;0;6.353145;6.159493;5239713;6.274473e+008
17655.78;1.736303;-1.49712;3044.545;314.6036;83;83;0;5.468669;5.324375;2794115;3.318082e+008
17700.28;0.9946601;-0.4437441;320.874;33.15705;83;83;0;3.132788;3.084717;294480.4;3.419579e+007
17744.36;0.3599462;-0.4071235;97.54312;10.07948;84;84;0;1.133689;1.127311;89519.67;1.019375e+007
17790.28;1.125267;-0.5987925;1345.341;139.0188;84;84;0;3.544148;3.482789;1234679;1.439459e+008
17833.63;1.847677;-1.702041;4729.138;488.6785;84;84;0;5.819457;5.656422;4340141;5.17117e+008
17858.4;1.879392;-1.767483;4018.695;415.266;84;84;0;5.919344;5.750771;3688136;4.39847e+008
17898.49;1.211463;-0.617843;895.194;92.50357;84;84;0;3.815633;3.744638;821559.5;9.603316e+007
17944.49;0.4448033;-0.4077945;97.20984;10.04504;84;84;0;1.400955;1.391233;89213.8;1.018576e+007
17988.57;0.9098565;-0.4283434;380.2255;39.29004;85;85;0;2.86569;2.825397;348949.8;4.041597e+007
18033.49;1.658731;-1.360947;3749.984;387.4991;85;85;0;5.22435;5.092455;3441527;4.077434e+008
18063.08;1.988356;-1.958043;4991.107;515.7488;85;85;0;6.262538;6.074262;4580562;5.480477e+008
18096.72;1.427624;-0.9235442;1595.935;164.9136;85;85;0;4.496454;4.398295;1464661;1.723289e+008
18142.72;0.6609102;-0.4098614;109.1505;11.2789;85;85;0;2.081607;2.060238;100172.3;1.151369e+007
18186.78;0.693321;-0.4093001;110.2121;11.38861;86;86;0;2.183688;2.160187;101146.6;1.16373e+007
18232.64;1.457678;-1.012231;2771.08;286.3455;86;86;0;4.591111;4.488838;2543143;2.994919e+008
18269.75;2.06507;-2.071345;5964.478;616.3306;86;86;0;6.504158;6.301384;5473867;6.564177e+008
18295.24;1.639124;-1.308236;2506.266;258.9814;86;86;0;5.162595;5.033749;2300113;2.723515e+008
18340.98;0.8767494;-0.4123284;109.9952;11.36619;86;86;0;2.761415;2.723976;100947.5;1.168006e+007
18384.99;0.476839;-0.4088083;97.79855;10.10587;87;87;0;1.501855;1.490689;89754.09;1.025765e+007
18430.93;1.242428;-0.7223976;1829.707;189.0701;87;87;0;3.913158;3.838535;1679203;1.964687e+008
18472.9;1.941856;-1.867965;5247.18;542.2097;87;87;0;6.116082;5.936342;4815571;5.753717e+008
18496.37;1.80691;-1.631803;3477.341;359.326;87;87;0;5.691054;5.535007;3191311;3.797754e+008
18539.21;1.09291;-0.50978;561.6892;58.04134;87;87;0;3.442236;3.384317;515487.3;6.003925e+007
18585.21;0.3264105;-0.4085166;97.85658;10.11187;87;87;0;1.028065;1.022816;89807.34;1.021582e+007
18630.17;1.042821;-0.5255818;966.816;99.90452;88;88;0;3.284475;3.231689;887290.1;1.031859e+008
18674.27;1.777874;-1.580462;4341.434;448.6158;88;88;0;5.599603;5.448442;3984328;4.737365e+008
18700.54;1.924231;-1.849646;4376.426;452.2316;88;88;0;6.06057;5.884016;4016442;4.796394e+008
18738.42;1.293053;-0.7226623;1136.122;117.3996;88;88;0;4.072607;3.991861;1042670;1.221808e+008
18784.42;0.526339;-0.4126166;97.62993;10.08845;88;88;0;1.657761;1.64417;89599.34;1.025569e+007
18829.39;0.8434281;-0.4104345;121.4828;12.55325;89;89;0;2.656466;2.621795;111490.2;1.288672e+007
18874.8;1.600231;-1.250794;3436.371;355.0924;89;89;0;5.040098;4.917197;3153711;3.729894e+008
18906.24;2.016052;-2.001944;5274.229;545.0047;89;89;0;6.349771;6.15632;4840395;5.796113e+008
18937.65;1.492553;-1.03355;1837.723;189.8984;89;89;0;4.700953;4.593804;1686560;1.988254e+008
18983.65;0.7257853;-0.4114586;109.3276;11.2972;89;89;0;2.285938;2.260202;100334.8;1.155545e+007
19028.6;0.6433389;-0.4098343;110.1076;11.37781;90;90;0;2.026264;2.006009;101050.7;1.160835e+007
19074.56;1.409142;-0.9394637;2533.374;261.7825;90;90;0;4.438242;4.342573;2324991;2.734011e+008
19113.88;2.064695;-2.06577;5988.178;618.7796;90;90;0;6.502977;6.300275;5495618;6.590187e+008
19137.5;1.68182;-1.392352;2716.039;280.6579;90;90;0;5.297072;5.161542;2492630;2.955246e+008
19182.87;0.9257137;-0.4182091;170.779;17.6472;90;90;0;2.915634;2.873938;156731.5;1.816173e+007
19227.81;0.4434104;-0.4097982;98.22395;10.14983;91;91;0;1.396568;1.386906;90144.5;1.029158e+007
19273.76;1.20916;-0.6848762;1677.867;173.3799;91;91;0;3.808378;3.737649;1539853;1.799829e+008
19316.15;1.915874;-1.823663;5084.486;525.3979;91;91;0;6.034248;5.859195;4666260;5.571017e+008
19339.91;1.828177;-1.673465;3614.499;373.499;91;91;0;5.758039;5.598365;3317187;3.950052e+008
19382.08;1.125428;-0.5368216;646.538;66.80907;91;91;0;3.544655;3.483278;593356.8;6.917722e+007
19428.08;0.3587141;-0.4111015;98.0605;10.13294;91;91;0;1.129808;1.123473;89994.49;1.024742e+007
19473.01;1.010035;-0.5000913;807.8336;83.4763;92;92;0;3.181213;3.13166;741384.9;8.613186e+007
19517.35;1.749052;-1.527584;4179.846;431.9183;92;92;0;5.508827;5.362443;3836032;4.55712e+008
19544.36;1.940945;-1.881562;4505.759;465.5961;92;92;0;6.113213;5.933638;4135136;4.940589e+008
19581.37;1.324231;-0.767751;1226.838;126.7735;92;92;0;4.170807;4.086174;1125924;1.32061e+008
19627.37;0.5575711;-0.4120285;101.311;10.46882;92;92;0;1.756129;1.740888;92977.58;1.065267e+007
19672.21;0.810053;-0.4121205;111.2471;11.49555;93;93;0;2.551348;2.519344;102096.4;1.178885e+007
19717.85;1.570553;-1.198132;3272.649;338.1744;93;93;0;4.946622;4.828168;3003456;3.549026e+008
19750.32;2.02832;-2.024769;5401.436;558.1495;93;93;0;6.38841;6.192645;4957139;5.938063e+008
19780.6;1.523624;-1.091397;1952.477;201.7563;93;93;0;4.798816;4.687228;1791875;2.114382e+008
19826.6;0.7568567;-0.4137711;109.9076;11.35714;93;93;0;2.383801;2.355832;100867.1;1.162788e+007
19871.42;0.6100711;-0.4113651;110.3502;11.40288;94;94;0;1.921484;1.903256;101273.3;1.162198e+007
19917.39;1.376303;-0.8953767;2371.476;245.053;94;94;0;4.334812;4.243488;2176410;2.556756e+008
19957.4;2.042945;-2.037679;5822.887;601.6995;94;94;0;6.434473;6.235933;5343923;6.404157e+008
19980.75;1.707802;-1.448756;2842.015;293.6755;94;94;0;5.378905;5.239229;2608244;3.09472e+008
20025.84;0.9565173;-0.4288493;229.2518;23.6894;94;94;0;3.012653;2.968164;210394.6;2.440308e+007
20070.62;0.4098747;-0.4121917;98.52102;10.18053;95;95;0;1.290944;1.282682;90417.13;1.031195e+007
20116.6;1.176106;-0.6501522;1524.839;157.567;95;95;0;3.704272;3.637312;1399413;1.634037e+008
20159.46;1.890481;-1.78468;4917.009;508.0919;95;95;0;5.954271;5.783741;4512559;5.383451e+008
20183.52;1.848374;-1.716452;3740.344;386.503;95;95;0;5.82165;5.658494;3432680;4.090038e+008
20225.04;1.156338;-0.5661783;724.6084;74.87636;95;95;0;3.642011;3.577257;665005.5;7.760336e+007
20271.04;0.3896248;-0.4126257;98.12786;10.1399;95;95;0;1.227165;1.219696;90056.31;1.026433e+007
20315.83;0.9767672;-0.4746649;651.0798;67.27837;96;96;0;3.076432;3.030059;597524.9;6.934815e+007
20360.46;1.720553;-1.479641;4013.765;414.7565;96;96;0;5.419063;5.27733;3683611;4.372324e+008
20388.2;1.957284;-1.912218;4639.998;479.4674;96;96;0;6.164675;5.982124;4258333;5.09025e+008
20424.27;1.356213;-0.8156532;1323.407;136.7523;96;96;0;4.271538;4.182825;1214550;1.425938e+008
20470.27;0.5895532;-0.4142246;109.976;11.3642;96;96;0;1.856861;1.839831;100929.8;1.157522e+007
20515.04;0.7766245;-0.4145328;111.3932;11.51065;97;97;0;2.446061;2.416624;102230.5;1.179221e+007
20560.84;1.540071;-1.145335;3110.256;321.3938;97;97;0;4.850616;4.736644;2854421;3.369833e+008
20594.46;2.039838;-2.043311;5537.917;572.2526;97;97;0;6.424686;6.226738;5082393;6.09018e+008
20623.49;1.555767;-1.149528;2082.732;215.216;97;97;0;4.900053;4.783783;1911416;2.257617e+008
20669.49;0.7891602;-0.4143612;110.2852;11.39616;97;97;0;2.485544;2.455157;101213.7;1.167942e+007
20714.24;0.5766425;-0.4130986;110.5186;11.42027;98;98;0;1.816197;1.799901;101427.8;1.162769e+007
20760.22;1.343035;-0.8520386;2221.979;229.6049;98;98;0;4.230031;4.143011;2039209;2.393173e+008
20800.82;2.019642;-2.00091;5662.562;585.1326;98;98;0;6.361076;6.166949;5196786;6.223533e+008
20824.05;1.733356;-1.497643;2981.617;308.101;98;98;0;5.459389;5.315576;2736363;3.249215e+008
20868.69;0.9894101;-0.4448825;298.0362;30.79713;98;98;0;3.116252;3.068683;273521.1;3.175685e+007
20913.45;0.3766605;-0.4137876;98.49574;10.17791;99;99;0;1.186332;1.17935;90393.93;1.029866e+007
20959.44;1.143053;-0.6193636;1380.429;142.6446;99;99;0;3.600167;3.536875;1266881;1.477801e+008
21002.66;1.863481;-1.736593;4755.841;491.4379;99;99;0;5.869232;5.703448;4364648;5.202816e+008
21027.16;1.868249;-1.7524;3879.316;400.8635;99;99;0;5.884248;5.717631;3560222;4.244513e+008
21067.93;1.188749;-0.5960093;809.1927;83.61674;99;99;0;3.744092;3.675703;742632.2;8.674743e+007
21113.93;0.422089;-0.4137071;98.36347;10.16425;99;99;0;1.329414;1.320655;90272.55;1.029937e+007
21120.66;0.3099641;-0.4131315;98.66688;10.1956;100;100;0;0.9762648;0.9715302;90551;1.029513e+007