File: Ensayos/Resistencia/comp/EsponjaB/REB3_com.raw
"Test Type";"Manual"
"Method Name:";"C:\INSTRON\user\template\CYCLE.MTM"
"Name:";""
"Operator ID:";""
"Company:";""
"Lab name:";""
"Test date:";"10/05/2017"
"Temperature:";""
"Humidity:";""
"Note 1:";""
"Note 2:";""
"Note 3:";""
"Geometry:";"Rectangular"
"Specimen";1
"Specimen name:";""
"Width:";0.250000;"in"
"Thickness:";0.060000;"in"
"Length:";1.250000;"in"
"Diameter:";0.039370;"in"
"Inner diameter:";0.019685;"in"
"Outer diameter:";0.039370;"in"
"Wall thickness:";0.019685;"in"
"Area:";0.015000;"in*in"
"Linear density:";1.000000;"den"
"Sled weight:";2.204623;"lbf"
"Loading span:";0.000000;"mm"
"Support span:";1.000000;"mm"
"Span ratio:";"2"
"Fixture type:";"3-point"
"Comment:";""
"Included"
"Final Width:";0.250000;"in"
"Final Thickness:";0.060000;"in"
"Final Length:";1.250000;"in"
"Final Diameter:";0.039370;"in"
"Final Inner diameter:";0.019685;"in"
"Final Outer diameter:";0.039370;"in"
"Final Wall thickness:";0.019685;"in"
"Final Area:";0.015000;"in*in"
"Final Linear density:";1.000000;"den"
"Time sec";"Extension mm";"Strain 1 %";"Load N";"Stress MPa";"Cycle Count ";"Total Cycle Count ";"Repetitions Count ";"Strain [Exten.] %";"True strain %";"Tenacity gf/tex";"True stress Pa"
0;0.3100177;-0.4121143;100.4092;10.37563;0;0;0;0.9764336;0.9716973;92149.97;1.047695e+007
14;0.5432139;-0.4134818;112.2251;11.59662;0;0;0;1.71091;1.696439;102994;1.179502e+007
28;0.7766245;-0.4154427;126.4801;13.06963;0;0;0;2.446061;2.416624;116076.4;1.338932e+007
41.91;1.008589;-0.5674362;1142.158;118.0232;0;0;0;3.176657;3.127245;1048209;1.217724e+008
55.91;1.241946;-0.801128;2084.865;215.4364;0;0;0;3.91164;3.837073;1913373;2.238635e+008
69.91;1.475195;-1.111651;3046.947;314.8518;0;0;0;4.646285;4.541576;2796319;3.294807e+008
83.10001;1.694945;-1.503914;4096.891;423.3462;0;0;0;5.338411;5.200794;3759899;4.459462e+008
95.232;1.897177;-1.851576;5147.803;531.9407;0;0;0;5.975362;5.803645;4724368;5.637261e+008
106.454;2.084195;-2.158619;6197.368;640.396;0;0;0;6.564394;6.357925;5687601;6.824341e+008
120.226;2.313909;-2.6667;6595.236;681.5091;0;0;0;7.287903;7.034572;6052742;7.311768e+008
129.72;2.439534;-3.031131;6434.299;664.8789;0;0;0;7.683572;7.402685;5905043;7.159653e+008
134.8;2.354891;-2.909754;5381.493;556.0887;0;0;0;7.416981;7.154809;4938836;5.973337e+008
142.158;2.232266;-2.70642;4330.131;447.4478;0;0;0;7.03076;6.794609;3973955;4.789068e+008
152.048;2.067481;-2.389373;3278.749;338.8047;0;0;0;6.51175;6.308512;3009054;3.608668e+008
165.474;1.843713;-1.915841;2258.373;233.3657;0;0;0;5.806971;5.644621;2072610;2.469172e+008
179.474;1.610356;-1.414967;1458;150.6603;0;0;0;5.071988;4.947553;1338071;1.583017e+008
193.474;1.377053;-0.9793481;854.2613;88.27385;0;0;0;4.337174;4.245752;783993.7;9.210244e+007
207.474;1.143535;-0.6739982;374.5183;38.70031;0;0;0;3.601685;3.538341;343712.2;4.009417e+007
221.474;0.910178;-0.552591;110.9718;11.46711;0;0;0;2.866702;2.826381;101843.7;1.179583e+007
234.246;1.064089;-0.6123054;547.9843;56.62516;1;1;0;3.35146;3.296523;502909.6;5.852293e+007
248.246;1.297338;-0.8470009;1552.454;160.4206;1;1;0;4.086105;4.00483;1424757;1.669756e+008
262.246;1.530803;-1.200356;2501.972;258.5376;1;1;0;4.821425;4.708801;2296171;2.710028e+008
276.246;1.76416;-1.648382;3472.743;358.8508;1;1;0;5.556408;5.40753;3187091;3.7879e+008
290.246;1.997517;-2.107084;4482.466;463.1891;1;1;0;6.29139;6.10141;4113759;4.923301e+008
303.87;2.224552;-2.558502;5518.877;570.285;1;1;0;7.006464;6.771906;5064919;6.102419e+008
317.404;2.450034;-3.073828;6274.072;648.322;1;1;0;7.716643;7.433392;5757996;6.983507e+008
321.628;2.379695;-2.983885;5295.21;547.1729;1;1;0;7.495102;7.22751;4859651;5.88184e+008
328.63;2.263123;-2.798913;4242.503;438.3929;1;1;0;7.127948;6.885371;3893534;4.696413e+008
338.17;2.103963;-2.499719;3190.738;329.7103;1;1;0;6.626655;6.416334;2928283;3.51559e+008
351.412;1.883356;-2.04807;2170.177;224.2521;1;1;0;5.93183;5.762559;1991668;2.375543e+008
365.412;1.650053;-1.5413;1373.26;141.9038;1;1;0;5.197016;5.066475;1260302;1.492786e+008
379.412;1.416695;-1.085119;777.5685;80.34891;1;1;0;4.462033;4.36535;713609.3;8.39341e+007
393.412;1.183338;-0.7550014;323.3283;33.41066;1;1;0;3.72705;3.659275;296732.8;3.465589e+007
407.412;0.949928;-0.6366497;110.6988;11.4389;1;1;0;2.991899;2.948015;101593.2;1.178114e+007
419.416;0.949928;-0.6350075;111.5348;11.52528;2;2;0;2.991899;2.948015;102360.4;1.187011e+007
433.416;1.183285;-0.757365;839.5679;86.75552;2;2;0;3.726882;3.659112;770508.9;8.99888e+007
447.416;1.416642;-1.040923;1773.949;183.3084;2;2;0;4.461864;4.365188;1628032;1.914874e+008
461.416;1.650053;-1.466521;2692.251;278.1998;2;2;0;5.197016;5.066475;2470799;2.926579e+008
475.416;1.883195;-1.933231;3634.837;375.6006;2;2;0;5.931324;5.762081;3335852;3.978787e+008
489.412;2.116606;-2.405131;4632.96;478.7401;2;2;0;6.666474;6.453672;4251874;5.106552e+008
503.012;2.343213;-2.846385;5682.099;587.1514;2;2;0;7.380198;7.12056;5214716;6.304844e+008
511.186;2.420838;-3.035426;5552.126;573.7208;2;2;0;7.624686;7.347986;5095434;6.174652e+008
516.984;2.324248;-2.891328;4499.733;464.9733;2;2;0;7.320467;7.06492;4129606;4.990115e+008
525.406;2.183838;-2.645048;3447.456;356.2378;2;2;0;6.878229;6.651996;3163884;3.807406e+008
537.538;1.981552;-2.247903;2401.636;248.1695;2;2;0;6.241109;6.054094;2204088;2.636581e+008
551.538;1.748249;-1.743148;1540.438;159.179;2;2;0;5.506296;5.360044;1413729;1.679438e+008
565.538;1.514892;-1.260895;903.6842;93.38089;2;2;0;4.771313;4.660981;829351.3;9.783638e+007
579.538;1.281696;-0.8837921;418.4709;43.24208;2;2;0;4.036837;3.957485;384049.4;4.498769e+007
593.538;1.048339;-0.6880094;111.0029;11.47033;2;2;0;3.301854;3.248514;101872.3;1.184906e+007
606.44;0.8665173;-0.684095;110.3501;11.40286;3;3;0;2.729188;2.69261;101273.2;1.171407e+007
620.44;1.100035;-0.7069951;296.8247;30.67195;3;3;0;3.464677;3.406009;272409.3;3.173463e+007
634.44;1.333392;-0.9490775;1263.919;130.6052;3;3;0;4.19966;4.113868;1159955;1.360902e+008
648.44;1.566588;-1.319755;2164.19;223.6334;3;3;0;4.934136;4.816269;1986174;2.346678e+008
662.44;1.799999;-1.77424;3074.179;317.6657;3;3;0;5.669288;5.51441;2821311;3.356751e+008
676.44;2.033195;-2.246871;4021.281;415.5332;3;3;0;6.403764;6.207077;3690509;4.42143e+008
690.1381;2.261624;-2.695777;5053.568;522.2031;3;3;0;7.123224;6.880961;4637885;5.594008e+008
701.8021;2.44548;-3.066546;5766.417;595.8643;3;3;0;7.702301;7.420076;5292098;6.417596e+008
706.6541;2.363463;-2.953129;4713.446;487.057;3;3;0;7.443977;7.179938;4325740;5.233135e+008
714.33;2.235374;-2.742142;3661.96;378.4033;3;3;0;7.040546;6.803752;3360744;4.05045e+008
725.34;2.051838;-2.391727;2610.554;269.7578;3;3;0;6.462481;6.262245;2395822;2.871908e+008
739.332;1.818695;-1.898367;1691.894;174.8294;3;3;0;5.728174;5.570122;1552726;1.848439e+008
753.332;1.585338;-1.394589;1013.294;104.7072;3;3;0;4.993191;4.872532;929944.9;1.099355e+008
767.332;1.352035;-0.992891;508.1561;52.50956;3;3;0;4.258378;4.170203;466357.5;5.474562e+007
781.332;1.118839;-0.744054;129.3157;13.36265;3;3;0;3.523901;3.463233;118678.8;1.383354e+007
795.332;0.8854816;-0.7300778;110.4358;11.41172;3;3;0;2.788918;2.750736;101351.8;1.172998e+007
807.46;1.016678;-0.7288995;111.5797;11.52992;4;4;0;3.202135;3.151936;102401.6;1.189912e+007
821.46;1.249928;-0.870081;823.4489;85.08989;4;4;0;3.93678;3.861265;755715.8;8.843969e+007
835.46;1.483392;-1.182662;1730.49;178.8177;4;4;0;4.672101;4.566243;1588148;1.871722e+008
849.46;1.716535;-1.616765;2617.206;270.4451;4;4;0;5.406408;5.265325;2401926;2.850665e+008
863.46;1.949892;-2.09167;3531.379;364.9099;4;4;0;6.141391;5.96019;3240904;3.873204e+008
877.45;2.183141;-2.556753;4519.769;467.0438;4;4;0;6.876036;6.649944;4147994;4.991579e+008
890.814;2.405945;-2.984685;5571.302;575.7023;4;4;0;7.577779;7.304393;5113032;6.193278e+008
896.5921;2.398123;-3.019587;4982.992;514.9102;4;4;0;7.553145;7.281491;4573114;5.538021e+008
903.4021;2.284659;-2.841894;3930.725;406.1757;4;4;0;7.195777;6.948667;3607402;4.354032e+008
913.2061;2.121266;-2.542588;2879.532;297.5522;4;4;0;6.681154;6.467433;2642675;3.174322e+008
926.8781;1.893374;-2.077927;1903.265;196.6711;4;4;0;5.963382;5.79234;1746711;2.083993e+008
940.8781;1.660124;-1.573052;1164.729;120.3556;4;4;0;5.228736;5.096624;1068924;1.266486e+008
954.8781;1.426713;-1.130971;619.9019;64.05666;4;4;0;4.493586;4.39555;568911.6;6.693509e+007
968.8781;1.19341;-0.8237182;207.3106;21.42214;4;4;0;3.758771;3.689851;190258.2;2.222735e+007
982.8781;0.9599458;-0.7715213;110.685;11.43747;4;4;0;3.023451;2.978646;101580.6;1.178328e+007
995.4841;0.949928;-0.7698439;111.2015;11.49084;5;5;0;2.991899;2.948015;102054.6;1.183464e+007
1009.484;1.183285;-0.8301715;479.6916;49.56823;5;5;0;3.726882;3.659112;440234.3;5.141558e+007
1023.484;1.416642;-1.097005;1397.007;144.3577;5;5;0;4.461864;4.365188;1282095;1.507987e+008
1037.484;1.650053;-1.503507;2274.08;234.9887;5;5;0;5.197016;5.066475;2087025;2.472011e+008
1051.484;1.883249;-1.973166;3164.886;327.0389;5;5;0;5.931493;5.76224;2904557;3.464372e+008
1065.484;2.116659;-2.451886;4104.73;424.1563;5;5;0;6.666643;6.45383;3767094;4.524332e+008
1079.08;2.343213;-2.882475;5148.961;532.0604;5;5;0;7.380198;7.12056;4725431;5.713275e+008
1087.28;2.420248;-3.068057;5173.042;534.5488;5;5;0;7.62283;7.346261;4747532;5.752965e+008
1093.276;2.320338;-2.919949;4120.325;425.7678;5;5;0;7.308151;7.053442;3781407;4.568836e+008
1102.344;2.16932;-2.659544;3068.609;317.0902;5;5;0;6.832504;6.609204;2816199;3.387554e+008
1115.452;1.950695;-2.229084;2054.047;212.2519;5;5;0;6.143922;5.962574;1885090;2.252925e+008
1129.452;1.717499;-1.729467;1281.247;132.3958;5;5;0;5.409446;5.268206;1175858;1.395577e+008
1143.452;1.484035;-1.261585;708.7056;73.23306;5;5;0;4.674125;4.568177;650410.7;7.665606e+007
1157.452;1.250839;-0.9161782;274.2803;28.34235;5;5;0;3.939649;3.864025;251719.3;2.945894e+007
1171.452;1.017535;-0.819801;111.1577;11.48632;5;5;0;3.204835;3.154551;102014.4;1.185444e+007
1183.504;0.8832852;-0.8173107;110.9912;11.46911;6;6;0;2.782001;2.744006;101861.6;1.178818e+007
1197.504;1.116642;-0.822759;170.1362;17.58078;6;6;0;3.516983;3.45655;156141.6;1.819909e+007
1211.504;1.349892;-1.04163;1086.653;112.2877;6;6;0;4.251628;4.163729;997270;1.170618e+008
1225.504;1.583142;-1.404503;1941.599;200.6323;6;6;0;4.986274;4.865943;1781892;2.106364e+008
1239.504;1.816659;-1.866637;2809.995;290.3667;6;6;0;5.721762;5.564057;2578858;3.069808e+008
1253.504;2.049963;-2.339473;3728.445;385.2734;6;6;0;6.456577;6.256698;3421760;4.101489e+008
1267.34;2.280534;-2.784795;4752.671;491.1104;6;6;0;7.182785;6.936546;4361739;5.263858e+008
1278.116;2.440391;-3.103498;5338.858;551.6831;6;6;0;7.686272;7.405193;4899709;5.94087e+008
1283.382;2.352266;-2.979233;4285.761;442.8629;6;6;0;7.408713;7.147112;3933234;4.756733e+008
1291.756;2.212713;-2.751113;3234.073;334.1882;6;6;0;6.969174;6.737052;2968053;3.574784e+008
1304.102;2.007052;-2.363344;2197.143;227.0385;6;6;0;6.321425;6.129663;2016416;2.413906e+008
1318.102;1.773695;-1.869451;1381.462;142.7514;6;6;0;5.586442;5.435979;1267829;1.507261e+008
1332.102;1.540338;-1.380207;784.8506;81.10139;6;6;0;4.851459;4.737449;720292.4;8.503599e+007
1346.102;1.30682;-1.000761;337.2455;34.84877;6;6;0;4.11597;4.033519;309505.2;3.628313e+007
1360.102;1.073571;-0.8462252;111.3837;11.50967;6;6;0;3.381325;3.325415;102221.8;1.189885e+007
1373.522;0.8499637;-0.8433899;110.7261;11.44172;6;6;0;2.677051;2.641845;101618.3;1.174803e+007
1386.524;1.066553;-0.8432355;112.1102;11.58474;7;7;0;3.359222;3.304032;102888.5;1.19739e+007
1400.524;1.300017;-1.001669;831.3803;85.90947;7;7;0;4.094542;4.012936;762994.8;8.942707e+007
1414.524;1.53316;-1.335311;1684.864;174.103;7;7;0;4.828849;4.715883;1546275;1.825102e+008
1428.524;1.766517;-1.78559;2536.836;262.1403;7;7;0;5.563832;5.414563;2328168;2.767253e+008
1442.524;1.999981;-2.260597;3424.028;353.817;7;7;0;6.299152;6.108712;3142384;3.761045e+008
1456.486;2.232749;-2.71396;4415.093;456.2271;7;7;0;7.032279;6.796027;4051927;4.883103e+008
1469.532;2.450034;-3.128586;5372.96;555.207;7;7;0;7.716643;7.433392;4931006;5.980504e+008
1474.086;2.374338;-3.031468;4395.551;454.2079;7;7;0;7.478229;7.211812;4033994;4.881746e+008
1481.966;2.242927;-2.823395;3343.305;345.4755;7;7;0;7.064338;6.825976;3068300;3.698811e+008
1493.736;2.046802;-2.461775;2294.947;237.1449;7;7;0;6.446621;6.247346;2106175;2.524328e+008
1507.736;1.813445;-1.974988;1450.9;149.9267;7;7;0;5.711638;5.554481;1331556;1.584899e+008
1521.736;1.580088;-1.477597;836.1035;86.39754;7;7;0;4.976656;4.856782;767329.4;9.069724e+007
1535.736;1.346731;-1.071192;380.3884;39.30688;7;7;0;4.241673;4.15418;349099.4;4.097415e+007
1549.736;1.113267;-0.8755314;111.4005;11.51141;7;7;0;3.506353;3.446281;102237.2;1.191504e+007
1563.736;0.8800709;-0.8724478;110.9346;11.46326;7;7;0;2.771877;2.734156;101809.6;1.178101e+007
1576.546;1.033178;-0.8707;111.8506;11.55792;8;8;0;3.254103;3.202279;102650.3;1.193402e+007
1590.546;1.266481;-0.9828568;654.4584;67.6275;8;8;0;3.988917;3.911414;600625.6;7.032511e+007
1604.546;1.499892;-1.298629;1511.253;156.1631;8;8;0;4.724069;4.615879;1386945;1.635404e+008
1618.546;1.733302;-1.738665;2343.445;242.1565;8;8;0;5.45922;5.315416;2150684;2.553763e+008
1632.546;1.966713;-2.215999;3210.972;331.8011;8;8;0;6.194372;6.010092;2946853;3.523541e+008
1646.546;2.199909;-2.66821;4168.312;430.7264;8;8;0;6.928848;6.699345;3825445;4.605708e+008
1660.084;2.425659;-3.08362;5217.736;539.1671;8;8;0;7.639872;7.362095;4788549;5.803588e+008
1665.24;2.388641;-3.059654;4462.671;461.1436;8;8;0;7.52328;7.253719;4095592;4.958367e+008
1672.748;2.263606;-2.866802;3411.357;352.5076;8;8;0;7.129467;6.886788;3130754;3.776395e+008
1684.122;2.074017;-2.523713;2359.957;243.8627;8;8;0;6.532335;6.327837;2165838;2.597926e+008
1698.122;1.84066;-2.047173;1494.667;154.4492;8;8;0;5.797353;5.635531;1371723;1.634032e+008
1712.122;1.607356;-1.549106;869.5398;89.85262;8;8;0;5.062539;4.93856;798015.4;9.440144e+007
1726.122;1.374106;-1.127487;404.4081;41.78892;8;8;0;4.327894;4.236858;371143.3;4.35975e+007
1740.122;1.140749;-0.9045261;111.6772;11.54;8;8;0;3.592911;3.529871;102491.2;1.195462e+007
1754.122;0.9073922;-0.9003684;110.97;11.46692;8;8;0;2.857928;2.817851;101842.1;1.179464e+007
1766.568;0.9999636;-0.9002797;111.8675;11.55966;9;9;0;3.149492;3.100913;102665.8;1.192373e+007
1780.568;1.233321;-0.9692778;474.6837;49.05074;9;9;0;3.884475;3.810927;435638.4;5.095611e+007
1794.568;1.466731;-1.261967;1342.211;138.6954;9;9;0;4.619626;4.516097;1231807;1.451027e+008
1808.568;1.699927;-1.690615;2166.812;223.9043;9;9;0;5.354102;5.215689;1988580;2.358924e+008
1822.568;1.933285;-2.16699;3019.297;311.9947;9;9;0;6.089085;5.910898;2770944;3.309923e+008
1836.568;2.166588;-2.622532;3945.478;407.7002;9;9;0;6.823899;6.601149;3620941;4.355213e+008
1850.224;2.394266;-3.02705;4964.95;513.0458;9;9;0;7.540996;7.270195;4556556;5.517346e+008
1856.478;2.401766;-3.07541;4514.882;466.5388;9;9;0;7.564619;7.292158;4143509;5.018307e+008
1863.56;2.283856;-2.897174;3462.652;357.808;9;9;0;7.193246;6.946306;3177830;3.835461e+008
1874.43;2.10257;-2.578123;2411.603;249.1994;9;9;0;6.622268;6.412219;2213235;2.657021e+008
1888.43;1.869267;-2.108977;1520.42;157.1103;9;9;0;5.887454;5.720659;1395357;1.663601e+008
1902.43;1.635963;-1.608305;888.0849;91.76895;9;9;0;5.15264;5.024282;815035.1;9.649748e+007
1916.43;1.402553;-1.173258;426.3107;44.0522;9;9;0;4.417489;4.322699;391244.4;4.59982e+007
1930.43;1.169356;-0.929164;111.994;11.57274;9;9;0;3.683012;3.61681;102781.9;1.199896e+007
1944.43;0.936053;-0.9246273;110.9697;11.46689;9;9;0;2.948198;2.905575;101841.9;1.180496e+007
1956.592;0.9667494;-0.9234767;111.4366;11.51514;10;10;0;3.04488;2.999444;102270.3;1.186576e+007
1970.592;1.199946;-0.9534973;296.1443;30.60163;10;10;0;3.779356;3.709689;271784.8;3.175818e+007
1984.592;1.433303;-1.221406;1171.508;121.0561;10;10;0;4.514339;4.415409;1075145;1.26521e+008
1998.592;1.66666;-1.630448;1984.877;205.1044;10;10;0;5.249322;5.116184;1821610;2.15871e+008
2012.592;1.899802;-2.103745;2821.212;291.5258;10;10;0;5.98363;5.811446;2589152;3.089696e+008
2026.592;2.133267;-2.561052;3713.119;383.6898;10;10;0;6.71895;6.502855;3407695;4.094697e+008
2040.452;2.36432;-2.972861;4730.25;488.7935;10;10;0;7.446677;7.182451;4341162;5.251923e+008
2047.788;2.413713;-3.096629;4574.548;472.7043;10;10;0;7.602244;7.327132;4198267;5.086404e+008
2054.456;2.302606;-2.930582;3522.877;364.0313;10;10;0;7.252302;7.001383;3233101;3.90432e+008
2064.966;2.127266;-2.628598;2471.08;255.3455;10;10;0;6.700052;6.485146;2267821;2.724538e+008
2078.94;1.894552;-2.169744;1560.771;161.28;10;10;0;5.967094;5.795843;1432389;1.709038e+008
2092.94;1.661142;-1.666755;910.7013;94.10599;10;10;0;5.231943;5.099671;835791.2;9.902956e+007
2106.94;1.427838;-1.220313;439.8885;45.45524;10;10;0;4.497128;4.398941;403705.3;4.749942e+007
2120.94;1.194374;-0.9526411;113.5895;11.7376;10;10;0;3.761808;3.692778;104246.1;1.217915e+007
2134.94;0.9610172;-0.9462806;111.2105;11.49177;10;10;0;3.026826;2.981921;102062.8;1.183961e+007
2147.614;0.9498744;-0.9445164;111.416;11.51301;11;11;0;2.99173;2.947851;102251.4;1.185745e+007
2161.614;1.183285;-0.9565015;191.6066;19.79939;11;11;0;3.726882;3.659112;175845.9;2.053729e+007
2175.614;1.416642;-1.205273;1057.827;109.3091;11;11;0;4.461864;4.365188;970815.4;1.141863e+008
2189.614;1.650053;-1.608559;1867.367;192.9616;11;11;0;5.197016;5.066475;1713766;2.029899e+008
2203.614;1.883195;-2.081324;2693.993;278.3798;11;11;0;5.931324;5.762081;2472397;2.948914e+008
2217.614;2.116606;-2.541418;3574.044;369.3186;11;11;0;6.666474;6.453672;3280060;3.939392e+008
2231.55;2.348731;-2.954204;4592.09;474.5169;11;11;0;7.397577;7.136743;4214366;5.096197e+008
2239.462;2.419338;-3.104183;4618.485;477.2444;11;11;0;7.619961;7.343596;4238590;5.136102e+008
2245.844;2.313266;-2.946571;3566.832;368.5733;11;11;0;7.285878;7.032684;3273441;3.954272e+008
2256.04;2.143124;-2.660166;2515.411;259.9263;11;11;0;6.749996;6.531942;2308505;2.774713e+008
2269.97;1.911052;-2.211039;1591.323;164.4371;11;11;0;6.019063;5.844873;1460428;1.743346e+008
2283.97;1.677642;-1.708873;932.2634;96.33408;11;11;0;5.283911;5.149043;855579.7;1.014243e+008
2297.97;1.444392;-1.257118;452.8536;46.79496;11;11;0;4.549265;4.448822;415603.9;4.892379e+007
2311.97;1.211142;-0.9725797;118.1378;12.20759;11;11;0;3.814621;3.743663;108420.3;1.267327e+007
2325.97;0.9777315;-0.9629603;111.5015;11.52185;11;11;0;3.079469;3.033005;102329.9;1.187666e+007
2338.636;0.9333208;-0.9608547;111.382;11.5095;12;12;0;2.939593;2.897216;102220.3;1.184783e+007
2352.636;1.166624;-0.9618911;115.8795;11.97424;12;12;0;3.674407;3.60851;106347.8;1.241422e+007
2366.636;1.399767;-1.19274;961.1324;99.31721;12;12;0;4.408715;4.314296;882074.1;1.036958e+008
2380.636;1.633231;-1.584301;1768.298;182.7245;12;12;0;5.144035;5.016099;1622846;1.921239e+008
2394.636;1.866642;-2.056802;2588.144;267.4421;12;12;0;5.879187;5.712851;2375255;2.831655e+008
2408.636;2.099999;-2.519049;3460.059;357.5401;12;12;0;6.614169;6.404623;3175450;3.811884e+008
2422.606;2.33282;-2.93236;4466.781;461.5683;12;12;0;7.347464;7.090072;4099364;4.954819e+008
2431.154;2.42507;-3.087124;4633.242;478.7693;12;12;0;7.638016;7.36037;4252133;5.153378e+008
2437.282;2.322909;-2.937285;3580.332;369.9683;12;12;0;7.31625;7.060989;3285830;3.970361e+008
2447.23;2.156999;-2.662534;2528.604;261.2896;12;12;0;6.793696;6.572871;2320613;2.790409e+008
2461.124;1.92557;-2.223103;1600.38;165.3729;12;12;0;6.064788;5.887993;1468740;1.754024e+008
2475.124;1.692106;-1.725382;943.9509;97.54179;12;12;0;5.329468;5.192304;866305.9;1.027403e+008
2489.124;1.458803;-1.276937;460.8679;47.62311;12;12;0;4.594654;4.492225;422959;4.981123e+007
2503.124;1.225338;-0.9871858;121.6692;12.57251;12;12;0;3.859334;3.786724;111661.2;1.305772e+007
2517.124;0.9920886;-0.9760514;111.3247;11.50357;12;12;0;3.124689;3.076864;102167.6;1.186302e+007
2529.656;0.9166601;-0.9732907;111.4963;11.52131;13;13;0;2.887119;2.846226;102325.1;1.185394e+007
2543.656;1.150071;-0.9729957;112.8074;11.65679;13;13;0;3.62227;3.558208;103528.4;1.207903e+007
2557.656;1.383213;-1.173622;867.097;89.6002;13;13;0;4.356577;4.264348;795773.6;9.350371e+007
2571.656;1.616678;-1.548837;1669.347;172.4996;13;13;0;5.091898;4.9665;1532034;1.812831e+008
2585.656;1.849927;-2.012808;2481.252;256.3966;13;13;0;5.826543;5.663118;2277156;2.713356e+008
2599.656;2.083177;-2.471886;3337.827;344.9095;13;13;0;6.561188;6.354917;3063273;3.675396e+008
2613.656;2.316588;-2.878982;4327.964;447.2238;13;13;0;7.29634;7.042435;3971966;4.798548e+008
2622.844;2.430427;-3.088379;4602.213;475.563;13;13;0;7.654888;7.376044;4223657;5.119668e+008
2628.85;2.330356;-2.941045;3549.709;366.804;13;13;0;7.339703;7.082841;3257726;3.937263e+008
2638.808;2.164284;-2.668108;2497.981;258.1252;13;13;0;6.816643;6.594356;2292508;2.757207e+008
2652.688;1.932963;-2.234279;1569.771;162.21;13;13;0;6.088073;5.909944;1440649;1.720855e+008
2666.688;1.699767;-1.740325;920.4983;95.11835;13;13;0;5.353596;5.215209;844782.3;1.002106e+008
2680.688;1.466463;-1.288473;444.5741;45.93941;13;13;0;4.618782;4.515291;408005.5;4.806126e+007
2694.688;1.233053;-0.9989607;122.1373;12.62088;13;13;0;3.883631;3.810115;112090.8;1.311102e+007
2708.688;0.9997493;-0.9869932;111.5852;11.53049;13;13;0;3.148817;3.100258;102406.7;1.189357e+007
2721.676;0.9166601;-0.984363;111.78;11.55062;14;14;0;2.887119;2.846226;102585.5;1.188411e+007
2735.676;1.150071;-0.986028;112.8663;11.66287;14;14;0;3.62227;3.558208;103582.4;1.208533e+007
2749.676;1.383213;-1.177396;831.0493;85.87526;14;14;0;4.356577;4.264348;762691;8.961649e+007
2763.676;1.616624;-1.549741;1620.168;167.4177;14;14;0;5.091729;4.96634;1486901;1.759422e+008
2777.676;1.849927;-2.016732;2420.279;250.096;14;14;0;5.826543;5.663118;2221198;2.646679e+008
2791.676;2.083177;-2.472474;3264.101;337.2911;14;14;0;6.561188;6.354917;2995611;3.594214e+008
2805.676;2.316588;-2.877297;4236.277;437.7495;14;14;0;7.29634;7.042435;3887821;4.696892e+008
2814.892;2.429945;-3.064339;4512.737;466.3171;14;14;0;7.65337;7.374634;4141540;5.020061e+008
2820.994;2.328266;-2.912045;3460.545;357.5903;14;14;0;7.333123;7.076711;3175896;3.838129e+008
2831.188;2.158392;-2.632169;2409.352;248.9669;14;14;0;6.798084;6.57698;2211170;2.658919e+008
2845.132;1.926052;-2.197708;1494.139;154.3947;14;14;0;6.066307;5.889425;1371238;1.637608e+008
2859.132;1.692695;-1.709754;874.284;90.34286;14;14;0;5.331324;5.194066;802369.4;9.515933e+007
2873.132;1.459338;-1.269688;422.714;43.68053;14;14;0;4.596341;4.493839;387943.5;4.568824e+007
2887.132;1.225874;-1.004094;113.608;11.73952;14;14;0;3.861021;3.788348;104263.1;1.219278e+007
2901.132;0.9926243;-0.9986903;111.4927;11.52094;14;14;0;3.126376;3.0785;102321.8;1.188112e+007
2913.696;0.9166601;-0.9958674;111.8455;11.55739;15;15;0;2.887119;2.846226;102645.6;1.189107e+007
2927.696;1.150071;-0.9958474;113.0337;11.68017;15;15;0;3.62227;3.558208;103736;1.210326e+007
2941.696;1.383267;-1.180489;803.4653;83.02491;15;15;0;4.356746;4.26451;737375.9;8.664209e+007
2955.696;1.616678;-1.551776;1577.863;163.0462;15;15;0;5.091898;4.9665;1448076;1.713484e+008
2969.696;1.849927;-2.018601;2363.968;244.2772;15;15;0;5.826543;5.663118;2169519;2.585101e+008
2983.696;2.083177;-2.46954;3186.894;329.3131;15;15;0;6.561188;6.354917;2924755;3.509199e+008
2997.696;2.316588;-2.853205;4139.223;427.7206;15;15;0;7.29634;7.042435;3798750;4.589285e+008
3006.912;2.429891;-3.042233;4463.726;461.2526;15;15;0;7.653202;7.374478;4096561;4.965532e+008
3013.04;2.327731;-2.89145;3411.624;352.5352;15;15;0;7.331435;7.075138;3131000;3.783811e+008
3023.33;2.156409;-2.610345;2360.08;243.8754;15;15;0;6.79184;6.571133;2165951;2.60439e+008
3037.306;1.923374;-2.175801;1460.013;150.8683;15;15;0;6.05787;5.88147;1339919;1.600077e+008
3051.306;1.690178;-1.694109;851.1014;87.94732;15;15;0;5.323394;5.186537;781093.7;9.26291e+007
3065.306;1.456767;-1.265208;407.4778;42.10613;15;15;0;4.588242;4.486095;373960.6;4.403806e+007
3079.306;1.223463;-1.007236;112.6142;11.63682;15;15;0;3.853428;3.781038;103351;1.208524e+007
3093.306;0.9900529;-1.002834;111.5523;11.5271;15;15;0;3.118277;3.070646;102376.6;1.188655e+007
3105.716;0.9166601;-0.9996309;111.9387;11.56702;16;16;0;2.887119;2.846226;102731.2;1.190098e+007
3119.716;1.150071;-1.000888;112.9804;11.67466;16;16;0;3.62227;3.558208;103687.1;1.209755e+007
3133.716;1.383267;-1.179943;776.9526;80.28526;16;16;0;4.356746;4.26451;713044;8.378309e+007
3147.716;1.616624;-1.550598;1540.508;159.1861;16;16;0;5.091729;4.96634;1413793;1.672914e+008
3161.716;1.849927;-2.016268;2315.655;239.2848;16;16;0;5.826543;5.663118;2125180;2.532268e+008
3175.716;2.083177;-2.456509;3128.947;323.3252;16;16;0;6.561188;6.354917;2871574;3.445391e+008
3189.716;2.316534;-2.843683;4085.483;422.1674;16;16;0;7.296171;7.042278;3749430;4.529695e+008
3198.93;2.429945;-3.032491;4429.239;457.6889;16;16;0;7.65337;7.374634;4064910;4.927175e+008
3205.086;2.327302;-2.882486;3376.741;348.9306;16;16;0;7.330085;7.073881;3098986;3.745075e+008
3215.452;2.154588;-2.59838;2325.162;240.2672;16;16;0;6.786103;6.565761;2133905;2.56572e+008
3229.44;1.921499;-2.167326;1432.662;148.042;16;16;0;6.051965;5.875902;1314818;1.570015e+008
3243.44;1.688088;-1.687701;825.7329;85.3259;16;16;0;5.316813;5.180289;757811.9;8.986252e+007
3257.44;1.454892;-1.263142;385.2499;39.80924;16;16;0;4.582337;4.480449;353561;4.163343e+007
3271.44;1.221588;-1.013036;112.2319;11.59731;16;16;0;3.847523;3.775351;103000.2;1.204352e+007
3285.44;0.9882315;-1.009469;111.8522;11.55808;16;16;0;3.11254;3.065083;102651.8;1.191783e+007
3297.736;0.9166601;-1.005738;111.9798;11.57127;17;17;0;2.887119;2.846226;102768.9;1.190535e+007
3311.736;1.150071;-1.006689;113.1987;11.69722;17;17;0;3.62227;3.558208;103887.5;1.212092e+007
3325.736;1.383267;-1.181503;742.5588;76.73123;17;17;0;4.356746;4.26451;681479.4;8.007422e+007
3339.736;1.616624;-1.553579;1505.619;155.5809;17;17;0;5.091729;4.96634;1381774;1.635027e+008
3353.736;1.849927;-2.018301;2276.19;235.2068;17;17;0;5.826543;5.663118;2088961;2.489112e+008
3367.736;2.083177;-2.454683;3088.877;319.1846;17;17;0;6.561188;6.354917;2834801;3.401269e+008
3381.736;2.316534;-2.839812;4042.781;417.7549;17;17;0;7.296171;7.042278;3710241;4.48235e+008
3390.964;2.429784;-3.022655;4353.978;449.912;17;17;0;7.652863;7.374163;3995840;4.843432e+008
3397.194;2.32607;-2.86983;3301.687;341.175;17;17;0;7.326205;7.070265;3030105;3.661701e+008
3407.678;2.15132;-2.581765;2250.542;232.5565;17;17;0;6.775811;6.556123;2065423;2.483141e+008
3421.678;1.917963;-2.140989;1379.347;142.5328;17;17;0;6.040829;5.865401;1265888;1.51143e+008
3435.678;1.684552;-1.668146;788.0142;81.42829;17;17;0;5.305677;5.169714;723195.8;8.574862e+007
3449.678;1.451303;-1.251767;369.3546;38.16671;17;17;0;4.571032;4.469639;338973.2;3.991133e+007
3463.678;1.217946;-1.018236;112.4444;11.61928;17;17;0;3.836049;3.764302;103195.3;1.2065e+007
3477.678;0.9845886;-1.016112;111.8897;11.56196;17;17;0;3.101067;3.053955;102686.2;1.192051e+007
3489.76;0.9166601;-1.011466;112.0873;11.58238;18;18;0;2.887119;2.846226;102867.5;1.191678e+007
3503.76;1.150071;-1.011683;113.1113;11.6882;18;18;0;3.62227;3.558208;103807.3;1.211157e+007
3517.76;1.383267;-1.180697;710.8262;73.45219;18;18;0;4.356746;4.26451;652356.9;7.665231e+007
3531.76;1.616678;-1.548379;1466.804;151.57;18;18;0;5.091898;4.9665;1346151;1.592878e+008
3545.76;1.849927;-2.009573;2223.876;229.801;18;18;0;5.826543;5.663118;2040950;2.431904e+008
3559.76;2.083177;-2.441963;3021.611;312.2337;18;18;0;6.561188;6.354917;2773067;3.3272e+008
3573.76;2.316534;-2.823732;3972.334;410.4753;18;18;0;7.296171;7.042278;3645588;4.404243e+008
3582.984;2.429838;-3.006789;4337.896;448.2502;18;18;0;7.653033;7.374321;3981081;4.825549e+008
3589.17;2.326766;-2.856309;3286.135;339.5679;18;18;0;7.328398;7.072309;3015833;3.644528e+008
3599.594;2.153034;-2.571684;2234.75;230.9246;18;18;0;6.78121;6.561179;2050930;2.465841e+008
3613.58;1.919838;-2.13461;1366.617;141.2174;18;18;0;6.046734;5.87097;1254206;1.497564e+008
3627.58;1.686695;-1.665768;782.1541;80.82275;18;18;0;5.312426;5.176123;717817.6;8.51164e+007
3641.58;1.453285;-1.250914;365.3296;37.7508;18;18;0;4.577275;4.475609;335279.2;3.947875e+007
3655.58;1.220035;-1.017561;112.6797;11.6436;18;18;0;3.84263;3.770639;103411.2;1.209102e+007
3669.58;0.9867315;-1.01418;111.9303;11.56615;18;18;0;3.107816;3.060501;102723.4;1.19256e+007
3681.784;0.9166601;-1.010929;112.3027;11.60463;19;19;0;2.887119;2.846226;103065.2;1.193967e+007
3695.784;1.150017;-1.011721;113.3934;11.71735;19;19;0;3.622101;3.558045;104066.2;1.214176e+007
3709.784;1.383267;-1.178639;690.6157;71.36377;19;19;0;4.356746;4.26451;633808.9;7.447291e+007
3723.784;1.616678;-1.547115;1441.932;149;19;19;0;5.091898;4.9665;1323326;1.565869e+008
3737.784;1.849927;-2.003947;2191.534;226.4589;19;19;0;5.826543;5.663118;2011268;2.396537e+008
3751.784;2.083177;-2.436472;2983.13;308.2574;19;19;0;6.561188;6.354917;2737752;3.284828e+008
3765.784;2.316534;-2.815703;3937.626;406.8889;19;19;0;7.296171;7.042278;3613735;4.365762e+008
3774.716;2.435034;-3.006773;4389.929;453.6269;19;19;0;7.669399;7.389522;4028833;4.884173e+008
3780.652;2.335927;-2.862453;3336.985;344.8224;19;19;0;7.35725;7.099188;3062500;3.701919e+008
3790.63;2.169642;-2.592249;2285.99;236.2194;19;19;0;6.833517;6.610152;2097955;2.523615e+008
3804.57;1.937249;-2.160496;1401.963;144.8698;19;19;0;6.101571;5.922667;1286644;1.537092e+008
3818.57;1.703892;-1.691881;808.2859;83.52304;19;19;0;5.366588;5.22754;741800;8.800538e+007
3832.57;1.470428;-1.27368;388.7239;40.16822;19;19;0;4.631268;4.527225;356749.3;4.202852e+007
3846.57;1.237231;-1.018151;112.5313;11.62825;19;19;0;3.896792;3.822783;103275;1.208138e+007
3860.57;1.003821;-1.015028;112.1098;11.5847;19;19;0;3.16164;3.11269;102888.2;1.195097e+007
3872.808;0.8998387;-1.007887;101.0511;10.44197;20;20;0;2.834138;2.794719;92739.09;1.073791e+007
3886.808;1.133249;-1.011383;113.2415;11.70164;20;20;0;3.569289;3.507066;103926.8;1.211931e+007
3900.808;1.366606;-1.156817;615.2212;63.57299;20;20;0;4.304272;4.214213;564616;6.630934e+007
3914.808;1.60007;-1.51776;1363.673;140.9131;20;20;0;5.039592;4.916716;1251503;1.480146e+008
3928.808;1.833374;-1.968815;2107.905;217.8173;20;20;0;5.774406;5.613839;1934519;2.30395e+008
3942.808;2.06657;-2.401538;2888.985;298.5291;20;20;0;6.508883;6.30582;2651351;3.1796e+008
3956.808;2.299981;-2.783173;3839.252;396.7235;20;20;0;7.244034;6.993674;3523453;4.254623e+008
3966.74;2.434981;-3.001639;4355.81;450.1012;20;20;0;7.66923;7.389366;3997521;4.846205e+008
3972.702;2.335445;-2.856143;3302.739;341.2837;20;20;0;7.355732;7.097773;3031071;3.663876e+008
3982.73;2.168249;-2.587184;2251.079;232.6119;20;20;0;6.82913;6.606045;2065915;2.484973e+008
3996.716;1.935267;-2.150819;1373.214;141.8991;20;20;0;6.095328;5.916782;1260260;1.505483e+008
4010.716;1.70191;-1.677364;786.0343;81.22371;20;20;0;5.360345;5.221615;721378.8;8.557758e+007
4024.716;1.468553;-1.253524;370.8771;38.32405;20;20;0;4.625362;4.521581;340370.5;4.009667e+007
4038.716;1.235142;-0.9950165;112.8115;11.65721;20;20;0;3.890211;3.81645;103532.1;1.21107e+007
4052.716;1.001732;-0.9931232;112.27;11.60126;20;20;0;3.15506;3.106311;103035.2;1.196729e+007
4064.832;0.8998387;-0.9850803;100.8981;10.42616;21;21;0;2.834138;2.794719;92598.7;1.072165e+007
4078.832;1.133249;-0.9883238;113.346;11.71245;21;21;0;3.569289;3.507066;104022.7;1.21305e+007
4092.832;1.366606;-1.134778;581.9592;60.13591;21;21;0;4.304272;4.214213;534089.9;6.272432e+007
4106.832;1.600017;-1.506701;1336.431;138.0981;21;21;0;5.039423;4.916555;1226502;1.450575e+008
4120.832;1.833374;-1.960282;2074.915;214.4083;21;21;0;5.774406;5.613839;1904242;2.267892e+008
4134.832;2.06657;-2.398271;2849.709;294.4706;21;21;0;6.508883;6.30582;2615306;3.136373e+008
4148.832;2.299981;-2.780654;3803.965;393.0772;21;21;0;7.244034;6.993674;3491069;4.215518e+008
4158.468;2.440016;-3.005863;4404.728;455.1561;21;21;0;7.685091;7.404095;4042415;4.901353e+008
4164.196;2.344338;-2.868651;3351.815;346.3549;21;21;0;7.383741;7.12386;3076111;3.719289e+008
4173.96;2.181588;-2.608564;2300.131;237.6807;21;21;0;6.871142;6.645365;2110933;2.540121e+008
4187.872;1.94957;-2.179099;1410.738;145.7765;21;21;0;6.140378;5.959236;1294697;1.547278e+008
4201.872;1.716267;-1.708892;812.2807;83.93584;21;21;0;5.405565;5.264525;745466.3;8.847305e+007
4215.872;1.482963;-1.282759;382.6157;39.53704;21;21;0;4.670751;4.564953;351143.5;4.138372e+007
4229.872;1.249553;-1.002531;112.8051;11.65655;21;21;0;3.935599;3.860128;103526.2;1.21153e+007
4243.872;1.01641;-0.998714;112.3603;11.61058;21;21;0;3.201292;3.151118;103118;1.198227e+007
4256.857;0.8998387;-0.9888516;100.6776;10.40337;22;22;0;2.834138;2.794719;92396.33;1.069822e+007
4270.857;1.133249;-0.9928831;113.1833;11.69563;22;22;0;3.569289;3.507066;103873.4;1.211308e+007
4284.857;1.366606;-1.13904;562.3782;58.11253;22;22;0;4.304272;4.214213;516119.6;6.061385e+007
4298.857;1.60007;-1.511202;1316.848;136.0745;22;22;0;5.039592;4.916716;1208530;1.429321e+008
4312.857;1.833374;-1.964358;2051.258;211.9637;22;22;0;5.774406;5.613839;1882531;2.242034e+008
4326.857;2.06657;-2.396417;2823.84;291.7974;22;22;0;6.508883;6.30582;2591564;3.107902e+008
4340.857;2.299981;-2.778338;3778.938;390.4911;22;22;0;7.244034;6.993674;3468100;4.187784e+008
4350.489;2.440016;-3.00309;4383.989;453.0131;22;22;0;7.685091;7.404095;4023383;4.878276e+008
4356.239;2.343963;-2.865153;3331.04;344.2082;22;22;0;7.38256;7.12276;3057044;3.696196e+008
4366.042;2.18057;-2.603891;2279.475;235.5462;22;22;0;6.867937;6.642365;2091976;2.517234e+008
4379.954;1.948659;-2.174837;1395.929;144.2462;22;22;0;6.13751;5.956533;1281106;1.530994e+008
4393.954;1.715142;-1.705982;801.2209;82.79299;22;22;0;5.402021;5.261163;735316.1;8.726548e+007
4407.954;1.481946;-1.282354;376.5845;38.91381;22;22;0;4.667545;4.56189;345608.4;4.073013e+007
4421.954;1.248588;-1.006981;112.8486;11.66104;22;22;0;3.932562;3.857206;103566.2;1.211962e+007
4435.954;1.015231;-1.00425;112.2623;11.60046;22;22;0;3.197579;3.147521;103028.1;1.19714e+007
4448.876;0.8998387;-0.9951157;100.7691;10.41283;23;23;0;2.834138;2.794719;92480.34;1.070795e+007
4462.876;1.133196;-0.9983317;113.2651;11.70409;23;23;0;3.56912;3.506903;103948.5;1.212182e+007
4476.876;1.366606;-1.139683;551.0614;56.94313;23;23;0;4.304272;4.214213;505733.6;5.939411e+007
4490.876;1.600017;-1.512255;1301.433;134.4817;23;23;0;5.039423;4.916555;1194383;1.412588e+008
4504.876;1.833374;-1.964134;2032.088;209.9829;23;23;0;5.774406;5.613839;1864938;2.221081e+008
4518.876;2.06657;-2.39389;2798.177;289.1456;23;23;0;6.508883;6.30582;2568012;3.079657e+008
4532.876;2.299981;-2.772746;3757.868;388.3138;23;23;0;7.244034;6.993674;3448763;4.164434e+008
4542.511;2.439963;-2.996863;4368.98;451.4622;23;23;0;7.684922;7.403939;4009608;4.861567e+008
4548.253;2.34407;-2.858154;3316.939;342.7511;23;23;0;7.382898;7.123075;3044103;3.68056e+008
4558.049;2.180784;-2.599946;2265.534;234.1056;23;23;0;6.868612;6.642997;2079182;2.501854e+008
4571.972;1.948659;-2.170223;1384.904;143.107;23;23;0;6.13751;5.956533;1270988;1.518902e+008
4585.972;1.715195;-1.704243;794.8558;82.13526;23;23;0;5.40219;5.261323;729474.6;8.657236e+007
4599.972;1.481946;-1.28485;372.4644;38.48807;23;23;0;4.667545;4.56189;341827.2;4.028452e+007
4613.972;1.248642;-1.012803;113.1786;11.69514;23;23;0;3.932731;3.857369;103869;1.215508e+007
4627.972;1.015285;-1.008446;112.5308;11.6282;23;23;0;3.197748;3.147685;103274.5;1.200004e+007
4640.896;0.8998387;-0.9999216;101.006;10.43731;24;24;0;2.834138;2.794719;92697.75;1.073312e+007
4654.896;1.133196;-1.003055;113.2427;11.70177;24;24;0;3.56912;3.506903;103927.9;1.211942e+007
4668.896;1.366606;-1.140305;540.805;55.8833;24;24;0;4.304272;4.214213;496320.9;5.828867e+007
4682.896;1.60007;-1.513415;1286.324;132.9204;24;24;0;5.039592;4.916716;1180517;1.39619e+008
4696.896;1.833374;-1.964058;2012.556;207.9645;24;24;0;5.774406;5.613839;1847012;2.199732e+008
4710.896;2.06657;-2.391517;2778.813;287.1446;24;24;0;6.508883;6.30582;2550241;3.058345e+008
4724.896;2.299981;-2.770132;3737.98;386.2587;24;24;0;7.244034;6.993674;3430511;4.142394e+008
4734.531;2.439963;-2.993136;4356.498;450.1723;24;24;0;7.684922;7.403939;3998152;4.847677e+008
4740.29;2.343802;-2.854086;3303.619;341.3747;24;24;0;7.382054;7.122288;3031879;3.665751e+008
4750.107;2.180195;-2.595428;2251.801;232.6865;24;24;0;6.866756;6.64126;2066578;2.486646e+008
4764.038;1.947909;-2.165114;1374.473;142.0292;24;24;0;6.135148;5.954308;1261415;1.507429e+008
4778.038;1.714499;-1.702868;786.964;81.31978;24;24;0;5.399997;5.259242;722232;8.571105e+007
4792.038;1.481088;-1.283958;367.5404;37.97926;24;24;0;4.664845;4.559311;337308.3;3.975093e+007
4806.038;1.247892;-1.015757;113.2108;11.69847;24;24;0;3.930369;3.855096;103898.6;1.215826e+007
4820.038;1.014481;-1.014007;112.6514;11.64067;24;24;0;3.195217;3.145232;103385.2;1.201261e+007
4832.916;0.8998387;-1.005596;100.9518;10.43171;25;25;0;2.834138;2.794719;92647.96;1.072736e+007
4846.916;1.133196;-1.00827;113.6023;11.73892;25;25;0;3.56912;3.506903;104257.9;1.21579e+007
4860.916;1.366606;-1.142414;530.5111;54.81959;25;25;0;4.304272;4.214213;486873.7;5.717917e+007
4874.916;1.60007;-1.515612;1273.556;131.601;25;25;0;5.039592;4.916716;1168799;1.382332e+008
4888.916;1.833374;-1.963231;1996.709;206.327;25;25;0;5.774406;5.613839;1832469;2.182412e+008
4902.916;2.06657;-2.389621;2760.975;285.3013;25;25;0;6.508883;6.30582;2533870;3.038712e+008
4916.916;2.299981;-2.767483;3721.576;384.5636;25;25;0;7.244034;6.993674;3415456;4.124215e+008
4926.552;2.439909;-2.990021;4340.808;448.5511;25;25;0;7.684753;7.403782;3983753;4.830211e+008
4932.324;2.343534;-2.850919;3288.38;339.8;25;25;0;7.38121;7.121503;3017893;3.648813e+008
4942.162;2.179552;-2.59092;2236.777;231.134;25;25;0;6.864731;6.639365;2052790;2.470008e+008
4956.098;1.947213;-2.161304;1363.003;140.844;25;25;0;6.132955;5.952241;1250889;1.494819e+008
4970.098;1.71391;-1.699595;780.2046;80.6213;25;25;0;5.39814;5.257481;716028.6;8.497335e+007
4984.098;1.480445;-1.282438;362.6536;37.47428;25;25;0;4.66282;4.557376;332823.3;3.922164e+007
4998.098;1.247196;-1.020572;113.2431;11.70181;25;25;0;3.928175;3.852985;103928.3;1.216148e+007
5012.098;1.013839;-1.01691;112.5304;11.62816;25;25;0;3.193192;3.14327;103274.1;1.199947e+007
5024.936;0.8998387;-1.009642;101.06;10.44288;26;26;0;2.834138;2.794719;92747.23;1.073885e+007
5038.936;1.133249;-1.013034;113.4045;11.71848;26;26;0;3.569289;3.507066;104076.3;1.213675e+007
5052.936;1.366606;-1.143653;520.9899;53.83573;26;26;0;4.304272;4.214213;478135.7;5.615296e+007
5066.936;1.600017;-1.516411;1262.63;130.472;26;26;0;5.039423;4.916555;1158772;1.37047e+008
5080.936;1.833374;-1.961855;1983.01;204.9114;26;26;0;5.774406;5.613839;1819897;2.167438e+008
5094.936;2.06657;-2.38802;2743.61;283.507;26;26;0;6.508883;6.30582;2517933;3.019601e+008
5108.936;2.299981;-2.764842;3705.869;382.9405;26;26;0;7.244034;6.993674;3401041;4.106809e+008
5118.573;2.439909;-2.987671;4326.439;447.0663;26;26;0;7.684753;7.403782;3970566;4.814222e+008
5124.361;2.343266;-2.849568;3274.178;338.3324;26;26;0;7.380366;7.120717;3004860;3.633026e+008
5134.215;2.178963;-2.588378;2222.733;229.6828;26;26;0;6.862875;6.637629;2039901;2.454457e+008
5148.166;1.946463;-2.159777;1352.46;139.7545;26;26;0;6.130592;5.950015;1241213;1.483223e+008
5162.166;1.71316;-1.697986;773.6711;79.94617;26;26;0;5.395779;5.25524;710032.4;8.425989e+007
5176.166;1.479749;-1.283005;358.542;37.04942;26;26;0;4.660627;4.55528;329050;3.877615e+007
5190.166;1.246339;-1.023719;113.2456;11.70207;26;26;0;3.925476;3.850388;103930.6;1.216144e+007
5204.166;1.013089;-1.021492;112.6045;11.63582;26;26;0;3.19083;3.140981;103342.1;1.20071e+007
5216.956;0.8998387;-1.013298;101.1562;10.45283;27;27;0;2.834138;2.794719;92835.55;1.074907e+007
5230.956;1.133249;-1.017379;113.7073;11.74978;27;27;0;3.569289;3.507066;104354.3;1.216917e+007
5244.956;1.366606;-1.144602;513.0148;53.01164;27;27;0;4.304272;4.214213;470816.6;5.52934e+007
5258.956;1.600017;-1.518766;1251.844;129.3575;27;27;0;5.039423;4.916555;1148873;1.358763e+008
5272.956;1.833374;-1.963815;1969.103;203.4744;27;27;0;5.774406;5.613839;1807134;2.152238e+008
5286.956;2.06657;-2.388414;2728.428;281.9382;27;27;0;6.508883;6.30582;2504001;3.002892e+008
5300.956;2.299981;-2.764798;3690.436;381.3458;27;27;0;7.244034;6.993674;3386877;4.089706e+008
5310.594;2.439963;-2.987664;4311.558;445.5286;27;27;0;7.684922;7.403939;3956909;4.797671e+008
5316.401;2.342998;-2.847753;3258.816;336.745;27;27;0;7.379523;7.119931;2990761;3.615951e+008
5326.29;2.177999;-2.586131;2207.422;228.1008;27;27;0;6.859838;6.634787;2025850;2.437481e+008
5340.259;1.945392;-2.156803;1342.27;138.7015;27;27;0;6.127217;5.946835;1231861;1.472e+008
5354.259;1.712035;-1.696371;765.9497;79.14829;27;27;0;5.392235;5.251877;702946.1;8.341615e+007
5368.259;1.478624;-1.281676;354.3227;36.61341;27;27;0;4.657084;4.551895;325177.7;3.831853e+007
5382.259;1.245267;-1.028975;113.486;11.72691;27;27;0;3.922101;3.84714;104151.2;1.218685e+007
5396.259;1.011857;-1.027522;112.7931;11.65531;27;27;0;3.18695;3.13722;103515.2;1.202676e+007
5408.981;0.8998387;-1.018265;101.2265;10.46009;28;28;0;2.834138;2.794719;92900.09;1.075655e+007
5422.981;1.133249;-1.022469;113.9206;11.77182;28;28;0;3.569289;3.507066;104550;1.219199e+007
5436.981;1.366553;-1.14738;502.2973;51.90416;28;28;0;4.304103;4.214051;460980.6;5.413816e+007
5450.981;1.600017;-1.52024;1242.698;128.4124;28;28;0;5.039423;4.916555;1140480;1.348837e+008
5464.981;1.833374;-1.963045;1956.626;202.1851;28;28;0;5.774406;5.613839;1795683;2.138601e+008
5478.981;2.06657;-2.389017;2711.898;280.2301;28;28;0;6.508883;6.30582;2488830;2.984699e+008
5492.981;2.299981;-2.765867;3672.669;379.5099;28;28;0;7.244034;6.993674;3370573;4.070018e+008
5502.616;2.439909;-2.988353;4288.143;443.109;28;28;0;7.684753;7.403782;3935420;4.771608e+008
5508.45;2.342463;-2.847626;3235.973;334.3846;28;28;0;7.377836;7.11836;2969797;3.590549e+008
5518.441;2.175909;-2.583911;2184.115;225.6923;28;28;0;6.853258;6.628628;2004460;2.411596e+008
5532.423;1.94282;-2.153379;1324.873;136.9038;28;28;0;6.119119;5.939204;1215895;1.452811e+008
5546.423;1.70957;-1.692472;754.7217;77.98807;28;28;0;5.384473;5.244513;692641.8;8.218731e+007
5560.423;1.47632;-1.28082;347.5784;35.91651;28;28;0;4.649828;4.544962;318988.3;3.758657e+007
5574.423;1.24291;-1.038148;113.4036;11.7184;28;28;0;3.914677;3.839996;104075.6;1.217714e+007
5588.423;1.009553;-1.035621;112.8384;11.65999;28;28;0;3.179694;3.130188;103556.8;1.203074e+007
5601.001;0.8998387;-1.028171;101.3167;10.46942;29;29;0;2.834138;2.794719;92982.89;1.076613e+007
5615.001;1.133196;-1.032325;113.6586;11.74474;29;29;0;3.56912;3.506903;104309.5;1.216393e+007
5629.001;1.366606;-1.152443;493.3957;50.98433;29;29;0;4.304272;4.214213;452811.3;5.317883e+007
5643.001;1.600017;-1.522799;1227.862;126.8793;29;29;0;5.039423;4.916555;1126863;1.332733e+008
5657.001;1.833374;-1.965925;1937.645;200.2237;29;29;0;5.774406;5.613839;1778263;2.117855e+008
5671.001;2.06657;-2.39055;2693.651;278.3445;29;29;0;6.508883;6.30582;2472083;2.964616e+008
5685.001;2.299981;-2.766121;3653.561;377.5354;29;29;0;7.244034;6.993674;3353036;4.048842e+008
5694.64;2.439909;-2.986995;4268.81;441.1112;29;29;0;7.684753;7.403782;3917677;4.750095e+008
5700.492;2.342088;-2.845818;3216.351;332.3569;29;29;0;7.376654;7.11726;2951789;3.568737e+008
5710.545;2.174463;-2.578427;2164.556;223.6713;29;29;0;6.848702;6.624365;1986510;2.389898e+008
5724.536;1.941374;-2.14777;1313.11;135.6883;29;29;0;6.114563;5.934911;1205099;1.43985e+008
5738.536;1.707963;-1.68882;745.0759;76.99133;29;29;0;5.379412;5.23971;683789.4;8.113301e+007
5752.536;1.474713;-1.279543;340.2645;35.16073;29;29;0;4.644766;4.540125;312275.9;3.679387e+007
5766.536;1.241463;-1.036672;113.5422;11.73272;29;29;0;3.910121;3.835612;104202.8;1.219149e+007
5780.536;1.008053;-1.035382;112.9088;11.66726;29;29;0;3.17497;3.12561;103621.4;1.20377e+007
5793.025;0.8998387;-1.026629;101.106;10.44764;30;30;0;2.834138;2.794719;92789.52;1.074374e+007
5807.025;1.133249;-1.031305;114.0767;11.78795;30;30;0;3.569289;3.507066;104693.3;1.220869e+007
5821.025;1.366606;-1.151943;486.7832;50.30103;30;30;0;4.304272;4.214213;446742.7;5.246613e+007
5835.025;1.600017;-1.524137;1217.169;125.7744;30;30;0;5.039423;4.916555;1117051;1.321127e+008
5849.025;1.833374;-1.965463;1922.989;198.7092;30;30;0;5.774406;5.613839;1764813;2.101835e+008
5863.025;2.06657;-2.389157;2677.334;276.6584;30;30;0;6.508883;6.30582;2457109;2.946658e+008
5877.023;2.299981;-2.763988;3633.984;375.5124;30;30;0;7.244034;6.993674;3335069;4.027147e+008
5886.664;2.439909;-2.974401;4253.978;439.5786;30;30;0;7.684753;7.403782;3904065;4.733591e+008
5892.531;2.34182;-2.833111;3201.277;330.7993;30;30;0;7.375811;7.116475;2937955;3.551985e+008
5902.635;2.173499;-2.563797;2149.73;222.1392;30;30;0;6.845665;6.621522;1972903;2.373461e+008
5916.631;1.940088;-2.132173;1302.597;134.602;30;30;0;6.110514;5.931095;1195451;1.428268e+008
5930.631;1.706892;-1.673976;737.859;76.24559;30;30;0;5.376037;5.236507;677166.1;8.034458e+007
5944.631;1.473481;-1.268666;336.4269;34.76419;30;30;0;4.640885;4.536416;308754;3.637755e+007
5958.631;1.240231;-1.041096;113.315;11.70924;30;30;0;3.90624;3.831877;103994.2;1.216663e+007
5972.631;1.006981;-1.03944;112.9505;11.67158;30;30;0;3.171595;3.122339;103659.7;1.204175e+007
5985.049;0.8997852;-1.031317;101.3537;10.47323;31;31;0;2.833969;2.794555;93016.79;1.077004e+007
5999.049;1.133249;-1.03461;113.7607;11.7553;31;31;0;3.569289;3.507066;104403.3;1.217488e+007
6013.049;1.366606;-1.149988;475.7135;49.15716;31;31;0;4.304272;4.214213;436583.5;5.127302e+007
6027.049;1.600017;-1.519144;1206.017;124.622;31;31;0;5.039423;4.916555;1106816;1.309022e+008
6041.049;1.833374;-1.953444;1909.007;197.2645;31;31;0;5.774406;5.613839;1751981;2.086553e+008
6055.049;2.06657;-2.365768;2664.266;275.308;31;31;0;6.508883;6.30582;2445116;2.932275e+008
6069.049;2.299981;-2.725683;3619.462;374.0118;31;31;0;7.244034;6.993674;3321742;4.011053e+008
6078.689;2.439909;-2.935953;4234.252;437.5403;31;31;0;7.684753;7.403782;3885962;4.711642e+008
6084.576;2.341445;-2.791532;3181.278;328.7327;31;31;0;7.374629;7.115375;2919601;3.529755e+008
6094.764;2.171784;-2.518601;2129.727;220.0723;31;31;0;6.840265;6.616468;1954546;2.351258e+008
6108.764;1.938427;-2.092735;1288.502;133.1455;31;31;0;6.105283;5.926165;1182516;1.412744e+008
6122.764;1.70491;-1.643488;727.052;75.12885;31;31;0;5.369794;5.230583;667248;7.916312e+007
6136.764;1.471713;-1.245419;329.447;34.04293;31;31;0;4.635318;4.531095;302348.2;3.562092e+007
6150.764;1.238356;-1.037137;113.5334;11.73181;31;31;0;3.900335;3.826194;104194.6;1.218939e+007
6164.764;1.004999;-1.034039;113.0738;11.68431;31;31;0;3.165352;3.116288;103772.8;1.205416e+007
6177.073;0.8998387;-1.02662;101.5115;10.48954;32;32;0;2.834138;2.794719;93161.66;1.078683e+007
6191.073;1.133249;-1.031537;113.9424;11.77407;32;32;0;3.569289;3.507066;104570;1.219432e+007
6205.073;1.366606;-1.145974;465.3589;48.08718;32;32;0;4.304272;4.214213;427080.6;5.015698e+007
6219.073;1.60007;-1.509839;1194.146;123.3954;32;32;0;5.039592;4.916716;1095922;1.29614e+008
6233.073;1.833374;-1.937736;1893.995;195.7132;32;32;0;5.774406;5.613839;1738203;2.070145e+008
6247.073;2.06657;-2.350503;2649.144;273.7455;32;32;0;6.508883;6.30582;2431238;2.915632e+008
6261.073;2.299981;-2.710437;3600.176;372.0189;32;32;0;7.244034;6.993674;3304042;3.989681e+008
6270.713;2.439909;-2.920142;4213.879;435.4351;32;32;0;7.684753;7.403782;3867265;4.688972e+008
6276.631;2.340909;-2.775096;3161.126;326.6504;32;32;0;7.372942;7.113803;2901107;3.507341e+008
6286.906;2.169856;-2.499585;2109.489;217.981;32;32;0;6.834191;6.610783;1935972;2.328782e+008
6300.906;1.936499;-2.073681;1273.551;131.6005;32;32;0;6.099209;5.92044;1168794;1.396271e+008
6314.906;1.703142;-1.628931;717.177;74.10844;32;32;0;5.364226;5.225298;658185.3;7.808378e+007
6328.906;1.469678;-1.236308;322.6231;33.33779;32;32;0;4.628906;4.524968;296085.7;3.488097e+007
6342.906;1.236321;-1.040178;113.5676;11.73535;32;32;0;3.893923;3.820022;104226.1;1.219231e+007
6356.906;1.003071;-1.03861;113.1589;11.69311;32;32;0;3.159278;3.110399;103851;1.206253e+007
6369.096;0.8998387;-1.03039;101.4192;10.48001;33;33;0;2.834138;2.794719;93076.95;1.077703e+007
6383.096;1.133196;-1.034483;114.2331;11.80411;33;33;0;3.56912;3.506903;104836.8;1.222541e+007
6397.096;1.366606;-1.14831;458.9724;47.42724;33;33;0;4.304272;4.214213;421219.4;4.946864e+007
6411.096;1.60007;-1.505926;1182.451;122.1868;33;33;0;5.039592;4.916716;1085188;1.283446e+008
6425.096;1.833374;-1.929898;1877.317;193.9898;33;33;0;5.774406;5.613839;1722898;2.051916e+008
6439.096;2.06657;-2.336973;2634.799;272.2631;33;33;0;6.508883;6.30582;2418072;2.899843e+008
6453.096;2.299981;-2.698258;3584.265;370.3748;33;33;0;7.244034;6.993674;3289440;3.972049e+008
6462.739;2.439856;-2.910869;4184.567;432.4062;33;33;0;7.684585;7.403625;3840364;4.656348e+008
6468.693;2.340374;-2.764043;3132.815;323.7249;33;33;0;7.371255;7.112232;2875124;3.475874e+008
6479.076;2.167284;-2.483662;2081.145;215.0521;33;33;0;6.826092;6.603202;1909960;2.297317e+008
6493.076;1.933981;-2.060092;1254.892;129.6725;33;33;0;6.091279;5.912966;1151671;1.375712e+008
6507.076;1.700731;-1.618402;701.2156;72.45909;33;33;0;5.356633;5.218092;643536.8;7.634046e+007
6521.076;1.46732;-1.230122;313.6735;32.413;33;33;0;4.621481;4.517871;287872.2;3.391096e+007
6535.076;1.234017;-1.046498;113.5737;11.73598;33;33;0;3.886668;3.813039;104231.7;1.219211e+007
6549.076;1.000553;-1.045727;113.1885;11.69617;33;33;0;3.151348;3.102712;103878.2;1.206476e+007
6561.122;0.8997852;-1.036869;101.7904;10.51837;34;34;0;2.833969;2.794555;93417.63;1.081645e+007
6575.122;1.133196;-1.040931;113.9145;11.77119;34;34;0;3.56912;3.506903;104544.4;1.219132e+007
6589.122;1.366553;-1.147673;439.9881;45.46552;34;34;0;4.304103;4.214051;403796.7;4.742241e+007
6603.122;1.600017;-1.501198;1162.008;120.0744;34;34;0;5.039423;4.916555;1066426;1.261254e+008
6617.122;1.83332;-1.923593;1859.139;192.1114;34;34;0;5.774237;5.61368;1706215;2.032044e+008
6631.123;2.06657;-2.329187;2618.121;270.5397;34;34;0;6.508883;6.30582;2402767;2.881488e+008
6645.123;2.299981;-2.691644;3562.561;368.132;34;34;0;7.244034;6.993674;3269521;3.947997e+008
6654.764;2.439856;-2.902099;4165.049;430.3893;34;34;0;7.684585;7.403625;3822451;4.634629e+008
6660.746;2.339891;-2.755556;3112.027;321.5768;34;34;0;7.369737;7.110817;2856046;3.452761e+008
6671.197;2.165731;-2.47314;2060.711;212.9406;34;34;0;6.821199;6.598622;1891207;2.274657e+008
6685.197;1.932374;-2.049643;1240.258;128.1603;34;34;0;6.086217;5.908194;1138240;1.359604e+008
6699.197;1.698963;-1.610193;691.9902;71.5058;34;34;0;5.351065;5.212806;635070.3;7.533212e+007
6713.197;1.465767;-1.22454;304.9462;31.51117;34;34;0;4.616589;4.513194;279862.7;3.296591e+007
6727.197;1.23241;-1.050401;113.5784;11.73646;34;34;0;3.881606;3.808166;104236;1.219202e+007
6741.197;0.9990529;-1.04891;113.09;11.68599;34;34;0;3.146623;3.098132;103787.7;1.20537e+007
6752.337;0.8864995;-1.041306;101.5657;10.49514;35;35;0;2.792124;2.753855;93211.38;1.078818e+007