File: Ensayos/Resistencia/comp/EsponjaB/REB4_com.raw
"Test Type";"Manual"
"Method Name:";"C:\INSTRON\user\template\CYCLE.MTM"
"Name:";""
"Operator ID:";""
"Company:";""
"Lab name:";""
"Test date:";"11/05/2017"
"Temperature:";""
"Humidity:";""
"Note 1:";""
"Note 2:";""
"Note 3:";""
"Geometry:";"Rectangular"
"Specimen";1
"Specimen name:";""
"Width:";0.250000;"in"
"Thickness:";0.060000;"in"
"Length:";1.250000;"in"
"Diameter:";0.039370;"in"
"Inner diameter:";0.019685;"in"
"Outer diameter:";0.039370;"in"
"Wall thickness:";0.019685;"in"
"Area:";0.015000;"in*in"
"Linear density:";1.000000;"den"
"Sled weight:";2.204623;"lbf"
"Loading span:";0.000000;"mm"
"Support span:";1.000000;"mm"
"Span ratio:";"2"
"Fixture type:";"3-point"
"Comment:";""
"Included"
"Final Width:";0.250000;"in"
"Final Thickness:";0.060000;"in"
"Final Length:";1.250000;"in"
"Final Diameter:";0.039370;"in"
"Final Inner diameter:";0.019685;"in"
"Final Outer diameter:";0.039370;"in"
"Final Wall thickness:";0.019685;"in"
"Final Area:";0.015000;"in*in"
"Final Linear density:";1.000000;"den"
"Time sec";"Extension mm";"Strain 1 %";"Load N";"Stress MPa";"Cycle Count ";"Total Cycle Count ";"Repetitions Count ";"Strain [Exten.] %";"True strain %";"Tenacity gf/tex";"True stress Pa"
0;0;0.001771011;47.9244;4.952198;0;0;0;0;0;43982.36;4952198
29;0.4834283;-0.2771413;691.3578;71.44044;0;0;0;1.522609;1.511133;634489.8;7.25282e+007
58;0.9665887;-0.9732984;1878.923;194.1557;0;0;0;3.044374;2.998953;1724371;2.000665e+008
87.00001;1.450071;-1.572691;3370.984;348.3357;0;0;0;4.567152;4.465928;3093702;3.642447e+008
116;1.933392;-2.168513;4587.943;474.0884;0;0;0;6.089422;5.911216;4210560;5.029576e+008
142.12;2.368713;-3.029498;4705.682;486.2548;0;0;0;7.460513;7.195327;4318614;5.225319e+008
156.95;2.121534;-2.666361;2602.151;268.8895;0;0;0;6.681997;6.468224;2388110;2.868567e+008
185.096;1.65241;-1.93091;891.8337;92.15633;0;0;0;5.20444;5.073531;818475.5;9.695255e+007
214.096;1.169089;-1.232336;238.9685;24.69346;0;0;0;3.682169;3.615996;219312;2.560271e+007
243.096;0.6859282;-0.9873351;46.03403;4.756859;0;0;0;2.160404;2.137398;42247.48;4859626
270.45;0.9632672;-1.094066;378.0063;39.06073;1;1;0;3.033912;2.988799;346913.3;4.02458e+007
299.45;1.446481;-1.657747;1430.105;147.7778;1;1;0;4.555846;4.455116;1312471;1.545103e+008
328.45;1.929963;-2.353957;2899.123;299.5767;1;1;0;6.078624;5.901037;2660655;3.177868e+008
351.714;2.254124;-3.021625;3701.257;382.464;1;1;0;7.099602;6.858907;3396809;4.096174e+008
372.012;1.915874;-2.50111;1536.206;158.7416;1;1;0;6.034248;5.859195;1409845;1.683205e+008
401.012;1.432606;-1.716664;457.8998;47.31641;1;1;0;4.512146;4.41331;420235.1;4.94514e+007
430.012;0.949178;-1.260502;47.16543;4.873771;1;1;0;2.989537;2.945721;43285.82;5019474
457.968;0.7167852;-1.259248;46.31392;4.785781;2;2;0;2.257591;2.232485;42504.35;4893825
486.968;1.199946;-1.511028;684.8599;70.769;2;2;0;3.779356;3.709689;628526.4;7.344361e+007
515.968;1.683374;-2.119211;1765.411;182.4262;2;2;0;5.301965;5.166189;1620196;1.920983e+008
544.968;2.166695;-2.943941;3583.523;370.2981;2;2;0;6.824236;6.601465;3288759;3.955681e+008
561.052;2.065552;-2.844433;2263.144;233.8587;2;2;0;6.505676;6.30281;2076988;2.490728e+008
588.9381;1.600713;-2.119686;654.4693;67.62862;2;2;0;5.041616;4.918643;600635.6;7.10382e+007
617.9381;1.117392;-1.49784;121.6657;12.57215;2;2;0;3.519345;3.458832;111658.1;1.301461e+007
646.9381;0.6341781;-1.433769;34.58183;3.573462;2;2;0;1.997411;1.977725;31737.28;3644839
673.9821;1.016571;-1.472607;202.5778;20.93308;3;3;0;3.201798;3.151609;185914.7;2.160332e+007
702.9821;1.499999;-2.021922;1174.466;121.3617;3;3;0;4.724406;4.616201;1077860;1.270953e+008
731.9821;1.983374;-2.721291;2726.286;281.7168;3;3;0;6.246846;6.059494;2502035;2.993152e+008
751.6381;2.109106;-2.974357;2644.181;273.2326;3;3;0;6.642853;6.431524;2426683;2.91383e+008
777.3001;1.681499;-2.290252;794.678;82.11689;3;3;0;5.296059;5.160581;729311.4;8.646585e+007
806.3001;1.198231;-1.639927;173.3281;17.91061;3;3;0;3.773957;3.704486;159071;1.858655e+007
835.3001;0.7148031;-1.523852;46.43831;4.798635;3;3;0;2.251348;2.22638;42618.51;4906669
863.1901;0.9499815;-1.525854;47.55559;4.914087;4;4;0;2.992068;2.948179;43643.89;5061120
892.1901;1.433356;-1.983216;974.2736;100.6751;4;4;0;4.514508;4.415571;894134.4;1.052201e+008
921.1901;1.916677;-2.672538;2388.915;246.855;4;4;0;6.036779;5.861582;2192414;2.617571e+008
941.5481;2.064481;-2.926123;2467.743;255.0006;4;4;0;6.502301;6.299641;2264758;2.715815e+008
967.598;1.630231;-2.232958;703.0102;72.64454;4;4;0;5.134586;5.007112;645183.8;7.637453e+007
996.598;1.146964;-1.61265;129.5494;13.3868;4;4;0;3.612484;3.548764;118893.2;1.387039e+007
1025.598;0.6635353;-1.551769;34.81984;3.598057;4;4;0;2.089875;2.068337;31955.72;3673252
1053.414;1.000017;-1.565044;86.89235;8.978894;5;5;0;3.14966;3.101076;79744.98;9261699
1082.414;1.483392;-2.066651;1062.072;109.7477;5;5;0;4.672101;4.566243;974711.1;1.148752e+008
1111.414;1.966552;-2.766459;2585.64;267.1833;5;5;0;6.193866;6.009616;2372957;2.837323e+008
1130.624;2.033677;-2.891684;2250.82;232.5852;5;5;0;6.405282;6.208504;2065678;2.47483e+008
1157.67;1.582928;-2.179715;614.8659;63.53627;5;5;0;4.985599;4.8653;564289.8;6.670393e+007
1186.67;1.099499;-1.598318;89.18153;9.215443;5;5;0;3.46299;3.404378;81845.87;9534573
1215.67;0.6162318;-1.579625;34.8581;3.602011;5;5;0;1.940887;1.922292;31990.84;3671922
1243.642;1.050107;-1.615085;190.4388;19.67871;6;6;0;3.307422;3.253904;174774.2;2.032957e+007
1272.642;1.533428;-2.155022;1149.783;118.8111;6;6;0;4.829693;4.716688;1055207;1.245493e+008
1301.642;2.016588;-2.865738;2792.045;288.5119;6;6;0;6.351458;6.157907;2562384;3.068366e+008
1319.91;1.999177;-2.847795;2020.785;208.8149;6;6;0;6.296621;6.106332;1854565;2.219631e+008
1347.924;1.532463;-2.116946;531.6841;54.9408;6;6;0;4.826656;4.713791;487950.2;5.75926e+007
1376.924;1.048981;-1.606355;51.68272;5.340558;6;6;0;3.303879;3.250474;47431.54;5517004
1404.866;0.6166067;-1.605553;35.07976;3.624916;7;7;0;1.942068;1.923451;32194.26;3695314
1433.866;1.099928;-1.661773;278.9926;28.82929;7;7;0;3.46434;3.405682;256044;2.982804e+007
1462.866;1.583356;-2.233885;1243.121;128.4561;7;7;0;4.986948;4.866585;1140868;1.348621e+008
1491.86;2.06657;-2.950395;2998.872;309.884;7;7;0;6.508883;6.30582;2752198;3.30054e+008
1509.468;1.960445;-2.800856;1788.783;184.8412;7;7;0;6.174631;5.991501;1641646;1.962545e+008
1538.124;1.482856;-2.053016;459.7485;47.50743;7;7;0;4.670413;4.56463;421931.7;4.972623e+007
1567.124;0.9993208;-1.625553;47.09976;4.866985;7;7;0;3.147467;3.09895;43225.55;5020172
1595.092;0.6667495;-1.625072;35.10889;3.627926;8;8;0;2.099998;2.078253;32221;3704113
1624.092;1.149856;-1.711047;365.4746;37.76579;8;8;0;3.621595;3.557557;335412.4;3.913351e+007
1653.092;1.633285;-2.313542;1355.556;140.0744;8;8;0;5.144204;5.016259;1244054;1.472801e+008
1681.94;2.114195;-3.034745;3209.422;331.6409;8;8;0;6.658882;6.446553;2945429;3.537245e+008
1699.382;1.915499;-2.737872;1554.372;160.6188;8;8;0;6.033067;5.858082;1426517;1.70309e+008
1728.356;1.432713;-1.991698;393.0566;40.61593;8;8;0;4.512483;4.413633;360725.6;4.244872e+007
1757.356;0.9493387;-1.64535;47.13841;4.870979;8;8;0;2.990043;2.946213;43261.02;5016623
1785.32;0.7167317;-1.646491;46.84398;4.840554;9;9;0;2.257423;2.23232;42990.81;4949826
1814.32;1.199946;-1.771357;450.1216;46.51266;9;9;0;3.779356;3.709689;413096.7;4.827054e+007
1843.32;1.68332;-2.396463;1482.668;153.2093;9;9;0;5.301796;5.166029;1360711;1.613322e+008
1871.902;2.15957;-3.11599;3424.127;353.8271;9;9;0;6.801795;6.580455;3142474;3.778937e+008
1888.56;1.883088;-2.690105;1398.199;144.4809;9;9;0;5.930986;5.761762;1283190;1.5305e+008
1917.56;1.399874;-1.949938;349.811;36.14721;9;9;0;4.409052;4.314619;321037.2;3.774096e+007
1946.56;0.9164459;-1.659423;46.99102;4.855749;9;9;0;2.886444;2.845571;43125.75;4995907
1974.546;0.7500531;-1.660805;46.95669;4.852201;10;10;0;2.362372;2.3349;43094.25;4966828
2003.546;1.233428;-1.813568;500.556;51.72423;10;10;0;3.884812;3.811252;459382.6;5.373361e+007
2032.546;1.716802;-2.451826;1572.798;162.5228;10;10;0;5.407251;5.266125;1443427;1.713108e+008
2059.16;2.160106;-3.120745;3417.489;353.1413;10;10;0;6.803483;6.582035;3136383;3.771672e+008
2077.8;1.84966;-2.638556;1253.101;129.4874;10;10;0;5.825699;5.662321;1150027;1.370309e+008
2106.8;1.366178;-1.908751;308.8701;31.91664;10;10;0;4.302922;4.212919;283463.8;3.328998e+007
2135.8;0.8829101;-1.669749;46.77298;4.833217;10;10;0;2.780819;2.742857;42925.64;4967620
2163.776;0.7832138;-1.671477;46.99352;4.856007;11;11;0;2.466815;2.43688;43128.05;4975795
2192.776;1.266642;-1.85258;550.6532;56.90094;11;11;0;3.989423;3.911901;505359;5.917096e+007
2221.776;1.750017;-2.504539;1663.802;171.9266;11;11;0;5.511864;5.365322;1526946;1.814029e+008
2247.054;2.149338;-3.112795;3256.537;336.5095;11;11;0;6.769568;6.550276;2988669;3.592897e+008
2267.058;1.815642;-2.585694;1122.003;115.9406;11;11;0;5.718557;5.561026;1029713;1.225707e+008
2296.058;1.332321;-1.875766;270.7864;27.98132;11;11;0;4.196285;4.110629;248512.8;2.91555e+007
2325.058;0.8491601;-1.678506;46.84542;4.840703;11;11;0;2.67452;2.63938;42992.13;4970169
2353.002;0.8166424;-1.681658;47.30847;4.888552;12;12;0;2.572102;2.53958;43417.09;5014290
2382.002;1.300017;-1.892627;600.7002;62.07247;12;12;0;4.094542;4.012936;551289.3;6.461406e+007
2411.002;1.783231;-2.557664;1761.202;181.9913;12;12;0;5.616476;5.464419;1616334;1.922128e+008
2434.95;2.137981;-3.100167;3097.043;320.0285;12;12;0;6.733797;6.516767;2842295;3.415785e+008
2456.304;1.781999;-2.533069;1009.469;104.312;12;12;0;5.612595;5.460745;926434.6;1.101666e+008
2485.304;1.298785;-1.854453;234.5533;24.23722;12;12;0;4.090661;4.009207;215260;2.522869e+007
2514.304;0.8153566;-1.699468;46.84704;4.84087;12;12;0;2.568052;2.535632;42993.61;4965186
2542.23;0.8500709;-1.70103;47.34791;4.892627;13;13;0;2.677389;2.642174;43453.29;5023622
2571.23;1.333231;-1.93571;650.9625;67.26626;13;13;0;4.199154;4.113382;597417.3;7.009087e+007
2600.23;1.816659;-2.614112;1863.538;192.566;13;13;0;5.721762;5.564057;1710252;2.035842e+008
2622.958;2.125016;-3.089965;2935.642;303.3503;13;13;0;6.692965;6.478504;2694170;3.236535e+008
2645.566;1.748142;-2.482195;910.7771;94.11382;13;13;0;5.505959;5.359724;835860.8;9.929569e+007
2674.566;1.264714;-1.812224;197.4867;20.407;13;13;0;3.98335;3.90606;181242.3;2.121988e+007
2703.566;0.7813387;-1.707862;46.79697;4.835696;13;13;0;2.460909;2.431117;42947.66;4954698
2731.454;0.8833387;-1.708369;47.64956;4.923798;14;14;0;2.782169;2.74417;43730.13;5060786
2760.454;1.366713;-1.980129;701.5386;72.49247;14;14;0;4.304609;4.214537;643833.3;7.561299e+007
2789.454;1.850088;-2.669555;1982.938;204.904;14;14;0;5.827049;5.663596;1819831;2.168439e+008
2811.1;2.109588;-3.069941;2779.893;287.2561;14;14;0;6.644372;6.432948;2551232;3.063425e+008
2834.776;1.715035;-2.431137;821.6472;84.90371;14;14;0;5.401684;5.260843;754062.3;8.948994e+007
2863.776;1.231606;-1.781369;167.2121;17.27862;14;14;0;3.879075;3.80573;153458;1.794887e+007
2892.776;0.7483923;-1.712286;41.58551;4.297178;14;14;0;2.357141;2.32979;38164.88;4398469
2920.678;0.9167137;-1.713413;47.74876;4.934049;15;15;0;2.887287;2.84639;43821.17;5076509
2949.678;1.400142;-2.021743;754.9073;78.00724;15;15;0;4.409896;4.315427;692812.1;8.144728e+007
2978.678;1.883356;-2.724966;2098.945;216.8914;15;15;0;5.93183;5.762559;1926295;2.29757e+008
2999.338;2.092766;-3.046923;2620.875;270.8243;15;15;0;6.59139;6.383255;2405294;2.886754e+008
3024.022;1.681285;-2.380894;737.818;76.24135;15;15;0;5.295385;5.15994;677128.5;8.027862e+007
3053.022;1.198071;-1.756054;134.8513;13.93466;15;15;0;3.773451;3.703998;123759.1;1.446048e+007
3082.022;0.7145888;-1.712951;35.07756;3.624688;15;15;0;2.250674;2.22572;32192.24;3706268
3109.902;0.9499815;-1.716834;48.10979;4.971355;16;16;0;2.992068;2.948179;44152.5;5120101
3138.902;1.433356;-2.063535;810.6921;83.77168;16;16;0;4.514508;4.415571;744008.3;8.755356e+007
3167.902;1.916677;-2.779466;2222.928;229.703;16;16;0;6.036779;5.861582;2040081;2.435697e+008
3187.678;2.074177;-3.020344;2457.292;253.9207;16;16;0;6.532842;6.328312;2255166;2.705089e+008
3213.336;1.646517;-2.332696;660.8931;68.29243;16;16;0;5.18588;5.055888;606531.1;7.183399e+007
3242.336;1.163089;-1.738404;102.5999;10.60201;16;16;0;3.663271;3.597768;94160.53;1.099039e+007
3271.336;0.6797138;-1.716815;35.11556;3.628615;16;16;0;2.140831;2.118237;32227.12;3706298
3299.126;0.9833565;-1.720944;48.03412;4.963535;17;17;0;3.097186;3.050191;44083.05;5117265
3328.126;1.466571;-2.104561;868.7393;89.76991;17;17;0;4.61912;4.515614;797280.8;9.391648e+007
3357.126;1.949999;-2.828602;2357.308;243.589;17;17;0;6.141728;5.960507;2163407;2.585496e+008
3376.112;2.054088;-2.988093;2295.952;237.2489;17;17;0;6.469568;6.268901;2107098;2.525979e+008
3402.604;1.612445;-2.28254;589.5803;60.92342;17;17;0;5.078568;4.953815;541084.1;6.401745e+007
3431.604;1.129071;-1.731254;74.47568;7.695835;17;17;0;3.556128;3.494358;68349.65;7969509
3460.604;0.6458567;-1.72927;35.52002;3.67041;17;17;0;2.034194;2.013781;32598.31;3745073
3488.354;1.016624;-1.734125;48.40311;5.001664;18;18;0;3.201966;3.151772;44421.69;5161816
3517.354;1.499999;-2.160671;925.5744;95.64288;18;18;0;4.724406;4.616201;849440.9;1.001614e+008
3546.322;1.982892;-2.883107;2493.866;257.7;18;18;0;6.245328;6.058065;2288732;2.737942e+008
3564.63;2.032606;-2.958024;2139.863;221.1197;18;18;0;6.401908;6.205332;1963848;2.352755e+008
3591.836;1.57907;-2.2421;532.4524;55.02019;18;18;0;4.97345;4.853728;488655.3;5.775659e+007
3620.836;1.095856;-1.743786;50.46093;5.214306;18;18;0;3.451516;3.393288;46310.24;5394279
3649.836;0.6123746;-1.745255;35.35354;3.653207;18;18;0;1.928739;1.910375;32445.52;3723668
3677.582;1.050053;-1.751631;51.98534;5.371829;19;19;0;3.307253;3.25374;47709.26;5549489
3706.582;1.533481;-2.220186;987.8891;102.0821;19;19;0;4.829862;4.716849;906629.9;1.070125e+008
3735.534;2.015892;-2.940589;2633.764;272.1562;19;19;0;6.349265;6.155844;2417123;2.894361e+008
3753.256;2.009141;-2.921856;1979.297;204.5278;19;19;0;6.328005;6.135852;1816489;2.174703e+008
3781.112;1.544945;-2.193899;482.8583;49.89546;19;19;0;4.86597;4.751287;443140.6;5.232336e+007
3810.112;1.061517;-1.75449;47.72236;4.931321;19;19;0;3.343361;3.288686;43796.94;5096192
3837.808;0.599946;-1.754819;35.44467;3.662623;20;20;0;1.889594;1.871963;32529.15;3731832
3866.808;1.083321;-1.774844;119.4441;12.34258;20;20;0;3.412034;3.355115;109619.2;1.276371e+007
3895.808;1.566695;-2.274226;1051.032;108.6068;20;20;0;4.934474;4.816591;964578.7;1.13966e+008
3924.718;2.048356;-2.993462;2774.133;286.6609;20;20;0;6.451514;6.251943;2545945;3.051549e+008
3941.97;1.984445;-2.883717;1822.772;188.3535;20;20;0;6.250221;6.06267;1672840;2.00126e+008
3970.328;1.511785;-2.145778;437.6747;45.22647;20;20;0;4.761527;4.65164;401673.5;4.737994e+007
3999.328;1.02841;-1.761272;47.68078;4.927023;20;20;0;3.239087;3.187735;43758.78;5086614
4027.034;0.6332674;-1.761028;35.58974;3.677614;21;21;0;1.994543;1.974913;32662.29;3750965
4056.034;1.116642;-1.797213;187.4392;19.36875;21;21;0;3.516983;3.45655;172021.3;2.004995e+007
4085.034;1.599963;-2.326043;1123.854;116.1318;21;21;0;5.039255;4.916395;1031411;1.21984e+008
4113.85;2.080338;-3.045518;2916.554;301.3778;21;21;0;6.552245;6.346524;2676652;3.211248e+008
4130.817;1.957392;-2.841908;1664.54;172.0028;21;21;0;6.165013;5.982442;1527623;1.826068e+008
4159.584;1.477874;-2.097391;393.6615;40.67844;21;21;0;4.654721;4.549638;361280.7;4.25719e+007
4188.584;0.9945529;-1.769215;47.86361;4.945917;21;21;0;3.13245;3.08439;43926.57;5100845
4216.259;0.6667495;-1.768743;35.66624;3.685519;22;22;0;2.099998;2.078253;32732.5;3762914
4245.259;1.14991;-1.821408;251.5984;25.99855;22;22;0;3.621764;3.55772;230903;2.694015e+007
4274.259;1.633285;-2.378571;1201.202;124.1245;22;22;0;5.144204;5.016259;1102397;1.305097e+008
4302.908;2.110874;-3.097563;3058.719;316.0682;22;22;0;6.648421;6.436745;2807123;3.370818e+008
4319.861;1.92707;-2.801009;1508.375;155.8657;22;22;0;6.069513;5.892447;1384303;1.65326e+008
4348.821;1.444338;-2.048754;352.2107;36.39518;22;22;0;4.549097;4.44866;323239.4;3.805083e+007
4377.821;0.9611779;-1.775922;47.65173;4.924022;22;22;0;3.027332;2.982413;43732.12;5073089
4405.489;0.6999102;-1.775414;35.85738;3.70527;23;23;0;2.204442;2.180495;32907.92;3786951
4434.489;1.183392;-1.851072;312.874;32.33038;23;23;0;3.727219;3.659438;287138.5;3.353541e+007
4463.489;1.666713;-2.430289;1283.7;132.6493;23;23;0;5.24949;5.116345;1178109;1.396127e+008
4491.914;2.140338;-3.149314;3201.431;330.8152;23;23;0;6.741222;6.523723;2938096;3.531162e+008
4508.956;1.895999;-2.752179;1366.329;141.1877;23;23;0;5.97165;5.800141;1253941;1.496189e+008
4537.956;1.412785;-2.004905;313.322;32.37667;23;23;0;4.449716;4.353558;287549.6;3.381734e+007
4566.956;0.9293566;-1.779413;47.48032;4.90631;23;23;0;2.927107;2.885086;43574.81;5049923
4594.72;0.7333388;-1.777695;35.96854;3.716756;24;24;0;2.309729;2.283458;33009.93;3802603
4623.72;1.216713;-1.875931;371.3833;38.37635;24;24;0;3.832169;3.760565;340835;3.9847e+007
4652.72;1.699927;-2.480861;1369.888;141.5553;24;24;0;5.354102;5.215689;1257207;1.491344e+008
4680.332;2.160052;-3.181875;3291.818;340.1552;24;24;0;6.803314;6.581877;3021048;3.63297e+008
4698.394;1.859302;-2.692646;1198.658;123.8616;24;24;0;5.856071;5.691016;1100062;1.31115e+008
4727.394;1.375874;-1.957962;274.9128;28.40771;24;24;0;4.333462;4.242195;252299.7;2.963875e+007
4756.394;0.892553;-1.784068;47.54164;4.912646;24;24;0;2.811191;2.772402;43631.09;5050750
4783.947;0.7667138;-1.78564;47.63514;4.922308;25;25;0;2.414847;2.38615;43716.89;5041174
4812.947;1.250035;-1.905124;425.3443;43.95233;25;25;0;3.937118;3.861589;390357.4;4.568279e+007
4841.947;1.73341;-2.528726;1461.858;151.059;25;25;0;5.459558;5.315735;1341612;1.593061e+008
4867.961;2.154481;-3.179954;3208.771;331.5737;25;25;0;6.785766;6.565446;2944833;3.540735e+008
4887.629;1.82566;-2.637982;1065.985;110.152;25;25;0;5.750109;5.590866;978302.4;1.164859e+008
4916.629;1.342285;-1.921973;241.8384;24.99001;25;25;0;4.227669;4.140744;221945.8;2.604651e+007
4945.629;0.8591244;-1.787349;47.74119;4.933266;25;25;0;2.705904;2.669941;43814.21;5066755
4973.171;0.8000352;-1.788486;47.66979;4.925889;26;26;0;2.519796;2.488572;43748.7;5050011
5002.171;1.283249;-1.933853;479.229;49.52043;26;26;0;4.041729;3.962188;439809.8;5.152191e+007
5031.171;1.766677;-2.579713;1561.393;161.3443;26;26;0;5.564338;5.415042;1432960;1.70322e+008
5055.793;2.143499;-3.166699;3052.203;315.3949;26;26;0;6.751176;6.533048;2801142;3.366878e+008
5076.877;1.79191;-2.59329;951.3584;98.30724;26;26;0;5.64381;5.490296;873104.1;1.038555e+008
5105.877;1.308749;-1.898487;210.2565;21.72655;26;26;0;4.122045;4.039353;192961.8;2.262213e+007
5134.877;0.8253209;-1.791105;47.5234;4.910761;26;26;0;2.599436;2.566225;43614.35;5038414
5162.399;0.8331959;-1.796082;47.83055;4.9425;27;27;0;2.624239;2.590397;43896.23;5072203
5191.399;1.316624;-1.972811;530.2071;54.78817;27;27;0;4.146848;4.063171;486594.7;5.706015e+007
5220.399;1.799999;-2.633821;1667.678;172.3271;27;27;0;5.669288;5.51441;1530503;1.820968e+008
5243.751;2.131177;-3.152778;2894.679;299.1174;27;27;0;6.712369;6.496689;2656576;3.191953e+008
5266.115;1.758481;-2.543566;855.9628;88.44967;27;27;0;5.538523;5.390584;785555.3;9.334847e+007
5295.115;1.275053;-1.866175;177.6782;18.36012;27;27;0;4.015914;3.937372;163063.3;1.909745e+007
5324.115;0.791678;-1.78453;46.59202;4.814518;27;27;0;2.493474;2.462894;42759.57;4934567
5351.622;0.8667316;-1.788079;48.02287;4.962373;28;28;0;2.729863;2.693267;44072.73;5097839
5380.622;1.350053;-1.995836;579.4101;59.8725;28;28;0;4.252135;4.164215;531750.5;6.241836e+007
5409.622;1.833213;-2.69091;1779.291;183.8604;28;28;0;5.773899;5.61336;1632935;1.944763e+008
5431.861;2.116552;-3.135649;2737.593;282.8852;28;28;0;6.666306;6.453514;2512411;3.017431e+008
5455.355;1.724892;-2.498776;768.9597;79.45933;28;28;0;5.43273;5.290293;705708.6;8.377614e+007
5484.355;1.241463;-1.84738;150.3153;15.53261;28;28;0;3.910121;3.835612;137951.1;1.613996e+007
5513.355;0.7583031;-1.790259;35.80456;3.699812;28;28;0;2.388356;2.360281;32859.44;3788176
5540.852;0.900053;-1.79865;47.87739;4.94734;29;29;0;2.834813;2.795375;43939.21;5087588
5569.852;1.383267;-2.047882;637.1941;65.84352;29;29;0;4.356746;4.26451;584781.4;6.871215e+007
5598.852;1.866695;-2.751231;1899.753;196.3082;29;29;0;5.879355;5.71301;1743488;2.078499e+008
5620.069;2.100213;-3.115878;2581.567;266.7625;29;29;0;6.614844;6.405257;2369220;2.844084e+008
5644.585;1.69157;-2.447582;687.9828;71.0917;29;29;0;5.327781;5.190702;631392.5;7.487931e+007
5673.585;1.208303;-1.828303;122.1379;12.62094;29;29;0;3.805678;3.735049;112091.4;1.310125e+007
5702.585;0.7249281;-1.798419;35.92293;3.712044;29;29;0;2.283238;2.257562;32968.07;3796798
5730.085;0.9333208;-1.804362;48.46645;5.00821;30;30;0;2.939593;2.897216;44479.82;5155431
5759.085;1.416642;-2.088394;694.5804;71.77345;30;30;0;4.461864;4.365188;637447.4;7.497589e+007
5788.085;1.90007;-2.809969;2028.9;209.6534;30;30;0;5.984474;5.812242;1862012;2.222e+008
5808.379;2.082266;-3.115803;2417.817;249.8416;30;30;0;6.55832;6.352225;2218938;2.66227e+008
5833.843;1.657874;-2.401326;612.3176;63.27295;30;30;0;5.22165;5.089889;561951.2;6.657684e+007
5862.843;1.174553;-1.801099;91.35535;9.440071;30;30;0;3.699379;3.632594;83840.88;9789295
5891.843;0.6911246;-1.788893;35.97206;3.71712;30;30;0;2.17677;2.153417;33013.16;3798034
5919.317;0.9664815;-1.790912;48.46342;5.007897;31;31;0;3.044036;2.998625;44477.05;5160339
5948.317;1.450017;-2.134323;751.3267;77.63725;31;31;0;4.566983;4.465766;689526;8.118293e+007
5977.317;1.933338;-2.887827;2162.177;223.4254;31;31;0;6.089254;5.911057;1984326;2.370304e+008
5996.802;2.062445;-3.171197;2248.867;232.3834;31;31;0;6.49589;6.293621;2063886;2.474788e+008
6023.1;1.624178;-2.382405;545.4499;56.36327;31;31;0;5.11552;4.988975;500583.8;5.924655e+007
6052.1;1.140749;-1.801322;62.76707;6.485944;31;31;0;3.592911;3.529871;57604.14;6718978
6081.1;0.6574282;-1.801043;35.9518;3.715027;31;31;0;2.07064;2.049494;32994.57;3791951
6108.549;0.9999636;-1.803909;48.7686;5.039432;32;32;0;3.149492;3.100913;44757.12;5198148
6137.549;1.483338;-2.203809;804.918;83.17503;32;32;0;4.671932;4.566082;738709.1;8.70609e+007
6166.549;1.966499;-3.014441;2292.448;236.8868;32;32;0;6.193696;6.009456;2103882;2.515588e+008
6185.31;2.041017;-3.190953;2084.533;215.4022;32;32;0;6.428399;6.230226;1913069;2.292491e+008
6212.365;1.59016;-2.344648;489.819;50.61473;32;32;0;5.008377;4.886994;449528.8;5.314971e+007
6241.365;1.106892;-1.806022;49.03108;5.066555;32;32;0;3.486274;3.42688;44998.01;5243189
6270.365;0.623571;-1.803634;36.09778;3.730111;32;32;0;1.964003;1.944966;33128.54;3803371
6297.777;1.033446;-1.80906;49.02315;5.065735;33;33;0;3.254947;3.203096;44990.73;5230622
6326.777;1.516606;-2.277042;858.7507;88.73775;33;33;0;4.776712;4.666135;788113.8;9.29765e+007
6355.753;1.999606;-3.12044;2428.929;250.9899;33;33;0;6.297971;6.107601;2229137;2.667971e+008
6373.899;2.018409;-3.181168;1927.494;199.1747;33;33;0;6.357194;6.1633;1768947;2.118367e+008
6401.603;1.556624;-2.29758;443.3416;45.81206;33;33;0;4.902753;4.786357;406874.3;4.805811e+007
6430.603;1.07341;-1.818627;48.64473;5.026632;33;33;0;3.380819;3.324926;44643.44;5196574
6459.003;0.5999996;-1.812651;35.93867;3.71367;33;33;0;1.889763;1.872128;32982.52;3783850
6487.005;1.06666;-1.819188;49.87827;5.154098;34;34;0;3.359559;3.304359;45775.51;5327253
6516.005;1.550088;-2.34816;917.6054;94.81941;34;34;0;4.882167;4.766732;842127.4;9.944866e+007
6544.93;2.032124;-3.208015;2568.592;265.4217;34;34;0;6.40039;6.203905;2357312;2.824098e+008
6562.615;1.993606;-3.151688;1768.973;182.7943;34;34;0;6.279074;6.089822;1623466;1.94272e+008
6590.868;1.522767;-2.243247;400.7952;41.41558;34;34;0;4.796116;4.684652;367827.6;4.340192e+007
6619.868;1.039285;-1.829782;48.50718;5.012418;34;34;0;3.273339;3.220906;44517.2;5176492
6647.233;0.6165532;-1.825005;36.31468;3.752524;35;35;0;1.9419;1.923285;33327.6;3825395
6676.233;1.099874;-1.842314;86.93376;8.983173;35;35;0;3.464171;3.405519;79782.99;9294366
6705.233;1.583356;-2.420433;979.2343;101.1877;35;35;0;4.986948;4.866585;898686.9;1.062339e+008
6734.058;2.063838;-3.286752;2711.46;280.1848;35;35;0;6.500277;6.29774;2488428;2.983976e+008
6751.427;1.967302;-3.116941;1612.868;166.6634;35;35;0;6.196228;6.01184;1480201;1.769902e+008
6780.103;1.489231;-2.195837;361.1425;37.31813;35;35;0;4.690492;4.583812;331436.6;3.906854e+007
6809.103;1.005856;-1.842679;48.11619;4.972016;35;35;0;3.168052;3.118904;44158.38;5129533
6836.463;0.6498746;-1.839671;36.36977;3.758217;36;36;0;2.046849;2.026183;33378.16;3835142
6865.463;1.133303;-1.870712;160.8268;16.61881;36;36;0;3.569458;3.507229;147598;1.721201e+007
6894.463;1.616678;-2.489671;1046.549;108.1436;36;36;0;5.091898;4.9665;960464.4;1.136501e+008
6923.169;2.095231;-3.361837;2853.935;294.9073;36;36;0;6.599152;6.390537;2619184;3.143686e+008
6940.43;1.937624;-3.069249;1456.371;150.492;36;36;0;6.102752;5.92378;1336577;1.596761e+008
6969.359;1.455374;-2.141731;323.2598;33.40358;36;36;0;4.583855;4.481901;296669.9;3.493475e+007
6998.359;0.9722137;-1.850124;48.40801;5.002171;36;36;0;3.06209;3.016144;44426.19;5155342
7025.693;0.6833567;-1.846264;36.52412;3.774167;37;37;0;2.152305;2.12947;33519.82;3855398
7054.693;1.166731;-1.895581;226.7951;23.43554;37;37;0;3.674745;3.608836;208139.9;2.429673e+007
7083.693;1.649838;-2.558578;1119.936;115.7269;37;37;0;5.196341;5.065833;1027815;1.217405e+008
7112.182;2.124909;-3.428936;2997.338;309.7255;37;37;0;6.692628;6.478188;2750791;3.304543e+008
7129.596;1.90532;-3.0112;1301.74;134.5134;37;37;0;6.001009;5.827842;1194665;1.425855e+008
7158.596;1.422106;-2.094772;289.1131;29.87508;37;37;0;4.479075;4.381663;265332;3.121321e+007
7187.596;0.938678;-1.855241;47.94073;4.953885;37;37;0;2.956466;2.913605;43997.34;5100345
7214.925;0.7167852;-1.852179;36.29509;3.7505;38;38;0;2.257591;2.232485;33309.63;3835171
7243.925;1.199946;-1.928985;289.2232;29.88646;38;38;0;3.779356;3.709689;265433;3.101597e+007
7272.925;1.68332;-2.629576;1203.609;124.3732;38;38;0;5.301796;5.166029;1104606;1.309672e+008
7301.16;2.153838;-3.492976;3141.655;324.6383;38;38;0;6.783741;6.563549;2883237;3.466609e+008
7318.804;1.872481;-2.966444;1151.951;119.0352;38;38;0;5.897578;5.73022;1057197;1.260554e+008
7347.804;1.389213;-2.058303;255.3372;26.3849;38;38;0;4.375475;4.282455;234334.3;2.753936e+007
7376.804;0.9057851;-1.864083;48.03535;4.963663;38;38;0;2.852867;2.81293;44084.18;5105269
7404.156;0.7499995;-1.862729;36.61105;3.783149;39;39;0;2.362203;2.334735;33599.59;3872515
7433.156;1.233321;-1.968376;345.242;35.67508;39;39;0;3.884475;3.810927;316843.9;3.706086e+007
7462.156;1.716749;-2.720584;1291.884;133.495;39;39;0;5.407083;5.265965;1185620;1.407131e+008
7488.773;2.160106;-3.530481;3154.964;326.0136;39;39;0;6.803483;6.582035;2895451;3.481939e+008
7508.169;1.83691;-2.907294;1011.227;104.4937;39;39;0;5.785542;5.624367;928048.5;1.105392e+008
7537.169;1.353481;-2.026675;222.1232;22.95278;39;39;0;4.262933;4.174573;203852.4;2.393124e+007
7566.169;0.8703209;-1.876125;48.24776;4.985611;39;39;0;2.741168;2.704271;44279.12;5122276
7593.386;0.7832138;-1.87272;38.93546;4.023338;40;40;0;2.466815;2.43688;35732.8;4122587
7622.386;1.266695;-2.011076;396.2987;40.95095;40;40;0;3.989592;3.912063;363701;4.258472e+007
7651.386;1.750017;-2.803396;1389.683;143.6008;40;40;0;5.511864;5.365322;1275374;1.515159e+008
7676.677;2.14907;-3.552118;2998.812;309.8779;40;40;0;6.768724;6.549485;2752144;3.308527e+008
7697.388;1.803642;-2.901528;896.2742;92.61519;40;40;0;5.680761;5.525268;822550.8;9.787644e+007
7726.388;1.320428;-2.017472;193.3255;19.97701;40;40;0;4.158827;4.074673;177423.4;2.080782e+007
7755.388;0.8369995;-1.891146;48.16779;4.977348;40;40;0;2.636219;2.602069;44205.73;5108562
7782.613;0.8165888;-1.891634;48.63489;5.025616;41;41;0;2.571933;2.539415;44634.41;5154871
7811.613;1.300017;-2.060716;444.321;45.91326;41;41;0;4.094542;4.012936;407773.2;4.77932e+007
7840.613;1.783231;-2.898822;1487.896;153.7496;41;41;0;5.616476;5.464419;1365509;1.623849e+008
7864.611;2.137231;-3.55664;2842.499;293.7255;41;41;0;6.731435;6.514554;2608688;3.134974e+008
7886.651;1.769892;-2.835679;801.3323;82.8045;41;41;0;5.574462;5.424632;735418.4;8.742041e+007
7915.651;1.28657;-1.989918;165.1866;17.06931;41;41;0;4.05219;3.972242;151599.1;1.7761e+007
7944.651;0.8030888;-1.895325;39.74468;4.106958;41;41;0;2.529413;2.497953;36475.46;4210840
7971.844;0.8500173;-1.90025;48.41705;5.003106;42;42;0;2.67722;2.642009;44434.49;5137050
8000.844;1.333178;-2.108265;494.3173;51.07956;42;42;0;4.198985;4.11322;453657;5.322438e+007
8029.844;1.816606;-2.981238;1592.73;164.5824;42;42;0;5.721593;5.563898;1461720;1.739992e+008
8052.649;2.123784;-3.548603;2686.736;277.6299;42;42;0;6.689085;6.474867;2465738;2.962009e+008
8075.879;1.73657;-2.769566;719.57;74.35571;42;42;0;5.469512;5.325175;660381.4;7.842261e+007
8104.879;1.253142;-1.965945;138.9326;14.3564;42;42;0;3.946904;3.871004;127504.6;1.492303e+007
8133.879;0.7699281;-1.898124;36.74281;3.796765;42;42;0;2.42497;2.396035;33720.52;3888835
8161.073;0.8833387;-1.905662;48.54242;5.01606;43;43;0;2.782169;2.74417;44549.54;5155615
8190.073;1.366713;-2.152484;545.7165;56.39082;43;43;0;4.304609;4.214537;500828.3;5.881822e+007
8219.073;1.850088;-3.048248;1708.716;176.5677;43;43;0;5.827049;5.663596;1568165;1.868564e+008
8240.832;2.107766;-3.521194;2526.617;261.0842;43;43;0;6.638635;6.427569;2318789;2.784167e+008
8265.162;1.702338;-2.699321;638.5565;65.9843;43;43;0;5.361695;5.222896;586031.8;6.952218e+007
8294.162;1.218964;-1.944319;111.0289;11.473;43;43;0;3.839255;3.767389;101896.1;1.191348e+007
8323.162;0.7356959;-1.901195;36.76431;3.798986;43;43;0;2.317153;2.290714;33740.25;3887015
8350.303;0.9167137;-1.90706;48.57064;5.018976;44;44;0;2.887287;2.84639;44575.44;5163888
8379.303;1.400088;-2.201851;597.0218;61.69238;44;44;0;4.409727;4.315266;547913.6;6.441285e+007
8408.303;1.883302;-3.113203;1833.087;189.4194;44;44;0;5.931661;5.7624;1682306;2.006551e+008
8429.137;2.089874;-3.49337;2350.228;242.8574;44;44;0;6.58228;6.374708;2156909;2.588429e+008
8454.479;1.667517;-2.616187;562.1773;58.09177;44;44;0;5.252021;5.118749;515935.2;6.114276e+007
8483.479;1.184089;-1.908324;81.10235;8.380593;44;44;0;3.729413;3.661552;74431.24;8693140
8512.479;0.7006602;-1.900291;36.77638;3.800233;44;44;0;2.206804;2.182806;33751.32;3884097
8539.528;0.949928;-1.904105;49.22918;5.087026;45;45;0;2.991899;2.948015;45179.81;5239224
8568.528;1.433303;-2.242774;632.6487;65.37383;45;45;0;4.514339;4.415409;580609.9;6.832503e+007
8597.528;1.916624;-3.184425;1967.393;203.2977;45;45;0;6.036611;5.861423;1805564;2.155699e+008
8617.496;2.070963;-3.468083;2189.441;226.2427;45;45;0;6.522718;6.318809;2009348;2.409999e+008
8643.732;1.63382;-2.552803;500.0367;51.67056;45;45;0;5.145891;5.017864;458906;5.432947e+007
8672.732;1.150392;-1.916203;56.57948;5.846558;45;45;0;3.623282;3.559185;51925.51;6058395
8701.732;0.6671246;-1.915554;36.63965;3.786105;45;45;0;2.10118;2.079409;33625.84;3865658
8728.761;0.9833565;-1.920151;49.29156;5.093471;46;46;0;3.097186;3.050191;45237.06;5251225
8757.761;1.466517;-2.311077;686.8197;70.97151;46;46;0;4.618951;4.515453;630325.1;7.424965e+007
8786.761;1.949945;-3.252758;2101.664;217.1724;46;46;0;6.14156;5.960348;1928791;2.305102e+008
8805.979;2.05007;-3.426924;2033.004;210.0775;46;46;0;6.456914;6.257015;1865778;2.23642e+008
8832.986;1.600017;-2.483107;445.5106;46.03618;46;46;0;5.039423;4.916555;408864.9;4.835614e+007
8861.986;1.116696;-1.928328;49.43431;5.108222;46;46;0;3.517152;3.456713;45368.07;5287886
8890.986;0.6333746;-1.920527;36.71621;3.794016;46;46;0;1.994881;1.975244;33696.1;3869702
8918.988;1.033446;-1.926939;49.40506;5.105199;47;47;0;3.254947;3.203096;45341.22;5271371
8947.988;1.516606;-2.409001;765.886;79.14171;47;47;0;4.776712;4.666135;702887.7;8.292208e+007
8976.988;1.999981;-3.349788;2312.309;238.9391;47;47;0;6.299152;6.108712;2122109;2.539902e+008
8995.278;2.015624;-3.364963;1803.166;186.3276;47;47;0;6.348421;6.155051;1654846;1.981564e+008
9023.215;1.549981;-2.39343;384.1265;39.69315;47;47;0;4.88183;4.76641;352530;4.16309e+007
9052.215;1.06666;-1.924478;48.99639;5.062971;47;47;0;3.359559;3.304359;44966.18;5233064
9080.217;0.5999996;-1.92188;36.66255;3.788471;47;47;0;1.889763;1.872128;33646.86;3860064
9108.219;1.06666;-1.926479;49.76024;5.141902;48;48;0;3.359559;3.304359;45667.2;5314647
9137.219;1.550142;-2.485365;816.029;84.32317;48;48;0;4.882337;4.766893;748906.2;8.844011e+007
9166.194;2.033034;-3.416313;2453.841;253.5641;48;48;0;6.403258;6.206601;2252000;2.698005e+008
9184.055;1.989802;-3.321301;1644.595;169.9419;48;48;0;6.267093;6.078549;1509319;1.805923e+008
9212.486;1.51591;-2.32986;345.4403;35.69557;48;48;0;4.774518;4.664041;317026;3.739986e+007
9241.486;1.032696;-1.93654;48.84897;5.047738;48;48;0;3.252585;3.200808;44830.88;5211919
9269.446;0.6332674;-1.927501;36.84633;3.807462;49;49;0;1.994543;1.974913;33815.52;3883403
9298.446;1.116696;-1.942479;86.50301;8.938663;49;49;0;3.517152;3.456713;79387.67;9253049
9327.446;1.599963;-2.589407;908.8246;93.91206;49;49;0;5.039255;4.916395;834068.9;9.864453e+007
9356.292;2.080874;-3.501644;2670.448;275.9468;49;49;0;6.553933;6.348108;2450789;2.940322e+008
9373.818;1.947481;-3.223303;1410.735;145.7763;49;49;0;6.133798;5.953036;1294695;1.547179e+008
9402.725;1.46566;-2.238488;295.5867;30.54402;49;49;0;4.616251;4.512872;271273.1;3.195401e+007
9431.725;0.9824993;-1.94082;49.00999;5.064376;49;49;0;3.094486;3.047572;44978.65;5221092
9459.671;0.6833567;-1.938197;37.1372;3.837519;50;50;0;2.152305;2.12947;34082.46;3920114
9488.671;1.166731;-1.976923;189.5845;19.59044;50;50;0;3.674745;3.608836;173990.2;2.031034e+007
9517.671;1.649892;-2.691232;1024.916;105.9081;50;50;0;5.196509;5.065993;940610.7;1.114117e+008
9546.267;2.12657;-3.580682;2887.117;298.336;50;50;0;6.697859;6.48309;2649636;3.183182e+008
9563.977;1.898731;-3.128806;1180.459;121.981;50;50;0;5.980255;5.808262;1083360;1.292758e+008
9592.977;1.415249;-2.155381;250.2815;25.86247;50;50;0;4.457477;4.360989;229694.5;2.701529e+007
9621.977;0.9320351;-1.943939;48.54853;5.016691;50;50;0;2.935544;2.893282;44555.15;5163958
9649.9;0.7333388;-1.940267;37.05706;3.829237;51;51;0;2.309729;2.283458;34008.92;3917682
9678.9;1.216713;-2.021745;278.265;28.75411;51;51;0;3.832169;3.760565;255376.3;2.985602e+007
9707.9;1.699927;-2.795453;1153.238;119.1682;51;51;0;5.354102;5.215689;1058378;1.255486e+008
9735.513;2.160052;-3.645599;3049.704;315.1367;51;51;0;6.803314;6.581877;2798850;3.365765e+008
9754.219;1.848534;-3.026163;978.4069;101.1022;51;51;0;5.822156;5.658972;897927.7;1.069886e+008
9783.219;1.36516;-2.099743;208.9147;21.58789;51;51;0;4.299716;4.209845;191730.3;2.251611e+007
9812.219;0.8818387;-1.946099;48.76173;5.038722;51;51;0;2.777445;2.739573;44750.81;5178670
9840.129;0.7832138;-1.94333;37.28926;3.853232;52;52;0;2.466815;2.43688;34222.02;3948284
9869.129;1.266642;-2.075823;352.3828;36.41296;52;52;0;3.989423;3.911901;323397.4;3.786563e+007
9898.129;1.749963;-2.905074;1298.674;134.1966;52;52;0;5.511695;5.365162;1191851;1.415931e+008
9923.431;2.148963;-3.631133;2892.517;298.894;52;52;0;6.768387;6.549169;2654592;3.191243e+008
9944.458;1.798392;-2.913852;811.8617;83.89254;52;52;0;5.664226;5.50962;745081.7;8.864441e+007
9973.458;1.314963;-2.045995;169.4037;17.50508;52;52;0;4.141617;4.058149;155469.3;1.823007e+007
10002.46;0.8316423;-1.950091;48.04683;4.964849;52;52;0;2.619346;2.585629;44094.72;5094896
10030.36;0.8331959;-1.951564;48.99977;5.06332;53;53;0;2.624239;2.590397;44969.27;5196193
10059.36;1.316624;-2.132716;418.9666;43.2933;53;53;0;4.146848;4.063171;384504.3;4.508861e+007
10088.36;1.799999;-3.006181;1453.056;150.1494;53;53;0;5.669288;5.51441;1333534;1.586618e+008
10111.74;2.130641;-3.607399;2660.711;274.9407;53;53;0;6.710681;6.495107;2441854;2.933911e+008
10134.69;1.748195;-2.806418;682.8988;70.56635;53;53;0;5.506127;5.359884;626726.7;7.445182e+007
10163.69;1.264714;-2.004494;132.2619;13.6671;53;53;0;3.98335;3.90606;121382.7;1.42115e+007
10192.69;0.7813924;-1.952103;37.12255;3.836004;53;53;0;2.461078;2.431282;34069.02;3930411
10220.59;0.8833387;-1.95799;49.10085;5.073765;54;54;0;2.782169;2.74417;45062.04;5214925
10249.59;1.366713;-2.191251;485.7358;50.1928;54;54;0;4.304609;4.214537;445781.4;5.235341e+007
10278.59;1.850034;-3.107639;1627.352;168.1601;54;54;0;5.82688;5.663437;1493494;1.779586e+008
10300.38;2.107284;-3.570969;2430.813;251.1846;54;54;0;6.637115;6.426144;2230866;2.67856e+008
10324.91;1.698427;-2.700962;574.2125;59.33541;54;54;0;5.349378;5.211205;526980.4;6.250949e+007
10353.91;1.215106;-1.974892;97.44471;10.06931;54;54;0;3.827107;3.755689;89429.35;1.045467e+007
10382.91;0.7316781;-1.956512;37.1525;3.8391;54;54;0;2.304498;2.278345;34096.51;3927572
10410.81;0.9333744;-1.961301;49.14126;5.07794;55;55;0;2.939762;2.897379;45099.13;5227219
10439.81;1.416695;-2.263496;553.1622;57.16021;55;55;0;4.462033;4.36535;507661.7;5.971072e+007
10468.81;1.900124;-3.20893;1815.7;187.6227;55;55;0;5.984642;5.812401;1666349;1.988512e+008
10489.27;2.079641;-3.521279;2199.996;227.3334;55;55;0;6.550052;6.344466;2019035;2.422238e+008
10515.14;1.648392;-2.599607;484.5114;50.06628;55;55;0;5.191785;5.061502;444657.8;5.266562e+007
10544.14;1.165178;-1.96503;61.13812;6.317618;55;55;0;3.669851;3.604116;56109.18;6549465
10573.14;0.6818031;-1.961356;37.07113;3.830691;55;55;0;2.147411;2.124679;34021.83;3912952
10601.04;0.9833565;-1.965822;49.79175;5.145158;56;56;0;3.097186;3.050191;45696.11;5304513
10630.04;1.466571;-2.346661;625.6035;64.64583;56;56;0;4.61912;4.515614;574144.3;6.763189e+007
10659.04;1.949999;-3.298004;2024.621;209.2113;56;56;0;6.141728;5.960507;1858085;2.220605e+008
10678.37;2.048249;-3.466465;1963.926;202.9395;56;56;0;6.451177;6.251626;1802383;2.160315e+008
10705.42;1.597338;-2.497428;407.2559;42.08319;56;56;0;5.030987;4.908523;373756.9;4.420039e+007
10734.42;1.114231;-1.970616;49.70744;5.136446;56;56;0;3.50939;3.449215;45618.74;5316704
10763.42;0.6307496;-1.964424;37.25781;3.849982;56;56;0;1.986613;1.967137;34193.16;3926466
10791.27;1.033446;-1.969777;49.94613;5.161111;57;57;0;3.254947;3.203096;45837.79;5329102
10820.27;1.516606;-2.445457;700.3941;72.37421;57;57;0;4.776712;4.666135;642782.9;7.583131e+007
10849.25;1.999713;-3.393403;2242.723;231.7485;57;57;0;6.298309;6.107919;2058247;2.463447e+008
10867.71;2.013052;-3.399673;1730.542;178.823;57;57;0;6.340322;6.147435;1588196;1.90161e+008
10895.67;1.546981;-2.395881;347.1925;35.87663;57;57;0;4.872381;4.757401;318634.1;3.762468e+007
10924.67;1.063821;-1.974447;49.29347;5.093668;57;57;0;3.350616;3.295706;45238.81;5264338
10952.49;0.5999996;-1.967976;37.18942;3.842914;58;58;0;1.889763;1.872128;34130.39;3915536
10981.49;1.083374;-1.971662;50.4002;5.208031;58;58;0;3.412203;3.355278;46254.51;5385740
11010.49;1.566695;-2.539912;781.4937;80.75451;58;58;0;4.934474;4.816591;717211.6;8.473932e+007
11039.44;2.048999;-3.481414;2459.468;254.1455;58;58;0;6.453539;6.253845;2257163;2.705469e+008
11057.32;1.973356;-3.31755;1494.219;154.4029;58;58;0;6.215294;6.029793;1371311;1.639995e+008
11085.97;1.495713;-2.287759;296.4446;30.63267;58;58;0;4.710908;4.603311;272060.5;3.207575e+007
11114.97;1.012606;-1.959105;49.40203;5.104887;58;58;0;3.189312;3.139509;45338.45;5267698
11142.73;0.6498746;-1.959008;37.53996;3.879137;59;59;0;2.046849;2.026183;34452.1;3958537
11171.73;1.133249;-1.972845;93.64305;9.676468;59;59;0;3.569289;3.507066;85940.4;1.002185e+007
11200.73;1.616624;-2.638866;887.1885;91.67632;59;59;0;5.091729;4.96634;814212.4;9.634424e+007
11229.51;2.096356;-3.563759;2679.501;276.8824;59;59;0;6.602695;6.393861;2459098;2.951641e+008
11247.21;1.929052;-3.214514;1264.412;130.6562;59;59;0;6.075756;5.898333;1160408;1.385946e+008
11276.21;1.445678;-2.18803;249.8113;25.81388;59;59;0;4.553315;4.452695;229263;2.698927e+007
11305.21;0.9625172;-1.949404;48.8848;5.05144;59;59;0;3.03155;2.986507;44863.76;5204577
11332.96;0.6999102;-1.951176;37.47735;3.872668;60;60;0;2.204442;2.180495;34394.64;3958038
11361.96;1.183338;-1.987425;185.7861;19.19793;60;60;0;3.72705;3.659275;170504.2;1.991345e+007
11390.96;1.666713;-2.735557;1008.009;104.1612;60;60;0;5.24949;5.116345;925095.3;1.096291e+008
11419.44;2.141516;-3.639337;2897.345;299.3929;60;60;0;6.744934;6.527201;2659022;3.195867e+008
11437.42;1.879499;-3.100995;1044.665;107.9489;60;60;0;5.919681;5.75109;958735.8;1.143392e+008
11466.42;1.396071;-2.097813;206.6728;21.35624;60;60;0;4.397073;4.303145;189672.9;2.229529e+007
11495.42;0.9127494;-1.942918;48.96753;5.059988;60;60;0;2.874801;2.834254;44939.68;5205452
11523.19;0.7499995;-1.943867;37.57447;3.882703;61;61;0;2.362203;2.334735;34483.77;3974420
11552.19;1.233374;-2.015931;261.1944;26.99014;61;61;0;3.884643;3.81109;239709.7;2.803861e+007
11581.19;1.716802;-2.828215;1141.86;117.9924;61;61;0;5.407251;5.266125;1047936;1.243725e+008
11607.8;2.160106;-3.667561;2980.411;307.9764;61;61;0;6.803483;6.582035;2735256;3.289295e+008
11627.68;1.828927;-2.986672;856.4822;88.50333;61;61;0;5.760401;5.600598;786031.9;9.360148e+007
11656.68;1.345499;-2.041571;167.6848;17.32747;61;61;0;4.237792;4.150457;153891.9;1.806177e+007
11685.68;0.862178;-1.948254;49.23368;5.08749;61;61;0;2.715521;2.679305;45183.94;5225642
11713.42;0.7999816;-1.943873;37.7413;3.899942;62;62;0;2.519627;2.488408;34636.88;3998206
11742.42;1.283249;-2.070141;330.8112;34.1839;62;62;0;4.041729;3.962188;303600.2;3.556552e+007
11771.42;1.766624;-2.925928;1287.744;133.0671;62;62;0;5.56417;5.414883;1181820;1.404712e+008
11796.06;2.14307;-3.640651;2749.64;284.13;62;62;0;6.749827;6.531785;2523467;3.033083e+008
11817.94;1.778463;-2.867619;706.448;72.99977;62;62;0;5.601459;5.4502;648338.8;7.708882e+007
11846.94;1.294981;-2.000952;133.9034;13.83671;62;62;0;4.078681;3.997698;122889.1;1.440106e+007
11875.94;0.8116601;-1.944302;37.35399;3.85992;62;62;0;2.55641;2.52428;34281.42;3958595
11903.65;0.8500709;-1.944168;49.46033;5.11091;63;63;0;2.677389;2.642174;45391.95;5247749
11932.65;1.333178;-2.121046;395.1903;40.83641;63;63;0;4.198985;4.11322;362683.8;4.255113e+007
11961.65;1.816606;-3.03149;1447.418;149.5668;63;63;0;5.721593;5.563898;1328360;1.581244e+008
11984.5;2.123034;-3.605728;2522.619;260.6711;63;63;0;6.686722;6.472653;2315120;2.781015e+008
12008.15;1.728802;-2.757734;592.2192;61.19611;63;63;0;5.445047;5.301975;543505.9;6.452826e+007
12037.15;1.245428;-1.961112;100.5845;10.39375;63;63;0;3.922607;3.847627;92310.89;1.080146e+007
12066.15;0.7619995;-1.943589;37.50281;3.875299;63;63;0;2.399998;2.371651;34418;3968306
12093.88;0.9001066;-1.945635;49.37261;5.101846;64;64;0;2.834981;2.79554;45311.45;5246483
12122.88;1.38332;-2.185926;458.2025;47.34769;64;64;0;4.356915;4.264671;420512.9;4.941059e+007
12151.88;1.866749;-3.129804;1625.428;167.9612;64;64;0;5.879524;5.713169;1491728;1.778365e+008
12173.25;2.097534;-3.558445;2289.602;236.5927;64;64;0;6.606407;6.397343;2101270;2.52223e+008
12198.44;1.677856;-2.645084;497.5307;51.41161;64;64;0;5.284586;5.149684;456606.1;5.41285e+007
12227.44;1.194374;-1.939218;68.09546;7.036545;64;64;0;3.761808;3.692778;62494.24;7301246
12256.44;0.710946;-1.939148;37.16445;3.840335;64;64;0;2.2392;2.214498;34107.48;3926327
12284.11;0.9499815;-1.946734;49.50725;5.11576;65;65;0;2.992068;2.948179;45435.02;5268827
12313.11;1.433356;-2.255359;525.9144;54.34459;65;65;0;4.514508;4.415571;482655.1;5.679798e+007
12342.11;1.916677;-3.22989;1824.932;188.5767;65;65;0;6.036779;5.861582;1674822;1.999607e+008
12362.23;2.068392;-3.500817;2065.567;213.4423;65;65;0;6.514619;6.311206;1895663;2.273473e+008
12388.64;1.628195;-2.528355;420.5976;43.46183;65;65;0;5.128174;5.001013;386001.1;4.569063e+007
12417.64;1.145035;-1.94323;50.10515;5.177543;65;65;0;3.606409;3.542901;45983.73;5364266
12446.64;0.6616067;-1.943711;37.59949;3.885288;65;65;0;2.083801;2.062386;34506.73;3966250
12474.34;1.000017;-1.94557;50.0483;5.171668;66;66;0;3.14966;3.101076;45931.55;5334558
12503.34;1.483338;-2.342575;605.2573;62.54338;66;66;0;4.671932;4.566082;555471.6;6.546536e+007
12532.34;1.966499;-3.320274;2037.388;210.5305;66;66;0;6.193696;6.009456;1869802;2.235701e+008
12551.42;2.035766;-3.435225;1838.68;189.9973;66;66;0;6.411862;6.214688;1687438;2.021797e+008
12578.86;1.578213;-2.422419;355.464;36.73135;66;66;0;4.97075;4.851156;326225.2;3.855718e+007
12607.86;1.094999;-1.941064;49.8299;5.1491;66;66;0;3.448817;3.390678;45731.12;5326683
12636.86;0.6115175;-1.941307;37.59039;3.884348;66;66;0;1.926039;1.907726;34498.38;3959162
12664.56;1.050053;-1.945406;50.73618;5.242749;67;67;0;3.307253;3.25374;46562.86;5416140
12693.56;1.533428;-2.440641;683.1903;70.59647;67;67;0;4.829693;4.716688;626994.2;7.400606e+007
12722.52;2.015784;-3.411089;2258.308;233.3589;67;67;0;6.348927;6.155527;2072550;2.481747e+008
12740.88;1.998534;-3.357376;1609.605;166.3262;67;67;0;6.294597;6.104427;1477207;1.767958e+008
12769.12;1.527856;-2.318406;304.8138;31.49749;67;67;0;4.812146;4.699947;279741.3;3.30132e+007
12798.12;1.044642;-1.942639;49.78706;5.144673;67;67;0;3.290212;3.237243;45691.8;5313943
12825.8;0.6166067;-1.943634;37.899;3.916238;68;68;0;1.942068;1.923451;34781.6;3992294
12854.8;1.099928;-1.946731;51.041;5.274248;68;68;0;3.46434;3.405682;46842.61;5456965
12883.8;1.583356;-2.543071;769.8626;79.55262;68;68;0;4.986948;4.866585;706537.2;8.351987e+007
12912.65;2.06432;-3.501354;2480.048;256.2721;68;68;0;6.501795;6.299166;2276051;2.729344e+008
12930.56;1.957767;-3.269032;1381.568;142.7623;68;68;0;6.166194;5.983555;1267927;1.515653e+008
12959.36;1.47766;-2.225334;259.3073;26.79515;68;68;0;4.654046;4.548993;237977.9;2.80422e+007
12988.36;0.9943922;-1.944792;49.45621;5.110486;68;68;0;3.131944;3.083899;45388.17;5270543
13016.02;0.6667495;-1.943106;37.6653;3.892089;69;69;0;2.099998;2.078253;34567.13;3973823
13045.02;1.149856;-1.96035;97.97343;10.12394;69;69;0;3.621595;3.557557;89914.58;1.049059e+007
13074.02;1.633285;-2.645778;889.0292;91.86654;69;69;0;5.144204;5.016259;815901.8;9.659234e+007
13102.66;2.110606;-3.580636;2703.191;279.3303;69;69;0;6.647577;6.435954;2480839;2.978989e+008
13120.6;1.910945;-3.1687;1155.122;119.3629;69;69;0;6.018725;5.844555;1060107;1.26547e+008
13149.6;1.427517;-2.135346;219.2956;22.66059;69;69;0;4.496116;4.397972;201257.3;2.367943e+007
13178.6;0.9441958;-1.951072;49.36001;5.100544;69;69;0;2.973845;2.930484;45299.88;5252227
13206.25;0.7167317;-1.94452;38.09828;3.93683;70;70;0;2.257423;2.23232;34964.49;4025701
13235.25;1.199946;-1.99212;190.8345;19.71961;70;70;0;3.779356;3.709689;175137.3;2.046488e+007
13264.25;1.68332;-2.743528;1018.141;105.2081;70;70;0;5.301796;5.166029;934392.9;1.10786e+008
13292.51;2.154106;-3.658729;2923.939;302.1409;70;70;0;6.784585;6.56434;2683429;3.226399e+008
13310.84;1.860749;-3.05446;950.7933;98.24883;70;70;0;5.860626;5.695319;872585.4;1.040068e+008
13339.84;1.377321;-2.070607;181.9246;18.79891;70;70;0;4.338017;4.246561;166960.3;1.961441e+007
13368.84;0.8939458;-1.951179;49.57056;5.122302;70;70;0;2.815578;2.776669;45493.12;5266524
13396.48;0.7667138;-1.949061;38.10832;3.937868;71;71;0;2.414847;2.38615;34973.71;4032961
13425.48;1.250035;-2.028097;264.6552;27.34776;71;71;0;3.937118;3.861589;242885.9;2.842448e+007
13454.48;1.73341;-2.852962;1154.131;119.2605;71;71;0;5.459558;5.315735;1059198;1.257716e+008
13480.51;2.154374;-3.662374;2873.711;296.9507;71;71;0;6.785429;6.56513;2637333;3.171001e+008
13501.1;1.810124;-2.943465;775.5768;80.1431;71;71;0;5.701177;5.544585;711781.4;8.471219e+007
13530.1;1.326749;-2.01093;145.1566;14.99954;71;71;0;4.178737;4.093786;133216.7;1.562633e+007
13559.1;0.8433209;-1.950014;40.18303;4.152255;71;71;0;2.656129;2.621466;36877.76;4262544
13586.71;0.8166424;-1.947759;38.54849;3.983352;72;72;0;2.572102;2.53958;35377.67;4085808
13615.71;1.300017;-2.083509;330.3889;34.14026;72;72;0;4.094542;4.012936;303212.7;3.553815e+007
13644.71;1.783231;-2.953416;1304.028;134.7499;72;72;0;5.616476;5.464419;1196765;1.423181e+008
13668.73;2.136802;-3.635966;2646.805;273.5037;72;72;0;6.730085;6.513289;2429091;2.919107e+008
13691.33;1.760088;-2.826297;644.2137;66.56888;72;72;0;5.543585;5.395381;591223.6;7.025918e+007
13720.33;1.276821;-1.985767;114.4627;11.82783;72;72;0;4.021482;3.942725;105047.5;1.230349e+007
13749.33;0.7933923;-1.946612;37.9868;3.925311;72;72;0;2.498873;2.468162;34862.18;4023399
13776.94;0.866678;-1.956142;49.87921;5.154195;73;73;0;2.729695;2.693103;45776.37;5294889
13805.94;1.350053;-0.5004951;380.9424;39.36413;73;73;0;4.252135;4.164215;349607.8;4.103794e+007
13834.94;1.833159;-1.387414;1459.712;150.8372;73;73;0;5.773731;5.613201;1339643;1.595462e+008
13857.32;2.114356;-1.845605;2403.958;248.4094;73;73;0;6.659389;6.447029;2206219;2.64952e+008
13881.63;1.708927;-1.018486;530.3304;54.80092;73;73;0;5.382449;5.242591;486707.9;5.775055e+007
13910.63;1.225713;-0.2132579;76.27616;7.881886;73;73;0;3.860515;3.787861;70002.03;8186167
13939.63;0.7422853;-0.2100451;37.9446;3.92095;73;73;0;2.337906;2.310996;34823.45;4012618
13967.17;0.9167137;-0.2104091;49.83002;5.149112;74;74;0;2.887287;2.84639;45731.23;5297782
13996.17;1.400088;-0.443934;444.6021;45.94231;74;74;0;4.409727;4.315266;408031.2;4.796824e+007
14025.17;1.883302;-1.420565;1643.686;169.8479;74;74;0;5.931661;5.7624;1508484;1.799227e+008
14046.15;2.087409;-1.758972;2174.41;224.6895;74;74;0;6.574518;6.367425;1995553;2.394617e+008
14071.87;1.658731;-0.8730119;442.9682;45.77348;74;74;0;5.22435;5.092455;406531.7;4.816484e+007
14100.87;1.175517;-0.1941876;51.14948;5.285457;74;74;0;3.702416;3.635523;46942.16;5481147
14129.87;0.6921424;-0.1895918;37.80761;3.906794;74;74;0;2.179976;2.156554;34697.73;3991961
14157.4;0.9664815;-0.1948998;50.26949;5.194524;75;75;0;3.044036;2.998625;46134.55;5352647
14186.4;1.449963;-0.5061946;513.1521;53.02582;75;75;0;4.566814;4.465605;470942.5;5.544741e+007
14215.4;1.933285;-1.497089;1848.99;191.0627;75;75;0;6.089085;5.910898;1696901;2.026966e+008
14235.22;2.056713;-1.687781;1945.448;201.0301;75;75;0;6.477836;6.276667;1785425;2.140525e+008
14262.12;1.608374;-0.7539906;370.347;38.26927;75;75;0;5.065745;4.941611;339884;4.020789e+007
14291.12;1.125214;-0.187351;50.54685;5.223186;75;75;0;3.54398;3.482626;46389.1;5408294
14320.12;0.6417853;-0.1837595;38.11108;3.938153;75;75;0;2.021371;2.001213;34976.24;4017758
14347.63;1.016571;-0.1864514;50.60074;5.228754;76;76;0;3.201798;3.151609;46438.55;5396168
14376.63;1.499999;-0.5937501;589.4944;60.91455;76;76;0;4.724406;4.616201;541005.3;6.37924e+007
14405.6;1.982838;-1.573992;2066.467;213.5354;76;76;0;6.245159;6.057906;1896489;2.26871e+008
14424.54;2.022159;-1.615136;1718.355;177.5638;76;76;0;6.369006;6.174405;1577011;1.888728e+008
14452.35;1.558499;-0.6370968;313.7034;32.41608;76;76;0;4.908659;4.791987;287899.6;3.400728e+007
14481.35;1.075231;-0.1882087;50.46853;5.215092;76;76;0;3.386556;3.330475;46317.22;5391704
14509.86;0.5999996;-0.1830155;37.9952;3.926179;76;76;0;1.889763;1.872128;34869.89;4000374
14537.86;1.06666;-0.184249;50.88976;5.258619;77;77;0;3.359559;3.304359;46703.8;5435286
14559.89;1.433785;-0.4751496;484.7426;50.09017;77;77;0;4.515858;4.416862;444869.9;5.235217e+007