File: Ensayos/Resistencia/comp/EsponjaB/REB5_comp.raw
"Test Type";"Manual"
"Method Name:";"C:\INSTRON\user\template\CYCLE.MTM"
"Name:";""
"Operator ID:";""
"Company:";""
"Lab name:";""
"Test date:";"12/05/2017"
"Temperature:";""
"Humidity:";""
"Note 1:";""
"Note 2:";""
"Note 3:";""
"Geometry:";"Rectangular"
"Specimen";1
"Specimen name:";""
"Width:";0.250000;"in"
"Thickness:";0.060000;"in"
"Length:";1.250000;"in"
"Diameter:";0.039370;"in"
"Inner diameter:";0.019685;"in"
"Outer diameter:";0.039370;"in"
"Wall thickness:";0.019685;"in"
"Area:";0.015000;"in*in"
"Linear density:";1.000000;"den"
"Sled weight:";2.204623;"lbf"
"Loading span:";0.000000;"mm"
"Support span:";1.000000;"mm"
"Span ratio:";"2"
"Fixture type:";"3-point"
"Comment:";""
"Included"
"Final Width:";0.250000;"in"
"Final Thickness:";0.060000;"in"
"Final Length:";1.250000;"in"
"Final Diameter:";0.039370;"in"
"Final Inner diameter:";0.019685;"in"
"Final Outer diameter:";0.039370;"in"
"Final Wall thickness:";0.019685;"in"
"Final Area:";0.015000;"in*in"
"Final Linear density:";1.000000;"den"
"Time sec";"Extension mm";"Strain 1 %";"Load N";"Stress MPa";"Cycle Count ";"Total Cycle Count ";"Repetitions Count ";"Strain [Exten.] %";"True strain %";"Tenacity gf/tex";"True stress Pa"
0;0;-0.08724982;58.80686;6.076721;0;0;0;0;0;53969.68;6076721
1;0.0001071428;-0.08729317;58.95496;6.092025;0;0;0;0.0003374576;0.000337457;54105.6;6092045
2;0.000267857;-0.08793658;58.78951;6.074928;0;0;0;0.000843644;0.0008436404;53953.75;6074979
3;0.0004821425;-0.08826992;58.85506;6.081701;0;0;0;0.001518559;0.001518548;54013.91;6081794
4;0.0005892853;-0.0883959;58.8448;6.080642;0;0;0;0.001856017;0.001856;54004.5;6080755
5;0.0008035709;-0.08902496;58.85341;6.081531;0;0;0;0.002530932;0.0025309;54012.39;6081685
6;0.0009642851;-0.08929833;58.94095;6.090577;0;0;0;0.003037118;0.003037072;54092.74;6090762
7;0.001124999;-0.0897974;58.7582;6.071693;0;0;0;0.003543305;0.003543242;53925.02;6071908
8;0.001285713;-0.0901356;58.74384;6.070209;0;0;0;0.004049491;0.004049409;53911.84;6070455
9;0.001446428;-0.09030768;58.66922;6.062499;0;0;0;0.004555678;0.004555574;53843.36;6062775
9.576;0.00155357;-0.09065506;58.92603;6.089035;0;0;0;0.004893135;0.004893015;54079.05;6089333
"Specimen";2
"Specimen name:";""
"Width:";0.250000;"in"
"Thickness:";0.060000;"in"
"Length:";1.250000;"in"
"Diameter:";0.039370;"in"
"Inner diameter:";0.019685;"in"
"Outer diameter:";0.039370;"in"
"Wall thickness:";0.019685;"in"
"Area:";0.015000;"in*in"
"Linear density:";1.000000;"den"
"Sled weight:";2.204623;"lbf"
"Loading span:";0.000000;"mm"
"Support span:";1.000000;"mm"
"Span ratio:";"2"
"Fixture type:";"3-point"
"Comment:";""
"Included"
"Final Width:";0.250000;"in"
"Final Thickness:";0.060000;"in"
"Final Length:";1.250000;"in"
"Final Diameter:";0.039370;"in"
"Final Inner diameter:";0.019685;"in"
"Final Outer diameter:";0.039370;"in"
"Final Wall thickness:";0.019685;"in"
"Final Area:";0.015000;"in*in"
"Final Linear density:";1.000000;"den"
"Time sec";"Extension mm";"Strain 1 %";"Load N";"Stress MPa";"Cycle Count ";"Total Cycle Count ";"Repetitions Count ";"Strain [Exten.] %";"True strain %";"Tenacity gf/tex";"True stress Pa"
0;0.001607142;-0.002495854;59.00914;6.097623;0;0;0;0.005061864;0.005061736;54155.32;6097932
6;0.002624998;-0.004036426;58.7888;6.074855;0;0;0;0.008267712;0.00826737;53953.11;6075357
12;0.003589283;-0.00561988;58.92327;6.08875;0;0;0;0.01130483;0.01130419;54076.51;6089438
18;0.004553569;-0.007244258;58.95099;6.091615;0;0;0;0.01434195;0.01434092;54101.96;6092489
24;0.005624996;-0.008945856;58.92676;6.089111;0;0;0;0.01771652;0.01771495;54079.72;6090190
30;0.006589282;-0.0104201;59.01396;6.098121;0;0;0;0.02075364;0.02075149;54159.74;6099387
36;0.007553567;-0.01186668;58.7824;6.074193;0;0;0;0.02379076;0.02378793;53947.23;6075638
42;0.008624995;-0.01343767;59.01222;6.097942;0;0;0;0.02716534;0.02716165;54158.15;6099598
48;0.009589279;-0.0148826;58.91922;6.088332;0;0;0;0.03020245;0.03019789;54072.79;6090170
54;0.01055356;-0.01598078;58.72082;6.06783;0;0;0;0.03323957;0.03323405;53890.71;6069847
60;0.01162499;-0.01739717;58.77177;6.073095;0;0;0;0.03661415;0.03660745;53937.47;6075318
66;0.01258928;-0.01853502;58.80578;6.076609;0;0;0;0.03965127;0.03964341;53968.68;6079019
72;0.01355356;-0.01958036;58.66537;6.062101;0;0;0;0.04268839;0.04267928;53839.83;6064689
78;0.01462499;-0.02078868;58.97707;6.094309;0;0;0;0.04606296;0.04605236;54125.89;6097116
84.00001;0.01558928;-0.02185425;58.95919;6.092462;0;0;0;0.04910008;0.04908803;54109.48;6095453
90.00001;0.01655356;-0.02309519;58.81538;6.077601;0;0;0;0.0521372;0.05212361;53977.5;6080770
96.00001;0.01762499;-0.0238017;59.01061;6.097775;0;0;0;0.05551178;0.05549637;54156.67;6101160
102;0.01858927;-0.02501073;58.87552;6.083816;0;0;0;0.05854889;0.05853176;54032.69;6087378
108;0.0196607;-0.02603208;58.94289;6.090777;0;0;0;0.06192347;0.0619043;54094.52;6094549
114;0.02062499;-0.02694047;58.834;6.079525;0;0;0;0.06496058;0.0649395;53994.58;6083474
120;0.02158927;-0.02778613;58.69844;6.065517;0;0;0;0.06799771;0.0679746;53870.18;6069642
126;0.0226607;-0.02856625;59.08749;6.105719;0;0;0;0.07137228;0.07134682;54227.22;6110077
132;0.02362498;-0.02936739;58.95816;6.092355;0;0;0;0.0744094;0.07438173;54108.53;6096889
138;0.02458927;-0.03013513;58.88715;6.085018;0;0;0;0.07744652;0.07741654;54043.36;6089730
144;0.02555355;-0.03110536;59.02341;6.099098;0;0;0;0.08048364;0.08045126;54168.42;6104007
150;0.02662498;-0.03179227;58.7424;6.07006;0;0;0;0.08385822;0.08382308;53910.52;6075151
156;0.02758927;-0.03255139;59.07243;6.104163;0;0;0;0.08689533;0.0868576;54213.4;6109467
162;0.02855355;-0.0331759;58.75104;6.070952;0;0;0;0.08993245;0.08989203;53918.45;6076412
168;0.02962498;-0.03397664;58.99275;6.09593;0;0;0;0.09330703;0.09326352;54140.28;6101618
174;0.03058926;-0.03464262;59.03034;6.099814;0;0;0;0.09634414;0.09629776;54174.78;6105691
180;0.03155355;-0.03507529;59.03134;6.099917;0;0;0;0.09938127;0.09933192;54175.7;6105980
186;0.03262498;-0.03586741;59.11709;6.108778;0;0;0;0.1027558;0.1027031;54254.39;6115055
192;0.03358926;-0.0365228;59.04473;6.101301;0;0;0;0.105793;0.105737;54187.98;6107756
198;0.03455355;-0.03699953;59.02958;6.099736;0;0;0;0.1088301;0.1087709;54174.08;6106374
204;0.03562498;-0.03773364;58.88659;6.08496;0;0;0;0.1122047;0.1121418;54042.85;6091788
210;0.03658926;-0.0380259;58.87493;6.083755;0;0;0;0.1152418;0.1151754;54032.15;6090766
216;0.03755355;-0.03847127;58.73589;6.069387;0;0;0;0.1182789;0.118209;53904.54;6076566
222;0.03862497;-0.03904741;58.9956;6.096224;0;0;0;0.1216535;0.1215795;54142.89;6103640
228;0.03958926;-0.03939494;58.98224;6.094843;0;0;0;0.1246906;0.1246129;54130.63;6102443
234;0.04066069;-0.03955691;59.05404;6.102263;0;0;0;0.1280652;0.1279832;54196.53;6110078
240;0.04162498;-0.04013038;59.03703;6.100506;0;0;0;0.1311023;0.1310164;54180.92;6108504
246;0.04258926;-0.04068802;59.02018;6.098764;0;0;0;0.1341394;0.1340495;54165.45;6106945
252;0.04366068;-0.04123671;58.93153;6.089603;0;0;0;0.137514;0.1374195;54084.09;6097977
258;0.04462497;-0.04176628;59.12261;6.109349;0;0;0;0.1405511;0.1404524;54259.46;6117936
264;0.04558926;-0.0422427;59.06136;6.103019;0;0;0;0.1435882;0.1434852;54203.24;6111782
270;0.04666068;-0.04288226;59.02062;6.09881;0;0;0;0.1469628;0.1468549;54165.86;6107773
276;0.04762497;-0.04358955;58.93064;6.089511;0;0;0;0.1499999;0.1498875;54083.28;6098646
282;0.04858925;-0.04441138;59.03627;6.100427;0;0;0;0.153037;0.15292;54180.22;6109763
288;0.04966068;-0.04643747;59.04288;6.10111;0;0;0;0.1564116;0.1562894;54186.29;6110653
294;0.05062497;-0.04759821;58.88724;6.085027;0;0;0;0.1594487;0.1593217;54043.45;6094730
300;0.05158925;-0.04856515;58.99774;6.096446;0;0;0;0.1624858;0.162354;54144.86;6106352
306;0.05255354;-0.04990511;58.88239;6.084526;0;0;0;0.1655229;0.1653861;54039;6094598
312;0.05362497;-0.0511462;59.28589;6.12622;0;0;0;0.1688975;0.1687551;54409.3;6136567
318;0.05458925;-0.05282922;59.02526;6.099289;0;0;0;0.1719347;0.171787;54170.12;6109776
324;0.05555354;-0.05452651;59.07519;6.104448;0;0;0;0.1749718;0.1748189;54215.93;6115129
330;0.05662496;-0.05656631;59.11072;6.10812;0;0;0;0.1783463;0.1781875;54248.54;6119013
336;0.05758925;-0.05901236;58.91813;6.088219;0;0;0;0.1813835;0.1812192;54071.79;6099262
342;0.05855354;-0.06194565;59.09533;6.10653;0;0;0;0.1844206;0.1842507;54234.42;6117791
348;0.05962496;-0.0655486;59.19509;6.116838;0;0;0;0.1877952;0.187619;54325.97;6128325
354;0.06058925;-0.06964804;59.11151;6.108202;0;0;0;0.1908323;0.1906504;54249.27;6119858
360;0.06155353;-0.07477674;58.94365;6.090856;0;0;0;0.1938694;0.1936817;54095.22;6102665
366;0.06262496;-0.08013084;59.00559;6.097256;0;0;0;0.197244;0.1970497;54152.06;6109283
372;0.06358925;-0.08517261;59.11938;6.109015;0;0;0;0.2002811;0.2000808;54256.49;6121250
378;0.06455353;-0.0908544;59.01002;6.097714;0;0;0;0.2033182;0.2031118;54156.13;6110112
384;0.06562495;-0.0975468;59.08056;6.105003;0;0;0;0.2066928;0.2064795;54220.86;6117622
390;0.06658925;-0.1047351;59.22569;6.12;0;0;0;0.2097299;0.2095103;54354.05;6132836
396;0.06755353;-0.1120305;58.96459;6.09302;0;0;0;0.212767;0.212541;54114.44;6105984
402;0.06862495;-0.1205132;59.06092;6.102973;0;0;0;0.2161416;0.2159083;54202.84;6116165
408;0.06958924;-0.1291993;59.00347;6.097038;0;0;0;0.2191787;0.2189389;54150.12;6110401
414;0.07066067;-0.137906;58.92154;6.088571;0;0;0;0.2225533;0.222306;54074.92;6102121
420;0.07162496;-0.1474773;59.09045;6.106026;0;0;0;0.2255904;0.2253363;54229.95;6119800
426;0.07258924;-0.1536902;59.12496;6.109591;0;0;0;0.2286275;0.2283666;54261.61;6123560
432;0.07366067;-0.1657757;59.09745;6.106749;0;0;0;0.2320021;0.2317334;54236.36;6120916
438;0.07462495;-0.1714263;59.20613;6.117979;0;0;0;0.2350392;0.2347634;54336.11;6132359
444;0.07558924;-0.181124;59.31816;6.129556;0;0;0;0.2380763;0.2377934;54438.92;6144149
450;0.07655352;-0.1917317;58.99642;6.096309;0;0;0;0.2411135;0.2408232;54143.65;6111008
456;0.07762495;-0.1976539;59.11867;6.108942;0;0;0;0.244488;0.2441896;54255.84;6123877
462;0.07858923;-0.2115697;59.26154;6.123705;0;0;0;0.2475251;0.2472193;54386.96;6138863
468;0.07955352;-0.2190272;59.05492;6.102354;0;0;0;0.2505623;0.2502489;54197.34;6117644
474;0.08062495;-0.2273769;59.2394;6.121417;0;0;0;0.2539369;0.253615;54366.64;6136962
480;0.08158923;-0.2431374;59.12628;6.109728;0;0;0;0.256974;0.2566443;54262.82;6125428
486;0.08255352;-0.2486824;59.35431;6.133291;0;0;0;0.2600111;0.2596736;54472.1;6149238
492;0.08362495;-0.2640018;59.14352;6.111509;0;0;0;0.2633857;0.2630394;54278.64;6127606
498;0.08458924;-0.2735701;59.1373;6.110866;0;0;0;0.2664228;0.2660685;54272.93;6127147
504;0.08555352;-0.2832698;59.28876;6.126518;0;0;0;0.2694599;0.2690975;54411.94;6143026
510;0.08662494;-0.2996605;59.28874;6.126515;0;0;0;0.2728345;0.2724629;54411.92;6143230
516;0.08758922;-0.3050064;59.12391;6.109482;0;0;0;0.2758716;0.2754917;54260.64;6126337
522;0.08855352;-0.3196306;59.2244;6.119867;0;0;0;0.2789087;0.2785205;54352.87;6136935
528;0.08962494;-0.3289175;59.24645;6.122145;0;0;0;0.2822833;0.2818856;54373.11;6139427
534;0.09058923;-0.3370517;59.30127;6.12781;0;0;0;0.2853204;0.2849141;54423.42;6145294
540;0.09155351;-0.3549691;59.05536;6.1024;0;0;0;0.2883575;0.2879426;54197.74;6119996
546;0.09262494;-0.3565772;59.309;6.128609;0;0;0;0.2917321;0.2913074;54430.51;6146488
552;0.09358922;-0.3729745;59.10643;6.107677;0;0;0;0.2947692;0.2943356;54244.61;6125680
558;0.09466065;-0.3806468;59.30278;6.127966;0;0;0;0.2981438;0.2977002;54424.8;6146236
564;0.09562494;-0.388547;59.23667;6.121135;0;0;0;0.3011809;0.3007283;54364.13;6139570
570;0.09658922;-0.4043416;59.03419;6.100212;0;0;0;0.304218;0.3037562;54178.31;6118770
576;0.09760708;-0.4052682;59.23576;6.121041;0;0;0;0.3074239;0.3069523;54363.3;6139859
582;0.09862493;-0.4192499;59.13862;6.111002;0;0;0;0.3106297;0.3101483;54274.14;6129985
588;0.09958922;-0.4260121;59.37196;6.135115;0;0;0;0.3136669;0.3131759;54488.3;6154359
594;0.1006607;-0.4344027;59.31164;6.128881;0;0;0;0.3170414;0.3165399;54432.94;6148313
600;0.1016249;-0.448771;59.24906;6.122415;0;0;0;0.3200786;0.3195674;54375.5;6142012
606;0.1025892;-0.4508755;59.16354;6.113578;0;0;0;0.3231156;0.3225948;54297.02;6133332
612;0.1036071;-0.4788829;59.26181;6.123733;0;0;0;0.3263215;0.3257902;54387.2;6143716
618;0.1046249;-0.4843549;59.23012;6.120458;0;0;0;0.3295273;0.3289856;54358.12;6140626
624;0.1055892;-0.5088545;59.37325;6.135248;0;0;0;0.3325644;0.3320127;54489.48;6155652
630;0.1065535;-0.5199331;59.1066;6.107695;0;0;0;0.3356016;0.3350397;54244.77;6128192
636;0.1076249;-0.5333631;59.31434;6.129161;0;0;0;0.3389761;0.3384029;54435.42;6149937
642;0.1085892;-0.5519668;59.16572;6.113804;0;0;0;0.3420133;0.3414298;54299.02;6134714
648.0001;0.1095535;-0.5543861;59.33975;6.131786;0;0;0;0.3450504;0.3444565;54458.73;6152944
654.0001;0.1106249;-0.5696646;59.23256;6.12071;0;0;0;0.348425;0.3478194;54360.36;6142036
660.0001;0.1115892;-0.5755646;59.24566;6.122064;0;0;0;0.3514621;0.3508459;54372.38;6143580
666.0001;0.1125535;-0.5848363;59.08297;6.105252;0;0;0;0.3544992;0.3538723;54223.07;6126895
672.0001;0.1136249;-0.6004281;59.19403;6.116728;0;0;0;0.3578738;0.3572349;54325;6138619
678.0001;0.1145892;-0.6055091;59.10599;6.107631;0;0;0;0.3609109;0.3602612;54244.2;6129674
684.0001;0.1156071;-0.6201878;59.29549;6.127213;0;0;0;0.3641168;0.3634555;54418.11;6149523
690.0001;0.1166249;-0.627345;59.26495;6.124057;0;0;0;0.3673226;0.3666496;54390.09;6146552
696.0001;0.1175892;-0.6334653;59.41836;6.13991;0;0;0;0.3703597;0.3696756;54530.88;6162649
702.0001;0.1185535;-0.6459922;59.16901;6.114143;0;0;0;0.3733968;0.3727014;54302.04;6136973
708.0001;0.1196249;-0.6494313;59.31534;6.129264;0;0;0;0.3767714;0.3760634;54436.33;6152357
714.0001;0.1205892;-0.6628662;59.17694;6.114963;0;0;0;0.3798085;0.3790891;54309.32;6138188
720.0001;0.1216606;-0.6735201;59.47847;6.146121;0;0;0;0.3831831;0.3824508;54586.05;6169672
726.0001;0.1226249;-0.6763031;59.29467;6.127128;0;0;0;0.3862202;0.3854763;54417.36;6150792
732.0001;0.1235892;-0.6868273;59.43087;6.141202;0;0;0;0.3892573;0.3885017;54542.36;6165107
738.0001;0.1246606;-0.6903425;59.18346;6.115636;0;0;0;0.3926319;0.3918631;54315.3;6139648
744.0001;0.1256249;-0.6999435;59.37308;6.135231;0;0;0;0.395669;0.3948883;54489.32;6159506
750.0001;0.1265892;-0.7096212;59.46987;6.145232;0;0;0;0.3987062;0.3979135;54578.15;6169733
756.0001;0.1275535;-0.7113343;59.37413;6.135339;0;0;0;0.4017433;0.4009385;54490.29;6159988
762.0001;0.1286249;-0.7213239;59.47562;6.145827;0;0;0;0.4051178;0.4042995;54583.43;6170725
768.0001;0.1295892;-0.7231395;59.34098;6.131914;0;0;0;0.408155;0.4073243;54459.87;6156942
774.0001;0.1305535;-0.7301605;59.45601;6.1438;0;0;0;0.4111921;0.410349;54565.43;6169063
780.0001;0.1316249;-0.7375167;59.3704;6.134954;0;0;0;0.4145666;0.4137097;54486.87;6160387
786.0001;0.1325892;-0.738268;59.22686;6.120121;0;0;0;0.4176038;0.4167342;54355.13;6145679
792.0001;0.1335535;-0.7466781;59.24484;6.121979;0;0;0;0.4206409;0.4197586;54371.63;6147730
798.0001;0.1346249;-0.7497199;59.28868;6.126509;0;0;0;0.4240155;0.423119;54411.86;6152486
804.0001;0.1355892;-0.7553393;59.40209;6.138228;0;0;0;0.4270526;0.4261433;54515.95;6164442
810.0001;0.1365535;-0.7617102;59.19867;6.117208;0;0;0;0.4300897;0.4291675;54329.26;6143518
816.0001;0.1376249;-0.7625641;59.44658;6.142826;0;0;0;0.4334643;0.4325275;54556.78;6169453
822.0001;0.1385892;-0.7702245;59.3571;6.13358;0;0;0;0.4365014;0.4355515;54474.66;6160353
828.0001;0.1395535;-0.772414;59.42526;6.140623;0;0;0;0.4395385;0.4385754;54537.21;6167613
834.0001;0.1406249;-0.7975043;59.48523;6.146819;0;0;0;0.4429131;0.4419351;54592.25;6174044
840.0001;0.1415892;-0.8064706;59.2567;6.123204;0;0;0;0.4459502;0.4449588;54382.51;6150511
846.0001;0.1425535;-0.8274303;59.651;6.163949;0;0;0;0.4489873;0.4479824;54744.38;6191624
852.0001;0.1436249;-0.8376417;59.36145;6.134028;0;0;0;0.4523619;0.4513418;54478.65;6161777
858.0001;0.1445892;-0.8486675;59.44523;6.142686;0;0;0;0.4553991;0.4543653;54555.54;6170660
864.0001;0.1455535;-0.8645175;59.29916;6.127593;0;0;0;0.4584362;0.4573886;54421.49;6155684
870.0001;0.1466249;-0.8677161;59.23518;6.12098;0;0;0;0.4618107;0.4607477;54362.76;6149248
876.0001;0.1475892;-0.8822674;59.65282;6.164137;0;0;0;0.4648478;0.4637708;54746.06;6192791
882.0001;0.148607;-0.888006;59.46914;6.145156;0;0;0;0.4680537;0.4669617;54577.48;6173919
888.0001;0.1496249;-0.8961509;59.42042;6.140122;0;0;0;0.4712595;0.4701526;54532.77;6169058
894.0001;0.1505892;-0.9056181;59.32553;6.130317;0;0;0;0.4742967;0.4731754;54445.69;6159393
900.0001;0.1516606;-0.9067603;59.37906;6.135849;0;0;0;0.4776712;0.476534;54494.82;6165158
906.0001;0.1526249;-0.9232754;59.25852;6.123393;0;0;0;0.4807083;0.4795566;54384.18;6152828
912.0001;0.1535892;-0.929221;59.3228;6.130035;0;0;0;0.4837455;0.4825792;54443.18;6159689
918.0001;0.1545535;-0.9447367;59.66721;6.165624;0;0;0;0.4867826;0.4856016;54759.26;6195638
924.0001;0.1556249;-0.9494147;59.39757;6.137761;0;0;0;0.4901572;0.4889598;54511.8;6167846
930.0001;0.1565892;-0.9586264;59.42271;6.140358;0;0;0;0.4931943;0.491982;54534.87;6170642
936.0001;0.1575535;-0.9701878;59.20997;6.118376;0;0;0;0.4962314;0.4950042;54339.63;6148737
942.0001;0.1586249;-0.9710341;59.43487;6.141615;0;0;0;0.499606;0.4983621;54546.03;6172299
948.0001;0.1595892;-0.9803288;59.32765;6.130536;0;0;0;0.5026431;0.5013841;54447.63;6161351
954.0001;0.1605535;-0.9814206;59.60501;6.159197;0;0;0;0.5056802;0.5044059;54702.18;6190343
960.0001;0.1616249;-0.9900077;59.49832;6.148172;0;0;0;0.5090548;0.5077635;54604.27;6179470
966.0001;0.1625892;-0.9932864;59.31358;6.129082;0;0;0;0.5120919;0.5107851;54434.72;6160469
972.0001;0.1635535;-0.9964763;59.41903;6.139979;0;0;0;0.515129;0.5138068;54531.5;6171608
978.0001;0.1645713;-1.002836;59.53503;6.151966;0;0;0;0.5183349;0.5169961;54637.95;6183853
984.0001;0.1655892;-1.002725;59.37405;6.135331;0;0;0;0.5215407;0.5201854;54490.21;6167329
990.0001;0.166607;-1.008243;59.56766;6.155337;0;0;0;0.5247465;0.5233745;54667.89;6187637
996.0001;0.1676249;-1.00973;59.48106;6.146389;0;0;0;0.5279524;0.5265636;54588.42;6178838
1002;0.1685892;-1.012917;59.56936;6.155513;0;0;0;0.5309895;0.5295848;54669.46;6188198
1008;0.1695535;-1.016977;59.51653;6.150054;0;0;0;0.5340266;0.5326058;54620.98;6182897
1014;0.1706249;-1.016657;59.27549;6.125146;0;0;0;0.5374012;0.5359624;54399.76;6158063
1020;0.1715892;-1.022398;59.41349;6.139406;0;0;0;0.5404383;0.5389832;54526.41;6172586
1026;0.1726606;-1.022579;59.5955;6.158214;0;0;0;0.5438129;0.5423396;54693.45;6191703
1032;0.1736249;-1.026631;59.52922;6.151365;0;0;0;0.54685;0.5453602;54632.62;6185004
1038;0.1745892;-1.027457;59.36973;6.134885;0;0;0;0.5498871;0.5483808;54486.25;6168620
1044;0.1756606;-1.028858;59.40473;6.138502;0;0;0;0.5532618;0.5517369;54518.38;6172463
1050;0.1766249;-1.031426;59.58619;6.157252;0;0;0;0.5562989;0.5547572;54684.9;6191504
1056;0.1775892;-1.031195;59.63417;6.16221;0;0;0;0.5593359;0.5577774;54728.94;6196678
1062;0.1785535;-1.034115;59.49498;6.147827;0;0;0;0.5623731;0.5607977;54601.2;6182401
1068;0.1796249;-1.034743;59.58689;6.157325;0;0;0;0.5657476;0.5641533;54685.55;6192160
1074;0.1805892;-1.036317;59.38456;6.136417;0;0;0;0.5687848;0.5671733;54499.86;6171320
1080;0.1815535;-1.037622;59.44232;6.142385;0;0;0;0.5718219;0.5701932;54552.87;6177509
1086;0.1826249;-1.036961;59.73619;6.172752;0;0;0;0.5751965;0.5735486;54822.57;6208257
1092;0.1835892;-1.03949;59.81748;6.181152;0;0;0;0.5782336;0.5765682;54897.17;6216893
1098;0.1845534;-1.039935;59.53447;6.151908;0;0;0;0.5812707;0.5795878;54637.44;6187667
1104;0.1856249;-1.041039;59.46402;6.144628;0;0;0;0.5846453;0.5829429;54572.79;6180552
1110;0.1865892;-1.043282;59.47748;6.146018;0;0;0;0.5876824;0.5859623;54585.13;6182137
1116;0.1875535;-1.042425;59.66715;6.165618;0;0;0;0.5907195;0.5889816;54759.2;6202039
1122;0.1886249;-1.044118;59.54916;6.153426;0;0;0;0.5940941;0.5923363;54650.92;6189983
1128;0.1895892;-1.043589;59.57318;6.155908;0;0;0;0.5971312;0.5953554;54672.96;6192667
1134;0.190607;-1.042777;59.49835;6.148175;0;0;0;0.6003371;0.5985422;54604.29;6185085
1140;0.1916249;-1.042676;59.72897;6.172006;0;0;0;0.6035429;0.6017289;54815.94;6209256
1146;0.1925892;-1.042322;59.72392;6.171484;0;0;0;0.60658;0.6047477;54811.3;6208919
1152;0.1936606;-1.042675;59.58701;6.157337;0;0;0;0.6099547;0.6081019;54685.66;6194894
1158;0.1946249;-1.042526;59.43483;6.141612;0;0;0;0.6129918;0.6111206;54546;6179259
1164;0.1955892;-1.042452;59.73328;6.172451;0;0;0;0.6160288;0.6141392;54819.9;6210476
1170;0.1966606;-1.042407;59.49647;6.147981;0;0;0;0.6194034;0.617493;54602.57;6186062
1176;0.1976249;-1.042468;59.52017;6.15043;0;0;0;0.6224405;0.6205114;54624.32;6188713
1182;0.1985892;-1.04254;59.65144;6.163995;0;0;0;0.6254776;0.6235296;54744.79;6202549
1188;0.199607;-1.042818;59.54361;6.152852;0;0;0;0.6286835;0.6267156;54645.82;6191534
1194;0.2006249;-1.042331;59.56783;6.155355;0;0;0;0.6318893;0.6299013;54668.05;6194250
1200;0.2015892;-1.042557;59.73995;6.173141;0;0;0;0.6349265;0.6329193;54826.02;6212336
1206;0.2026606;-1.042488;59.72797;6.171902;0;0;0;0.6383011;0.6362726;54815.02;6211298
1212;0.2036249;-1.042197;59.45997;6.144209;0;0;0;0.6413382;0.6392904;54569.07;6183614
1218;0.2045892;-1.042299;59.58346;6.15697;0;0;0;0.6443753;0.6423081;54682.39;6196644
1224;0.2055534;-1.041865;59.8127;6.180657;0;0;0;0.6474124;0.6453257;54892.78;6220672
1230;0.2066249;-1.041826;59.5992;6.158597;0;0;0;0.650787;0.6486785;54696.84;6198676
1236;0.2075891;-1.041214;59.76251;6.175472;0;0;0;0.6538241;0.6516959;54846.72;6215848
1242;0.2085534;-1.04136;59.87098;6.186681;0;0;0;0.6568612;0.6547133;54946.27;6227319
1248;0.2096249;-1.040746;59.7554;6.174737;0;0;0;0.6602358;0.6580658;54840.19;6215505
1254;0.2105892;-1.040858;60.356;6.236799;0;0;0;0.6632729;0.6610829;55391.39;6278166
1260;0.2115534;-1.040246;59.60308;6.158997;0;0;0;0.66631;0.6641;54700.4;6200035
1266;0.2126249;-1.040031;59.5987;6.158545;0;0;0;0.6696846;0.6674522;54696.38;6199787
1272;0.2135892;-1.03964;59.76627;6.17586;0;0;0;0.6727217;0.6704691;54850.17;6217406
1278;0.2145534;-1.039189;59.68556;6.167521;0;0;0;0.6757588;0.6734858;54776.1;6209198
1284;0.2156249;-1.038652;59.69182;6.168167;0;0;0;0.6791334;0.6768377;54781.85;6210057
1290;0.2165891;-1.038262;59.73599;6.172731;0;0;0;0.6821705;0.6798543;54822.38;6214840
1296;0.217607;-1.03779;59.71238;6.170291;0;0;0;0.6853764;0.6830384;54800.71;6212581
1302;0.2186249;-1.037438;59.53985;6.152463;0;0;0;0.6885822;0.6862223;54642.38;6194828
1308;0.2195891;-1.036906;59.54091;6.152573;0;0;0;0.6916193;0.6892386;54643.34;6195125
1314;0.2205534;-1.036062;60.19599;6.220264;0;0;0;0.6946565;0.6922548;55244.54;6263474
1320;0.2216249;-1.034084;59.66078;6.164959;0;0;0;0.6980311;0.6956061;54753.36;6207993
1326;0.2225892;-1.034536;59.58128;6.156745;0;0;0;0.7010682;0.6986222;54680.4;6199908
1332;0.2236606;-1.033339;59.7208;6.171162;0;0;0;0.7044427;0.7019731;54808.44;6214634
1338;0.2246249;-1.032019;59.71062;6.170109;0;0;0;0.7074798;0.704989;54799.1;6213762
1344;0.2255891;-1.031036;59.64935;6.163779;0;0;0;0.710517;0.7080047;54742.87;6207573
1350;0.2266606;-1.03006;59.7391;6.173053;0;0;0;0.7138915;0.7113554;54825.24;6217122
1356;0.2276248;-1.029669;59.7245;6.171545;0;0;0;0.7169287;0.7143709;54811.84;6215790
1362;0.2285891;-1.029859;58.97584;6.094182;0;0;0;0.7199658;0.7173864;54124.76;6138058
1368;0.2295534;-1.026541;59.90478;6.190174;0;0;0;0.7230029;0.7204018;54977.29;6234929
1374;0.2306249;-1.026395;60.57352;6.259276;0;0;0;0.7263775;0.7237521;55591.02;6304742
1380;0.2315891;-1.024001;60.37556;6.238821;0;0;0;0.7294146;0.7267673;55409.34;6284327
1386;0.2325534;-1.022687;59.9785;6.19779;0;0;0;0.7324517;0.7297823;55044.94;6243186
1392;0.2336249;-1.021152;59.70486;6.169515;0;0;0;0.7358263;0.7331323;54793.81;6214912
1398;0.2345891;-1.019601;59.08514;6.105476;0;0;0;0.7388634;0.7361472;54225.07;6150588
1404;0.2355534;-1.017898;59.196;6.116932;0;0;0;0.7419006;0.739162;54326.8;6162313
1410;0.2366248;-1.014652;59.84908;6.184417;0;0;0;0.7452751;0.7425116;54926.17;6230508
1416;0.2375891;-1.013031;59.76395;6.17562;0;0;0;0.7483122;0.7455263;54848.04;6221833
1422;0.2385534;-1.010799;59.74533;6.173696;0;0;0;0.7513493;0.7485408;54830.95;6220082
1428;0.2396249;-1.009219;59.66049;6.164929;0;0;0;0.754724;0.7518902;54753.09;6211458
1434;0.2405891;-1.007256;59.8237;6.181795;0;0;0;0.7577611;0.7549045;54902.88;6228638
1440;0.2415534;-1.003535;60.18145;6.218762;0;0;0;0.7607982;0.7579187;55231.2;6266075
1446;0.2426248;-1.001637;60.82689;6.285458;0;0;0;0.7641727;0.7612677;55823.55;6333490
1452;0.2435891;-0.9979483;59.77452;6.176713;0;0;0;0.7672098;0.7642818;54857.74;6224101
1458;0.2445534;-0.9941179;59.79977;6.179322;0;0;0;0.770247;0.7672957;54880.92;6226918
1464;0.2456248;-0.9904893;59.74642;6.173809;0;0;0;0.7736215;0.7706444;54831.95;6221571
1470;0.2465891;-0.9874154;59.75534;6.174731;0;0;0;0.7766587;0.7736582;54840.14;6222688
1476;0.2476606;-0.9838103;59.65482;6.164343;0;0;0;0.7800332;0.7770067;54747.88;6212427
1482;0.2486248;-0.9803668;59.75193;6.174379;0;0;0;0.7830703;0.7800202;54837.02;6222729
1488;0.2495891;-0.9772185;59.75384;6.174576;0;0;0;0.7861075;0.7830337;54838.77;6223115
1494;0.2505534;-0.9738616;59.72125;6.171208;0;0;0;0.7891446;0.7860471;54808.85;6219908
1500;0.2516248;-0.9708288;59.78917;6.178226;0;0;0;0.7925192;0.7893952;54871.19;6227190
1506;0.2525891;-0.9658156;59.72809;6.171915;0;0;0;0.7955563;0.7924084;54815.13;6221016
1512;0.2536605;-0.9603063;59.87703;6.187306;0;0;0;0.7989309;0.7957564;54951.82;6236738
1518;0.2546248;-0.9540206;59.78835;6.178142;0;0;0;0.8019679;0.7987692;54870.43;6227688
1524;0.2555891;-0.9477221;59.80033;6.17938;0;0;0;0.8050051;0.8017822;54881.43;6229124
1530;0.2565534;-0.9417296;59.91404;6.19113;0;0;0;0.8080422;0.8047951;54985.79;6241157
1536;0.2576248;-0.9354512;59.7917;6.178488;0;0;0;0.8114168;0.8081425;54873.51;6228621
1542;0.2585891;-0.9299463;59.78124;6.177407;0;0;0;0.8144539;0.8111551;54863.91;6227720
1548;0.2595534;-0.9242055;59.89486;6.189148;0;0;0;0.817491;0.8141677;54968.18;6239744
1554;0.2606248;-0.9177843;59.68868;6.167842;0;0;0;0.8208656;0.8175149;54778.96;6218472
1560;0.2615891;-0.9088208;59.86447;6.186007;0;0;0;0.8239027;0.8205271;54940.29;6236974
1566;0.2625534;-0.8994661;59.902;6.189886;0;0;0;0.8269399;0.8235394;54974.73;6241072
1572;0.2636248;-0.8895762;59.6648;6.165375;0;0;0;0.8303144;0.8268863;54757.05;6216567
1578;0.2645891;-0.8765087;60.16227;6.21678;0;0;0;0.8333516;0.8298984;55213.6;6268588
1584;0.2655534;-0.8646089;58.93452;6.089912;0;0;0;0.8363886;0.8329103;54086.83;6140848
1590;0.2666248;-0.8526935;59.93201;6.192987;0;0;0;0.8397632;0.8362568;55002.28;6244993
1596;0.2675891;-0.840783;59.87976;6.187588;0;0;0;0.8428004;0.8392686;54954.33;6239737
1602;0.268607;-0.8283054;59.87404;6.186996;0;0;0;0.8460062;0.8424477;54949.07;6239339
1608;0.2696248;-0.816697;60.45432;6.246958;0;0;0;0.849212;0.8456265;55481.62;6300008
1614;0.2705891;-0.8036059;59.97051;6.196965;0;0;0;0.8522492;0.848638;55037.61;6249778
1620;0.271607;-0.7870133;60.23695;6.224497;0;0;0;0.855455;0.8518167;55282.14;6277745
1626;0.2726248;-0.7702546;59.66081;6.164962;0;0;0;0.8586608;0.8549953;54753.38;6217899
1632;0.2735891;-0.749069;60.0838;6.208672;0;0;0;0.861698;0.8580065;55141.58;6262172
1638;0.2746605;-0.728367;60.25478;6.226339;0;0;0;0.8650725;0.8613523;55298.5;6280202
1644;0.2755713;-0.7059507;59.77457;6.176718;0;0;0;0.867941;0.864196;54857.79;6230328
1650;0.2765355;-0.6817077;59.8279;6.182229;0;0;0;0.870978;0.8672069;54906.73;6236075
1656;0.2775534;-0.6599583;59.94011;6.193824;0;0;0;0.8741839;0.870385;55009.71;6247970
1662;0.2786248;-0.6402944;59.95794;6.195666;0;0;0;0.8775585;0.8737304;55026.07;6250037
1668;0.2795891;-0.621906;59.96616;6.196516;0;0;0;0.8805956;0.8767409;55033.62;6251082
1674;0.2805534;-0.6031919;60.17082;6.217664;0;0;0;0.8836327;0.8797516;55221.45;6272605
1680;0.2816248;-0.5866137;60.50005;6.251684;0;0;0;0.8870073;0.8830965;55523.59;6307137
1686;0.2825891;-0.566812;60.32989;6.234101;0;0;0;0.8900445;0.8861069;55367.43;6289588
1692;0.2835534;-0.5478017;59.86816;6.186389;0;0;0;0.8930815;0.8891172;54943.68;6241639
1698;0.2846248;-0.5278548;59.92161;6.191912;0;0;0;0.8964561;0.8924618;54992.73;6247420
1704;0.2855891;-0.5069345;60.14001;6.21448;0;0;0;0.8994932;0.8954719;55193.17;6270379
1710;0.2865534;-0.4819533;63.14114;6.524598;0;0;0;0.9025304;0.8984819;57947.44;6583484
1716;0.2876248;-0.4681591;59.86561;6.186126;0;0;0;0.9059049;0.9018262;54941.34;6242166
1722;0.2885891;-0.4500625;59.94799;6.194638;0;0;0;0.908942;0.904836;55016.94;6250943
1728;0.2895534;-0.4360424;60.21149;6.221866;0;0;0;0.9119791;0.9078457;55258.77;6278608
1734;0.2906248;-0.4227464;60.33682;6.234818;0;0;0;0.9153537;0.9111897;55373.79;6291888
1740;0.2915891;-0.4094932;59.98032;6.197978;0;0;0;0.9183909;0.9141993;55046.61;6254900
1746;0.2925534;-0.3901537;60.06689;6.206924;0;0;0;0.921428;0.9172088;55126.06;6264117
1752;0.2935712;-0.3760504;59.77352;6.176609;0;0;0;0.9246339;0.9203853;54856.82;6233720
1758;0.2945891;-0.3615701;59.99259;6.199247;0;0;0;0.9278397;0.9235617;55057.88;6256766
1764;0.2955534;-0.3524451;59.8793;6.18754;0;0;0;0.9308768;0.9265708;54953.9;6245138
1770;0.2966248;-0.3394712;60.2502;6.225866;0;0;0;0.9342514;0.9299143;55294.29;6284031
1776;0.2975891;-0.3276644;60.16007;6.216553;0;0;0;0.9372885;0.9329232;55211.58;6274820
1782;0.2986605;-0.3135776;60.01749;6.20182;0;0;0;0.940663;0.9362663;55080.73;6260158
1788;0.2996248;-0.2985242;59.99576;6.199574;0;0;0;0.9437002;0.9392751;55060.79;6258080
1794;0.3005891;-0.2860509;60.0678;6.207018;0;0;0;0.9467373;0.9422839;55126.9;6265782
1800;0.3015534;-0.2702431;60.15945;6.216489;0;0;0;0.9497744;0.9452924;55211.02;6275532
1806;0.3026248;-0.256917;60.34352;6.23551;0;0;0;0.953149;0.9486352;55379.94;6294943
1812;0.3035891;-0.2462056;59.85111;6.184627;0;0;0;0.9561861;0.9516436;54928.03;6243763
1818;0.3046605;-0.2320643;60.86747;6.289651;0;0;0;0.9595608;0.9549862;55860.8;6350005
1824;0.3056248;-0.2205772;60.30141;6.231158;0;0;0;0.9625977;0.9579943;55341.29;6291139
1830;0.3065891;-0.2120275;59.18578;6.115876;0;0;0;0.9656349;0.9610025;54317.43;6174933
1836;0.3075533;-0.2038011;58.78264;6.074218;0;0;0;0.968672;0.9640104;53947.45;6133057
1842;0.3086248;-0.195946;58.43585;6.038383;0;0;0;0.9720465;0.9673525;53629.18;6097079
1848;0.3095891;-0.1884783;59.49894;6.148236;0;0;0;0.9750837;0.9703605;54604.83;6208187
1854;0.3105534;-0.1765097;60.09608;6.209941;0;0;0;0.9781209;0.9733682;55152.85;6270681
1860;0.3116248;-0.1701232;60.43012;6.244458;0;0;0;0.9814954;0.97671;55459.41;6305747
1866;0.3125891;-0.1610204;60.10536;6.210899;0;0;0;0.9845325;0.9797176;55161.37;6272048
1872;0.3135534;-0.1489141;60.33442;6.234569;0;0;0;0.9875696;0.982725;55371.59;6296140
1878;0.3146248;-0.1354901;60.41473;6.242868;0;0;0;0.9909443;0.9860666;55445.29;6304732
1884;0.3155891;-0.1235308;59.96425;6.196319;0;0;0;0.9939813;0.9890738;55031.87;6257909
1890;0.3165534;-0.1114114;60.17205;6.217791;0;0;0;0.9970185;0.9920811;55222.57;6279783
1896;0.3176248;-0.1003849;60.01144;6.201195;0;0;0;1.000393;0.9954223;55075.18;6263231
1902;0.318589;-0.09300733;59.41416;6.139476;0;0;0;1.00343;0.9984291;54527.03;6201081
1908;0.3195534;-0.08205697;59.39513;6.137509;0;0;0;1.006467;1.001436;54509.56;6199281
1914;0.3206248;-0.07318035;59.82314;6.181737;0;0;0;1.009842;1.004777;54902.37;6244163
1920;0.3215891;-0.06584643;60.1613;6.21668;0;0;0;1.012879;1.007784;55212.71;6279647
1926;0.3225534;-0.05439268;60.18074;6.218689;0;0;0;1.015916;1.01079;55230.55;6281866
1932;0.3236248;-0.0435513;60.20614;6.221314;0;0;0;1.019291;1.014131;55253.86;6284727
1938;0.3245891;-0.03105347;61.08155;6.311773;0;0;0;1.022328;1.017137;56057.27;6376300
1944;0.3256605;-0.01690852;60.08645;6.208945;0;0;0;1.025702;1.020478;55144.01;6272631
1950;0.3266248;-0.0101868;59.62249;6.161003;0;0;0;1.028739;1.023484;54718.21;6224384
1956;0.3275891;-0.00103705;60.25193;6.226045;0;0;0;1.031777;1.02649;55295.88;6290284
1962;0.3286605;0.008508128;59.95068;6.194916;0;0;0;1.035151;1.02983;55019.41;6259043
1968;0.3296248;0.01623302;59.96319;6.196209;0;0;0;1.038188;1.032836;55030.89;6260537
1974;0.3305891;0.02361108;60.14266;6.214754;0;0;0;1.041225;1.035842;55195.6;6279463
1980;0.3315533;0.03383039;59.66069;6.16495;0;0;0;1.044263;1.038848;54753.27;6229329
1986;0.3326248;0.04204424;60.80058;6.282739;0;0;0;1.047637;1.042187;55799.4;6348559
1992;0.3335891;0.05098207;60.95152;6.298337;0;0;0;1.050674;1.045193;55937.93;6364512
1998;0.3345534;0.06187983;61.24786;6.328958;0;0;0;1.053711;1.048199;56209.89;6395647
2004;0.3356248;0.06890338;60.89729;6.292732;0;0;0;1.057086;1.051538;55888.16;6359252
2010;0.336589;0.0756153;60.63592;6.265725;0;0;0;1.060123;1.054543;55648.29;6332149
2016;0.3375534;0.07993888;60.047;6.20487;0;0;0;1.06316;1.057548;55107.81;6270837
2022;0.3386248;0.0879409;60.22182;6.222934;0;0;0;1.066535;1.060887;55268.25;6289304
2028;0.3395891;0.09136487;58.43835;6.038641;0;0;0;1.069572;1.063892;53631.48;6103229
2034;0.3405533;0.09780696;58.92266;6.088686;0;0;0;1.072609;1.066897;54075.95;6153994
2040;0.3416248;0.1032235;59.73117;6.172234;0;0;0;1.075984;1.070236;54817.96;6238646
2046;0.3425891;0.1086551;60.50644;6.252345;0;0;0;1.079021;1.073241;55529.46;6319809
2052;0.3435533;0.1154964;60.22291;6.223047;0;0;0;1.082058;1.076245;55269.25;6290384
2058;0.3446248;0.123289;60.63622;6.265755;0;0;0;1.085432;1.079584;55648.56;6333766
2064;0.3455891;0.1276913;60.31309;6.232366;0;0;0;1.08847;1.082588;55352.02;6300203
2070;0.3465534;0.1327484;60.24969;6.225814;0;0;0;1.091507;1.085593;55293.83;6293769
2076;0.3476248;0.1371395;60.06492;6.206721;0;0;0;1.094881;1.088931;55124.26;6274677
2082;0.3485891;0.1406747;60.19918;6.220595;0;0;0;1.097918;1.091935;55247.48;6288892
2088;0.3496605;0.1455717;60.0732;6.207577;0;0;0;1.101293;1.095273;55131.86;6275941
2094;0.3506248;0.1478788;59.90587;6.190286;0;0;0;1.10433;1.098277;54978.29;6258647
2100;0.351589;0.1513169;59.96652;6.196552;0;0;0;1.107367;1.101281;55033.95;6265171
2106;0.3525534;0.1558515;60.17578;6.218176;0;0;0;1.110404;1.104285;55226;6287223
2112;0.3536248;0.1604897;60.51367;6.253091;0;0;0;1.113779;1.107622;55536.09;6322737
2118;0.354589;0.164592;60.76869;6.279443;0;0;0;1.116816;1.110625;55770.13;6349573
2124;0.3556605;0.1690148;60.39764;6.241102;0;0;0;1.120191;1.113963;55429.61;6311014
2130;0.3566248;0.1728014;58.20891;6.014932;0;0;0;1.123228;1.116966;53420.91;6082494
2136;0.3575891;0.1757868;59.58548;6.157179;0;0;0;1.126265;1.11997;54684.25;6226525
2142;0.3585533;0.1786223;60.06724;6.206961;0;0;0;1.129302;1.122973;55126.38;6277056
2148;0.3596248;0.1819851;60.14195;6.214681;0;0;0;1.132676;1.12631;55194.95;6285073
2154;0.3605891;0.1835589;59.67552;6.166482;0;0;0;1.135714;1.129313;54766.88;6236516
2160;0.3615533;0.1862617;59.85942;6.185485;0;0;0;1.138751;1.132316;54935.66;6255923
2166;0.3626247;0.1898493;60.09904;6.210247;0;0;0;1.142125;1.135652;55155.57;6281176
2172;0.3635891;0.1935318;60.41397;6.242789;0;0;0;1.145162;1.138655;55444.59;6314280
2178;0.3645533;0.1964826;60.34733;6.235904;0;0;0;1.1482;1.141658;55383.44;6307504
2184;0.3656248;0.1990269;60.2918;6.230165;0;0;0;1.151574;1.144994;55332.48;6301911
2190;0.366589;0.1970005;60.31321;6.232378;0;0;0;1.154611;1.147997;55352.13;6304338
2196;0.3675533;1.349718;60.11972;6.212383;0;0;0;1.157648;1.150999;55174.55;6284301
2202;0.3686248;1.349044;60.16553;6.217117;0;0;0;1.161023;1.154335;55216.59;6289300
2208;0.369589;1.350037;60.10439;6.2108;0;0;0;1.16406;1.157337;55160.48;6283097
2214;0.3705533;1.348587;59.39002;6.136981;0;0;0;1.167097;1.160339;54504.88;6208606
2220;0.3716248;1.349076;59.44338;6.142495;0;0;0;1.170472;1.163675;54553.84;6214391
2226;0.372589;1.350968;59.49721;6.148057;0;0;0;1.173509;1.166677;54603.24;6220205
2232;0.3735533;1.351261;60.32161;6.233245;0;0;0;1.176546;1.169678;55359.83;6306582
2238;0.3745712;1.351898;61.13586;6.317384;0;0;0;1.179752;1.172847;56107.1;6391914
2244;0.375589;1.352207;61.14975;6.31882;0;0;0;1.182958;1.176015;56119.85;6393569
2250;0.3766605;1.349685;60.16923;6.2175;0;0;0;1.186332;1.17935;55219.99;6291260
2256;0.3776247;1.351037;60.23495;6.224291;0;0;0;1.189369;1.182352;55280.3;6298321
2262;0.378589;1.350065;59.8951;6.189172;0;0;0;1.192406;1.185353;54968.4;6262972
2268;0.3796605;1.350284;59.73787;6.172925;0;0;0;1.195781;1.188688;54824.1;6246740
2274;0.3805712;1.349753;59.70589;6.169621;0;0;0;1.198649;1.191522;54794.76;6243573
2280;0.3815891;1.349716;59.81172;6.180557;0;0;0;1.201855;1.19469;54891.89;6254839
2286;0.3825533;1.350363;60.2215;6.222901;0;0;0;1.204892;1.197691;55267.96;6297880
2292;0.3836247;1.352226;60.7565;6.278184;0;0;0;1.208267;1.201026;55758.95;6354041
2298;0.3845355;1.353505;60.47035;6.248616;0;0;0;1.211135;1.20386;55496.34;6324295
2304;0.3855533;1.354069;60.507;6.252403;0;0;0;1.214341;1.207027;55529.98;6328328
2310;0.3866247;1.352287;60.93241;6.296361;0;0;0;1.217716;1.210361;55920.39;6373033
2316;0.387589;1.351112;60.41858;6.243266;0;0;0;1.220753;1.213362;55448.82;6319481
2322;0.3885533;1.351565;59.98443;6.198403;0;0;0;1.22379;1.216362;55050.38;6274259
2328;0.3896248;1.350273;59.8926;6.188914;0;0;0;1.227165;1.219696;54966.11;6264862
2334;0.390589;1.350375;60.18315;6.218938;0;0;0;1.230202;1.222696;55232.76;6295443
2340;0.3915533;1.351952;60.01726;6.201796;0;0;0;1.233239;1.225696;55080.51;6278278
2346;0.3926248;1.351806;60.16527;6.21709;0;0;0;1.236613;1.22903;55216.35;6293971
2352;0.393589;1.353177;60.28085;6.229034;0;0;0;1.23965;1.23203;55322.43;6306252
2358;0.3945533;1.35353;60.33794;6.234933;0;0;0;1.242688;1.23503;55374.82;6312414
2364;0.3955712;1.354444;60.92533;6.29563;0;0;0;1.245893;1.238196;55913.89;6374067
2370;0.396589;1.352757;59.96492;6.196388;0;0;0;1.249099;1.241362;55032.48;6273787
2376;0.3976069;1.353497;60.27589;6.228521;0;0;0;1.252305;1.244529;55317.87;6306521
2382;0.3986247;1.353714;60.23249;6.224036;0;0;0;1.255511;1.247695;55278.04;6302180
2388;0.399589;1.353937;60.38328;6.239618;0;0;0;1.258548;1.250694;55416.43;6318147
2394;0.4006605;1.352149;59.16252;6.113472;0;0;0;1.261923;1.254027;54296.08;6190620
2400;0.4016247;1.350869;59.88135;6.187752;0;0;0;1.26496;1.257026;54955.79;6266024
2406;0.402589;1.353749;60.06862;6.207103;0;0;0;1.267997;1.260025;55127.65;6285809
2412;0.4036069;1.354906;60.15496;6.216024;0;0;0;1.271203;1.263191;55206.89;6295043
2418;0.4046247;1.356695;60.57231;6.259151;0;0;0;1.274409;1.266356;55589.91;6338919
2424;0.405589;1.356452;60.76839;6.279413;0;0;0;1.277446;1.269355;55769.86;6359629
2430;0.4066604;1.356673;60.73436;6.275896;0;0;0;1.28082;1.272687;55738.63;6356279
2436;0.4076248;1.355679;60.21762;6.2225;0;0;0;1.283857;1.275686;55264.4;6302388
2442;0.408589;1.356164;60.2373;6.224534;0;0;0;1.286894;1.278684;55282.46;6304637
2448;0.4095533;1.356682;60.08048;6.208329;0;0;0;1.289932;1.281683;55138.54;6288412
2454;0.4106247;1.356608;60.19252;6.219906;0;0;0;1.293306;1.285014;55241.36;6300349
2460;0.411589;1.35726;60.24611;6.225444;0;0;0;1.296343;1.288013;55290.54;6306147
2466;0.4125533;1.357165;60.28664;6.229631;0;0;0;1.299381;1.291011;55327.73;6310578
2472;0.4136247;1.357493;60.61833;6.263906;0;0;0;1.302755;1.294342;55632.14;6345510
2478;0.414589;1.35822;61.61825;6.367232;0;0;0;1.305792;1.29734;56549.82;6450375
2484;0.4155533;1.359449;61.83989;6.390134;0;0;0;1.308829;1.300338;56753.22;6473770
2490;0.4166247;1.358314;60.40287;6.241642;0;0;0;1.312204;1.303669;55434.41;6323546
2496;0.417589;1.358895;60.3178;6.232852;0;0;0;1.315241;1.306667;55356.33;6314828
2502;0.4185533;1.358756;60.42428;6.243855;0;0;0;1.318278;1.309664;55454.06;6326166
2508;0.4195712;1.359474;60.41697;6.243099;0;0;0;1.321484;1.312829;55447.34;6325601
2514;0.4206426;1.359693;60.28444;6.229404;0;0;0;1.324859;1.316159;55325.71;6311935
2520;0.4215533;1.359864;60.31257;6.232311;0;0;0;1.327727;1.31899;55351.54;6315060
2526;0.4226247;1.360541;60.27589;6.228521;0;0;0;1.331102;1.32232;55317.87;6311429
2532;0.423589;1.360549;60.41332;6.242723;0;0;0;1.334139;1.325317;55444;6326009
2538;0.4245533;1.362259;60.7641;6.27897;0;0;0;1.337176;1.328314;55765.93;6362931
2544;0.4256247;1.362829;60.68276;6.270564;0;0;0;1.34055;1.331645;55691.27;6354624
2550;0.426589;1.361246;60.55217;6.25707;0;0;0;1.343587;1.334641;55571.43;6341139
2556;0.4276604;1.361572;60.24376;6.225201;0;0;0;1.346962;1.337971;55288.39;6309052
2562;0.4286247;1.36191;60.47664;6.249265;0;0;0;1.349999;1.340968;55502.11;6333630
2568;0.429589;1.362396;60.43634;6.245101;0;0;0;1.353036;1.343964;55465.13;6329600
2574;0.4306604;1.362254;60.42557;6.243989;0;0;0;1.356411;1.347294;55455.24;6328683
2580;0.4316247;1.362378;59.96199;6.196085;0;0;0;1.359448;1.35029;55029.79;6280317
2586;0.432589;1.361165;60.35025;6.236205;0;0;0;1.362485;1.353287;55386.11;6321172
2592;0.4335533;1.362424;60.51264;6.252985;0;0;0;1.365522;1.356283;55535.15;6338371
2598;0.4346247;1.363752;60.64814;6.266987;0;0;0;1.368897;1.359612;55659.5;6352776
2604;0.435589;1.362144;60.48298;6.249921;0;0;0;1.371934;1.362608;55507.93;6335665
2610;0.4365533;1.361798;60.38225;6.239512;0;0;0;1.374971;1.365604;55415.48;6325303
2616;0.4376247;1.362732;60.91802;6.294874;0;0;0;1.378345;1.368933;55907.18;6381639
2622;0.438589;1.36144;60.57695;6.259631;0;0;0;1.381383;1.371929;55594.17;6346100
2628;0.4395533;1.361487;60.39744;6.241081;0;0;0;1.38442;1.374924;55429.42;6327484
2634;0.4406247;1.361125;60.49074;6.250722;0;0;0;1.387794;1.378253;55515.05;6337469
2640;0.4416426;1.36089;60.3533;6.23652;0;0;0;1.391;1.381415;55388.91;6323270
2646;0.4426068;1.360531;60.44155;6.245639;0;0;0;1.394037;1.38441;55469.9;6332706
2652;0.4435712;1.360527;60.76866;6.27944;0;0;0;1.397074;1.387405;55770.11;6367169
2658;0.444589;1.360509;60.48618;6.250251;0;0;0;1.40028;1.390567;55510.87;6337772
2664;0.4455533;1.360632;60.54794;6.256633;0;0;0;1.403317;1.393562;55567.55;6344434
2670;0.4466247;1.360449;60.57158;6.259076;0;0;0;1.406692;1.39689;55589.24;6347122
2676;0.447589;1.360174;60.57628;6.259562;0;0;0;1.409729;1.399885;55593.55;6347804
2682;0.4486604;1.360027;60.49361;6.251019;0;0;0;1.413104;1.403212;55517.69;6339353
2688;0.4496247;1.359811;60.62367;6.264459;0;0;0;1.416141;1.406207;55637.05;6353172
2694;0.450589;1.35958;60.53261;6.255049;0;0;0;1.419178;1.409202;55553.48;6343819
2700;0.4516605;1.357497;60.47297;6.248886;0;0;0;1.422553;1.412529;55498.74;6337779
2706;0.4526247;1.357337;60.4589;6.247432;0;0;0;1.42559;1.415524;55485.83;6336495
2712;0.453589;1.359388;60.6432;6.266477;0;0;0;1.428627;1.418518;55654.97;6356001
2718;0.4545533;1.359265;60.47496;6.249092;0;0;0;1.431664;1.421512;55500.57;6338558
2724;0.4556247;1.359324;60.76135;6.278685;0;0;0;1.435038;1.424839;55763.39;6368786
2730;0.456589;1.359123;60.4779;6.249396;0;0;0;1.438076;1.427833;55503.27;6339267
2736;0.4576604;1.359109;60.43734;6.245204;0;0;0;1.44145;1.43116;55466.04;6335226
2742;0.4586247;1.358988;60.53332;6.255122;0;0;0;1.444487;1.434154;55554.12;6345476
2748;0.459589;1.358935;60.59287;6.261276;0;0;0;1.447524;1.437148;55608.78;6351909
2754;0.4605533;1.364017;61.6969;6.375359;0;0;0;1.450562;1.440141;56622;6467837
2760;0.4616247;1.357675;60.65786;6.267991;0;0;0;1.453936;1.443468;55668.42;6359124
2766;0.462589;1.358681;60.62805;6.264911;0;0;0;1.456973;1.446461;55641.07;6356189
2772;0.4635533;1.358805;60.45784;6.247323;0;0;0;1.46001;1.449455;55484.86;6338535
2778;0.4646247;1.358643;60.77503;6.280099;0;0;0;1.463385;1.452781;55775.95;6372001
2784;0.465589;1.358716;60.59328;6.261318;0;0;0;1.466422;1.455774;55609.16;6353136
2790;0.4665533;1.358632;60.79348;6.282005;0;0;0;1.469459;1.458767;55792.88;6374317
2796;0.4675711;1.359335;60.62191;6.264277;0;0;0;1.472665;1.461927;55635.43;6356529
2802;0.468589;1.359096;60.51937;6.25368;0;0;0;1.475871;1.465086;55541.32;6345977
2808;0.4695533;1.358217;60.2721;6.228129;0;0;0;1.478908;1.468079;55314.39;6320238
2814;0.4705711;1.358553;60.76384;6.278943;0;0;0;1.482114;1.471238;55765.68;6372004
2820;0.471589;1.358699;60.80704;6.283407;0;0;0;1.48532;1.474397;55805.33;6376735
2826;0.4725533;1.358707;60.50313;6.252002;0;0;0;1.488357;1.477389;55526.42;6345054
2832;0.4736247;1.358818;60.6225;6.264338;0;0;0;1.491731;1.480714;55635.97;6357784
2838;0.474589;1.358767;60.74249;6.276737;0;0;0;1.494769;1.483707;55746.09;6370559
2844;0.4756068;1.3588;60.69845;6.272185;0;0;0;1.497974;1.486865;55705.67;6366141
2850;0.4766247;1.361518;61.31555;6.335953;0;0;0;1.50118;1.490024;56272.02;6431067
2856;0.477589;1.36022;60.41981;6.243393;0;0;0;1.504217;1.493016;55449.95;6337307
2862;0.4786604;1.043364;60.5714;6.259058;0;0;0;1.507592;1.496341;55589.08;6353419
2868;0.4796247;1.004083;60.58494;6.260457;0;0;0;1.510629;1.499333;55601.5;6355029
2874;0.480589;1.380993;60.60201;6.26222;0;0;0;1.513666;1.502324;55617.16;6357009
2880;0.4816604;1.35671;60.66649;6.268883;0;0;0;1.517041;1.505649;55676.34;6363985
2886;0.4826247;1.36411;60.63478;6.265606;0;0;0;1.520078;1.50864;55647.24;6360848
2892;0.483589;1.17149;60.67046;6.269293;0;0;0;1.523115;1.511632;55679.98;6364782
2898;0.4845533;1.437657;60.80877;6.283586;0;0;0;1.526152;1.514623;55806.92;6379483
2904;0.4856247;1.281644;60.83711;6.286514;0;0;0;1.529527;1.517947;55832.93;6382668
2910;0.486589;1.299613;60.74572;6.27707;0;0;0;1.532564;1.520939;55749.05;6373270
2916;0.4875533;0.8917659;60.4199;6.243402;0;0;0;1.535601;1.52393;55450.04;6339276
2922;0.4886247;1.082649;60.46172;6.247724;0;0;0;1.538975;1.527253;55488.42;6343874
2928;0.489589;1.083034;60.82252;6.285006;0;0;0;1.542012;1.530244;55819.54;6381922
2934;0.4905532;1.083065;60.79033;6.28168;0;0;0;1.545049;1.533235;55790;6378735
2940;0.4916246;1.09139;60.72711;6.275147;0;0;0;1.548424;1.536558;55731.97;6372313
2946;0.492589;1.0918;60.6943;6.271757;0;0;0;1.551461;1.539549;55701.87;6369061
2952;0.4935532;1.092081;60.71142;6.273526;0;0;0;1.554498;1.54254;55717.58;6371048
2958;0.4946247;1.09258;60.76211;6.278764;0;0;0;1.557873;1.545863;55764.09;6376579
2964;0.4955889;0.4308981;60.5134;6.253064;0;0;0;1.56091;1.548853;55535.85;6350669
2970;0.4965533;0.1900557;60.81658;6.284393;0;0;0;1.563947;1.551844;55814.09;6382677
2976;0.4976247;0.5677105;60.62394;6.264486;0;0;0;1.567322;1.555166;55637.29;6362671
2982;0.498589;0.4062027;60.87208;6.290128;0;0;0;1.570359;1.558156;55865.03;6388906
2988;0.4995532;0.4188487;60.87027;6.28994;0;0;0;1.573396;1.561146;55863.36;6388906
2994;0.5006247;0.9444021;60.67178;6.26943;0;0;0;1.576771;1.564469;55681.2;6368284
3000;0.5015889;0.9206092;60.92342;6.295432;0;0;0;1.579808;1.567459;55912.14;6394888
3006;0.5026604;0.958125;60.83256;6.286043;0;0;0;1.583182;1.570781;55828.75;6385563
3012;0.5036247;0.9911964;60.7797;6.280581;0;0;0;1.586219;1.57377;55780.24;6380206
3012.632;0.5037318;0.9893595;60.66071;6.268286;0;0;0;1.586557;1.574103;55671.04;6367735