File: Ensayos/Resistencia/comp/EsponjaB/REB6_comp.raw
"Test Type";"Manual"
"Method Name:";"C:\INSTRON\user\template\CYCLE.MTM"
"Name:";""
"Operator ID:";""
"Company:";""
"Lab name:";""
"Test date:";"12/05/2017"
"Temperature:";""
"Humidity:";""
"Note 1:";""
"Note 2:";""
"Note 3:";""
"Geometry:";"Rectangular"
"Specimen";1
"Specimen name:";""
"Width:";0.250000;"in"
"Thickness:";0.060000;"in"
"Length:";1.250000;"in"
"Diameter:";0.039370;"in"
"Inner diameter:";0.019685;"in"
"Outer diameter:";0.039370;"in"
"Wall thickness:";0.019685;"in"
"Area:";0.015000;"in*in"
"Linear density:";1.000000;"den"
"Sled weight:";2.204623;"lbf"
"Loading span:";0.000000;"mm"
"Support span:";1.000000;"mm"
"Span ratio:";"2"
"Fixture type:";"3-point"
"Comment:";""
"Included"
"Final Width:";0.250000;"in"
"Final Thickness:";0.060000;"in"
"Final Length:";1.250000;"in"
"Final Diameter:";0.039370;"in"
"Final Inner diameter:";0.019685;"in"
"Final Outer diameter:";0.039370;"in"
"Final Wall thickness:";0.019685;"in"
"Final Area:";0.015000;"in*in"
"Final Linear density:";1.000000;"den"
"Time sec";"Extension mm";"Strain 1 %";"Load N";"Stress MPa";"Cycle Count ";"Total Cycle Count ";"Repetitions Count ";"Strain [Exten.] %";"True strain %";"Tenacity gf/tex";"True stress Pa"
0;0.5036782;-0.00577362;62.73656;6.482791;0;0;0;1.586388;1.573937;57576.14;6585633
20;0.5070532;-0.01152044;61.36488;6.341051;0;0;0;1.597018;1.5844;56317.29;6442318
40;0.5103747;-0.01303381;61.20275;6.324297;0;0;0;1.607479;1.594696;56168.49;6425959
60;0.5136961;-0.009028765;62.74934;6.484111;0;0;0;1.61794;1.604991;57587.86;6589020
80;0.5170175;-0.01470542;61.09169;6.31282;0;0;0;1.628402;1.615285;56066.57;6415619
100;0.5203389;-0.01511489;61.31989;6.336402;0;0;0;1.638863;1.625578;56276;6440247
120;0.5236604;-0.01769151;59.7415;6.173301;0;0;0;1.649324;1.63587;54827.44;6275119
140;0.5269818;-0.01487605;61.39349;6.344007;0;0;0;1.659785;1.646161;56343.54;6449303
160;0.5304104;-0.01380857;61.41255;6.345976;0;0;0;1.670584;1.656783;56361.04;6451991
180;0.5337318;0.01049266;121.3965;12.54433;0;0;0;1.681045;1.667072;111410.9;1.27552e+007
200;0.5370532;-0.01210713;62.08427;6.415388;0;0;0;1.691506;1.67736;56977.51;6523905
220;0.5403747;-0.01085705;61.25784;6.329989;0;0;0;1.701967;1.687646;56219.05;6437724
240;0.543696;-0.009269795;61.49879;6.354888;0;0;0;1.712428;1.697932;56440.18;6463711
260;0.5470175;-0.005892313;61.87459;6.393721;0;0;0;1.72289;1.708216;56785.07;6503878
280;0.5503925;-0.004846815;61.01827;6.305234;0;0;0;1.73352;1.718666;55999.19;6414536
300;0.5536603;-0.003781719;61.4351;6.348306;0;0;0;1.743812;1.728782;56381.73;6459009
320;0.5570889;-0.001194278;62.08956;6.415934;0;0;0;1.754611;1.739395;56982.36;6528509
340;0.5604103;0.0001885595;61.71443;6.377171;0;0;0;1.765072;1.749675;56638.09;6489732
360;0.5637318;0.001252872;60.79118;6.281768;0;0;0;1.775533;1.759955;55790.78;6393303
380;0.5670532;0.00414798;61.70686;6.376388;0;0;0;1.785994;1.770233;56631.14;6490270
400;0.5703746;0.005690237;61.70703;6.376406;0;0;0;1.796456;1.78051;56631.3;6490955
420;0.5736961;0.005969368;61.43419;6.348212;0;0;0;1.806917;1.790786;56380.89;6462919
440;0.5770175;0.006098566;61.68125;6.373742;0;0;0;1.817378;1.801061;56607.64;6489577
460;0.5803389;0.005888228;64.09347;6.623005;0;0;0;1.827839;1.811335;58821.43;6744063
480;0.5836603;0.007091027;61.84949;6.391127;0;0;0;1.8383;1.821608;56762.04;6508615
500;0.5870353;0.007827407;62.11866;6.418941;0;0;0;1.84893;1.832045;57009.07;6537623
520;0.5904103;0.007903922;61.61679;6.367081;0;0;0;1.85956;1.842482;56548.47;6485481
540;0.5937318;0.007998429;61.31804;6.33621;0;0;0;1.870021;1.852751;56274.3;6454699
560;0.5970532;0.007555331;61.8884;6.395147;0;0;0;1.880483;1.86302;56797.74;6515407
580;0.6003746;0.005781177;61.83681;6.389816;0;0;0;1.890944;1.873287;56750.39;6510644
600;0.6036961;0.002822685;61.81786;6.387858;0;0;0;1.901405;1.883554;56733.01;6509318
620;0.6070175;0.003946383;63.39182;6.550501;0;0;0;1.911866;1.89382;58177.5;6675738
640;0.6103925;0.009940234;61.87959;6.394237;0;0;0;1.922496;1.904249;56789.66;6517166
660.0001;0.6136603;0.02542646;61.7174;6.377477;0;0;0;1.932788;1.914347;56640.81;6500740
680.0001;0.6169818;0.04319196;61.77108;6.383024;0;0;0;1.94325;1.92461;56690.07;6507062
700.0001;0.6203567;0.06111099;61.82773;6.388878;0;0;0;1.953879;1.935036;56742.06;6513709
720.0001;0.6237318;0.07896041;61.9617;6.402721;0;0;0;1.964509;1.945462;56865.01;6528504
740.0001;0.6270532;0.09375286;61.86822;6.393063;0;0;0;1.974971;1.955721;56779.23;6519324
760.0001;0.630321;0.1041365;61.79243;6.385231;0;0;0;1.985263;1.965814;56709.67;6511994
780.0001;0.633696;0.1142491;61.91312;6.397702;0;0;0;1.995893;1.976236;56820.43;6525394
800.0001;0.6370174;0.1191037;62.34654;6.442489;0;0;0;2.006354;1.986492;57218.2;6571748
820.0001;0.6403388;0.1209628;61.8871;6.395014;0;0;0;2.016815;1.996747;56796.55;6523989
840.0001;0.6436603;0.1235744;62.01318;6.408041;0;0;0;2.027277;2.007001;56912.26;6537950
860.0001;0.6470353;0.1241635;61.80174;6.386193;0;0;0;2.037906;2.017419;56718.21;6516337
880.0001;0.6503567;0.1234205;62.18976;6.426288;0;0;0;2.048368;2.027671;57074.32;6557922
900.0001;0.6536781;0.1235821;61.88476;6.394771;0;0;0;2.058829;2.037921;56794.4;6526428
920.0001;0.6570531;0.1229968;63.65053;6.577235;0;0;0;2.069458;2.048336;58414.93;6713348
940.0001;0.6603746;0.1209086;62.1798;6.425259;0;0;0;2.07992;2.058585;57065.18;6558899
960.0001;0.663696;0.1208491;61.93856;6.40033;0;0;0;2.090381;2.068833;56843.77;6534121
980.0001;0.6670174;0.1203937;62.09593;6.416593;0;0;0;2.100842;2.079079;56988.21;6551395
1000;0.6703388;0.1206663;62.05552;6.412417;0;0;0;2.111304;2.089324;56951.12;6547803
1020;0.6736603;0.1184501;62.13522;6.420652;0;0;0;2.121765;2.099569;57024.27;6556884
1040;0.6770888;0.117273;61.92061;6.398476;0;0;0;2.132563;2.110142;56827.3;6534927
1060;0.6803031;0.1157729;62.24294;6.431783;0;0;0;2.142687;2.120054;57123.12;6569596
1080;0.6837317;0.1145688;62.26995;6.434575;0;0;0;2.153486;2.130626;57147.91;6573143
1100;0.6870531;0.1116844;62.1359;6.420722;0;0;0;2.163947;2.140866;57024.89;6559664
1120;0.6903746;0.1088503;62.14436;6.421597;0;0;0;2.174408;2.151105;57032.65;6561228
1140;0.693696;0.1063252;62.35776;6.443648;0;0;0;2.184869;2.161343;57228.5;6584434
1160;0.6970174;0.1044533;62.22459;6.429887;0;0;0;2.19533;2.17158;57106.28;6571044
1180;0.7003389;0.1028254;62.10462;6.41749;0;0;0;2.205792;2.181816;56996.18;6559047
1200;0.7036603;0.101892;62.12685;6.419788;0;0;0;2.216253;2.192051;57016.59;6562067
1220;0.7070888;0.1006592;58.57992;6.05327;0;0;0;2.227051;2.202615;53761.41;6188080
1240;0.7104102;0.1009438;62.13396;6.420522;0;0;0;2.237513;2.212848;57023.11;6564182
1260;0.7136781;0.1008455;61.99556;6.40622;0;0;0;2.247805;2.222914;56896.09;6550220
1280;0.7170531;0.101121;62.2773;6.435333;0;0;0;2.258435;2.23331;57154.65;6580671
1300;0.7203746;0.1009195;62.13922;6.421065;0;0;0;2.268896;2.24354;57027.93;6566753
1320;0.7236959;0.09667894;60.88418;6.291378;0;0;0;2.279357;2.253768;55876.13;6434781
1340;0.7270174;0.1011302;62.47796;6.456069;0;0;0;2.289819;2.263996;57338.81;6603901
1360;0.7303389;0.1007533;62.17745;6.425016;0;0;0;2.30028;2.274222;57063.02;6572810
1380;0.7336602;0.09975067;62.18239;6.425526;0;0;0;2.310741;2.284447;57067.55;6574003
1400;0.7370888;0.09907784;62.35506;6.443369;0;0;0;2.32154;2.295002;57226.02;6592954
1420;0.7404102;0.0982729;62.3124;6.438961;0;0;0;2.332;2.305225;57186.86;6589117
1440;0.7437317;0.09674185;62.18021;6.425302;0;0;0;2.342462;2.315447;57065.55;6575812
1460;0.7470531;0.09555955;62.21507;6.428904;0;0;0;2.352923;2.325669;57097.55;6580171
1480;0.7503745;0.09365836;62.39329;6.44732;0;0;0;2.363384;2.335889;57261.11;6599695
1500;0.7536959;0.09174152;62.35251;6.443106;0;0;0;2.373845;2.346108;57223.68;6596055
1520;0.7570174;0.08987376;62.32376;6.440135;0;0;0;2.384307;2.356326;57197.29;6593687
1540;0.7603387;0.08811795;62.35454;6.443315;0;0;0;2.394768;2.366543;57225.54;6597617
1560;0.7636602;0.08584155;62.41658;6.449727;0;0;0;2.405229;2.376759;57282.48;6604857
1580;0.7670888;0.08397709;62.4444;6.4526;0;0;0;2.416028;2.387303;57308.01;6608497
1600;0.7703566;0.08312915;62.35542;6.443406;0;0;0;2.42632;2.397353;57226.34;6599743
1620;0.7737317;0.08255093;62.35879;6.443754;0;0;0;2.43695;2.40773;57229.44;6600786
1640;0.7770531;0.08121529;62.39042;6.447022;0;0;0;2.447411;2.417942;57258.47;6604808
1660;0.7803209;0.07759564;62.49429;6.457756;0;0;0;2.457704;2.427988;57353.8;6616469
1680;0.7836959;0.07489398;62.15143;6.422328;0;0;0;2.468334;2.438363;57039.14;6580852
1700;0.7870173;0.07238634;62.50007;6.458354;0;0;0;2.478795;2.448571;57359.11;6618443
1720;0.7903387;0.06356202;63.04694;6.514863;0;0;0;2.489256;2.458779;57860.98;6677035
1740;0.7936602;0.04157785;61.50388;6.355413;0;0;0;2.499717;2.468985;56444.85;6514281
1760;0.7969816;0.01773674;62.51872;6.460281;0;0;0;2.510178;2.479191;57376.22;6622446
1780;0.8004102;-0.0048251;62.40234;6.448255;0;0;0;2.520977;2.489725;57269.41;6610814
1800;0.803678;-0.02575633;62.66115;6.474998;0;0;0;2.53127;2.499763;57506.93;6638898
1820;0.8069995;-0.02749956;62.43403;6.45153;0;0;0;2.541731;2.509966;57298.49;6615510
1840;0.8103745;-0.02484022;62.77988;6.487267;0;0;0;2.552361;2.520332;57615.89;6652845
1860;0.813696;-0.02329997;62.67783;6.476722;0;0;0;2.562822;2.530532;57522.23;6642708
1880;0.8170173;-0.02133092;62.69301;6.478291;0;0;0;2.573283;2.540731;57536.17;6644995
1900;0.8203388;-0.02135526;62.7666;6.485895;0;0;0;2.583744;2.550929;57603.71;6653474
1920;0.8236602;-0.02207855;62.4922;6.457541;0;0;0;2.594205;2.561127;57351.88;6625062
1940;0.8269816;-0.02234349;62.59962;6.46864;0;0;0;2.604666;2.571323;57450.46;6637127
1960;0.8303566;-0.02327739;62.68006;6.476953;0;0;0;2.615296;2.581682;57524.29;6646344
1980;0.8337316;-0.02481678;62.65007;6.473854;0;0;0;2.625926;2.592041;57496.77;6643853
2000;0.837053;-0.02557453;64.7607;6.691952;0;0;0;2.636387;2.602234;59433.78;6868378
2020;0.8403745;-0.02727855;62.87335;6.496925;0;0;0;2.646849;2.612426;57701.68;6668889
2040;0.8436959;-0.02920864;62.64036;6.47285;0;0;0;2.65731;2.622616;57487.85;6644854
2060;0.8470173;-0.0304397;62.76073;6.485288;0;0;0;2.667771;2.632806;57598.32;6658301
2080;0.8503388;-0.0320061;62.78951;6.488262;0;0;0;2.678232;2.642995;57624.73;6662033
2100;0.8536602;-0.03389707;62.75439;6.484633;0;0;0;2.688694;2.653183;57592.5;6658985
2120;0.8570352;-0.03506087;62.82137;6.491555;0;0;0;2.699323;2.663534;57653.98;6666783
2140;0.8604102;-0.03664154;62.80431;6.489791;0;0;0;2.709954;2.673884;57638.31;6665662
2160;0.8637315;-0.03863085;62.87954;6.497566;0;0;0;2.720414;2.684069;57707.36;6674326
2180;0.867053;-0.03999374;62.88856;6.498497;0;0;0;2.730876;2.694253;57715.64;6675963
2200;0.8703745;-0.04152934;62.79007;6.48832;0;0;0;2.741337;2.704435;57625.24;6666187
2220;0.8736958;-0.04352696;62.63986;6.472798;0;0;0;2.751798;2.714616;57487.39;6650916
2240;0.8770173;-0.04415045;62.83949;6.493427;0;0;0;2.762259;2.724797;57670.6;6672792
2260;0.8803388;-0.04466528;61.96916;6.403492;0;0;0;2.772721;2.734977;56871.86;6581043
2280;0.8836601;-0.04700283;62.87476;6.497071;0;0;0;2.783181;2.745155;57702.97;6677897
2300;0.8870888;-0.04799274;62.95793;6.505665;0;0;0;2.79398;2.755661;57779.3;6687433
2320;0.8904102;-0.04973248;62.13443;6.420571;0;0;0;2.804441;2.765837;57023.54;6600632
2340;0.8937316;-0.0515717;62.98852;6.508827;0;0;0;2.814903;2.776012;57807.38;6692044
2360;0.897053;-0.05188894;62.86762;6.496334;0;0;0;2.825364;2.786187;57696.42;6679879
2380;0.9003744;-0.05281194;62.97011;6.506924;0;0;0;2.835825;2.79636;57790.48;6691449
2400;0.9036958;-0.05437093;62.9038;6.500072;0;0;0;2.846286;2.806532;57729.63;6685083
2420;0.9070173;-0.05445309;62.89068;6.498716;0;0;0;2.856747;2.816703;57717.58;6684368
2440;0.9103923;-0.05494233;63.0627;6.516492;0;0;0;2.867377;2.827037;57875.45;6703345
2460;0.9136601;-0.05648866;63.00832;6.510872;0;0;0;2.87767;2.837042;57825.54;6698234
2480;0.9170351;-0.05656122;63.00485;6.510514;0;0;0;2.8883;2.847374;57822.36;6698558
2500;0.9204101;-0.05775194;63.15624;6.526157;0;0;0;2.898929;2.857705;57961.29;6715346
2520;0.9237316;-0.05856699;63.22069;6.532818;0;0;0;2.909391;2.867871;58020.45;6722883
2540;0.927053;-0.05853904;63.05245;6.515433;0;0;0;2.919852;2.878036;57866.05;6705674
2560;0.9303744;-0.05836775;63.25153;6.536005;0;0;0;2.930313;2.8882;58048.75;6727530
2580;0.9336958;-0.05919813;63.23626;6.534427;0;0;0;2.940774;2.898363;58034.74;6726590
2600;0.9370173;-0.05925152;63.10261;6.520617;0;0;0;2.951236;2.908525;57912.08;6713055
2620;0.9403387;-0.05997755;63.2569;6.53656;0;0;0;2.961697;2.918685;58053.68;6730153
2640;0.9436601;-0.06096895;63.34756;6.545928;0;0;0;2.972158;2.928845;58136.88;6740483
2660;0.9470887;-0.06038384;63.3349;6.54462;0;0;0;2.982957;2.939332;58125.27;6739843
2680;0.9504101;-0.06085892;63.22102;6.532852;0;0;0;2.993418;2.949489;58020.75;6728408
2700;0.9537316;-0.06203514;63.53048;6.564829;0;0;0;3.003879;2.959646;58304.75;6762029
2720;0.9569994;-0.06217018;63.8501;6.597857;0;0;0;3.014171;2.969638;58598.09;6796728
2740;0.9603208;-0.0610787;63.30542;6.541573;0;0;0;3.024632;2.979792;58098.21;6739432
2760;0.9636959;-0.0602956;63.3848;6.549776;0;0;0;3.035263;2.99011;58171.05;6748578
2780;0.9670173;-0.06083352;63.39038;6.550352;0;0;0;3.045724;3.000262;58176.18;6749858
2800;0.9703387;-0.06266835;63.52211;6.563965;0;0;0;3.056185;3.010414;58297.07;6764572
2820;0.9736601;-0.06445403;63.2804;6.538988;0;0;0;3.066646;3.020564;58075.25;6739515
2840;0.977035;-0.06426114;64.22723;6.636827;0;0;0;3.077276;3.030877;58944.19;6841060
2860;0.9803029;-0.06457735;63.41563;6.552961;0;0;0;3.087568;3.040862;58199.35;6755289
2880;0.9837315;-0.0659812;63.47795;6.559401;0;0;0;3.098367;3.051337;58256.54;6762635
2900;0.9870529;-0.07479791;64.86139;6.702358;0;0;0;3.108828;3.061483;59526.2;6910722
2920;0.9903744;-0.07600095;63.44059;6.555541;0;0;0;3.119289;3.071628;58222.26;6760027
2940;0.9936958;-0.07727807;63.49956;6.561634;0;0;0;3.12975;3.081772;58276.38;6766997
2960;0.9970171;-0.0777546;63.63347;6.575471;0;0;0;3.140211;3.091915;58399.27;6781955
2980;1.000339;-0.07878944;63.53022;6.564802;0;0;0;3.150673;3.102058;58304.51;6771638
3000;1.00366;-0.08079204;63.23165;6.53395;0;0;0;3.161134;3.112199;58030.51;6740497
3020;1.006981;-0.08116686;63.64126;6.576276;0;0;0;3.171595;3.122339;58406.42;6784849
3040;1.010357;-0.08196348;63.62988;6.575101;0;0;0;3.182225;3.132642;58395.98;6784336
3060;1.013731;-0.08395985;63.5706;6.568974;0;0;0;3.192855;3.142943;58341.57;6778713
3080;1.017053;-0.08481465;63.43401;6.554861;0;0;0;3.203316;3.15308;58216.22;6764834
3100;1.020374;-0.08630611;63.6562;6.577821;0;0;0;3.213778;3.163216;58420.14;6789217
3120;1.023696;-0.0879649;63.60149;6.572167;0;0;0;3.224239;3.173351;58369.92;6784069
3140;1.027017;-0.08877999;63.74956;6.587467;0;0;0;3.2347;3.183485;58505.81;6800552
3160;1.030339;-0.08964215;63.8995;6.602962;0;0;0;3.245161;3.193618;58643.42;6817238
3180;1.03366;-0.09116168;63.70633;6.583;0;0;0;3.255622;3.20375;58466.14;6797318
3200;1.036981;-0.09165377;63.68724;6.581028;0;0;0;3.266083;3.213881;58448.62;6795970
3220;1.04041;-0.09276363;63.74924;6.587434;0;0;0;3.276882;3.224337;58505.52;6803297
3240;1.043731;-0.09445998;63.83249;6.596037;0;0;0;3.287343;3.234466;58581.92;6812871
3260;1.047053;-0.0928777;63.72466;6.584894;0;0;0;3.297805;3.244594;58482.96;6802051
3280;1.050374;-0.09429844;63.87744;6.600682;0;0;0;3.308265;3.25472;58623.18;6819050
3300;1.053696;-0.09628066;63.86432;6.599326;0;0;0;3.318727;3.264846;58611.13;6818340
3320;1.057017;-0.09745093;63.7791;6.59052;0;0;0;3.329188;3.27497;58532.92;6809931
3340;1.060339;-0.0980126;63.75134;6.587652;0;0;0;3.339649;3.285094;58507.45;6807657
3360;1.06366;-0.09964102;63.74134;6.586618;0;0;0;3.35011;3.295217;58498.27;6807277
3380;1.067089;-0.1009375;63.83766;6.596571;0;0;0;3.360909;3.305665;58586.66;6818276
3400;1.07041;-0.1012677;63.86623;6.599523;0;0;0;3.37137;3.315785;58612.88;6822018
3420;1.073731;-0.1010864;63.9434;6.607498;0;0;0;3.381831;3.325905;58683.71;6830953
3440;1.077053;-0.1006436;63.90114;6.603131;0;0;0;3.392293;3.336024;58644.93;6827129
3460;1.080374;-0.1002081;64.11878;6.62562;0;0;0;3.402754;3.346141;58844.66;6851074
3480;1.083696;-0.09999564;63.90831;6.603872;0;0;0;3.413215;3.356257;58651.5;6829276
3500;1.087017;-0.100357;64.17237;6.631159;0;0;0;3.423676;3.366373;58893.85;6858188
3520;1.090392;-0.1006339;64.01435;6.61483;0;0;0;3.434306;3.37665;58748.83;6842003
3540;1.09366;-0.1004739;64.10797;6.624504;0;0;0;3.444598;3.3866;58834.75;6852691
3560;1.097035;-0.1006824;64.19084;6.633067;0;0;0;3.455229;3.396876;58910.8;6862255
3580;1.10041;-0.1013577;64.21187;6.63524;0;0;0;3.465858;3.40715;58930.1;6865208
3600;1.103731;-0.102009;64.17457;6.631386;0;0;0;3.47632;3.41726;58895.87;6861914
3620;1.107053;-0.1019327;64.12709;6.626479;0;0;0;3.48678;3.427369;58852.29;6857530
3640;1.110374;-0.1018128;64.12277;6.626033;0;0;0;3.497242;3.437478;58848.33;6857762
3660;1.113696;-0.1013929;64.20873;6.634915;0;0;0;3.507703;3.447585;58927.21;6867649
3680;1.117017;-0.1012696;64.17281;6.631204;0;0;0;3.518164;3.457691;58894.25;6864501
3700;1.120339;-0.1008748;64.23108;6.637225;0;0;0;3.528625;3.467796;58947.72;6871427
3720;1.12366;-0.1006757;64.23213;6.637333;0;0;0;3.539087;3.477901;58948.69;6872234
3740;1.126981;-0.1005277;64.35354;6.649879;0;0;0;3.549548;3.488004;59060.11;6885919
3760;1.130356;-0.1005053;64.32167;6.646586;0;0;0;3.560178;3.498269;59030.86;6883216
3780;1.133731;-0.1002803;64.42067;6.656816;0;0;0;3.570808;3.508533;59121.72;6894518
3800;1.137053;-0.1001436;64.45764;6.660636;0;0;0;3.581269;3.518632;59155.65;6899171
3820;1.140321;-0.09968555;64.5364;6.668775;0;0;0;3.591561;3.528568;59227.93;6908288
3840;1.143696;-0.09830741;64.52416;6.66751;0;0;0;3.602191;3.538829;59216.7;6907686
3860;1.147017;-0.09625138;64.48213;6.663167;0;0;0;3.612652;3.548926;59178.13;6903884
3880;1.150339;-0.09388796;64.48953;6.663932;0;0;0;3.623114;3.559022;59184.92;6905373
3900;1.15366;-0.0911879;64.58036;6.673317;0;0;0;3.633575;3.569117;59268.28;6915798
3920;1.156981;-0.08836217;64.5379;6.668929;0;0;0;3.644036;3.579211;59229.3;6911947
3940;1.160303;-0.08560787;64.69072;6.684721;0;0;0;3.654497;3.589304;59369.56;6929014
3960;1.163731;-0.08294583;64.59534;6.674865;0;0;0;3.665296;3.599721;59282.02;6919519
3980;1.167053;-0.08054019;64.64532;6.680029;0;0;0;3.675757;3.609812;59327.89;6925571
4000;1.170321;-0.07809449;64.7128;6.687003;0;0;0;3.686049;3.619739;59389.83;6933489
4020;1.173696;-0.07547863;64.48069;6.663018;0;0;0;3.696679;3.629991;59176.8;6909328
4040;1.177017;-0.07363035;64.79106;6.69509;0;0;0;3.70714;3.640078;59461.65;6943286
4060;1.180339;-0.07144532;64.81212;6.697266;0;0;0;3.717602;3.650165;59480.98;6946244
4080;1.18366;-0.06949078;64.6884;6.684481;0;0;0;3.728063;3.660251;59367.43;6933683
4100;1.187089;-0.06769503;65.02538;6.719303;0;0;0;3.738862;3.670661;59676.69;6970528
4120;1.190303;-0.06590166;64.84563;6.700728;0;0;0;3.748985;3.680419;59511.73;6951938
4140;1.193731;-0.06420571;64.77838;6.693779;0;0;0;3.759784;3.690827;59450.01;6945451
4160;1.197053;-0.06263809;64.74302;6.690125;0;0;0;3.770245;3.700909;59417.56;6942360
4180;1.200374;-0.06148519;64.86448;6.702677;0;0;0;3.780706;3.710989;59529.03;6956085
4200;1.203696;-0.0599211;64.69318;6.684976;0;0;0;3.791167;3.721069;59371.82;6938414
4220;1.207017;-0.05882033;64.98553;6.715185;0;0;0;3.801629;3.731148;59640.12;6970471
4240;1.210339;-0.05753886;65.03804;6.720611;0;0;0;3.81209;3.741225;59688.3;6976806
4260;1.21366;-0.05627001;65.1074;6.727778;0;0;0;3.822551;3.751301;59751.96;6984951
4280;1.217089;-0.0549085;65.06749;6.723654;0;0;0;3.83335;3.761702;59715.34;6981395
4300;1.22041;-0.054205;65.19879;6.737222;0;0;0;3.843811;3.771776;59835.84;6996188
4320;1.223731;-0.05310071;65.06388;6.723281;0;0;0;3.854272;3.78185;59712.02;6982415
4340;1.227053;-0.05212816;65.29408;6.747069;0;0;0;3.864733;3.791922;59923.29;7007825
4360;1.230374;-0.05112818;64.95249;6.711771;0;0;0;3.875194;3.801994;59609.8;6971865
4380;1.233696;-0.05034876;65.38148;6.7561;0;0;0;3.885656;3.812064;60003.5;7018618
4400;1.237017;-0.04928123;65.29003;6.74665;0;0;0;3.896117;3.822134;59919.57;7009507
4420;1.240338;-0.04855292;65.20114;6.737465;0;0;0;3.906578;3.832202;59838;7000669
4440;1.24366;-0.04748908;65.26953;6.744532;0;0;0;3.917039;3.842269;59900.76;7008718
4460;1.247088;-0.04664859;65.13468;6.730597;0;0;0;3.927837;3.85266;59777;6994964
4480;1.25041;-0.04592013;65.27168;6.744753;0;0;0;3.938299;3.862726;59902.73;7010382
4500;1.253731;-0.04490074;65.3191;6.749654;0;0;0;3.94876;3.87279;59946.25;7016182
4520;1.257053;-0.04436776;65.44376;6.762536;0;0;0;3.959221;3.882853;60060.66;7030279
4540;1.260374;-0.04354562;65.43912;6.762056;0;0;0;3.969682;3.892915;60056.4;7030489
4560;1.263696;-0.04280434;65.31822;6.749563;0;0;0;3.980144;3.902977;59945.45;7018205
4580;1.267017;-0.04212671;65.28709;6.746346;0;0;0;3.990605;3.913037;59916.88;7015566
4600;1.270338;-0.04125926;65.58029;6.776643;0;0;0;4.001066;3.923096;60185.96;7047781
4620;1.273767;-0.04057078;65.58534;6.777165;0;0;0;4.011865;3.933479;60190.59;7049056
4640;1.277088;-0.03973722;65.33957;6.751769;0;0;0;4.022326;3.943536;59965.04;7023347
4660;1.280356;-0.03915678;65.537;6.772171;0;0;0;4.032618;3.95343;60146.23;7045266
4680;1.283678;-0.03853443;65.65899;6.784776;0;0;0;4.043079;3.963485;60258.18;7059090
4700;1.286999;-0.03787672;65.69584;6.788584;0;0;0;4.053541;3.97354;60292;7063762
4720;1.290374;-0.03713379;65.66398;6.785292;0;0;0;4.064171;3.983755;60262.77;7061058
4740;1.293696;-0.03666576;65.76497;6.795727;0;0;0;4.074632;3.993807;60355.45;7072628
4760;1.297017;-0.03590943;65.71534;6.790599;0;0;0;4.085093;4.003858;60309.9;7068001
4780;1.300338;-0.0354808;65.52326;6.77075;0;0;0;4.095554;4.013908;60133.62;7048050
4800;1.30366;-0.03469581;65.64748;6.783587;0;0;0;4.106015;4.023957;60247.62;7062121
4820;1.306981;-0.0340316;65.67817;6.786758;0;0;0;4.116477;4.034005;60275.79;7066133
4840;1.310356;-0.03342881;65.90299;6.809989;0;0;0;4.127107;4.044214;60482.12;7091045
4860;1.313678;-0.03285498;65.7189;6.790967;0;0;0;4.137568;4.054261;60313.16;7071947
4880;1.317053;-0.03216842;65.74183;6.793336;0;0;0;4.148197;4.064467;60334.21;7075137
4900;1.320374;-0.03161698;65.91186;6.810906;0;0;0;4.158659;4.074512;60490.26;7094149
4920;1.323696;-0.03105221;65.86638;6.806206;0;0;0;4.16912;4.084555;60448.51;7089965
4940;1.327017;-0.03049791;66.05262;6.825451;0;0;0;4.179581;4.094596;60619.43;7110726
4960;1.330338;-0.0300126;65.95639;6.815507;0;0;0;4.190042;4.104638;60531.12;7101079
4980;1.33366;-0.02945665;65.98041;6.817989;0;0;0;4.200504;4.114678;60553.16;7104379
5000;1.336981;-0.02882603;66.09297;6.82962;0;0;0;4.210965;4.124716;60656.46;7117213
5020;1.340356;-0.02829618;66.16709;6.837279;0;0;0;4.221594;4.134916;60724.48;7125921
5040;1.343678;-0.02768822;66.16465;6.837028;0;0;0;4.232056;4.144953;60722.25;7126374
5060;1.347053;-0.02725316;66.16726;6.837297;0;0;0;4.242686;4.155151;60724.64;7127382
5080;1.350374;-0.02674758;66.18773;6.839413;0;0;0;4.253147;4.165186;60743.43;7130303
5100;1.353696;-0.02626363;66.41832;6.86324;0;0;0;4.263608;4.17522;60955.05;7155862
5120;1.357017;-0.02578988;66.35453;6.856649;0;0;0;4.274069;4.185252;60896.52;7149707
5140;1.360338;-0.02519552;66.31522;6.852586;0;0;0;4.28453;4.195285;60860.43;7146187
5160.001;1.36366;-0.02481749;66.25933;6.846811;0;0;0;4.294991;4.205316;60809.14;7140881
5180.001;1.367088;-0.02433041;66.30152;6.851171;0;0;0;4.30579;4.215669;60847.87;7146168
5200.001;1.37041;-0.0239416;66.44242;6.865731;0;0;0;4.316252;4.225698;60977.18;7162073
5220.001;1.373731;-0.02353715;66.55284;6.877141;0;0;0;4.326713;4.235726;61078.51;7174695
5240.001;1.377053;-0.02309175;66.44912;6.866423;0;0;0;4.337174;4.245752;60983.32;7164232
5260.001;1.380374;-0.022518;66.4333;6.864788;0;0;0;4.347635;4.255778;60968.8;7163243
5280.001;1.383695;-0.02211849;66.55805;6.877678;0;0;0;4.358096;4.265803;61083.29;7177414
5300.001;1.387071;-0.02169064;66.56303;6.878194;0;0;0;4.368726;4.275989;61087.86;7178683
5320.001;1.390338;-0.02097704;66.34843;6.856018;0;0;0;4.379019;4.28585;60890.91;7156244
5340.001;1.39366;-0.0208144;66.59531;6.881529;0;0;0;4.38948;4.295871;61117.48;7183592
5360.001;1.397088;-0.02044586;66.55267;6.877123;0;0;0;4.400278;4.306215;61078.35;7179735
5380.001;1.40041;-0.02020949;66.49209;6.870863;0;0;0;4.410739;4.316235;61022.75;7173919
5400.001;1.403731;-0.01973707;66.78798;6.901439;0;0;0;4.421201;4.326254;61294.31;7206565
5420.001;1.407053;-0.01920899;66.61948;6.884027;0;0;0;4.431662;4.336272;61139.66;7189103
5440.001;1.410374;-0.0187617;66.69327;6.891652;0;0;0;4.442123;4.346289;61207.39;7197788
5460.001;1.413695;-0.01852044;66.64755;6.886927;0;0;0;4.452584;4.356304;61165.43;7193574
5480.001;1.417017;-0.01810964;66.81036;6.903751;0;0;0;4.463046;4.366319;61314.85;7211869
5500.001;1.420392;-0.01761664;66.8688;6.90979;0;0;0;4.473675;4.376494;61368.48;7218911
5520.001;1.42366;-0.01730533;66.98714;6.922019;0;0;0;4.483968;4.386346;61477.09;7232400
5540.001;1.427088;-0.0168941;67.09401;6.933062;0;0;0;4.494767;4.39668;61575.17;7244687
5560.001;1.43041;-0.01656272;66.98283;6.921573;0;0;0;4.505228;4.406691;61473.13;7233405
5580.001;1.433678;-0.01618155;67.2385;6.947992;0;0;0;4.51552;4.416539;61707.77;7261730
5600.001;1.437053;-0.01568879;67.1165;6.935386;0;0;0;4.52615;4.426709;61595.81;7249292
5620.001;1.440374;-0.01559381;67.00547;6.923913;0;0;0;4.536611;4.436717;61493.91;7238024
5640.001;1.443696;-0.01527376;67.29109;6.953426;0;0;0;4.547072;4.446724;61756.03;7269603
5660.001;1.447017;-0.01496601;67.05061;6.928577;0;0;0;4.557534;4.45673;61535.33;7244349
5680.001;1.450338;-0.0147389;66.97076;6.920325;0;0;0;4.567995;4.466734;61462.05;7236445
5700.001;1.45366;-0.01424508;67.14813;6.938654;0;0;0;4.578456;4.476738;61624.84;7256337
5720.001;1.457035;-0.01375839;67.03751;6.927223;0;0;0;4.589086;4.486902;61523.31;7245120
5740.001;1.460303;-0.01344696;67.13339;6.93713;0;0;0;4.599378;4.496742;61611.3;7256195
5760.001;1.463731;-0.0132144;67.14866;6.938709;0;0;0;4.610178;4.507066;61625.32;7258596
5780.001;1.466999;-0.01287149;67.17078;6.940994;0;0;0;4.620469;4.516904;61645.62;7261701
5800.001;1.47032;-0.0125819;67.32495;6.956925;0;0;0;4.63093;4.526902;61787.11;7279096
5820.001;1.473695;-0.01211673;67.28706;6.95301;0;0;0;4.641561;4.537061;61752.34;7275738
5840.001;1.477017;-0.01202955;67.15442;6.939304;0;0;0;4.652022;4.547058;61630.61;7262122
5860.001;1.480338;-0.01174956;67.29972;6.954318;0;0;0;4.662483;4.557054;61763.95;7278562
5880.001;1.48366;-0.01135581;67.48091;6.973042;0;0;0;4.672944;4.567048;61930.24;7298888
5900.001;1.487035;-0.01117887;67.30721;6.955092;0;0;0;4.683574;4.577203;61770.83;7280840
5920.001;1.490303;-0.01068364;67.52074;6.977157;0;0;0;4.693866;4.587035;61966.79;7304655
5940.001;1.493731;-0.01028115;67.30595;6.954962;0;0;0;4.704665;4.597349;61769.67;7282170
5960.001;1.496999;-0.01014619;67.51657;6.976726;0;0;0;4.714958;4.607178;61962.96;7305675
5980.001;1.500374;-0.009884307;67.51392;6.976452;0;0;0;4.725587;4.617329;61960.53;7306131
6000.001;1.503695;-0.009620346;67.49745;6.97475;0;0;0;4.736048;4.627317;61945.42;7305078
6020.001;1.507017;-0.009063298;67.46764;6.97167;0;0;0;4.74651;4.637306;61918.06;7302581
6040.001;1.510338;-0.008757356;67.5022;6.975242;0;0;0;4.756971;4.647292;61949.78;7307052
6060.001;1.51366;-0.008528163;67.47495;6.972425;0;0;0;4.767432;4.657277;61924.77;7304831
6080.001;1.516981;-0.008158876;67.60217;6.985571;0;0;0;4.777894;4.667262;62041.52;7319334
6100.001;1.520356;-0.008086477;67.59336;6.984661;0;0;0;4.788523;4.677407;62033.44;7319123
6120.001;1.523731;-0.007720796;67.43369;6.968162;0;0;0;4.799153;4.68755;61886.9;7302575
6140.001;1.527053;-0.007418107;67.64936;6.990448;0;0;0;4.809614;4.697532;62084.83;7326661
6160.001;1.530374;-0.007067086;67.54473;6.979636;0;0;0;4.820076;4.707513;61988.81;7316060
6180.001;1.533695;-0.006989042;67.71467;6.997197;0;0;0;4.830537;4.717493;62144.77;7335199
6200.001;1.537017;-0.006669615;67.54255;6.979411;0;0;0;4.840998;4.727471;61986.81;7317284
6220.001;1.540392;-0.006504708;67.7505;7.000899;0;0;0;4.851628;4.73761;62177.65;7340556
6240.001;1.54366;-0.006112646;67.79666;7.005669;0;0;0;4.86192;4.747425;62220.02;7346279
6260.001;1.547035;-0.006044637;67.57324;6.982582;0;0;0;4.87255;4.757562;62014.98;7322812
6280.001;1.55041;-0.005736421;67.91615;7.018016;0;0;0;4.88318;4.767697;62329.68;7360719
6300.001;1.553731;-0.005754139;67.8756;7.013826;0;0;0;4.893641;4.777671;62292.46;7357057
6320.001;1.557053;-0.005514637;67.98217;7.024838;0;0;0;4.904103;4.787644;62390.27;7369343
6340.001;1.560374;-0.005129788;67.90252;7.016608;0;0;0;4.914564;4.797615;62317.18;7361444
6360.001;1.563695;-0.005014075;67.87231;7.013486;0;0;0;4.925025;4.807586;62289.44;7358902
6380.001;1.567017;-0.004697548;67.94816;7.021324;0;0;0;4.935486;4.817556;62359.06;7367861
6400.001;1.570392;-0.004568547;67.98041;7.024656;0;0;0;4.946116;4.827685;62388.65;7372104
6420.001;1.57366;-0.0042051;67.86356;7.012581;0;0;0;4.956409;4.837492;62281.41;7360154
6440.001;1.577088;-0.00409264;68.01018;7.027733;0;0;0;4.967207;4.84778;62415.98;7376815
6460.001;1.58041;-0.003817546;68.00184;7.026871;0;0;0;4.977668;4.857746;62408.32;7376645
6480.001;1.583731;-0.003586512;68.01715;7.028452;0;0;0;4.988129;4.86771;62422.37;7379041
6500.001;1.587053;-0.003363552;68.00017;7.026698;0;0;0;4.99859;4.877674;62406.79;7377934
6520.001;1.590374;-0.00317246;68.03934;7.030746;0;0;0;5.009052;4.887637;62442.74;7382920
6540.001;1.593695;-0.002896112;67.83648;7.009784;0;0;0;5.019513;4.897599;62256.56;7361641
6560.001;1.597017;-0.002666527;68.17751;7.045024;0;0;0;5.029974;4.90756;62569.54;7399387
6580.001;1.600392;-0.002396177;68.12888;7.039999;0;0;0;5.040604;4.91768;62524.91;7394857
6600.001;1.60366;-0.002264235;68.29865;7.057541;0;0;0;5.050897;4.927477;62680.72;7414011
6620.001;1.607035;-0.002037395;68.0787;7.034813;0;0;0;5.061526;4.937596;62478.86;7390882
6640.001;1.61041;-0.001918349;68.04202;7.031023;0;0;0;5.072156;4.947713;62445.2;7387647
6660.001;1.613678;-0.001702759;68.17288;7.044545;0;0;0;5.082449;4.957509;62565.29;7402580
6680.001;1.617052;-0.001500417;68.49038;7.077353;0;0;0;5.093079;4.967623;62856.68;7437809
6700.001;1.620374;-0.001316459;68.48815;7.077123;0;0;0;5.10354;4.977577;62854.63;7438307
6720.001;1.623695;-0.0009357654;68.35277;7.063134;0;0;0;5.114001;4.98753;62730.39;7424343
6740.001;1.627017;-0.0007783843;68.41911;7.069989;0;0;0;5.124462;4.997482;62791.27;7432287
6760.001;1.630338;-0.0007813633;68.3188;7.059623;0;0;0;5.134923;5.007433;62699.21;7422129
6780.001;1.63366;-0.0005858031;68.20177;7.047531;0;0;0;5.145385;5.017382;62591.81;7410153
6800.001;1.636981;-0.0002772341;68.44328;7.072487;0;0;0;5.155846;5.027331;62813.45;7437133
6820.001;1.640356;-8.359435e-005;68.50803;7.079177;0;0;0;5.166476;5.037439;62872.88;7444922
6840.001;1.643731;5.873459e-005;68.28267;7.05589;0;0;0;5.177106;5.047546;62666.05;7421181
6860.001;1.647053;0.0003176395;68.22289;7.049713;0;0;0;5.187567;5.057492;62611.19;7415421
6880.001;1.65032;0.000368558;68.25043;7.052558;0;0;0;5.197859;5.067277;62636.46;7419140
6900.001;1.653695;0.0006573711;68.42754;7.07086;0;0;0;5.208489;5.077381;62799;7439145
6920.001;1.657017;0.0007193044;68.60984;7.089698;0;0;0;5.21895;5.087323;62966.31;7459706
6940.001;1.660338;0.0008887195;68.32731;7.060503;0;0;0;5.229412;5.097265;62707.02;7429726
6960.001;1.66366;0.00100263;68.48639;7.076941;0;0;0;5.239873;5.107206;62853.01;7447763
6980.001;1.666981;0.001341499;68.42974;7.071087;0;0;0;5.250334;5.117146;62801.02;7442343
7000.001;1.670303;0.001470814;68.30958;7.058671;0;0;0;5.260796;5.127085;62690.75;7430013
7020.001;1.673731;0.00156928;68.60021;7.088703;0;0;0;5.271594;5.137343;62957.47;7462390
7040.001;1.677052;0.00180694;68.57702;7.086306;0;0;0;5.282055;5.14728;62936.18;7460608
7060.001;1.680374;0.001998502;68.5897;7.087616;0;0;0;5.292516;5.157216;62947.83;7462730
7080.001;1.683695;0.002165839;68.82099;7.111517;0;0;0;5.302977;5.16715;63160.09;7488639
7100.001;1.687017;0.002252585;68.52145;7.080564;0;0;0;5.313439;5.177085;62885.19;7456786
7120.001;1.690338;0.002585026;68.70173;7.099193;0;0;0;5.3239;5.187018;63050.64;7477147
7140.001;1.69366;0.002584869;68.52706;7.081144;0;0;0;5.334361;5.196949;62890.34;7458877
7160.001;1.697088;0.002697486;68.78413;7.107708;0;0;0;5.34516;5.207201;63126.27;7487626
7180.001;1.700356;0.003078532;68.65851;7.094727;0;0;0;5.355452;5.216971;63010.98;7474681
7200.001;1.703731;0.003012915;68.6682;7.095728;0;0;0;5.366082;5.22706;63019.87;7476490
7220.001;1.707053;0.003214041;68.62018;7.090766;0;0;0;5.376544;5.236988;62975.8;7472005
7240.001;1.71032;0.003420734;68.51247;7.079636;0;0;0;5.386836;5.246754;62876.95;7461004
7260.001;1.713749;0.003573607;68.7121;7.100264;0;0;0;5.397634;5.257;63060.16;7483511
7280.001;1.717124;0.003772264;68.48924;7.077235;0;0;0;5.408264;5.267085;62855.63;7459991
7300.001;1.720338;0.003924667;68.6682;7.095728;0;0;0;5.418388;5.276689;63019.87;7480202
7320.001;1.72366;0.003953791;68.70866;7.099909;0;0;0;5.428849;5.286613;63057;7485352
7340.001;1.727088;0.00419392;68.58356;7.086982;0;0;0;5.439648;5.296855;62942.19;7472489
7360.001;1.73041;0.004166521;68.69971;7.098984;0;0;0;5.450109;5.306775;63048.79;7485886
7380.001;1.733731;0.004418174;68.77885;7.107162;0;0;0;5.46057;5.316695;63121.42;7495254
7400.001;1.737053;0.004518561;68.87186;7.116773;0;0;0;5.471032;5.326615;63206.77;7506134
7420.001;1.740374;0.004593155;68.79042;7.108357;0;0;0;5.481493;5.336532;63132.04;7498002
7440.001;1.743695;0.004843671;69.04941;7.135119;0;0;0;5.491954;5.34645;63369.72;7526977
7460.001;1.747124;0.005077685;68.96885;7.126795;0;0;0;5.502752;5.356686;63295.79;7518965
7480.001;1.750338;0.005206765;68.79186;7.108506;0;0;0;5.512876;5.366281;63133.36;7500389
7500.001;1.75366;0.005287435;69.01763;7.131836;0;0;0;5.523337;5.376195;63340.56;7525752
7520.001;1.757088;0.00555614;68.87382;7.116975;0;0;0;5.534136;5.386428;63208.57;7510839
7540.001;1.76041;0.005574406;69.05888;7.136099;0;0;0;5.544597;5.39634;63378.42;7531767
7560.001;1.763731;0.005595495;68.83174;7.112628;0;0;0;5.555058;5.406251;63169.96;7507738
7580.001;1.767052;0.005934795;69.17773;7.14838;0;0;0;5.565519;5.416161;63487.49;7546225
7600.001;1.770374;0.005900026;68.94424;7.124252;0;0;0;5.57598;5.42607;63273.2;7521499
7620.001;1.773695;0.006168025;68.92442;7.122204;0;0;0;5.586442;5.435979;63255.01;7520082
7640.001;1.777017;0.006311138;69.174;7.147995;0;0;0;5.596903;5.445886;63484.07;7548061
7660.001;1.780338;0.006376599;68.97634;7.127569;0;0;0;5.607365;5.455792;63302.66;7527238
7680.001;1.78366;0.006515008;68.89359;7.119018;0;0;0;5.617826;5.465698;63226.71;7518952
7700.001;1.787035;0.006476594;69.07727;7.137999;0;0;0;5.628455;5.475761;63395.29;7539758
7720.001;1.79041;0.006869557;69.15004;7.145519;0;0;0;5.639085;5.485824;63462.08;7548461
7740.001;1.793677;0.007017687;69.12555;7.142988;0;0;0;5.649377;5.495567;63439.6;7546522
7760.001;1.797052;0.007088597;69.00362;7.130388;0;0;0;5.660007;5.505628;63327.7;7533969
7780.001;1.800374;0.007095418;69.15635;7.146171;0;0;0;5.670469;5.515528;63467.87;7551392
7800.001;1.803695;0.007238335;69.0541;7.135604;0;0;0;5.68093;5.525428;63374.03;7540973
7820.001;1.807017;0.007460119;69.22269;7.153026;0;0;0;5.691391;5.535326;63528.75;7560133
7840.001;1.810338;0.00759598;69.21835;7.152577;0;0;0;5.701852;5.545223;63524.77;7560407
7860.001;1.81366;0.007621733;69.4176;7.173167;0;0;0;5.712314;5.55512;63707.63;7582920
7880.001;1.817035;0.007811532;69.36915;7.168159;0;0;0;5.722944;5.565175;63663.16;7578389
7900.001;1.820356;0.007945472;69.15016;7.14553;0;0;0;5.733405;5.575069;63462.18;7555213
7920.001;1.823677;0.008042214;69.20719;7.151424;0;0;0;5.743866;5.584963;63514.52;7562192
7940.001;1.827052;0.008134682;69.35543;7.166742;0;0;0;5.754496;5.595014;63650.57;7579152
7960.001;1.830374;0.008184543;69.40174;7.171527;0;0;0;5.764957;5.604906;63693.07;7584963
7980.001;1.833695;0.008317268;69.12482;7.142912;0;0;0;5.775418;5.614796;63438.93;7555445
8000.001;1.837017;0.008447994;69.23611;7.154413;0;0;0;5.78588;5.624686;63541.07;7568358
8020.001;1.840338;0.008612627;69.45545;7.177078;0;0;0;5.796341;5.634575;63742.37;7593086
8040.001;1.84366;0.008684752;69.23033;7.153815;0;0;0;5.806802;5.644462;63535.76;7569223
8060.001;1.847034;0.008885996;69.22404;7.153165;0;0;0;5.817431;5.654508;63529.99;7569296
8080.001;1.850409;0.008913474;69.24783;7.155624;0;0;0;5.828061;5.664553;63551.82;7572658
8100.001;1.853677;0.009112131;69.28422;7.159383;0;0;0;5.838354;5.674278;63585.21;7577374
8120.001;1.857052;0.009238741;69.18064;7.14868;0;0;0;5.848984;5.684321;63490.16;7566805
8140.001;1.860374;0.009259517;69.28833;7.159808;0;0;0;5.859445;5.694204;63588.98;7579333
8160.001;1.863695;0.009392124;69.09715;7.140054;0;0;0;5.869906;5.704086;63413.54;7559168
8180.001;1.86707;0.009384403;69.30342;7.161368;0;0;0;5.880536;5.714126;63602.84;7582494
8200;1.870338;0.00956495;69.48881;7.180525;0;0;0;5.890829;5.723846;63772.98;7603517
8220;1.873659;0.009656125;69.51492;7.183222;0;0;0;5.90129;5.733725;63796.94;7607125
8240;1.877088;0.009698773;69.29693;7.160697;0;0;0;5.912089;5.743921;63596.88;7584044
8260;1.88041;0.00986607;69.46391;7.177952;0;0;0;5.92255;5.753798;63750.13;7603070
8280;1.883731;0.009730367;69.43777;7.175251;0;0;0;5.933011;5.763673;63726.14;7600959
8300;1.887052;0.009968731;69.29928;7.16094;0;0;0;5.943472;5.773548;63599.04;7586549
8320;1.890374;0.01018158;69.44726;7.176231;0;0;0;5.953933;5.783422;63734.85;7603499
8340;1.893695;0.0101089;69.43383;7.174844;0;0;0;5.964395;5.793295;63722.53;7602780
8360;1.89707;0.01030599;69.3098;7.162027;0;0;0;5.975025;5.803326;63608.69;7589960
8380;1.900392;0.01035193;69.66331;7.198556;0;0;0;5.985486;5.813197;63933.13;7629425
8400;1.903659;0.01051966;69.73884;7.206361;0;0;0;5.995778;5.822907;64002.44;7638438
8420;1.907034;0.01059136;69.74603;7.207105;0;0;0;6.006408;5.832936;64009.04;7639993
8440;1.910409;0.01066168;69.74137;7.206622;0;0;0;6.017038;5.842963;64004.76;7640248
8460;1.913731;0.01081753;69.53407;7.185202;0;0;0;6.027499;5.85283;63814.52;7618289
8480;1.917052;0.01084803;69.49613;7.181281;0;0;0;6.037961;5.862696;63779.7;7614884
8500;1.920374;0.01112865;69.71109;7.203494;0;0;0;6.048421;5.872561;63976.97;7639191
8520;1.923695;0.01110576;69.47727;7.179333;0;0;0;6.058883;5.882425;63762.39;7614320
8540;1.92707;0.0111878;69.57286;7.189209;0;0;0;6.069513;5.892447;63850.11;7625559
8560;1.930392;0.01125553;69.54696;7.186533;0;0;0;6.079974;5.90231;63826.34;7623472
8580;1.93366;0.01140566;69.82224;7.214979;0;0;0;6.090266;5.912011;64078.98;7654390
8600;1.937035;0.01162517;69.55263;7.187119;0;0;0;6.100896;5.922031;63831.55;7625598
8620;1.940409;0.01151381;69.54114;7.185933;0;0;0;6.111526;5.932048;63821.01;7625103
8640;1.943731;0.01164787;69.65112;7.197297;0;0;0;6.121987;5.941907;63921.94;7637915
8660;1.946999;0.01165053;69.60974;7.193021;0;0;0;6.13228;5.951605;63883.96;7634117
8680;1.950374;0.01180094;69.60657;7.192694;0;0;0;6.14291;5.961621;63881.05;7634534
8700;1.953695;0.01182708;69.7053;7.202896;0;0;0;6.153371;5.971476;63971.66;7646117
8720;1.957017;0.01198301;69.9059;7.223625;0;0;0;6.163832;5.98133;64155.77;7668877
8740;1.960338;0.01215306;69.71311;7.203703;0;0;0;6.174293;5.991183;63978.83;7648480
8760;1.963659;0.0122095;69.7379;7.206264;0;0;0;6.184754;6.001035;64001.58;7651953
8780;1.967034;0.01237876;69.84156;7.216976;0;0;0;6.195384;6.011045;64096.71;7664095
8800;1.970356;0.01227253;69.62798;7.194906;0;0;0;6.205845;6.020896;63900.7;7641410
8820;1.973731;0.01256048;69.74019;7.206501;0;0;0;6.216475;6.030904;64003.68;7654491
8840;1.976999;0.01246856;69.48855;7.180498;0;0;0;6.226768;6.040594;63772.74;7627611
8860;1.980374;0.01267361;69.6064;7.192676;0;0;0;6.237397;6.0506;63880.89;7641311
8880;1.983695;0.01265221;69.64713;7.196884;0;0;0;6.247858;6.060446;63918.27;7646535
8900;1.987017;0.01278638;69.68721;7.201026;0;0;0;6.25832;6.070292;63955.06;7651690
8920;1.990338;0.0128767;69.81777;7.214518;0;0;0;6.268781;6.080137;64074.89;7666780
8940;1.993659;0.01307151;69.95163;7.228349;0;0;0;6.279242;6.08998;64197.73;7682235
8960;1.996981;0.01301644;69.91087;7.224138;0;0;0;6.289703;6.099823;64160.32;7678514
8980;2.000356;0.01322787;69.71373;7.203766;0;0;0;6.300333;6.109824;63979.39;7657628
9000;2.003731;0.01325194;69.91592;7.224659;0;0;0;6.310963;6.119823;64164.96;7680605
9020;2.006999;0.01342441;69.94017;7.227166;0;0;0;6.321256;6.129504;64187.21;7684013
9040;2.010374;0.01351426;70.06031;7.23958;0;0;0;6.331886;6.139501;64297.47;7697982
9060;2.013695;0.01346451;69.83149;7.215935;0;0;0;6.342347;6.149339;64087.47;7673594
9080;2.017017;0.01361625;69.96194;7.229414;0;0;0;6.352808;6.159176;64207.19;7688685
9100;2.020338;0.01353429;70.00601;7.233969;0;0;0;6.363269;6.169011;64247.64;7694286
9120;2.023659;0.01365467;70.04722;7.238227;0;0;0;6.373731;6.178847;64285.45;7699572
9140;2.026981;0.01372777;69.80482;7.21318;0;0;0;6.384192;6.18868;64063;7673683
9160;2.030356;0.01375972;70.05485;7.239016;0;0;0;6.394822;6.198672;64292.46;7701938
9180;2.033731;0.01393137;70.12286;7.246044;0;0;0;6.405451;6.208662;64354.88;7710185
9200;2.037052;0.01402203;69.87028;7.219944;0;0;0;6.415913;6.218494;64123.07;7683169
9220;2.040374;0.01409835;70.07914;7.241525;0;0;0;6.426374;6.228324;64314.75;7706893
9240;2.043695;0.01431437;70.09262;7.242918;0;0;0;6.436835;6.238152;64327.12;7709133
9260;2.047017;0.01412555;70.14976;7.248823;0;0;0;6.447297;6.247981;64379.56;7716176
9280;2.050391;0.01430834;69.9205;7.225133;0;0;0;6.457926;6.257966;64169.16;7691727
9300;2.053659;0.01440265;70.03127;7.236579;0;0;0;6.468219;6.267634;64270.82;7704657
9320;2.057088;0.01430928;70.00114;7.233465;0;0;0;6.479017;6.277775;64243.16;7702123
9340;2.060409;0.01452502;70.13757;7.247564;0;0;0;6.489479;6.2876;64368.38;7717893
9360;2.063731;0.01455336;69.99574;7.232907;0;0;0;6.499939;6.297423;64238.21;7703042
9380;2.067052;0.01450844;70.09952;7.243631;0;0;0;6.510401;6.307245;64333.45;7715221
9400;2.070374;0.01461581;69.83936;7.216748;0;0;0;6.520862;6.317066;64094.7;7687342
9420;2.073695;0.01475136;69.88555;7.221521;0;0;0;6.531322;6.326886;64137.09;7693182
9440;2.077017;0.01487989;69.98135;7.231421;0;0;0;6.541784;6.336706;64225;7704484
9460;2.080391;0.01489537;70.27486;7.26175;0;0;0;6.552414;6.346683;64494.38;7737570
9480;2.083659;0.01489219;70.11447;7.245176;0;0;0;6.562707;6.356342;64347.17;7720656
9500;2.087088;0.01520096;70.17146;7.251066;0;0;0;6.573505;6.366475;64399.48;7727715
9520;2.090409;0.01504789;70.24955;7.259134;0;0;0;6.583967;6.376291;64471.14;7737073
9540;2.093731;0.015076;70.32558;7.266991;0;0;0;6.594428;6.386105;64540.92;7746207
9560;2.097052;0.01517677;70.12381;7.246141;0;0;0;6.604888;6.395918;64355.74;7724741
9580;2.100374;0.0153329;70.11103;7.244821;0;0;0;6.61535;6.405731;64344.02;7724091
9600;2.103749;0.01537375;70.12049;7.245798;0;0;0;6.62598;6.415701;64352.7;7725903
9620;2.107016;0.01543305;70.24755;7.258928;0;0;0;6.636272;6.425353;64469.31;7740650
9640;2.110391;0.01547868;69.73869;7.206346;0;0;0;6.646902;6.435321;64002.31;7685345
9660;2.113659;0.01549271;70.22224;7.256312;0;0;0;6.657195;6.444972;64446.08;7739379
9680;2.117034;0.01554398;70.11062;7.244778;0;0;0;6.667825;6.454938;64343.64;7727847
9700;2.120356;0.0157132;70.25469;7.259665;0;0;0;6.678286;6.464744;64475.86;7744487
9720;2.123731;0.01578584;70.12689;7.246459;0;0;0;6.688916;6.474709;64358.57;7731169
9740;2.127052;0.01580297;70.24171;7.258325;0;0;0;6.699377;6.484513;64463.95;7744587
9760;2.13032;0.0159607;69.92681;7.225785;0;0;0;6.70967;6.494159;64174.95;7710611
9780;2.133695;0.01604486;70.38519;7.273151;0;0;0;6.720299;6.50412;64595.63;7761929
9800;2.137017;0.01593197;70.18597;7.252565;0;0;0;6.730761;6.513922;64412.8;7740718
9820;2.140338;0.01601001;70.13857;7.247667;0;0;0;6.741222;6.523723;64369.29;7736248
9840;2.143659;0.01612965;70.08616;7.24225;0;0;0;6.751683;6.533523;64321.19;7731224
9860;2.146981;0.01609006;70.09796;7.243471;0;0;0;6.762144;6.543322;64332.02;7733284
9880;2.150356;0.01612314;70.27061;7.261311;0;0;0;6.772773;6.553278;64490.47;7753103
9900;2.153731;0.01619777;70.23883;7.258027;0;0;0;6.783404;6.563233;64461.31;7750369
9920;2.157052;0.01629494;70.43521;7.278319;0;0;0;6.793865;6.573029;64641.53;7772798
9940;2.16032;0.01631211;70.3731;7.271901;0;0;0;6.804158;6.582667;64584.53;7766693
9960;2.163695;0.01628342;70.24526;7.258691;0;0;0;6.814787;6.592619;64467.21;7753356
9980;2.167017;0.01651983;70.25569;7.259769;0;0;0;6.825249;6.602412;64476.78;7755266
10000;2.170338;0.01661167;70.41802;7.276544;0;0;0;6.83571;6.612205;64625.76;7773947
10020;2.173659;0.01654766;70.28338;7.262631;0;0;0;6.84617;6.621996;64502.2;7759843
10040;2.177088;0.01667109;70.21408;7.255469;0;0;0;6.85697;6.632102;64438.59;7752975
10060;2.180302;0.01667486;70.41153;7.275873;0;0;0;6.867093;6.641576;64619.8;7775514
10080;2.183731;0.01679625;70.34546;7.269045;0;0;0;6.877892;6.65168;64559.16;7769002
10100;2.187052;0.01669379;70.48099;7.28305;0;0;0;6.888353;6.661467;64683.54;7784732
10120;2.190374;0.01679735;70.37691;7.272295;0;0;0;6.898815;6.671254;64588.03;7773997
10140;2.193695;0.01691263;70.43106;7.277891;0;0;0;6.909276;6.68104;64637.73;7780741
10160;2.197017;0.01693607;70.35157;7.269677;0;0;0;6.919737;6.690825;64564.77;7772719
10180;2.200338;0.01707311;70.47691;7.282628;0;0;0;6.930198;6.700608;64679.8;7787329
10200;2.203713;0.01696559;70.19358;7.253351;0;0;0;6.940828;6.710549;64419.78;7756793
10220;2.207088;0.0169376;70.35192;7.269713;0;0;0;6.951458;6.720488;64565.09;7775064
10240;2.210409;0.01713685;70.3797;7.272584;0;0;0;6.961918;6.730268;64590.59;7778895
10260;2.213731;0.0170091;70.29795;7.264136;0;0;0;6.97238;6.740049;64515.56;7770619
10280;2.217052;0.01711701;70.41964;7.276711;0;0;0;6.982841;6.749827;64627.24;7784832
10300;2.220374;0.0172241;70.44114;7.278932;0;0;0;6.993303;6.759606;64646.97;7787970
10320;2.223748;0.01730489;70.61452;7.296848;0;0;0;7.003932;6.76954;64806.09;7807914
10340;2.227124;0.01735279;70.43773;7.27858;0;0;0;7.014563;6.779474;64643.84;7789140
10360;2.230338;0.01727867;70.20621;7.254656;0;0;0;7.024686;6.788933;64431.37;7764273
10380;2.233767;0.01750727;70.52175;7.287262;0;0;0;7.035485;6.799023;64720.95;7799956
10400;2.237088;0.01758124;70.32526;7.266958;0;0;0;7.045946;6.808796;64540.63;7778984
10420;2.240409;0.01752812;70.64861;7.300371;0;0;0;7.056407;6.818568;64837.38;7815515
10440;2.243731;0.01758371;70.36886;7.271464;0;0;0;7.066868;6.828339;64580.64;7785329
10460;2.247052;0.01767159;70.45582;7.280449;0;0;0;7.077329;6.838109;64660.45;7795711
10480;2.250374;0.0175725;70.45946;7.280825;0;0;0;7.087791;6.847879;64663.79;7796875
10500;2.253749;0.01771867;70.35128;7.269646;0;0;0;7.098421;6.857804;64564.5;7785676
10520;2.25707;0.01774156;70.36584;7.271152;0;0;0;7.108882;6.867572;64577.87;7788049
10540;2.260391;0.01773658;70.31997;7.266411;0;0;0;7.119343;6.877338;64535.77;7783732
10560;2.263767;0.01779785;70.4148;7.27621;0;0;0;7.129973;6.887261;64622.8;7795002
10580;2.267034;0.0178688;70.39089;7.27374;0;0;0;7.140265;6.896868;64600.86;7793104
10600;2.270356;0.01786993;70.59279;7.294602;0;0;0;7.150726;6.906631;64786.15;7816220
10620;2.273677;0.01785664;70.48665;7.283635;0;0;0;7.161188;6.916395;64688.74;7805230
10640;2.277052;0.01800293;70.38466;7.273097;0;0;0;7.171818;6.926313;64595.14;7794710
10660;2.28032;0.01805687;70.44487;7.279317;0;0;0;7.18211;6.935917;64650.39;7802126
10680;2.283695;0.01810563;70.56265;7.291489;0;0;0;7.19274;6.945834;64758.49;7815947
10700;2.287016;0.0181736;70.55364;7.290557;0;0;0;7.203201;6.955592;64750.22;7815710
10720;2.290338;0.01815753;70.42704;7.277475;0;0;0;7.213663;6.96535;64634.04;7802448
10740;2.293659;0.01830594;70.74737;7.310576;0;0;0;7.224123;6.975107;64928.02;7838701
10760;2.296981;0.01811045;70.45048;7.279897;0;0;0;7.234585;6.984863;64655.54;7806567
10780;2.300302;0.01835756;70.4708;7.281997;0;0;0;7.245046;6.994618;64674.19;7809581
10800;2.303677;0.01813766;70.41109;7.275828;0;0;0;7.255676;7.004529;64619.4;7803738
10820;2.306999;0.01826109;70.46639;7.281542;0;0;0;7.266137;7.014282;64670.15;7810629
10840;2.310374;0.01838288;70.38;7.272614;0;0;0;7.276767;7.024192;64590.86;7801826
10860;2.313695;0.01845415;70.45811;7.280686;0;0;0;7.287229;7.033943;64662.55;7811246
10880;2.317016;0.01839688;70.51485;7.286549;0;0;0;7.297689;7.043693;64714.62;7818299
10900;2.320338;0.01855986;70.40419;7.275115;0;0;0;7.308151;7.053442;64613.07;7806791
10920;2.323659;0.01845728;70.64714;7.30022;0;0;0;7.318612;7.06319;64836.04;7834494
10940;2.326981;0.01857817;70.58894;7.294205;0;0;0;7.329073;7.072938;64782.62;7828802
10960;2.330356;0.01852713;70.41374;7.276101;0;0;0;7.339703;7.082841;64621.82;7810145
10980;2.333677;0.01882578;70.45367;7.280228;0;0;0;7.350164;7.092587;64658.48;7815336
11000;2.337052;0.01885836;70.68221;7.303843;0;0;0;7.360794;7.102488;64868.21;7841464
11020;2.340374;0.01882637;70.54157;7.28931;0;0;0;7.371255;7.112232;64739.14;7826623
11040;2.343641;0.01870819;70.73089;7.308874;0;0;0;7.381547;7.121817;64912.89;7848381
11060;2.347016;0.01866299;70.64717;7.300222;0;0;0;7.392177;7.131716;64836.06;7839868
11080;2.350338;0.01879054;70.62527;7.297959;0;0;0;7.402639;7.141457;64815.96;7838200
11100;2.353659;0.0187847;70.67404;7.302999;0;0;0;7.4131;7.151196;64860.72;7844378
11120;2.356981;0.01888932;70.55734;7.290939;0;0;0;7.423561;7.160935;64753.62;7832187
11140;2.360409;0.01874594;70.54539;7.289705;0;0;0;7.43436;7.170987;64742.65;7831647
11160;2.363677;0.01893087;70.46102;7.280986;0;0;0;7.444653;7.180567;64665.21;7823030
11180;2.367052;0.01882096;70.70203;7.305891;0;0;0;7.455282;7.190459;64886.41;7850566
11200;2.370373;0.01884189;70.52113;7.287198;0;0;0;7.465743;7.200194;64720.38;7831241
11220;2.373695;0.01902769;70.6161;7.297012;0;0;0;7.476204;7.209928;64807.55;7842551
11240;2.377123;0.01899543;70.38772;7.273412;0;0;0;7.487002;7.219975;64597.95;7817972
11260;2.380391;0.01910464;70.60382;7.295743;0;0;0;7.497296;7.22955;64796.28;7842726
11280;2.383659;0.0190429;70.61158;7.296544;0;0;0;7.507588;7.239124;64803.39;7844339
11300;2.386981;0.01913455;70.53261;7.288384;0;0;0;7.51805;7.248855;64730.92;7836329
11320;2.390409;0.01919656;70.44801;7.279642;0;0;0;7.528848;7.258898;64653.28;7827715
11340;2.393731;0.01910687;70.6524;7.300762;0;0;0;7.539309;7.268626;64840.86;7851189
11360;2.397052;0.01914345;70.52545;7.287644;0;0;0;7.54977;7.278354;64724.35;7837844
11380;2.400373;0.01927688;70.67698;7.303302;0;0;0;7.560231;7.288079;64863.41;7855449
11389.89;2.401981;0.01906089;70.73084;7.308868;0;0;0;7.565293;7.292786;64912.84;7861805